File: PPMS_Data_and_Plotting/Data/RuCl3/Data/Magnetisation/Rotator/TB001_RuCl3_H-parra-ab_61p2_mg_14-06-25_ZFCW_5K.dat
[Header]
; MPMS3 Data File (default extension .dat)
; Copyright (c) 2007, Quantum Design, Inc. All rights reserved.
TITLE,
FILEOPENTIME,3959097772.57813,06/14/2025,9:22 pm
BYAPP,MPMS3 w/ AC,1.0,1.1
INFO,MPMS3 Measurement Release 1.2.2 Build 0, MultiVu Release 2.3.5.2,APPNAME
INFO,Linear Motor Servo Controller,MOTOR_MODULE_NAME
INFO,3101-100 N4,MOTOR_HW_VERSION
INFO,MMC1299,MOTOR_SERIAL_NUMBER
INFO,01.04.28,MOTOR_SOFTWARE_VERSION
INFO,Quantum Design Squid Module,SQUID_MODULE_NAME
INFO,3101-501 B0,SQUID_HW_VERSION
INFO,SQM364,SQUID_SERIAL_NUMBER
INFO,01.03.04,SQUID_SOFTWARE_VERSION
INFO,Quantum Design VSM Oven,OVEN_MODULE_NAME
INFO,3101-201 A3,OVEN_HW_VERSION
INFO,OVB387,OVEN_SERIAL_NUMBER
INFO,01.07.07,OVEN_SOFTWARE_VERSION
INFO,SQUID AC,AC_MODULE_NAME
INFO,3101-401 G0,AC_HW_VERSION
INFO,SAC242,AC_SERIAL_NUMBER
INFO,SQUID AC 00.95.11,AC_SOFTWARE_VERSION
INFO,TCI374,COIL_SERIAL_NUMBER
INFO,0,MOMENT_UNITS
INFO,RuCl3,SAMPLE_MATERIAL
INFO,single crystal,SAMPLE_COMMENT
INFO,61.2,SAMPLE_MASS
INFO,,SAMPLE_VOLUME
INFO,,SAMPLE_MOLECULAR_WEIGHT
INFO,,SAMPLE_SIZE
INFO,,SAMPLE_SHAPE
INFO,Rotator,SAMPLE_HOLDER
INFO,Standard,SAMPLE_HOLDER_DETAIL
INFO,67.44,SAMPLE_OFFSET
DATATYPE,COMMENT,1
DATATYPE,TIME,2
STARTUPAXIS,X,2
STARTUPAXIS,Y1,5
FIELDGROUP, VSM,2,3,4,5,6,8,9,10,11,14,15
FIELDGROUP, DC, 2,3,4,14,56,57,58,59,60,61,62,63,64,65,66,67,68,69
FIELDGROUP, AC, 2,3,4,11,16,17,18,19,20,21,22,23,24,25,26,27,28,29,30
STARTUPGROUP, All
[Data]
Comment,Time Stamp (sec),Temperature (K),Magnetic Field (Oe),Moment (emu),M. Std. Err. (emu),Transport Action,Averaging Time (sec),Frequency (Hz),Peak Amplitude (mm),Center Position (mm),Lockin Signal' (V),Lockin Signal (V),Range,M. Quad. Signal (emu),AC Moment (emu),AC M. Std Err. (emu),AC Phase (deg),AC Phase Std. Err. (deg),AC Susceptibility (emu/Oe),AC Suscept. Std Err. (emu/Oe),AC X' (emu/Oe),AC X' Std Err. (emu/Oe),AC X'' (emu/Oe),AC X'' Std Err. (emu/Oe),AC Drive (Oe),AC Frequency (Hz),AC Averaging Time (sec),AC Cycles,AC Range,AC Measure Type,AC Signal' (V),AC Signal'' (V),AC Trim Coil Ratio,AC Trim Coil Phase,Min. Temperature (K),Max. Temperature (K),Min. Field (Oe),Max. Field (Oe),Mass (grams),Motor Lag (deg),Pressure (Torr),Measure Count,Measurement Number,SQUID Status (code),Motor Status (code),Measure Status (code),Motor Current (amps),Motor Temp. (C),Temp. Status (code),Field Status (code),Chamber Status (code),Chamber Temp (K),Redirection State,Average Temp (K),Rotation Angle (deg),Rotator state,DC Moment Fixed Ctr (emu),DC Moment Err Fixed Ctr (emu),DC Moment Free Ctr (emu),DC Moment Err Free Ctr (emu),DC Fixed Fit,DC Free Fit,DC Calculated Center (mm),DC Calculated Center Err (mm),DC Scan Length (mm),DC Scan Time (s),DC Number of Points,DC Squid Drift,DC Min V (V),DC Max V (V),DC Scans per Measure,He3 temp,Map 02,Map 03,Map 04,Map 05,Map 06,Map 07,Map 08,Map 09,Map 10,Map 11,Map 12,Map 13,Map 14,Map 15,Map 16
,3959099070.23962,5.0061354637146,999.978332519531,,,6,,,,30.738023492992,,,10,,,,,,,,,,,,,,,,,,,,,,4.99377965927124,5.00618076324463,999.978332519531,999.978332519531,,,3.98064923286438,,1,0,0,0,7.62939453125E-5,34.7018585205078,6,1,1,5.00609016418457,0,5.00033696492513,-299.995208740234,1,0.0035126808936016,0.000173076335101551,0.00351270490207532,0.000173074571620253,0.985202610492706,0.986401438713074,30.7160243988037,3.82517043817643E-7,30,4,200,-0.000677020696457475,-1.43811631202698,0.187081933021545,1,,,,,,,,,,,,,,,,
,3959099196.95992,5.00163626670837,999.978332519531,,,6,,,,30.738023492992,,,10,,,,,,,,,,,,,,,,,,,,,,4.99345970153809,5.00575685501099,999.978332519531,999.978332519531,,,4.01062965393066,,1,0,0,0,0.000152587890625,34.7018585205078,1,1,1,5.00340127944946,0,5.00019720622471,-295.996826171875,1,0.00351098884709733,9.98757384824935E-5,0.00351102498933595,9.98749481556008E-5,0.986505210399628,0.987929344177246,30.715238571167,0,30,4,200,-0.000634233059827238,-1.44158113002777,0.183114066720009,3,,,,,,,,,,,,,,,,
,3959099328.46862,5.00109648704529,999.978332519531,,,6,,,,30.738023492992,,,10,,,,,,,,,,,,,,,,,,,,,,4.99826765060425,5.00283002853394,999.978332519531,999.978332519531,,,4.01511287689209,,1,0,0,0,0.000152587890625,35.190616607666,1,1,1,5.00191831588745,0,5.00027778413561,-289.996826171875,1,0.00354965362786348,0.000174894186688773,0.00354967511598551,0.000174891788915188,0.986778318881988,0.988368451595306,30.7142906188965,0,30,4,200,-0.000296365993563086,-1.45799851417542,0.184694856405258,1,,,,,,,,,,,,,,,,
,3959099456.50146,5.0013689994812,999.978332519531,,,6,,,,30.738023492992,,,10,,,,,,,,,,,,,,,,,,,,,,4.99681520462036,5.00310850143433,999.978332519531,999.978332519531,,,4.02480745315552,,1,0,0,0,0.00030517578125,35.190616607666,1,1,1,5.0016975402832,0,5.00021144321987,-285.998413085938,1,0.00358271552503167,0.000101918173958074,0.00358281656604208,0.000101918095511034,0.985042929649353,0.98712432384491,30.7093086242676,0,30,4,200,-0.000396626448491588,-1.47260570526123,0.186744466423988,3,,,,,,,,,,,,,,,,
,3959099584.97146,5.00436544418335,999.978332519531,,,6,,,,30.738023492992,,,10,,,,,,,,,,,,,,,,,,,,,,4.99727630615234,5.00536870956421,999.978332519531,999.978332519531,,,4.02865076065063,,1,0,0,0,0,34.7018585205078,1,1,1,5.0048942565918,0,5.00076092614068,-279.998413085938,1,0.00362213323682233,0.000178473693457029,0.00362218221872999,0.000178471705997721,0.983608067035675,0.985188186168671,30.7115268707275,0,30,4,200,-0.00037994357990101,-1.48929023742676,0.188796684145927,1,,,,,,,,,,,,,,,,
,3959099709.96789,5.00358986854553,999.978332519531,,,6,,,,30.738023492992,,,10,,,,,,,,,,,,,,,,,,,,,,4.99171257019043,5.00703907012939,999.978332519531,999.978332519531,,,4.03517866134644,,1,0,0,0,0.000152587890625,34.7018585205078,1,1,1,5.00600862503052,0,4.99995501836141,-275.995208740234,1,0.00366837576367564,0.000104357530016423,0.00366837964314311,0.000104357178812056,0.983495354652405,0.983765482902527,30.7268218994141,0,30,4,200,-0.000890962837729603,-1.50846695899963,0.191961646080017,3,,,,,,,,,,,,,,,,
,3959099840.13016,5.00670194625854,999.978332519531,,,6,,,,30.738023492992,,,10,,,,,,,,,,,,,,,,,,,,,,4.99244070053101,5.00975131988525,999.978332519531,999.978332519531,,,4.03479719161987,,1,0,0,0,7.62939453125E-5,34.7018585205078,6,1,1,5.0072078704834,0,5.00388177235921,-269.995208740234,1,0.00373445585412825,0.00018400788760901,0.00373451517235472,0.000184009622328869,0.983696520328522,0.984097361564636,30.7515544891357,5.95148435422743E-7,30,4,200,-0.000915683107450604,-1.53274083137512,0.197318911552429,1,,,,,,,,,,,,,,,,
,3959099967.0741,5.00181865692139,999.978332519531,,,6,,,,30.738023492992,,,10,,,,,,,,,,,,,,,,,,,,,,4.99316644668579,5.00617599487305,999.978332519531,999.978332519531,,,4.03912925720215,,1,0,0,0,7.62939453125E-5,34.7018585205078,6,1,1,5.0032844543457,0,4.99992043883712,-265.996826171875,1,0.00377666825711573,0.00010743796520386,0.00377685147583907,0.000107439427521729,0.983620524406433,0.985910952091217,30.7695198059082,7.73056854086462E-6,30,4,200,-0.000797478889580816,-1.54863560199738,0.200326561927795,3,,,,,,,,,,,,,,,,
,3959100096.41245,5.00140023231506,999.978332519531,,,6,,,,30.738023492992,,,10,,,,,,,,,,,,,,,,,,,,,,4.99756383895874,5.00379085540771,999.978332519531,999.978332519531,,,4.03674745559692,,1,0,0,0,0.0002288818359375,34.7018585205078,1,1,1,5.00169801712036,0,5.0006019115448,-259.996826171875,1,0.00382689778456458,0.000188565415537779,0.00382745517911923,0.000188574735165271,0.982854545116425,0.989921927452087,30.7905311584473,5.45656212125323E-6,30,4,200,8.85023400769569E-5,-1.5669252872467,0.202843353152275,1,,,,,,,,,,,,,,,,
,3959100222.26301,5.00141263008118,999.978332519531,,,6,,,,30.738023492992,,,10,,,,,,,,,,,,,,,,,,,,,,4.99660062789917,5.00327920913696,999.978332519531,999.978332519531,,,4.04039192199707,,1,0,0,0,0.00030517578125,34.2131004333496,1,1,1,5.00156354904175,0,5.00021215721413,-255.998413085938,1,0.00385434804704718,0.000109649771221881,0.00385484381807047,0.000109650835899999,0.982566177845001,0.991865813732147,30.796272277832,5.54943895339966,30,4,200,-0.000500880763866007,-1.57772541046143,0.203543916344643,3,,,,,,,,,,,,,,,,
,3959100352.49741,5.00344777107239,999.978332519531,,,6,,,,30.738023492992,,,10,,,,,,,,,,,,,,,,,,,,,,4.99788761138916,5.00500392913818,999.978332519531,999.978332519531,,,4.04035949707031,,1,0,0,0,0,34.7018585205078,1,1,1,5.00463390350342,0,5.00032652748956,-249.998413085938,1,0.0038876090278342,0.000191563990335843,0.00388835369404432,0.000191570904871332,0.980829000473022,0.992468655109406,30.8047180175781,0,30,4,200,1.13146579678869E-5,-1.59025537967682,0.204025834798813,1,,,,,,,,,,,,,,,,
,3959100479.44405,5.0028121471405,999.978332519531,,,6,,,,30.738023492992,,,10,,,,,,,,,,,,,,,,,,,,,,4.99392461776733,5.00584697723389,999.978332519531,999.978332519531,,,4.04372596740723,,1,0,0,0,0.000152587890625,34.7018585205078,1,1,1,5.00421333312988,0,5.00006333419255,-245.995208740234,1,0.00390292474070829,0.000111039623095685,0.0039037916301882,0.000111042459960335,0.978861689567566,0.992662072181702,30.81298828125,0,30,4,200,-0.000882905500475317,-1.59663486480713,0.203127205371857,3,,,,,,,,,,,,,,,,
,3959100607.72824,5.00553441047668,999.978332519531,,,6,,,,30.738023492992,,,10,,,,,,,,,,,,,,,,,,,,,,4.99546480178833,5.00606107711792,999.978332519531,999.978332519531,,,4.0437479019165,,1,0,0,0,0.000152587890625,34.7018585205078,6,1,1,5.00507879257202,0,5.00042714012994,-239.995208740234,1,0.00390833337761388,0.000192618748157298,0.00390973052657013,0.000192628099611768,0.973244428634644,0.990081489086151,30.8320560455322,0,30,4,200,-0.00101941986940801,-1.59857881069183,0.200147792696953,1,,,,,,,,,,,,,,,,
,3959100733.03545,5.00377702713013,999.978332519531,,,6,,,,30.738023492992,,,10,,,,,,,,,,,,,,,,,,,,,,4.99212074279785,5.00629091262817,999.978332519531,999.978332519531,,,4.04762983322144,,1,0,0,0,0.000152587890625,34.7018585205078,6,1,1,5.00575542449951,0,5.0001973765237,-235.996810913086,1,0.00390027448699867,0.000110991530469875,0.00390205809088087,0.00011099761339853,0.969355225563049,0.988391935825348,30.8455791473389,0,30,4,200,-0.000836645776871592,-1.59656381607056,0.196439430117607,3,,,,,,,,,,,,,,,,
,3959100865.2656,5.0035834312439,999.978332519531,,,6,,,,30.738023492992,,,10,,,,,,,,,,,,,,,,,,,,,,4.99593305587769,5.01260662078857,999.978332519531,999.978332519531,,,4.04186153411865,,1,0,0,0,0.000152587890625,33.7243423461914,1,1,1,5.00510549545288,0,5.00295209884644,-229.996810913086,1,0.00387560216891253,0.000191065967828528,0.00387836013702972,0.000191096849338142,0.963297426700592,0.984237849712372,30.8641471862793,5.55555105209351,30,4,200,-0.000836910679936409,-1.58850347995758,0.189534738659859,1,,,,,,,,,,,,,,,,
,3959100990.86698,5.00118803977966,999.978332519531,,,6,,,,30.738023492992,,,10,,,,,,,,,,,,,,,,,,,,,,4.99635553359985,5.00368690490723,999.978332519531,999.978332519531,,,4.04000759124756,,1,0,0,0,0.0002288818359375,34.7018585205078,1,1,1,5.00173997879028,0,5.00025066307613,-225.998413085938,1,0.00385782665574826,0.000109818303494208,0.00386061025514184,0.000109829358086038,0.960382163524628,0.981847941875458,30.8721580505371,0,30,4,200,-0.000320193503284827,-1.58333659172058,0.185291364789009,3,,,,,,,,,,,,,,,,
,3959101121.02566,5.00193643569946,999.978332519531,,,6,,,,30.738023492992,,,10,,,,,,,,,,,,,,,,,,,,,,4.99792242050171,5.00362491607666,999.978332519531,999.978332519531,,,4.03787755966186,,1,0,0,0,0,34.7018585205078,1,1,1,5.00303030014038,0,5.00029775831434,-219.998413085938,1,0.00382913933913323,0.000188817210429907,0.00383205698813935,0.000188835023184385,0.957689344882965,0.978621959686279,30.8772640228271,5.35480165481567,30,4,200,-0.000152059103129432,-1.57472538948059,0.178605228662491,1,,,,,,,,,,,,,,,,
,3959101244.40603,5.00304269790649,999.978332519531,,,6,,,,30.738023492992,,,10,,,,,,,,,,,,,,,,,,,,,,4.99346780776978,5.00593709945679,999.978332519531,999.978332519531,,,4.04543733596802,,1,0,0,0,0,34.7018585205078,1,1,1,5.00593709945679,0,4.99983041627066,-215.995208740234,1,0.00380088002623356,0.000108227175567822,0.00380415074904425,0.000108236263637825,0.953926980495453,0.976073861122131,30.8882713317871,0.223665297031403,30,4,200,-0.000649965659249574,-1.56630980968475,0.173683851957321,3,,,,,,,,,,,,,,,,
,3959101374.16799,5.00497555732727,999.978332519531,,,6,,,,30.738023492992,,,10,,,,,,,,,,,,,,,,,,,,,,4.99502182006836,5.00530195236206,999.978332519531,999.978332519531,,,4.04234504699707,,1,0,0,0,0,34.7018585205078,6,1,1,5.00543546676636,0,5.00015523698595,-209.995208740234,1,0.00374755377074573,0.000184890453106235,0.00375190575984972,0.000184912839014943,0.946805655956268,0.972535908222199,30.9117984771729,0,30,4,200,-0.000860854110214859,-1.55043733119965,0.164243280887604,1,,,,,,,,,,,,,,,,
,3959101500.17279,5.00286173820496,999.978332519531,,,6,,,,30.738023492992,,,10,,,,,,,,,,,,,,,,,,,,,,4.99270963668823,5.00685739517212,999.978332519531,999.978332519531,,,4.04896402359009,,1,0,0,0,0.000152587890625,35.190616607666,6,1,1,5.00390386581421,0,5.00036663668496,-205.996810913086,1,0.00370306128458236,0.000105512374952322,0.00370834828908851,0.000105525960858911,0.941208779811859,0.970570683479309,30.9324855804443,0,30,4,200,-0.000858488550875336,-1.53772556781769,0.156837522983551,3,,,,,,,,,,,,,,,,
,3959101632.58771,5.00125598907471,999.978332519531,,,6,,,,30.738023492992,,,10,,,,,,,,,,,,,,,,,,,,,,4.99398326873779,5.004723072052,999.978332519531,999.978332519531,,,4.04509401321411,,1,0,0,0,0.000152587890625,34.7018585205078,6,1,1,5.00223970413208,0,4.99993834495544,-199.996810913086,1,0.00363014632894171,0.000179237138806503,0.00363673237099601,0.000179257178630575,0.933840751647949,0.968622863292694,30.9606704711914,0,30,4,200,-0.00134843098931015,-1.5160619020462,0.145608082413673,1,,,,,,,,,,,,,,,,
,3959101761.01576,4.99778437614441,999.978332519531,,,6,,,,30.738023492992,,,10,,,,,,,,,,,,,,,,,,,,,,4.99072885513306,5.0037989616394,999.978332519531,999.978332519531,,,4.04520606994629,,1,0,0,0,0.00030517578125,34.7018585205078,1,1,1,4.99416303634644,0,4.99877458148532,-195.998413085938,1,0.00359391645261183,0.000102464673030501,0.00360176154174946,0.000102499562455906,0.931697010993958,0.968446731567383,30.9703750610352,0,30,4,200,-0.000284975423710421,-1.50603675842285,0.13935175538063,3,,,,,,,,,,,,,,,,
,3959101893.5139,5.00257873535156,999.978332519531,,,6,,,,30.738023492992,,,10,,,,,,,,,,,,,,,,,,,,,,4.99757385253906,5.00365495681763,999.978332519531,999.978332519531,,,4.04166507720947,,1,0,0,0,0.000152587890625,37.1456527709961,1,1,1,5.00365495681763,0,5.00038924217224,-189.998413085938,1,0.00354751493944234,0.000175208029093698,0.00355527972566496,0.00017523581789849,0.929618418216705,0.969836473464966,30.98122215271,0,30,4,200,-0.000438535091234371,-1.49330043792725,0.244520843029022,1,,,,,,,,,,,,,,,,
,3959102015.41993,5.00278472900391,999.978332519531,,,6,,,,30.738023492992,,,10,,,,,,,,,,,,,,,,,,,,,,4.99663066864014,5.00519418716431,999.978332519531,999.978332519531,,,4.04188776016235,,1,0,0,0,0,34.7018585205078,1,1,1,5.00519418716431,0,5.00012885607206,-186.000015258789,1,0.00351641167644627,0.000100280857002358,0.00352476666623873,0.00010030223916158,0.928038060665131,0.970476508140564,30.9891681671143,0.00014496166841127,30,4,200,-0.000329463568050414,-1.48582971096039,0.239303037524223,3,,,,,,,,,,,,,,,,
,3959102145.93008,5.00418329238892,999.978332519531,,,6,,,,30.738023492992,,,10,,,,,,,,,,,,,,,,,,,,,,4.99511051177978,5.00609254837036,999.978332519531,999.978332519531,,,4.04625606536865,,1,0,0,0,0,35.190616607666,6,1,1,5.00481176376343,0,5.00027269787259,-180.000015258789,1,0.00346701144241508,0.000171299680693697,0.00347615292969823,0.000171323882795493,0.924239754676819,0.972216367721558,31.0069274902344,,30,4,200,-0.000902335275895894,-1.47276675701141,0.231649130582809,1,,,,,,,,,,,,,,,,
,3959102269.26126,5.00396990776062,999.978332519531,,,6,,,,30.738023492992,,,10,,,,,,,,,,,,,,,,,,,,,,4.9910626411438,5.00673198699951,999.978332519531,999.978332519531,,,4.04845523834229,,1,0,0,0,0.000152587890625,34.7018585205078,6,1,1,5.00579309463501,0,4.99956475363837,-175.996810913086,1,0.0034242686378084,9.77033251271209E-5,0.00343458205997869,9.77261854425573E-5,0.921257734298706,0.974064469337463,31.0216197967529,0,30,4,200,-0.000844346883241087,-1.34977185726166,0.224734425544739,3,,,,,,,,,,,,,,,,
,3959102400.0213,5.00468277931213,999.978332519531,,,6,,,,30.738023492992,,,10,,,,,,,,,,,,,,,,,,,,,,4.9957013130188,5.0056471824646,999.978332519531,999.978332519531,,,4.04445457458496,,1,0,0,0,0.0153350830078125,34.7018585205078,6,1,1,5.00638294219971,0,5.00043137868245,-169.996810913086,1,0.00337594232872006,0.000166861543442647,0.00338696764825128,0.000166908653175039,0.919555425643921,0.976854085922241,31.0322551727295,6.01220672251657E-5,30,4,200,-0.000582606822717935,-1.33698701858521,0.216439947485924,1,,,,,,,,,,,,,,,,
,3959102527.74711,4.99620270729065,999.978332519531,,,6,,,,30.738023492992,,,10,,,,,,,,,,,,,,,,,,,,,,4.98974132537842,5.00519227981567,999.978332519531,999.978332519531,,,4.0457501411438,,1,0,0,0,7.62939453125E-5,35.190616607666,1,1,1,4.99163246154785,0,4.99896240234375,-165.998413085938,1,0.00335602297195195,9.5765404169602E-5,0.00336759922281993,9.58088553413632E-5,0.920035660266876,0.979142069816589,31.0328960418701,9.23910045623779,30,4,200,-0.000383455102564767,-1.33312129974365,0.212627366185188,3,,,,,,,,,,,,,,,,
,3959102657.62999,5.00072264671326,999.978332519531,,,6,,,,30.738023492992,,,10,,,,,,,,,,,,,,,,,,,,,,4.99784564971924,5.0025954246521,999.978332519531,999.978332519531,,,4.0427680015564,,1,0,0,0,0.00030517578125,34.7018585205078,1,1,1,5.00244903564453,0,5.00008742014567,-159.998413085938,1,0.00333950636329395,0.000165033397691882,0.00335012981947138,0.00016507213905015,0.921618819236755,0.983273684978485,31.029468536377,0,30,4,200,-0.000437277049059048,-1.33053338527679,0.208781465888023,1,,,,,,,,,,,,,,,,
,3959102783.58801,5.00200462341309,999.978332519531,,,6,,,,30.738023492992,,,10,,,,,,,,,,,,,,,,,,,,,,4.99648189544678,5.00437688827515,999.978332519531,999.978332519531,,,4.04633092880249,,1,0,0,0,0,34.7018585205078,1,1,1,5.00348329544067,0,5.00002560248742,-155.995208740234,1,0.00333953760069937,9.52720434073169E-5,0.00335005570602636,9.52980601560806E-5,0.923082292079926,0.986189663410187,31.0260181427002,,30,4,200,-0.000195006912690587,-1.33331429958344,0.208882853388786,3,,,,,,,,,,,,,,,,
,3959102910.54333,5.00495195388794,999.978332519531,,,6,,,,30.738023492992,,,10,,,,,,,,,,,,,,,,,,,,,,4.99573707580566,5.00578784942627,999.978332519531,999.978332519531,,,4.04503440856934,,1,0,0,0,0.00030517578125,34.7018585205078,6,1,1,5.00469350814819,0,5.00029012891981,-149.995208740234,1,0.00333917903496952,0.000164979889201836,0.00334909864949438,0.000165009614883898,0.924543738365173,0.988265931606293,31.0209255218506,3.30170792040008E-6,30,4,200,-0.000717418268322945,-1.33670294284821,0.207307979464531,1,,,,,,,,,,,,,,,,
,3959103036.33907,5.00277042388916,999.978332519531,,,6,,,,30.738023492992,,,10,,,,,,,,,,,,,,,,,,,,,,4.99444961547852,5.0063648223877,999.978332519531,999.978332519531,,,4.04940032958984,,1,0,0,0,0,34.7018585205078,1,1,1,5.005934715271,0,4.99955045259916,-145.996810913086,1,0.00334163449785758,9.53156827240712E-5,0.00335141133942465,9.53325648753884E-5,0.925313174724579,0.989755511283875,31.0184478759766,7.54312736717111E-7,30,4,200,-0.000533799408003688,-1.34038817882538,0.205824285745621,3,,,,,,,,,,,,,,,,
,3959103167.24085,5.00440526008606,999.978332519531,,,6,,,,30.738023492992,,,10,,,,,,,,,,,,,,,,,,,,,,4.99380826950073,5.00585699081421,999.978332519531,999.978332519531,,,4.04513216018677,,1,0,0,0,0.000152587890625,35.190616607666,6,1,1,5.00469923019409,0,5.0005423757765,-139.996810913086,1,0.0033500024124377,0.000165457533375999,0.00335907216387679,0.00016549730166939,0.929235816001892,0.990338623523712,31.0035171508789,0,30,4,200,-0.000738226401153952,-1.34610390663147,0.204201921820641,1,,,,,,,,,,,,,,,,
,3959103292.1966,5.00295758247375,999.978332519531,,,6,,,,30.738023492992,,,10,,,,,,,,,,,,,,,,,,,,,,4.99331760406494,5.00473928451538,999.978332519531,999.978332519531,,,4.04245805740356,,1,0,0,0,0.000152587890625,35.190616607666,1,1,1,5.00352334976196,0,5.00004694196913,-135.998413085938,1,0.00337061938590192,9.60941535691393E-5,0.00337932562420313,9.61251095691477E-5,0.932337701320648,0.991422057151794,30.991943359375,5.56704092025757,30,4,200,-0.000911967479623854,-1.35584831237793,0.205008774995804,3,,,,,,,,,,,,,,,,
,3959103424.0485,5.00027346611023,999.978332519531,,,6,,,,30.738023492992,,,10,,,,,,,,,,,,,,,,,,,,,,4.99801445007324,5.00336170196533,999.978332519531,999.978332519531,,,4.04385614395142,,1,0,0,0,0.00030517578125,34.2131004333496,1,1,1,5.00112247467041,0,5.00036153793335,-129.998413085938,1,0.00340420641919281,0.000168034323667573,0.00341124347571671,0.000168065053269582,0.938206911087036,0.992167413234711,30.9698791503906,0,30,4,200,-0.000279353436781093,-1.36919927597046,0.206420257687569,1,,,,,,,,,,,,,,,,
,3959103552.4108,5.00240564346313,999.978332519531,,,6,,,,30.738023492992,,,10,,,,,,,,,,,,,,,,,,,,,,4.99652767181396,5.00321006774902,999.978332519531,999.978332519531,,,4.04546308517456,,1,0,0,0,0.000152587890625,34.7018585205078,1,1,1,5.00287675857544,0,5.00020885467529,-125.995208740234,1,0.00344810202651179,9.82552632938229E-5,0.00345463488093667,9.82701599163247E-5,0.939936816692352,0.988526701927185,30.960880279541,2.33377681979618E-6,30,4,200,-0.000281631015241146,-1.38822174072266,0.211083114147186,3,,,,,,,,,,,,,,,,
,3959103680.07752,5.00329351425171,999.978332519531,,,6,,,,30.738023492992,,,10,,,,,,,,,,,,,,,,,,,,,,4.99707937240601,5.00461959838867,999.978332519531,999.978332519531,,,4.04386281967163,,1,0,0,0,0,34.2131004333496,1,1,1,5.00416135787964,0,5.00067403581407,-119.995208740234,1,0.00350142554915297,0.000172764623130477,0.00350667156650918,0.000172780069720292,0.944969892501831,0.985254526138306,30.9380626678467,3.44582622346934E-6,30,4,200,-0.00047280450235121,-1.40829253196716,0.215747281908989,1,,,,,,,,,,,,,,,,
,3959103806.56612,5.00400400161743,999.978332519531,,,6,,,,30.738023492992,,,10,,,,,,,,,,,,,,,,,,,,,,4.99582195281982,5.00699424743652,999.978332519531,999.978332519531,,,4.04743003845215,,1,0,0,0,0,34.2131004333496,1,1,1,5.00699424743652,0,5.00005184687101,-115.996803283691,1,0.00354377301699059,0.000100934539589942,0.0035482719298931,0.000100940934037916,0.948210477828979,0.983417570590973,30.9229431152344,0,30,4,200,-0.000643162347842008,-1.424485206604,0.219394654035568,3,,,,,,,,,,,,,,,,
,3959103936.51117,5.00341701507568,999.978332519531,,,6,,,,30.738023492992,,,10,,,,,,,,,,,,,,,,,,,,,,4.99644374847412,5.00594663619995,999.978332519531,999.978332519531,,,4.04686498641968,,1,0,0,0,0.000152587890625,34.7018585205078,6,1,1,5.00268459320068,0,5.00058512687683,-109.996803283691,1,0.00360175798033655,0.000177619066848998,0.00360510398827926,0.000177634707766775,0.955848813056946,0.983562827110291,30.8925170898438,0,30,4,200,-0.000640417041722685,-1.44532859325409,0.223773121833801,1,,,,,,,,,,,,,,,,
,3959104061.12543,5.00283002853394,999.978332519531,,,6,,,,30.738023492992,,,10,,,,,,,,,,,,,,,,,,,,,,4.99343490600586,5.01138830184937,999.978332519531,999.978332519531,,,4.04589176177978,,1,0,0,0,0.0002288818359375,33.7243423461914,6,1,1,5.00707006454468,0,5.00054018314068,-105.998405456543,1,0.00364924742419216,0.000103881061307695,0.00365177367169822,0.000103884654749275,0.960309147834778,0.983822762966156,30.8746891021729,0.0513334348797798,30,4,200,-0.000151664833538234,-1.46217751502991,0.228004574775696,3,,,,,,,,,,,,,,,,
,3959104191.47404,5.00020122528076,999.978332519531,,,6,,,,30.738023492992,,,10,,,,,,,,,,,,,,,,,,,,,,4.99797439575195,5.0038948059082,999.978332519531,999.978332519531,,,4.04338693618774,,1,0,0,0,0.0002288818359375,34.7018585205078,1,1,1,5.00125503540039,0,5.00044431686401,-99.998405456543,1,0.00370775670543002,0.000182774933795917,0.00370995790306959,0.000182796500859214,0.965805292129517,0.985203862190247,30.8543529510498,0,30,4,200,-0.000318449281621724,-1.48301291465759,0.232911616563797,1,,,,,,,,,,,,,,,,
,3959104320.03323,5.00190997123718,999.978332519531,,,6,,,,30.738023492992,,,10,,,,,,,,,,,,,,,,,,,,,,4.99683952331543,5.00310897827148,999.978332519531,999.978332519531,,,4.04129695892334,,1,0,0,0,0.000152587890625,34.7018585205078,1,1,1,5.00252962112427,0,5.00020982601025,-96.0000076293945,1,0.00375147909231085,0.000106755168320596,0.0037529166211026,0.000106759594953989,0.970018625259399,0.985304415225983,30.8365173339844,,30,4,200,-0.000468703045044094,-1.49944853782654,0.236391365528107,3,,,,,,,,,,,,,,,,
,3959104448.57669,5.00275683403015,999.978332519531,,,6,,,,30.738023492992,,,10,,,,,,,,,,,,,,,,,,,,,,4.99722051620483,5.00461483001709,999.978332519531,999.978332519531,,,4.04398679733276,,1,0,0,0,0.000152587890625,34.2131004333496,1,1,1,5.00460815429687,0,5.00031407674154,-90.0000076293945,1,0.00381527364731937,0.000188023856290956,0.00381622713287594,0.000188032313922136,0.9749955534935,0.985316872596741,30.8144187927246,1.80020265361236E-6,30,4,200,-0.000589129165746272,-1.52163600921631,0.241986781358719,1,,,,,,,,,,,,,,,,
,3959104575.14439,5.00223731994629,999.978332519531,,,6,,,,30.738023492992,,,10,,,,,,,,,,,,,,,,,,,,,,4.99239778518677,5.00635862350464,999.978332519531,999.978332519531,,,4.04878711700439,,1,0,0,0,0.000152587890625,34.7018585205078,1,1,1,5.00444555282593,0,4.99968933176111,-85.9968032836914,1,0.00384594089524202,0.000109420982807262,0.00384653419112278,0.000109422159984969,0.977781236171722,0.985620021820068,30.8018531799316,,30,4,200,-0.000433789478847757,-1.53267729282379,0.244280502200127,3,,,,,,,,,,,,,,,,
,3959104706.41317,5.00357174873352,999.978332519531,,,6,,,,30.738023492992,,,10,,,,,,,,,,,,,,,,,,,,,,4.99551725387573,5.00677347183228,999.978332519531,999.978332519531,,,4.04745101928711,,1,0,0,0,0.000152587890625,34.7018585205078,6,1,1,5.00231695175171,0,5.00069804191589,-79.9968032836914,1,0.00387966799114194,0.000191159844487438,0.00387997662982853,0.000191163302237166,0.984722018241882,0.98948734998703,30.7798767089844,0,30,4,200,-0.000687556574121118,-1.54262065887451,0.246443718671799,1,,,,,,,,,,,,,,,,
,3959104834.06884,5.00247001647949,999.978332519531,,,6,,,,30.738023492992,,,10,,,,,,,,,,,,,,,,,,,,,,4.99399185180664,5.00619029998779,999.978332519531,999.978332519531,,,4.04813003540039,,1,0,0,0,0,34.7018585205078,6,1,1,5.00498914718628,0,4.99972903286969,-75.998405456543,1,0.00389106824748141,0.000110683699435429,0.00389121439357033,0.000110685133842613,0.989472329616547,0.99214905500412,30.7645664215088,0,30,4,200,-0.000609966577030718,-1.54552519321442,0.246677994728088,3,,,,,,,,,,,,,,,,
,3959104964.12378,4.99878644943237,999.978332519531,,,6,,,,30.738023492992,,,10,,,,,,,,,,,,,,,,,,,,,,4.99562072753906,5.00501251220703,999.978332519531,999.978332519531,,,4.04512548446655,,1,0,0,0,0.0002288818359375,35.6793746948242,1,1,1,5.00023221969604,0,4.9997510433197,-69.998405456543,1,0.00390112077390569,0.000192197390567682,0.0039011492765309,0.000192198459934036,0.994449198246002,0.994772493839264,30.7451171875,5.34462404251099,30,4,200,-0.000316524645313621,-1.54799926280975,0.245980530977249,1,,,,,,,,,,,,,,,,
,3959105091.85435,5.00133562088013,999.978332519531,,,6,,,,30.738023492992,,,10,,,,,,,,,,,,,,,,,,,,,,4.99618339538574,5.00373935699463,999.978332519531,999.978332519531,,,4.04525852203369,,1,0,0,0,0.0002288818359375,34.7018585205078,1,1,1,5.00182676315308,0,5.00031333310263,-65.9952011108398,1,0.00390132755682561,0.000110972066214936,0.00390132332724407,0.000110971868856022,0.993090748786926,0.993191957473755,30.7335548400879,0,30,4,200,-0.000340705388225615,-1.54763352870941,0.244995802640915,3,,,,,,,,,,,,,,,,
,3959105222.46301,5.00227212905884,999.978332519531,,,6,,,,30.738023492992,,,10,,,,,,,,,,,,,,,,,,,,,,4.99796390533447,5.00430536270142,999.978332519531,999.978332519531,,,4.04359865188599,,1,0,0,0,0,34.7018585205078,1,1,1,5.0037055015564,0,5.00007581710815,-59.9952011108398,1,0.00390854720365893,0.000192575420897858,0.00390862127237164,0.000192573590172789,0.987439393997192,0.989956974983215,30.7093620300293,0,30,4,200,-0.00031206471612677,-1.54995024204254,0.244386404752731,1,,,,,,,,,,,,,,,,
,3959105343.31848,5.00218892097473,999.978332519531,,,6,,,,30.738023492992,,,10,,,,,,,,,,,,,,,,,,,,,,4.99340915679932,5.00465774536133,999.978332519531,999.978332519531,,,4.04726791381836,,1,0,0,0,0.000152587890625,34.7018585205078,1,1,1,5.00389003753662,0,5.00005669063992,-55.9968032836914,1,0.00389577408834384,0.000110828259198475,0.00389600932919148,0.000110828009608589,0.982564985752106,0.98663055896759,30.6955223083496,9.2907133102417,30,4,200,-0.000706983730196953,-1.54577088356018,0.241701051592827,3,,,,,,,,,,,,,,,,
,3959105471.70965,5.00552082061768,999.978332519531,,,6,,,,30.738023492992,,,10,,,,,,,,,,,,,,,,,,,,,,4.9926118850708,5.00622272491455,999.978332519531,999.978332519531,,,4.04290580749512,,1,0,0,0,0.000152587890625,34.2131004333496,6,1,1,5.00597906112671,0,4.99961847729153,-49.9968032836914,1,0.00386088450168592,0.000190269711930026,0.00386128546422728,0.000190267211170106,0.975388586521149,0.980716407299042,30.6798648834229,0,30,4,200,-0.00069922796683386,-1.53412187099457,0.235505625605583,1,,,,,,,,,,,,,,,,
,3959105599.13079,5.00362730026245,999.978332519531,,,6,,,,30.738023492992,,,10,,,,,,,,,,,,,,,,,,,,,,4.99235391616821,5.00605726242065,999.978332519531,999.978332519531,,,4.04823589324951,,1,0,0,0,7.62939453125E-5,34.2131004333496,6,1,1,5.005211353302,0,5.00017537011041,-45.9984016418457,1,0.00382652943368167,0.000108887495281307,0.00382710239750862,0.00010888561861725,0.971035480499268,0.977522253990173,30.6683921813965,0,30,4,200,-0.000620859500486404,-1.52279186248779,0.230028554797173,3,,,,,,,,,,,,,,,,
,3959105729.03248,5.00037527084351,999.978332519531,,,6,,,,30.738023492992,,,10,,,,,,,,,,,,,,,,,,,,,,4.99462223052978,5.00422525405884,999.978332519531,999.978332519531,,,4.04502296447754,,1,0,0,0,0.000152587890625,34.2131004333496,1,1,1,5.00128316879272,0,4.99954255421956,-39.9984016418457,1,0.00376821183683155,0.000185764804065546,0.00376895158749876,0.000185747563275036,0.964309215545654,0.973614692687988,30.6461143493652,0,30,4,200,-0.00108114362228662,-1.50378799438477,0.220384642481804,1,,,,,,,,,,,,,,,,
,3959105857.15168,5.00134825706482,999.978332519531,,,6,,,,30.738023492992,,,10,,,,,,,,,,,,,,,,,,,,,,4.99627733230591,5.00346040725708,999.978332519531,999.978332519531,,,4.04497814178467,,1,0,0,0,0.0002288818359375,34.7018585205078,1,1,1,5.00149011611938,0,5.00020105498178,-35.9952011108398,1,0.00374081635900589,0.000106483709117685,0.0037420681437815,0.000106479783171075,0.961266040802002,0.972463190555572,30.6339378356934,0.219161942601204,30,4,200,-0.000298044789815322,-1.49664807319641,0.214789777994156,3,,,,,,,,,,,,,,,,
,3959105987.84208,5.0023353099823,999.978332519531,,,6,,,,30.738023492992,,,10,,,,,,,,,,,,,,,,,,,,,,4.99710559844971,5.00376224517822,999.978332519531,999.978332519531,,,4.04327917098999,,1,0,0,0,0,34.7018585205078,1,1,1,5.00425958633423,0,5.00000445048014,-29.9952011108398,1,0.00370019475550987,0.000182481032645745,0.00370248993455012,0.000182481107985709,0.9549201130867,0.971811592578888,30.6035900115967,1.32976265376783E-5,30,4,200,-0.000397383439121768,-1.48568511009216,0.207532852888107,1,,,,,,,,,,,,,,,,
,3959106112.13077,5.0019326210022,999.978332519531,,,6,,,,30.738023492992,,,10,,,,,,,,,,,,,,,,,,,,,,4.99479103088379,5.00561809539795,999.978332519531,999.978332519531,,,4.04364252090454,,1,0,0,0,7.62939453125E-5,34.2131004333496,1,1,1,5.0036187171936,0,4.9998429969505,-25.9968013763428,1,0.00366402313101985,0.000104342640940085,0.00366680929666692,0.000104342939065578,0.951427817344665,0.970894038677216,30.5892944335937,1.45870362757705E-5,30,4,200,-0.000302887812722474,-1.47517144680023,0.201653689146042,3,,,,,,,,,,,,,,,,
,3959106243.11036,5.00365805625916,999.978332519531,,,6,,,,30.738023492992,,,10,,,,,,,,,,,,,,,,,,,,,,4.99567079544067,5.00547409057617,999.978332519531,999.978332519531,,,4.04445362091064,,1,0,0,0,0.000152587890625,34.7018585205078,6,1,1,5.00529861450195,0,5.00033606423272,-19.9968013763428,1,0.00360287417435992,0.000177750361006965,0.00360614891814241,0.000177742414290772,0.947033405303955,0.969957411289215,30.5712718963623,0,30,4,200,-0.000598925456870347,-1.45649933815002,0.192417114973068,1,,,,,,,,,,,,,,,,
,3959106372.12184,5.00327825546265,999.978332519531,,,6,,,,30.738023492992,,,10,,,,,,,,,,,,,,,,,,,,,,4.99438619613647,5.00664234161377,999.978332519531,999.978332519531,,,4.04755401611328,,1,0,0,0,0.000152587890625,34.7018585205078,6,1,1,5.00572919845581,0,5.00004301752363,-15.9984006881714,1,0.00355150160082252,0.000101172329461279,0.00355530282821923,0.000101173484888494,0.944954633712769,0.96970933675766,30.5622463226318,1.6554920875933E-5,30,4,200,-0.000486069184262305,-1.44073963165283,0.184826552867889,3,,,,,,,,,,,,,,,,
,3959106502.71226,5.001296043396,999.978332519531,,,6,,,,30.738023492992,,,10,,,,,,,,,,,,,,,,,,,,,,4.99433708190918,5.00368738174438,999.978332519531,999.978332519531,,,4.04504346847534,,1,0,0,0,0.0002288818359375,34.2131004333496,6,1,1,5.00288343429565,0,5.00030612945557,-9.99840068817139,1,0.00348371009799946,0.000171917248453499,0.00348784826734736,0.000171907898911134,0.942225158214569,0.970673263072968,30.5478191375732,,30,4,200,-0.000687445746734738,-1.41990029811859,0.17504708468914,1,,,,,,,,,,,,,,,,
,3959106629.19679,5.00080466270447,999.978332519531,,,6,,,,30.738023492992,,,10,,,,,,,,,,,,,,,,,,,,,,4.99605560302734,5.00448274612427,999.978332519531,999.978332519531,,,4.04595041275024,,1,0,0,0,0.00030517578125,34.2131004333496,1,1,1,5.00076293945313,0,5.00017651489803,-6.00000047683716,1,0.00345494012751928,9.84421768872579E-5,0.00345923870230278,9.84333945610535E-5,0.941288530826569,0.971938788890839,30.5403099060059,,30,4,200,-0.000209443824132904,-1.41142964363098,0.170473977923393,3,,,,,,,,,,,,,,,,
,3959106761.37376,5.00160312652588,999.978332519531,,,6,,,,30.738023492992,,,10,,,,,,,,,,,,,,,,,,,,,,4.99770307540894,5.00346326828003,999.978332519531,999.978332519531,,,4.04399108886719,,1,0,0,0,0.000152587890625,34.2131004333496,1,1,1,5.00355243682861,0,5.00011506080627,0,1,0.00342101845026736,0.000168851169551977,0.00342642215719117,0.000168858243644857,0.939462900161743,0.975536704063416,30.5266342163086,0,30,4,200,-0.000423939840402454,-1.40268039703369,0.165883287787437,1,,,,,,,,,,,,,,,,
,3959106886.01149,5.00246334075928,999.978332519531,,,6,,,,30.738023492992,,,10,,,,,,,,,,,,,,,,,,,,,,4.99490308761597,5.00542068481445,999.978332519531,999.978332519531,,,4.04632520675659,,1,0,0,0,0,35.190616607666,1,1,1,5.00471591949463,0,4.99979404302744,3.99840021133423,1,0.00339621473237608,9.67826171271521E-5,0.00340180513941146,9.6785693562613E-5,0.938922762870789,0.977385520935059,30.5213623046875,0,30,4,200,-0.000456974259577692,-1.39649987220764,0.162219166755676,3,,,,,,,,,,,,,,,,
,3959107017.70483,5.0045530796051,999.978332519531,,,6,,,,30.738023492992,,,10,,,,,,,,,,,,,,,,,,,,,,4.99317169189453,5.00714349746704,999.978332519531,999.978332519531,,,4.04567575454712,,1,0,0,0,0.000152587890625,34.2131004333496,6,1,1,5.00702857971191,0,5.00029063224793,9.99840068817139,1,0.00336692744873333,0.000166176198745882,0.00337252476259217,0.000166185099847948,0.939981520175934,0.980159342288971,30.5223846435547,5.35580539703369,30,4,200,-0.00037661794340238,-1.38989806175232,0.156913667917252,1,,,,,,,,,,,,,,,,
,3959107143.82504,5.00386023521423,999.978332519531,,,6,,,,30.738023492992,,,10,,,,,,,,,,,,,,,,,,,,,,4.99118900299072,5.00716304779053,999.978332519531,999.978332519531,,,4.04635286331177,,1,0,0,0,0.000152587890625,34.7018585205078,6,1,1,5.00586652755737,0,4.99974374417905,13.9968004226685,1,0.00334532592499466,9.53113085183345E-5,0.00335043711395624,9.53140345137143E-5,0.942657589912415,0.982756495475769,30.5301113128662,0,30,4,200,-0.000590674171689898,-1.38496232032776,0.152981117367744,3,,,,,,,,,,,,,,,,
,3959107274.83225,5.00338530540466,999.978332519531,,,6,,,,30.738023492992,,,10,,,,,,,,,,,,,,,,,,,,,,4.99481916427612,5.0075798034668,999.978332519531,999.978332519531,,,4.04519510269165,,1,0,0,0,0.0142669677734375,34.7018585205078,6,1,1,5.00528144836426,0,5.00030501683553,19.9968013763428,1,0.00332882728660239,0.000164230185426328,0.00333333398504758,0.000164237340139501,0.947021305561066,0.986145317554474,30.5437183380127,0.607021868228912,30,4,200,-0.000725291145499796,-1.38216972351074,0.149037107825279,1,,,,,,,,,,,,,,,,
,3959107402.64162,5.0009434223175,999.978332519531,,,6,,,,30.738023492992,,,10,,,,,,,,,,,,,,,,,,,,,,4.99427604675293,5.00572872161865,999.978332519531,999.978332519531,,,4.04633188247681,,1,0,0,0,0.000152587890625,34.7018585205078,1,1,1,5.00139474868774,0,5.00007873111301,24.0000019073486,1,0.0033273203873265,9.47591201380659E-5,0.00333097982031432,9.4752233042557E-5,0.950360238552094,0.988893330097198,30.5537395477295,6.77259874343872,30,4,200,-0.000629689428023994,-1.38352406024933,0.147601917386055,3,,,,,,,,,,,,,,,,
,3959107535.46269,5.00118541717529,999.978332519531,,,6,,,,30.738023492992,,,10,,,,,,,,,,,,,,,,,,,,,,4.99720525741577,5.00283861160278,999.978332519531,999.978332519531,,,4.04360008239746,,1,0,0,0,0.0002288818359375,34.2131004333496,1,1,1,5.00235509872437,0,4.99977599249946,29.9952011108398,1,0.00333710458368744,0.000164584644610039,0.0033407150788523,0.000164589548265207,0.953600943088531,0.992782115936279,30.564302444458,,30,4,200,-0.000457389774965122,-1.38976502418518,0.147335231304169,1,,,,,,,,,,,,,,,,
,3959107659.61735,5.00227880477905,999.978332519531,,,6,,,,30.738023492992,,,10,,,,,,,,,,,,,,,,,,,,,,4.99665355682373,5.00486183166504,999.978332519531,999.978332519531,,,4.04506254196167,,1,0,0,0,0,32.7468223571777,1,1,1,5.00415897369385,0,5.00014527027424,33.9984016418457,1,0.00335290939276482,9.54578772982308E-5,0.00335594180608518,9.54586981649406E-5,0.957151710987091,0.993154942989349,30.577579498291,,30,4,200,-0.000365198793588206,-1.39718818664551,0.14960840344429,3,,,,,,,,,,,,,,,,
,3959107787.26066,5.00196504592895,999.978332519531,,,6,,,,30.738023492992,,,10,,,,,,,,,,,,,,,,,,,,,,4.99248695373535,5.00568914413452,999.978332519531,999.978332519531,,,4.04532194137573,,1,0,0,0,0.000152587890625,34.7018585205078,6,1,1,5.00322103500366,0,4.99989199638367,39.9984016418457,1,0.0033833161042155,0.000166807028618004,0.00338568226526519,0.00016680717959098,0.961603879928589,0.991116046905518,30.596736907959,0,30,4,200,-0.000548755866475403,-1.4103307723999,0.152076721191406,1,,,,,,,,,,,,,,,,
,3959107915.48482,5.00358462333679,999.978332519531,,,6,,,,30.738023492992,,,10,,,,,,,,,,,,,,,,,,,,,,4.9931902885437,5.00577068328857,999.978332519531,999.978332519531,,,4.04998683929443,,1,0,0,0,0.000152587890625,34.7018585205078,1,1,1,5.00576543807983,0,5.00004839014124,43.9968032836914,1,0.00341433944024903,9.71719138764014E-5,0.00341612074010127,9.71729776841688E-5,0.966521620750427,0.98999160528183,30.6173267364502,0.208045184612274,30,4,200,-0.000597312347963452,-1.42303907871246,0.154954269528389,3,,,,,,,,,,,,,,,,
,3959108046.98261,5.00441765785217,999.978332519531,,,6,,,,30.738023492992,,,10,,,,,,,,,,,,,,,,,,,,,,4.9953293800354,5.00645875930786,999.978332519531,999.978332519531,,,4.04786443710327,,1,0,0,0,7.62939453125E-5,34.2131004333496,6,1,1,5.00296211242676,0,5.00095834732056,49.9968032836914,1,0.0034651184424442,0.000170773600399924,0.00346607573136856,0.000170772804976757,0.973615109920502,0.988397061824799,30.6485328674316,0,30,4,200,-0.00068005220964551,-1.44250726699829,0.15958009660244,1,,,,,,,,,,,,,,,,
,3959108175.32719,4.99995946884155,999.978332519531,,,6,,,,30.738023492992,,,10,,,,,,,,,,,,,,,,,,,,,,4.98412990570068,5.00535297393799,999.978332519531,999.978332519531,,,4.04901885986328,,1,0,0,0,0.000152587890625,33.7243423461914,1,1,1,4.99881076812744,0,4.99826062167132,53.9952011108398,1,0.00350702075753493,9.97780448549162E-5,0.00350753845046928,9.97757352940177E-5,0.97791177034378,0.98789656162262,30.6682643890381,0,30,4,200,-0.000762325769755989,-1.45906627178192,0.16369540989399,3,,,,,,,,,,,,,,,,
,3959108306.6498,4.99963307380676,999.978332519531,,,6,,,,30.738023492992,,,10,,,,,,,,,,,,,,,,,,,,,,4.99776315689087,5.00286531448364,999.978332519531,999.978332519531,,,4.04341077804565,,1,0,0,0,0.0002288818359375,34.2131004333496,1,1,1,5.0013108253479,0,5.00004892349243,59.9952011108398,1,0.00356141730323335,0.000175487463929509,0.00356170394645317,0.000175485696335943,0.981826961040497,0.987785577774048,30.68723487854,0,30,4,200,-0.00019664439605549,-1.47900068759918,0.169461980462074,1,,,,,,,,,,,,,,,,
,3959108432.9827,5.00249242782593,999.978332519531,,,6,,,,30.738023492992,,,10,,,,,,,,,,,,,,,,,,,,,,4.99639320373535,5.00396680831909,999.978332519531,999.978332519531,,,4.04673147201538,,1,0,0,0,0.000152587890625,34.7018585205078,1,1,1,5.00376558303833,0,5.00005301407405,63.9984016418457,1,0.00360442954042223,0.000102538871943903,0.00360457045274524,0.000102538247246902,0.983210384845734,0.986160218715668,30.7021808624268,0,30,4,200,-0.000329796923324466,-1.49505746364594,0.174922257661819,3,,,,,,,,,,,,,,,,
,3959108562.72585,5.00226712226868,999.978332519531,,,6,,,,30.738023492992,,,10,,,,,,,,,,,,,,,,,,,,,,4.99723196029663,5.00493669509888,999.978332519531,999.978332519531,,,4.04423427581787,,1,0,0,0,0.000152587890625,33.7243423461914,1,1,1,5.00247192382812,0,5.00068593025207,69.998405456543,1,0.00367572485609103,0.000181113507849444,0.00367573927548331,0.000181113181560363,0.983903288841248,0.984262824058533,30.7252712249756,0,30,4,200,-0.000493488973006606,-1.52107262611389,0.182571440935135,1,,,,,,,,,,,,,,,,
,3959108687.004,5.0037739276886,999.978332519531,,,6,,,,30.738023492992,,,10,,,,,,,,,,,,,,,,,,,,,,4.99252128601074,5.00733280181885,999.978332519531,999.978332519531,,,4.04799699783325,,1,0,0,0,0,34.2131004333496,6,1,1,5.00594663619995,0,5.00025738202609,73.9968032836914,1,0.00371941635607265,0.000105809131949857,0.00371941889749259,0.000105809192133797,0.983711659908295,0.983718693256378,30.7398242950439,,30,4,200,-0.000370759313227609,-1.53696298599243,0.186969354748726,3,,,,,,,,,,,,,,,,
,3959108817.73674,5.00484323501587,999.978332519531,,,6,,,,30.738023492992,,,10,,,,,,,,,,,,,,,,,,,,,,4.99657297134399,5.00581502914429,999.978332519531,999.978332519531,,,4.04670238494873,,1,0,0,0,0.000152587890625,34.7018585205078,6,1,1,5.00569868087769,0,5.00095872879028,79.9968032836914,1,0.00378283863731274,0.000186392548738042,0.00378298830955942,0.000186395090102786,0.983475685119629,0.985127091407776,30.7651824951172,0,30,4,200,-0.000748072809074074,-1.55858063697815,0.193194001913071,1,,,,,,,,,,,,,,,,
,3959108945.35514,5.00399470329285,999.978332519531,,,6,,,,30.738023492992,,,10,,,,,,,,,,,,,,,,,,,,,,4.99247932434082,5.00739860534668,999.978332519531,999.978332519531,,,4.05122041702271,,1,0,0,0,0.000152587890625,34.2131004333496,6,1,1,5.00602054595947,0,4.99988603591919,84.0000076293945,1,0.00381850438161144,0.000108628743074432,0.00381871404306672,0.00010862829162624,0.983278214931488,0.987290859222412,30.7790622711182,0,30,4,200,-0.000444423232693225,-1.57095515727997,0.19586917757988,3,,,,,,,,,,,,,,,,
,3959109077.31247,5.00510907173157,999.978332519531,,,6,,,,30.738023492992,,,10,,,,,,,,,,,,,,,,,,,,,,4.99718570709229,5.00599670410156,999.978332519531,999.978332519531,,,4.04006576538086,,1,0,0,0,0.000152587890625,34.2131004333496,6,1,1,5.00422143936157,0,5.00066725413005,90.0000076293945,1,0.00382191964693744,0.000188319399063698,0.00382214204413069,0.000188318420249948,0.983098208904266,0.987393379211426,30.7805042266846,0,30,4,200,-0.000578322273213416,-1.57370519638062,0.19447349011898,1,,,,,,,,,,,,,,,,
,3959109101.07749,5.00128722190857,999.978332519531,,,6,,,,30.738023492992,,,10,,,,,,,,,,,,,,,,,,,,,,4.99011659622192,5.00577974319458,999.978332519531,999.978332519531,,,4.04858350753784,,1,0,0,0,0.000152587890625,34.7018585205078,1,1,1,5.0028223991394,0,4.99963514893143,90.0000076293945,1,0.0038218910585946,0.000108725265362179,0.00382211835273325,0.000108724850264638,0.98319548368454,0.987516224384308,30.7804718017578,0,30,4,200,-0.000524922565091401,-1.57389831542969,0.194365933537483,3,,,,,,,,,,,,,,,,