File: PPMS_Data_and_Plotting/Data/RuCl3/Data/Magnetisation/Rotator/TB001_RuCl3_H-parra-ab_61p2_mg_14-06-25_ZFCW_1p8K.dat
[Header]
; MPMS3 Data File (default extension .dat)
; Copyright (c) 2007, Quantum Design, Inc. All rights reserved.
TITLE,
FILEOPENTIME,3959075230.2838,06/14/2025,3:06 pm
BYAPP,MPMS3 w/ AC,1.0,1.1
INFO,MPMS3 Measurement Release 1.2.2 Build 0, MultiVu Release 2.3.5.2,APPNAME
INFO,Linear Motor Servo Controller,MOTOR_MODULE_NAME
INFO,3101-100 N4,MOTOR_HW_VERSION
INFO,MMC1299,MOTOR_SERIAL_NUMBER
INFO,01.04.28,MOTOR_SOFTWARE_VERSION
INFO,Quantum Design Squid Module,SQUID_MODULE_NAME
INFO,3101-501 B0,SQUID_HW_VERSION
INFO,SQM364,SQUID_SERIAL_NUMBER
INFO,01.03.04,SQUID_SOFTWARE_VERSION
INFO,Quantum Design VSM Oven,OVEN_MODULE_NAME
INFO,3101-201 A3,OVEN_HW_VERSION
INFO,OVB387,OVEN_SERIAL_NUMBER
INFO,01.07.07,OVEN_SOFTWARE_VERSION
INFO,SQUID AC,AC_MODULE_NAME
INFO,3101-401 G0,AC_HW_VERSION
INFO,SAC242,AC_SERIAL_NUMBER
INFO,SQUID AC 00.95.11,AC_SOFTWARE_VERSION
INFO,TCI374,COIL_SERIAL_NUMBER
INFO,0,MOMENT_UNITS
INFO,RuCl3,SAMPLE_MATERIAL
INFO,single crystal,SAMPLE_COMMENT
INFO,61.2,SAMPLE_MASS
INFO,,SAMPLE_VOLUME
INFO,,SAMPLE_MOLECULAR_WEIGHT
INFO,,SAMPLE_SIZE
INFO,,SAMPLE_SHAPE
INFO,Rotator,SAMPLE_HOLDER
INFO,Standard,SAMPLE_HOLDER_DETAIL
INFO,67.44,SAMPLE_OFFSET
DATATYPE,COMMENT,1
DATATYPE,TIME,2
STARTUPAXIS,X,2
STARTUPAXIS,Y1,5
FIELDGROUP, VSM,2,3,4,5,6,8,9,10,11,14,15
FIELDGROUP, DC, 2,3,4,14,56,57,58,59,60,61,62,63,64,65,66,67,68,69
FIELDGROUP, AC, 2,3,4,11,16,17,18,19,20,21,22,23,24,25,26,27,28,29,30
STARTUPGROUP, All
[Data]
Comment,Time Stamp (sec),Temperature (K),Magnetic Field (Oe),Moment (emu),M. Std. Err. (emu),Transport Action,Averaging Time (sec),Frequency (Hz),Peak Amplitude (mm),Center Position (mm),Lockin Signal' (V),Lockin Signal (V),Range,M. Quad. Signal (emu),AC Moment (emu),AC M. Std Err. (emu),AC Phase (deg),AC Phase Std. Err. (deg),AC Susceptibility (emu/Oe),AC Suscept. Std Err. (emu/Oe),AC X' (emu/Oe),AC X' Std Err. (emu/Oe),AC X'' (emu/Oe),AC X'' Std Err. (emu/Oe),AC Drive (Oe),AC Frequency (Hz),AC Averaging Time (sec),AC Cycles,AC Range,AC Measure Type,AC Signal' (V),AC Signal'' (V),AC Trim Coil Ratio,AC Trim Coil Phase,Min. Temperature (K),Max. Temperature (K),Min. Field (Oe),Max. Field (Oe),Mass (grams),Motor Lag (deg),Pressure (Torr),Measure Count,Measurement Number,SQUID Status (code),Motor Status (code),Measure Status (code),Motor Current (amps),Motor Temp. (C),Temp. Status (code),Field Status (code),Chamber Status (code),Chamber Temp (K),Redirection State,Average Temp (K),Rotation Angle (deg),Rotator state,DC Moment Fixed Ctr (emu),DC Moment Err Fixed Ctr (emu),DC Moment Free Ctr (emu),DC Moment Err Free Ctr (emu),DC Fixed Fit,DC Free Fit,DC Calculated Center (mm),DC Calculated Center Err (mm),DC Scan Length (mm),DC Scan Time (s),DC Number of Points,DC Squid Drift,DC Min V (V),DC Max V (V),DC Scans per Measure,He3 temp,Map 02,Map 03,Map 04,Map 05,Map 06,Map 07,Map 08,Map 09,Map 10,Map 11,Map 12,Map 13,Map 14,Map 15,Map 16
,3959078044.54393,1.80498760938644,999.929748535156,,,6,,,,30.738023492992,,,10,,,,,,,,,,,,,,,,,,,,,,1.76740944385529,1.8432993888855,999.929748535156,999.929748535156,,,2.73277401924133,,1,0,0,0,0.0005340576171875,34.2131004333496,6,1,1,1.80033433437347,0,1.800179819266,-299.995208740234,1,0.00340348899882392,0.000167697516996658,0.00340341629992285,0.000167688839374123,0.984708249568939,0.986844122409821,30.7086143493652,0,30,4,200,-0.00130796653684229,-4.75223302841186,4.73097133636475,1,,,,,,,,,,,,,,,,
,3959078274.39404,1.80755060911179,999.929748535156,,,6,,,,30.738023492992,,,10,,,,,,,,,,,,,,,,,,,,,,1.76228761672974,1.82879030704498,999.929748535156,999.929748535156,,,2.73528528213501,,1,0,0,0,0.000457763671875,35.6793746948242,6,1,1,1.80064260959625,0,1.80215528181621,-295.996826171875,1,0.00340241561784566,9.67884011034419E-5,0.0034023809597958,9.67848989642615E-5,0.985576510429382,0.987507998943329,30.7107963562012,0,30,4,200,-0.000651514157652855,-1.39046800136566,0.185459017753601,3,,,,,,,,,,,,,,,,
,3959078505.04094,1.80186665058136,999.929748535156,,,6,,,,30.738023492992,,,10,,,,,,,,,,,,,,,,,,,,,,1.7882673740387,1.81000077724457,999.929748535156,999.929748535156,,,2.72231793403626,,1,0,0,0,0.000457763671875,35.6793746948242,6,1,1,1.80184817314148,0,1.80080534219742,-290.995208740234,1,0.0034358036084798,0.000169285310782619,0.00343581503334669,0.000169281755348854,0.986498355865479,0.988439500331879,30.711669921875,,30,4,200,-0.000119492855446879,-1.44242238998413,0.255749702453613,1,,,,,,,,,,,,,,,,
,3959078730.42399,1.8007447719574,999.929748535156,,,6,,,,30.738023492992,,,10,,,,,,,,,,,,,,,,,,,,,,1.79381251335144,1.80335581302643,999.929748535156,999.929748535156,,,2.71875739097595,,1,0,0,0,0.00030517578125,35.190616607666,5,1,1,1.79620277881622,0,1.8002313375473,-286.996826171875,1,0.00346437500130789,9.85513134964599E-5,0.00346448180808684,9.85507660761464E-5,0.985371470451355,0.988115608692169,30.7058238983154,0,30,4,200,-0.000553789432160556,-1.38169777393341,0.222634062170982,3,,,,,,,,,,,,,,,,
,3959078959.53333,1.8019095659256,999.929748535156,,,6,,,,30.738023492992,,,10,,,,,,,,,,,,,,,,,,,,,,1.7800612449646,1.81555461883545,999.929748535156,999.929748535156,,,2.72670316696167,,1,0,0,0,0.0002288818359375,35.190616607666,6,1,1,1.7949481010437,0,1.80132122039795,-281.995208740234,1,0.00350037992499951,0.000172472014314011,0.00350047195475902,0.000172471634410677,0.984517097473145,0.986481726169586,30.7095642089844,0.186347529292107,30,4,200,-0.000468132522655651,-1.41996252536774,0.198597177863121,1,,,,,,,,,,,,,,,,
,3959079186.79931,1.80073487758636,999.929748535156,,,6,,,,30.738023492992,,,10,,,,,,,,,,,,,,,,,,,,,,1.77153992652893,1.82770264148712,999.929748535156,999.929748535156,,,2.72095608711243,,1,0,0,0,0.000152587890625,35.190616607666,6,1,1,1.79112434387207,0,1.8014498507535,-277.996826171875,1,0.00353896263388665,0.000100674701257292,0.00353900985920071,0.00010067465643981,0.984308302402496,0.985212981700897,30.7182292938232,INF,30,4,200,-0.000687282416038215,-1.45846581459045,0.180399611592293,3,,,,,,,,,,,,,,,,
,3959079417.71902,1.80558544397354,999.929748535156,,,6,,,,30.738023492992,,,10,,,,,,,,,,,,,,,,,,,,,,1.76319515705109,1.83612668514252,999.929748535156,999.929748535156,,,2.72892594337463,,1,0,0,0,0.000152587890625,35.190616607666,6,1,1,1.79170680046082,0,1.80325755808089,-272.995208740234,1,0.00360083259132407,0.000177424178908673,0.00360083507636443,0.00017742429483958,0.983595192432404,0.983597457408905,30.7390441894531,0,30,4,200,-0.00108222058042884,-1.49785661697388,0.168082416057587,1,,,,,,,,,,,,,,,,
,3959079643.78151,1.80529147386551,999.929748535156,,,6,,,,30.738023492992,,,10,,,,,,,,,,,,,,,,,,,,,,1.75486028194427,1.82793533802032,999.929748535156,999.929748535156,,,2.72931742668152,,1,0,0,0,0.00030517578125,35.190616607666,6,1,1,1.80043125152588,0,1.79816121525235,-268.996826171875,1,0.00365264868134808,0.000103910441337864,0.00365275239719604,0.000103912169475644,0.983298718929291,0.984018385410309,30.7562694549561,,30,4,200,-0.000737894442863762,-1.5329202413559,0.269061058759689,3,,,,,,,,,,,,,,,,
,3959079872.45844,1.80954855680466,999.929748535156,,,6,,,,30.738023492992,,,10,,,,,,,,,,,,,,,,,,,,,,1.78084588050842,1.81867098808289,999.929748535156,999.929748535156,,,2.71711349487305,,1,0,0,0,7.62939453125E-5,35.190616607666,6,1,1,1.80104029178619,0,1.80017795827654,-263.995208740234,1,0.00370888568700661,0.000182752969649972,0.00370934376236129,0.000182765381057707,0.982090532779694,0.985522329807282,30.7777633666992,5.36633539199829,30,4,200,-0.000922882987651974,-1.45836281776428,0.2565558552742,1,,,,,,,,,,,,,,,,
,3959080098.42407,1.80058574676514,999.929748535156,,,6,,,,30.738023492992,,,10,,,,,,,,,,,,,,,,,,,,,,1.7868812084198,1.81411421298981,999.929748535156,999.929748535156,,,2.7033679485321,,1,0,0,0,0.000152587890625,35.190616607666,6,1,1,1.79675185680389,0,1.80067977640364,-259.996826171875,1,0.00374855003454327,0.000106641893743568,0.00374906037037282,0.000106646053531308,0.981548547744751,0.987906634807587,30.7906436920166,0,30,4,200,-0.000591478252317756,-1.48316812515259,0.249671116471291,3,,,,,,,,,,,,,,,,
,3959080328.31322,1.80109721422195,999.929748535156,,,6,,,,30.738023492992,,,10,,,,,,,,,,,,,,,,,,,,,,1.79554581642151,1.80355978012085,999.929748535156,999.929748535156,,,2.69485640525818,,1,0,0,0,0.00030517578125,35.190616607666,6,1,1,1.80005478858948,0,1.80036660035451,-254.995208740234,1,0.00378870577314887,0.000186690047687505,0.00378924397613277,0.000186692598373657,0.980938971042633,0.98967432975769,30.798526763916,0,30,4,200,-0.000341270351782441,-1.50515687465668,0.244550734758377,1,,,,,,,,,,,,,,,,
,3959080553.57242,1.80287331342697,999.929748535156,,,6,,,,30.738023492992,,,10,,,,,,,,,,,,,,,,,,,,,,1.7846816778183,1.81275928020477,999.929748535156,999.929748535156,,,2.69747710227966,,1,0,0,0,0.0142669677734375,35.190616607666,6,1,1,1.79873085021973,0,1.80083991421594,-250.996810913086,1,0.0038185619790523,0.000108638059119768,0.00381922101313007,0.000108639305937089,0.979494273662567,0.990081429481506,30.8058109283447,,30,4,200,-0.000312212388962507,-1.52578103542328,0.238636672496796,3,,,,,,,,,,,,,,,,
,3959080783.60457,1.79320478439331,999.929748535156,,,6,,,,30.738023492992,,,10,,,,,,,,,,,,,,,,,,,,,,1.76923370361328,1.8236608505249,999.929748535156,999.929748535156,,,2.6950900554657,,1,0,0,0,0.000152587890625,35.190616607666,6,1,1,1.78364527225494,0,1.80043885442946,-245.995208740234,1,0.00384480184400083,0.000189467153140482,0.00384565099292438,0.000189470570552937,0.977640032768249,0.990279018878937,30.8141307830811,0,30,4,200,-0.000959790777415037,-1.54499852657318,0.22925628721714,1,,,,,,,,,,,,,,,,
,3959081011.75932,1.81028920412064,999.929748535156,,,6,,,,30.738023492992,,,10,,,,,,,,,,,,,,,,,,,,,,1.76123809814453,1.83436000347137,999.929748535156,999.929748535156,,,2.70502734184265,,1,0,0,0,7.62939453125E-5,35.190616607666,6,1,1,1.80653047561646,0,1.80141602622138,-241.996810913086,1,0.0038602294417618,0.000109834844142489,0.00386142091452451,0.000109840020071624,0.974968671798706,0.989812076091766,30.8244819641113,0,30,4,200,-0.000443321303464472,-1.55806040763855,0.22277607023716,3,,,,,,,,,,,,,,,,
,3959081236.07535,1.80284279584885,999.929748535156,,,6,,,,30.738023492992,,,10,,,,,,,,,,,,,,,,,,,,,,1.77176940441132,1.82373893260956,999.929748535156,999.929748535156,,,2.6985228061676,,1,0,0,0,0.000152587890625,35.6793746948242,6,1,1,1.79349422454834,0,1.80346557829115,-236.995208740234,1,0.00386374151102848,0.000190439667666824,0.00386559360719315,0.000190457215112613,0.969814598560333,0.988279819488525,30.8432178497314,0,30,4,200,-0.00057152530644089,-1.56584405899048,0.213770568370819,1,,,,,,,,,,,,,,,,
,3959081462.35654,1.80824172496796,999.929748535156,,,6,,,,30.738023492992,,,10,,,,,,,,,,,,,,,,,,,,,,1.75850808620453,1.85114312171936,999.929748535156,999.929748535156,,,2.69101905822754,,1,0,0,0,0.0142669677734375,35.190616607666,6,1,1,1.79678857326508,0,1.80096469606672,-232.996810913086,1,0.00385625970254617,0.000109753404380085,0.00385850471388256,0.000109762672723054,0.965342223644257,0.985621452331543,30.8575744628906,0,30,4,200,-0.000741085154004395,-1.57010686397552,0.204464361071587,3,,,,,,,,,,,,,,,,
,3959081690.3519,1.79763174057007,999.929748535156,,,6,,,,30.738023492992,,,10,,,,,,,,,,,,,,,,,,,,,,1.78857600688934,1.8066109418869,999.929748535156,999.929748535156,,,2.68477296829224,,1,0,0,0,0.0002288818359375,35.6793746948242,6,1,1,1.79433357715607,0,1.7988737821579,-227.995208740234,1,0.00384142743461194,0.000189389702025309,0.0038440878729706,0.000189410327358812,0.962092578411102,0.983534455299377,30.8680076599121,2.54960395977832E-5,30,4,200,-0.000400509918108583,-1.56906759738922,0.196512922644615,1,,,,,,,,,,,,,,,,
,3959081919.72209,1.80032062530518,999.929748535156,,,6,,,,30.738023492992,,,10,,,,,,,,,,,,,,,,,,,,,,1.79443359375,1.80335915088654,999.929748535156,999.929748535156,,,2.68209099769592,,1,0,0,0,0.00030517578125,35.190616607666,6,1,1,1.7989227771759,0,1.80048461045538,-223.996810913086,1,0.00382481327216148,0.000108884482336329,0.0038275751399411,0.000108891367043236,0.959033370018005,0.980963170528412,30.8761386871338,0,30,4,200,-0.000400450895540416,-1.56864190101624,0.18823179602623,3,,,,,,,,,,,,,,,,
,3959082149.33799,1.79938536882401,999.929748535156,,,6,,,,30.738023492992,,,10,,,,,,,,,,,,,,,,,,,,,,1.78434145450592,1.8083381652832,999.929748535156,999.929748535156,,,2.68665146827698,,1,0,0,0,0.000152587890625,35.190616607666,6,1,1,1.7906448841095,0,1.80098662111494,-218.995208740234,1,0.00380592365365248,0.000187675526598911,0.0038086843926842,0.000187684706719659,0.957313716411591,0.978291392326355,30.8780250549316,,30,4,200,-0.000271947996225208,-1.56888329982758,0.178777247667313,1,,,,,,,,,,,,,,,,
,3959082375.47446,1.80364906787872,999.929748535156,,,6,,,,30.738023492992,,,10,,,,,,,,,,,,,,,,,,,,,,1.76952052116394,1.82042646408081,999.929748535156,999.929748535156,,,2.68794679641724,,1,0,0,0,7.62939453125E-5,35.190616607666,6,1,1,1.79592227935791,0,1.79898569760499,-214.996810913086,1,0.00377947820232099,0.000107619324139936,0.00378267300729286,0.000107626227517181,0.953623712062836,0.975683450698852,30.8885478973389,0,30,4,200,-0.000596948084421456,-1.56633973121643,0.16864849627018,3,,,,,,,,,,,,,,,,
,3959082603.27498,1.79612737894058,999.929748535156,,,6,,,,30.738023492992,,,10,,,,,,,,,,,,,,,,,,,,,,1.75897777080536,1.8285471200943,999.929748535156,999.929748535156,,,2.6982216835022,,1,0,0,0,0.0142669677734375,35.6793746948242,6,1,1,1.78564155101776,0,1.79855044682821,-209.995208740234,1,0.00373676088860935,0.000184348317612047,0.00374081873929162,0.000184366760887889,0.947794735431671,0.972464025020599,30.907247543335,0,30,4,200,-0.000228486489504576,-1.55740106105804,0.156690001487732,1,,,,,,,,,,,,,,,,
,3959082828.07422,1.8022478222847,999.929748535156,,,6,,,,30.738023492992,,,10,,,,,,,,,,,,,,,,,,,,,,1.76236510276794,1.83231580257416,999.929748535156,999.929748535156,,,2.69338130950928,,1,0,0,0,7.62939453125E-5,35.6793746948242,6,1,1,1.79305458068848,0,1.79951663370486,-205.996810913086,1,0.003691453192591,0.000105179752944034,0.00369672090525044,0.000105197378458534,0.941515803337097,0.969850361347198,30.9292373657227,0,30,4,200,-0.000592634722124785,-1.54844343662262,0.144380658864975,3,,,,,,,,,,,,,,,,
,3959083057.0611,1.80289649963379,999.929748535156,,,6,,,,30.738023492992,,,10,,,,,,,,,,,,,,,,,,,,,,1.76583194732666,1.83293414115906,999.929748535156,999.929748535156,,,2.67749619483948,,1,0,0,0,0.0002288818359375,35.190616607666,6,1,1,1.79673933982849,0,1.8017492029402,-200.995208740234,1,0.00363123740995048,0.000179283821700351,0.00363741276846532,0.000179297118040062,0.93444961309433,0.967511177062988,30.9552268981934,,30,4,200,-0.000751372252125293,-1.42169773578644,0.242280706763268,1,,,,,,,,,,,,,,,,
,3959083280.94848,1.79988068342209,999.929748535156,,,6,,,,30.738023492992,,,10,,,,,,,,,,,,,,,,,,,,,,1.78332006931305,1.81561458110809,999.929748535156,999.929748535156,,,2.67897725105286,,1,0,0,0,0.000152587890625,36.1681327819824,6,1,1,1.79530513286591,0,1.79989524682363,-196.996810913086,1,0.00358634857484151,0.000102250917599198,0.00359393144791636,0.000102280499269937,0.931414127349854,0.96730762720108,30.9690399169922,0,30,4,200,-0.000135956928716041,-1.41230034828186,0.231702581048012,3,,,,,,,,,,,,,,,,
,3959083508.57306,1.79802161455154,999.929748535156,,,6,,,,30.738023492992,,,10,,,,,,,,,,,,,,,,,,,,,,1.79655420780182,1.80288004875183,999.929748535156,999.929748535156,,,2.67589020729065,,1,0,0,0,0.0002288818359375,35.6793746948242,6,1,1,1.79668378829956,0,1.79989101886749,-192.000015258789,1,0.00354225738570735,0.000174967175142681,0.00354986821877904,0.000174984728761615,0.928113341331482,0.967006325721741,30.9824886322022,1,30,4,200,-0.000458497524959967,-1.40319800376892,0.21930031478405,1,,,,,,,,,,,,,,,,
,3959083735.62472,1.80550855398178,999.929748535156,,,6,,,,30.738023492992,,,10,,,,,,,,,,,,,,,,,,,,,,1.7895565032959,1.80768537521362,999.929748535156,999.929748535156,,,2.67935633659363,,1,0,0,0,0.000152587890625,35.190616607666,6,1,1,1.80368077754974,0,1.80032722864832,-187.996810913086,1,0.00351413197533859,0.000100214565062192,0.0035219029651794,0.000100227640085383,0.928207635879517,0.968218564987183,30.984317779541,1.89950096682878E-5,30,4,200,-0.000218868881347589,-1.40006506443024,0.210329830646515,3,,,,,,,,,,,,,,,,
,3959083956.51969,1.79433476924896,999.929748535156,,,6,,,,30.738023492992,,,10,,,,,,,,,,,,,,,,,,,,,,1.78387320041656,1.81244826316834,999.929748535156,999.929748535156,,,2.67656111717224,,1,0,0,0,0.000152587890625,35.190616607666,6,1,1,1.78165519237518,0,1.80084692239761,-183.000015258789,1,0.00346842172721137,0.000171360993046861,0.00347703208987379,0.000171383141724248,0.924884021282196,0.969055473804474,30.9997310638428,5.56774044036865,30,4,200,-0.000680621480569243,-1.39218366146088,0.197166875004768,1,,,,,,,,,,,,,,,,
,3959084183.322,1.8043726682663,999.929748535156,,,6,,,,30.738023492992,,,10,,,,,,,,,,,,,,,,,,,,,,1.77759897708893,1.83255136013031,999.929748535156,999.929748535156,,,2.68928003311157,,1,0,0,0,0,36.1681327819824,6,1,1,1.79219746589661,0,1.80125891720807,-178.996810913086,1,0.00343179087246717,9.79111695850273E-5,0.00344114811938847,9.79234835585258E-5,0.922128438949585,0.97020548582077,31.0128593444824,0,30,4,200,-0.000381961202947423,-1.3873724937439,0.186266094446182,3,,,,,,,,,,,,,,,,
,3959084408.25075,1.8029373884201,999.929748535156,,,6,,,,30.738023492992,,,10,,,,,,,,,,,,,,,,,,,,,,1.76439416408539,1.82730162143707,999.929748535156,999.929748535156,,,2.68322682380676,,1,0,0,0,0.000152587890625,35.190616607666,6,1,1,1.78949558734894,0,1.80292170577579,-174.000015258789,1,0.00337895957462928,0.000167034232908763,0.00339034409686098,0.000167098586148487,0.917834103107452,0.971416294574738,31.0320472717285,,30,4,200,-0.000745796365663409,-1.37811350822449,0.172353461384773,1,,,,,,,,,,,,,,,,
,3959084634.17102,1.80626487731934,999.929748535156,,,6,,,,30.738023492992,,,10,,,,,,,,,,,,,,,,,,,,,,1.76744103431702,1.82809448242187,999.929748535156,999.929748535156,,,2.68140912055969,,1,0,0,0,0.000762939453125,35.190616607666,6,1,1,1.80041432380676,0,1.79965953473692,-169.996810913086,1,0.00333766022876095,9.52785978736685E-5,0.00335038699244138,9.53335163596615E-5,0.915318667888641,0.972846746444702,31.0432643890381,0,30,4,200,-0.000873909040819854,-1.37115347385406,0.162079006433487,3,,,,,,,,,,,,,,,,
,3959084859.39394,1.79690492153168,999.929748535156,,,6,,,,30.738023492992,,,10,,,,,,,,,,,,,,,,,,,,,,1.78726291656494,1.80961978435516,999.929748535156,999.929748535156,,,2.67307233810425,,1,0,0,0,0.00030517578125,35.190616607666,6,1,1,1.79560899734497,0,1.79943543010288,-165.000015258789,1,0.00330857785803054,0.000163574890187818,0.00332090133332382,0.000163654132486174,0.916373610496521,0.976529479026794,31.0445404052734,,30,4,200,-0.000390671601053327,-1.36710155010223,0.152863845229149,1,,,,,,,,,,,,,,,,
,3959085087.01714,1.80095791816711,999.929748535156,,,6,,,,30.738023492992,,,10,,,,,,,,,,,,,,,,,,,,,,1.79326558113098,1.80663299560547,999.929748535156,999.929748535156,,,2.66838622093201,,1,0,0,0,0.0002288818359375,35.190616607666,6,1,1,1.79987955093384,0,1.80000361689815,-160.996810913086,1,0.0032910132547576,9.39326627250733E-5,0.0033022823982792,9.39513405107084E-5,0.91713947057724,0.978778421878815,31.043327331543,4.29672309110174E-6,30,4,200,-0.000329901347868145,-1.36670804023743,0.145726129412651,3,,,,,,,,,,,,,,,,
,3959085314.82785,1.80283230543137,999.929748535156,,,6,,,,30.738023492992,,,10,,,,,,,,,,,,,,,,,,,,,,1.79768490791321,1.80647504329681,999.929748535156,999.929748535156,,,2.67766380310059,,1,0,0,0,0.000152587890625,37.6344108581543,6,1,1,1.79918956756592,0,1.80152734120687,-155.995208740234,1,0.00328353380373556,0.000162302792576737,0.00329454730450538,0.000162333968036593,0.918894529342651,0.983064234256744,31.0399150848389,0,30,4,200,-0.000224457413423806,-1.36999952793121,0.139868080615997,1,,,,,,,,,,,,,,,,
,3959085537.77949,1.79976582527161,999.929748535156,,,6,,,,30.738023492992,,,10,,,,,,,,,,,,,,,,,,,,,,1.77424073219299,1.81849765777588,999.929748535156,999.929748535156,,,2.67890477180481,,1,0,0,0,0.000152587890625,35.190616607666,6,1,1,1.79302477836609,0,1.79924280996676,-151.996810913086,1,0.00327496644570562,9.34530263179767E-5,0.00328581645662579,9.34719829557091E-5,0.919961631298065,0.985258936882019,31.0370941162109,0,30,4,200,-0.000363838247722015,-1.37239265441895,0.135464027523994,3,,,,,,,,,,,,,,,,
,3959085764.63598,1.80633807182312,999.929748535156,,,6,,,,30.738023492992,,,10,,,,,,,,,,,,,,,,,,,,,,1.76733732223511,1.82930088043213,999.929748535156,999.929748535156,,,2.68603920936584,,1,0,0,0,0,34.7018585205078,6,1,1,1.80197620391846,0,1.80077134370804,-146.995208740234,1,0.00327230536936951,0.000161719681200481,0.00328295527390418,0.000161752794905782,0.921050250530243,0.987213671207428,31.0336608886719,1.3015795730098E-6,30,4,200,-0.000458582711871713,-1.37879812717438,0.129077166318893,1,,,,,,,,,,,,,,,,
,3959085987.83191,1.79791623353958,999.929748535156,,,6,,,,30.738023492992,,,10,,,,,,,,,,,,,,,,,,,,,,1.76142501831055,1.84175169467926,999.929748535156,999.929748535156,,,2.68031096458435,,1,0,0,0,0.000152587890625,35.6793746948242,6,1,1,1.7871173620224,0,1.80078237145035,-142.996810913086,1,0.00326925347617511,9.32705488330614E-5,0.0032797541052995,9.32961469037109E-5,0.922591745853424,0.987945795059204,31.0277423858643,0.208988398313522,30,4,200,-0.000529465149156749,-1.38483560085297,0.235164895653725,3,,,,,,,,,,,,,,,,
,3959086217.23102,1.79913824796677,999.929748535156,,,6,,,,30.738023492992,,,10,,,,,,,,,,,,,,,,,,,,,,1.77102518081665,1.84049081802368,999.929748535156,999.929748535156,,,2.6763186454773,,1,0,0,0,0,35.190616607666,6,1,1,1.78879010677338,0,1.80143831835853,-137.995208740234,1,0.00327817394280657,0.000161968091239964,0.00328890034904569,0.000162043225732792,0.924356698989868,0.988491952419281,31.0205593109131,0,30,4,200,-0.000591775111388415,-1.28208386898041,0.231816217303276,1,,,,,,,,,,,,,,,,
,3959086440.27764,1.80137473344803,999.929748535156,,,6,,,,30.738023492992,,,10,,,,,,,,,,,,,,,,,,,,,,1.77710509300232,1.82069051265717,999.929748535156,999.929748535156,,,2.67161202430725,,1,0,0,0,0.0002288818359375,35.6793746948242,6,1,1,1.79242467880249,0,1.80054988684478,-133.996810913086,1,0.00329610182979953,9.39935190323526E-5,0.00330550018123468,9.40256488874154E-5,0.9287069439888,0.990801572799683,31.0060749053955,3.11090443574358E-5,30,4,200,-0.000244773837039247,-1.29426527023315,0.228723183274269,3,,,,,,,,,,,,,,,,
,3959086669.14264,1.80043709278107,999.929748535156,,,6,,,,30.738023492992,,,10,,,,,,,,,,,,,,,,,,,,,,1.79471361637115,1.80334901809692,999.929748535156,999.929748535156,,,2.66492533683777,,1,0,0,0,0.00030517578125,35.190616607666,6,1,1,1.79807794094086,0,1.80023820400238,-128.995208740234,1,0.00332180592366378,0.000164018095304278,0.00332949536149038,0.000164038677299594,0.933375597000122,0.991320908069611,30.9881191253662,5.3479905128479,30,4,200,-0.000422833603806794,-1.3079297542572,0.2273338586092,1,,,,,,,,,,,,,,,,
,3959086897.90455,1.80396342277527,999.929748535156,,,6,,,,30.738023492992,,,10,,,,,,,,,,,,,,,,,,,,,,1.7882878780365,1.80521321296692,999.929748535156,999.929748535156,,,2.67475414276123,,1,0,0,0,0.000152587890625,35.190616607666,6,1,1,1.80135643482208,0,1.80061059969443,-124.996803283691,1,0.00336277352368013,9.58545369286387E-5,0.00337021889582032,9.58685122155011E-5,0.934825956821442,0.988817393779755,30.9807033538818,,30,4,200,-0.000141913260449655,-1.32772445678711,0.228707149624825,3,,,,,,,,,,,,,,,,
,3959087122.57835,1.79349082708359,999.929748535156,,,6,,,,30.738023492992,,,10,,,,,,,,,,,,,,,,,,,,,,1.77580738067627,1.81881713867187,999.929748535156,999.929748535156,,,2.67704892158508,,1,0,0,0,7.62939453125E-5,35.190616607666,6,1,1,1.77961480617523,0,1.79780761003494,-119.995208740234,1,0.00340418244526116,0.000168024958691592,0.00341073188972472,0.000168050781259005,0.938998937606812,0.986172139644623,30.9623336791992,5.56438064575195,30,4,200,-0.00032401314820163,-1.34628558158875,0.230571001768112,1,,,,,,,,,,,,,,,,
,3959087349.60051,1.81057608127594,999.929748535156,,,6,,,,30.738023492992,,,10,,,,,,,,,,,,,,,,,,,,,,1.76099073886871,1.83644795417786,999.929748535156,999.929748535156,,,2.68464207649231,,1,0,0,0,7.62939453125E-5,37.6344108581543,6,1,1,1.80693590641022,0,1.80022362426475,-115.996803283691,1,0.00344356229801492,9.81130775223299E-5,0.00344924419534,9.81228148454668E-5,0.942137002944946,0.984034419059753,30.947660446167,0,30,4,200,-0.00101771054323763,-1.3645133972168,0.231894671916962,3,,,,,,,,,,,,,,,,
,3959087577.06141,1.80566257238388,999.929748535156,,,6,,,,30.738023492992,,,10,,,,,,,,,,,,,,,,,,,,,,1.77476561069489,1.8214123249054,999.929748535156,999.929748535156,,,2.67908096313477,,1,0,0,0,0.000152587890625,35.190616607666,6,1,1,1.80146527290344,0,1.80005518595378,-110.995208740234,1,0.00349520685306303,0.000172427955652731,0.00350011233837409,0.000172462271037304,0.948198735713959,0.983269333839416,30.9227333068848,0,30,4,200,-0.000614468823187053,-1.38601219654083,0.234722822904587,1,,,,,,,,,,,,,,,,
,3959087804.50844,1.7992656826973,999.929748535156,,,6,,,,30.738023492992,,,10,,,,,,,,,,,,,,,,,,,,,,1.74343812465668,1.85956382751465,999.929748535156,999.929748535156,,,2.67545247077942,,1,0,0,0,0.000152587890625,35.190616607666,6,1,1,1.78943085670471,0,1.80057213924549,-106.996803283691,1,0.0035423380366013,0.000100867070415413,0.00354600247476942,0.000100876791666365,0.953574597835541,0.98319286108017,30.9008197784424,0.123127400875092,30,4,200,-0.000576043908949941,-1.40795159339905,0.235709369182587,3,,,,,,,,,,,,,,,,
,3959088032.53757,1.79367297887802,999.929748535156,,,6,,,,30.738023492992,,,10,,,,,,,,,,,,,,,,,,,,,,1.77803218364716,1.81578624248505,999.929748535156,999.929748535156,,,2.67129111289978,,1,0,0,0,0.0002288818359375,34.7018585205078,6,1,1,1.78621697425842,0,1.80050210952759,-101.99520111084,1,0.00359924754917184,0.000177471225731702,0.00360228110840824,0.000177494652503574,0.959026455879211,0.983898878097534,30.8802127838135,,30,4,200,0.000487268669530749,-1.43191885948181,0.237634003162384,1,,,,,,,,,,,,,,,,
,3959088259.50174,1.79977399110794,999.929748535156,,,6,,,,30.738023492992,,,10,,,,,,,,,,,,,,,,,,,,,,1.7934650182724,1.80352532863617,999.929748535156,999.929748535156,,,2.66779351234436,,1,0,0,0,0.0002288818359375,34.7018585205078,6,1,1,1.79814612865448,0,1.8000107076433,-97.9968032836914,1,0.00364094891403618,0.000103634529152485,0.00364319683491737,0.000103639525202021,0.962890863418579,0.984507918357849,30.8651580810547,0,30,4,200,-0.000360409118002281,-1.45009386539459,0.238632023334503,3,,,,,,,,,,,,,,,,
,3959088487.99472,1.79766029119492,999.929748535156,,,6,,,,30.738023492992,,,10,,,,,,,,,,,,,,,,,,,,,,1.78939282894135,1.80673480033874,999.929748535156,999.929748535156,,,2.67455816268921,,1,0,0,0,0.000152587890625,35.190616607666,6,1,1,1.79242324829102,0,1.80074309110641,-93.0000076293945,1,0.00370217708235935,0.000182500044729618,0.00370398991805514,0.000182508745215931,0.965787172317505,0.983046770095825,30.8500080108643,2.7830012186314E-5,30,4,200,-0.000437365553807467,-1.47591531276703,0.242283046245575,1,,,,,,,,,,,,,,,,
,3959088714.58139,1.80469936132431,999.929748535156,,,6,,,,30.738023492992,,,10,,,,,,,,,,,,,,,,,,,,,,1.77561020851135,1.82319033145905,999.929748535156,999.929748535156,,,2.67639756202698,,1,0,0,0,0.000152587890625,34.7018585205078,6,1,1,1.79854333400726,0,1.80046251085069,-88.9968032836914,1,0.00374342647261686,0.000106527733763678,0.00374479389455736,0.000106531843441954,0.969471573829651,0.983293831348419,30.8343715667725,0,30,4,200,4.99492816743441E-5,-1.49303531646729,0.244215235114098,3,,,,,,,,,,,,,,,,
,3959088944.35526,1.79993653297424,999.929748535156,,,6,,,,30.738023492992,,,10,,,,,,,,,,,,,,,,,,,,,,1.76834273338318,1.82794761657715,999.929748535156,999.929748535156,,,2.68413710594177,,1,0,0,0,7.62939453125E-5,34.7018585205078,6,1,1,1.79444563388824,0,1.80164987511105,-84.0000076293945,1,0.00378870449429022,0.000186720558061819,0.00378969326006378,0.000186728039737536,0.973717391490936,0.984212875366211,30.8172149658203,INF,30,4,200,-0.00111780827865005,-1.5106748342514,0.246056199073791,1,,,,,,,,,,,,,,,,
,3959089168.2407,1.80259758234024,999.929748535156,,,6,,,,30.738023492992,,,10,,,,,,,,,,,,,,,,,,,,,,1.76378059387207,1.83309531211853,999.929748535156,999.929748535156,,,2.68214511871338,,1,0,0,0,0.000152587890625,34.2131004333496,6,1,1,1.79432332515717,0,1.79957714787236,-79.9968032836914,1,0.00381481118710178,0.000108534792574425,0.00381549587824894,0.00010853839123498,0.977998733520508,0.986160397529602,30.8025321960449,,30,4,200,-0.000772884115576744,-1.52127742767334,0.245285600423813,3,,,,,,,,,,,,,,,,
,3959089397.04303,1.80228406190872,999.929748535156,,,6,,,,30.738023492992,,,10,,,,,,,,,,,,,,,,,,,,,,1.77140724658966,1.82465577125549,999.929748535156,999.929748535156,,,2.67379117012024,,1,0,0,0,0.000152587890625,34.2131004333496,6,1,1,1.80093169212341,0,1.80151442686717,-74.9952011108398,1,0.00383675425332108,0.000189049940248176,0.00383707328021571,0.000189052009736809,0.983224987983704,0.988293945789337,30.7833614349365,0,30,4,200,-0.000726230733562261,-1.52977192401886,0.243372350931168,1,,,,,,,,,,,,,,,,
,3959089622.34187,1.8011172413826,999.929748535156,,,6,,,,30.738023492992,,,10,,,,,,,,,,,,,,,,,,,,,,1.77715837955475,1.82486188411713,999.929748535156,999.929748535156,,,2.66569423675537,,1,0,0,0,0.00030517578125,35.190616607666,6,1,1,1.79630768299103,0,1.80151206254959,-70.9968032836914,1,0.00385020749679223,0.000109524226475551,0.00385040867988505,0.000109526077544359,0.987252354621887,0.990418195724487,30.7698593139648,0,30,4,200,-0.000164499782840721,-1.53620290756226,0.241267681121826,3,,,,,,,,,,,,,,,,
,3959089851.40296,1.80001431703568,999.929748535156,,,6,,,,30.738023492992,,,10,,,,,,,,,,,,,,,,,,,,,,1.79371023178101,1.80450332164764,999.929748535156,999.929748535156,,,2.66594743728638,,1,0,0,0,0.0002288818359375,35.190616607666,6,1,1,1.79793214797974,0,1.80033543109894,-65.9952011108398,1,0.00385642448043399,0.000190002581830339,0.00385647398509746,0.000190003020657945,0.989645659923553,0.990717768669128,30.7554187774658,,30,4,200,-0.000418091251049191,-1.54067862033844,0.236613363027573,1,,,,,,,,,,,,,,,,
,3959090077.6083,1.80231261253357,999.929748535156,,,6,,,,30.738023492992,,,10,,,,,,,,,,,,,,,,,,,,,,1.78915739059448,1.80592393875122,999.929748535156,999.929748535156,,,2.6701807975769,,1,0,0,0,0.000152587890625,34.7018585205078,6,1,1,1.80045986175537,0,1.80007211651121,-61.9968032836914,1,0.00386980774562334,0.00011007856714874,0.00386980941517848,0.000110078604732546,0.989807069301605,0.989815950393677,30.739631652832,0.313024371862412,30,4,200,-0.000308472139295191,-1.54869771003723,0.234489262104034,3,,,,,,,,,,,,,,,,
,3959090308.29585,1.80308026075363,999.929748535156,,,6,,,,30.738023492992,,,10,,,,,,,,,,,,,,,,,,,,,,1.77840304374695,1.81546783447266,999.929748535156,999.929748535156,,,2.67458033561707,,1,0,0,0,0.000152587890625,34.7018585205078,6,1,1,1.79745626449585,0,1.80125278896756,-56.9952011108398,1,0.00386346811203575,0.000190358260650664,0.00386348338391932,0.000190357475016662,0.985910892486572,0.986496448516846,30.7227592468262,5.36047840118408,30,4,200,-0.000489292317070067,-1.54924535751343,0.228652432560921,1,,,,,,,,,,,,,,,,
,3959090534.33398,1.79892176389694,999.929748535156,,,6,,,,30.738023492992,,,10,,,,,,,,,,,,,,,,,,,,,,1.76651406288147,1.83178758621216,999.929748535156,999.929748535156,,,2.68342232704163,,1,0,0,0,0.0142669677734375,34.2131004333496,6,1,1,1.79363536834717,0,1.80065243332474,-52.9968032836914,1,0.00384992503164153,0.000109525079520685,0.0038500115588891,0.000109524540124363,0.981972515583038,0.983562052249908,30.7099304199219,0,30,4,200,-0.00104953953996301,-1.54700565338135,0.222906082868576,3,,,,,,,,,,,,,,,,
,3959090763.50194,1.80412799119949,999.929748535156,,,6,,,,30.738023492992,,,10,,,,,,,,,,,,,,,,,,,,,,1.76792633533478,1.83131313323975,999.929748535156,999.929748535156,,,2.68084335327148,,1,0,0,0,0.000152587890625,35.190616607666,6,1,1,1.80187857151031,0,1.80222491423289,-48.0000038146973,1,0.00381420739675041,0.000187965783661004,0.0038143732742716,0.000187962618397753,0.976199448108673,0.978884339332581,30.6962566375732,INF,30,4,200,-0.000913988682441413,-1.5371994972229,0.212762862443924,1,,,,,,,,,,,,,,,,
,3959090991.53742,1.79988700151443,999.929748535156,,,6,,,,30.738023492992,,,10,,,,,,,,,,,,,,,,,,,,,,1.75135493278503,1.84863877296448,999.929748535156,999.929748535156,,,2.67609214782715,,1,0,0,0,0.00030517578125,35.190616607666,6,1,1,1.79541838169098,0,1.80079970977925,-43.9968032836914,1,0.00377553126755549,0.000107435962372884,0.00377589738015875,0.000107435292396616,0.971151888370514,0.974980711936951,30.6833820343018,5.17309163114987E-5,30,4,200,-0.000734711240511388,-1.52636027336121,0.20419479906559,3,,,,,,,,,,,,,,,,
,3959091221.24463,1.79528266191483,999.929748535156,,,6,,,,30.738023492992,,,10,,,,,,,,,,,,,,,,,,,,,,1.7840234041214,1.82006895542145,999.929748535156,999.929748535156,,,2.66428327560425,,1,0,0,0,0.00030517578125,34.7018585205078,6,1,1,1.78396368026733,0,1.80248771905899,-38.9952011108398,1,0.00373033280276554,0.000183884690986853,0.00373084912001887,0.000183874085340326,0.966312646865845,0.972741067409515,30.6624088287354,4.82771429233253E-5,30,4,200,-0.00053075299365446,-1.51292014122009,0.195304796099663,1,,,,,,,,,,,,,,,,
,3959091448.40675,1.79950141906738,999.929748535156,,,6,,,,30.738023492992,,,10,,,,,,,,,,,,,,,,,,,,,,1.79347324371338,1.80501878261566,999.929748535156,999.929748535156,,,2.66487407684326,,1,0,0,0,0.0002288818359375,34.7018585205078,6,1,1,1.7973096370697,0,1.79980619306918,-34.9968032836914,1,0.0037034419841817,0.000105410526132823,0.00370441602089119,0.000105410384645184,0.963627636432648,0.971806406974792,30.6502513885498,0.107743382453918,30,4,200,-0.000309940689476207,-1.50648057460785,0.188735321164131,3,,,,,,,,,,,,,,,,
,3959091676.55384,1.80041116476059,999.929748535156,,,6,,,,30.738023492992,,,10,,,,,,,,,,,,,,,,,,,,,,1.79077517986298,1.8074164390564,999.929748535156,999.929748535156,,,2.67048954963684,,1,0,0,0,0.000152587890625,34.7018585205078,6,1,1,1.79442882537842,0,1.80073901414871,-29.9952011108398,1,0.00366966408941495,0.00018094518310121,0.0036712052598992,0.000180942159108476,0.958777546882629,0.971238970756531,30.6251926422119,0,30,4,200,-0.000362945487722754,-1.49822402000427,0.181633502244949,1,,,,,,,,,,,,,,,,
,3959091901.53886,1.8007869720459,999.929748535156,,,6,,,,30.738023492992,,,10,,,,,,,,,,,,,,,,,,,,,,1.7739120721817,1.82476246356964,999.929748535156,999.929748535156,,,2.67184829711914,,1,0,0,0,0.000152587890625,35.6793746948242,6,1,1,1.7957079410553,0,1.79907814220146,-25.9968013763428,1,0.00363214213710098,0.000103418896339724,0.00363426856661729,0.000103419630399905,0.954685688018799,0.97002100944519,30.6081295013428,0,30,4,200,-0.000266346731223166,-1.49006164073944,0.172824114561081,3,,,,,,,,,,,,,,,,
,3959092129.64222,1.80578207969666,999.929748535156,,,6,,,,30.738023492992,,,10,,,,,,,,,,,,,,,,,,,,,,1.76547181606293,1.83965134620666,999.929748535156,999.929748535156,,,2.68136382102966,,1,0,0,0,0.00030517578125,35.190616607666,6,1,1,1.80577635765076,0,1.80351388454437,-21.0000019073486,1,0.00358272752521579,0.00017672070152435,0.00358533661804332,0.000176720722554591,0.950989544391632,0.969198226928711,30.592601776123,1.54687495523831E-5,30,4,200,-0.000683304853737354,-1.47801554203033,0.162190496921539,1,,,,,,,,,,,,,,,,
,3959092355.53047,1.79991209506989,999.929748535156,,,6,,,,30.738023492992,,,10,,,,,,,,,,,,,,,,,,,,,,1.76560711860657,1.83460962772369,999.929748535156,999.929748535156,,,2.67848086357117,,1,0,0,0,0.000152587890625,35.190616607666,6,1,1,1.79237675666809,0,1.8010300927692,-16.9968013763428,1,0.00352782732355856,0.000100479894574213,0.00353067136856326,0.000100476599722761,0.948308348655701,0.968411684036255,30.5818538665771,0,30,4,200,-0.00078059738734737,-1.46240282058716,0.152843117713928,3,,,,,,,,,,,,,,,,
,3959092584.84323,1.79625248908997,999.929748535156,,,6,,,,30.738023492992,,,10,,,,,,,,,,,,,,,,,,,,,,1.77505266666412,1.81558930873871,999.929748535156,999.929748535156,,,2.67224931716919,,1,0,0,0,0.001068115234375,34.7018585205078,6,1,1,1.78772258758545,0,1.79790186882019,-12.0000009536743,1,0.00345677231205504,0.000170554801136299,0.00345949864216234,0.000170525521080891,0.945674538612366,0.967829465866089,30.5707778930664,1.77963847818319E-5,30,4,200,-0.00118330703116953,-1.44112038612366,0.141769915819168,1,,,,,,,,,,,,,,,,
,3959092810.25701,1.79757350683212,999.929748535156,,,6,,,,30.738023492992,,,10,,,,,,,,,,,,,,,,,,,,,,1.77873504161835,1.81954038143158,999.929748535156,999.929748535156,,,2.66525721549988,,1,0,0,0,0.000152587890625,34.7018585205078,6,1,1,1.78734242916107,0,1.80240933711712,-7.99680042266846,1,0.00342196197201596,9.74844956472494E-5,0.00342528829846191,9.74734091101511E-5,0.944503724575043,0.969775140285492,30.5598373413086,1.62551659741439E-5,30,4,200,-0.00065877556335181,-1.43153488636017,0.247944802045822,3,,,,,,,,,,,,,,,,
,3959093039.45855,1.79946172237396,999.929748535156,,,6,,,,30.738023492992,,,10,,,,,,,,,,,,,,,,,,,,,,1.79470300674438,1.80398726463318,999.929748535156,999.929748535156,,,2.66279911994934,,1,0,0,0,0.0002288818359375,34.7018585205078,6,1,1,1.79826486110687,0,1.8001594543457,-3.00000023841858,1,0.0033908401561529,0.000167323586611059,0.00339497815752446,0.000167326487446261,0.943328201770782,0.971504390239716,30.5508670806885,0,30,4,200,-0.000150953346746974,-1.42438340187073,0.241176947951317,1,,,,,,,,,,,,,,,,
,3959093265.56244,1.80263519287109,999.929748535156,,,6,,,,30.738023492992,,,10,,,,,,,,,,,,,,,,,,,,,,1.79155611991882,1.80455315113068,999.929748535156,999.929748535156,,,2.66866016387939,,1,0,0,0,0.000152587890625,34.7018585205078,6,1,1,1.80085587501526,0,1.80028838139993,0.998400032520294,1,0.00336790099695917,9.59588851115923E-5,0.00337255172114384,9.59607866338523E-5,0.941861093044281,0.974205076694489,30.539270401001,0,30,4,200,-0.000227062540943734,-1.42085754871368,0.235508695244789,3,,,,,,,,,,,,,,,,
,3959093493.54604,1.7959680557251,999.929748535156,,,6,,,,30.738023492992,,,10,,,,,,,,,,,,,,,,,,,,,,1.77287757396698,1.80994737148285,999.929748535156,999.929748535156,,,2.67185616493225,,1,0,0,0,7.62939453125E-5,34.2131004333496,6,1,1,1.78532576560974,0,1.79697551727295,6.00000047683716,1,0.00333608315761778,0.000164641646576739,0.00334101672174593,0.000164647281968155,0.941219389438629,0.976043343544006,30.533239364624,7.74791442381684E-6,30,4,200,-0.000554156547877938,-1.41378974914551,0.229058533906937,1,,,,,,,,,,,,,,,,
,3959093720.56758,1.80593109130859,999.929748535156,,,6,,,,30.738023492992,,,10,,,,,,,,,,,,,,,,,,,,,,1.76142907142639,1.82595264911652,999.929748535156,999.929748535156,,,2.67994165420532,,1,0,0,0,0.00030517578125,35.6793746948242,6,1,1,1.79514312744141,0,1.80162528267613,9.99840068817139,1,0.00331259611969149,9.43826121735323E-5,0.00331742007812744,9.43839158915108E-5,0.941969752311706,0.977856814861298,30.5339488983154,0,30,4,200,-0.00101314519997686,-1.40925097465515,0.223925292491913,3,,,,,,,,,,,,,,,,
,3959093947.21497,1.79545587301254,999.929748535156,,,6,,,,30.738023492992,,,10,,,,,,,,,,,,,,,,,,,,,,1.76679444313049,1.82185506820679,999.929748535156,999.929748535156,,,2.67702555656433,,1,0,0,0,0.0002288818359375,35.190616607666,6,1,1,1.77939438819885,0,1.80095655388302,14.9952011108398,1,0.00328591577032077,0.000162133017276496,0.00329023309521795,0.000162129489969118,0.944753885269165,0.980323553085327,30.5417175292969,1.88539961527567E-5,30,4,200,-0.000707227794919163,-1.40388655662537,0.218355774879456,1,,,,,,,,,,,,,,,,
,3959094172.11434,1.801882147789,999.929748535156,,,6,,,,30.738023492992,,,10,,,,,,,,,,,,,,,,,,,,,,1.76307857036591,1.84920334815979,999.929748535156,999.929748535156,,,2.67493939399719,,1,0,0,0,0.01129150390625,35.6793746948242,6,1,1,1.79435575008392,0,1.80007208718194,18.9984016418457,1,0.00326788429519778,9.30774588095314E-5,0.00327187799873792,9.30801605106553E-5,0.948042154312134,0.982152044773102,30.552619934082,2.23259121412411E-6,30,4,200,-0.000371456873835996,-1.28955984115601,0.21417061984539,3,,,,,,,,,,,,,,,,
,3959094400.80351,1.80019497871399,999.929748535156,,,6,,,,30.738023492992,,,10,,,,,,,,,,,,,,,,,,,,,,1.78997850418091,1.81248271465302,999.929748535156,999.929748535156,,,2.66544365882874,,1,0,0,0,0.000152587890625,34.7018585205078,6,1,1,1.79817712306976,0,1.8007716205385,24.0000019073486,1,0.00326259152380255,0.00016092356585522,0.00326577419313668,0.000160909698757933,0.951770424842834,0.98563426733017,30.5630683898926,,30,4,200,-0.000436122849350795,-1.29074347019196,0.211036369204521,1,,,,,,,,,,,,,,,,
,3959094628.51596,1.7997083067894,999.929748535156,,,6,,,,30.738023492992,,,10,,,,,,,,,,,,,,,,,,,,,,1.79408872127533,1.80386388301849,999.929748535156,999.929748535156,,,2.66406440734863,,1,0,0,0,0.0002288818359375,35.190616607666,6,1,1,1.79943811893463,0,1.79965164831706,27.9984016418457,1,0.00326716604319687,9.30266310458857E-5,0.00327024337670595,9.30251697402691E-5,0.954753756523132,0.988381505012512,30.5719509124756,,30,4,200,-0.000127029590657912,-1.29588901996613,0.209131598472595,3,,,,,,,,,,,,,,,,
,3959094857.33046,1.80126738548279,999.929748535156,,,6,,,,30.738023492992,,,10,,,,,,,,,,,,,,,,,,,,,,1.79225707054138,1.80480623245239,999.929748535156,999.929748535156,,,2.66848230361938,,1,0,0,0,0.000152587890625,35.6793746948242,6,1,1,1.79846477508545,0,1.8007720179028,32.9952011108398,1,0.00328009386532996,0.000161738705970996,0.00328280018376111,0.00016173903515826,0.9583899974823,0.990646183490753,30.5843753814697,4.34928715264959E-8,30,4,200,-0.000128521511214785,-1.3041273355484,0.207411468029022,1,,,,,,,,,,,,,,,,
,3959095081.5682,1.80299586057663,999.929748535156,,,6,,,,30.738023492992,,,10,,,,,,,,,,,,,,,,,,,,,,1.77320826053619,1.82122325897217,999.929748535156,999.929748535156,,,2.67100119590759,,1,0,0,0,7.62939453125E-5,35.190616607666,6,1,1,1.79429972171783,0,1.80103506360735,36.9984016418457,1,0.00329407103042009,9.37664584578827E-5,0.00329638971335712,9.37666605233944E-5,0.96139657497406,0.99060070514679,30.5961151123047,0,30,4,200,-4.92908566229744E-6,-1.31217288970947,0.206703796982765,3,,,,,,,,,,,,,,,,
,3959095311.40598,1.79940074682236,999.929748535156,,,6,,,,30.738023492992,,,10,,,,,,,,,,,,,,,,,,,,,,1.77196681499481,1.82715928554535,999.929748535156,999.929748535156,,,2.67658448219299,,1,0,0,0,0.0002288818359375,34.7018585205078,6,1,1,1.79598546028137,0,1.80073331462012,42.0000038146973,1,0.00332031796839623,0.000163676871643324,0.00332201278074614,0.000163673434717403,0.965660870075226,0.98917156457901,30.6149215698242,0,30,4,200,-0.000836900901049375,-1.3236939907074,0.208244547247887,1,,,,,,,,,,,,,,,,
,3959095535.67167,1.80200344324112,999.929748535156,,,6,,,,30.738023492992,,,10,,,,,,,,,,,,,,,,,,,,,,1.76420426368713,1.83687102794647,999.929748535156,999.929748535156,,,2.67873048782349,,1,0,0,0,0.00030517578125,35.190616607666,6,1,1,1.79820084571838,0,1.80101025104523,45.9984016418457,1,0.00335781041253777,9.55499148733345E-5,0.00335894928020771,9.55485567971523E-5,0.970938622951508,0.988241612911224,30.637674331665,0,30,4,200,-0.000530074001289904,-1.33971881866455,0.211075827479362,3,,,,,,,,,,,,,,,,
,3959095764.81654,1.8055671453476,999.929748535156,,,6,,,,30.738023492992,,,10,,,,,,,,,,,,,,,,,,,,,,1.75882339477539,1.82711017131805,999.929748535156,999.929748535156,,,2.67448472976685,,1,0,0,0,0.00030517578125,34.7018585205078,6,1,1,1.79321563243866,0,1.80134341716766,50.9952011108398,1,0.00340339953992086,0.000167719385706928,0.0034040565647717,0.00016771941593198,0.976604104042053,0.987279832363129,30.6639060974121,0,30,4,200,-0.000250812649028376,-1.35791909694672,0.214828088879585,1,,,,,,,,,,,,,,,,
,3959095991.13261,1.80543822050095,999.929748535156,,,6,,,,30.738023492992,,,10,,,,,,,,,,,,,,,,,,,,,,1.78076040744782,1.8225005865097,999.929748535156,999.929748535156,,,2.6640841960907,,1,0,0,0,0,35.6793746948242,6,1,1,1.80138409137726,0,1.80145522400185,54.9984016418457,1,0.00344678218741322,9.80581029563693E-5,0.00344695531866072,9.80530326243602E-5,0.980923652648926,0.987347483634949,30.684103012085,0.569479167461395,30,4,200,-0.000682153215166181,-1.37543416023254,0.217952638864517,3,,,,,,,,,,,,,,,,
,3959096220.57728,1.79983645677567,999.929748535156,,,6,,,,30.738023492992,,,10,,,,,,,,,,,,,,,,,,,,,,1.79633700847626,1.80354750156403,999.929748535156,999.929748535156,,,2.65696096420288,,1,0,0,0,0.00030517578125,34.7018585205078,6,1,1,1.79786610603333,0,1.8002598285675,59.9952011108398,1,0.00349360838775348,0.000172139988169012,0.00349374725728623,0.000172138260169687,0.983917534351349,0.9873868227005,30.7003498077393,0,30,4,200,-9.57713782554492E-5,-1.39418017864227,0.221246585249901,1,,,,,,,,,,,,,,,,
,3959096446.33129,1.80311489105225,999.929748535156,,,6,,,,30.738023492992,,,10,,,,,,,,,,,,,,,,,,,,,,1.79179632663727,1.80493474006653,999.929748535156,999.929748535156,,,2.66093873977661,,1,0,0,0,0.00030517578125,34.7018585205078,6,1,1,1.80209982395172,0,1.80010569947106,63.9984016418457,1,0.00353971090958696,0.000100695695950662,0.00353978597134658,0.000100695647501973,0.984469294548035,0.985934495925903,30.7132034301758,0,30,4,200,-0.000322040257742628,-1.41282403469086,0.224386051297188,3,,,,,,,,,,,,,,,,
,3959096673.7274,1.80077666044235,999.929748535156,,,6,,,,30.738023492992,,,10,,,,,,,,,,,,,,,,,,,,,,1.77744901180267,1.81120598316193,999.929748535156,999.929748535156,,,2.66851139068604,,1,0,0,0,0.000152587890625,34.7018585205078,6,1,1,1.79645657539368,0,1.80102672841814,68.9952011108398,1,0.00359610509785831,0.000177188396308722,0.00359610496837898,0.000177188084005444,0.98460054397583,0.984713077545166,30.731014251709,0,30,4,200,-0.000240417924942449,-1.43389582633972,0.22930058836937,1,,,,,,,,,,,,,,,,
,3959096899.82994,1.80613881349564,999.929748535156,,,6,,,,30.738023492992,,,10,,,,,,,,,,,,,,,,,,,,,,1.76722323894501,1.83013164997101,999.929748535156,999.929748535156,,,2.67333078384399,,1,0,0,0,0.000152587890625,34.7018585205078,6,1,1,1.80385780334473,0,1.79985524106909,72.998405456543,1,0.00364716514832191,0.000103753453964628,0.00364717986213658,0.000103753586880316,0.983894765377045,0.984066605567932,30.7468700408936,0,30,4,200,-0.000496070249937475,-1.45211219787598,0.234770223498344,3,,,,,,,,,,,,,,,,
,3959097126.25076,1.79894036054611,999.929748535156,,,6,,,,30.738023492992,,,10,,,,,,,,,,,,,,,,,,,,,,1.76490867137909,1.83570861816406,999.929748535156,999.929748535156,,,2.6713342666626,,1,0,0,0,0.0002288818359375,34.7018585205078,6,1,1,1.79147720336914,0,1.80101977454291,77.9952011108398,1,0.00370508602563529,0.000182563957774387,0.00370522449899857,0.000182565901736168,0.982653439044952,0.9842689037323,30.7655792236328,0.30920085310936,30,4,200,-0.000580144638661295,-1.47332644462585,0.239885449409485,1,,,,,,,,,,,,,,,,
,3959097351.89771,1.80364954471588,999.929748535156,,,6,,,,30.738023492992,,,10,,,,,,,,,,,,,,,,,,,,,,1.76569664478302,1.83041751384735,999.929748535156,999.929748535156,,,2.67294502258301,,1,0,0,0,0.00030517578125,34.7018585205078,6,1,1,1.79363656044006,0,1.79987006275742,81.998405456543,1,0.00374614425003872,0.00010657339941907,0.00374644907032945,0.000106574930603666,0.981584191322327,0.985675871372223,30.7816581726074,9.29651260375977,30,4,200,-0.00057892658514902,-1.48851370811462,0.242755770683289,3,,,,,,,,,,,,,,,,
,3959097580.77309,1.79174214601517,999.929748535156,,,6,,,,30.738023492992,,,10,,,,,,,,,,,,,,,,,,,,,,1.76630473136902,1.81609928607941,999.929748535156,999.929748535156,,,2.65874648094177,,1,0,0,0,0.00030517578125,35.190616607666,6,1,1,1.7777578830719,0,1.79637706279755,87.0000076293945,1,0.00377788160696133,0.000186157179836125,0.00377832535830846,0.000186160153304744,0.980800330638886,0.987126767635345,30.7918682098389,0,30,4,200,-0.000673083821311593,-1.50118625164032,0.244282513856888,1,,,,,,,,,,,,,,,,
,3959097757.43989,1.80227357149124,999.929748535156,,,6,,,,30.738023492992,,,10,,,,,,,,,,,,,,,,,,,,,,1.76497030258179,1.82657039165497,999.929748535156,999.929748535156,,,2.67106246948242,,1,0,0,0,0.000152587890625,35.190616607666,6,1,1,1.79713129997253,0,1.80033117311972,90.0000076293945,1,0.0037798772547979,0.000107534724212403,0.00378034109117512,0.000107536641100369,0.980787038803101,0.987373232841492,30.7927665710449,5.54912328720093,30,4,200,-0.000536536041181535,-1.50388062000275,0.242545261979103,3,,,,,,,,,,,,,,,,