File: PPMS_Data_and_Plotting/Data/RuCl3/Data/Magnetisation/Rotator/TB001_RuCl3_H-parra-ab_61p2_mg_14-06-25_ZFCW_30K.dat
[Header]
; MPMS3 Data File (default extension .dat)
; Copyright (c) 2007, Quantum Design, Inc. All rights reserved.
TITLE,
FILEOPENTIME,3959122830.50068,06/15/2025,4:20 am
BYAPP,MPMS3 w/ AC,1.0,1.1
INFO,MPMS3 Measurement Release 1.2.2 Build 0, MultiVu Release 2.3.5.2,APPNAME
INFO,Linear Motor Servo Controller,MOTOR_MODULE_NAME
INFO,3101-100 N4,MOTOR_HW_VERSION
INFO,MMC1299,MOTOR_SERIAL_NUMBER
INFO,01.04.28,MOTOR_SOFTWARE_VERSION
INFO,Quantum Design Squid Module,SQUID_MODULE_NAME
INFO,3101-501 B0,SQUID_HW_VERSION
INFO,SQM364,SQUID_SERIAL_NUMBER
INFO,01.03.04,SQUID_SOFTWARE_VERSION
INFO,Quantum Design VSM Oven,OVEN_MODULE_NAME
INFO,3101-201 A3,OVEN_HW_VERSION
INFO,OVB387,OVEN_SERIAL_NUMBER
INFO,01.07.07,OVEN_SOFTWARE_VERSION
INFO,SQUID AC,AC_MODULE_NAME
INFO,3101-401 G0,AC_HW_VERSION
INFO,SAC242,AC_SERIAL_NUMBER
INFO,SQUID AC 00.95.11,AC_SOFTWARE_VERSION
INFO,TCI374,COIL_SERIAL_NUMBER
INFO,0,MOMENT_UNITS
INFO,RuCl3,SAMPLE_MATERIAL
INFO,single crystal,SAMPLE_COMMENT
INFO,61.2,SAMPLE_MASS
INFO,,SAMPLE_VOLUME
INFO,,SAMPLE_MOLECULAR_WEIGHT
INFO,,SAMPLE_SIZE
INFO,,SAMPLE_SHAPE
INFO,Rotator,SAMPLE_HOLDER
INFO,Standard,SAMPLE_HOLDER_DETAIL
INFO,67.44,SAMPLE_OFFSET
DATATYPE,COMMENT,1
DATATYPE,TIME,2
STARTUPAXIS,X,2
STARTUPAXIS,Y1,5
FIELDGROUP, VSM,2,3,4,5,6,8,9,10,11,14,15
FIELDGROUP, DC, 2,3,4,14,56,57,58,59,60,61,62,63,64,65,66,67,68,69
FIELDGROUP, AC, 2,3,4,11,16,17,18,19,20,21,22,23,24,25,26,27,28,29,30
STARTUPGROUP, All
[Data]
Comment,Time Stamp (sec),Temperature (K),Magnetic Field (Oe),Moment (emu),M. Std. Err. (emu),Transport Action,Averaging Time (sec),Frequency (Hz),Peak Amplitude (mm),Center Position (mm),Lockin Signal' (V),Lockin Signal (V),Range,M. Quad. Signal (emu),AC Moment (emu),AC M. Std Err. (emu),AC Phase (deg),AC Phase Std. Err. (deg),AC Susceptibility (emu/Oe),AC Suscept. Std Err. (emu/Oe),AC X' (emu/Oe),AC X' Std Err. (emu/Oe),AC X'' (emu/Oe),AC X'' Std Err. (emu/Oe),AC Drive (Oe),AC Frequency (Hz),AC Averaging Time (sec),AC Cycles,AC Range,AC Measure Type,AC Signal' (V),AC Signal'' (V),AC Trim Coil Ratio,AC Trim Coil Phase,Min. Temperature (K),Max. Temperature (K),Min. Field (Oe),Max. Field (Oe),Mass (grams),Motor Lag (deg),Pressure (Torr),Measure Count,Measurement Number,SQUID Status (code),Motor Status (code),Measure Status (code),Motor Current (amps),Motor Temp. (C),Temp. Status (code),Field Status (code),Chamber Status (code),Chamber Temp (K),Redirection State,Average Temp (K),Rotation Angle (deg),Rotator state,DC Moment Fixed Ctr (emu),DC Moment Err Fixed Ctr (emu),DC Moment Free Ctr (emu),DC Moment Err Free Ctr (emu),DC Fixed Fit,DC Free Fit,DC Calculated Center (mm),DC Calculated Center Err (mm),DC Scan Length (mm),DC Scan Time (s),DC Number of Points,DC Squid Drift,DC Min V (V),DC Max V (V),DC Scans per Measure,He3 temp,Map 02,Map 03,Map 04,Map 05,Map 06,Map 07,Map 08,Map 09,Map 10,Map 11,Map 12,Map 13,Map 14,Map 15,Map 16
,3959122840.7617,20.4900417327881,1000.35467529297,,,6,,,,30.738023492992,,,10,,,,,,,,,,,,,,,,,,,,,,19.9995937347412,20.9255695343018,1000.35467529297,1000.35467529297,,,5.52126836776733,,1,0,0,0,0.0142669677734375,33.2355842590332,6,1,1,20.9793128967285,0,20.3200084898207,90.0000076293945,1,0.0041789008533092,0.000145610257889692,0.0041792699757612,0.000145604979907846,0.979251682758331,0.986530721187592,30.7975425720215,0,30,4,200,-0.000666946056298912,-1.68232929706573,0.261649072170258,2,,,,,,,,,,,,,,,,
,3959122950.71583,28.9021739959717,1000.35467529297,,,6,,,,30.738023492992,,,100,,,,,,,,,,,,,,,,,,,,,,28.1762027740479,29.6148910522461,1000.35467529297,1000.35467529297,,,5.68654346466064,,1,0,0,0,0.000152587890625,32.7468223571777,2,1,1,29.6281452178955,0,28.8960956997342,90.0000076293945,1,0.00376213195154331,0.000131089664005149,0.0037626295339744,0.000131088214632764,0.978748083114624,0.987150251865387,30.8018760681152,0.188331335783005,30,4,200,-8.32942387205549E-5,-0.15516260266304,0.0200305115431547,2,,,,,,,,,,,,,,,,
,3959123054.10673,30.0009889602661,1000.35467529297,,,6,,,,30.738023492992,,,100,,,,,,,,,,,,,,,,,,,,,,29.9996566772461,30.0011367797852,1000.35467529297,1000.35467529297,,,5.72216796875,,1,0,0,0,0.000152587890625,33.2355842590332,1,1,1,30.0009937286377,0,30.0004240337171,90.0000076293945,1,0.00372325086966365,0.000129734016809141,0.00372392706575356,0.000129736224702085,0.979058384895325,0.989536583423614,30.8065872192383,0,30,4,200,-5.24692659382708E-5,-0.153208449482918,0.0190583318471909,2,,,,,,,,,,,,,,,,
,3959123152.89714,30.000636100769,1000.35467529297,,,6,,,,30.738023492992,,,100,,,,,,,,,,,,,,,,,,,,,,29.9994106292725,30.0009708404541,1000.35467529297,1000.35467529297,,,5.73839950561523,,1,0,0,0,0.000152587890625,33.2355842590332,1,1,1,30.0006237030029,0,30.0002464718289,90.0000076293945,1,0.00372307053530377,0.000129727651583462,0.00372385476861712,0.000129733354513933,0.979117810726166,0.989859104156494,30.8070316314697,0.185273438692093,30,4,200,-6.72682435833849E-5,-0.153298497200012,0.0189772117882967,2,,,,,,,,,,,,,,,,
,3959123256.21967,30.0005960464478,1000.35467529297,,,6,,,,30.738023492992,,,100,,,,,,,,,,,,,,,,,,,,,,29.9990081787109,30.0009574890137,1000.35467529297,1000.35467529297,,,5.74784755706787,,1,0,0,0,0.000152587890625,33.2355842590332,1,1,1,30.0003795623779,0,30.0000727971395,90.0000076293945,1,0.00372263079289479,0.000129712469984684,0.00372341884722847,0.000129717952945911,0.979028344154358,0.989945113658905,30.8076114654541,0.069673664867878,30,4,200,-5.42489506187849E-5,-0.153371199965477,0.0188874937593937,2,,,,,,,,,,,,,,,,
,3959123359.62816,30.0005292892456,1000.35467529297,,,6,,,,30.738023492992,,,100,,,,,,,,,,,,,,,,,,,,,,29.999002456665,30.0009632110596,1000.35467529297,1000.35467529297,,,5.75287866592407,,1,0,0,0,0.000152587890625,32.7468223571777,1,1,1,30.0003147125244,0,30.0000032848782,90.0000076293945,1,0.00372287372049185,0.000129721417165278,0.00372366743177243,0.000129726708116967,0.978883683681488,0.989939510822296,30.8082122802734,0,30,4,200,-4.54475011792965E-5,-0.153456136584282,0.0188055504113436,2,,,,,,,,,,,,,,,,
,3959123462.96611,30.0004863739014,1000.35467529297,,,6,,,,30.738023492992,,,100,,,,,,,,,,,,,,,,,,,,,,29.9994144439697,30.0010452270508,1000.35467529297,1000.35467529297,,,5.75673151016235,,1,0,0,0,7.62939453125E-5,32.7468223571777,1,1,1,30.0002059936523,0,30.0002040863037,90.0000076293945,1,0.00372295849638019,0.000129724430689814,0.00372377473951273,0.000129730448139545,0.978855788707733,0.98992532491684,30.8082675933838,0,30,4,200,-4.43439857917838E-5,-0.153541684150696,0.0187263898551464,2,,,,,,,,,,,,,,,,
,3959123566.27232,30.000581741333,1000.35467529297,,,6,,,,30.738023492992,,,100,,,,,,,,,,,,,,,,,,,,,,29.9988689422607,30.0011177062988,1000.35467529297,1000.35467529297,,,5.75825929641724,,1,0,0,0,0.000152587890625,33.2355842590332,1,1,1,30.0004577636719,0,30.0000455519732,90.0000076293945,1,0.00372295979417889,0.000129724697916359,0.00372380772422129,0.000129731614865994,0.978769958019257,0.989901125431061,30.8085975646973,,30,4,200,-4.52615386166144E-5,-0.153653457760811,0.0186322424560785,2,,,,,,,,,,,,,,,,
,3959123669.75719,30.0005226135254,1000.37896728516,,,6,,,,30.738023492992,,,100,,,,,,,,,,,,,,,,,,,,,,29.9990539550781,30.0010108947754,1000.37896728516,1000.37896728516,,,5.7601842880249,,1,0,0,0,0.000152587890625,33.2355842590332,1,1,1,30.0001049041748,0,30.0000976986355,90.0000076293945,1,0.00372325676010827,0.000129736429845024,0.00372411348419842,0.000129742066538928,0.978274762630463,0.990058362483978,30.8110446929932,0,30,4,200,-4.60659757663961E-5,-0.151708245277405,0.0205596592277288,2,,,,,,,,,,,,,,,,
,3959123773.43817,30.0004510879517,1000.37896728516,,,6,,,,30.738023492992,,,100,,,,,,,,,,,,,,,,,,,,,,29.9989833831787,30.0008125305176,1000.37896728516,1000.37896728516,,,5.76165533065796,,1,0,0,0,0.0142669677734375,33.2355842590332,1,1,1,30.0004253387451,0,29.9999176661174,-86.7504043579102,5,0.00368334593767093,0.000128333478517149,0.00368337575255416,0.000128333929943083,0.983249247074127,0.983524680137634,30.7494831085205,0,30,4,200,7.85108568379655E-6,-0.15192811191082,0.0200881566852331,2,,,,,,,,,,,,,,,,
,3959123876.63917,30.0005826950073,1000.37896728516,,,6,,,,30.738023492992,,,100,,,,,,,,,,,,,,,,,,,,,,29.9988574981689,30.0007762908936,1000.37896728516,1000.37896728516,,,5.76161479949951,,1,0,0,0,7.62939453125E-5,33.7243423461914,1,1,1,30.0004177093506,0,29.9999963860763,-196.656005859375,5,0.00355759215742112,0.000124379654096302,0.00356974737278712,0.0001244114221863,0.91547966003418,0.970708906650543,31.0414581298828,,30,4,200,-7.8436620242428E-5,-0.145736381411552,0.0180529151111841,2,,,,,,,,,,,,,,,,
,3959123979.24814,30.0006351470947,1000.37896728516,,,6,,,,30.738023492992,,,100,,,,,,,,,,,,,,,,,,,,,,29.9990482330322,30.0011196136475,1000.37896728516,1000.37896728516,,,5.76258325576782,,1,0,0,0,0.00030517578125,33.2355842590332,1,1,1,30.0002307891846,0,30.0001734683388,-291.408020019531,5,0.0037285155356179,0.000129907485184665,0.00372871834847269,0.000129910312768709,0.983110308647156,0.985166847705841,30.7685356140137,0.132093384861946,30,4,200,-0.000104488346551079,-0.15268437564373,0.0204601194709539,2,,,,,,,,,,,,,,,,
,3959124112.99221,30.0002746582031,1000.37896728516,,,6,,,,30.7452130966154,,,100,,,,,,,,,,,,,,,,,,,,,,29.9987258911133,30.0006217956543,1000.37896728516,1000.37896728516,,,5.76175355911255,,1,0,0,0,7.62939453125E-5,33.7243423461914,1,1,1,30.0002937316895,0,29.9996185302734,-295.996826171875,1,0.00369842490752426,0.000182230477550161,0.00369873064439279,0.000182230510776159,0.984413802623749,0.991168558597565,30.6966934204102,0,30,4,200,-6.9138863182161E-5,-0.151262387633324,0.0196851454675198,1,,,,,,,,,,,,,,,,
,3959124232.63983,30.0003128051758,1000.37896728516,,,6,,,,30.7452130966154,,,100,,,,,,,,,,,,,,,,,,,,,,29.9988555908203,30.0004482269287,1000.37896728516,1000.37896728516,,,5.76276445388794,,1,0,0,0,0,33.2355842590332,1,1,1,30.000431060791,0,29.9997315979004,-291.998413085937,1,0.0037028775507963,0.00010533843986495,0.00370316476772245,0.000105337570678002,0.983824968338013,0.990511417388916,30.6957206726074,,30,4,200,-1.5208634067676E-5,-0.151563718914986,0.0196538958698511,3,,,,,,,,,,,,,,,,
,3959124359.74092,30.0004386901855,1000.37896728516,,,6,,,,30.7452130966154,,,100,,,,,,,,,,,,,,,,,,,,,,29.9987182617188,30.0005664825439,1000.37896728516,1000.37896728516,,,5.76140213012695,,1,0,0,0,0.000152587890625,33.2355842590332,1,1,1,30.0005779266357,0,29.9997225867377,-285.998413085938,1,0.00371222196315729,0.000182915069293684,0.0037123651767779,0.000182906132757461,0.982827246189117,0.989042401313782,30.6952114105225,,30,4,200,-5.51826778973918E-5,-0.152088522911072,0.0196959879249334,1,,,,,,,,,,,,,,,,
,3959124484.98463,30.0003089904785,1000.37896728516,,,6,,,,30.7452130966154,,,100,,,,,,,,,,,,,,,,,,,,,,29.9988422393799,30.0007801055908,1000.37896728516,1000.37896728516,,,5.76270771026611,,1,0,0,0,0.0002288818359375,33.2355842590332,1,1,1,30.0001659393311,0,29.9999175752912,-281.995208740234,1,0.00371797102696977,0.000105767931615391,0.00371814743369583,0.000105766198152247,0.98375791311264,0.988331258296967,30.7025909423828,,30,4,200,-2.3402288206853E-5,-0.152463674545288,0.0196549445390701,3,,,,,,,,,,,,,,,,
,3959124610.1065,30.000337600708,1000.37896728516,,,6,,,,30.7452130966154,,,100,,,,,,,,,,,,,,,,,,,,,,29.9986972808838,30.000509262085,1000.37896728516,1000.37896728516,,,5.76278734207153,,1,0,0,0,0,33.2355842590332,1,1,1,30.0002689361572,0,29.9997942182753,-275.995208740234,1,0.00373015187579038,0.000183794232700548,0.00373021518524741,0.000183792830017696,0.984222233295441,0.985867023468018,30.7187442779541,0,30,4,200,-3.85093844670337E-5,-0.153114005923271,0.0197806544601917,1,,,,,,,,,,,,,,,,
,3959124729.32629,30.0004196166992,1000.37896728516,,,6,,,,30.7452130966154,,,100,,,,,,,,,,,,,,,,,,,,,,29.9989185333252,30.0007438659668,1000.37896728516,1000.37896728516,,,5.762451171875,,1,0,0,0,0.000152587890625,33.7243423461914,1,1,1,30.0005435943604,0,29.9999303084153,-271.996826171875,1,0.00373471851139146,0.000106242554778661,0.00373473944728802,0.000106242545922051,0.984858274459839,0.98523873090744,30.732494354248,0,30,4,200,-8.62456727190874E-5,-0.153430968523026,0.0197263564914465,3,,,,,,,,,,,,,,,,
,3959124851.40348,30.0005865097046,1000.37896728516,,,6,,,,30.7452130966154,,,100,,,,,,,,,,,,,,,,,,,,,,29.9989452362061,30.0009288787842,1000.37896728516,1000.37896728516,,,5.76156139373779,,1,0,0,0,0,33.2355842590332,1,1,1,30.0003433227539,0,29.9999027252197,-265.996826171875,1,0.00373583317855646,0.000184072420028053,0.00373587502761156,0.000184072927159696,0.984842956066132,0.985410749912262,30.7607040405273,0,30,4,200,-6.81574601912871E-5,-0.153602749109268,0.019572151824832,1,,,,,,,,,,,,,,,,
,3959124970.31198,30.0003051757812,1000.37896728516,,,6,,,,30.7452130966154,,,100,,,,,,,,,,,,,,,,,,,,,,29.9989185333252,30.0006771087646,1000.37896728516,1000.37896728516,,,5.76290035247803,,1,0,0,0,0,33.2355842590332,1,1,1,30.0002727508545,0,29.9998176281269,-261.998413085938,1,0.00373160875932969,0.000106156459204318,0.00373183529114299,0.000106157606296689,0.983423948287964,0.986771643161774,30.782922744751,8.51239310577512E-5,30,4,200,-5.61915294383652E-5,-0.153493419289589,0.0193954091519117,3,,,,,,,,,,,,,,,,
,3959125095.48454,30.0004606246948,1000.37896728516,,,6,,,,30.7452130966154,,,100,,,,,,,,,,,,,,,,,,,,,,29.9987087249756,30.0008869171143,1000.37896728516,1000.37896728516,,,5.76273441314697,,1,0,0,0,0.00030517578125,32.7468223571777,1,1,1,30.0002784729004,0,29.9998676300049,-255.998413085938,1,0.00372270057807132,0.000183443268781072,0.00372347807040174,0.000183452643267825,0.979389071464539,0.989538729190826,30.8123474121094,0,30,4,200,-2.75714810413774E-5,-0.153187915682793,0.0190981812775135,1,,,,,,,,,,,,,,,,
,3959125221.31738,30.0004272460937,1000.37896728516,,,6,,,,30.7452130966154,,,100,,,,,,,,,,,,,,,,,,,,,,29.9986324310303,30.0008811950684,1000.37896728516,1000.37896728516,,,5.76258230209351,,1,0,0,0,0.0002288818359375,33.7243423461914,1,1,1,30.0004901885986,0,29.9998544965472,-251.995208740234,1,0.003716926760064,0.000105750478127106,0.00371796115390479,0.000105757337425164,0.977739214897156,0.991700828075409,30.8232479095459,0,30,4,200,-5.29977041878738E-5,-0.152966991066933,0.0189026780426502,3,,,,,,,,,,,,,,,,
,3959125349.24061,30.0001392364502,1000.37896728516,,,6,,,,30.7452130966154,,,100,,,,,,,,,,,,,,,,,,,,,,29.998498916626,30.0008106231689,1000.37896728516,1000.37896728516,,,5.76258659362793,,1,0,0,0,0.000152587890625,33.2355842590332,1,1,1,29.9999141693115,0,29.9996412065294,-245.995208740234,1,0.00370854205356813,0.000182763550768276,0.00370982170597416,0.000182773232453685,0.97506982088089,0.99386328458786,30.83664894104,0,30,4,200,-5.24053284607362E-5,-0.152657702565193,0.01861322671175,1,,,,,,,,,,,,,,,,
,3959125471.61773,30.0002565383911,1000.37896728516,,,6,,,,30.7452130966154,,,100,,,,,,,,,,,,,,,,,,,,,,29.9985237121582,30.0005397796631,1000.37896728516,1000.37896728516,,,5.76290798187256,,1,0,0,0,0,33.2355842590332,1,1,1,30.000394821167,0,29.9996940906231,-241.996810913086,1,0.00370125418407445,0.000105318869011405,0.00370275554132624,0.000105322782147725,0.972327589988708,0.994590699672699,30.8479843139648,5.55409622192383,30,4,200,-5.08648809045553E-5,-0.152405887842178,0.0184009484946728,3,,,,,,,,,,,,,,,,
,3959125593.64327,30.0000905990601,1000.37896728516,,,6,,,,30.7452130966154,,,100,,,,,,,,,,,,,,,,,,,,,,29.9983787536621,30.0002841949463,1000.37896728516,1000.37896728516,,,5.76215219497681,,1,0,0,0,0,33.2355842590332,1,1,1,29.9999942779541,0,29.9994292789035,-235.996810913086,1,0.00368350707414704,0.00018158009802694,0.00368566234415133,0.000181583590283877,0.96571671962738,0.993320822715759,30.8726024627686,1.37764152441378E-6,30,4,200,-8.51425429573283E-5,-0.151739627122879,0.0179918613284826,1,,,,,,,,,,,,,,,,
,3959125712.48543,30.0005111694336,1000.37896728516,,,6,,,,30.7452130966154,,,100,,,,,,,,,,,,,,,,,,,,,,29.9989967346191,30.0006465911865,1000.37896728516,1000.37896728516,,,5.76265048980713,,1,0,0,0,0,33.2355842590332,1,1,1,30.0006446838379,0,29.9999128488394,-231.998413085938,1,0.00366784015427388,0.000104408808738911,0.00367068684696469,0.000104413450507455,0.960681557655335,0.990812838077545,30.8903713226318,6.57805139780976E-6,30,4,200,-5.05557072756346E-5,-0.151161342859268,0.0176834221929312,3,,,,,,,,,,,,,,,,
,3959125835.57796,30.0006532669067,1000.37896728516,,,6,,,,30.7452130966154,,,100,,,,,,,,,,,,,,,,,,,,,,29.9989166259766,30.0005970001221,1000.37896728516,1000.37896728516,,,5.76185846328735,,1,0,0,0,0.000152587890625,32.7468223571777,1,1,1,30.0009574890137,0,29.9997342427572,-225.998413085938,1,0.00364411534508203,0.000179727402563427,0.00364825178435956,0.000179754885200177,0.953466415405273,0.985696494579315,30.9137592315674,5.56001424789429,30,4,200,1.28274791677541E-6,-0.15026818215847,0.0172235574573278,1,,,,,,,,,,,,,,,,
,3959125960.61453,30.0005512237549,1000.37896728516,,,6,,,,30.7452130966154,,,100,,,,,,,,,,,,,,,,,,,,,,29.998872756958,30.0010414123535,1000.37896728516,1000.37896728516,,,5.7625298500061,,1,0,0,0,0.00030517578125,33.7243423461914,1,1,1,30.0005435943604,0,29.9999735090468,-221.995208740234,1,0.00362923299945412,0.000103357738738615,0.00363408547776682,0.000103383216714085,0.950284063816071,0.982815265655518,30.9232578277588,0,30,4,200,-3.0821352993371E-5,-0.149707779288292,0.0169490072876215,3,,,,,,,,,,,,,,,,
,3959126088.44131,30.0005588531494,1000.37896728516,,,6,,,,30.7452130966154,,,100,,,,,,,,,,,,,,,,,,,,,,29.9988784790039,30.0006561279297,1000.37896728516,1000.37896728516,,,5.76228904724121,,1,0,0,0,7.62939453125E-5,34.2131004333496,1,1,1,30.0006847381592,0,29.9998993343777,-215.995208740234,1,0.00361857094911146,0.000178517974657701,0.00362337786468374,0.000178546415933485,0.947758853435516,0.980091154575348,30.9293384552002,0,30,4,200,-1.84235723281745E-5,-0.149324044585228,0.0166716184467077,1,,,,,,,,,,,,,,,,
,3959126211.70968,30.00071144104,1000.37896728516,,,6,,,,30.7452130966154,,,100,,,,,,,,,,,,,,,,,,,,,,29.998987197876,30.0008430480957,1000.37896728516,1000.37896728516,,,5.76231384277344,,1,0,0,0,0.000152587890625,31.7693061828613,1,1,1,30.0008792877197,0,30.000146512632,-211.996810913086,1,0.00361009962910217,0.00010283923607771,0.00361507708015324,0.000102851899651063,0.945374965667725,0.978116512298584,30.9363784790039,0,30,4,200,-1.60364579642192E-5,-0.149068385362625,0.0164517909288406,3,,,,,,,,,,,,,,,,
,3959126334.23775,30.0001220703125,1000.37896728516,,,6,,,,30.7452130966154,,,100,,,,,,,,,,,,,,,,,,,,,,29.9987277984619,30.0005512237549,1000.37896728516,1000.37896728516,,,5.76184034347534,,1,0,0,0,0,33.2355842590332,1,1,1,30.0000419616699,0,29.9995755089654,-205.996810913086,1,0.00359666506965767,0.000177512484278531,0.00360216941333215,0.000177521150143126,0.940214157104492,0.975105702877045,30.9527797698975,0,30,4,200,-4.13211673730984E-5,-0.148635923862457,0.016158252954483,1,,,,,,,,,,,,,,,,
,3959126453.12681,30.0004930496216,1000.37896728516,,,6,,,,30.7452130966154,,,100,,,,,,,,,,,,,,,,,,,,,,29.9990673065186,30.0008544921875,1000.37896728516,1000.37896728516,,,5.76226949691772,,1,0,0,0,0,33.2355842590332,1,1,1,30.0006008148193,0,29.9999542969924,-201.998413085938,1,0.00358409812427152,0.000102154359713717,0.003590478030892,0.000102164847322379,0.936177909374237,0.972987473011017,30.9662227630615,0,30,4,200,-5.08624616486486E-5,-0.148284986615181,0.0159252546727657,3,,,,,,,,,,,,,,,,
,3959126575.89107,30.0001735687256,1000.37896728516,,,6,,,,30.7452130966154,,,100,,,,,,,,,,,,,,,,,,,,,,29.9985198974609,30.000280380249,1000.37896728516,1000.37896728516,,,5.76263666152954,,1,0,0,0,7.62939453125E-5,34.7018585205078,1,1,1,30.0000667572022,0,29.9995124816895,-195.998413085938,1,0.00356603134563359,0.00017610936955933,0.00357369881766214,0.000176141569879084,0.930684804916382,0.970238149166107,30.9849319458008,5.56641101837158,30,4,200,-1.85063599928981E-5,-0.147784501314163,0.0155805423855782,1,,,,,,,,,,,,,,,,
,3959126700.29588,30.0002403259277,1000.37896728516,,,6,,,,30.7452130966154,,,100,,,,,,,,,,,,,,,,,,,,,,29.9986782073975,30.0008926391602,1000.37896728516,1000.37896728516,,,5.76309728622437,,1,0,0,0,0.000152587890625,32.2580642700195,1,1,1,30.0005588531494,0,29.9999645096915,-192.000015258789,1,0.00355960441244246,0.000101507099290375,0.00356785760771529,0.000101531996645101,0.9287890791893,0.969305217266083,30.9915084838867,0,30,4,200,-3.03403448924655E-5,-0.147674262523651,0.0154268760234118,3,,,,,,,,,,,,,,,,
,3959126828.77765,30.0004682540894,1000.37896728516,,,6,,,,30.7452130966154,,,100,,,,,,,,,,,,,,,,,,,,,,29.998514175415,30.0007781982422,1000.37896728516,1000.37896728516,,,5.76179456710815,,1,0,0,0,0.0002288818359375,33.2355842590332,1,1,1,30.0001583099365,0,29.9995649337769,-186.000015258789,1,0.00355775931693349,0.000175737555390048,0.00356622940196002,0.000175777010627952,0.927746534347534,0.969553887844086,30.99587059021,0,30,4,200,-2.2469570467365E-5,-0.147700518369675,0.0153307989239693,1,,,,,,,,,,,,,,,,
,3959126952.79718,30.000283241272,1000.37896728516,,,6,,,,30.7452130966154,,,100,,,,,,,,,,,,,,,,,,,,,,29.9990558624268,30.0010414123535,1000.37896728516,1000.37896728516,,,5.76241397857666,,1,0,0,0,0,33.2355842590332,1,1,1,30.0001373291016,0,30.000038419451,-181.996810913086,1,0.00356357911236707,0.000101630651712044,0.00357219234758315,0.000101650838048663,0.927401840686798,0.970792591571808,30.999813079834,0,30,4,200,-1.75675882019277E-6,-0.148000255227089,0.0154549181461334,3,,,,,,,,,,,,,,,,
,3959127074.29616,30.0002593994141,1000.37896728516,,,6,,,,30.7452130966154,,,100,,,,,,,,,,,,,,,,,,,,,,29.9986209869385,30.0003528594971,1000.37896728516,1000.37896728516,,,5.76201725006103,,1,0,0,0,0,33.2355842590332,1,1,1,30.0002784729004,0,29.99968846639,-175.996810913086,1,0.0035691686239869,0.000176327166992119,0.00357810357788617,0.000176347799272802,0.925739169120789,0.972374558448792,31.0087776184082,0,30,4,200,-4.8783822421683E-5,-0.148349165916443,0.0154988272115588,1,,,,,,,,,,,,,,,,
,3959127193.24195,30.0002355575562,1000.37896728516,,,6,,,,30.7452130966154,,,100,,,,,,,,,,,,,,,,,,,,,,29.9986000061035,30.0007133483887,1000.37896728516,1000.37896728516,,,5.76221752166748,,1,0,0,0,0,33.2355842590332,1,1,1,30.0003051757812,0,29.9997747802734,-171.998413085938,1,0.0035705374534408,0.000101849854443805,0.00357984243257706,0.000101860991658163,0.924658060073853,0.973434805870056,31.0146350860596,1.14733520604204E-5,30,4,200,-5.90371564612724E-5,-0.148541688919067,0.0154594024643302,3,,,,,,,,,,,,,,,,
,3959127315.45604,30.0005550384521,1000.37896728516,,,6,,,,30.7452130966154,,,100,,,,,,,,,,,,,,,,,,,,,,29.9990196228027,30.0005531311035,1000.37896728516,1000.37896728516,,,5.76198673248291,,1,0,0,0,0,33.2355842590332,1,1,1,30.0005855560303,0,29.9999406602648,-165.998413085938,1,0.0035713071394157,0.000176456188942758,0.0035813073988081,0.000176492487588166,0.923990845680237,0.975244760513306,31.0197887420654,0,30,4,200,-5.29591779923066E-5,-0.14879284799099,0.0153722381219268,1,,,,,,,,,,,,,,,,
,3959127436.85828,30.0005588531494,1000.37896728516,,,6,,,,30.7452130966154,,,100,,,,,,,,,,,,,,,,,,,,,,29.9990139007568,30.0007781982422,1000.37896728516,1000.37896728516,,,5.7630352973938,,1,0,0,0,0.0116729736328125,33.2355842590332,1,1,1,30.000846862793,0,30.0000792283278,-162.000015258789,1,0.00357703136927739,0.000102038184206447,0.00358766176177731,0.000102073790941742,0.924265265464783,0.97730565071106,31.0213298797607,0,30,4,200,-1.24113921629032E-5,-0.149201452732086,0.0153895802795887,3,,,,,,,,,,,,,,,,
,3959127564.60767,30.0003004074097,1000.37896728516,,,6,,,,30.7452130966154,,,100,,,,,,,,,,,,,,,,,,,,,,29.9986171722412,30.0006084442139,1000.37896728516,1000.37896728516,,,5.76196908950806,,1,0,0,0,0.00030517578125,32.7468223571777,1,1,1,30.0001945495605,0,29.999656867981,-155.995208740234,1,0.00358932676143654,0.000177313406135303,0.00359934269334785,0.000177359965465005,0.926470279693603,0.980683386325836,31.0154647827148,4.14881251344923E-5,30,4,200,-5.74370606045704E-5,-0.149773746728897,0.0155075406655669,1,,,,,,,,,,,,,,,,
,3959127690.58196,30.0002965927124,1000.37896728516,,,6,,,,30.7452130966154,,,100,,,,,,,,,,,,,,,,,,,,,,29.9991893768311,30.0008773803711,1000.37896728516,1000.37896728516,,,5.76291847229004,,1,0,0,0,0.000152587890625,33.7243423461914,1,1,1,30.0004196166992,0,30.0000274799488,-151.996810913086,1,0.00360866625125118,0.000102916308859794,0.00361880337770796,0.000102945840913483,0.92741847038269,0.984332919120789,31.0153045654297,,30,4,200,3.23353310704988E-6,-0.150641813874245,0.0158117804676294,3,,,,,,,,,,,,,,,,
,3959127816.80963,30.0002269744873,1000.37896728516,,,6,,,,30.7452130966154,,,100,,,,,,,,,,,,,,,,,,,,,,29.9986743927002,30.0004024505615,1000.37896728516,1000.37896728516,,,5.76227331161499,,1,0,0,0,0,34.7018585205078,1,1,1,30.0001811981201,0,29.9996621873644,-145.996810913086,1,0.00362914888654318,0.000179247777370179,0.00363855354159943,0.000179271464106972,0.928997337818146,0.98807293176651,31.0112724304199,0.0697943493723869,30,4,200,-6.83870312059298E-5,-0.151625037193298,0.015995305031538,1,,,,,,,,,,,,,,,,
,3959127935.6401,30.0002908706665,1000.37896728516,,,6,,,,30.7452130966154,,,100,,,,,,,,,,,,,,,,,,,,,,29.9989967346191,30.0008354187012,1000.37896728516,1000.37896728516,,,5.76320266723633,,1,0,0,0,0,33.2355842590332,1,1,1,30.000545501709,0,29.9999160003662,-141.998413085938,1,0.00364162460982716,0.000103835829177723,0.00365079459602032,0.000103848141310825,0.930176973342895,0.990282475948334,31.0076427459717,9.26454067230225,30,4,200,-5.84645749768242E-5,-0.152261137962341,0.0160616375505924,3,,,,,,,,,,,,,,,,
,3959128057.94612,30.0001668930054,1000.37896728516,,,6,,,,30.7452130966154,,,100,,,,,,,,,,,,,,,,,,,,,,29.9985580444336,30.0007152557373,1000.37896728516,1000.37896728516,,,5.76195621490479,,1,0,0,0,0,33.2355842590332,1,1,1,29.9999446868897,0,29.9995844099257,-135.998413085938,1,0.00365254128223499,0.000180368597988543,0.0036614618576774,0.000180392132007685,0.931735634803772,0.992704927921295,31.0026435852051,0.183452010154724,30,4,200,-5.18607739650179E-5,-0.152899235486984,0.0160327702760696,1,,,,,,,,,,,,,,,,
,3959128178.93239,30.000524520874,1000.37896728516,,,6,,,,30.7452130966154,,,100,,,,,,,,,,,,,,,,,,,,,,29.9988956451416,30.0010013580322,1000.37896728516,1000.37896728516,,,5.76229763031006,,1,0,0,0,7.62939453125E-5,32.7468223571777,1,1,1,30.0007400512695,0,30.000052520207,-131.995208740234,1,0.00366192619918466,0.000104389221178703,0.00367073227136759,0.000104412664797106,0.933741867542267,0.993280172348022,30.9951953887939,5.56733274459839,30,4,200,-2.60428223555209E-5,-0.15340282022953,0.0160766504704952,3,,,,,,,,,,,,,,,,
,3959128306.5968,30.000186920166,1000.37896728516,,,6,,,,30.7452130966154,,,100,,,,,,,,,,,,,,,,,,,,,,29.9984664916992,30.0005550384521,1000.37896728516,1000.37896728516,,,5.76164817810059,,1,0,0,0,0.00030517578125,33.2355842590332,1,1,1,29.9999618530273,0,29.9995649337769,-125.995208740234,1,0.0036787037188278,0.000181592811217126,0.00368675890872183,0.000181639125097057,0.937408626079559,0.992201566696167,30.9802894592285,5.56599426269531,30,4,200,-2.22474682232132E-5,-0.154202595353127,0.0162025019526482,1,,,,,,,,,,,,,,,,
,3959128432.81738,30.0003128051758,1000.37896728516,,,6,,,,30.7452130966154,,,100,,,,,,,,,,,,,,,,,,,,,,29.9988479614258,30.0007457733154,1000.37896728516,1000.37896728516,,,5.76285457611084,,1,0,0,0,0.0002288818359375,33.2355842590332,1,1,1,30.0007209777832,0,29.9999288629602,-121.996803283691,1,0.00369244206967171,0.000105210069467698,0.00369941024559928,0.000105230866275003,0.941171705722809,0.990443348884583,30.9645595550537,9.26947498321533,30,4,200,-1.77373240148881E-5,-0.154828354716301,0.0162566863000393,3,,,,,,,,,,,,,,,,
,3959128559.02955,30.0003976821899,1000.37896728516,,,6,,,,30.7452130966154,,,100,,,,,,,,,,,,,,,,,,,,,,29.998722076416,30.000825881958,1000.37896728516,1000.37896728516,,,5.76096439361572,,1,0,0,0,0,32.7468223571777,1,1,1,30.0001964569092,0,29.9997848934597,-115.996803283691,1,0.0037167634500215,0.000183390677437675,0.00372254603303465,0.000183413395561647,0.944877564907074,0.986523032188415,30.9470653533936,0,30,4,200,-3.24927968904376E-5,-0.155920401215553,0.0164890307933092,1,,,,,,,,,,,,,,,,
,3959128679.7058,30.0002508163452,1000.37896728516,,,6,,,,30.7452130966154,,,100,,,,,,,,,,,,,,,,,,,,,,29.9993267059326,30.0008296966553,1000.37896728516,1000.37896728516,,,5.76308727264404,,1,0,0,0,0,32.7468223571777,1,1,1,30.0006656646729,0,30.0000873712393,-111.998405456543,1,0.00372868074849186,0.000106199599662471,0.00373340959661676,0.000106205640932587,0.948483884334564,0.984627544879913,30.9306526184082,0,30,4,200,-2.63998663285747E-5,-0.156491532921791,0.0165203083306551,3,,,,,,,,,,,,,,,,
,3959128802.62513,30.0001068115234,1000.37896728516,,,6,,,,30.7452130966154,,,100,,,,,,,,,,,,,,,,,,,,,,29.9988307952881,30.0006198883057,1000.37896728516,1000.37896728516,,,5.76202917098999,,1,0,0,0,0,33.2355842590332,1,1,1,29.9999027252197,0,29.9996899498834,-105.998405456543,1,0.00373174040638077,0.000184038424943654,0.0037353594215554,0.000184050901599372,0.954712867736816,0.98419064283371,30.9052886962891,5.55925273895264,30,4,200,-3.51682101609185E-5,-0.156718596816063,0.0163221936672926,1,,,,,,,,,,,,,,,,
,3959128921.5972,30.0004291534424,1000.37896728516,,,6,,,,30.7452130966154,,,100,,,,,,,,,,,,,,,,,,,,,,29.9990749359131,30.0008640289307,1000.37896728516,1000.37896728516,,,5.76254653930664,,1,0,0,0,0,33.2355842590332,1,1,1,30.0006370544434,0,30.0000264828022,-101.99520111084,1,0.00372938061683928,0.000106163724350623,0.0037322356164485,0.000106171754315593,0.959940910339356,0.984941303730011,30.8853092193604,INF,30,4,200,-3.87371583201457E-5,-0.156664296984673,0.0161449406296015,3,,,,,,,,,,,,,,,,
,3959129047.66327,30.0002689361572,1000.37896728516,,,6,,,,30.7452130966154,,,100,,,,,,,,,,,,,,,,,,,,,,29.9986610412598,30.0005779266357,1000.37896728516,1000.37896728516,,,5.76164102554321,,1,0,0,0,0.0002288818359375,33.2355842590332,1,1,1,30.0001430511475,0,29.9997383117676,-96.0000076293945,1,0.00373001251294393,0.000183866512401199,0.00373215750240404,0.000183889418139238,0.966695666313171,0.985539078712463,30.8586254119873,2.63636957242852E-5,30,4,200,-1.93044033949263E-5,-0.15670482814312,0.0159786436706781,1,,,,,,,,,,,,,,,,
,3959129172.67806,30.0004072189331,1000.37896728516,,,6,,,,30.7452130966154,,,100,,,,,,,,,,,,,,,,,,,,,,29.9988918304443,30.0010070800781,1000.37896728516,1000.37896728516,,,5.76222896575928,,1,0,0,0,0.000152587890625,33.2355842590332,1,1,1,30.0005569458008,0,29.9999526694969,-91.9968032836914,1,0.00372744020930074,0.000106065410353772,0.00372884554207787,0.000106072484119675,0.971820592880249,0.986814558506012,30.8391532897949,1.94633212231565E-5,30,4,200,-2.89657309622271E-5,-0.156626775860786,0.0158188473433256,3,,,,,,,,,,,,,,,,
,3959129300.40455,30.0003519058228,1000.37896728516,,,6,,,,30.7452130966154,,,100,,,,,,,,,,,,,,,,,,,,,,29.9988193511963,30.0006275177002,1000.37896728516,1000.37896728516,,,5.76231718063354,,1,0,0,0,0,32.7468223571777,1,1,1,30.0002460479736,0,29.9998185899523,-85.9968032836914,1,0.0037425147620603,0.000184429419998449,0.00374327130385011,0.000184435882420437,0.97696042060852,0.98597264289856,30.8142528533936,0,30,4,200,3.45726948580705E-5,-0.157252594828606,0.0158357918262482,1,,,,,,,,,,,,,,,,
,3959129422.55437,30.0004816055298,1000.37896728516,,,6,,,,30.7452130966154,,,100,,,,,,,,,,,,,,,,,,,,,,29.9990615844727,30.0009727478027,1000.37896728516,1000.37896728516,,,5.76162767410278,,1,0,0,0,0.000152587890625,32.7468223571777,1,1,1,30.0007286071777,0,30.0000854774758,-81.998405456543,1,0.00374039410368203,0.000106410703487131,0.00374078711747397,0.000106411351032827,0.98115348815918,0.987458944320679,30.7983283996582,0,30,4,200,-3.84166423827992E-6,-0.157166838645935,0.0157047174870968,3,,,,,,,,,,,,,,,,
,3959129544.96277,30.0000095367432,1000.37896728516,,,6,,,,30.7452130966154,,,100,,,,,,,,,,,,,,,,,,,,,,29.9986324310303,30.0005054473877,1000.37896728516,1000.37896728516,,,5.76213550567627,,1,0,0,0,0.000152587890625,33.2355842590332,1,1,1,29.9998016357422,0,29.9995511372884,-75.998405456543,1,0.0037254249844303,0.000183551653090667,0.00372557594589381,0.000183553018619328,0.988020479679108,0.991204977035522,30.7759456634521,5.547607421875,30,4,200,-3.52538881998044E-5,-0.156559705734253,0.0153587562963366,1,,,,,,,,,,,,,,,,
,3959129663.88445,30.0005016326904,1000.37896728516,,,6,,,,30.7452130966154,,,100,,,,,,,,,,,,,,,,,,,,,,29.9987812042236,30.0008220672607,1000.37896728516,1000.37896728516,,,5.76335859298706,,1,0,0,0,0,33.7243423461914,1,1,1,30.0008926391602,0,30.0000013938317,-71.9952011108398,1,0.00370931830810554,0.000105510443260739,0.00370935901266534,0.000105510777430336,0.993076622486115,0.994314849376679,30.7601699829102,0,30,4,200,-3.54906733264215E-5,-0.155925065279007,0.0150619251653552,3,,,,,,,,,,,,,,,,
,3959129788.39693,30.0002908706665,1000.37896728516,,,6,,,,30.7452130966154,,,100,,,,,,,,,,,,,,,,,,,,,,29.9988689422607,30.0006999969482,1000.37896728516,1000.37896728516,,,5.76232051849365,,1,0,0,0,7.62939453125E-5,32.7468223571777,1,1,1,30.0002098083496,0,29.9997611575656,-65.9952011108398,1,0.00368706189000842,0.000181651705588127,0.00368704498750619,0.000181650295849849,0.994028091430664,0.994586050510407,30.7356433868408,0,30,4,200,-2.77896670013433E-5,-0.155039221048355,0.0146289393305778,1,,,,,,,,,,,,,,,,
,3959129912.24843,30.0002489089966,1000.37896728516,,,6,,,,30.7452130966154,,,100,,,,,,,,,,,,,,,,,,,,,,29.9988651275635,30.0008392333984,1000.37896728516,1000.37896728516,,,5.76295900344849,,1,0,0,0,0.00030517578125,33.7243423461914,1,1,1,30.0003700256348,0,29.9999812797264,-61.9968032836914,1,0.00367850945405237,0.000104635479269265,0.00367852032908742,0.000104633696431746,0.991277277469635,0.993991851806641,30.7212085723877,1.50399728227057E-5,30,4,200,-3.41199520335067E-5,-0.154703125357628,0.014445697888732,3,,,,,,,,,,,,,,,,
,3959130039.64167,30.0005102157593,1000.37896728516,,,6,,,,30.7452130966154,,,100,,,,,,,,,,,,,,,,,,,,,,29.9990272521973,30.0006217956543,1000.37896728516,1000.37896728516,,,5.76265811920166,,1,0,0,0,0.000152587890625,33.2355842590332,1,1,1,30.0005760192871,0,29.9999008178711,-55.9968032836914,1,0.00367190849436321,0.000180923856757766,0.0036721251150143,0.000180919860414936,0.984446704387665,0.991068661212921,30.6968002319336,0.186854720115662,30,4,200,2.88034225377487E-5,-0.154438033699989,0.0254861265420914,1,,,,,,,,,,,,,,,,
,3959130161.64104,30.0002384185791,1000.37896728516,,,6,,,,30.7452130966154,,,100,,,,,,,,,,,,,,,,,,,,,,29.9989814758301,30.0010452270508,1000.37896728516,1000.37896728516,,,5.76181173324585,,1,0,0,0,7.62939453125E-5,33.2355842590332,1,1,1,30.0001583099365,0,29.9999788072374,-51.9984016418457,1,0.00366162619005085,0.000104171402627574,0.0036620450767476,0.000104170284705692,0.980347514152527,0.988336503505707,30.6850433349609,0,30,4,200,-4.00439603254199E-5,-0.154056996107101,0.025298910215497,3,,,,,,,,,,,,,,,,
,3959130287.40978,30.0002746582031,1000.37896728516,,,6,,,,30.7452130966154,,,100,,,,,,,,,,,,,,,,,,,,,,29.9988555908203,30.0005798339844,1000.37896728516,1000.37896728516,,,5.76280784606934,,1,0,0,0,0,33.2355842590332,1,1,1,30.0001602172852,0,29.9998392105103,-45.9984016418457,1,0.00364288536976644,0.000179531322639424,0.00364361569296041,0.000179532065948828,0.974302172660828,0.983631670475006,30.6697959899902,0,30,4,200,-3.54982294084039E-5,-0.153357997536659,0.0249702334403992,1,,,,,,,,,,,,,,,,
,3959130408.58643,30.0002822875977,1000.37896728516,,,6,,,,30.7452130966154,,,100,,,,,,,,,,,,,,,,,,,,,,29.9988346099854,30.0007705688477,1000.37896728516,1000.37896728516,,,5.76285028457642,,1,0,0,0,0,33.2355842590332,1,1,1,30.0002975463867,0,29.999916443458,-42.0000038146973,1,0.00362397362912771,0.000103126160649726,0.00362484534194865,0.000103125950286835,0.970200896263123,0.979920268058777,30.6612319946289,1.18210343489943E-38,30,4,200,-2.63761794485617E-5,-0.152681991457939,0.0246894955635071,3,,,,,,,,,,,,,,,,
,3959130530.79037,30.0001735687256,1000.37896728516,,,6,,,,30.7452130966154,,,100,,,,,,,,,,,,,,,,,,,,,,29.9984874725342,30.0004959106445,1000.37896728516,1000.37896728516,,,5.76301336288452,,1,0,0,0,7.62939453125E-5,33.2355842590332,1,1,1,30.0001220703125,0,29.9995562235514,-35.9952011108398,1,0.00360104416640817,0.000177523051991274,0.00360203733678847,0.000177513896428913,0.964427649974823,0.975274860858917,30.647439956665,,30,4,200,-4.45181140094064E-5,-0.15185073018074,0.0243188962340355,1,,,,,,,,,,,,,,,,
,3959130654.4842,30.0006484985352,1000.37896728516,,,6,,,,30.7452130966154,,,100,,,,,,,,,,,,,,,,,,,,,,29.9990234375,30.0010356903076,1000.37896728516,1000.37896728516,,,5.76345062255859,,1,0,0,0,0.000152587890625,33.2355842590332,1,1,1,30.0007629394531,0,30.0002290937636,-31.9968013763428,1,0.00358973950062875,0.000102184147879946,0.0035908285549862,0.00010217447653429,0.961046099662781,0.973123848438263,30.637149810791,5.53508377075195,30,4,200,1.72256040968932E-5,-0.151464983820915,0.024102333933115,3,,,,,,,,,,,,,,,,
,3959130782.89266,30.0002670288086,1000.37896728516,,,6,,,,30.7452130966154,,,100,,,,,,,,,,,,,,,,,,,,,,29.9987049102783,30.0009021759033,1000.37896728516,1000.37896728516,,,5.76263952255249,,1,0,0,0,0.0002288818359375,34.2131004333496,1,1,1,30.0001411437988,0,29.9998701095581,-25.9968013763428,1,0.00358724268012656,0.000176891255100846,0.00358899176775754,0.000176884310044174,0.957408487796783,0.972396790981293,30.6211795806885,0,30,4,200,-3.15848519676365E-5,-0.151452660560608,0.0240155942738056,1,,,,,,,,,,,,,,,,
,3959130906.61485,30.0002632141113,1000.37896728516,,,6,,,,30.7452130966154,,,100,,,,,,,,,,,,,,,,,,,,,,29.9987926483154,30.0010509490967,1000.37896728516,1000.37896728516,,,5.76395273208618,,1,0,0,0,0.0142669677734375,33.2355842590332,1,1,1,30.0003719329834,0,29.9999782420971,-21.9984016418457,1,0.00358428303010308,0.000102053458844503,0.00358639927116616,0.000102052247284801,0.955286681652069,0.971773684024811,30.6124496459961,0.0643637552857399,30,4,200,3.26430949826317E-6,-0.15138928592205,0.0239654127508402,3,,,,,,,,,,,,,,,,
,3959131034.07155,30.0001058578491,1000.37896728516,,,6,,,,30.7452130966154,,,100,,,,,,,,,,,,,,,,,,,,,,29.9987869262695,30.0001945495605,1000.37896728516,1000.37896728516,,,5.7626166343689,,1,0,0,0,0,33.2355842590332,1,1,1,30.0001811981201,0,29.9996185302734,-15.9984006881714,1,0.00357890482143542,0.000176514431525616,0.00358147066283697,0.00017652051032676,0.953075528144836,0.971025884151459,30.6041069030762,0,30,4,200,-3.11361691274215E-5,-0.151317954063416,0.0237968731671572,1,,,,,,,,,,,,,,,,
,3959131153.95428,30.0004510879517,1000.37896728516,,,6,,,,30.7452130966154,,,100,,,,,,,,,,,,,,,,,,,,,,29.9991645812988,30.0008659362793,1000.37896728516,1000.37896728516,,,5.76328182220459,,1,0,0,0,0,33.7243423461914,1,1,1,30.0005340576172,0,29.9999904632568,-12.0000009536743,1,0.00357289282033494,0.000101744355177252,0.00357549368960851,0.000101745704298583,0.95206892490387,0.970490515232086,30.6006927490234,0,30,4,200,-2.95773606922012E-5,-0.15116623044014,0.023672953248024,3,,,,,,,,,,,,,,,,
,3959131276.80945,30.0005254745483,1000.37896728516,,,6,,,,30.7452130966154,,,100,,,,,,,,,,,,,,,,,,,,,,29.9987754821777,30.0006332397461,1000.37896728516,1000.37896728516,,,5.76318883895874,,1,0,0,0,0.000152587890625,33.7243423461914,1,1,1,30.0006771087646,0,29.9998306274414,-6.00000047683716,1,0.0035661730345074,0.000175903467053938,0.00356874481020781,0.000175896705919808,0.951064765453339,0.970360934734344,30.5961093902588,,30,4,200,-3.88267835660372E-5,-0.151017397642136,0.0234823599457741,1,,,,,,,,,,,,,,,,
,3959131399.48513,30.0003137588501,1000.37896728516,,,6,,,,30.7452130966154,,,100,,,,,,,,,,,,,,,,,,,,,,29.9988574981689,30.00071144104,1000.37896728516,1000.37896728516,,,5.76302814483643,,1,0,0,0,0.016326904296875,35.6793746948242,1,1,1,30.0004062652588,0,29.9998579819997,-1.99680006504059,1,0.00356717141626891,0.000101586923626035,0.00356965106168204,0.000101577445868069,0.950946927070618,0.971149027347565,30.593053817749,5.53109884262085,30,4,200,-1.49756465361861E-6,-0.151113852858543,0.0234562195837498,3,,,,,,,,,,,,,,,,
,3959131527.60491,30.0004606246948,1000.37896728516,,,6,,,,30.7452130966154,,,100,,,,,,,,,,,,,,,,,,,,,,29.998779296875,30.0007724761963,1000.37896728516,1000.37896728516,,,5.76265525817871,,1,0,0,0,0.00030517578125,33.7243423461914,1,1,1,30.0004272460937,0,29.9999082565308,3.99840021133423,1,0.00357344996672486,0.000176267226696128,0.00357637890511353,0.000176257882638999,0.95052033662796,0.973422586917877,30.5858192443848,1.22246437967988E-5,30,4,200,-4.11854889534879E-5,-0.151470512151718,0.023448271676898,1,,,,,,,,,,,,,,,,
,3959131651.19439,30.0004968643188,1000.37896728516,,,6,,,,30.7452130966154,,,100,,,,,,,,,,,,,,,,,,,,,,29.9990558624268,30.0008430480957,1000.37896728516,1000.37896728516,,,5.76370143890381,,1,0,0,0,0.000152587890625,33.2355842590332,1,1,1,30.0006275177002,0,30.0000389946832,7.99680042266846,1,0.0035860648792407,0.000102121081157541,0.00358911940263177,0.00010211794751915,0.951728463172913,0.976156771183014,30.5848350524902,,30,4,200,-1.28370065795025E-5,-0.152042239904404,0.0236640684306622,3,,,,,,,,,,,,,,,,
,3959131772.97317,30.0001659393311,1000.37896728516,,,6,,,,30.7452130966154,,,100,,,,,,,,,,,,,,,,,,,,,,29.9988059997559,30.0009288787842,1000.37896728516,1000.37896728516,,,5.762779712677,,1,0,0,0,0.0142669677734375,33.2355842590332,1,1,1,29.9998035430908,0,29.9998327891032,13.9968004226685,1,0.00359842259091292,0.000177474689169777,0.00360173997305521,0.000177482816292848,0.953364789485931,0.979366183280945,30.5858039855957,5.35490989685059,30,4,200,-2.7874564693775E-5,-0.152666553854942,0.0237554349005222,1,,,,,,,,,,,,,,,,
,3959131891.9327,30.0003499984741,1000.37896728516,,,6,,,,30.7452130966154,,,100,,,,,,,,,,,,,,,,,,,,,,29.9989109039307,30.0006008148193,1000.37896728516,1000.37896728516,,,5.76377296447754,,1,0,0,0,0,33.7243423461914,1,1,1,30.0003795623779,0,29.9997439751258,17.9952011108398,1,0.00360675738004005,0.000102694111239035,0.00360987926452108,0.000102696258883447,0.955113351345062,0.981882750988007,30.5888614654541,0,30,4,200,-4.5299413613975E-5,-0.153094068169594,0.0237977243959904,3,,,,,,,,,,,,,,,,
,3959132014.12639,30.0004024505615,1000.37896728516,,,6,,,,30.7452130966154,,,100,,,,,,,,,,,,,,,,,,,,,,29.9989147186279,30.0005378723145,1000.37896728516,1000.37896728516,,,5.76251316070557,,1,0,0,0,0,32.2580642700195,1,1,1,30.0003147125244,0,29.9998529222276,24.0000019073486,1,0.00361829123519917,0.000178414190380067,0.00362100157454715,0.000178412593915266,0.958486557006836,0.985530614852905,30.5971641540527,0.0677592232823372,30,4,200,-4.07635743613355E-5,-0.153711915016174,0.0237988028675318,1,,,,,,,,,,,,,,,,
,3959132137.79308,30.0008325576782,1000.37896728516,,,6,,,,30.7452130966154,,,100,,,,,,,,,,,,,,,,,,,,,,29.9989414215088,30.0009708404541,1000.37896728516,1000.37896728516,,,5.76321935653687,,1,0,0,0,0.000152587890625,33.2355842590332,1,1,1,30.0010223388672,0,30.0000667572022,27.9984016418457,1,0.00362999314480064,0.000103329573582879,0.00363218043159327,0.00010332086955931,0.961143434047699,0.98826414346695,30.6042499542236,0,30,4,200,-3.59213117917534E-5,-0.154265999794006,0.0239058081060648,3,,,,,,,,,,,,,,,,
,3959132266.98046,30.0002899169922,1000.37896728516,,,6,,,,30.7452130966154,,,100,,,,,,,,,,,,,,,,,,,,,,29.9983825683594,30.0004234313965,1000.37896728516,1000.37896728516,,,5.76318693161011,,1,0,0,0,0.00030517578125,33.2355842590332,1,1,1,30.0002861022949,0,29.9994752671983,33.9984016418457,1,0.00364692462846866,0.000179787891111437,0.00364892552809193,0.000179775108242291,0.963953912258148,0.992192685604095,30.6117095947266,0,30,4,200,-3.40285660058726E-5,-0.155053436756134,0.0240685846656561,1,,,,,,,,,,,,,,,,
,3959132392.09944,30.0003795623779,1000.37896728516,,,6,,,,30.7452130966154,,,100,,,,,,,,,,,,,,,,,,,,,,29.9990329742432,30.000825881958,1000.37896728516,1000.37896728516,,,5.76280975341797,,1,0,0,0,0.000152587890625,34.2131004333496,1,1,1,30.0004463195801,0,29.9999925118906,37.9968032836914,1,0.00366265752709297,0.000104239863155078,0.00366444571958167,0.000104233215174056,0.966307461261749,0.99433696269989,30.6192207336426,0.0690822005271912,30,4,200,-7.16231261321809E-6,-0.144567653536797,0.0243190098553896,3,,,,,,,,,,,,,,,,
,3959132518.79864,30.0003490447998,1000.37896728516,,,6,,,,30.7452130966154,,,100,,,,,,,,,,,,,,,,,,,,,,29.9987354278564,30.0007801055908,1000.37896728516,1000.37896728516,,,5.76359128952026,,1,0,0,0,7.62939453125E-5,32.7468223571777,1,1,1,30.0000801086426,0,29.9997497134738,43.9968032836914,1,0.00368207284389739,0.000181487383883425,0.00368371312853913,0.000181487024491731,0.969454228878021,0.993774175643921,30.6320114135742,0.186675101518631,30,4,200,-3.78014119633008E-5,-0.145495682954788,0.0245541073381901,1,,,,,,,,,,,,,,,,
,3959132641.10927,30.000319480896,1000.37896728516,,,6,,,,30.7452130966154,,,100,,,,,,,,,,,,,,,,,,,,,,29.999210357666,30.0008373260498,1000.37896728516,1000.37896728516,,,5.76437330245972,,1,0,0,0,0.0142669677734375,33.7243423461914,1,1,1,30.0002517700195,0,29.9999680152306,48.0000038146973,1,0.00369421876949087,0.000105118453329427,0.00369557148169925,0.000105120379622568,0.972379922866821,0.991778016090393,30.6455154418945,0,30,4,200,-4.20567703258712E-5,-0.146083369851112,0.0246797315776348,3,,,,,,,,,,,,,,,,
,3959132763.38408,30.0006189346313,1000.37896728516,,,6,,,,30.7452130966154,,,100,,,,,,,,,,,,,,,,,,,,,,29.9990196228027,30.0009098052978,1000.37896728516,1000.37896728516,,,5.76330041885376,,1,0,0,0,0,33.2355842590332,1,1,1,30.0005779266357,0,30.000041325887,53.9952011108398,1,0.00370831440140721,0.000182740418360705,0.00370900552915239,0.000182739649631368,0.977841198444366,0.989511728286743,30.6714553833008,0,30,4,200,-4.76753048133105E-5,-0.146792516112328,0.024772260338068,1,,,,,,,,,,,,,,,,
,3959132883.87292,30.0003328323364,1000.37896728516,,,6,,,,30.7452130966154,,,100,,,,,,,,,,,,,,,,,,,,,,29.9988441467285,30.0007743835449,1000.37896728516,1000.37896728516,,,5.76330423355103,,1,0,0,0,0.000152587890625,33.2355842590332,1,1,1,30.0003757476807,0,29.9998856297246,57.9984016418457,1,0.00371638342068307,0.000105727641335728,0.00371666640468479,0.000105724264752354,0.981141865253448,0.988187968730926,30.6896915435791,0.186733260750771,30,4,200,-4.75118467875291E-5,-0.147218152880669,0.0248362924903631,3,,,,,,,,,,,,,,,,
,3959133011.08264,30.0001316070557,1000.37896728516,,,6,,,,30.7452130966154,,,100,,,,,,,,,,,,,,,,,,,,,,29.9985656738281,30.0001602172852,1000.37896728516,1000.37896728516,,,5.76279640197754,,1,0,0,0,0.00030517578125,33.7243423461914,1,1,1,30.0002460479736,0,29.9995057847765,63.9984016418457,1,0.00372501010451353,0.000183540897723636,0.00372505199941027,0.000183535231046041,0.984212338924408,0.987153768539429,30.710542678833,0.187839284539223,30,4,200,-5.96669560763985E-5,-0.147652730345726,0.0248876661062241,1,,,,,,,,,,,,,,,,
,3959133134.97969,30.0004539489746,1000.37896728516,,,6,,,,30.7452130966154,,,100,,,,,,,,,,,,,,,,,,,,,,29.9986743927002,30.0008697509766,1000.37896728516,1000.37896728516,,,5.76390171051025,,1,0,0,0,0.00030517578125,34.2131004333496,1,1,1,30.0008239746094,0,29.9999323950873,67.9968032836914,1,0.00373035763033769,0.000106118432099504,0.00373037878920726,0.000106116945674756,0.984892845153809,0.986256778240204,30.7215557098389,0,30,4,200,-8.35748687677551E-6,-0.147961735725403,0.0249188039451838,3,,,,,,,,,,,,,,,,
,3959133260.00499,30.0003538131714,1000.37896728516,,,6,,,,30.7452130966154,,,100,,,,,,,,,,,,,,,,,,,,,,29.9988613128662,30.0006160736084,1000.37896728516,1000.37896728516,,,5.76296854019165,,1,0,0,0,0.000152587890625,34.2131004333496,1,1,1,30.0002765655518,0,29.9997963375515,73.9968032836914,1,0.00373734470135498,0.000184146093427459,0.00373734062969701,0.000184145799589329,0.985130786895752,0.985164821147919,30.7414169311523,0,30,4,200,-4.38509159721434E-5,-0.148346975445747,0.0249511040747166,1,,,,,,,,,,,,,,,,
,3959133383.10282,30.0003547668457,1000.37896728516,,,6,,,,30.7452130966154,,,100,,,,,,,,,,,,,,,,,,,,,,29.9988994598389,30.0007667541504,1000.37896728516,1000.37896728516,,,5.76288795471191,,1,0,0,0,0.0142669677734375,34.7018585205078,1,1,1,30.0007400512695,0,29.9999051977087,77.9952011108398,1,0.00373818490567885,0.000106341207455892,0.00373820656491894,0.000106341266606268,0.984816431999207,0.985165297985077,30.7574119567871,0,30,4,200,-8.03678485681303E-5,-0.148429468274117,0.0248788688331842,3,,,,,,,,,,,,,,,,
,3959133507.0524,30.0000677108765,1000.37896728516,,,6,,,,30.7452130966154,,,100,,,,,,,,,,,,,,,,,,,,,,29.9984397888184,30.000452041626,1000.37896728516,1000.37896728516,,,5.76215696334839,,1,0,0,0,0,33.7243423461914,1,1,1,29.9998340606689,0,29.9994956122504,84.0000076293945,1,0.00373257743364383,0.000183917428614505,0.00373284534107462,0.000183919347308386,0.983000218868256,0.987102746963501,30.7870006561279,0,30,4,200,-5.46128794667311E-5,-0.148228764533997,0.0246764104813337,1,,,,,,,,,,,,,,,,
,3959133626.92927,30.0004386901855,1000.37896728516,,,6,,,,30.7452130966154,,,100,,,,,,,,,,,,,,,,,,,,,,29.9991817474365,30.0009536743164,1000.37896728516,1000.37896728516,,,5.76328086853027,,1,0,0,0,0,32.7468223571777,1,1,1,30.0003604888916,0,30.000092086792,87.998405456543,1,0.0037235845989679,0.000105934549179977,0.00372423353855861,0.000105938105980912,0.98015946149826,0.989400863647461,30.8085823059082,,30,4,200,-4.28104649472516E-5,-0.147875308990479,0.0244567543268204,3,,,,,,,,,,,,,,,,
,3959133677.2387,30.0004243850708,1000.37896728516,,,6,,,,30.7452130966154,,,100,,,,,,,,,,,,,,,,,,,,,,29.9991397857666,30.0009078979492,1000.37896728516,1000.37896728516,,,5.76306247711182,,1,0,0,0,0.000152587890625,33.2355842590332,1,1,1,30.000524520874,0,30.0000197799118,90.0000076293945,1,0.00371920543316858,0.000105813997687211,0.00372014495864806,0.000105820376192141,0.9783034324646,0.990713477134705,30.8193550109863,5.55151844024658,30,4,200,-3.66298409062438E-5,-0.147711366415024,0.0243503171950579,3,,,,,,,,,,,,,,,,