File: PPMS_Data_and_Plotting/Data/RuCl3/Data/Magnetisation/Rotator/TB001_RuCl3_H-parra-ab_61p2_mg_14-06-25_ZFCW_10K.dat
[Header]
; MPMS3 Data File (default extension .dat)
; Copyright (c) 2007, Quantum Design, Inc. All rights reserved.
TITLE,
FILEOPENTIME,3959109116.08924,06/15/2025,12:31 am
BYAPP,MPMS3 w/ AC,1.0,1.1
INFO,MPMS3 Measurement Release 1.2.2 Build 0, MultiVu Release 2.3.5.2,APPNAME
INFO,Linear Motor Servo Controller,MOTOR_MODULE_NAME
INFO,3101-100 N4,MOTOR_HW_VERSION
INFO,MMC1299,MOTOR_SERIAL_NUMBER
INFO,01.04.28,MOTOR_SOFTWARE_VERSION
INFO,Quantum Design Squid Module,SQUID_MODULE_NAME
INFO,3101-501 B0,SQUID_HW_VERSION
INFO,SQM364,SQUID_SERIAL_NUMBER
INFO,01.03.04,SQUID_SOFTWARE_VERSION
INFO,Quantum Design VSM Oven,OVEN_MODULE_NAME
INFO,3101-201 A3,OVEN_HW_VERSION
INFO,OVB387,OVEN_SERIAL_NUMBER
INFO,01.07.07,OVEN_SOFTWARE_VERSION
INFO,SQUID AC,AC_MODULE_NAME
INFO,3101-401 G0,AC_HW_VERSION
INFO,SAC242,AC_SERIAL_NUMBER
INFO,SQUID AC 00.95.11,AC_SOFTWARE_VERSION
INFO,TCI374,COIL_SERIAL_NUMBER
INFO,0,MOMENT_UNITS
INFO,RuCl3,SAMPLE_MATERIAL
INFO,single crystal,SAMPLE_COMMENT
INFO,61.2,SAMPLE_MASS
INFO,,SAMPLE_VOLUME
INFO,,SAMPLE_MOLECULAR_WEIGHT
INFO,,SAMPLE_SIZE
INFO,,SAMPLE_SHAPE
INFO,Rotator,SAMPLE_HOLDER
INFO,Standard,SAMPLE_HOLDER_DETAIL
INFO,67.44,SAMPLE_OFFSET
DATATYPE,COMMENT,1
DATATYPE,TIME,2
STARTUPAXIS,X,2
STARTUPAXIS,Y1,5
FIELDGROUP, VSM,2,3,4,5,6,8,9,10,11,14,15
FIELDGROUP, DC, 2,3,4,14,56,57,58,59,60,61,62,63,64,65,66,67,68,69
FIELDGROUP, AC, 2,3,4,11,16,17,18,19,20,21,22,23,24,25,26,27,28,29,30
STARTUPGROUP, All
[Data]
Comment,Time Stamp (sec),Temperature (K),Magnetic Field (Oe),Moment (emu),M. Std. Err. (emu),Transport Action,Averaging Time (sec),Frequency (Hz),Peak Amplitude (mm),Center Position (mm),Lockin Signal' (V),Lockin Signal (V),Range,M. Quad. Signal (emu),AC Moment (emu),AC M. Std Err. (emu),AC Phase (deg),AC Phase Std. Err. (deg),AC Susceptibility (emu/Oe),AC Suscept. Std Err. (emu/Oe),AC X' (emu/Oe),AC X' Std Err. (emu/Oe),AC X'' (emu/Oe),AC X'' Std Err. (emu/Oe),AC Drive (Oe),AC Frequency (Hz),AC Averaging Time (sec),AC Cycles,AC Range,AC Measure Type,AC Signal' (V),AC Signal'' (V),AC Trim Coil Ratio,AC Trim Coil Phase,Min. Temperature (K),Max. Temperature (K),Min. Field (Oe),Max. Field (Oe),Mass (grams),Motor Lag (deg),Pressure (Torr),Measure Count,Measurement Number,SQUID Status (code),Motor Status (code),Measure Status (code),Motor Current (amps),Motor Temp. (C),Temp. Status (code),Field Status (code),Chamber Status (code),Chamber Temp (K),Redirection State,Average Temp (K),Rotation Angle (deg),Rotator state,DC Moment Fixed Ctr (emu),DC Moment Err Fixed Ctr (emu),DC Moment Free Ctr (emu),DC Moment Err Free Ctr (emu),DC Fixed Fit,DC Free Fit,DC Calculated Center (mm),DC Calculated Center Err (mm),DC Scan Length (mm),DC Scan Time (s),DC Number of Points,DC Squid Drift,DC Min V (V),DC Max V (V),DC Scans per Measure,He3 temp,Map 02,Map 03,Map 04,Map 05,Map 06,Map 07,Map 08,Map 09,Map 10,Map 11,Map 12,Map 13,Map 14,Map 15,Map 16
,3959110492.71045,10.0002226829529,1000.22119140625,,,6,,,,30.738023492992,,,10,,,,,,,,,,,,,,,,,,,,,,9.99682712554932,10.0029296875,1000.22119140625,1000.22119140625,,,4.8362340927124,,1,0,0,0,0.000152587890625,34.2131004333496,1,1,1,10.0029296875,0,9.99894025590685,-299.995208740234,1,0.00487887718740549,0.000240391611358903,0.00487903337387587,0.000240394463996797,0.985131502151489,0.986554205417633,30.761926651001,,30,4,200,-0.000812362763099372,-1.96077752113342,0.297533422708511,1,,,,,,,,,,,,,,,,
,3959110618.81522,10.0018906593323,1000.22119140625,,,6,,,,30.738023492992,,,10,,,,,,,,,,,,,,,,,,,,,,9.99614334106445,10.0038728713989,1000.22119140625,1000.22119140625,,,4.85895299911499,,1,0,0,0,7.62939453125E-5,34.2131004333496,1,1,1,10.0035419464111,0,9.99984685305891,-295.996826171875,1,0.00488491799529594,0.000138962059551652,0.00488497630081874,0.000138962450216705,0.985125958919525,0.985752463340759,30.75412940979,0,30,4,200,-0.000499768066219985,-1.96756565570831,0.295230180025101,3,,,,,,,,,,,,,,,,
,3959110748.25321,10.0027012825012,1000.22119140625,,,6,,,,30.738023492992,,,10,,,,,,,,,,,,,,,,,,,,,,9.99704360961914,10.0036811828613,1000.22119140625,1000.22119140625,,,4.8661322593689,,1,0,0,0,0,34.2131004333496,1,1,1,10.0044898986816,0,9.99981615278456,-289.996826171875,1,0.00489084140683802,0.000240984655829305,0.00489090104683422,0.000240986209214697,0.984171748161316,0.984539031982422,30.7508144378662,0,30,4,200,-0.000635826436337084,-1.9723699092865,0.29302841424942,1,,,,,,,,,,,,,,,,
,3959110871.44285,10.0028657913208,1000.22119140625,,,6,,,,30.738023492992,,,10,,,,,,,,,,,,,,,,,,,,,,9.99586963653564,10.0046863555908,1000.22119140625,1000.22119140625,,,4.87379932403564,,1,0,0,0,0.001220703125,34.7018585205078,1,1,1,10.0039663314819,0,9.99961061830874,-285.998413085938,1,0.00489899711480536,0.000139365637222304,0.00489902935693762,0.000139366039538242,0.983680665493011,0.983908593654633,30.7482643127441,0,30,4,200,-0.000902190105989575,-1.9778516292572,0.29186350107193,3,,,,,,,,,,,,,,,,
,3959110999.87424,10.0025930404663,1000.22119140625,,,6,,,,30.738023492992,,,10,,,,,,,,,,,,,,,,,,,,,,9.99663257598877,10.00328540802,1000.22119140625,1000.22119140625,,,4.87565469741821,,1,0,0,0,0,34.2131004333496,1,1,1,10.0044631958008,0,9.99960814581977,-279.998413085938,1,0.00490137074327689,0.000241505667018053,0.00490150457296447,0.000241508730879373,0.983604967594147,0.984521985054016,30.7583999633789,0,30,4,200,-0.000997087568975985,-1.97986578941345,0.289485961198807,1,,,,,,,,,,,,,,,,
,3959111122.70519,10.0030660629272,1000.22119140625,,,6,,,,30.738023492992,,,10,,,,,,,,,,,,,,,,,,,,,,9.99615955352783,10.0053548812866,1000.22119140625,1000.22119140625,,,4.87925052642822,,1,0,0,0,0.000152587890625,34.2131004333496,1,1,1,10.0045108795166,0,9.99995457684552,-275.995208740234,1,0.00489972057314533,0.000139389296946493,0.00490010065221327,0.000139391208808702,0.982403993606567,0.98651123046875,30.7806797027588,0,30,4,200,-0.000922569481190294,-1.98017859458923,0.287179917097092,3,,,,,,,,,,,,,,,,
,3959111254.20747,10.0008449554443,1000.22119140625,,,6,,,,30.738023492992,,,10,,,,,,,,,,,,,,,,,,,,,,9.99643707275391,10.003833770752,1000.22119140625,1000.22119140625,,,4.88018703460693,,1,0,0,0,0.0002288818359375,34.2131004333496,1,1,1,10.0039901733398,0,9.9989764213562,-269.995208740234,1,0.00489462851192701,0.000241189435517805,0.00489580908336539,0.000241209345049855,0.979982197284698,0.990859985351562,30.8054389953613,0,30,4,200,-0.000838911393657327,-1.97908401489258,0.283000886440277,1,,,,,,,,,,,,,,,,
,3959111382.07647,10.0020174980164,1000.22119140625,,,6,,,,30.738023492992,,,10,,,,,,,,,,,,,,,,,,,,,,9.99618530273437,10.0038471221924,1000.22119140625,1000.22119140625,,,4.88470363616943,,1,0,0,0,0.00030517578125,34.2131004333496,1,1,1,10.0036468505859,0,9.99993620600019,-265.996826171875,1,0.00489166261832609,0.000139171859527373,0.00489278339944305,0.00013917396942068,0.978106439113617,0.992818653583527,30.8162250518799,9.28070545196533,30,4,200,-0.000567847047932446,-1.97887313365936,0.280206143856049,3,,,,,,,,,,,,,,,,
,3959111512.70173,10.0021109580994,1000.22119140625,,,6,,,,30.738023492992,,,10,,,,,,,,,,,,,,,,,,,,,,9.99655151367187,10.0031509399414,1000.22119140625,1000.22119140625,,,4.88509845733643,,1,0,0,0,0,33.7243423461914,1,1,1,10.0040740966797,0,9.99931282467312,-259.996826171875,1,0.00488665901030986,0.000240819462523549,0.00488819448900984,0.00024082949798892,0.975716114044189,0.993300437927246,30.8264198303223,0.186790958046913,30,4,200,-0.000412184919696301,-1.97847294807434,0.275363504886627,1,,,,,,,,,,,,,,,,
,3959111635.50979,10.0026926994324,1000.22119140625,,,6,,,,30.738023492992,,,10,,,,,,,,,,,,,,,,,,,,,,9.99639320373535,10.0047035217285,1000.22119140625,1000.22119140625,,,4.88882493972778,,1,0,0,0,0.000152587890625,34.2131004333496,1,1,1,10.0043296813965,0,9.99974476849591,-255.998413085938,1,0.00487731585843009,0.000138783532253182,0.00487922367030395,0.000138787656455211,0.972321450710297,0.993392467498779,30.8397235870361,,30,4,200,-0.000877371756359935,-1.97633194923401,0.271414548158646,3,,,,,,,,,,,,,,,,
,3959111763.35731,10.0033106803894,1000.22119140625,,,6,,,,30.738023492992,,,10,,,,,,,,,,,,,,,,,,,,,,9.9974889755249,10.0046091079712,1000.22119140625,1000.22119140625,,,4.88837146759033,,1,0,0,0,0.000152587890625,32.7468223571777,1,1,1,10.0046091079712,0,10.0003834724426,-249.998413085938,1,0.00485376113264204,0.000239273868273875,0.00485687405854198,0.000239292019254567,0.965034663677216,0.990369081497192,30.8653545379639,0,30,4,200,-0.00130192376673222,-1.9681783914566,0.265335381031036,1,,,,,,,,,,,,,,,,
,3959111890.61339,10.003116607666,1000.22119140625,,,6,,,,30.738023492992,,,10,,,,,,,,,,,,,,,,,,,,,,9.99609565734863,10.0046005249023,1000.22119140625,1000.22119140625,,,4.89068365097046,,1,0,0,0,0.000152587890625,34.2131004333496,1,1,1,10.0044164657593,0,9.99982872715703,-245.995208740234,1,0.00483192810551066,0.00013754955769347,0.00483593847606003,0.000137563099425332,0.959988176822662,0.988174080848694,30.8831596374512,0,30,4,200,-0.000933740346226841,-1.96081256866455,0.260323464870453,3,,,,,,,,,,,,,,,,
,3959112023.15625,10.0014524459839,1000.22119140625,,,6,,,,30.738023492992,,,10,,,,,,,,,,,,,,,,,,,,,,9.99648857116699,10.0036001205444,1000.22119140625,1000.22119140625,,,4.88878488540649,,1,0,0,0,0.000152587890625,34.2131004333496,1,1,1,10.003924369812,0,9.99915456771851,-239.995208740234,1,0.0048000973610661,0.000236735654716246,0.00480548499768809,0.000236777503596278,0.953883826732636,0.984543144702911,30.9034233093262,0,30,4,200,-0.000940519385039806,-1.94955348968506,0.25333508849144,1,,,,,,,,,,,,,,,,
,3959112152.23712,10.0019454956055,1000.22119140625,,,6,,,,30.738023492992,,,10,,,,,,,,,,,,,,,,,,,,,,9.99651718139648,10.0038242340088,1000.22119140625,1000.22119140625,,,4.88994073867798,,1,0,0,0,0.0002288818359375,34.7018585205078,1,1,1,10.0034103393555,0,9.99991726875305,-235.996810913086,1,0.00478498069314244,0.000136266892030786,0.0047906092257836,0.00013628563379713,0.951112985610962,0.982206523418426,30.9114303588867,5.55980491638184,30,4,200,-0.000499654212035239,-1.94474279880524,0.249320775270462,3,,,,,,,,,,,,,,,,
,3959112283.64474,10.001615524292,1000.22119140625,,,6,,,,30.738023492992,,,10,,,,,,,,,,,,,,,,,,,,,,9.99622344970703,10.0032138824463,1000.22119140625,1000.22119140625,,,4.88948774337769,,1,0,0,0,0,33.7243423461914,1,1,1,10.0038995742798,0,9.99931123521593,-229.996810913086,1,0.00476620470047012,0.000235124246801649,0.00477206249119686,0.000235153759382649,0.94865208864212,0.979155957698822,30.9171276092529,5.5603175163269,30,4,200,-0.00069665937917307,-1.93842494487762,0.244931131601334,1,,,,,,,,,,,,,,,,
,3959112405.25056,10.002613067627,1000.22119140625,,,6,,,,30.738023492992,,,10,,,,,,,,,,,,,,,,,,,,,,9.9957447052002,10.0044965744019,1000.22119140625,1000.22119140625,,,4.89254283905029,,1,0,0,0,0,34.2131004333496,1,1,1,10.0037050247192,0,9.99982687143179,-225.998413085938,1,0.00475162897597395,0.000135355410342283,0.0047579259154848,0.000135370652679716,0.945650219917297,0.976877331733704,30.9256820678711,0,30,4,200,-0.000767954275943339,-1.93382787704468,0.242014050483704,3,,,,,,,,,,,,,,,,
,3959112534.48785,10.0026669502258,1000.22119140625,,,6,,,,30.738023492992,,,10,,,,,,,,,,,,,,,,,,,,,,9.99696254730225,10.0028190612793,1000.22119140625,1000.22119140625,,,4.89178419113159,,1,0,0,0,0,34.2131004333496,1,1,1,10.0046434402466,0,9.99932373894585,-219.998413085938,1,0.00472518861290404,0.000233220168098296,0.0047330397090982,0.000233262041041639,0.939530193805695,0.973508834838867,30.9453525543213,0,30,4,200,-0.000953346840105951,-1.92530798912048,0.237380906939507,1,,,,,,,,,,,,,,,,
,3959112662.66197,10.003116607666,1000.22119140625,,,6,,,,30.738023492992,,,10,,,,,,,,,,,,,,,,,,,,,,9.99591255187988,10.0046682357788,1000.22119140625,1000.22119140625,,,4.89395952224731,,1,0,0,0,0.000152587890625,34.2131004333496,1,1,1,10.0048456192017,0,9.99970531463623,-215.995208740234,1,0.00470262850122361,0.000134044498167329,0.00471149384496003,0.000134068822657473,0.935069978237152,0.971354722976685,30.96067237854,0,30,4,200,-0.00123013055417687,-1.91870987415314,0.233626708388329,3,,,,,,,,,,,,,,,,
,3959112792.43174,10.0019688606262,1000.22119140625,,,6,,,,30.738023492992,,,10,,,,,,,,,,,,,,,,,,,,,,9.99671268463135,10.0041055679321,1000.22119140625,1000.22119140625,,,4.89179849624634,,1,0,0,0,0.000152587890625,34.7018585205078,1,1,1,10.004430770874,0,9.99925765991211,-209.995208740234,1,0.00467546270083557,0.000230912306162999,0.00468575486592004,0.000230959084814156,0.929855048656464,0.969351232051849,30.978967666626,5.56587505340576,30,4,200,-0.00104902940802276,-1.91054701805115,0.229252517223358,1,,,,,,,,,,,,,,,,
,3959112919.51876,10.0015306472778,1000.22119140625,,,6,,,,30.738023492992,,,10,,,,,,,,,,,,,,,,,,,,,,9.99611568450928,10.0037536621094,1000.22119140625,1000.22119140625,,,4.89126873016357,,1,0,0,0,0.00030517578125,34.2131004333496,1,1,1,10.003321647644,0,9.99982650191696,-205.996810913086,1,0.00466497188913468,0.000133027171364268,0.00467651278849237,0.000133081800715129,0.928896307945251,0.969218850135803,30.9837169647217,5.56630182266235,30,4,200,-0.000340392434736714,-1.90858864784241,0.226629465818405,3,,,,,,,,,,,,,,,,
,3959113051.09011,10.0012741088867,1000.22119140625,,,6,,,,30.738023492992,,,10,,,,,,,,,,,,,,,,,,,,,,9.99609279632568,10.0017910003662,1000.22119140625,1000.22119140625,,,4.89053726196289,,1,0,0,0,0.000152587890625,34.2131004333496,1,1,1,10.0038709640503,0,9.99868795606825,-199.996810913086,1,0.00466430144000254,0.000230392820741882,0.00467527548270084,0.000230434841428253,0.927928268909454,0.970466732978821,30.9895191192627,0.250306665897369,30,4,200,-0.000632978626526892,-1.91059911251068,0.225693196058273,1,,,,,,,,,,,,,,,,
,3959113175.27541,10.0027461051941,1000.22119140625,,,6,,,,30.738023492992,,,10,,,,,,,,,,,,,,,,,,,,,,9.99620056152344,10.0036602020264,1000.22119140625,1000.22119140625,,,4.89134931564331,,1,0,0,0,0.008392333984375,33.7243423461914,1,1,1,10.0039587020874,0,9.99970746923376,-195.998413085938,1,0.00466161419102003,0.000132949389242034,0.00467310185762949,0.000132978083291915,0.927034556865692,0.970899045467377,30.9942398071289,,30,4,200,-0.0001101073648897,-1.91195619106293,0.224528193473816,3,,,,,,,,,,,,,,,,
,3959113306.03543,10.0028963088989,1000.22119140625,,,6,,,,30.738023492992,,,10,,,,,,,,,,,,,,,,,,,,,,9.99694633483887,10.0034961700439,1000.22119140625,1000.22119140625,,,4.88932418823242,,1,0,0,0,0.000152587890625,34.2131004333496,1,1,1,10.0045032501221,0,9.99985980987549,-189.998413085938,1,0.00466098383924493,0.000230285430380779,0.00467326341198881,0.000230323247128977,0.924618721008301,0.972350537776947,31.0057239532471,0,30,4,200,-0.00106147502083331,-1.91452825069427,0.223918944597244,1,,,,,,,,,,,,,,,,
,3959113431.29989,10.0033841133118,1000.22119140625,,,6,,,,30.738023492992,,,10,,,,,,,,,,,,,,,,,,,,,,9.99533271789551,10.0047740936279,1000.22119140625,1000.22119140625,,,4.89437198638916,,1,0,0,0,0.000152587890625,33.2355842590332,1,1,1,10.004846572876,0,9.99958451588949,-186.000015258789,1,0.00465685224817492,0.000132852620604575,0.00467029535140575,0.000132887339948303,0.923133730888367,0.973862528800964,31.0137271881103,0.24935519695282,30,4,200,-0.00122652947902679,-1.91565108299255,0.22292223572731,3,,,,,,,,,,,,,,,,
,3959113564.60125,10.0013794898987,1000.22119140625,,,6,,,,30.738023492992,,,10,,,,,,,,,,,,,,,,,,,,,,9.99622249603271,10.0029535293579,1000.22119140625,1000.22119140625,,,4.89204025268555,,1,0,0,0,0,33.7243423461914,1,1,1,10.0035285949707,0,9.9987891515096,-180.000015258789,1,0.0046541645569214,0.000229979920731324,0.00466804318071784,0.000230043637976508,0.922838866710663,0.976116418838501,31.0181827545166,0.187150463461876,30,4,200,-0.000859801075421274,-1.91700506210327,0.221659526228905,1,,,,,,,,,,,,,,,,
,3959113691.50209,10.0022554397583,1000.22119140625,,,6,,,,30.738023492992,,,10,,,,,,,,,,,,,,,,,,,,,,9.99650764465332,10.0047292709351,1000.22119140625,1000.22119140625,,,4.89324331283569,,1,0,0,0,0.00030517578125,33.7243423461914,1,1,1,10.0038642883301,0,9.99983102303964,-175.996810913086,1,0.0046583172223777,0.000132889426125681,0.00467302992327491,0.000132950095805458,0.9236199259758,0.978622853755951,31.0185451507568,0,30,4,200,-0.000877373677212745,-1.92025625705719,0.222011998295784,3,,,,,,,,,,,,,,,,
,3959113824.98251,10.0011992454529,1000.22119140625,,,6,,,,30.738023492992,,,10,,,,,,,,,,,,,,,,,,,,,,9.99639892578125,10.0039844512939,1000.22119140625,1000.22119140625,,,4.89108610153198,,1,0,0,0,0.00030517578125,34.2131004333496,1,1,1,10.0039844512939,0,9.99907360076904,-169.996810913086,1,0.00467734413064263,0.000231079687756963,0.00469041206357653,0.000231113962747319,0.925424158573151,0.982862412929535,31.0143756866455,0,30,4,200,-0.000604557862970978,-1.92879581451416,0.223848700523376,1,,,,,,,,,,,,,,,,
,3959113950.36889,10.0023865699768,1000.22119140625,,,6,,,,30.738023492992,,,10,,,,,,,,,,,,,,,,,,,,,,9.99624443054199,10.003981590271,1000.22119140625,1000.22119140625,,,4.89342641830444,,1,0,0,0,0,33.7243423461914,1,1,1,10.003607749939,0,9.99986094694871,-165.998413085938,1,0.00469818115239266,0.000133999998391145,0.00471163540995568,0.000134031279597248,0.926251530647278,0.985813975334167,31.0136394500732,9.09556365513708E-6,30,4,200,-0.000506037380546331,-1.93836617469788,0.22795931994915,3,,,,,,,,,,,,,,,,
,3959114076.85741,10.0030755996704,1000.22119140625,,,6,,,,30.738023492992,,,10,,,,,,,,,,,,,,,,,,,,,,9.99770927429199,10.0035562515259,1000.22119140625,1000.22119140625,,,4.89119338989258,,1,0,0,0,7.62939453125E-5,34.7018585205078,1,1,1,10.0049295425415,0,9.99990537431505,-159.998413085938,1,0.00472307600421651,0.000233302587008602,0.00473619917414976,0.00023335130459983,0.927533566951752,0.988447308540344,31.0093574523926,0,30,4,200,-0.00156143645290285,-1.95020163059235,0.230733945965767,1,,,,,,,,,,,,,,,,
,3959114201.81478,10.003146648407,1000.22119140625,,,6,,,,30.738023492992,,,10,,,,,,,,,,,,,,,,,,,,,,9.99597549438477,10.0048675537109,1000.22119140625,1000.22119140625,,,4.89298582077026,,1,0,0,0,0.000152587890625,33.7243423461914,1,1,1,10.0046672821045,0,9.99965664192482,-155.995208740234,1,0.0047379889403011,0.000135114401932916,0.00475060266460269,0.000135132545929528,0.9283726811409,0.990263402462006,31.006814956665,,30,4,200,-0.00120790430810302,-1.95769846439362,0.231589958071709,3,,,,,,,,,,,,,,,,
,3959114334.33273,10.0032930374146,1000.22119140625,,,6,,,,30.738023492992,,,10,,,,,,,,,,,,,,,,,,,,,,9.9971809387207,10.0027685165405,1000.22119140625,1000.22119140625,,,4.8894305229187,,1,0,0,0,0.00030517578125,34.2131004333496,1,1,1,10.0050001144409,0,9.99948819478353,-149.995208740234,1,0.004750164925114,0.000234574900089399,0.00476217304811429,0.000234625078253499,0.9314945936203,0.990927517414093,30.9951610565186,0,30,4,200,-0.00134850083850324,-1.96451675891876,0.231283321976662,1,,,,,,,,,,,,,,,,
,3959114459.3869,10.002185344696,1000.22119140625,,,6,,,,30.738023492992,,,10,,,,,,,,,,,,,,,,,,,,,,9.99660301208496,10.0037927627563,1000.22119140625,1000.22119140625,,,4.89303588867188,,1,0,0,0,7.62939453125E-5,33.7243423461914,1,1,1,10.0034189224243,0,9.99968489894161,-145.996810913086,1,0.00476735768764371,0.000135901435163398,0.00477950031053512,0.00013595196016063,0.933731555938721,0.992450177669525,30.9871368408203,4.84659551602817E-7,30,4,200,-0.00100677239242941,-1.97302794456482,0.232602566480637,3,,,,,,,,,,,,,,,,
,3959114590.24967,10.0007758140564,1000.22119140625,,,6,,,,30.738023492992,,,10,,,,,,,,,,,,,,,,,,,,,,9.99614524841309,10.0022192001343,1000.22119140625,1000.22119140625,,,4.88798570632935,,1,0,0,0,0.0002288818359375,34.2131004333496,1,1,1,10.0034646987915,0,9.99838076697456,-139.996810913086,1,0.00479024348599055,0.000236437174135111,0.00479998631269575,0.000236485279111689,0.939101040363312,0.992331862449646,30.966402053833,0.348595857620239,30,4,200,-0.000524324539583176,-1.98191618919373,0.345936387777329,1,,,,,,,,,,,,,,,,
,3959114716.65501,10.0023393630981,1000.22119140625,,,6,,,,30.738023492992,,,10,,,,,,,,,,,,,,,,,,,,,,9.99624061584473,10.0039405822754,1000.22119140625,1000.22119140625,,,4.89314126968384,,1,0,0,0,7.62939453125E-5,36.6568908691406,1,1,1,10.0037870407104,0,9.99976638511375,-135.998413085938,1,0.00482478935476018,0.000137474396030639,0.00483360683909316,0.000137496390205236,0.941161870956421,0.988332509994507,30.9560604095459,2.91547094093403E-5,30,4,200,-0.000507606717292219,-1.9977343082428,0.350363254547119,3,,,,,,,,,,,,,,,,
,3959114843.38287,10.0028505325317,1000.22119140625,,,6,,,,30.738023492992,,,10,,,,,,,,,,,,,,,,,,,,,,9.99648952484131,10.0048208236694,1000.22119140625,1000.22119140625,,,4.8912844657898,,1,0,0,0,7.62939453125E-5,33.7243423461914,1,1,1,10.0050582885742,0,9.99948558807373,-129.998413085938,1,0.00485246716063469,0.000239414818959296,0.00485944032178165,0.000239435563879677,0.945876061916351,0.984671652317047,30.9337425231934,0,30,4,200,-0.00118140201084316,-2.0088312625885,0.351670205593109,1,,,,,,,,,,,,,,,,
,3959114970.82954,10.0028519630432,1000.22119140625,,,6,,,,30.738023492992,,,10,,,,,,,,,,,,,,,,,,,,,,9.99571800231934,10.0042495727539,1000.22119140625,1000.22119140625,,,4.89395570755005,,1,0,0,0,0.0142669677734375,33.2355842590332,1,1,1,10.0038805007935,0,9.99967349017108,-125.995208740234,1,0.00487125863962639,0.000138737142421638,0.00487721118811761,0.000138747816727561,0.949208080768585,0.982838153839111,30.9180126190186,0,30,4,200,-0.00119970412924886,-2.01656746864319,0.352726310491562,3,,,,,,,,,,,,,,,,
,3959115101.94437,10.0027537345886,1000.22119140625,,,6,,,,30.738023492992,,,10,,,,,,,,,,,,,,,,,,,,,,9.99620151519775,10.0025854110718,1000.22119140625,1000.22119140625,,,4.89059686660767,,1,0,0,0,0.0142669677734375,33.7243423461914,1,1,1,10.0050163269043,0,9.9988800684611,-119.995208740234,1,0.00487826659597778,0.000240564696720889,0.00488262865931237,0.000240586229638769,0.956305146217346,0.982608437538147,30.8890209197998,0,30,4,200,-0.00144175975583494,-2.01968002319336,0.350896120071411,1,,,,,,,,,,,,,,,,
,3959115228.66678,10.0031137466431,1000.22119140625,,,6,,,,30.738023492992,,,10,,,,,,,,,,,,,,,,,,,,,,9.99564170837402,10.0046472549438,1000.22119140625,1000.22119140625,,,4.89414501190186,,1,0,0,0,0.000152587890625,34.2131004333496,1,1,1,10.0045824050903,0,9.99979039600917,-115.996803283691,1,0.00488555292247334,0.000139072732163116,0.0048889260262643,0.000139080480710564,0.960594296455383,0.98311710357666,30.8721618652344,0,30,4,200,-0.000581319443881512,-2.02361702919006,0.238079503178597,3,,,,,,,,,,,,,,,,
,3959115360.37247,10.0003538131714,1000.22119140625,,,6,,,,30.738023492992,,,10,,,,,,,,,,,,,,,,,,,,,,9.99607849121094,10.0023059844971,1000.22119140625,1000.22119140625,,,4.88945770263672,,1,0,0,0,0.00030517578125,33.7243423461914,1,1,1,10.0032968521118,0,9.99832852681478,-109.996803283691,1,0.00489641434150373,0.000241360798584055,0.00489909112006491,0.000241389434097031,0.966961681842804,0.984627842903137,30.848258972168,0,30,4,200,-0.000655309821013361,-2.0281810760498,0.237621828913689,1,,,,,,,,,,,,,,,,
,3959115486.72022,10.0019655227661,1000.22119140625,,,6,,,,30.738023492992,,,10,,,,,,,,,,,,,,,,,,,,,,9.99606990814209,10.0037651062012,1000.22119140625,1000.22119140625,,,4.89356422424316,,1,0,0,0,0.0002288818359375,33.7243423461914,1,1,1,10.0034513473511,0,9.99979714994077,-105.998405456543,1,0.00490650152328389,0.000139615341830569,0.00490802261506489,0.000139619322177062,0.971991658210754,0.985105931758881,30.8274173736572,,30,4,200,-0.000499900372233242,-2.03156924247742,0.23835089802742,3,,,,,,,,,,,,,,,,
,3959115614.64331,10.0025849342346,1000.22119140625,,,6,,,,30.738023492992,,,10,,,,,,,,,,,,,,,,,,,,,,9.9966402053833,10.0040006637573,1000.22119140625,1000.22119140625,,,4.89128398895264,,1,0,0,0,0.000152587890625,33.7243423461914,1,1,1,10.0046424865723,0,9.99944343566895,-99.998405456543,1,0.00491970413754467,0.000242434419235002,0.00492050750601931,0.000242442675466228,0.978135287761688,0.98517769575119,30.7986869812012,1.54828683207597E-6,30,4,200,-0.00132873794063926,-2.03608083724976,0.23935803771019,1,,,,,,,,,,,,,,,,
,3959115741.78613,10.0032658576965,1000.22119140625,,,6,,,,30.738023492992,,,10,,,,,,,,,,,,,,,,,,,,,,9.99607849121094,10.003999710083,1000.22119140625,1000.22119140625,,,4.89384651184082,,1,0,0,0,7.62939453125E-5,33.7243423461914,1,1,1,10.0045204162598,0,9.9997354083591,-96.0000076293945,1,0.00492001065695907,0.000139969436550271,0.00492041567068426,0.000139970387298908,0.981232762336731,0.985815346240997,30.7843151092529,9.29772853851318,30,4,200,-0.00114390812814236,-2.03618121147156,0.238286197185516,3,,,,,,,,,,,,,,,,
,3959115872.72595,10.0029306411743,1000.22119140625,,,6,,,,30.738023492992,,,10,,,,,,,,,,,,,,,,,,,,,,9.99619007110596,10.0026321411133,1000.22119140625,1000.22119140625,,,4.88947343826294,,1,0,0,0,0.0006866455078125,33.2355842590332,1,1,1,10.0046157836914,0,9.99921586778429,-90.0000076293945,1,0.00489956690256021,0.000241402007959948,0.00489970429746047,0.000241404607689028,0.987886548042297,0.989407777786255,30.7602100372314,5.36599540710449,30,4,200,-0.0013042954960838,-2.0268759727478,0.233107522130013,1,,,,,,,,,,,,,,,,
,3959115998.39483,10.0031018257141,1000.22119140625,,,6,,,,30.738023492992,,,10,,,,,,,,,,,,,,,,,,,,,,9.99554347991943,10.0042428970337,1000.22119140625,1000.22119140625,,,4.89416074752808,,1,0,0,0,0,33.7243423461914,1,1,1,10.0042057037354,0,9.99961519241333,-85.9968032836914,1,0.00487884255788958,0.000138778165576979,0.00487885154876492,0.000138778322928739,0.992030441761017,0.992119908332825,30.7425289154053,0,30,4,200,-0.00100307678803802,-2.01836967468262,0.228912383317947,3,,,,,,,,,,,,,,,,
,3959116130.51752,10.0013365745544,1000.22119140625,,,6,,,,30.738023492992,,,10,,,,,,,,,,,,,,,,,,,,,,9.99650478363037,10.0037183761597,1000.22119140625,1000.22119140625,,,4.89177989959717,,1,0,0,0,0.0002288818359375,33.7243423461914,1,1,1,10.0042133331299,0,9.99895477294922,-79.9968032836914,1,0.00485874674755228,0.000239379338698455,0.00485872704117833,0.000239375780170883,0.992871344089508,0.994596421718597,30.7203559875488,0.338779836893082,30,4,200,-0.00123408052604645,-2.00995373725891,0.336128830909729,1,,,,,,,,,,,,,,,,
,3959116258.69669,10.0020051002502,1000.22119140625,,,6,,,,30.738023492992,,,10,,,,,,,,,,,,,,,,,,,,,,9.99654388427734,10.003589630127,1000.22119140625,1000.22119140625,,,4.89262962341309,,1,0,0,0,0.0002288818359375,33.2355842590332,1,1,1,10.0030612945557,0,9.99998993343777,-75.998405456543,1,0.00484563889165425,0.00013783700862684,0.0048457379946885,0.000137835389769614,0.989492774009705,0.993216633796692,30.7075843811035,2.58974318967375E-6,30,4,200,-0.000425214995630085,-2.00524044036865,0.332816988229752,3,,,,,,,,,,,,,,,,
,3959116389.53129,10.0022358894348,1000.22119140625,,,6,,,,30.738023492992,,,10,,,,,,,,,,,,,,,,,,,,,,9.99664115905762,10.0030097961426,1000.22119140625,1000.22119140625,,,4.89163494110107,,1,0,0,0,0,33.7243423461914,1,1,1,10.0039863586426,0,9.99927457173665,-69.998405456543,1,0.0048428948599491,0.000238629807473254,0.0048433246166042,0.000238625321872321,0.982268989086151,0.990031719207764,30.6823081970215,0,30,4,200,-0.00052498112199828,-2.00396943092346,0.331595838069916,1,,,,,,,,,,,,,,,,
,3959116512.83903,10.002655506134,1000.22119140625,,,6,,,,30.738023492992,,,10,,,,,,,,,,,,,,,,,,,,,,9.99649333953857,10.0039892196655,1000.22119140625,1000.22119140625,,,4.89279937744141,,1,0,0,0,0.000152587890625,33.7243423461914,1,1,1,10.0040254592896,0,9.99971015365036,-65.9952011108398,1,0.00482633588627341,0.000137314527288613,0.00482712701078257,0.000137314720446919,0.977681696414947,0.986838757991791,30.6695652008057,5.53801107406616,30,4,200,-0.000943823892157525,-1.99776971340179,0.328031271696091,3,,,,,,,,,,,,,,,,
,3959116641.68432,10.0035929679871,1000.22119140625,,,6,,,,30.738023492992,,,10,,,,,,,,,,,,,,,,,,,,,,9.99652481079102,10.0025682449341,1000.22119140625,1000.22119140625,,,4.89223289489746,,1,0,0,0,0.000152587890625,32.7468223571777,1,1,1,10.0048427581787,0,9.99930699666341,-59.9952011108398,1,0.00479438434070814,0.000236298930127831,0.00479543883504434,0.000236296247510783,0.971408545970917,0.981153309345245,30.6562461853027,0,30,4,200,-0.00117744063027203,-1.98637139797211,0.322745263576508,1,,,,,,,,,,,,,,,,
,3959116769.25808,10.0037050247192,1000.22119140625,,,6,,,,30.738023492992,,,10,,,,,,,,,,,,,,,,,,,,,,9.99568939208984,10.0050077438354,1000.22119140625,1000.22119140625,,,4.89502334594727,,1,0,0,0,0.0002288818359375,33.2355842590332,1,1,1,10.0051031112671,0,9.99962100276241,-55.9968032836914,1,0.00476730849259891,0.000135673861326894,0.00476857933775278,0.000135671058485037,0.967306792736054,0.977753698825836,30.6467437744141,0,30,4,200,-0.00118825049139559,-1.97654926776886,0.318653702735901,3,,,,,,,,,,,,,,,,
,3959116899.22709,10.0013995170593,1000.22119140625,,,6,,,,30.738023492992,,,10,,,,,,,,,,,,,,,,,,,,,,9.99611759185791,10.0021915435791,1000.22119140625,1000.22119140625,,,4.89053249359131,,1,0,0,0,0.000152587890625,33.7243423461914,1,1,1,10.0036888122559,0,9.99839221106635,-49.9968032836914,1,0.00473395589897381,0.000233392838313512,0.00473549982671402,0.000233377331817219,0.962112724781036,0.974481165409088,30.6308994293213,0,30,4,200,-0.00051227246876806,-1.96475875377655,0.313305765390396,1,,,,,,,,,,,,,,,,
,3959117026.59774,10.0017466545105,1000.22119140625,,,6,,,,30.738023492992,,,10,,,,,,,,,,,,,,,,,,,,,,9.99642276763916,10.0035820007324,1000.22119140625,1000.22119140625,,,4.89006757736206,,1,0,0,0,0.0002288818359375,33.7243423461914,1,1,1,10.0031509399414,0,9.99980760503698,-45.9984016418457,1,0.00472444766429742,0.000134489720568015,0.00472625674971164,0.000134480734368355,0.960019528865814,0.97353982925415,30.6234855651855,0,30,4,200,-0.0005902792327106,-1.96181046962738,0.311658143997192,3,,,,,,,,,,,,,,,,
,3959117159.09886,10.0019884109497,1000.22119140625,,,6,,,,30.738023492992,,,10,,,,,,,,,,,,,,,,,,,,,,9.99584579467773,10.0035266876221,1000.22119140625,1000.22119140625,,,4.89155673980713,,1,0,0,0,0,34.7018585205078,1,1,1,10.0039262771606,0,9.99882078170776,-39.9984016418457,1,0.00471485963179947,0.000232513034010623,0.00471766851008379,0.000232509964358969,0.955672383308411,0.972631394863129,30.604700088501,5.53215169906616,30,4,200,-0.000543834990821779,-1.95943772792816,0.309790164232254,1,,,,,,,,,,,,,,,,
,3959117280.76055,10.002893447876,1000.22119140625,,,6,,,,30.738023492992,,,10,,,,,,,,,,,,,,,,,,,,,,9.99601554870605,10.0046224594116,1000.22119140625,1000.22119140625,,,4.89326095581055,,1,0,0,0,0.000152587890625,33.7243423461914,1,1,1,10.0039472579956,0,9.99964057074653,-35.9952011108398,1,0.00470433167272982,0.000133957016395438,0.00470761999273509,0.000133957698353549,0.953161299228668,0.971563816070557,30.595775604248,9.2744140625,30,4,200,-0.000453545799246058,-1.95615220069885,0.308390200138092,3,,,,,,,,,,,,,,,,
,3959117410.61769,10.0033020973206,1000.22119140625,,,6,,,,30.738023492992,,,10,,,,,,,,,,,,,,,,,,,,,,9.99678802490234,10.0043277740479,1000.22119140625,1000.22119140625,,,4.89211988449097,,1,0,0,0,0.00030517578125,32.7468223571777,1,1,1,10.005030632019,0,9.9999095916748,-29.9952011108398,1,0.0046883309584128,0.00023125893825466,0.00469192687878946,0.000231255749731189,0.950678527355194,0.970432877540588,30.587366104126,5.36309909820557,30,4,200,-0.00157654867507517,-1.95149552822113,0.30560889840126,1,,,,,,,,,,,,,,,,
,3959117538.98511,10.0035352706909,1000.22119140625,,,6,,,,30.738023492992,,,10,,,,,,,,,,,,,,,,,,,,,,9.99550056457519,10.0046730041504,1000.22119140625,1000.22119140625,,,4.89440536499023,,1,0,0,0,0.000152587890625,33.7243423461914,1,1,1,10.0048713684082,0,9.99977084568569,-25.9968013763428,1,0.00467187269512888,0.000133057653490757,0.00467582019964151,0.000133059638253577,0.949342548847198,0.969838678836823,30.5825386047363,0,30,4,200,-0.00149978790432215,-1.94681298732758,0.302688241004944,3,,,,,,,,,,,,,,,,
,3959117670.89757,10.0019640922546,1000.22119140625,,,6,,,,30.738023492992,,,10,,,,,,,,,,,,,,,,,,,,,,9.99646091461182,10.0012540817261,1000.22119140625,1000.22119140625,,,4.8925666809082,,1,0,0,0,0.000152587890625,33.2355842590332,1,1,1,10.0039367675781,0,9.99847020043267,-19.9968013763428,1,0.00465928805366886,0.000229849698593085,0.00466310206484315,0.000229834437438948,0.948664844036102,0.970519304275513,30.5776901245117,0,30,4,200,-0.000685611623339355,-1.94394433498383,0.299993246793747,1,,,,,,,,,,,,,,,,
,3959117798.00837,10.0016417503357,1000.22119140625,,,6,,,,30.738023492992,,,10,,,,,,,,,,,,,,,,,,,,,,9.99649620056152,10.0041475296021,1000.22119140625,1000.22119140625,,,4.89326238632202,,1,0,0,0,0.0002288818359375,33.7243423461914,1,1,1,10.0034923553467,0,9.9998727021394,-15.9984006881714,1,0.00465763060345721,0.000132657163163817,0.00466130850608237,0.000132639297238268,0.948579728603363,0.971730351448059,30.5735530853271,0.205164059996605,30,4,200,-0.000484530930407345,-1.94411909580231,0.298614680767059,3,,,,,,,,,,,,,,,,
,3959117929.16826,10.0011343955994,1000.22119140625,,,6,,,,30.738023492992,,,10,,,,,,,,,,,,,,,,,,,,,,9.99599647521973,10.0021381378174,1000.22119140625,1000.22119140625,,,4.89134550094604,,1,0,0,0,7.62939453125E-5,33.7243423461914,1,1,1,10.003228187561,0,9.99860615200467,-9.99840068817139,1,0.0046698499851564,0.00023037435801765,0.00467463010132249,0.000230373372618327,0.948361873626709,0.975198090076447,30.5651912689209,0,30,4,200,-0.000754559179767966,-1.95119798183441,0.299987018108368,1,,,,,,,,,,,,,,,,
,3959118052.74773,10.002546787262,1000.22119140625,,,6,,,,30.738023492992,,,10,,,,,,,,,,,,,,,,,,,,,,9.99584674835205,10.0042715072632,1000.22119140625,1000.22119140625,,,4.8927493095398,,1,0,0,0,0,33.2355842590332,1,1,1,10.0035409927368,0,9.99950188856858,-6.00000047683716,1,0.00467382368479167,0.000133118827977389,0.0046788207748214,0.000133120259546028,0.948521792888641,0.976811647415161,30.5625534057617,,30,4,200,-4.36395202996209E-5,-1.95451354980469,0.3001509308815,3,,,,,,,,,,,,,,,,
,3959118181.94484,10.0029902458191,1000.22119140625,,,6,,,,30.738023492992,,,10,,,,,,,,,,,,,,,,,,,,,,9.99665546417236,10.0045175552368,1000.22119140625,1000.22119140625,,,4.89083814620972,,1,0,0,0,0.000152587890625,33.7243423461914,1,1,1,10.0045175552368,0,9.99979429244995,0,1,0.00468376271689452,0.000231043852861634,0.00468892958010626,0.000231055225922235,0.949792563915253,0.97957319021225,30.563549041748,,30,4,200,-0.00149149587377906,-1.96037042140961,0.300810188055038,1,,,,,,,,,,,,,,,,
,3959118309.24689,10.0036482810974,1000.22119140625,,,6,,,,30.738023492992,,,10,,,,,,,,,,,,,,,,,,,,,,9.99528312683105,10.0050630569458,1000.22119140625,1000.22119140625,,,4.89341735839844,,1,0,0,0,0.00030517578125,33.2355842590332,1,1,1,10.0050573348999,0,9.99964067671034,3.99840021133423,1,0.00469322350911939,0.000133649426353612,0.00469808139445129,0.000133653694218352,0.951799392700195,0.982091546058655,30.5680084228516,0,30,4,200,-0.00104810285847634,-1.96558475494385,0.301373302936554,3,,,,,,,,,,,,,,,,
,3959118441.83289,10.0024170875549,1000.22119140625,,,6,,,,30.738023492992,,,10,,,,,,,,,,,,,,,,,,,,,,9.99646377563477,10.0022315979004,1000.22119140625,1000.22119140625,,,4.8911190032959,,1,0,0,0,0,33.2355842590332,1,1,1,10.0046043395996,0,9.99890910254584,9.99840068817139,1,0.00470751992611943,0.000232152702422455,0.00471179195257835,0.000232157136996426,0.955516278743744,0.985689520835876,30.5779590606689,0,30,4,200,-0.000912584830075502,-1.97252941131592,0.30225545167923,1,,,,,,,,,,,,,,,,
,3959118567.49626,10.0026574134827,1000.22119140625,,,6,,,,30.738023492992,,,10,,,,,,,,,,,,,,,,,,,,,,9.99650859832764,10.0041360855103,1000.22119140625,1000.22119140625,,,4.89262342453003,,1,0,0,0,0.000152587890625,33.2355842590332,1,1,1,10.0041007995605,0,9.99975340706962,13.9968004226685,1,0.0047183881412596,0.000134326798799863,0.00472193193695425,0.000134318692511835,0.958277940750122,0.989046275615692,30.5848789215088,8.36081198940519E-7,30,4,200,-0.000840447028167546,-1.97767698764801,0.303194642066956,3,,,,,,,,,,,,,,,,
,3959118700.23135,10.0009088516235,1000.22119140625,,,6,,,,30.738023492992,,,10,,,,,,,,,,,,,,,,,,,,,,9.99569892883301,10.0019006729126,1000.22119140625,1000.22119140625,,,4.89040184020996,,1,0,0,0,0.00030517578125,33.2355842590332,1,1,1,10.0033435821533,0,9.99827353159587,19.9968013763428,1,0.00474198821170145,0.000233804041239606,0.00474563621659055,0.000233805678639965,0.960433304309845,0.993461668491364,30.5901184082031,2.95023414764728E-6,30,4,200,-0.000723441364243627,-1.87611222267151,0.305492371320724,1,,,,,,,,,,,,,,,,
,3959118826.60967,10.0025372505188,1000.22119140625,,,6,,,,30.738023492992,,,10,,,,,,,,,,,,,,,,,,,,,,9.99613189697266,10.0041351318359,1000.22119140625,1000.22119140625,,,4.89221143722534,,1,0,0,0,0,31.7693061828613,1,1,1,10.0037183761597,0,9.99982017940945,24.0000019073486,1,0.00476198819260263,0.000135543036351978,0.00476518891748528,0.000135543593997435,0.962968528270721,0.993944525718689,30.5995140075684,6.79373215461965E-6,30,4,200,-0.000185393742867745,-1.88527774810791,0.309615224599838,3,,,,,,,,,,,,,,,,
,3959118955.71681,10.0027437210083,1000.22119140625,,,6,,,,30.738023492992,,,10,,,,,,,,,,,,,,,,,,,,,,9.99680995941162,10.0043535232544,1000.22119140625,1000.22119140625,,,4.89093494415283,,1,0,0,0,0.000152587890625,33.2355842590332,1,1,1,10.0045080184937,0,9.9996111869812,29.9952011108398,1,0.00479019484562486,0.000236131418190551,0.00479282009976047,0.000236133624933438,0.966130971908569,0.991593837738037,30.6140213012695,0,30,4,200,-0.00122490967623889,-1.89828813076019,0.312528371810913,1,,,,,,,,,,,,,,,,
,3959119083.14532,10.0023288726807,1000.22119140625,,,6,,,,30.738023492992,,,10,,,,,,,,,,,,,,,,,,,,,,9.9957857131958,10.0051755905151,1000.22119140625,1000.22119140625,,,4.89350605010986,,1,0,0,0,0.000152587890625,33.2355842590332,1,1,1,10.0045347213745,0,9.99971396582467,33.9984016418457,1,0.00480941801060714,0.000136864559467221,0.0048116031034358,0.000136868851583347,0.96908175945282,0.989481329917908,30.6283092498779,0,30,4,200,-0.00167013693135232,-1.90704166889191,0.314534187316895,3,,,,,,,,,,,,,,,,
,3959119212.94478,10.00252866745,1000.22119140625,,,6,,,,30.738023492992,,,10,,,,,,,,,,,,,,,,,,,,,,9.99629688262939,10.0022964477539,1000.22119140625,1000.22119140625,,,4.89238357543945,,1,0,0,0,7.62939453125E-5,33.2355842590332,1,1,1,10.0039253234863,0,9.99905225965712,39.9984016418457,1,0.00483182377127534,0.000238118592755,0.0048328907789778,0.000238118601688593,0.975461363792419,0.987320184707642,30.6588172912598,0,30,4,200,-0.0009602434001863,-1.91744124889374,0.316253006458282,1,,,,,,,,,,,,,,,,
,3959119340.94118,10.0028715133667,1000.22119140625,,,6,,,,30.738023492992,,,10,,,,,,,,,,,,,,,,,,,,,,9.9963550567627,10.0041284561157,1000.22119140625,1000.22119140625,,,4.89334869384766,,1,0,0,0,0.000152587890625,32.7468223571777,1,1,1,10.0044498443604,0,9.99967490302192,43.9968032836914,1,0.00484897937468473,0.000137954139715995,0.00484942689467774,0.000137948435589936,0.979236781597137,0.987196981906891,30.6763439178467,,30,4,200,-0.000707878672983497,-1.92488825321198,0.318039447069168,3,,,,,,,,,,,,,,,,
,3959119474.18751,10.0009145736694,1000.22119140625,,,6,,,,30.738023492992,,,10,,,,,,,,,,,,,,,,,,,,,,9.99594306945801,10.0031509399414,1000.22119140625,1000.22119140625,,,4.89001750946045,,1,0,0,0,0.00030517578125,33.2355842590332,1,1,1,10.0031509399414,0,9.99884099960327,49.9968032836914,1,0.00486732520627938,0.000239834239267301,0.00486758492800852,0.000239828845899019,0.982105314731598,0.98701685667038,30.6915836334229,0,30,4,200,-0.000613671145401895,-1.93273568153381,0.319846928119659,1,,,,,,,,,,,,,,,,
,3959119601.30087,10.00235414505,1000.22119140625,,,6,,,,30.738023492992,,,10,,,,,,,,,,,,,,,,,,,,,,9.99605369567871,10.0041589736938,1000.22119140625,1000.22119140625,,,4.89239168167114,,1,0,0,0,0.000152587890625,33.2355842590332,1,1,1,10.0038595199585,0,9.99990382017913,53.9952011108398,1,0.00488214858458201,0.000138888648662854,0.00488234130307462,0.000138887874253575,0.982701659202576,0.985537767410278,30.7022533416748,0,30,4,200,-0.000493731000460684,-1.93935465812683,0.322078943252563,3,,,,,,,,,,,,,,,,
,3959119729.11462,10.0022578239441,1000.22119140625,,,6,,,,30.738023492992,,,10,,,,,,,,,,,,,,,,,,,,,,9.99695205688477,10.002272605896,1000.22119140625,1000.22119140625,,,4.88788986206055,,1,0,0,0,0.000152587890625,33.7243423461914,1,1,1,10.0041437149048,0,9.99913681877984,59.9952011108398,1,0.00489727978932749,0.000241304304645017,0.00489730987720929,0.000241304380634424,0.98354297876358,0.983900964260101,30.7251644134521,8.30379485705635E-6,30,4,200,-0.00152669101953506,-1.94576120376587,0.323342859745026,1,,,,,,,,,,,,,,,,
,3959119854.04907,10.0028171539307,1000.22119140625,,,6,,,,30.738023492992,,,10,,,,,,,,,,,,,,,,,,,,,,9.99575519561768,10.0045652389526,1000.22119140625,1000.22119140625,,,4.89295816421509,,1,0,0,0,0.000152587890625,34.2131004333496,1,1,1,10.0040216445923,0,9.99993697802226,63.9984016418457,1,0.00490445679348123,0.000139521625976126,0.00490446410284809,0.000139521766578739,0.983426094055176,0.983455240726471,30.741720199585,0,30,4,200,-0.00158306234516203,-1.94881081581116,0.323369741439819,3,,,,,,,,,,,,,,,,
,3959119986.51832,10.0024652481079,1000.22119140625,,,6,,,,30.738023492992,,,10,,,,,,,,,,,,,,,,,,,,,,9.99656867980957,10.0047035217285,1000.22119140625,1000.22119140625,,,4.89175653457642,,1,0,0,0,0.00030517578125,33.2355842590332,1,1,1,10.0047035217285,0,9.99957828521729,69.998405456543,1,0.00490517866262361,0.000241699696365179,0.00490549037885306,0.000241703130925863,0.982059240341187,0.985059320926666,30.775463104248,5.54756355285645,30,4,200,-0.00144526874646544,-1.94870662689209,0.3214291036129,1,,,,,,,,,,,,,,,,
,3959120112.9658,10.0035490989685,1000.22119140625,,,6,,,,30.738023492992,,,10,,,,,,,,,,,,,,,,,,,,,,9.99550056457519,10.0049514770508,1000.22119140625,1000.22119140625,,,4.89307928085327,,1,0,0,0,0.000152587890625,33.2355842590332,1,1,1,10.0048999786377,0,9.99977357046945,73.9968032836914,1,0.00490192422318559,0.000139456772953594,0.00490240699261241,0.000139454801427588,0.980546057224274,0.987619340419769,30.7946701049805,0.107688665390015,30,4,200,-0.00101921218447387,-1.94721043109894,0.319444477558136,3,,,,,,,,,,,,,,,,
,3959120241.98865,10.0040369033813,1000.22119140625,,,6,,,,30.738023492992,,,10,,,,,,,,,,,,,,,,,,,,,,9.99712753295898,10.0053310394287,1000.22119140625,1000.22119140625,,,4.8915581703186,,1,0,0,0,0.0142669677734375,34.7018585205078,1,1,1,10.0053310394287,0,10.0005983352661,79.9968032836914,1,0.00490216036571132,0.00024155939123499,0.00490272580139654,0.000241558974889818,0.980215847492218,0.987455904483795,30.7958374023438,5.54939985275269,30,4,200,-9.86224185908213E-5,-1.94852590560913,0.317990571260452,1,,,,,,,,,,,,,,,,
,3959120366.16429,10.0030488967896,1000.22119140625,,,6,,,,30.738023492992,,,10,,,,,,,,,,,,,,,,,,,,,,9.99571514129639,10.0044927597046,1000.22119140625,1000.22119140625,,,4.89094924926758,,1,0,0,0,0.000152587890625,34.2131004333496,1,1,1,10.0042457580566,0,9.9998240837684,84.0000076293945,1,0.00490205494144358,0.000139461104290346,0.00490267349050368,0.00013946235514948,0.980322241783142,0.987635970115662,30.7958011627197,INF,30,4,200,-0.00071407447103411,-1.9495210647583,0.317238926887512,3,,,,,,,,,,,,,,,,
,3959120494.5735,10.0029902458191,1000.22119140625,,,6,,,,30.738023492992,,,10,,,,,,,,,,,,,,,,,,,,,,9.99685001373291,10.0031261444092,1000.22119140625,1000.22119140625,,,4.89120626449585,,1,0,0,0,0,33.7243423461914,1,1,1,10.0050401687622,0,9.9997525744968,90.0000076293945,1,0.00490186400892798,0.000241543455259156,0.0049023334213222,0.000241538684337408,0.980488002300262,0.987762331962585,30.7953987121582,0.186541005969048,30,4,200,-0.000704399426467717,-1.9505535364151,0.315933644771576,1,,,,,,,,,,,,,,,,
,3959120517.54414,10.0032925605774,1000.22119140625,,,6,,,,30.738023492992,,,10,,,,,,,,,,,,,,,,,,,,,,9.9954137802124,10.0046329498291,1000.22119140625,1000.22119140625,,,4.89110851287842,,1,0,0,0,0.0008392333984375,33.2355842590332,1,1,1,10.0046167373657,0,9.99985243723943,90.0000076293945,1,0.00490202645875761,0.00013945941561644,0.00490257525232317,0.000139459073390643,0.980625808238983,0.987891435623169,30.7951183319092,0,30,4,200,-0.000529024109710008,-1.95070362091064,0.31596314907074,3,,,,,,,,,,,,,,,,