File: PPMS_Data_and_Plotting/Data/RuCl3/Data/Magnetisation/Rotator/TB001_RuCl3_H-parra-ab_61p2_mg_14-06-25_ZFCW_150K.dat
[Header]
; MPMS3 Data File (default extension .dat)
; Copyright (c) 2007, Quantum Design, Inc. All rights reserved.
TITLE,
FILEOPENTIME,3959147215.69308,06/15/2025,11:06 am
BYAPP,MPMS3 w/ AC,1.0,1.1
INFO,MPMS3 Measurement Release 1.2.2 Build 0, MultiVu Release 2.3.5.2,APPNAME
INFO,Linear Motor Servo Controller,MOTOR_MODULE_NAME
INFO,3101-100 N4,MOTOR_HW_VERSION
INFO,MMC1299,MOTOR_SERIAL_NUMBER
INFO,01.04.28,MOTOR_SOFTWARE_VERSION
INFO,Quantum Design Squid Module,SQUID_MODULE_NAME
INFO,3101-501 B0,SQUID_HW_VERSION
INFO,SQM364,SQUID_SERIAL_NUMBER
INFO,01.03.04,SQUID_SOFTWARE_VERSION
INFO,Quantum Design VSM Oven,OVEN_MODULE_NAME
INFO,3101-201 A3,OVEN_HW_VERSION
INFO,OVB387,OVEN_SERIAL_NUMBER
INFO,01.07.07,OVEN_SOFTWARE_VERSION
INFO,SQUID AC,AC_MODULE_NAME
INFO,3101-401 G0,AC_HW_VERSION
INFO,SAC242,AC_SERIAL_NUMBER
INFO,SQUID AC 00.95.11,AC_SOFTWARE_VERSION
INFO,TCI374,COIL_SERIAL_NUMBER
INFO,0,MOMENT_UNITS
INFO,RuCl3,SAMPLE_MATERIAL
INFO,single crystal,SAMPLE_COMMENT
INFO,61.2,SAMPLE_MASS
INFO,,SAMPLE_VOLUME
INFO,,SAMPLE_MOLECULAR_WEIGHT
INFO,,SAMPLE_SIZE
INFO,,SAMPLE_SHAPE
INFO,Rotator,SAMPLE_HOLDER
INFO,Standard,SAMPLE_HOLDER_DETAIL
INFO,67.44,SAMPLE_OFFSET
DATATYPE,COMMENT,1
DATATYPE,TIME,2
STARTUPAXIS,X,2
STARTUPAXIS,Y1,5
FIELDGROUP, VSM,2,3,4,5,6,8,9,10,11,14,15
FIELDGROUP, DC, 2,3,4,14,56,57,58,59,60,61,62,63,64,65,66,67,68,69
FIELDGROUP, AC, 2,3,4,11,16,17,18,19,20,21,22,23,24,25,26,27,28,29,30
STARTUPGROUP, All
[Data]
Comment,Time Stamp (sec),Temperature (K),Magnetic Field (Oe),Moment (emu),M. Std. Err. (emu),Transport Action,Averaging Time (sec),Frequency (Hz),Peak Amplitude (mm),Center Position (mm),Lockin Signal' (V),Lockin Signal (V),Range,M. Quad. Signal (emu),AC Moment (emu),AC M. Std Err. (emu),AC Phase (deg),AC Phase Std. Err. (deg),AC Susceptibility (emu/Oe),AC Suscept. Std Err. (emu/Oe),AC X' (emu/Oe),AC X' Std Err. (emu/Oe),AC X'' (emu/Oe),AC X'' Std Err. (emu/Oe),AC Drive (Oe),AC Frequency (Hz),AC Averaging Time (sec),AC Cycles,AC Range,AC Measure Type,AC Signal' (V),AC Signal'' (V),AC Trim Coil Ratio,AC Trim Coil Phase,Min. Temperature (K),Max. Temperature (K),Min. Field (Oe),Max. Field (Oe),Mass (grams),Motor Lag (deg),Pressure (Torr),Measure Count,Measurement Number,SQUID Status (code),Motor Status (code),Measure Status (code),Motor Current (amps),Motor Temp. (C),Temp. Status (code),Field Status (code),Chamber Status (code),Chamber Temp (K),Redirection State,Average Temp (K),Rotation Angle (deg),Rotator state,DC Moment Fixed Ctr (emu),DC Moment Err Fixed Ctr (emu),DC Moment Free Ctr (emu),DC Moment Err Free Ctr (emu),DC Fixed Fit,DC Free Fit,DC Calculated Center (mm),DC Calculated Center Err (mm),DC Scan Length (mm),DC Scan Time (s),DC Number of Points,DC Squid Drift,DC Min V (V),DC Max V (V),DC Scans per Measure,He3 temp,Map 02,Map 03,Map 04,Map 05,Map 06,Map 07,Map 08,Map 09,Map 10,Map 11,Map 12,Map 13,Map 14,Map 15,Map 16
,3959148597.54018,149.993362426758,999.553466796875,,,6,,,,30.8585091895643,,,10,,,,,,,,,,,,,,,,,,,,,,149.987991333008,149.997848510742,999.553466796875,999.553466796875,,,6.3680419921875,,1,0,0,0,0.000152587890625,35.190616607666,1,1,1,149.989456176758,0,149.994632297092,-299.995208740234,1,0.00103546817062425,5.10276326989167E-5,0.00103558032314553,5.10292071331931E-5,0.976763367652893,0.98037576675415,30.90549659729,0,30,4,200,-0.000372700858861208,-0.449020445346832,0.0339602045714855,1,,,,,,,,,,,,,,,,
,3959148722.44631,149.993560791016,999.553466796875,,,6,,,,30.8585091895643,,,10,,,,,,,,,,,,,,,,,,,,,,149.986785888672,150.002792358398,999.553466796875,999.553466796875,,,6.3702507019043,,1,0,0,0,0.00030517578125,35.190616607666,1,1,1,149.991180419922,0,149.995775575991,-295.996826171875,1,0.00103267188335301,2.93796149892466E-5,0.00103273281012595,2.93799269913494E-5,0.97931045293808,0.981797337532044,30.8956832885742,0,30,4,200,-0.000244288996327668,-0.447552680969238,0.0341056101024151,3,,,,,,,,,,,,,,,,
,3959148849.09395,149.997764587402,999.553466796875,,,6,,,,30.8585091895643,,,10,,,,,,,,,,,,,,,,,,,,,,149.986968994141,150.008224487305,999.553466796875,999.553466796875,,,6.37177276611328,,1,0,0,0,7.62939453125E-5,35.190616607666,1,1,1,149.9873046875,0,149.999740600586,-289.996826171875,1,0.00103620159177286,5.10602917094715E-5,0.00103625107941734,5.10611592235339E-5,0.979905307292938,0.981499075889587,30.8881378173828,,30,4,200,-0.00025278065004386,-0.448962360620499,0.0344107858836651,1,,,,,,,,,,,,,,,,
,3959148970.86475,149.997611999512,999.553466796875,,,6,,,,30.8585091895643,,,10,,,,,,,,,,,,,,,,,,,,,,149.991668701172,150.008590698242,999.553466796875,999.553466796875,,,6.37383556365967,,1,0,0,0,0.000152587890625,35.6793746948242,1,1,1,149.994445800781,0,150.000226621275,-285.998413085938,1,0.00103659576097889,2.94915674493889E-5,0.00103663123447063,2.94918826970905E-5,0.978790581226349,0.97993016242981,30.8843955993652,0,30,4,200,-0.000393750058719888,-0.45017346739769,0.0341506265103817,3,,,,,,,,,,,,,,,,
,3959149098.53235,149.998344421387,999.553466796875,,,6,,,,30.8585091895643,,,10,,,,,,,,,,,,,,,,,,,,,,149.986541748047,150.009414672852,999.553466796875,999.553466796875,,,6.37492609024048,,1,0,0,0,0.01129150390625,35.190616607666,1,1,1,149.987274169922,0,150.000764634874,-279.998413085938,1,0.00103921720124786,5.12144168647468E-5,0.00103929237163787,5.12148672086975E-5,0.97510814666748,0.977805435657501,30.9010028839111,0,30,4,200,-0.000480464892461896,-0.451507329940796,0.0338472947478294,1,,,,,,,,,,,,,,,,
,3959149221.98528,149.999252319336,999.553466796875,,,6,,,,30.8585091895643,,,10,,,,,,,,,,,,,,,,,,,,,,149.990356445313,150.009750366211,999.553466796875,999.553466796875,,,6.37719583511353,,1,0,0,0,0.000152587890625,35.190616607666,1,1,1,149.996017456055,0,150.000349191519,-275.995208740234,1,0.00103750027615392,2.95217627803742E-5,0.00103765010192769,2.95223054728659E-5,0.972580432891846,0.977640330791473,30.9183082580566,0,30,4,200,-0.000635999313089997,-0.451452881097794,0.0334218330681324,3,,,,,,,,,,,,,,,,
,3959149347.63061,149.997741699219,999.553466796875,,,6,,,,30.8585091895643,,,10,,,,,,,,,,,,,,,,,,,,,,149.98518371582,150.009689331055,999.553466796875,999.553466796875,,,6.37832736968994,,1,0,0,0,7.62939453125E-5,35.190616607666,1,1,1,149.985794067383,0,149.999415079753,-269.995208740234,1,0.00103686208917277,5.11077672640571E-5,0.00103717579908672,5.11092900060787E-5,0.968575358390808,0.978965222835541,30.9466075897217,0.164226427674294,30,4,200,-0.000468230020487681,-0.451113164424896,0.0329417884349823,1,,,,,,,,,,,,,,,,
,3959149473.14972,149.998420715332,999.553466796875,,,6,,,,30.8585091895643,,,10,,,,,,,,,,,,,,,,,,,,,,149.986557006836,150.009552001953,999.553466796875,999.553466796875,,,6.3809061050415,,1,0,0,0,0.000152587890625,34.2131004333496,1,1,1,149.993942260742,0,149.998851634838,-265.996826171875,1,0.0010340068653719,2.94284411510385E-5,0.00103444174331336,2.94290630224003E-5,0.965875804424286,0.980859458446503,30.9652805328369,0,30,4,200,-0.000287581235170364,-0.449979066848755,0.0328314900398254,3,,,,,,,,,,,,,,,,
,3959149600.65069,149.998687744141,999.553466796875,,,6,,,,30.8635757340929,,,10,,,,,,,,,,,,,,,,,,,,,,149.98567199707,150.010925292969,999.553466796875,999.553466796875,,,6.38163137435913,,1,0,0,0,0.00030517578125,35.6793746948242,1,1,1,149.986450195313,0,150.000593397352,-259.996826171875,1,0.001032341733803,5.08931248669465E-5,0.00103291112169649,5.08961904694967E-5,0.963834166526794,0.98193234205246,30.9821147918701,0,30,4,200,-0.000311040377710015,-0.449304491281509,0.0319482050836086,1,,,,,,,,,,,,,,,,
,3959149726.31224,149.999145507813,999.553466796875,,,6,,,,30.8635757340929,,,10,,,,,,,,,,,,,,,,,,,,,,149.989456176758,150.010498046875,999.553466796875,999.553466796875,,,6.3838849067688,,1,0,0,0,0,35.190616607666,1,1,1,149.99609375,0,150.001055203951,-255.998413085938,1,0.00103000424091604,2.93183610770795E-5,0.00103062396901379,2.93199816672964E-5,0.96223247051239,0.981699466705322,30.9886035919189,0,30,4,200,-0.000306276342598721,-0.448788464069366,0.031545165926218,3,,,,,,,,,,,,,,,,
,3959149849.28987,149.998580932617,999.553466796875,,,6,,,,30.8635757340929,,,10,,,,,,,,,,,,,,,,,,,,,,149.986877441406,150.009780883789,999.553466796875,999.553466796875,,,6.38521528244019,,1,0,0,0,0.000152587890625,35.190616607666,1,1,1,149.988052368164,0,150.000671386719,-249.998413085938,1,0.00102746401687636,5.06644410650245E-5,0.00102822760803611,5.06669406354464E-5,0.957892835140228,0.980318248271942,31.0044918060303,5.36446046829224,30,4,200,-0.00042130981455557,-0.447744101285934,0.0306562036275864,1,,,,,,,,,,,,,,,,
,3959149975.23808,149.998107910156,999.553466796875,,,6,,,,30.8635757340929,,,10,,,,,,,,,,,,,,,,,,,,,,149.988800048828,150.009170532227,999.553466796875,999.553466796875,,,6.38671970367432,,1,0,0,0,0.00030517578125,35.190616607666,1,1,1,149.995178222656,0,150.000965824834,-245.995208740234,1,0.00102303753901914,2.91297217629908E-5,0.00102395008056832,2.9131601365989E-5,0.95430999994278,0.979130804538727,31.0173797607422,5.56932497024536,30,4,200,-0.000451671483460814,-0.446569591760635,0.0297145936638117,3,,,,,,,,,,,,,,,,
,3959150102.07239,149.99772644043,999.553466796875,,,6,,,,30.8635757340929,,,10,,,,,,,,,,,,,,,,,,,,,,149.98551940918,150.009811401367,999.553466796875,999.553466796875,,,6.38744449615479,,1,0,0,0,0,35.6793746948242,1,1,1,149.986541748047,0,150.000323486328,-239.995208740234,1,0.0010170971133868,5.01762514770618E-5,0.00101827031059595,5.01791351727381E-5,0.948154151439667,0.97762143611908,31.040901184082,1.12853126665868E-6,30,4,200,-0.000402034347644076,-0.444175183773041,0.0283141098916531,1,,,,,,,,,,,,,,,,
,3959150226.71005,149.998908996582,999.553466796875,,,6,,,,30.8635757340929,,,10,,,,,,,,,,,,,,,,,,,,,,149.989486694336,150.012771606445,999.553466796875,999.553466796875,,,6.38952207565308,,1,0,0,0,0,35.6793746948242,1,1,1,149.996078491211,0,150.001096872183,-235.996810913086,1,0.00101174883828231,2.88220231746468E-5,0.0010130930522449,2.88240860293032E-5,0.944868206977844,0.976941525936127,31.0538749694824,0,30,4,200,-0.000342453742632642,-0.442414879798889,0.0274342894554138,3,,,,,,,,,,,,,,,,
,3959150354.45291,149.998527526855,999.553466796875,,,6,,,,30.8635757340929,,,10,,,,,,,,,,,,,,,,,,,,,,149.984588623047,150.011703491211,999.553466796875,999.553466796875,,,6.38993549346924,,1,0,0,0,0.000457763671875,35.6793746948242,1,1,1,149.9853515625,0,150.000389946832,-229.996810913086,1,0.00100756288083067,4.97254036049531E-5,0.00100911918968835,4.9731138299446E-5,0.941097438335419,0.975117743015289,31.0669612884521,0.0174636356532574,30,4,200,-0.000324469525367022,-0.440752744674683,0.0261761769652367,1,,,,,,,,,,,,,,,,
,3959150480.01099,149.998611450195,999.553466796875,,,6,,,,30.8635757340929,,,10,,,,,,,,,,,,,,,,,,,,,,149.986770629883,150.010940551758,999.553466796875,999.553466796875,,,6.3914647102356,,1,0,0,0,7.62939453125E-5,35.6793746948242,1,1,1,149.994918823242,0,149.999647412981,-225.998413085938,1,0.00100467692019948,2.86284079379657E-5,0.00100629969723344,2.86329604179366E-5,0.940120816230774,0.973886728286743,31.0688323974609,6.01129249844234E-6,30,4,200,-0.000204189767828211,-0.440203815698624,0.0259019397199154,3,,,,,,,,,,,,,,,,
,3959150607.27221,149.99951171875,999.553466796875,,,6,,,,30.8635757340929,,,10,,,,,,,,,,,,,,,,,,,,,,149.98600769043,150.012344360352,999.553466796875,999.553466796875,,,6.39251565933228,,1,0,0,0,0,34.7018585205078,1,1,1,149.986679077148,0,150.000998602973,-219.998413085938,1,0.00100210527970752,4.9469049242757E-5,0.00100379255891674,4.94735969409867E-5,0.936812043190002,0.971371591091156,31.078218460083,0,30,4,200,-0.000467365054646507,-0.439231067895889,0.0247541237622499,1,,,,,,,,,,,,,,,,
,3959150729.83817,149.99781036377,999.553466796875,,,6,,,,30.8635757340929,,,10,,,,,,,,,,,,,,,,,,,,,,149.990142822266,150.010711669922,999.553466796875,999.553466796875,,,6.3939356803894,,1,0,0,0,0.00030517578125,35.6793746948242,1,1,1,149.995254516602,0,150.000254494803,-215.995208740234,1,0.000998387857778228,2.84604497767033E-5,0.00100015236903257,2.84618180782278E-5,0.93387246131897,0.969234049320221,31.0866088867188,0,30,4,200,-0.000420748081523925,-0.43836921453476,0.0241103656589985,3,,,,,,,,,,,,,,,,
,3959150858.79438,149.999206542969,999.553466796875,,,6,,,,30.8687038625824,,,10,,,,,,,,,,,,,,,,,,,,,,149.984008789062,150.012619018555,999.553466796875,999.553466796875,,,6.39443254470825,,1,0,0,0,0.000152587890625,35.6793746948242,1,1,1,149.985794067383,0,149.998918151855,-209.995208740234,1,0.000994523384913493,4.9116396861498E-5,0.00099650380533661,4.9121805585768E-5,0.930214107036591,0.966490685939789,31.1022644042969,5.57649326324463,30,4,200,-0.000465564196929336,-0.436777055263519,0.0234167948365211,1,,,,,,,,,,,,,,,,
,3959150984.87959,149.998542785645,999.553466796875,,,6,,,,30.8687038625824,,,10,,,,,,,,,,,,,,,,,,,,,,149.989456176758,150.011764526367,999.553466796875,999.553466796875,,,6.39540386199951,,1,0,0,0,0.000152587890625,35.6793746948242,1,1,1,149.99365234375,0,150.000961868851,-205.996810913086,1,0.000990227117994422,2.82403537495107E-5,0.000992382904757548,2.824446415297E-5,0.927499711513519,0.965198993682861,31.1116180419922,0,30,4,200,-0.000386389292543754,-0.435709357261658,0.0226421896368265,3,,,,,,,,,,,,,,,,
,3959151111.23679,149.99934387207,999.553466796875,,,6,,,,30.8687038625824,,,10,,,,,,,,,,,,,,,,,,,,,,149.985549926758,150.012359619141,999.553466796875,999.553466796875,,,6.39612054824829,,1,0,0,0,0.0002288818359375,36.6568908691406,1,1,1,149.986328125,0,150.001234266493,-199.996810913086,1,0.000989756594105362,4.88983743439841E-5,0.000992103004418287,4.89075279566035E-5,0.925316989421844,0.964914619922638,31.1209144592285,0,30,4,200,-0.000265280774328858,-0.435883611440659,0.0219139605760574,1,,,,,,,,,,,,,,,,
,3959151237.61576,149.997619628906,999.553466796875,,,6,,,,30.8687038625824,,,10,,,,,,,,,,,,,,,,,,,,,,149.988067626953,150.010101318359,999.553466796875,999.553466796875,,,6.3961968421936,,1,0,0,0,0.0002288818359375,35.190616607666,1,1,1,149.993255615234,0,149.999500981084,-195.998413085938,1,0.000988117978332592,2.81860909914528E-5,0.000990497077541228,2.81914875512049E-5,0.924685597419739,0.964491188526154,31.1227741241455,0,30,4,200,-0.000334469077643007,-0.435573667287827,0.0218688044697046,3,,,,,,,,,,,,,,,,
,3959151365.3114,149.997657775879,999.553466796875,,,6,,,,30.8687038625824,,,10,,,,,,,,,,,,,,,,,,,,,,149.983612060547,150.011169433594,999.553466796875,999.553466796875,,,6.39731884002686,,1,0,0,0,0.000152587890625,35.6793746948242,1,1,1,149.984146118164,0,150.000120374891,-189.998413085938,1,0.000990980135065619,4.89649902249342E-5,0.0009934527900928,4.89741042514277E-5,0.923653602600098,0.964883208274841,31.1276245117188,,30,4,200,-0.000466848374344409,-0.436890244483948,0.0219873879104853,1,,,,,,,,,,,,,,,,
,3959151489.30258,149.998184204102,999.553466796875,,,6,,,,30.8687038625824,,,10,,,,,,,,,,,,,,,,,,,,,,149.987045288086,150.010269165039,999.553466796875,999.553466796875,,,6.39773511886597,,1,0,0,0,0.00030517578125,35.6793746948242,1,1,1,149.994155883789,0,149.9997309932,-186.000015258789,1,0.000990678553546676,2.82631144484802E-5,0.000993179305482997,2.82672553616027E-5,0.922844350337982,0.965059399604797,31.1313781738281,0.0390623547136784,30,4,200,-0.00041968235746026,-0.437457531690598,0.0218583587557077,3,,,,,,,,,,,,,,,,
,3959151616.54041,149.997589111328,999.553466796875,,,6,,,,30.8687038625824,,,10,,,,,,,,,,,,,,,,,,,,,,149.984588623047,150.009750366211,999.553466796875,999.553466796875,,,6.39818954467773,,1,0,0,0,0,36.1681327819824,1,1,1,149.985427856445,0,149.998385959201,-180.000015258789,1,0.000992395938350202,4.90436476840246E-5,0.000995005418526969,4.90498784789816E-5,0.921381711959839,0.965339958667755,31.1377944946289,,30,4,200,-0.000560811371542513,-0.438556581735611,0.0214112382382154,1,,,,,,,,,,,,,,,,
,3959151739.11494,149.997489929199,999.553466796875,,,6,,,,30.8687038625824,,,10,,,,,,,,,,,,,,,,,,,,,,149.984588623047,150.011779785156,999.553466796875,999.553466796875,,,6.39866256713867,,1,0,0,0,0.0142669677734375,37.1456527709961,1,1,1,149.992660522461,0,149.998087565104,-175.996810913086,1,0.000991951219379558,2.83018161190246E-5,0.000994570134246915,2.8305649205649E-5,0.921762526035309,0.966284394264221,31.1381416320801,0,30,4,200,-0.000437066657468677,-0.439307808876038,0.0212588775902987,3,,,,,,,,,,,,,,,,
,3959151865.89639,149.998352050781,999.553466796875,,,6,,,,30.8687038625824,,,10,,,,,,,,,,,,,,,,,,,,,,149.98583984375,150.01091003418,999.553466796875,999.553466796875,,,6.39947414398193,,1,0,0,0,0.000152587890625,35.190616607666,1,1,1,149.986877441406,0,150.001847839355,-169.996810913086,1,0.000995880403511191,4.92128353030614E-5,0.000998630122374677,4.92228392359365E-5,0.922157406806946,0.968865215778351,31.1410388946533,,30,4,200,-0.00035307728103362,-0.441304981708527,0.0209016762673855,1,,,,,,,,,,,,,,,,
,3959151990.87648,149.999336242676,999.553466796875,,,6,,,,30.8687038625824,,,10,,,,,,,,,,,,,,,,,,,,,,149.986068725586,150.011413574219,999.553466796875,999.553466796875,,,6.39876317977905,,1,0,0,0,0.0002288818359375,36.1681327819824,1,1,1,149.994613647461,0,150.00025318287,-165.998413085938,1,0.000996729754622402,2.84338538329719E-5,0.00099941368836333,2.84400322019929E-5,0.923713505268097,0.970124900341034,31.1365756988525,0,30,4,200,-0.000278635154245421,-0.441965252161026,0.0212249029427767,3,,,,,,,,,,,,,,,,
,3959152117.36473,149.99813079834,999.553466796875,,,6,,,,30.8687038625824,,,10,,,,,,,,,,,,,,,,,,,,,,149.985244750977,150.010238647461,999.553466796875,999.553466796875,,,6.39950561523437,,1,0,0,0,7.62939453125E-5,35.6793746948242,1,1,1,149.986022949219,0,150.000011867947,-159.998413085938,1,0.00100497304155974,4.9651261643935E-5,0.00100759891419955,4.96590999134542E-5,0.92501312494278,0.972881734371185,31.1347465515137,,30,4,200,-0.000496012158691883,-0.44579142332077,0.0216619186103344,1,,,,,,,,,,,,,,,,
,3959152235.98456,149.997840881348,999.553466796875,,,6,,,,30.8687038625824,,,10,,,,,,,,,,,,,,,,,,,,,,149.98957824707,150.011657714844,999.553466796875,999.553466796875,,,6.3998384475708,,1,0,0,0,0,35.6793746948242,1,1,1,149.99333190918,0,150.000885009766,-155.995208740234,1,0.00100759578003206,2.87387386236604E-5,0.00101018276332502,2.87434364023248E-5,0.926061868667603,0.97392064332962,31.131649017334,0,30,4,200,-0.000440013274783269,-0.447463810443878,0.0220939964056015,3,,,,,,,,,,,,,,,,
,3959152362.51242,149.997970581055,999.553466796875,,,6,,,,30.8687038625824,,,10,,,,,,,,,,,,,,,,,,,,,,149.982635498047,150.011352539062,999.553466796875,999.553466796875,,,6.39995050430298,,1,0,0,0,0.0002288818359375,35.190616607666,1,1,1,149.984588623047,0,149.999465942383,-149.995208740234,1,0.00101323021385065,5.0047912210861E-5,0.00101568331893517,5.0054226348841E-5,0.928073406219482,0.975450217723846,31.1251163482666,0,30,4,200,-0.000690514454618096,-0.450194358825684,0.0220108889043331,1,,,,,,,,,,,,,,,,
,3959152486.78795,149.996696472168,999.553466796875,,,6,,,,30.8687038625824,,,10,,,,,,,,,,,,,,,,,,,,,,149.989349365234,150.009384155273,999.553466796875,999.553466796875,,,6.40003347396851,,1,0,0,0,0.000152587890625,36.1681327819824,1,1,1,149.991912841797,0,149.999712430514,-145.996810913086,1,0.00101399478458003,2.89127342095209E-5,0.00101630401381606,2.8915664227134E-5,0.930131196975708,0.97662079334259,31.1181983947754,,30,4,200,-0.000599731458351016,-0.451255857944489,0.0217328481376171,3,,,,,,,,,,,,,,,,
,3959152613.32338,149.998947143555,999.553466796875,,,6,,,,30.8687038625824,,,10,,,,,,,,,,,,,,,,,,,,,,149.986465454102,150.010757446289,999.553466796875,999.553466796875,,,6.39952993392944,,1,0,0,0,0.0002288818359375,35.190616607666,1,1,1,149.987594604492,0,150.001445007324,-139.996810913086,1,0.00102030359874007,5.03776976759312E-5,0.0010224775678842,5.0384156973687E-5,0.933671355247498,0.979785084724426,31.1079940795898,0,30,4,200,-0.000392833811929449,-0.454389065504074,0.0216235443949699,1,,,,,,,,,,,,,,,,
,3959152738.47721,149.998863220215,999.553466796875,,,6,,,,30.8687038625824,,,10,,,,,,,,,,,,,,,,,,,,,,149.98698425293,150.011505126953,999.553466796875,999.553466796875,,,6.39995718002319,,1,0,0,0,0.00030517578125,35.6793746948242,1,1,1,149.99446105957,0,149.999720820674,-135.998413085938,1,0.00102234877606001,2.9138378240164E-5,0.00102439970972913,2.91434145122428E-5,0.936569273471832,0.980791389942169,31.0978050231934,,30,4,200,-0.000280087115243077,-0.455563694238663,0.0222314558923244,3,,,,,,,,,,,,,,,,
,3959152866.10976,149.998527526855,999.553466796875,,,6,,,,30.8687038625824,,,10,,,,,,,,,,,,,,,,,,,,,,149.984405517578,150.011978149414,999.553466796875,999.553466796875,,,6.39987754821777,,1,0,0,0,0.000152587890625,35.190616607666,1,1,1,149.985076904297,0,150.000696818034,-129.998413085938,1,0.00103048457959282,5.08577771170504E-5,0.0010322058164791,5.08623735643786E-5,0.940719068050385,0.980940818786621,31.0808868408203,0,30,4,200,-0.000364697596523911,-0.45895454287529,0.0224724300205708,1,,,,,,,,,,,,,,,,
,3959152987.33657,149.99877166748,999.553466796875,,,6,,,,30.8687038625824,,,10,,,,,,,,,,,,,,,,,,,,,,149.988983154297,150.010620117187,999.553466796875,999.553466796875,,,6.39979553222656,,1,0,0,0,0.000152587890625,37.1456527709961,1,1,1,149.996215820313,0,150.00066786546,-125.995208740234,1,0.00103240860826941,2.94126634258321E-5,0.00103396339105965,2.94164343988785E-5,0.943590760231018,0.979174673557282,31.0664215087891,0,30,4,200,-0.000568696181289852,-0.460485726594925,0.0225878916680813,3,,,,,,,,,,,,,,,,
,3959153114.09939,149.998374938965,999.553466796875,,,6,,,,30.8687038625824,,,10,,,,,,,,,,,,,,,,,,,,,,149.985366821289,150.010543823242,999.553466796875,999.553466796875,,,6.39963817596436,,1,0,0,0,0.000152587890625,35.6793746948242,1,1,1,149.986206054687,0,149.999121771918,-119.995208740234,1,0.0010370148362829,5.11579140558077E-5,0.0010382578092804,5.11625052607143E-5,0.948508322238922,0.979059040546417,31.0457763671875,1.00360193755478E-6,30,4,200,-0.000423375808168203,-0.462575852870941,0.0221718791872263,1,,,,,,,,,,,,,,,,
,3959153234.53442,149.996406555176,999.553466796875,,,6,,,,30.8687038625824,,,10,,,,,,,,,,,,,,,,,,,,,,149.987457275391,150.008438110352,999.553466796875,999.553466796875,,,6.39994192123413,,1,0,0,0,0.0032806396484375,35.6793746948242,1,1,1,149.992889404297,0,149.999298095703,-115.996803283691,1,0.00103587938273324,2.94979710739483E-5,0.00103687102588313,2.94995098610449E-5,0.952429354190826,0.978644013404846,31.02880859375,5.67601490020752,30,4,200,-0.000466401659650728,-0.462704300880432,0.0215525291860104,3,,,,,,,,,,,,,,,,
,3959153360.38644,149.998481750488,999.553466796875,,,6,,,,30.8687038625824,,,10,,,,,,,,,,,,,,,,,,,,,,149.984252929687,150.011001586914,999.553466796875,999.553466796875,,,6.39917898178101,,1,0,0,0,0.00030517578125,36.1681327819824,1,1,1,149.985961914062,0,149.99910736084,-109.996803283691,1,0.00103792435817941,5.11785996639613E-5,0.00103864978560832,5.11804148401987E-5,0.958664238452911,0.980413913726807,31.0060405731201,5.5683069229126,30,4,200,-0.000577742524910718,-0.463652789592743,0.0209726057946682,1,,,,,,,,,,,,,,,,
,3959153485.91605,149.999824523926,999.553466796875,,,6,,,,30.8687038625824,,,10,,,,,,,,,,,,,,,,,,,,,,149.986206054687,150.012283325195,999.553466796875,999.553466796875,,,6.39932489395142,,1,0,0,0,0.00030517578125,35.6793746948242,1,1,1,149.994018554687,0,150.000560215541,-105.998405456543,1,0.00103704610907568,2.95180425988646E-5,0.00103767408716741,2.95205181581309E-5,0.962923526763916,0.981763899326324,30.9906387329102,0.107755333185196,30,4,200,-0.000320289749652147,-0.463752329349518,0.0210788436233997,3,,,,,,,,,,,,,,,,
,3959153614.35558,149.998458862305,999.553466796875,,,6,,,,30.8687038625824,,,10,,,,,,,,,,,,,,,,,,,,,,149.98486328125,150.011489868164,999.553466796875,999.553466796875,,,6.39904546737671,,1,0,0,0,0.00030517578125,35.6793746948242,1,1,1,149.985427856445,0,149.999186706543,-99.998405456543,1,0.00103942547833506,5.1233800839494E-5,0.0010398137487153,5.12356781625332E-5,0.968775749206543,0.982629895210266,30.9666633605957,,30,4,200,-0.000372129463357851,-0.464680671691895,0.0200709290802479,1,,,,,,,,,,,,,,,,
,3959153735.56934,149.99821472168,999.553466796875,,,6,,,,30.8687038625824,,,10,,,,,,,,,,,,,,,,,,,,,,149.989028930664,150.010025024414,999.553466796875,999.553466796875,,,6.39933824539185,,1,0,0,0,0.000152587890625,35.6793746948242,1,1,1,149.996612548828,0,149.999977111816,-96.0000076293945,1,0.00103893949629064,2.95634754579897E-5,0.00103921834354832,2.95644594988755E-5,0.971650421619415,0.981729388237,30.95041847229,6.99563588568708E-6,30,4,200,-0.000329513306496665,-0.465238243341446,0.0196934044361114,3,,,,,,,,,,,,,,,,
,3959153861.33615,149.998832702637,999.553466796875,,,6,,,,30.8687038625824,,,10,,,,,,,,,,,,,,,,,,,,,,149.984619140625,150.011642456055,999.553466796875,999.553466796875,,,6.39874315261841,,1,0,0,0,7.62939453125E-5,35.6793746948242,1,1,1,149.986022949219,0,149.999069213867,-90.0000076293945,1,0.00103904036812877,5.12049698351038E-5,0.00103918548623898,5.12057562777132E-5,0.975683867931366,0.981485247611999,30.9281139373779,0,30,4,200,-0.000489322177600116,-0.465279668569565,0.0188714284449816,1,,,,,,,,,,,,,,,,
,3959153986.29105,149.998573303223,999.553466796875,,,6,,,,30.8687038625824,,,10,,,,,,,,,,,,,,,,,,,,,,149.985641479492,150.010726928711,999.553466796875,999.553466796875,,,6.39853143692017,,1,0,0,0,0.01129150390625,35.190616607666,1,1,1,149.993881225586,0,149.999419076102,-85.9968032836914,1,0.0010341960758075,2.94239319692371E-5,0.00103427221516262,2.94240907170894E-5,0.977806746959686,0.981128036975861,30.9127082824707,0,30,4,200,-0.000626654655206948,-0.463603436946869,0.0182553436607122,3,,,,,,,,,,,,,,,,
,3959154113.05751,149.997337341309,999.553466796875,,,6,,,,30.8687038625824,,,10,,,,,,,,,,,,,,,,,,,,,,149.982803344727,150.011306762695,999.553466796875,999.553466796875,,,6.39893436431885,,1,0,0,0,0.0003814697265625,35.6793746948242,1,1,1,149.983367919922,0,149.999255710178,-79.9968032836914,1,0.00102949740181486,5.07284881295546E-5,0.00102952282659777,5.07286498327293E-5,0.98137092590332,0.982563257217407,30.8935146331787,5.55819320678711,30,4,200,-0.000402738223783672,-0.461748450994492,0.0166463013738394,1,,,,,,,,,,,,,,,,
,3959154237.97876,149.999946594238,999.553466796875,,,6,,,,30.8687038625824,,,10,,,,,,,,,,,,,,,,,,,,,,149.98908996582,150.011520385742,999.553466796875,999.553466796875,,,6.39925813674927,,1,0,0,0,0.0142669677734375,35.6793746948242,1,1,1,149.996383666992,0,150.001770584672,-75.998405456543,1,0.00102494230603905,2.91578134488744E-5,0.00102494832038983,2.91578825029466E-5,0.982717156410217,0.98292076587677,30.8787231445313,0,30,4,200,-0.000362906459486112,-0.460501402616501,0.0156653504818678,3,,,,,,,,,,,,,,,,
,3959154364.34664,149.999923706055,999.553466796875,,,6,,,,30.8687038625824,,,10,,,,,,,,,,,,,,,,,,,,,,149.98600769043,150.013198852539,999.553466796875,999.553466796875,,,6.39922046661377,,1,0,0,0,0.0002288818359375,36.1681327819824,1,1,1,149.98664855957,0,150.002234564887,-69.998405456543,1,0.00102112913790479,5.03160660289964E-5,0.00102112967427643,5.03159283426593E-5,0.981451332569122,0.981627941131592,30.8590145111084,0,30,4,200,-0.000400475488277152,-0.45914563536644,0.0143813537433743,1,,,,,,,,,,,,,,,,
,3959154487.89976,149.997711181641,999.553466796875,,,6,,,,30.8687038625824,,,10,,,,,,,,,,,,,,,,,,,,,,149.990600585938,150.009185791016,999.553466796875,999.553466796875,,,6.39914989471436,,1,0,0,0,0.000152587890625,35.6793746948242,1,1,1,149.99560546875,0,150.001919673039,-65.9952011108398,1,0.00101987690861167,2.90152664423553E-5,0.00101989054778497,2.90150785754783E-5,0.97985178232193,0.980861842632294,30.8448009490967,,30,4,200,-0.000356607168214396,-0.459096759557724,0.0139476871117949,3,,,,,,,,,,,,,,,,
,3959154615.50716,149.998481750488,999.553466796875,,,6,,,,30.8687038625824,,,10,,,,,,,,,,,,,,,,,,,,,,149.984832763672,150.011352539062,999.553466796875,999.553466796875,,,6.39867925643921,,1,0,0,0,0.00030517578125,35.6793746948242,1,1,1,149.985610961914,0,149.999272155762,-59.9952011108398,1,0.00101748760207353,5.01436879778893E-5,0.00101753141058994,5.01430086951002E-5,0.975004255771637,0.977380335330963,30.8283405303955,0,30,4,200,-0.000429111329140142,-0.458489507436752,0.0129634439945221,1,,,,,,,,,,,,,,,,
,3959154741.65081,149.997787475586,999.553466796875,,,6,,,,30.8687038625824,,,10,,,,,,,,,,,,,,,,,,,,,,149.989044189453,150.011199951172,999.553466796875,999.553466796875,,,6.39858293533325,,1,0,0,0,0.0142669677734375,35.6793746948242,1,1,1,149.993225097656,0,150.000420161656,-55.9968032836914,1,0.0010116258046482,2.87866797907616E-5,0.00101170507893061,2.87864782602754E-5,0.971141576766968,0.974266529083252,30.8191432952881,9.31366157531738,30,4,200,-0.000394226430216804,-0.45672345161438,0.0122106652706861,3,,,,,,,,,,,,,,,,
,3959154869.17769,149.99779510498,999.553466796875,,,6,,,,30.8687038625824,,,10,,,,,,,,,,,,,,,,,,,,,,149.983032226562,150.012145996094,999.553466796875,999.553466796875,,,6.39865255355835,,1,0,0,0,0.00030517578125,35.6793746948242,1,1,1,149.983444213867,0,150.000278049045,-49.9968032836914,1,0.00100617257526217,4.95981710542852E-5,0.00100629807067973,4.95980862846239E-5,0.966643691062927,0.970673561096191,30.8082389831543,0,30,4,200,-0.000533899525180459,-0.454451501369476,0.0110292723402381,1,,,,,,,,,,,,,,,,
,3959154992.21548,149.998481750488,999.553466796875,,,6,,,,30.8687038625824,,,10,,,,,,,,,,,,,,,,,,,,,,149.990783691406,150.012649536133,999.553466796875,999.553466796875,,,6.39841365814209,,1,0,0,0,0,35.190616607666,1,1,1,149.994903564453,0,150.001454106084,-45.9984016418457,1,0.00100094218722825,2.84893496041902E-5,0.00100111038156928,2.84894862225919E-5,0.963926732540131,0.968771874904633,30.7998504638672,0.000591800198890269,30,4,200,-0.000187915546121076,-0.453060001134872,0.0100760804489255,3,,,,,,,,,,,,,,,,
,3959155118.93215,149.998489379883,999.553466796875,,,6,,,,30.8687038625824,,,10,,,,,,,,,,,,,,,,,,,,,,149.984268188477,150.011444091797,999.553466796875,999.553466796875,,,6.39793634414673,,1,0,0,0,0.000457763671875,36.1681327819824,1,1,1,149.985534667969,0,149.999197387695,-39.9984016418457,1,0.000998656912806514,4.92376182379765E-5,0.000998857678275374,4.923678519549E-5,0.961071789264679,0.9671351313591,30.7889957427978,0,30,4,200,-0.00039532347000204,-0.452102035284042,0.00930329225957394,1,,,,,,,,,,,,,,,,
,3959155244.09647,149.998077392578,999.553466796875,,,6,,,,30.8687038625824,,,10,,,,,,,,,,,,,,,,,,,,,,149.986694335938,150.011016845703,999.553466796875,999.553466796875,,,6.3980131149292,,1,0,0,0,0.000152587890625,35.6793746948242,1,1,1,149.995056152344,0,149.999698215061,-35.9952011108398,1,0.00099698869085101,2.83822328712153E-5,0.000997249052060989,2.83817318125171E-5,0.958990752696991,0.966458857059479,30.7786083221436,0,30,4,200,-0.00030796421924606,-0.451966375112534,0.00931055843830109,3,,,,,,,,,,,,,,,,
,3959155369.76612,149.997436523438,999.553466796875,,,6,,,,30.8687038625824,,,10,,,,,,,,,,,,,,,,,,,,,,149.982971191406,150.011093139648,999.553466796875,999.553466796875,,,6.39747905731201,,1,0,0,0,0.000152587890625,35.6793746948242,1,1,1,149.984252929687,0,149.999819946289,-29.9952011108398,1,0.000996988776271979,4.91655642825723E-5,0.00099731602125698,4.91643855975177E-5,0.956075608730316,0.964983463287353,30.7675113677978,1.38714030981646E-5,30,4,200,-0.000527709897141904,-0.452115565538406,0.00866807717829943,1,,,,,,,,,,,,,,,,
,3959155495.91473,150.001441955566,999.553466796875,,,6,,,,30.8687038625824,,,10,,,,,,,,,,,,,,,,,,,,,,149.992050170898,150.015090942383,999.553466796875,999.553466796875,,,6.3977222442627,,1,0,0,0,0.000152587890625,35.6793746948242,1,1,1,149.995529174805,0,150.003141049986,-25.9968013763428,1,0.000994692815333373,2.83225182380364E-5,0.000995075666126502,2.83223342830988E-5,0.954394161701202,0.96396404504776,30.7621574401855,5.54636430740356,30,4,200,-0.000345581502187997,-0.45163831114769,0.00841299723833799,3,,,,,,,,,,,,,,,,
,3959155620.48577,149.999008178711,999.553466796875,,,6,,,,30.8687038625824,,,10,,,,,,,,,,,,,,,,,,,,,,149.984481811523,150.01203918457,999.553466796875,999.553466796875,,,6.39763259887695,,1,0,0,0,0.0002288818359375,35.6793746948242,1,1,1,149.985977172852,0,149.999287414551,-19.9968013763428,1,0.000993303558059464,4.89923640738626E-5,0.000993752660848011,4.89931001141835E-5,0.952276825904846,0.962515294551849,30.7559394836426,0,30,4,200,-0.000437574490206316,-0.451120793819428,0.00768539542332292,1,,,,,,,,,,,,,,,,
,3959155745.68432,149.997085571289,999.553466796875,,,6,,,,30.8687038625824,,,10,,,,,,,,,,,,,,,,,,,,,,149.986206054687,150.011337280273,999.553466796875,999.553466796875,,,6.39803218841553,,1,0,0,0,0.0006103515625,35.6793746948242,1,1,1,149.994018554687,0,149.999478940611,-15.9984006881714,1,0.000991260198483271,2.82277175285141E-5,0.000991709238889393,2.82278781372154E-5,0.952167630195618,0.962648034095764,30.7545566558838,,30,4,200,-0.000341491890139878,-0.450771510601044,0.00731840077787638,3,,,,,,,,,,,,,,,,
,3959155872.20795,149.999671936035,999.553466796875,,,6,,,,30.8687038625824,,,10,,,,,,,,,,,,,,,,,,,,,,149.985748291016,150.012573242187,999.553466796875,999.553466796875,,,6.39821577072144,,1,0,0,0,0.0005340576171875,35.6793746948242,1,1,1,149.986770629883,0,150.00185139974,-9.99840068817139,1,0.000993843088481566,4.90166889551655E-5,0.000994254750342025,4.90143715128612E-5,0.953262567520142,0.96445894241333,30.7525978088379,5.54550266265869,30,4,200,-0.000340415630489588,-0.452073335647583,0.00686395820230246,1,,,,,,,,,,,,,,,,
,3959155997.17068,149.997291564941,999.553466796875,,,6,,,,30.8687038625824,,,10,,,,,,,,,,,,,,,,,,,,,,149.988235473633,150.010711669922,999.553466796875,999.553466796875,,,6.39794445037842,,1,0,0,0,0.00030517578125,35.6793746948242,1,1,1,149.993408203125,0,149.999689919608,-6.00000047683716,1,0.00099393929640061,2.83030041958379E-5,0.000994450687261878,2.83032339936605E-5,0.952916741371155,0.965271711349487,30.7472190856934,0,30,4,200,-0.000347254448570311,-0.452513843774796,0.00705330213531852,3,,,,,,,,,,,,,,,,
,3959156121.57716,149.998634338379,999.553466796875,,,6,,,,30.8687038625824,,,10,,,,,,,,,,,,,,,,,,,,,,149.985382080078,150.011245727539,999.553466796875,999.553466796875,,,6.39772796630859,,1,0,0,0,0.000152587890625,35.6793746948242,1,1,1,149.986022949219,0,149.999569702148,0,1,0.000999598393339128,4.92977142501817E-5,0.00100010999357314,4.92975402698251E-5,0.954512000083923,0.967745542526245,30.7463722229004,0.0817579329013825,30,4,200,-0.000441720214439556,-0.45507875084877,0.00717534963041544,1,,,,,,,,,,,,,,,,
,3959156247.52277,149.997482299805,999.553466796875,,,6,,,,30.8687038625824,,,10,,,,,,,,,,,,,,,,,,,,,,149.989166259766,150.010559082031,999.553466796875,999.553466796875,,,6.39729690551758,,1,0,0,0,0.0113677978515625,37.1456527709961,1,1,1,149.993667602539,0,150.000286647252,3.99840021133423,1,0.00100093307710661,2.8498888346542E-5,0.00100146619000353,2.84995583170574E-5,0.955415904521942,0.968834042549133,30.7472438812256,0,30,4,200,-0.000320435356115922,-0.456436604261398,0.00706019904464483,3,,,,,,,,,,,,,,,,
,3959156374.38676,149.999359130859,999.553466796875,,,6,,,,30.8687038625824,,,10,,,,,,,,,,,,,,,,,,,,,,149.984878540039,150.012313842773,999.553466796875,999.553466796875,,,6.39773416519165,,1,0,0,0,0.0002288818359375,35.6793746948242,1,1,1,149.986404418945,0,149.99959564209,9.99840068817139,1,0.00100520351956286,4.95674109730884E-5,0.00100567356435382,4.95671787947007E-5,0.957596600055695,0.970760822296143,30.7518501281738,,30,4,200,-0.000600854109507054,-0.458504527807236,0.00672073662281036,1,,,,,,,,,,,,,,,,
,3959156500.46022,149.996543884277,999.553466796875,,,6,,,,30.8687038625824,,,10,,,,,,,,,,,,,,,,,,,,,,149.989364624023,150.010940551758,999.553466796875,999.553466796875,,,6.39763927459717,,1,0,0,0,0.000152587890625,35.6793746948242,1,1,1,149.992553710938,0,150.000346996166,13.9968004226685,1,0.00100647096490329,2.86509522908155E-5,0.00100690715800809,2.86510412690905E-5,0.960042655467987,0.972848296165466,30.7573223114014,0.315127581357956,30,4,200,-0.000420793803641573,-0.459438502788544,0.00686262408271432,3,,,,,,,,,,,,,,,,
,3959156625.40808,149.998138427734,999.553466796875,,,6,,,,30.8687038625824,,,10,,,,,,,,,,,,,,,,,,,,,,149.985214233398,150.011077880859,999.553466796875,999.553466796875,,,6.39765024185181,,1,0,0,0,0.000152587890625,35.6793746948242,1,1,1,149.986175537109,0,150.001051330566,19.9968013763428,1,0.00101199254619056,4.98873113193446E-5,0.00101229590768369,4.98854082810017E-5,0.96530145406723,0.977003574371338,30.7699222564697,0.000155823319801129,30,4,200,-0.000366346939699724,-0.461735039949417,0.00711256638169289,1,,,,,,,,,,,,,,,,
,3959156749.66944,149.998893737793,999.553466796875,,,6,,,,30.8687038625824,,,10,,,,,,,,,,,,,,,,,,,,,,149.990081787109,150.012649536133,999.553466796875,999.553466796875,,,6.39777231216431,,1,0,0,0,0.0003814697265625,35.190616607666,1,1,1,149.995010375977,0,150.000778198242,24.0000019073486,1,0.00101400318834563,2.88577013332204E-5,0.00101430902411895,2.88575804036451E-5,0.967343151569366,0.978659451007843,30.774730682373,0.113979697227478,30,4,200,-0.000307107373373583,-0.462674766778946,0.00765627389773726,3,,,,,,,,,,,,,,,,
,3959156877.37348,149.998680114746,999.553466796875,,,6,,,,30.8687038625824,,,10,,,,,,,,,,,,,,,,,,,,,,149.985275268555,150.011383056641,999.553466796875,999.553466796875,,,6.3977518081665,,1,0,0,0,0,35.190616607666,1,1,1,149.985977172852,0,149.999666002062,29.9952011108398,1,0.00102189943104163,5.03668631202467E-5,0.0010221439471855,5.03668500836312E-5,0.970797121524811,0.98065859079361,30.7857284545898,0.161496371030807,30,4,200,-0.000428962608566508,-0.466216892004013,0.00844572298228741,1,,,,,,,,,,,,,,,,
,3959157001.00288,149.997268676758,999.553466796875,,,6,,,,30.8687038625824,,,10,,,,,,,,,,,,,,,,,,,,,,149.986236572266,150.011810302734,999.553466796875,999.553466796875,,,6.39744138717651,,1,0,0,0,0.0002288818359375,35.190616607666,1,1,1,149.99250793457,0,149.998800005232,33.9984016418457,1,0.00102445158338812,2.91508556827727E-5,0.00102463418373193,2.9150455168187E-5,0.972106456756592,0.980141878128052,30.7945537567139,0,30,4,200,-0.000429802254075184,-0.46784582734108,0.00916554871946573,3,,,,,,,,,,,,,,,,
,3959157128.07493,149.998115539551,999.553466796875,,,6,,,,30.8687038625824,,,10,,,,,,,,,,,,,,,,,,,,,,149.984725952148,150.011505126953,999.553466796875,999.553466796875,,,6.39772653579712,,1,0,0,0,0.000152587890625,35.6793746948242,1,1,1,149.984725952148,0,149.999401855469,39.9984016418457,1,0.0010299507660083,5.07578617168556E-5,0.00103005995075454,5.07575817976625E-5,0.975038230419159,0.979995846748352,30.8123435974121,0.114733159542084,30,4,200,-0.000450697058113292,-0.470612376928329,0.00891376193612814,1,,,,,,,,,,,,,,,,
,3959157251.87778,149.998741149902,999.553466796875,,,6,,,,30.8687038625824,,,10,,,,,,,,,,,,,,,,,,,,,,149.989181518555,150.01091003418,999.553466796875,999.553466796875,,,6.3979868888855,,1,0,0,0,0.0142669677734375,36.1681327819824,1,1,1,149.995330810547,0,150.000199538011,43.9968032836914,1,0.00103115097793124,2.93375906259328E-5,0.00103121059728279,2.9337657555349E-5,0.977359414100647,0.97996062040329,30.8289585113525,0.107298754155636,30,4,200,-0.000414670357713476,-0.471977472305298,0.00886020250618458,3,,,,,,,,,,,,,,,,
,3959157378.05689,150.000015258789,999.553466796875,,,6,,,,30.8687038625824,,,10,,,,,,,,,,,,,,,,,,,,,,149.986206054687,150.013641357422,999.553466796875,999.553466796875,,,6.39725637435913,,1,0,0,0,0,36.6568908691406,1,1,1,149.986389160156,0,150.002446492513,49.9968032836914,1,0.00103550035706448,5.10250291174321E-5,0.00103550375725239,5.10249002109713E-5,0.980618059635162,0.980920076370239,30.8558387756348,0,30,4,200,-0.00040429166983813,-0.473714143037796,0.00914482958614826,1,,,,,,,,,,,,,,,,
,3959157503.06729,149.997634887695,999.553466796875,,,6,,,,30.8687038625824,,,10,,,,,,,,,,,,,,,,,,,,,,149.988891601562,150.010879516602,999.553466796875,999.553466796875,,,6.39720344543457,,1,0,0,0,0.0003814697265625,36.1681327819824,1,1,1,149.993377685547,0,149.999993783456,53.9952011108398,1,0.00103550016479527,2.94589348704086E-5,0.00103550019160554,2.94589356250577E-5,0.98128217458725,0.981282234191895,30.8687934875488,0,30,4,200,-0.000160601062816568,-0.474258273839951,0.00934938620775938,3,,,,,,,,,,,,,,,,
,3959157630.718,149.997901916504,999.553466796875,,,6,,,,30.8687038625824,,,10,,,,,,,,,,,,,,,,,,,,,,149.984146118164,150.010696411133,999.553466796875,999.553466796875,,,6.39720630645752,,1,0,0,0,0.000152587890625,36.1681327819824,1,1,1,149.985107421875,0,150.00047132704,59.9952011108398,1,0.00103961704410763,5.12286233215899E-5,0.00103963079300803,5.12288026316968E-5,0.979887545108795,0.980376839637756,30.8853549957275,0.186443775892258,30,4,200,-0.00037682568654418,-0.475841462612152,0.0096006914973259,1,,,,,,,,,,,,,,,,
,3959157752.52672,149.999816894531,999.553466796875,,,6,,,,30.8687038625824,,,10,,,,,,,,,,,,,,,,,,,,,,149.987335205078,150.012771606445,999.553466796875,999.553466796875,,,6.39715719223022,,1,0,0,0,0.000152587890625,35.6793746948242,1,1,1,149.995193481445,0,150.000944349501,63.9984016418457,1,0.00103916087548088,2.9565308259082E-5,0.0010392004169693,2.95654854661375E-5,0.977623045444489,0.979103982448578,30.8989181518555,0,30,4,200,-0.000280879525234923,-0.475965082645416,0.00992675684392452,3,,,,,,,,,,,,,,,,
,3959157881.75597,149.998115539551,999.553466796875,,,6,,,,30.8687038625824,,,10,,,,,,,,,,,,,,,,,,,,,,149.984420776367,150.011428833008,999.553466796875,999.553466796875,,,6.39687776565552,,1,0,0,0,7.62939453125E-5,35.6793746948242,1,1,1,149.984802246094,0,149.998558044434,69.998405456543,1,0.0010402991622702,5.12690221556165E-5,0.00104042073775992,5.12700913958112E-5,0.974128723144531,0.978149950504303,30.9209175109863,,30,4,200,-0.000408928550314158,-0.476822227239609,0.00926664937287569,1,,,,,,,,,,,,,,,,
,3959158006.6828,149.997993469238,999.553466796875,,,6,,,,30.8687038625824,,,10,,,,,,,,,,,,,,,,,,,,,,149.988082885742,150.011764526367,999.553466796875,999.553466796875,,,6.39735841751099,,1,0,0,0,0.000152587890625,35.6793746948242,1,1,1,149.992874145508,0,150.000209667065,73.9968032836914,1,0.00103717997559419,2.95139603377089E-5,0.00103737841235651,2.95143433654666E-5,0.971004784107208,0.977993130683899,30.9399013519287,5.56236457824707,30,4,200,-0.000277069921139628,-0.476398557424545,0.00849857274442911,3,,,,,,,,,,,,,,,,
,3959158134.43706,149.998153686523,999.553466796875,,,6,,,,30.8687038625824,,,10,,,,,,,,,,,,,,,,,,,,,,149.985015869141,150.011016845703,999.553466796875,999.553466796875,,,6.39699554443359,,1,0,0,0,0.00030517578125,35.6793746948242,1,1,1,149.985290527344,0,150.001134236654,79.9968032836914,1,0.00103503662952906,5.10203954144487E-5,0.0010354335484783,5.1022352193967E-5,0.966987073421478,0.97999370098114,30.967887878418,0.116177693009377,30,4,200,-0.000350620015524328,-0.475391149520874,0.007592071313411,1,,,,,,,,,,,,,,,,
,3959158258.4004,149.998962402344,999.553466796875,,,6,,,,30.8687038625824,,,10,,,,,,,,,,,,,,,,,,,,,,149.988616943359,150.011962890625,999.553466796875,999.553466796875,,,6.39718866348267,,1,0,0,0,0.0003814697265625,35.6793746948242,1,1,1,149.996398925781,0,150.001003689236,84.0000076293945,1,0.00103283115193448,2.93948737274494E-5,0.00103324593366124,2.93954496336908E-5,0.96596884727478,0.980128824710846,30.9730815887451,,30,4,200,-0.000222999515244737,-0.475061744451523,0.00722504872828722,3,,,,,,,,,,,,,,,,
,3959158387.2279,149.998718261719,999.553466796875,,,6,,,,30.8687038625824,,,10,,,,,,,,,,,,,,,,,,,,,,149.985061645508,150.011688232422,999.553466796875,999.553466796875,,,6.39741611480713,,1,0,0,0,7.62939453125E-5,35.6793746948242,1,1,1,149.985748291016,0,150.001224093967,90.0000076293945,1,0.00103417541318428,5.0979594725989E-5,0.00103459930780151,5.09808575010938E-5,0.966025292873383,0.980383515357971,30.9735527038574,0.163324475288391,30,4,200,-0.000250738317845389,-0.475758135318756,0.0066687953658402,1,,,,,,,,,,,,,,,,
,3959158411.16904,149.997383117676,999.553466796875,,,6,,,,30.8687038625824,,,10,,,,,,,,,,,,,,,,,,,,,,149.983657836914,150.011367797852,999.553466796875,999.553466796875,,,6.39737272262573,,1,0,0,0,0.0142669677734375,35.6793746948242,1,1,1,149.992401123047,0,149.998285364222,90.0000076293945,1,0.00103283650921192,2.9394957522395E-5,0.00103326026471098,2.93958471268589E-5,0.966039061546326,0.980149030685425,30.9728717803955,0,30,4,200,-0.000193188490811735,-0.475540339946747,0.00667481264099479,3,,,,,,,,,,,,,,,,