File: PPMS_Data_and_Plotting/Data/RuCl3/Data/Magnetisation/Rotator/TB001_RuCl3_H-parra-ab_61p2_mg_14-06-25_ZFCW_180K.dat
[Header]
; MPMS3 Data File (default extension .dat)
; Copyright (c) 2007, Quantum Design, Inc. All rights reserved.
TITLE,
FILEOPENTIME,3959158426.33019,06/15/2025,2:13 pm
BYAPP,MPMS3 w/ AC,1.0,1.1
INFO,MPMS3 Measurement Release 1.2.2 Build 0, MultiVu Release 2.3.5.2,APPNAME
INFO,Linear Motor Servo Controller,MOTOR_MODULE_NAME
INFO,3101-100 N4,MOTOR_HW_VERSION
INFO,MMC1299,MOTOR_SERIAL_NUMBER
INFO,01.04.28,MOTOR_SOFTWARE_VERSION
INFO,Quantum Design Squid Module,SQUID_MODULE_NAME
INFO,3101-501 B0,SQUID_HW_VERSION
INFO,SQM364,SQUID_SERIAL_NUMBER
INFO,01.03.04,SQUID_SOFTWARE_VERSION
INFO,Quantum Design VSM Oven,OVEN_MODULE_NAME
INFO,3101-201 A3,OVEN_HW_VERSION
INFO,OVB387,OVEN_SERIAL_NUMBER
INFO,01.07.07,OVEN_SOFTWARE_VERSION
INFO,SQUID AC,AC_MODULE_NAME
INFO,3101-401 G0,AC_HW_VERSION
INFO,SAC242,AC_SERIAL_NUMBER
INFO,SQUID AC 00.95.11,AC_SOFTWARE_VERSION
INFO,TCI374,COIL_SERIAL_NUMBER
INFO,0,MOMENT_UNITS
INFO,RuCl3,SAMPLE_MATERIAL
INFO,single crystal,SAMPLE_COMMENT
INFO,61.2,SAMPLE_MASS
INFO,,SAMPLE_VOLUME
INFO,,SAMPLE_MOLECULAR_WEIGHT
INFO,,SAMPLE_SIZE
INFO,,SAMPLE_SHAPE
INFO,Rotator,SAMPLE_HOLDER
INFO,Standard,SAMPLE_HOLDER_DETAIL
INFO,67.44,SAMPLE_OFFSET
DATATYPE,COMMENT,1
DATATYPE,TIME,2
STARTUPAXIS,X,2
STARTUPAXIS,Y1,5
FIELDGROUP, VSM,2,3,4,5,6,8,9,10,11,14,15
FIELDGROUP, DC, 2,3,4,14,56,57,58,59,60,61,62,63,64,65,66,67,68,69
FIELDGROUP, AC, 2,3,4,11,16,17,18,19,20,21,22,23,24,25,26,27,28,29,30
STARTUPGROUP, All
[Data]
Comment,Time Stamp (sec),Temperature (K),Magnetic Field (Oe),Moment (emu),M. Std. Err. (emu),Transport Action,Averaging Time (sec),Frequency (Hz),Peak Amplitude (mm),Center Position (mm),Lockin Signal' (V),Lockin Signal (V),Range,M. Quad. Signal (emu),AC Moment (emu),AC M. Std Err. (emu),AC Phase (deg),AC Phase Std. Err. (deg),AC Susceptibility (emu/Oe),AC Suscept. Std Err. (emu/Oe),AC X' (emu/Oe),AC X' Std Err. (emu/Oe),AC X'' (emu/Oe),AC X'' Std Err. (emu/Oe),AC Drive (Oe),AC Frequency (Hz),AC Averaging Time (sec),AC Cycles,AC Range,AC Measure Type,AC Signal' (V),AC Signal'' (V),AC Trim Coil Ratio,AC Trim Coil Phase,Min. Temperature (K),Max. Temperature (K),Min. Field (Oe),Max. Field (Oe),Mass (grams),Motor Lag (deg),Pressure (Torr),Measure Count,Measurement Number,SQUID Status (code),Motor Status (code),Measure Status (code),Motor Current (amps),Motor Temp. (C),Temp. Status (code),Field Status (code),Chamber Status (code),Chamber Temp (K),Redirection State,Average Temp (K),Rotation Angle (deg),Rotator state,DC Moment Fixed Ctr (emu),DC Moment Err Fixed Ctr (emu),DC Moment Free Ctr (emu),DC Moment Err Free Ctr (emu),DC Fixed Fit,DC Free Fit,DC Calculated Center (mm),DC Calculated Center Err (mm),DC Scan Length (mm),DC Scan Time (s),DC Number of Points,DC Squid Drift,DC Min V (V),DC Max V (V),DC Scans per Measure,He3 temp,Map 02,Map 03,Map 04,Map 05,Map 06,Map 07,Map 08,Map 09,Map 10,Map 11,Map 12,Map 13,Map 14,Map 15,Map 16
,3959159689.6707,179.990379333496,999.832702636719,,,6,,,,30.9165343095545,,,10,,,,,,,,,,,,,,,,,,,,,,179.983322143555,179.996505737305,999.832702636719,999.832702636719,,,6.41564226150513,,1,0,0,0,0.00030517578125,35.6793746948242,1,1,1,179.984252929687,0,179.992075602214,-299.995208740234,1,0.00078906983584696,3.88872629365373E-5,0.000789082764537044,3.8887602627373E-5,0.974557638168335,0.974859893321991,30.9312553405762,0,30,4,200,-0.0003618472837843,-0.346626102924347,0.0217897854745388,1,,,,,,,,,,,,,,,,
,3959159814.55518,179.990531921387,999.832702636719,,,6,,,,30.9165343095545,,,10,,,,,,,,,,,,,,,,,,,,,,179.98258972168,180.002899169922,999.832702636719,999.832702636719,,,6.41687536239624,,1,0,0,0,0.0002288818359375,35.6793746948242,1,1,1,179.988754272461,0,179.994168316876,-295.996826171875,1,0.000787997564423649,2.24204499289814E-5,0.000788002680488322,2.24204984858476E-5,0.9756680727005,0.975846469402313,30.927661895752,9.30163669586182,30,4,200,-0.000276497157756239,-0.346042722463608,0.0219789296388626,3,,,,,,,,,,,,,,,,
,3959159940.91089,179.996704101562,999.832702636719,,,6,,,,30.9165343095545,,,10,,,,,,,,,,,,,,,,,,,,,,179.981826782227,180.011566162109,999.832702636719,999.832702636719,,,6.41744232177734,,1,0,0,0,0.0002288818359375,35.190616607666,1,1,1,179.981842041016,0,179.999876234266,-289.996826171875,1,0.00079710477674008,3.92811992825913E-5,0.000797111578015928,3.92811732945149E-5,0.976703286170959,0.977101147174835,30.9327487945557,,30,4,200,-0.000201880422537215,-0.349650293588638,0.0226331073790789,1,,,,,,,,,,,,,,,,
,3959160066.04539,179.995018005371,999.832702636719,,,6,,,,30.9165343095545,,,10,,,,,,,,,,,,,,,,,,,,,,179.9853515625,180.011032104492,999.832702636719,999.832702636719,,,6.41828441619873,,1,0,0,0,0.0005340576171875,35.6793746948242,1,1,1,179.993087768555,0,179.998848243996,-285.998413085938,1,0.000800320075864841,2.2770468327448E-5,0.000800329977267156,2.27704645044105E-5,0.97673100233078,0.977275967597961,30.9355010986328,5.56196928024292,30,4,200,-0.000138085320941173,-0.351108849048615,0.0231912042945623,3,,,,,,,,,,,,,,,,
,3959160194.9435,179.996871948242,999.832702636719,,,6,,,,30.9165343095545,,,10,,,,,,,,,,,,,,,,,,,,,,179.979217529297,180.004943847656,999.832702636719,999.832702636719,,,6.41908550262451,,1,0,0,0,0.000152587890625,36.1681327819824,1,1,1,179.979476928711,0,179.991622924805,-279.998413085938,1,0.000810230226913657,3.99294152681717E-5,0.000810262438256735,3.99296007858585E-5,0.975249588489532,0.976710379123688,30.9482002258301,0,30,4,200,-0.000347032037097961,-0.354598701000214,0.0244258157908916,1,,,,,,,,,,,,,,,,
,3959160318.65891,179.996635437012,999.832702636719,,,6,,,,30.9165343095545,,,10,,,,,,,,,,,,,,,,,,,,,,179.986068725586,180.01301574707,999.832702636719,999.832702636719,,,6.4201602935791,,1,0,0,0,0.000152587890625,34.7018585205078,1,1,1,179.993133544922,0,180.00057248716,-275.995208740234,1,0.000814179612208746,2.31669524328023E-5,0.000814245370057186,2.31673790380647E-5,0.973038673400879,0.975458204746246,30.9586696624756,0,30,4,200,-0.000348064495483413,-0.356870502233505,0.0247575007379055,3,,,,,,,,,,,,,,,,
,3959160446.67333,179.996696472168,999.832702636719,,,6,,,,30.9165343095545,,,10,,,,,,,,,,,,,,,,,,,,,,179.979873657227,180.012573242187,999.832702636719,999.832702636719,,,6.42089986801148,,1,0,0,0,0.0005340576171875,35.6793746948242,1,1,1,179.980819702148,0,179.999014282227,-269.995208740234,1,0.000822272563344477,4.0527580459707E-5,0.00082238260735706,4.05285375213374E-5,0.970931470394135,0.975005328655243,30.9725093841553,0,30,4,200,-0.000328569760313258,-0.360005587339401,0.0251278728246689,1,,,,,,,,,,,,,,,,
,3959160572.55779,179.996589660645,999.832702636719,,,6,,,,30.9165343095545,,,10,,,,,,,,,,,,,,,,,,,,,,179.98747253418,180.013412475586,999.832702636719,999.832702636719,,,6.4220986366272,,1,0,0,0,0.0002288818359375,35.6793746948242,1,1,1,179.993301391602,0,180.001228049949,-265.996826171875,1,0.000826368026761181,2.35170063521066E-5,0.000826547093596023,2.351785727423E-5,0.968315660953522,0.974638104438782,30.9882144927978,0,30,4,200,-0.000239926841459237,-0.362225115299225,0.0253017488867044,3,,,,,,,,,,,,,,,,
,3959160700.45187,179.99674987793,999.832702636719,,,6,,,,30.9165343095545,,,10,,,,,,,,,,,,,,,,,,,,,,179.981216430664,180.012588500977,999.832702636719,999.832702636719,,,6.4233193397522,,1,0,0,0,0.000152587890625,36.6568908691406,1,1,1,179.980911254883,0,180.001090155707,-259.996826171875,1,0.000834292543872935,4.11284046451591E-5,0.000834613139580612,4.11300109060438E-5,0.964624762535095,0.976298809051514,31.0156917572022,0,30,4,200,-0.000229120007134043,-0.364635616540909,0.0258390139788389,1,,,,,,,,,,,,,,,,
,3959160824.70618,179.997131347656,999.832702636719,,,6,,,,30.9165343095545,,,10,,,,,,,,,,,,,,,,,,,,,,179.983779907227,180.015151977539,999.832702636719,999.832702636719,,,6.42415714263916,,1,0,0,0,0.0003814697265625,36.6568908691406,1,1,1,179.992965698242,0,180.000014128508,-255.998413085938,1,0.00083649501022707,2.38100454336626E-5,0.000836864807505338,2.38100466540957E-5,0.962459564208984,0.977059245109558,31.0289859771729,0,30,4,200,-0.000181641546078026,-0.365809440612793,0.0258615221828222,3,,,,,,,,,,,,,,,,
,3959160953.49299,179.997634887695,999.832702636719,,,6,,,,30.9165343095545,,,10,,,,,,,,,,,,,,,,,,,,,,179.9814453125,180.014083862305,999.832702636719,999.832702636719,,,6.42476081848145,,1,0,0,0,0.0005340576171875,35.6793746948242,1,1,1,179.981185913086,0,180.002327813043,-249.998413085938,1,0.000841543977852878,4.14914446522767E-5,0.000842025547430196,4.14939542428067E-5,0.961014688014984,0.977691113948822,31.0375499725342,3.37970595865045E-5,30,4,200,-0.000353313109371811,-0.367635190486908,0.0257362090051174,1,,,,,,,,,,,,,,,,
,3959161078.54975,179.995544433594,999.832702636719,,,6,,,,30.9165343095545,,,10,,,,,,,,,,,,,,,,,,,,,,179.986907958984,180.013961791992,999.832702636719,999.832702636719,,,6.42603015899658,,1,0,0,0,0.0002288818359375,35.6793746948242,1,1,1,179.991088867187,0,180.000952261466,-245.995208740234,1,0.000842399821785693,2.39813153708691E-5,0.000842935177649877,2.39827044524206E-5,0.959077060222626,0.977170705795288,31.0450744628906,0,30,4,200,-0.000299893436022103,-0.368349969387054,0.0256185904145241,3,,,,,,,,,,,,,,,,
,3959161206.17972,179.999458312988,999.832702636719,,,6,,,,30.9165343095545,,,10,,,,,,,,,,,,,,,,,,,,,,179.984313964844,180.015609741211,999.832702636719,999.832702636719,,,6.42686223983765,,1,0,0,0,0.0142669677734375,35.6793746948242,1,1,1,179.983306884766,0,180.004380967882,-239.995208740234,1,0.000844412891861338,4.16431026237422E-5,0.00084509754966188,4.16462584562323E-5,0.955174922943115,0.97672426700592,31.0613956451416,0,30,4,200,-0.000338013982400298,-0.369095385074615,0.0250388346612453,1,,,,,,,,,,,,,,,,
,3959161331.16358,179.994644165039,999.832702636719,,,6,,,,30.9216344234171,,,10,,,,,,,,,,,,,,,,,,,,,,179.984741210938,180.013473510742,999.832702636719,999.832702636719,,,6.42754554748535,,1,0,0,0,0.005340576171875,35.190616607666,1,1,1,179.991058349609,0,179.999497590242,-235.996810913086,1,0.000842115000132926,2.39794315765067E-5,0.000842838785259386,2.39810276937418E-5,0.953167676925659,0.975294172763825,31.0722980499268,5.57425308227539,30,4,200,-0.000357654120307416,-0.368401497602463,0.0250407364219427,3,,,,,,,,,,,,,,,,
,3959161459.01864,179.995384216309,999.832702636719,,,6,,,,30.9216344234171,,,10,,,,,,,,,,,,,,,,,,,,,,179.978897094727,180.013305664062,999.832702636719,999.832702636719,,,6.42835140228271,,1,0,0,0,0.000152587890625,35.6793746948242,1,1,1,179.977813720703,0,179.999340481228,-229.996810913086,1,0.000839853612892192,4.14323083146586E-5,0.000840772772212459,4.14356210884689E-5,0.948166489601135,0.974263727664947,31.0924415588379,0,30,4,200,-0.00030698801856488,-0.367370754480362,0.0236027892678976,1,,,,,,,,,,,,,,,,
,3959161584.06611,179.99666595459,999.832702636719,,,6,,,,30.9216344234171,,,10,,,,,,,,,,,,,,,,,,,,,,179.987411499023,180.014373779297,999.832702636719,999.832702636719,,,6.42942047119141,,1,0,0,0,0.0002288818359375,35.6793746948242,1,1,1,179.993118286133,0,180.000822884696,-225.998413085938,1,0.000835839463207304,2.38096734077782E-5,0.000836791758467882,2.38100447263343E-5,0.945755362510681,0.973534882068634,31.1017456054687,0,30,4,200,-0.000183819647645578,-0.366544842720032,0.0226745177060366,3,,,,,,,,,,,,,,,,
,3959161712.2358,179.99626159668,999.832702636719,,,6,,,,30.9216344234171,,,10,,,,,,,,,,,,,,,,,,,,,,179.978240966797,180.014358520508,999.832702636719,999.832702636719,,,6.42980813980103,,1,0,0,0,0.000457763671875,35.6793746948242,1,1,1,179.978164672852,0,180.000206841363,-219.998413085938,1,0.000832083055227724,4.10600859042051E-5,0.000833159849370996,4.10633728601092E-5,0.943194925785065,0.971622347831726,31.1092205047607,0,30,4,200,-0.000296541751595214,-0.364748299121857,0.0217337850481272,1,,,,,,,,,,,,,,,,
,3959161836.14627,179.99764251709,999.832702636719,,,6,,,,30.9216344234171,,,10,,,,,,,,,,,,,,,,,,,,,,179.985900878906,180.015090942383,999.832702636719,999.832702636719,,,6.4308819770813,,1,0,0,0,0.000152587890625,35.6793746948242,1,1,1,179.994781494141,0,180.000640869141,-215.995208740234,1,0.000828340614456277,2.36003098945727E-5,0.000829396450775014,2.36016582853841E-5,0.942538321018219,0.97044438123703,31.1094837188721,0,30,4,200,-0.000254200160270557,-0.364367067813873,0.0208096858114004,3,,,,,,,,,,,,,,,,
,3959161964.92621,179.996704101562,999.832702636719,,,6,,,,30.9216344234171,,,10,,,,,,,,,,,,,,,,,,,,,,179.979110717773,180.014511108398,999.832702636719,999.832702636719,,,6.43099021911621,,1,0,0,0,0.00030517578125,36.1681327819824,1,1,1,179.978897094727,0,180.001870049371,-209.995208740234,1,0.000823519555896103,4.06463692906668E-5,0.000824669829836849,4.06493057700996E-5,0.939490973949432,0.968055963516235,31.1175346374512,9.55377163336379E-6,30,4,200,-0.000399199343519285,-0.362867951393127,0.0192936267703772,1,,,,,,,,,,,,,,,,
,3959162089.90562,179.997177124023,999.832702636719,,,6,,,,30.9216344234171,,,10,,,,,,,,,,,,,,,,,,,,,,179.987274169922,180.016265869141,999.832702636719,999.832702636719,,,6.43209457397461,,1,0,0,0,0.0005340576171875,34.7018585205078,1,1,1,179.99186706543,0,180.001994380245,-205.996810913086,1,0.000817268398779432,2.32922157717232E-5,0.000818548931243796,2.32960893301446E-5,0.937304615974426,0.966248750686646,31.1228923797607,0,30,4,200,-0.000262402900261804,-0.361613899469376,0.0181484799832106,3,,,,,,,,,,,,,,,,
,3959162217.65648,179.996803283691,999.832702636719,,,6,,,,30.9216344234171,,,10,,,,,,,,,,,,,,,,,,,,,,179.978973388672,180.014633178711,999.832702636719,999.832702636719,,,6.43234157562256,,1,0,0,0,0.0002288818359375,36.6568908691406,1,1,1,179.978973388672,0,179.999256896973,-199.996810913086,1,0.000808830879886056,3.99375433342275E-5,0.000810217421269559,3.99429789067946E-5,0.933164179325104,0.963630080223084,31.135669708252,0,30,4,200,-0.000330651208059862,-0.358889847993851,0.0162408482283354,1,,,,,,,,,,,,,,,,
,3959162342.72975,179.995887756348,999.832702636719,,,6,,,,30.9216344234171,,,10,,,,,,,,,,,,,,,,,,,,,,179.984939575195,180.014022827148,999.832702636719,999.832702636719,,,6.4335789680481,,1,0,0,0,7.62939453125E-5,35.6793746948242,1,1,1,179.992584228516,0,180.000348691587,-195.998413085938,1,0.000801460986980704,2.28508950304097E-5,0.000802885240915326,2.28530587424283E-5,0.931211054325104,0.962843894958496,31.1428298950195,1.85185999725945E-5,30,4,200,-0.00023332133423537,-0.357209503650665,0.0150644229725003,3,,,,,,,,,,,,,,,,
,3959162470.49597,179.996994018555,999.832702636719,,,6,,,,30.9216344234171,,,10,,,,,,,,,,,,,,,,,,,,,,179.979278564453,180.015045166016,999.832702636719,999.832702636719,,,6.4337854385376,,1,0,0,0,0.0005340576171875,36.1681327819824,1,1,1,179.978942871094,0,180.000062730577,-189.998413085938,1,0.000795222476635638,3.92742500412601E-5,0.00079666084550726,3.92770741221718E-5,0.929958999156952,0.961969554424286,31.1468486785889,0,30,4,200,-0.000225838099140674,-0.354928076267242,0.0137684475630522,1,,,,,,,,,,,,,,,,
,3959162595.49776,179.995025634766,999.832702636719,,,6,,,,30.9216344234171,,,10,,,,,,,,,,,,,,,,,,,,,,179.986633300781,180.013824462891,999.832702636719,999.832702636719,,,6.43413019180298,,1,0,0,0,0.0003814697265625,36.1681327819824,1,1,1,179.990631103516,0,180.000739203559,-186.000015258789,1,0.000790825881980479,2.25485828379704E-5,0.000792273401369853,2.25516200037517E-5,0.930629849433899,0.962122082710266,31.1439208984375,0,30,4,200,-0.000203358169528656,-0.354334831237793,0.0132094696164131,3,,,,,,,,,,,,,,,,
,3959162722.24114,179.996910095215,999.832702636719,,,6,,,,30.9216344234171,,,10,,,,,,,,,,,,,,,,,,,,,,179.982955932617,180.013336181641,999.832702636719,999.832702636719,,,6.43442249298096,,1,0,0,0,0.00030517578125,36.1681327819824,1,1,1,179.982421875,0,180.003509521484,-180.000015258789,1,0.000786358638618992,3.88361952200138E-5,0.000787815868371868,3.88409265857618E-5,0.930066287517548,0.962019979953766,31.1461582183838,0,30,4,200,-0.000372151582268998,-0.352993756532669,0.0121366996318102,1,,,,,,,,,,,,,,,,
,3959162848.02632,179.995811462402,999.832702636719,,,6,,,,30.9216344234171,,,10,,,,,,,,,,,,,,,,,,,,,,179.982818603516,180.015441894531,999.832702636719,999.832702636719,,,6.43510007858276,,1,0,0,0,0.000457763671875,35.6793746948242,1,1,1,179.991317749023,0,179.999649592808,-175.996810913086,1,0.000781178548913489,2.22754564946365E-5,0.000782790065197073,2.22816525321519E-5,0.929386854171753,0.962154448032379,31.1491107940674,0,30,4,200,-0.000313465599901974,-0.35196128487587,0.0117698470130563,3,,,,,,,,,,,,,,,,
,3959162975.57312,179.998123168945,999.832702636719,,,6,,,,30.9216344234171,,,10,,,,,,,,,,,,,,,,,,,,,,179.979537963867,180.015609741211,999.832702636719,999.832702636719,,,6.43523216247559,,1,0,0,0,0.000152587890625,35.6793746948242,1,1,1,179.98063659668,0,180.001148223877,-169.996810913086,1,0.000775621372838344,3.83103014206281E-5,0.000777171665965073,3.83158840500506E-5,0.92845618724823,0.962204575538635,31.1535949707031,,30,4,200,-0.000284753215964884,-0.349970757961273,0.0104883182793856,1,,,,,,,,,,,,,,,,
,3959163100.62312,179.996726989746,999.832702636719,,,6,,,,30.9216344234171,,,10,,,,,,,,,,,,,,,,,,,,,,179.986679077148,180.014190673828,999.832702636719,999.832702636719,,,6.43598079681396,,1,0,0,0,0.0142669677734375,35.6793746948242,1,1,1,179.99348449707,0,180.000828495732,-165.998413085938,1,0.000771199510517375,2.19921915056916E-5,0.00077274239415266,2.19948044451323E-5,0.928552448749542,0.963159024715424,31.1555099487305,1.42714643516229E-5,30,4,200,-0.000200906360987574,-0.349411636590958,0.00992374867200851,3,,,,,,,,,,,,,,,,
,3959163229.23126,179.997123718262,999.832702636719,,,6,,,,30.9216344234171,,,10,,,,,,,,,,,,,,,,,,,,,,179.980194091797,180.014144897461,999.832702636719,999.832702636719,,,6.43595361709595,,1,0,0,0,0.0006866455078125,34.7018585205078,1,1,1,179.980102539062,0,180.002187093099,-159.998413085938,1,0.000769835240026023,3.80203495700266E-5,0.000771311992246226,3.80230674512803E-5,0.929987132549286,0.965025663375854,31.1534576416016,0,30,4,200,-0.000199332673219033,-0.348979651927948,0.0092514930292964,1,,,,,,,,,,,,,,,,
,3959163353.659,179.996520996094,999.832702636719,,,6,,,,30.9216344234171,,,10,,,,,,,,,,,,,,,,,,,,,,179.985336303711,180.016510009766,999.832702636719,999.832702636719,,,6.43660163879395,,1,0,0,0,0.0003814697265625,35.6793746948242,1,1,1,179.992370605469,0,180.001347678048,-155.995208740234,1,0.00076800566500961,2.18963246086553E-5,0.000769449197266729,2.18988725235316E-5,0.93167507648468,0.966005504131317,31.1479835510254,0.107969626784325,30,4,200,-0.000197142857359722,-0.349257230758667,0.00915425270795822,3,,,,,,,,,,,,,,,,
,3959163482.24666,179.997428894043,999.832702636719,,,6,,,,30.9216344234171,,,10,,,,,,,,,,,,,,,,,,,,,,179.981979370117,180.013534545898,999.832702636719,999.832702636719,,,6.43673038482666,,1,0,0,0,0.00030517578125,35.6793746948242,1,1,1,179.981323242187,0,180.002736409505,-149.995208740234,1,0.000770528749998027,3.8046242892589E-5,0.000771955090578784,3.80510875433176E-5,0.933183252811432,0.967909812927246,31.1449604034424,0,30,4,200,-0.000328690512105823,-0.350617587566376,0.0088169751688838,1,,,,,,,,,,,,,,,,
,3959163608.85596,179.995277404785,999.832702636719,,,6,,,,30.9216344234171,,,10,,,,,,,,,,,,,,,,,,,,,,179.984954833984,180.015289306641,999.832702636719,999.832702636719,,,6.43647146224976,,1,0,0,0,0.00030517578125,35.6793746948242,1,1,1,179.993148803711,0,179.999641701027,-145.996810913086,1,0.000770601287634227,2.19666249519053E-5,0.000771934230925546,2.19676462813765E-5,0.934172689914703,0.968716502189636,31.1419239044189,0,30,4,200,-0.000278937281109393,-0.351557403802872,0.0088306562975049,3,,,,,,,,,,,,,,,,
,3959163739.17245,179.996940612793,999.832702636719,,,6,,,,30.9216344234171,,,10,,,,,,,,,,,,,,,,,,,,,,179.979339599609,180.013946533203,999.832702636719,999.832702636719,,,6.43676662445068,,1,0,0,0,0.000152587890625,35.6793746948242,1,1,1,179.979934692383,0,179.998954772949,-139.996810913086,1,0.000772610863370772,3.81412797271082E-5,0.000773971224902953,3.81474828388232E-5,0.936292886734009,0.970447540283203,31.1359672546387,0,30,4,200,-0.000381928926799446,-0.352781534194946,0.00818474031984806,1,,,,,,,,,,,,,,,,
,3959163866.50311,179.997428894043,999.832702636719,,,6,,,,30.9216344234171,,,10,,,,,,,,,,,,,,,,,,,,,,179.982940673828,180.015167236328,999.832702636719,999.832702636719,,,6.43651437759399,,1,0,0,0,0.0003814697265625,35.6793746948242,1,1,1,179.993133544922,0,179.999839500145,-135.998413085938,1,0.000773517021058087,2.20439371999963E-5,0.000774788273646215,2.20468036424964E-5,0.938288748264313,0.971874475479126,31.1302261352539,0.0536865442991257,30,4,200,-0.000205748583539389,-0.353630691766739,0.00847603660076857,3,,,,,,,,,,,,,,,,
,3959163994.7499,179.998748779297,999.832702636719,,,6,,,,30.9216344234171,,,10,,,,,,,,,,,,,,,,,,,,,,179.979965209961,180.017288208008,999.832702636719,999.832702636719,,,6.43616342544556,,1,0,0,0,0.000457763671875,35.190616607666,1,1,1,179.980209350586,0,180.000625610352,-129.998413085938,1,0.000780547311416584,3.8522115820372E-5,0.000781698075757722,3.85240495936771E-5,0.940905869007111,0.97446620464325,31.1239204406738,,30,4,200,-0.000217380598769523,-0.356734961271286,0.00829481054097414,1,,,,,,,,,,,,,,,,
,3959164121.0426,179.996139526367,999.832702636719,,,6,,,,30.9216344234171,,,10,,,,,,,,,,,,,,,,,,,,,,179.986694335938,180.015060424805,999.832702636719,999.832702636719,,,6.43679428100586,,1,0,0,0,0.0005340576171875,35.6793746948242,1,1,1,179.991470336914,0,180.001299257632,-125.995208740234,1,0.000783217816647139,2.23128293259548E-5,0.000784259456551613,2.23145271058339E-5,0.94403350353241,0.974880039691925,31.1115016937256,,30,4,200,-0.000131831679027528,-0.358554482460022,0.00845386926084757,3,,,,,,,,,,,,,,,,
,3959164247.77646,179.997444152832,999.832702636719,,,6,,,,30.9216344234171,,,10,,,,,,,,,,,,,,,,,,,,,,179.979553222656,180.015380859375,999.832702636719,999.832702636719,,,6.4364767074585,,1,0,0,0,0.0003814697265625,35.6793746948242,1,1,1,179.979507446289,0,180.002056545681,-119.995208740234,1,0.000793260344148463,3.91365560423611E-5,0.000794196833112106,3.91390018630657E-5,0.946804404258728,0.975528180599213,31.1005458831787,0,30,4,200,-0.000286416383460164,-0.362487643957138,0.00909578334540129,1,,,,,,,,,,,,,,,,
,3959164374.05219,179.995895385742,999.832702636719,,,6,,,,30.9216344234171,,,10,,,,,,,,,,,,,,,,,,,,,,179.986480712891,180.013412475586,999.832702636719,999.832702636719,,,6.43617010116577,,1,0,0,0,0.00030517578125,35.6793746948242,1,1,1,179.992660522461,0,180.000652737088,-115.996803283691,1,0.000798118915962245,2.27312756918114E-5,0.000798967314106776,2.27330233975898E-5,0.949015736579895,0.974870800971985,31.0894737243652,0,30,4,200,-0.000232535239774734,-0.365055590867996,0.0095044719055295,3,,,,,,,,,,,,,,,,
,3959164502.83727,179.996650695801,999.832702636719,,,6,,,,30.9216344234171,,,10,,,,,,,,,,,,,,,,,,,,,,179.978271484375,180.015029907227,999.832702636719,999.832702636719,,,6.43663883209229,,1,0,0,0,0.000457763671875,36.6568908691406,1,1,1,179.978271484375,0,179.998861694336,-109.996803283691,1,0.000805500968540329,3.97269957200165E-5,0.00080621531235668,3.97315038665114E-5,0.953585982322693,0.975292384624481,31.0699348449707,0.186317712068558,30,4,200,-0.000475138542242348,-0.367950201034546,0.0094660697504878,1,,,,,,,,,,,,,,,,
,3959164628.62652,179.997673034668,999.832702636719,,,6,,,,30.9216344234171,,,10,,,,,,,,,,,,,,,,,,,,,,179.984802246094,180.015274047852,999.832702636719,999.832702636719,,,6.43658494949341,,1,0,0,0,0.0002288818359375,35.6793746948242,1,1,1,179.993423461914,0,180.000727900752,-105.998405456543,1,0.000809912287288946,2.30576424222354E-5,0.000810453700036421,2.30591668353909E-5,0.957850158214569,0.976047396659851,31.0525722503662,0,30,4,200,-0.000254793063504621,-0.370202392339706,0.00966656859964132,3,,,,,,,,,,,,,,,,
,3959164757.5981,179.9970703125,999.832702636719,,,6,,,,30.9216344234171,,,10,,,,,,,,,,,,,,,,,,,,,,179.980972290039,180.012420654297,999.832702636719,999.832702636719,,,6.43685150146484,,1,0,0,0,0.0003814697265625,35.6793746948242,1,1,1,179.981719970703,0,180.001807318793,-99.998405456543,1,0.000820103746097167,4.04318209707391E-5,0.000820494764395701,4.04330279839453E-5,0.962650060653687,0.977589845657349,31.0344352722168,1.7741378997016E-6,30,4,200,-0.000260415632510558,-0.373855262994766,0.00997642707079649,1,,,,,,,,,,,,,,,,
,3959164882.4777,179.996513366699,999.832702636719,,,6,,,,30.9216344234171,,,10,,,,,,,,,,,,,,,,,,,,,,179.986968994141,180.015151977539,999.832702636719,999.832702636719,,,6.43678140640259,,1,0,0,0,0.0005340576171875,35.6793746948242,1,1,1,179.991882324219,0,180.001436021593,-96.0000076293945,1,0.000823910226382928,2.34489468836635E-5,0.000824209203874051,2.34494220208821E-5,0.965913951396942,0.978152275085449,31.0206069946289,0,30,4,200,-0.000122848665341735,-0.375661313533783,0.0104639362543821,3,,,,,,,,,,,,,,,,
,3959165008.79131,179.997413635254,999.832702636719,,,6,,,,30.9216344234171,,,10,,,,,,,,,,,,,,,,,,,,,,179.982940673828,180.014953613281,999.832702636719,999.832702636719,,,6.43628549575806,,1,0,0,0,0.0003814697265625,35.6793746948242,1,1,1,179.981719970703,0,180.00377231174,-90.0000076293945,1,0.000833234172577193,4.10687231084885E-5,0.000833425734577877,4.10692270300096E-5,0.970204949378967,0.978720307350159,31.0004711151123,0,30,4,200,-0.000246921932557598,-0.378576159477234,0.0110608628019691,1,,,,,,,,,,,,,,,,
,3959165134.21986,179.99592590332,999.832702636719,,,6,,,,30.9216344234171,,,10,,,,,,,,,,,,,,,,,,,,,,179.983322143555,180.014068603516,999.832702636719,999.832702636719,,,6.43665504455566,,1,0,0,0,0.0002288818359375,35.6793746948242,1,1,1,179.993362426758,0,179.999634354203,-85.9968032836914,1,0.000837038270447766,2.38176217351836E-5,0.000837177855701214,2.3818242235941E-5,0.972665190696716,0.978413581848145,30.9849872589111,6.78713798522949,30,4,200,-0.000268378295004368,-0.380620092153549,0.0113558219745755,3,,,,,,,,,,,,,,,,
,3959165262.34504,179.993125915527,999.832702636719,,,6,,,,30.9216344234171,,,10,,,,,,,,,,,,,,,,,,,,,,179.979309082031,180.009338378906,999.832702636719,999.832702636719,,,6.43630933761597,,1,0,0,0,0.000762939453125,35.6793746948242,1,1,1,179.980178833008,0,179.998350524902,-79.9968032836914,1,0.000842017421843317,4.14955404413799E-5,0.000842095192632233,4.14966374684496E-5,0.975639283657074,0.978513479232788,30.9649982452393,,30,4,200,-0.000369911023881286,-0.382534921169281,0.0106985801830888,1,,,,,,,,,,,,,,,,
,3959165387.75247,179.99681854248,999.832702636719,,,6,,,,30.9216344234171,,,10,,,,,,,,,,,,,,,,,,,,,,179.985458374023,180.016036987305,999.832702636719,999.832702636719,,,6.43683099746704,,1,0,0,0,0.0142669677734375,37.1456527709961,1,1,1,179.993743896484,0,180.001069810655,-75.998405456543,1,0.000842740777845661,2.39769021219635E-5,0.00084277053563267,2.39770524078883E-5,0.977658092975617,0.978997528553009,30.9504413604736,0,30,4,200,-0.000333950301865116,-0.383023351430893,0.0108733354136348,3,,,,,,,,,,,,,,,,
,3959165513.1865,179.997711181641,999.832702636719,,,6,,,,30.9216344234171,,,10,,,,,,,,,,,,,,,,,,,,,,179.978927612305,180.015426635742,999.832702636719,999.832702636719,,,6.43736982345581,,1,0,0,0,0.00030517578125,35.190616607666,1,1,1,179.979995727539,0,180.000323486328,-69.998405456543,1,0.000844472074105458,4.16131937956604E-5,0.000844477470437151,4.16132775996253E-5,0.979159653186798,0.979370594024658,30.9328346252441,0.0712810605764389,30,4,200,-0.00037260027602315,-0.383432984352112,0.00995059870183468,1,,,,,,,,,,,,,,,,
,3959165639.17881,179.995613098145,999.832702636719,,,6,,,,30.9216344234171,,,10,,,,,,,,,,,,,,,,,,,,,,179.985198974609,180.013061523438,999.832702636719,999.832702636719,,,6.43709182739258,,1,0,0,0,0.0003814697265625,37.1456527709961,1,1,1,179.992248535156,0,180.000022040473,-65.9952011108398,1,0.000843206607672239,2.39895229649717E-5,0.000843207038823607,2.39895300240138E-5,0.978880405426025,0.978890657424927,30.9191341400146,0,30,4,200,-0.000137418377562426,-0.383147925138474,0.00962657667696476,3,,,,,,,,,,,,,,,,
,3959165765.41946,179.998497009277,999.832702636719,,,6,,,,30.9216344234171,,,10,,,,,,,,,,,,,,,,,,,,,,179.982269287109,180.015335083008,999.832702636719,999.832702636719,,,6.4371771812439,,1,0,0,0,0.0003814697265625,35.190616607666,1,1,1,179.981658935547,0,180.003311157227,-59.9952011108398,1,0.000843442185684685,4.15645121507295E-5,0.00084345479144037,4.15645414667526E-5,0.97687304019928,0.977496922016144,30.9013652801514,0,30,4,200,-0.000244093214860186,-0.383006036281586,0.00900927092880011,1,,,,,,,,,,,,,,,,
,3959165891.81597,179.995338439941,999.832702636719,,,6,,,,30.9216344234171,,,10,,,,,,,,,,,,,,,,,,,,,,179.986465454102,180.014343261719,999.832702636719,999.832702636719,,,6.43686580657959,,1,0,0,0,0.0003814697265625,35.190616607666,1,1,1,179.990783691406,0,180.001053421586,-55.9968032836914,1,0.000841835260029653,2.39529827533889E-5,0.000841864578899422,2.39529203862314E-5,0.974438369274139,0.975946307182312,30.8887538909912,0,30,4,200,-0.000236241641687229,-0.383123070001602,0.00879895221441984,3,,,,,,,,,,,,,,,,
,3959166018.79855,179.998901367187,999.832702636719,,,6,,,,30.9216344234171,,,10,,,,,,,,,,,,,,,,,,,,,,179.980697631836,180.016296386719,999.832702636719,999.832702636719,,,6.43627452850342,,1,0,0,0,0.0003814697265625,35.190616607666,1,1,1,179.981506347656,0,180.001432800293,-49.9968032836914,1,0.000839038110435785,4.13542829578599E-5,0.00083908769047335,4.13536488298633E-5,0.970625162124634,0.973276376724243,30.8753604888916,6.78711795806885,30,4,200,-0.000319952087011188,-0.382071912288666,0.00761727569624782,1,,,,,,,,,,,,,,,,
,3959166144.27,179.996772766113,999.832702636719,,,6,,,,30.9216344234171,,,10,,,,,,,,,,,,,,,,,,,,,,179.983520507813,180.014923095703,999.832702636719,999.832702636719,,,6.43685913085938,,1,0,0,0,0.0142669677734375,35.6793746948242,1,1,1,179.993133544922,0,179.999550148293,-45.9984016418457,1,0.000832831181858111,2.37024297298777E-5,0.000832916543645208,2.37022726064091E-5,0.966407060623169,0.96982604265213,30.8654956817627,0,30,4,200,-0.000426111597334966,-0.380396723747253,0.00662616407498717,3,,,,,,,,,,,,,,,,
,3959166272.18987,179.993804931641,999.832702636719,,,6,,,,30.9216344234171,,,10,,,,,,,,,,,,,,,,,,,,,,179.973678588867,180.012924194336,999.832702636719,999.832702636719,,,6.43644523620605,,1,0,0,0,0.0003814697265625,35.6793746948242,1,1,1,179.974685668945,0,179.996688842773,-39.9984016418457,1,0.000825591045712277,4.07018719689252E-5,0.00082569281642275,4.07014739791176E-5,0.962963342666626,0.966743946075439,30.8594436645508,0,30,4,200,-0.000304576649796218,-0.378080189228058,0.00479147583246231,1,,,,,,,,,,,,,,,,
,3959166398.16,180.001243591309,999.832702636719,,,6,,,,30.9216344234171,,,10,,,,,,,,,,,,,,,,,,,,,,179.988723754883,180.020080566406,999.832702636719,999.832702636719,,,6.4364161491394,,1,0,0,0,0.0003814697265625,36.1681327819824,1,1,1,179.993728637695,0,180.003866125036,-35.9952011108398,1,0.00081933135547422,2.33234278264002E-5,0.000819481871981178,2.33236500065163E-5,0.96032989025116,0.964987456798553,30.8504295349121,0,30,4,200,-0.000163333272212185,-0.376472920179367,0.00383695005439222,3,,,,,,,,,,,,,,,,
,3959166526.22027,179.994445800781,999.832702636719,,,6,,,,30.9216344234171,,,10,,,,,,,,,,,,,,,,,,,,,,179.973358154297,180.015518188477,999.832702636719,999.832702636719,,,6.4365382194519,,1,0,0,0,0.0005340576171875,35.6793746948242,1,1,1,179.973373413086,0,179.995690917969,-29.9952011108398,1,0.000813249450330761,4.01026601918044E-5,0.000813443988655685,4.01029816155628E-5,0.957203030586243,0.962986707687378,30.8394222259521,5.55332517623901,30,4,200,-0.000248028227360919,-0.37399822473526,0.0027364210691303,1,,,,,,,,,,,,,,,,
,3959166651.17542,179.996208190918,999.832702636719,,,6,,,,30.9216344234171,,,10,,,,,,,,,,,,,,,,,,,,,,179.986480712891,180.014907836914,999.832702636719,999.832702636719,,,6.43635749816895,,1,0,0,0,0.0006866455078125,35.190616607666,1,1,1,179.991485595703,0,180.000951696325,-25.9968013763428,1,0.000809355985119446,2.30442162926346E-5,0.000809609160485309,2.30447034182466E-5,0.955442249774933,0.962541580200195,30.8293266296387,1.38376926770434E-5,30,4,200,-0.000189592246897519,-0.374141991138458,0.00159493531100452,3,,,,,,,,,,,,,,,,
,3959166777.56669,179.997047424316,999.832702636719,,,6,,,,30.9216344234171,,,10,,,,,,,,,,,,,,,,,,,,,,179.983245849609,180.014373779297,999.832702636719,999.832702636719,,,6.43621587753296,,1,0,0,0,0.0002288818359375,34.7018585205078,1,1,1,179.982376098633,0,180.004211425781,-19.9968013763428,1,0.000802911448758763,3.95998985668325E-5,0.000803185056046816,3.95997195788463E-5,0.953253626823425,0.961321413516998,30.8212299346924,5.55168724060059,30,4,200,-0.000356195319909602,-0.371990025043488,8.74485413078219E-5,1,,,,,,,,,,,,,,,,
,3959166903.9268,179.995216369629,999.832702636719,,,6,,,,30.9216344234171,,,10,,,,,,,,,,,,,,,,,,,,,,179.986053466797,180.014251708984,999.832702636719,999.832702636719,,,6.43619251251221,,1,0,0,0,0.0005340576171875,36.6568908691406,1,1,1,179.992279052734,0,179.999869452582,-15.9984006881714,1,0.000796198272209175,2.26731311376966E-5,0.000796474556563,2.26727463796213E-5,0.952070534229279,0.960366487503052,30.8187580108643,5.5514645576477,30,4,200,-0.00040661750244908,-0.370478630065918,-0.00076958118006587,3,,,,,,,,,,,,,,,,
,3959167033.2757,179.996635437012,999.832702636719,,,6,,,,30.9216344234171,,,10,,,,,,,,,,,,,,,,,,,,,,179.97639465332,180.015670776367,999.832702636719,999.832702636719,,,6.43607091903687,,1,0,0,0,0.000152587890625,35.190616607666,1,1,1,179.977600097656,0,179.998835754395,-9.99840068817139,1,0.0007886371351917,3.88991399533283E-5,0.000788908424242761,3.8898204682629E-5,0.951502680778503,0.959782004356384,30.8180694580078,0,30,4,200,-0.00035633792867884,-0.36826103925705,-0.00288032391108572,1,,,,,,,,,,,,,,,,
,3959167158.43299,179.997123718262,999.832702636719,,,6,,,,30.9216344234171,,,10,,,,,,,,,,,,,,,,,,,,,,179.981781005859,180.015289306641,999.832702636719,999.832702636719,,,6.43591928482056,,1,0,0,0,0.0002288818359375,35.6793746948242,1,1,1,179.992370605469,0,179.999894883898,-6.00000047683716,1,0.000782584561241076,2.22857655187866E-5,0.000782867155366455,2.22856030530474E-5,0.951785027980804,0.960131824016571,30.8180389404297,,30,4,200,-0.000295009987894446,-0.367025017738342,-0.00392905343323946,3,,,,,,,,,,,,,,,,
,3959167285.93574,179.997528076172,999.832702636719,,,6,,,,30.9216344234171,,,10,,,,,,,,,,,,,,,,,,,,,,179.978103637695,180.016220092773,999.832702636719,999.832702636719,,,6.43631315231323,,1,0,0,0,0.0006866455078125,35.6793746948242,1,1,1,179.97883605957,0,180.000971984863,0,1,0.000778554567012974,3.83999247445072E-5,0.000778862945694368,3.840065445644E-5,0.952519595623016,0.961247086524963,30.8165912628174,0,30,4,200,-0.000176006782567129,-0.365826368331909,-0.00505836261436343,1,,,,,,,,,,,,,,,,
,3959167411.33172,179.996627807617,999.832702636719,,,6,,,,30.9216344234171,,,10,,,,,,,,,,,,,,,,,,,,,,179.983673095703,180.016998291016,999.832702636719,999.832702636719,,,6.43585634231567,,1,0,0,0,0.0006866455078125,35.190616607666,1,1,1,179.992599487305,0,180.000689276334,3.99840021133423,1,0.000775693543434967,2.20884658365911E-5,0.000776016182191018,2.2088609921358E-5,0.952783286571503,0.962420046329498,30.8122158050537,0,30,4,200,-0.000114822854811791,-0.365596503019333,-0.00529539072886109,3,,,,,,,,,,,,,,,,
,3959167539.73142,179.99747467041,999.832702636719,,,6,,,,30.9216344234171,,,10,,,,,,,,,,,,,,,,,,,,,,179.979202270508,180.01579284668,999.832702636719,999.832702636719,,,6.43564176559448,,1,0,0,0,0.00030517578125,34.7018585205078,1,1,1,179.979156494141,0,180.001388549805,9.99840068817139,1,0.000774575644203736,3.82002782121092E-5,0.000774887904205893,3.82004556952996E-5,0.954435050487518,0.964213371276855,30.8139038085937,5.3571720123291,30,4,200,-0.00032494158949703,-0.365271061658859,-0.00582243781536818,1,,,,,,,,,,,,,,,,
,3959167663.55379,179.995826721191,999.832702636719,,,6,,,,30.9216344234171,,,10,,,,,,,,,,,,,,,,,,,,,,179.985931396484,180.014221191406,999.832702636719,999.832702636719,,,6.43624973297119,,1,0,0,0,0.0003814697265625,36.6568908691406,1,1,1,179.990371704102,0,179.998946578414,13.9968004226685,1,0.000771676270752419,2.19713506897732E-5,0.000771915723583882,2.19696241174933E-5,0.955470621585846,0.965266346931458,30.8155498504639,0,30,4,200,-0.000199435526155867,-0.365533828735352,-0.00626254733651876,3,,,,,,,,,,,,,,,,
,3959167792.53448,179.996307373047,999.832702636719,,,6,,,,30.9216344234171,,,10,,,,,,,,,,,,,,,,,,,,,,179.978012084961,180.014602661133,999.832702636719,999.832702636719,,,6.43587398529053,,1,0,0,0,0.00030517578125,36.6568908691406,1,1,1,179.978012084961,0,179.998136901855,19.9968013763428,1,0.00077099186804518,3.8016683719039E-5,0.000771217446526539,3.80152494996871E-5,0.958578646183014,0.967502176761627,30.8238754272461,0,30,4,200,-0.000289178395178169,-0.365241020917892,-0.00723103759810328,1,,,,,,,,,,,,,,,,
,3959167917.50938,179.996055603027,999.832702636719,,,6,,,,30.9216344234171,,,10,,,,,,,,,,,,,,,,,,,,,,179.986038208008,180.015426635742,999.832702636719,999.832702636719,,,6.43630170822144,,1,0,0,0,0.00030517578125,35.6793746948242,1,1,1,179.991455078125,0,180.000945479782,24.0000019073486,1,0.000770097458731316,2.19211841568794E-5,0.000770302376055943,2.19207953276693E-5,0.961175739765167,0.969333589076996,30.8309783935547,9.28899383544922,30,4,200,-0.000209641599212773,-0.36616176366806,-0.0076997852884233,3,,,,,,,,,,,,,,,,
,3959168045.12799,179.996940612793,999.832702636719,,,6,,,,30.9216344234171,,,10,,,,,,,,,,,,,,,,,,,,,,179.9794921875,180.014892578125,999.832702636719,999.832702636719,,,6.43664216995239,,1,0,0,0,0.0005340576171875,35.6793746948242,1,1,1,179.978988647461,0,180.002158270942,29.9952011108398,1,0.000773277408806868,3.81192244394522E-5,0.000773450395566616,3.81197525417397E-5,0.965588629245758,0.97234320640564,30.8436603546143,0.303847104310989,30,4,200,-0.000179171445779502,-0.367142856121063,-0.00758999958634377,1,,,,,,,,,,,,,,,,
,3959168171.41259,179.998481750488,999.832702636719,,,6,,,,30.9216344234171,,,10,,,,,,,,,,,,,,,,,,,,,,179.983062744141,180.01708984375,999.832702636719,999.832702636719,,,6.43624591827393,,1,0,0,0,0.0003814697265625,35.6793746948242,1,1,1,179.993255615234,0,180.000100029839,33.9984016418457,1,0.000774601602031125,2.20447469705198E-5,0.000774748771348068,2.20446989571473E-5,0.96703690290451,0.97349339723587,30.847053527832,0.0997461974620819,30,4,200,-0.000172437357832678,-0.368575423955917,-0.00745148956775665,3,,,,,,,,,,,,,,,,
,3959168300.13748,179.997512817383,999.832702636719,,,6,,,,30.9216344234171,,,10,,,,,,,,,,,,,,,,,,,,,,179.980117797852,180.015350341797,999.832702636719,999.832702636719,,,6.43634366989136,,1,0,0,0,0.000457763671875,35.190616607666,1,1,1,179.979675292969,0,180.001678466797,39.9984016418457,1,0.000781412520094115,3.85147558032773E-5,0.000781510513458223,3.85145063794561E-5,0.970010876655579,0.974784851074219,30.8600101470947,0,30,4,200,-0.000364282022928819,-0.370844274759293,-0.0065741091966629,1,,,,,,,,,,,,,,,,
,3959168425.5984,179.995765686035,999.832702636719,,,6,,,,30.9216344234171,,,10,,,,,,,,,,,,,,,,,,,,,,179.984558105469,180.014785766602,999.832702636719,999.832702636719,,,6.4359335899353,,1,0,0,0,7.62939453125E-5,35.6793746948242,1,1,1,179.99284362793,0,179.999917489511,43.9968032836914,1,0.00078450831636822,2.23237580368123E-5,0.000784577382224876,2.23235974319205E-5,0.971290707588196,0.974822461605072,30.86936378479,9.2955207824707,30,4,200,-0.000276646023849025,-0.373094826936722,-0.00652003940194845,3,,,,,,,,,,,,,,,,
,3959168556.40485,179.99666595459,999.832702636719,,,6,,,,30.9216344234171,,,10,,,,,,,,,,,,,,,,,,,,,,179.979293823242,180.012771606445,999.832702636719,999.832702636719,,,6.43574285507202,,1,0,0,0,0.00030517578125,35.6793746948242,1,1,1,179.980560302734,0,179.998500061035,49.9968032836914,1,0.000792548781244737,3.90588767230366E-5,0.000792564643260151,3.90582193316243E-5,0.974393963813782,0.975874781608582,30.8891582489014,3.96997618675232,30,4,200,-0.000383244885597378,-0.376510083675385,-0.00631593586876988,1,,,,,,,,,,,,,,,,
,3959168681.99144,179.995193481445,999.832702636719,,,6,,,,30.9216344234171,,,10,,,,,,,,,,,,,,,,,,,,,,179.981964111328,180.016174316406,999.832702636719,999.832702636719,,,6.435715675354,,1,0,0,0,0.0003814697265625,36.1681327819824,1,1,1,179.990234375,0,179.999893188477,53.9952011108398,1,0.000796790545471,2.26707155368387E-5,0.000796794611567482,2.26705694332687E-5,0.975493013858795,0.975968539714813,30.9034671783447,2.27699672450399E-8,30,4,200,-0.000272236677119508,-0.378259897232056,-0.00538181746378541,3,,,,,,,,,,,,,,,,
,3959168811.60645,179.998817443848,999.832702636719,,,6,,,,30.9216344234171,,,10,,,,,,,,,,,,,,,,,,,,,,179.979858398438,180.016479492187,999.832702636719,999.832702636719,,,6.43591928482056,,1,0,0,0,0.0005340576171875,35.190616607666,1,1,1,179.981155395508,0,180.000360107422,59.9952011108398,1,0.000806119562335264,3.97254497978257E-5,0.000806118900555656,3.972536142906E-5,0.976708590984344,0.976768910884857,30.9279689788818,,30,4,200,-0.000241267684032209,-0.382035672664642,-0.00499489810317755,1,,,,,,,,,,,,,,,,
,3959168936.49481,179.996131896973,999.832702636719,,,6,,,,30.9216344234171,,,10,,,,,,,,,,,,,,,,,,,,,,179.984848022461,180.01383972168,999.832702636719,999.832702636719,,,6.43595457077026,,1,0,0,0,0.0006866455078125,35.6793746948242,1,1,1,179.993103027344,0,179.999322396738,63.9984016418457,1,0.000809925936478598,2.30440868069923E-5,0.000809935862937271,2.30441394967396E-5,0.976170063018799,0.976591944694519,30.9385318756103,,30,4,200,-0.000180822840775363,-0.383884102106094,-0.00444429274648428,3,,,,,,,,,,,,,,,,
,3959169064.82451,179.997856140137,999.832702636719,,,6,,,,30.9216344234171,,,10,,,,,,,,,,,,,,,,,,,,,,179.98307800293,180.014785766602,999.832702636719,999.832702636719,,,6.43556404113769,,1,0,0,0,0.0005340576171875,36.1681327819824,1,1,1,179.983657836914,0,180.003001403809,69.998405456543,1,0.000819933515141251,4.04089003075741E-5,0.000819970291937336,4.04089700536841E-5,0.973985075950623,0.975698232650757,30.9567413330078,0,30,4,200,-0.000315365439746529,-0.388011068105698,-0.00394957419484854,1,,,,,,,,,,,,,,,,
,3959169190.05688,179.996910095215,999.832702636719,,,6,,,,30.9216344234171,,,10,,,,,,,,,,,,,,,,,,,,,,179.983062744141,180.015991210938,999.832702636719,999.832702636719,,,6.4354190826416,,1,0,0,0,0.000152587890625,35.6793746948242,1,1,1,179.991439819336,0,179.999610355922,73.9968032836914,1,0.000825368839350284,2.34862453314655E-5,0.00082544891779765,2.34865366453858E-5,0.971633315086365,0.974789559841156,30.9707622528076,0.103539817035198,30,4,200,-0.000293299410259351,-0.389942228794098,-0.00270363851450384,3,,,,,,,,,,,,,,,,
,3959169318.52396,179.997787475586,999.832702636719,,,6,,,,30.9216344234171,,,10,,,,,,,,,,,,,,,,,,,,,,179.981323242187,180.014251708984,999.832702636719,999.832702636719,,,6.43539237976074,,1,0,0,0,0.0003814697265625,36.1681327819824,1,1,1,179.981323242187,0,180.000833129883,79.9968032836914,1,0.000832747819919672,4.10465793326929E-5,0.000832943252200102,4.10490780352834E-5,0.968750655651092,0.974915444850922,30.9919471740723,5.37065458297729,30,4,200,-0.000376028794562444,-0.392729669809341,-0.00256331218406558,1,,,,,,,,,,,,,,,,
,3959169442.71833,179.99585723877,999.832702636719,,,6,,,,30.9216344234171,,,10,,,,,,,,,,,,,,,,,,,,,,179.985794067383,180.014221191406,999.832702636719,999.832702636719,,,6.43591070175171,,1,0,0,0,0,37.1456527709961,1,1,1,179.99235534668,0,180.00008420591,84.0000076293945,1,0.000835346280574226,2.37740158257959E-5,0.000835603076453986,2.37751151705411E-5,0.966391861438751,0.975348174571991,31.0078296661377,5.56846761703491,30,4,200,-0.000285032379906625,-0.393660396337509,-0.00191742484457791,3,,,,,,,,,,,,,,,,
,3959169571.89574,179.997123718262,999.832702636719,,,6,,,,30.9216344234171,,,10,,,,,,,,,,,,,,,,,,,,,,179.977828979492,180.016067504883,999.832702636719,999.832702636719,,,6.43497323989868,,1,0,0,0,0.00030517578125,35.6793746948242,1,1,1,179.978179931641,0,179.998448181152,90.0000076293945,1,0.000841136579692021,4.14689745923423E-5,0.000841533613227742,4.14704826935811E-5,0.962506532669067,0.976858675479889,31.0332527160645,6.98379199093324E-6,30,4,200,-0.000331411312799901,-0.395186841487885,-0.00180522620212287,1,,,,,,,,,,,,,,,,
,3959169595.88916,179.995574951172,999.832702636719,,,6,,,,30.9216344234171,,,10,,,,,,,,,,,,,,,,,,,,,,179.98518371582,180.015655517578,999.832702636719,999.832702636719,,,6.43537998199463,,1,0,0,0,0.0150299072265625,35.6793746948242,1,1,1,179.991409301758,0,179.999908447266,90.0000076293945,1,0.000839848396391698,2.39055756555965E-5,0.00084024849775152,2.39066475129068E-5,0.962374448776245,0.976470470428467,31.0327548980713,,30,4,200,-0.00022769313363824,-0.395369440317154,-0.00171706802211702,3,,,,,,,,,,,,,,,,