File: PPMS_Data_and_Plotting/Data/RuCl3/Data/Magnetisation/Rotator/TB001_RuCl3_H-parra-ab_61p2_mg_14-06-25_ZFCW_100K.dat
[Header]
; MPMS3 Data File (default extension .dat)
; Copyright (c) 2007, Quantum Design, Inc. All rights reserved.
TITLE,
FILEOPENTIME,3959135986.62032,06/15/2025,7:59 am
BYAPP,MPMS3 w/ AC,1.0,1.1
INFO,MPMS3 Measurement Release 1.2.2 Build 0, MultiVu Release 2.3.5.2,APPNAME
INFO,Linear Motor Servo Controller,MOTOR_MODULE_NAME
INFO,3101-100 N4,MOTOR_HW_VERSION
INFO,MMC1299,MOTOR_SERIAL_NUMBER
INFO,01.04.28,MOTOR_SOFTWARE_VERSION
INFO,Quantum Design Squid Module,SQUID_MODULE_NAME
INFO,3101-501 B0,SQUID_HW_VERSION
INFO,SQM364,SQUID_SERIAL_NUMBER
INFO,01.03.04,SQUID_SOFTWARE_VERSION
INFO,Quantum Design VSM Oven,OVEN_MODULE_NAME
INFO,3101-201 A3,OVEN_HW_VERSION
INFO,OVB387,OVEN_SERIAL_NUMBER
INFO,01.07.07,OVEN_SOFTWARE_VERSION
INFO,SQUID AC,AC_MODULE_NAME
INFO,3101-401 G0,AC_HW_VERSION
INFO,SAC242,AC_SERIAL_NUMBER
INFO,SQUID AC 00.95.11,AC_SOFTWARE_VERSION
INFO,TCI374,COIL_SERIAL_NUMBER
INFO,0,MOMENT_UNITS
INFO,RuCl3,SAMPLE_MATERIAL
INFO,single crystal,SAMPLE_COMMENT
INFO,61.2,SAMPLE_MASS
INFO,,SAMPLE_VOLUME
INFO,,SAMPLE_MOLECULAR_WEIGHT
INFO,,SAMPLE_SIZE
INFO,,SAMPLE_SHAPE
INFO,Rotator,SAMPLE_HOLDER
INFO,Standard,SAMPLE_HOLDER_DETAIL
INFO,67.44,SAMPLE_OFFSET
DATATYPE,COMMENT,1
DATATYPE,TIME,2
STARTUPAXIS,X,2
STARTUPAXIS,Y1,5
FIELDGROUP, VSM,2,3,4,5,6,8,9,10,11,14,15
FIELDGROUP, DC, 2,3,4,14,56,57,58,59,60,61,62,63,64,65,66,67,68,69
FIELDGROUP, AC, 2,3,4,11,16,17,18,19,20,21,22,23,24,25,26,27,28,29,30
STARTUPGROUP, All
[Data]
Comment,Time Stamp (sec),Temperature (K),Magnetic Field (Oe),Moment (emu),M. Std. Err. (emu),Transport Action,Averaging Time (sec),Frequency (Hz),Peak Amplitude (mm),Center Position (mm),Lockin Signal' (V),Lockin Signal (V),Range,M. Quad. Signal (emu),AC Moment (emu),AC M. Std Err. (emu),AC Phase (deg),AC Phase Std. Err. (deg),AC Susceptibility (emu/Oe),AC Suscept. Std Err. (emu/Oe),AC X' (emu/Oe),AC X' Std Err. (emu/Oe),AC X'' (emu/Oe),AC X'' Std Err. (emu/Oe),AC Drive (Oe),AC Frequency (Hz),AC Averaging Time (sec),AC Cycles,AC Range,AC Measure Type,AC Signal' (V),AC Signal'' (V),AC Trim Coil Ratio,AC Trim Coil Phase,Min. Temperature (K),Max. Temperature (K),Min. Field (Oe),Max. Field (Oe),Mass (grams),Motor Lag (deg),Pressure (Torr),Measure Count,Measurement Number,SQUID Status (code),Motor Status (code),Measure Status (code),Motor Current (amps),Motor Temp. (C),Temp. Status (code),Field Status (code),Chamber Status (code),Chamber Temp (K),Redirection State,Average Temp (K),Rotation Angle (deg),Rotator state,DC Moment Fixed Ctr (emu),DC Moment Err Fixed Ctr (emu),DC Moment Free Ctr (emu),DC Moment Err Free Ctr (emu),DC Fixed Fit,DC Free Fit,DC Calculated Center (mm),DC Calculated Center Err (mm),DC Scan Length (mm),DC Scan Time (s),DC Number of Points,DC Squid Drift,DC Min V (V),DC Max V (V),DC Scans per Measure,He3 temp,Map 02,Map 03,Map 04,Map 05,Map 06,Map 07,Map 08,Map 09,Map 10,Map 11,Map 12,Map 13,Map 14,Map 15,Map 16
,3959135996.68338,50.5287971496582,1000.30609130859,,,6,,,,30.7535683068927,,,100,,,,,,,,,,,,,,,,,,,,,,50.0006217956543,50.9496612548828,1000.30609130859,1000.30609130859,,,6.09316301345825,,1,0,0,0,0,33.7243423461914,1,1,1,51.0568313598633,0,50.2619291941325,90.0000076293945,1,0.00291960030430424,0.000101739025627547,0.00292035569625725,0.00010174246574119,0.975744783878326,0.988222539424896,30.8338146209717,0,30,4,200,-8.59568317537196E-5,-0.123376950621605,0.0124021386727691,2,,,,,,,,,,,,,,,,
,3959136105.20703,66.3422584533691,1000.30609130859,,,6,,,,30.7535683068927,,,10,,,,,,,,,,,,,,,,,,,,,,64.7397079467773,67.9120330810547,1000.30609130859,1000.30609130859,,,6.16491174697876,,1,0,0,0,0.0002288818359375,32.7468223571777,2,1,1,67.9448089599609,0,66.2938987330386,90.0000076293945,1,0.00237530381778596,8.27835640881237E-5,0.00237578551310886,8.2775678229078E-5,0.970529735088348,0.983484387397766,30.8456649780273,5.55388736724854,30,4,200,-0.000907928799279034,-0.949295341968536,0.166462644934654,2,,,,,,,,,,,,,,,,
,3959136208.95419,82.851863861084,1000.30609130859,,,6,,,,30.7535683068927,,,10,,,,,,,,,,,,,,,,,,,,,,81.1862182617187,84.3389205932617,1000.30609130859,1000.30609130859,,,6.21051645278931,,1,0,0,0,0.00030517578125,33.7243423461914,2,1,1,84.5175094604492,0,82.7925925003855,90.0000076293945,1,0.00193746836062332,6.75340733389475E-5,0.00193834969400742,6.75355669088824E-5,0.965954542160034,0.982842445373535,30.8644676208496,0.131572887301445,30,4,200,-0.000841038883663714,-0.801928400993347,0.108451627194881,2,,,,,,,,,,,,,,,,
,3959136312.70115,98.7180633544922,1000.30609130859,,,6,,,,30.7535683068927,,,10,,,,,,,,,,,,,,,,,,,,,,98.0344009399414,99.3875274658203,1000.30609130859,1000.30609130859,,,6.24448013305664,,1,0,0,0,0.02197265625,33.2355842590332,6,1,1,99.401725769043,0,98.8427005343967,90.0000076293945,1,0.00162505110192384,5.6652049659227E-5,0.00162619281794558,5.66581545816862E-5,0.962094783782959,0.984230816364288,30.8835983276367,,30,4,200,-0.000618954480160028,-0.688860952854157,0.0680283755064011,2,,,,,,,,,,,,,,,,
,3959136416.06457,99.9954872131348,1000.30609130859,,,6,,,,30.7535683068927,,,10,,,,,,,,,,,,,,,,,,,,,,99.990364074707,100.000549316406,1000.30609130859,1000.30609130859,,,6.25093698501587,,1,0,0,0,0.0005340576171875,33.7243423461914,1,1,1,100.001106262207,0,99.9964226616754,90.0000076293945,1,0.00161734610740037,5.63852772213022E-5,0.00161850536178897,5.63902666796064E-5,0.961249232292175,0.984294056892395,30.88747215271,0.0459075681865215,30,4,200,-0.000515121326316148,-0.687207937240601,0.0641257464885712,2,,,,,,,,,,,,,,,,
,3959136519.34141,100.00150680542,1000.30609130859,,,6,,,,30.7535683068927,,,10,,,,,,,,,,,,,,,,,,,,,,100.000503540039,100.005256652832,1000.30609130859,1000.30609130859,,,6.25575733184814,,1,0,0,0,0.000457763671875,33.2355842590332,1,1,1,100.000709533691,0,100.002757178413,90.0000076293945,1,0.0016175109080796,5.63919988633871E-5,0.00161869132938172,5.63964862768567E-5,0.960800528526306,0.98457670211792,30.8896827697754,0,30,4,200,-0.00047929523861967,-0.68752920627594,0.0639722794294357,2,,,,,,,,,,,,,,,,
,3959136622.88154,99.9987983703613,1000.30609130859,,,6,,,,30.7535683068927,,,10,,,,,,,,,,,,,,,,,,,,,,99.998046875,100.002639770508,1000.30609130859,1000.30609130859,,,6.26035594940186,,1,0,0,0,0.000152587890625,33.7243423461914,1,1,1,99.9985198974609,0,100.000413682726,90.0000076293945,1,0.00161824132114422,5.64177926535441E-5,0.00161940704621719,5.64213202764657E-5,0.960660576820374,0.98471599817276,30.8906192779541,0.14547111093998,30,4,200,-0.000439098890637979,-0.688363194465637,0.0634839162230492,2,,,,,,,,,,,,,,,,
,3959136726.07315,99.9980773925781,1000.30609130859,,,6,,,,30.7535683068927,,,10,,,,,,,,,,,,,,,,,,,,,,99.996826171875,100.003036499023,1000.30609130859,1000.30609130859,,,6.26454925537109,,1,0,0,0,0.00030517578125,33.7243423461914,1,1,1,99.99755859375,0,100.000057893641,90.0000076293945,1,0.00161856898021155,5.64292577274823E-5,0.00161977003273852,5.64338213370689E-5,0.960636794567108,0.984872698783875,30.8909568786621,INF,30,4,200,-0.000335472577717155,-0.688949704170227,0.0630723387002945,2,,,,,,,,,,,,,,,,
,3959136830.82662,99.9972877502441,1000.30609130859,,,6,,,,30.7535683068927,,,10,,,,,,,,,,,,,,,,,,,,,,99.9958343505859,100.002815246582,1000.30609130859,1000.30609130859,,,6.26826047897339,,1,0,0,0,0.00030517578125,33.7243423461914,1,1,1,99.9972076416016,0,99.999144660102,90.0000076293945,1,0.00161875781972578,5.64358336371032E-5,0.00162003506054848,5.64427710940622E-5,0.960639238357544,0.985206127166748,30.8915672302246,3.98553943634033,30,4,200,-0.000358546414645389,-0.689537882804871,0.0627391710877418,2,,,,,,,,,,,,,,,,
,3959136934.50935,99.9973564147949,1000.30609130859,,,6,,,,30.7535683068927,,,10,,,,,,,,,,,,,,,,,,,,,,99.9960784912109,100.003349304199,1000.30609130859,1000.30609130859,,,6.27189493179321,,1,0,0,0,0.0002288818359375,33.7243423461914,1,1,1,99.9970474243164,0,99.9997895893298,90.0000076293945,1,0.00161868405996974,5.64336919510647E-5,0.0016199967030984,5.64414480642624E-5,0.960445940494537,0.985188663005829,30.8923664093018,5.55809020996094,30,4,200,-0.000399074458982795,-0.690004229545593,0.0622510388493538,2,,,,,,,,,,,,,,,,
,3959137039.88124,99.9966506958008,1000.00256347656,,,6,,,,30.7535683068927,,,10,,,,,,,,,,,,,,,,,,,,,,99.99560546875,100.002906799316,1000.00256347656,1000.00256347656,,,6.27458810806274,,1,0,0,0,0.00030517578125,33.7243423461914,1,1,1,99.9960327148438,0,99.9992014567057,90.0000076293945,5,0.00161875758974546,5.64366034378148E-5,0.00162005919053164,5.64436150892344E-5,0.960283875465393,0.985182583332062,30.8929691314697,7.57303953170776,30,4,200,-0.000367844389984384,-0.623381853103638,0.128892108798027,2,,,,,,,,,,,,,,,,
,3959137143.39168,99.9979629516602,1000.00256347656,,,6,,,,30.7535683068927,,,10,,,,,,,,,,,,,,,,,,,,,,99.9965972900391,100.004425048828,1000.00256347656,1000.00256347656,,,6.27739477157593,,1,0,0,0,0.0142669677734375,34.2131004333496,1,1,1,99.9971084594727,0,100.000124104818,-107.064002990723,5,0.00158110845846874,5.50955482015459E-5,0.00158115855489466,5.50964206022164E-5,0.976643741130829,0.97733211517334,30.7750053405762,0,30,4,200,-0.00013756105909124,-0.610687851905823,0.122818537056446,2,,,,,,,,,,,,,,,,
,3959137247.73015,99.9987907409668,1000.00256347656,,,6,,,,30.7535683068927,,,10,,,,,,,,,,,,,,,,,,,,,,99.9964828491211,100.005126953125,1000.00256347656,1000.00256347656,,,6.28043270111084,,1,0,0,0,0.00030517578125,34.2131004333496,1,1,1,99.9979095458984,0,100.000677744548,-207.196807861328,5,0.00158459218406826,5.54252559710756E-5,0.00159120008635552,5.54417501902414E-5,0.910313427448273,0.981334567070007,31.0866031646729,0,30,4,200,-0.00058479601284489,-0.616032898426056,0.126430779695511,2,,,,,,,,,,,,,,,,
,3959137350.44158,99.9972381591797,1000.00256347656,,,6,,,,30.7535683068927,,,10,,,,,,,,,,,,,,,,,,,,,,99.9964752197266,100.003616333008,1000.00256347656,1000.00256347656,,,6.28271389007568,,1,0,0,0,0,33.7243423461914,1,1,1,99.9969787597656,0,100.000018225776,-299.995208740234,5,0.00159154771844986,5.55826837980428E-5,0.00159546541396875,5.55900594335618E-5,0.929449439048767,0.981613755226135,31.0118274688721,0,30,4,200,-0.000644206709694117,-0.616375267505646,0.124583177268505,2,,,,,,,,,,,,,,,,
,3959137477.71376,99.9996643066406,1000.00256347656,,,6,,,,30.7943755037081,,,10,,,,,,,,,,,,,,,,,,,,,,99.9931945800781,100.004539489746,1000.00256347656,1000.00256347656,,,6.2847261428833,,1,0,0,0,0.000152587890625,34.2131004333496,1,1,1,99.9947891235352,0,99.9989827473958,-295.996826171875,1,0.00160532884375618,7.91942629812476E-5,0.0016076406714974,7.92091351990597E-5,0.948423802852631,0.9873086810112,30.9839897155762,0.388784408569336,30,4,200,-0.000331935589201748,-0.619018077850342,0.125007897615433,1,,,,,,,,,,,,,,,,
,3959137601.43855,100.001247406006,1000.00256347656,,,6,,,,30.7943755037081,,,10,,,,,,,,,,,,,,,,,,,,,,99.9935760498047,100.005378723145,1000.00256347656,1000.00256347656,,,6.28676080703735,,1,0,0,0,0.000152587890625,34.2131004333496,1,1,1,99.9983444213867,0,100.000097769278,-291.998413085937,1,0.00160144539757541,4.56104986171129E-5,0.00160345737990007,4.56135917690817E-5,0.949167370796204,0.985447466373444,30.9790630340576,0,30,4,200,-0.000467590871267021,-0.618071317672729,0.12414263188839,3,,,,,,,,,,,,,,,,
,3959137729.66488,100.000629425049,1000.00256347656,,,6,,,,30.7943755037081,,,10,,,,,,,,,,,,,,,,,,,,,,99.9933700561523,100.004997253418,1000.00256347656,1000.00256347656,,,6.28928470611572,,1,0,0,0,0.0002288818359375,34.2131004333496,1,1,1,99.9962615966797,0,99.999267578125,-285.998413085938,1,0.00159499054870979,7.86834555942957E-5,0.00159704129579613,7.86914789025628E-5,0.948622941970825,0.98335212469101,30.9789352416992,0.203653499484062,30,4,200,-0.000477118388516828,-0.615779340267181,0.122159220278263,1,,,,,,,,,,,,,,,,
,3959137853.96038,99.9999618530273,1000.00256347656,,,6,,,,30.7943755037081,,,10,,,,,,,,,,,,,,,,,,,,,,99.9926071166992,100.004104614258,1000.00256347656,1000.00256347656,,,6.29104375839233,,1,0,0,0,0.0006866455078125,34.2131004333496,1,1,1,99.9974822998047,0,99.9995760236468,-281.995208740234,1,0.00158638395389488,4.51886656565413E-5,0.00158860462391759,4.51944828177742E-5,0.946156322956085,0.980946779251099,30.9858055114746,9.27791881561279,30,4,200,-0.000474029744509608,-0.612841308116913,0.120792061090469,3,,,,,,,,,,,,,,,,
,3959137983.44364,99.9999542236328,1000.00256347656,,,6,,,,30.7943755037081,,,10,,,,,,,,,,,,,,,,,,,,,,99.9934158325195,100.004554748535,1000.00256347656,1000.00256347656,,,6.29286050796509,,1,0,0,0,0.0002288818359375,35.6793746948242,1,1,1,99.9953536987305,0,99.9994218614366,-275.995208740234,1,0.00157972196858276,7.79587188017184E-5,0.00158246942751998,7.7978999767646E-5,0.941964268684387,0.979540526866913,31.0017166137695,3.96154141426086,30,4,200,-0.000393465830711648,-0.610605776309967,0.118631586432457,1,,,,,,,,,,,,,,,,
,3959138108.46183,100.000305175781,1000.00256347656,,,6,,,,30.7943755037081,,,10,,,,,,,,,,,,,,,,,,,,,,99.9939422607422,100.005065917969,1000.00256347656,1000.00256347656,,,6.29500246047974,,1,0,0,0,0.0003814697265625,34.2131004333496,1,1,1,99.9975738525391,0,100.000463415075,-271.996826171875,1,0.00157248570507786,4.48094206775434E-5,0.00157536482928934,4.48210671313319E-5,0.939675152301788,0.97748726606369,31.0081081390381,0.144745692610741,30,4,200,-0.000112967740278691,-0.608403086662292,0.117288410663605,3,,,,,,,,,,,,,,,,
,3959138236.18769,100.000087738037,1000.00256347656,,,6,,,,30.7943755037081,,,10,,,,,,,,,,,,,,,,,,,,,,99.9937362670898,100.004974365234,1000.00256347656,1000.00256347656,,,6.29637479782104,,1,0,0,0,0.000152587890625,34.2131004333496,1,1,1,99.9952011108398,0,100.000128004286,-265.996826171875,1,0.00157025519666945,7.75135693826342E-5,0.00157318186547492,7.75289492684301E-5,0.937272906303406,0.975203037261963,31.0144062042236,0,30,4,200,-0.000227691692998633,-0.608370661735535,0.11549373716116,1,,,,,,,,,,,,,,,,
,3959138360.29684,100.000240325928,1000.00256347656,,,6,,,,30.7943755037081,,,10,,,,,,,,,,,,,,,,,,,,,,99.9904937744141,100.004730224609,1000.00256347656,1000.00256347656,,,6.29848098754883,,1,0,0,0,0.000152587890625,34.7018585205078,1,1,1,99.9965972900391,0,99.9985752812138,-261.998413085938,1,0.00156546393219753,4.46234009515872E-5,0.0015685042300276,4.46305226346486E-5,0.934667885303497,0.973243951797485,31.0220146179199,9.26291656494141,30,4,200,-0.000329353439155966,-0.607195377349854,0.11477318406105,3,,,,,,,,,,,,,,,,
,3959138489.09434,100.000701904297,1000.00256347656,,,6,,,,30.7943755037081,,,10,,,,,,,,,,,,,,,,,,,,,,99.9938888549805,100.005714416504,1000.00256347656,1000.00256347656,,,6.3001971244812,,1,0,0,0,0.0002288818359375,34.2131004333496,1,1,1,99.9956893920898,0,100.000345018175,-255.998413085938,1,0.00156043486569236,7.7068354149678E-5,0.00156393276114196,7.70836262480973E-5,0.929596841335297,0.970224022865295,31.0379543304443,6.92797329975292E-5,30,4,200,-0.000454440945759416,-0.606110870838165,0.112969912588596,1,,,,,,,,,,,,,,,,
,3959138614.11087,100.000118255615,1000.00256347656,,,6,,,,30.7943755037081,,,10,,,,,,,,,,,,,,,,,,,,,,99.9924163818359,100.004920959473,1000.00256347656,1000.00256347656,,,6.30122137069702,,1,0,0,0,0.0113677978515625,34.2131004333496,1,1,1,99.9964828491211,0,99.9994389670236,-251.995208740234,1,0.00155437006811626,4.43321525440657E-5,0.00155806257035917,4.43394958278571E-5,0.926578760147095,0.96852719783783,31.0478992462158,0,30,4,200,-0.000516993226483464,-0.604517817497253,0.111969403922558,3,,,,,,,,,,,,,,,,
,3959138740.53222,99.9998283386231,1000.00256347656,,,6,,,,30.7943755037081,,,10,,,,,,,,,,,,,,,,,,,,,,99.9930801391602,100.005302429199,1000.00256347656,1000.00256347656,,,6.30225515365601,,1,0,0,0,0.000457763671875,33.7243423461914,1,1,1,99.9943542480469,0,99.9993379380968,-245.995208740234,1,0.00155112174461313,7.66466866004653E-5,0.00155543837842459,7.66715958223315E-5,0.922859847545624,0.967448592185974,31.0623168945313,0,30,4,200,-0.000400802324293181,-0.603993117809296,0.11069256067276,1,,,,,,,,,,,,,,,,
,3959138865.18626,99.9996871948242,1000.00256347656,,,6,,,,30.7943755037081,,,10,,,,,,,,,,,,,,,,,,,,,,99.9928741455078,100.004768371582,1000.00256347656,1000.00256347656,,,6.30368375778198,,1,0,0,0,0.0003814697265625,34.7018585205078,1,1,1,99.9967880249023,0,99.9996174403599,-241.996810913086,1,0.00154918427613407,4.41982375230631E-5,0.00155362475174823,4.42145256359011E-5,0.922417938709259,0.967610776424408,31.0649471282959,,30,4,200,-0.000331848685164005,-0.603857278823853,0.110359542071819,3,,,,,,,,,,,,,,,,
,3959138993.19816,100.000358581543,1000.00256347656,,,6,,,,30.7994671619301,,,10,,,,,,,,,,,,,,,,,,,,,,99.9937591552734,100.005500793457,1000.00256347656,1000.00256347656,,,6.30462884902954,,1,0,0,0,7.62939453125E-5,34.7018585205078,1,1,1,99.9952163696289,0,99.9996219211154,-235.996810913086,1,0.00155347458110558,7.67630451552924E-5,0.00155780231921966,7.6786035189781E-5,0.922839462757111,0.968282580375671,31.0690250396729,0,30,4,200,-6.95238413754851E-5,-0.606196880340576,0.110097847878933,1,,,,,,,,,,,,,,,,
,3959139118.43812,100.001094818115,1000.00256347656,,,6,,,,30.7994671619301,,,10,,,,,,,,,,,,,,,,,,,,,,99.9929962158203,100.005737304688,1000.00256347656,1000.00256347656,,,6.3055477142334,,1,0,0,0,0.00244140625,34.2131004333496,1,1,1,99.9976654052734,0,99.9999838935004,-231.998413085938,1,0.00155329907897792,4.43174057401512E-5,0.00155769216801416,4.43289227680258E-5,0.921898722648621,0.96854829788208,31.073091506958,9.25170040130615,30,4,200,-0.000222671194933355,-0.607006788253784,0.110055185854435,3,,,,,,,,,,,,,,,,
,3959139245.96457,100.000453948975,1000.00256347656,,,6,,,,30.7994671619301,,,10,,,,,,,,,,,,,,,,,,,,,,99.9937591552734,100.00560760498,1000.00256347656,1000.00256347656,,,6.30651807785034,,1,0,0,0,0.0011444091796875,36.6568908691406,1,1,1,99.9953002929688,0,99.9997304280599,-225.998413085938,1,0.00155794222603199,7.69986796434361E-5,0.00156244894363629,7.70124853495754E-5,0.920395255088806,0.969371974468231,31.0795421600342,0,30,4,200,-0.000449990853667259,-0.609422326087952,0.109814420342445,1,,,,,,,,,,,,,,,,
,3959139371.0157,100.00122833252,1000.00256347656,,,6,,,,30.7994671619301,,,10,,,,,,,,,,,,,,,,,,,,,,99.9929809570312,100.006042480469,1000.00256347656,1000.00256347656,,,6.30699253082275,,1,0,0,0,0.00030517578125,34.2131004333496,1,1,1,99.9978561401367,0,100.000032778139,-221.995208740234,1,0.00155734674466988,4.44386501510325E-5,0.00156197261864441,4.444813209525E-5,0.920273244380951,0.970486342906952,31.0823135375977,0,30,4,200,-0.000403834477765486,-0.610309302806854,0.10963312536478,3,,,,,,,,,,,,,,,,
,3959139498.6406,100.000267028809,1000.00256347656,,,6,,,,30.7994671619301,,,10,,,,,,,,,,,,,,,,,,,,,,99.9934310913086,100.005401611328,1000.00256347656,1000.00256347656,,,6.30751085281372,,1,0,0,0,0.0003814697265625,34.7018585205078,1,1,1,99.9951324462891,0,99.9995447794596,-215.995208740234,1,0.00156260055196505,7.72281949952375E-5,0.00156748110443471,7.72529807947488E-5,0.920505702495575,0.972724854946136,31.0847110748291,0.187214478850365,30,4,200,-0.000527026131749153,-0.613045752048492,0.109294153749943,1,,,,,,,,,,,,,,,,
,3959139624.96518,100.000228881836,1000.00256347656,,,6,,,,30.7994671619301,,,10,,,,,,,,,,,,,,,,,,,,,,99.9914932250977,100.005157470703,1000.00256347656,1000.00256347656,,,6.3087306022644,,1,0,0,0,0.0002288818359375,34.2131004333496,1,1,1,99.9970779418945,0,99.9992785983615,-211.996810913086,1,0.00156444699179585,4.46366614330119E-5,0.00156944103363812,4.46549098627263E-5,0.921558678150177,0.975198984146118,31.0840625762939,9.23535251617432,30,4,200,-0.000199643400264904,-0.614656925201416,0.109528847038746,3,,,,,,,,,,,,,,,,
,3959139752.68275,99.9997787475586,1000.00256347656,,,6,,,,30.7994671619301,,,10,,,,,,,,,,,,,,,,,,,,,,99.993278503418,100.00439453125,1000.00256347656,1000.00256347656,,,6.308997631073,,1,0,0,0,0.00030517578125,34.7018585205078,1,1,1,99.9951629638672,0,99.9990649753147,-205.996810913086,1,0.00157512571902436,7.78282194636299E-5,0.00157992572464501,7.78551038541609E-5,0.923620164394379,0.978643178939819,31.0791702270508,0,30,4,200,-1.40740503411507E-5,-0.619452595710754,0.110202468931675,1,,,,,,,,,,,,,,,,
,3959139876.55207,100.000743865967,1000.00256347656,,,6,,,,30.7994671619301,,,10,,,,,,,,,,,,,,,,,,,,,,99.9937515258789,100.005439758301,1000.00256347656,1000.00256347656,,,6.30973386764526,,1,0,0,0,0,34.7018585205078,1,1,1,99.9983215332031,0,100.000042668095,-201.998413085938,1,0.00158112111835075,4.51024361420126E-5,0.00158578918481529,4.51146712023056E-5,0.924418091773987,0.980626046657562,31.0778064727783,1.67421840160387E-5,30,4,200,-0.000107477091660257,-0.622634768486023,0.111304931342602,3,,,,,,,,,,,,,,,,
,3959140004.73976,99.9994926452637,1000.00256347656,,,6,,,,30.7994671619301,,,10,,,,,,,,,,,,,,,,,,,,,,99.9921035766602,100.004463195801,1000.00256347656,1000.00256347656,,,6.30940914154053,,1,0,0,0,0.0003814697265625,34.2131004333496,1,1,1,99.9945220947266,0,99.9984039306641,-195.998413085938,1,0.00159079885915104,7.85916550296901E-5,0.00159529761278944,7.86076760775972E-5,0.925466656684876,0.981825053691864,31.0739307403564,1.23617485314753E-6,30,4,200,-0.000259539141552523,-0.627142310142517,0.111747674643993,1,,,,,,,,,,,,,,,,
,3959140130.00626,100.000274658203,1000.00256347656,,,6,,,,30.7994671619301,,,10,,,,,,,,,,,,,,,,,,,,,,99.9909896850586,100.004386901855,1000.00256347656,1000.00256347656,,,6.31028366088867,,1,0,0,0,0.011749267578125,34.7018585205078,1,1,1,99.9972610473633,0,99.9991223370587,-192.000015258789,1,0.00159340910912926,4.54425052131148E-5,0.00159776332567276,4.54532977113653E-5,0.92750495672226,0.98307478427887,31.0668869018555,0,30,4,200,-0.000397692434489727,-0.629002749919891,0.111746311187744,3,,,,,,,,,,,,,,,,
,3959140257.46504,100.000106811523,1000.00256347656,,,6,,,,30.7994671619301,,,10,,,,,,,,,,,,,,,,,,,,,,99.9932098388672,100.005485534668,1000.00256347656,1000.00256347656,,,6.3105731010437,,1,0,0,0,0.000152587890625,34.7018585205078,1,1,1,99.9947280883789,0,99.9996965196398,-186.000015258789,1,0.00160024963961639,7.90274234807705E-5,0.00160438059184122,7.90506428676797E-5,0.930923879146576,0.985363781452179,31.0556983947754,0,30,4,200,-0.00040762426215224,-0.632695913314819,0.111424960196018,1,,,,,,,,,,,,,,,,
,3959140382.40901,100.000774383545,1000.00256347656,,,6,,,,30.7994671619301,,,10,,,,,,,,,,,,,,,,,,,,,,99.9933700561523,100.005706787109,1000.00256347656,1000.00256347656,,,6.31097602844238,,1,0,0,0,0,34.7018585205078,1,1,1,99.9967651367187,0,100.000131753775,-181.996810913086,1,0.00160435551446904,4.57342264146996E-5,0.0016081698272637,4.57466297958728E-5,0.933932363986969,0.987057685852051,31.0455131530762,2.05192714020086E-6,30,4,200,-0.000277133891358972,-0.634764730930328,0.111762069165707,3,,,,,,,,,,,,,,,,
,3959140509.34401,99.9997444152832,1000.00256347656,,,6,,,,30.7994671619301,,,10,,,,,,,,,,,,,,,,,,,,,,99.9931564331055,100.004768371582,1000.00256347656,1000.00256347656,,,6.31103372573853,,1,0,0,0,0.00030517578125,35.190616607666,1,1,1,99.9947204589844,0,99.9994142320421,-175.996810913086,1,0.00161230940378976,7.95788274361613E-5,0.00161559332195461,7.96002681585579E-5,0.93944525718689,0.988042771816254,31.0243549346924,0,30,4,200,-4.65617558802478E-5,-0.638424158096313,0.111656598746777,1,,,,,,,,,,,,,,,,
,3959140633.5092,100.000785827637,1000.00256347656,,,6,,,,30.7994671619301,,,10,,,,,,,,,,,,,,,,,,,,,,99.9926223754883,100.005569458008,1000.00256347656,1000.00256347656,,,6.31091117858887,,1,0,0,0,0.000152587890625,35.190616607666,1,1,1,99.9973297119141,0,99.9995433262416,-171.998413085938,1,0.00162063136352586,4.61759517108537E-5,0.00162356570449941,4.61855252009427E-5,0.941639065742493,0.98556250333786,31.0135173797607,0,30,4,200,-2.49669483309845E-5,-0.642282903194428,0.11315905302763,3,,,,,,,,,,,,,,,,
,3959140760.02246,99.9999847412109,1000.00256347656,,,6,,,,30.7994671619301,,,10,,,,,,,,,,,,,,,,,,,,,,99.9934310913086,100.005378723145,1000.00256347656,1000.00256347656,,,6.31136655807495,,1,0,0,0,0.0002288818359375,34.7018585205078,1,1,1,99.9945907592773,0,99.9999245537652,-165.998413085938,1,0.00162898325485478,8.03731848521969E-5,0.00163133342537576,8.03824630893815E-5,0.945619404315949,0.98241925239563,30.9935932159424,5.35766363143921,30,4,200,-0.00012732672621496,-0.646223545074463,0.112822659313679,1,,,,,,,,,,,,,,,,
,3959140884.57572,100.000217437744,1000.00256347656,,,6,,,,30.7994671619301,,,10,,,,,,,,,,,,,,,,,,,,,,99.9920043945313,100.006736755371,1000.00256347656,1000.00256347656,,,6.31112241744995,,1,0,0,0,0,35.6793746948242,1,1,1,99.9967803955078,0,99.9993346078055,-162.000015258789,1,0.00162887344008127,4.63898705509368E-5,0.00163084812636721,4.63954784467162E-5,0.949927031993866,0.981861054897308,30.9752140045166,2.57992837759957E-6,30,4,200,-0.000540339096914977,-0.648470520973206,0.110601596534252,3,,,,,,,,,,,,,,,,
,3959141012.79819,100.00048828125,1000.00256347656,,,6,,,,30.7994671619301,,,10,,,,,,,,,,,,,,,,,,,,,,99.9938583374023,100.005393981934,1000.00256347656,1000.00256347656,,,6.31153297424316,,1,0,0,0,0.00030517578125,35.6793746948242,1,1,1,99.9955825805664,0,99.999715423584,-155.995208740234,1,0.00162945117632409,8.03553539106244E-5,0.00163096815708101,8.03645164070051E-5,0.955938160419464,0.982386529445648,30.9516620635986,0,30,4,200,-0.000482726725749671,-0.650096774101257,0.108355715870857,1,,,,,,,,,,,,,,,,
,3959141136.47468,100.000453948975,1000.00256347656,,,6,,,,30.7994671619301,,,10,,,,,,,,,,,,,,,,,,,,,,99.9918975830078,100.005401611328,1000.00256347656,1000.00256347656,,,6.31123876571655,,1,0,0,0,0.00030517578125,34.7018585205078,1,1,1,99.9977416992188,0,99.9998061568649,-151.996810913086,1,0.001628278458961,4.63501447211491E-5,0.00162943398127113,4.6353912949204E-5,0.960937142372131,0.983543694019318,30.9332809448242,3.95450282096863,30,4,200,-0.00022639958478976,-0.650092720985413,0.107683122158051,3,,,,,,,,,,,,,,,,
,3959141264.80294,100.000610351562,1000.00256347656,,,6,,,,30.7994671619301,,,10,,,,,,,,,,,,,,,,,,,,,,99.9923477172852,100.005599975586,1000.00256347656,1000.00256347656,,,6.31063556671143,,1,0,0,0,0.000457763671875,35.190616607666,1,1,1,99.9956207275391,0,99.9987350463867,-145.996810913086,1,0.0016285888446946,8.02772396584275E-5,0.00162950399571029,8.02873508035308E-5,0.96749347448349,0.986377835273743,30.9110679626465,1.21332607250224E-6,30,4,200,-5.16947366122622E-5,-0.65046900510788,0.106509193778038,1,,,,,,,,,,,,,,,,
,3959141389.77419,100.001239776611,1000.00256347656,,,6,,,,30.7994671619301,,,10,,,,,,,,,,,,,,,,,,,,,,99.9927444458008,100.005508422852,1000.00256347656,1000.00256347656,,,6.31102418899536,,1,0,0,0,0.0002288818359375,33.7243423461914,1,1,1,99.9985122680664,0,100.000024301034,-141.998413085938,1,0.00163024269555465,4.63888479098878E-5,0.00163087365322769,4.63930139756441E-5,0.971986889839172,0.9861900806427,30.8915538787842,0,30,4,200,1.73750086105429E-5,-0.651538550853729,0.106501191854477,3,,,,,,,,,,,,,,,,
,3959141517.91531,100.000514984131,1000.00256347656,,,6,,,,30.7994671619301,,,10,,,,,,,,,,,,,,,,,,,,,,99.9930267333984,100.005599975586,1000.00256347656,1000.00256347656,,,6.31076812744141,,1,0,0,0,0.000152587890625,34.7018585205078,1,1,1,99.9954299926758,0,99.9992179870605,-135.998413085938,1,0.00163045521830111,8.03476604537558E-5,0.00163080578590268,8.03517618602069E-5,0.977194547653198,0.986132204532623,30.8678894042969,1,30,4,200,-5.76172496948857E-5,-0.651664257049561,0.105337105691433,1,,,,,,,,,,,,,,,,
,3959141643.11019,100.000881195068,1000.00256347656,,,6,,,,30.7994671619301,,,10,,,,,,,,,,,,,,,,,,,,,,99.9934234619141,100.005470275879,1000.00256347656,1000.00256347656,,,6.31084394454956,,1,0,0,0,0.0142669677734375,33.2355842590332,1,1,1,99.9970397949219,0,100.000079119647,-131.995208740234,1,0.00162582590024078,4.6253831543149E-5,0.00162600266469366,4.62543593374003E-5,0.98044627904892,0.986296355724335,30.8520526885986,2.4394332740485E-6,30,4,200,-0.000369631336070597,-0.650010526180267,0.104353465139866,3,,,,,,,,,,,,,,,,
,3959141772.53728,100.000007629395,1000.00256347656,,,6,,,,30.7994671619301,,,10,,,,,,,,,,,,,,,,,,,,,,99.9937057495117,100.004776000977,1000.00256347656,1000.00256347656,,,6.31024789810181,,1,0,0,0,0,35.190616607666,1,1,1,99.9952392578125,0,99.9994430541992,-125.995208740234,1,0.00161735658364477,7.96902625323217E-5,0.00161741829472688,7.96906956577626E-5,0.9851393699646,0.987533569335938,30.8300399780273,0,30,4,200,-0.000467688747448847,-0.646939396858215,0.101946718990803,1,,,,,,,,,,,,,,,,
,3959141897.47931,99.9991569519043,1000.00256347656,,,6,,,,30.7994671619301,,,10,,,,,,,,,,,,,,,,,,,,,,99.9928436279297,100.005500793457,1000.00256347656,1000.00256347656,,,6.31040906906128,,1,0,0,0,7.62939453125E-5,34.7018585205078,1,1,1,99.9947967529297,0,99.9993348298249,-121.996803283691,1,0.00160799121605284,4.5741374471709E-5,0.00160800771409802,4.57415432757213E-5,0.987322509288788,0.987851679325104,30.8132057189941,0,30,4,200,-0.000358823512215167,-0.643918871879578,0.100472271442413,3,,,,,,,,,,,,,,,,
,3959142024.18795,100.000553131104,1000.00256347656,,,6,,,,30.7994671619301,,,10,,,,,,,,,,,,,,,,,,,,,,99.9924545288086,100.005676269531,1000.00256347656,1000.00256347656,,,6.309898853302,,1,0,0,0,0.00030517578125,35.190616607666,1,1,1,99.9954299926758,0,99.9992463853624,-115.996803283691,1,0.00160251234917017,7.89552237033512E-5,0.00160250667718094,7.8954889864172E-5,0.988642632961273,0.988703429698944,30.7950038909912,0,30,4,200,-8.23751761345193E-5,-0.64154988527298,0.0988050997257233,1,,,,,,,,,,,,,,,,
,3959142149.25343,100.000400543213,1000.00256347656,,,6,,,,30.7994671619301,,,10,,,,,,,,,,,,,,,,,,,,,,99.9918975830078,100.005523681641,1000.00256347656,1000.00256347656,,,6.31041479110718,,1,0,0,0,0.00030517578125,34.7018585205078,1,1,1,99.9968109130859,0,99.9995708465576,-111.998405456543,1,0.00159641186371316,4.54128785278836E-5,0.00159640640292317,4.54121733703322E-5,0.985883414745331,0.986768662929535,30.78076171875,0.107819639146328,30,4,200,-2.03054096346023E-5,-0.639584541320801,0.0978023409843445,3,,,,,,,,,,,,,,,,
,3959142278.07283,99.9998397827148,1000.00256347656,,,6,,,,30.7994671619301,,,10,,,,,,,,,,,,,,,,,,,,,,99.9933471679688,100.004638671875,1000.00256347656,1000.00256347656,,,6.30973529815674,,1,0,0,0,0.000152587890625,36.1681327819824,1,1,1,99.9950408935547,0,99.9990592956543,-105.998405456543,1,0.00159528669560007,7.86088044316502E-5,0.00159533161680694,7.8606742218637E-5,0.980689406394958,0.98374730348587,30.7598152160645,5.55440374228056E-6,30,4,200,-9.35186471906491E-5,-0.639112770557404,0.0968410074710846,1,,,,,,,,,,,,,,,,
,3959142400.72186,100.000217437744,1000.00256347656,,,6,,,,30.7994671619301,,,10,,,,,,,,,,,,,,,,,,,,,,99.9933395385742,100.005104064941,1000.00256347656,1000.00256347656,,,6.31011009216309,,1,0,0,0,0.0017547607421875,34.7018585205078,1,1,1,99.9966659545898,0,100.000044413975,-101.99520111084,1,0.00158873562099313,4.52024175761266E-5,0.00158886840858633,4.52020770695092E-5,0.976562559604645,0.980838119983673,30.7481689453125,0,30,4,200,-0.000130296728457324,-0.63725221157074,0.0957775488495827,3,,,,,,,,,,,,,,,,
,3959142524.55025,100.000354766846,1000.00256347656,,,6,,,,30.7994671619301,,,10,,,,,,,,,,,,,,,,,,,,,,99.9929885864258,100.005393981934,1000.00256347656,1000.00256347656,,,6.30914831161499,,1,0,0,0,0.000152587890625,35.190616607666,1,1,1,99.9953155517578,0,99.9990395439996,-96.0000076293945,1,0.00157928622158559,7.78390219272696E-5,0.00157950213910411,7.78387542174727E-5,0.970801591873169,0.97607409954071,30.7358283996582,0,30,4,200,-0.000441426964243874,-0.634034276008606,0.0935951396822929,1,,,,,,,,,,,,,,,,
,3959142646.77611,100.00025177002,1000.00256347656,,,6,,,,30.7994671619301,,,10,,,,,,,,,,,,,,,,,,,,,,99.9934158325195,100.004844665527,1000.00256347656,1000.00256347656,,,6.31007766723633,,1,0,0,0,0,34.7018585205078,1,1,1,99.9972991943359,0,99.999851499285,-91.9968032836914,1,0.00157034242910054,4.46907959088148E-5,0.00157062876536648,4.46909467520412E-5,0.96725857257843,0.973271250724792,30.7272872924805,5.6539323850302E-5,30,4,200,-0.000416414404753596,-0.631178975105286,0.0922708660364151,3,,,,,,,,,,,,,,,,
,3959142775.02551,100.000202178955,1000.00256347656,,,6,,,,30.7994671619301,,,10,,,,,,,,,,,,,,,,,,,,,,99.993278503418,100.004852294922,1000.00256347656,1000.00256347656,,,6.30961227416992,,1,0,0,0,0.0002288818359375,35.190616607666,1,1,1,99.9955520629883,0,99.9995574951172,-85.9968032836914,1,0.0015657099153472,7.71874752103058E-5,0.0015659499230096,7.71810456156899E-5,0.963848173618317,0.97111576795578,30.716251373291,1.02020349004306E-5,30,4,200,-0.000228034492465667,-0.629600405693054,0.0907239019870758,1,,,,,,,,,,,,,,,,
,3959142899.89274,100.000099182129,1000.00256347656,,,6,,,,30.7994671619301,,,10,,,,,,,,,,,,,,,,,,,,,,99.9933853149414,100.005615234375,1000.00256347656,1000.00256347656,,,6.31000137329102,,1,0,0,0,0.000457763671875,35.190616607666,1,1,1,99.9962768554687,0,99.9997650782267,-81.998405456543,1,0.00156039062247906,4.44170870059883E-5,0.00156073885416048,4.4414254147518E-5,0.961283504962921,0.969572842121124,30.7078514099121,INF,30,4,200,-0.000141194803291,-0.628110349178314,0.0899504274129868,3,,,,,,,,,,,,,,,,
,3959143027.56014,100.000190734863,1000.00256347656,,,6,,,,30.7994671619301,,,10,,,,,,,,,,,,,,,,,,,,,,99.9933853149414,100.005485534668,1000.00256347656,1000.00256347656,,,6.30972194671631,,1,0,0,0,0,35.190616607666,1,1,1,99.9948959350586,0,99.9998609754774,-75.998405456543,1,0.00156287149504734,7.70630406091561E-5,0.00156336498619884,7.70583079697034E-5,0.958662748336792,0.969088435173035,30.6945095062256,0,30,4,200,-8.04655574029311E-5,-0.629334926605225,0.0895390138030052,1,,,,,,,,,,,,,,,,
,3959143149.65171,100.001518249512,1000.00256347656,,,6,,,,30.7994671619301,,,10,,,,,,,,,,,,,,,,,,,,,,99.994026184082,100.006172180176,1000.00256347656,1000.00256347656,,,6.30970525741577,,1,0,0,0,0,35.190616607666,1,1,1,99.9982757568359,0,100.000417269193,-71.9952011108398,1,0.00155944309859743,4.43985901318301E-5,0.00156006652977239,4.43971016176729E-5,0.956631481647491,0.968131005764008,30.6870250701904,0,30,4,200,-0.000188404665095732,-0.628814041614532,0.088989146053791,3,,,,,,,,,,,,,,,,
,3959143275.98545,99.9992828369141,1000.00256347656,,,6,,,,30.7994671619301,,,10,,,,,,,,,,,,,,,,,,,,,,99.9930267333984,100.004173278809,1000.00256347656,1000.00256347656,,,6.30979824066162,,1,0,0,0,0,34.7018585205078,1,1,1,99.9943923950195,0,99.9986724853516,-65.9952011108398,1,0.00155858513799242,7.68664431806552E-5,0.00155931965384622,7.68650950711899E-5,0.954255700111389,0.966582715511322,30.6803417205811,,30,4,200,-0.000362612481694669,-0.628856360912323,0.0880810245871544,1,,,,,,,,,,,,,,,,
,3959143395.82906,100.000785827637,1000.00256347656,,,6,,,,30.7994671619301,,,10,,,,,,,,,,,,,,,,,,,,,,99.9944229125977,100.005950927734,1000.00256347656,1000.00256347656,,,6.30997323989868,,1,0,0,0,0,34.2131004333496,1,1,1,99.9973754882813,0,100.000414921687,-61.9968032836914,1,0.00155475735553725,4.42712989938241E-5,0.0015555697285504,4.42715058025561E-5,0.953563630580902,0.966494262218475,30.6767177581787,,30,4,200,-0.00041240468272008,-0.627894520759582,0.0874978378415108,3,,,,,,,,,,,,,,,,
,3959143522.57905,99.9992828369141,1000.00256347656,,,6,,,,30.7994671619301,,,10,,,,,,,,,,,,,,,,,,,,,,99.9924392700195,100.004623413086,1000.00256347656,1000.00256347656,,,6.309898853302,,1,0,0,0,0.000152587890625,34.7018585205078,1,1,1,99.9939422607422,0,99.9987903171115,-55.9968032836914,1,0.00155762376932895,7.68191969231809E-5,0.00155831894647719,7.68130334844911E-5,0.954203128814697,0.967656135559082,30.6753234863281,1.59684113896219E-5,30,4,200,-0.000457507674582303,-0.629043042659759,0.0872263759374618,1,,,,,,,,,,,,,,,,
,3959143647.56582,100.000316619873,1000.00256347656,,,6,,,,30.7994671619301,,,10,,,,,,,,,,,,,,,,,,,,,,99.9934539794922,100.005424499512,1000.00256347656,1000.00256347656,,,6.30958795547485,,1,0,0,0,0.00030517578125,35.190616607666,1,1,1,99.9966278076172,0,99.9999641135887,-51.9984016418457,1,0.00155808915301341,4.43633034467524E-5,0.00155877718289352,4.43590318503709E-5,0.954962313175201,0.969106018543243,30.6739826202393,0,30,4,200,-0.000196892695385031,-0.62978720664978,0.0871750935912132,3,,,,,,,,,,,,,,,,
,3959143774.37088,99.9996681213379,1000.00256347656,,,6,,,,30.7994671619301,,,10,,,,,,,,,,,,,,,,,,,,,,99.9931106567383,100.004859924316,1000.00256347656,1000.00256347656,,,6.30957984924316,,1,0,0,0,0.000152587890625,35.6793746948242,1,1,1,99.9944763183594,0,99.9988166809082,-45.9984016418457,1,0.00156600732647086,7.72272786060756E-5,0.00156683366923204,7.72235299865768E-5,0.955753684043884,0.971589148044586,30.6698398590088,5.35278177261353,30,4,200,-5.89023038628511E-5,-0.633512198925018,0.0876070559024811,1,,,,,,,,,,,,,,,,
,3959143897.30844,100.000564575195,1000.00256347656,,,6,,,,30.7994671619301,,,10,,,,,,,,,,,,,,,,,,,,,,99.9929122924805,100.004951477051,1000.00256347656,1000.00256347656,,,6.30946683883667,,1,0,0,0,0,35.190616607666,1,1,1,99.9982070922852,0,99.9996540363018,-42.0000038146973,1,0.00156781465102388,4.46373499880153E-5,0.00156868115171909,4.46358887918885E-5,0.956417918205261,0.972973883152008,30.6690254211426,,30,4,200,-0.000109058433736209,-0.634771049022675,0.0878246650099754,3,,,,,,,,,,,,,,,,
,3959144022.49529,100.000015258789,1000.00256347656,,,6,,,,30.7994671619301,,,10,,,,,,,,,,,,,,,,,,,,,,99.9922561645508,100.005004882813,1000.00256347656,1000.00256347656,,,6.30893850326538,,1,0,0,0,7.62939453125E-5,34.7018585205078,1,1,1,99.9950256347656,0,99.9990598890516,-35.9952011108398,1,0.00157595136095945,7.77089687886815E-5,0.00157680255285967,7.77066865435835E-5,0.958353638648987,0.975564956665039,30.6714534759521,0,30,4,200,-0.000652963994070888,-0.638688743114471,0.0878575071692467,1,,,,,,,,,,,,,,,,
,3959144143.26164,100.000785827637,1000.00256347656,,,6,,,,30.7994671619301,,,10,,,,,,,,,,,,,,,,,,,,,,99.9938278198242,100.00520324707,1000.00256347656,1000.00256347656,,,6.3093376159668,,1,0,0,0,7.62939453125E-5,35.190616607666,1,1,1,99.9983139038086,0,100.000274951641,-31.9968013763428,1,0.00157750897444468,4.49058162107909E-5,0.00157835040440296,4.49058187581023E-5,0.960446417331696,0.977657198905945,30.6753387451172,1,30,4,200,-0.000384589424356818,-0.639962315559387,0.0877807289361954,3,,,,,,,,,,,,,,,,
,3959144267.01051,99.9995727539063,1000.00256347656,,,6,,,,30.7994671619301,,,10,,,,,,,,,,,,,,,,,,,,,,99.9926071166992,100.004783630371,1000.00256347656,1000.00256347656,,,6.30926561355591,,1,0,0,0,0.0002288818359375,34.7018585205078,1,1,1,99.9943618774414,0,99.9992175632053,-25.9968013763428,1,0.00158762970482373,7.82644084711214E-5,0.00158828040447284,7.82624941619167E-5,0.965161383152008,0.981400489807129,30.687572479248,0,30,4,200,-0.000556214014068246,-0.644753515720367,0.0881489440798759,1,,,,,,,,,,,,,,,,
,3959144392.27279,99.9996490478516,1000.00256347656,,,6,,,,30.7994671619301,,,10,,,,,,,,,,,,,,,,,,,,,,99.9926452636719,100.004821777344,1000.00256347656,1000.00256347656,,,6.3092794418335,,1,0,0,0,7.62939453125E-5,35.190616607666,1,1,1,99.9957656860352,0,99.9990143952546,-21.9984016418457,1,0.00159064010478707,4.52662550957897E-5,0.00159117225486407,4.52648087082231E-5,0.968773782253265,0.984423577785492,30.6965255737305,0.000142158052767627,30,4,200,-0.000293109507765621,-0.646572232246399,0.088542252779007,3,,,,,,,,,,,,,,,,
,3959144519.85826,99.9991722106934,1000.00256347656,,,6,,,,30.7994671619301,,,10,,,,,,,,,,,,,,,,,,,,,,99.9924163818359,100.004264831543,1000.00256347656,1000.00256347656,,,6.30915117263794,,1,0,0,0,0.00030517578125,35.190616607666,1,1,1,99.9940795898438,0,99.998462677002,-15.9984006881714,1,0.00160065782972873,7.88901821131825E-5,0.00160108692137611,7.88861169265255E-5,0.971784710884094,0.987459123134613,30.7035598754883,0,30,4,200,-0.000248462369199842,-0.650901556015015,0.0892964527010918,1,,,,,,,,,,,,,,,,
,3959144643.65525,100.001201629639,1000.00256347656,,,6,,,,30.7994671619301,,,10,,,,,,,,,,,,,,,,,,,,,,99.993278503418,100.005844116211,1000.00256347656,1000.00256347656,,,6.3093433380127,,1,0,0,0,0.01129150390625,34.7018585205078,1,1,1,99.9979553222656,0,100.000176943265,-12.0000009536743,1,0.00160595413706612,4.56947476756805E-5,0.00160631504417501,4.56935749997281E-5,0.974371314048767,0.987498223781586,30.7146892547607,0,30,4,200,-0.000215074644074775,-0.653701663017273,0.0905875489115715,3,,,,,,,,,,,,,,,,
,3959144766.5072,100.000072479248,1000.00256347656,,,6,,,,30.7994671619301,,,10,,,,,,,,,,,,,,,,,,,,,,99.993293762207,100.005256652832,1000.00256347656,1000.00256347656,,,6.30940675735474,,1,0,0,0,0,34.7018585205078,1,1,1,99.9948883056641,0,99.9995040893555,-6.00000047683716,1,0.00161531445507235,7.96026843614277E-5,0.00161556720352613,7.96009794707703E-5,0.976571977138519,0.986098408699036,30.7281608581543,,30,4,200,-0.000434524699812755,-0.658004999160767,0.0912464037537575,1,,,,,,,,,,,,,,,,
,3959144887.64718,100.000068664551,1000.00256347656,,,6,,,,30.7994671619301,,,10,,,,,,,,,,,,,,,,,,,,,,99.9934158325195,100.005256652832,1000.00256347656,1000.00256347656,,,6.30896425247192,,1,0,0,0,0.000152587890625,34.7018585205078,1,1,1,99.9976272583008,0,100.000155413592,-1.99680006504059,1,0.00161808500357842,4.60349714166884E-5,0.00161821586822222,4.60335040660653E-5,0.978999197483063,0.985316276550293,30.7428455352783,,30,4,200,-0.000473823805805296,-0.659726619720459,0.0919367671012878,3,,,,,,,,,,,,,,,,
,3959145013.88399,99.9995307922363,1000.00256347656,,,6,,,,30.7994671619301,,,10,,,,,,,,,,,,,,,,,,,,,,99.9929733276367,100.004417419434,1000.00256347656,1000.00256347656,,,6.30929851531982,,1,0,0,0,0.0002288818359375,35.6793746948242,1,1,1,99.9946441650391,0,99.999025132921,3.99840021133423,1,0.00162405636850985,8.00232070064695E-5,0.00162408832946561,8.00223992721147E-5,0.982901751995087,0.984741568565369,30.7703590393066,0,30,4,200,-0.000313455180730671,-0.662398278713226,0.0920971035957336,1,,,,,,,,,,,,,,,,
,3959145139.20506,100.001026153564,1000.00256347656,,,6,,,,30.7994671619301,,,10,,,,,,,,,,,,,,,,,,,,,,99.993293762207,100.005912780762,1000.00256347656,1000.00256347656,,,6.30942630767822,,1,0,0,0,0,34.7018585205078,1,1,1,99.9975433349609,0,99.9999242510114,7.99680042266846,1,0.00162522284244194,4.62331906103786E-5,0.00162522013535646,4.62328219176829E-5,0.984781205654144,0.985201418399811,30.7860546112061,0,30,4,200,-0.00028755990206264,-0.663274765014648,0.0929106250405312,3,,,,,,,,,,,,,,,,
,3959145267.80835,100.00040435791,1000.00256347656,,,6,,,,30.7994671619301,,,10,,,,,,,,,,,,,,,,,,,,,,99.9926376342773,100.005218505859,1000.00256347656,1000.00256347656,,,6.30874681472778,,1,0,0,0,0.000457763671875,33.7243423461914,1,1,1,99.9955902099609,0,99.9991790771484,13.9968004226685,1,0.00162873296211536,8.02502332735919E-5,0.00162874023074875,8.02505016564797E-5,0.985595464706421,0.985673308372498,30.8051166534424,0.145426854491234,30,4,200,-0.000313268887111917,-0.664556324481964,0.0928818434476852,1,,,,,,,,,,,,,,,,
,3959145393.78052,100.000671386719,1000.00256347656,,,6,,,,30.7994671619301,,,10,,,,,,,,,,,,,,,,,,,,,,99.9940719604492,100.005531311035,1000.00256347656,1000.00256347656,,,6.30892038345337,,1,0,0,0,0.000152587890625,34.7018585205078,1,1,1,99.9973373413086,0,99.9998287624783,17.9952011108398,1,0.00163021722398942,4.63761113387137E-5,0.00163024524188202,4.63765559856767E-5,0.983670949935913,0.984143018722534,30.8141784667969,0,30,4,200,-0.000255477090831846,-0.665595710277557,0.0936191231012344,3,,,,,,,,,,,,,,,,
,3959145517.7705,100.000129699707,1000.00256347656,,,6,,,,30.7994671619301,,,10,,,,,,,,,,,,,,,,,,,,,,99.9930191040039,100.005462646484,1000.00256347656,1000.00256347656,,,6.30962514877319,,1,0,0,0,0,33.2355842590332,1,1,1,99.9947967529297,0,99.9988488091363,24.0000019073486,1,0.00163279551612727,8.04580283268881E-5,0.001632893398122,8.04592919366077E-5,0.980083763599396,0.982444226741791,30.8349208831787,0,30,4,200,-0.000458246737252921,-0.666541397571564,0.0935304015874863,1,,,,,,,,,,,,,,,,
,3959145638.11529,100.000556945801,1000.00256347656,,,6,,,,30.7994671619301,,,10,,,,,,,,,,,,,,,,,,,,,,99.9928512573242,100.00505065918,1000.00256347656,1000.00256347656,,,6.30977869033814,,1,0,0,0,0,35.190616607666,1,1,1,99.9972610473633,0,99.9997179949725,27.9984016418457,1,0.0016295865039139,4.63629949481045E-5,0.00162976311976522,4.63642163112831E-5,0.978189289569855,0.982344746589661,30.8476657867432,0,30,4,200,-0.000484954158309847,-0.665634155273437,0.0932924076914787,3,,,,,,,,,,,,,,,,
,3959145761.02086,99.9996643066406,1000.00256347656,,,6,,,,30.7994671619301,,,10,,,,,,,,,,,,,,,,,,,,,,99.9926834106445,100.004913330078,1000.00256347656,1000.00256347656,,,6.30994653701782,,1,0,0,0,0,34.2131004333496,1,1,1,99.9944152832031,0,99.9994388156467,33.9984016418457,1,0.00162622258917118,8.01479555943863E-5,0.0016266433535147,8.01510594348848E-5,0.972774744033814,0.982636630535126,30.8784408569336,,30,4,200,-0.000603653723374009,-0.664278626441956,0.0921576768159866,1,,,,,,,,,,,,,,,,
,3959145885.08621,100.000091552734,1000.00256347656,,,6,,,,30.7994671619301,,,10,,,,,,,,,,,,,,,,,,,,,,99.9928131103516,100.005737304688,1000.00256347656,1000.00256347656,,,6.31047582626343,,1,0,0,0,0.000457763671875,34.7018585205078,1,1,1,99.996696472168,0,99.9991635923032,37.9968032836914,1,0.00162145091971519,4.61412500188952E-5,0.00162206072457977,4.61435842224181E-5,0.970061361789703,0.984320759773254,30.8956756591797,0.14516793191433,30,4,200,-0.000488012010464445,-0.662607610225677,0.0914799124002457,3,,,,,,,,,,,,,,,,
,3959146012.82936,100.000881195068,1000.00256347656,,,6,,,,30.7994671619301,,,10,,,,,,,,,,,,,,,,,,,,,,99.9929046630859,100.005523681641,1000.00256347656,1000.00256347656,,,6.30966186523437,,1,0,0,0,0.000152587890625,34.7018585205078,1,1,1,99.9962387084961,0,99.9997389051649,43.9968032836914,1,0.00162263494009636,7.99774441426351E-5,0.00162321051960332,7.99789240046303E-5,0.970015585422516,0.984928846359253,30.8973331451416,0,30,4,200,-0.000589388073422015,-0.663219690322876,0.0908035188913345,1,,,,,,,,,,,,,,,,
,3959146138.54128,100.000312805176,1000.00256347656,,,6,,,,30.7994671619301,,,10,,,,,,,,,,,,,,,,,,,,,,99.9915161132813,100.004768371582,1000.00256347656,1000.00256347656,,,6.31021595001221,,1,0,0,0,0.0005340576171875,34.7018585205078,1,1,1,99.9968338012695,0,99.9991958053024,48.0000038146973,1,0.00162104315030978,4.61300842531326E-5,0.00162165125755596,4.61316063305102E-5,0.96970796585083,0.984707415103912,30.8980731964111,0,30,4,200,-0.000344022875651717,-0.663308024406433,0.0905255004763603,3,,,,,,,,,,,,,,,,
,3959146267.61225,100.000427246094,1000.00256347656,,,6,,,,30.7994671619301,,,10,,,,,,,,,,,,,,,,,,,,,,99.99365234375,100.005630493164,1000.00256347656,1000.00256347656,,,6.31000185012817,,1,0,0,0,0.0002288818359375,34.7018585205078,1,1,1,99.9952239990234,0,100.000308566623,53.9952011108398,1,0.00162279053007292,7.99858944935336E-5,0.00162338860738794,7.99879995594931E-5,0.969695270061493,0.984688460826874,30.8982334136963,0,30,4,200,-0.000498446519486606,-0.664333045482636,0.0898756384849548,1,,,,,,,,,,,,,,,,
,3959146392.8146,100.000057220459,1000.00256347656,,,6,,,,30.7994671619301,,,10,,,,,,,,,,,,,,,,,,,,,,99.9935913085938,100.005218505859,1000.00256347656,1000.00256347656,,,6.31015777587891,,1,0,0,0,0.0003814697265625,35.190616607666,1,1,1,99.9966735839844,0,100.000204580802,57.9984016418457,1,0.00162096225423886,4.61277700253644E-5,0.00162155720836386,4.61288621138381E-5,0.969775140285492,0.984922051429748,30.8983592987061,1.72466201320276E-7,30,4,200,-0.000415319576859474,-0.664368748664856,0.0894618406891823,3,,,,,,,,,,,,,,,,
,3959146519.20501,100.000461578369,1000.00256347656,,,6,,,,30.7994671619301,,,10,,,,,,,,,,,,,,,,,,,,,,99.9926910400391,100.005477905273,1000.00256347656,1000.00256347656,,,6.30953025817871,,1,0,0,0,0.00030517578125,35.190616607666,1,1,1,99.9954452514648,0,99.9996978759766,63.9984016418457,1,0.00162183455027015,7.99392331501893E-5,0.00162245948333483,7.99421846671234E-5,0.969497621059418,0.984698235988617,30.8990440368652,5.36909103393555,30,4,200,-0.000413029018091038,-0.664919197559357,0.0888756960630417,1,,,,,,,,,,,,,,,,
,3959146643.88317,100.001045227051,1000.00256347656,,,6,,,,30.7994671619301,,,10,,,,,,,,,,,,,,,,,,,,,,99.9915161132813,100.005722045898,1000.00256347656,1000.00256347656,,,6.31020355224609,,1,0,0,0,0,34.2131004333496,1,1,1,99.9976196289063,0,99.9996335064923,67.9968032836914,1,0.00162084172675062,4.61244678612967E-5,0.00162144272700084,4.61256247189276E-5,0.969657421112061,0.984841585159302,30.8986968994141,2.92294885184674E-6,30,4,200,-0.000323731772368774,-0.665196895599365,0.0887063592672348,3,,,,,,,,,,,,,,,,
,3959146772.08086,100.000694274902,1000.00256347656,,,6,,,,30.7994671619301,,,10,,,,,,,,,,,,,,,,,,,,,,99.9929962158203,100.005584716797,1000.00256347656,1000.00256347656,,,6.31008577346802,,1,0,0,0,0.0003814697265625,34.2131004333496,1,1,1,99.9958038330078,0,99.9993492126465,73.9968032836914,1,0.00162270430807137,7.99816924879201E-5,0.0016232749285617,7.99821837296208E-5,0.969676434993744,0.984866321086884,30.8986701965332,5.36707019805908,30,4,200,-0.000514180748723447,-0.66647881269455,0.0877579674124718,1,,,,,,,,,,,,,,,,
,3959146897.95741,100.000606536865,1000.00256347656,,,6,,,,30.7994671619301,,,10,,,,,,,,,,,,,,,,,,,,,,99.9935150146484,100.005386352539,1000.00256347656,1000.00256347656,,,6.31038284301758,,1,0,0,0,0.0003814697265625,34.7018585205078,1,1,1,99.9971923828125,0,99.9999220106337,77.9952011108398,1,0.00162086819709798,4.61252169838667E-5,0.00162144773257807,4.61258216735304E-5,0.96966153383255,0.984766006469727,30.8984565734863,0,30,4,200,-0.000461319141322747,-0.666301488876343,0.0875326320528984,3,,,,,,,,,,,,,,,,
,3959147024.6722,100.00004196167,1000.00256347656,,,6,,,,30.7994671619301,,,10,,,,,,,,,,,,,,,,,,,,,,99.9930191040039,100.005340576172,1000.00256347656,1000.00256347656,,,6.30994081497192,,1,0,0,0,0.0002288818359375,35.190616607666,1,1,1,99.994743347168,0,99.9995939466688,84.0000076293945,1,0.00162241817428126,7.9967605342544E-5,0.00162303249201274,7.99702565983843E-5,0.969653904438019,0.98481947183609,30.8986511230469,0,30,4,200,-0.000414222420658916,-0.667430460453033,0.0865516513586044,1,,,,,,,,,,,,,,,,
,3959147150.47137,100.001171112061,1000.00256347656,,,6,,,,30.7994671619301,,,10,,,,,,,,,,,,,,,,,,,,,,99.9920806884766,100.005729675293,1000.00256347656,1000.00256347656,,,6.31020879745483,,1,0,0,0,0.000152587890625,34.7018585205078,1,1,1,99.9978713989258,0,99.9995617336697,87.998405456543,1,0.00162090049787187,4.61260645025528E-5,0.00162148665332588,4.61268614118295E-5,0.969714105129242,0.984865009784698,30.8985004425049,0,30,4,200,-0.000428023544372991,-0.66743665933609,0.0863656625151634,3,,,,,,,,,,,,,,,,
,3959147200.61508,100.001190185547,1000.00256347656,,,6,,,,30.7994671619301,,,10,,,,,,,,,,,,,,,,,,,,,,99.9928359985352,100.005630493164,1000.00256347656,1000.00256347656,,,6.30999517440796,,1,0,0,0,0.000457763671875,35.190616607666,1,1,1,99.9981842041016,0,99.9998814509465,90.0000076293945,1,0.00162094002843071,4.61271580457005E-5,0.00162151425164682,4.61276358253509E-5,0.969736635684967,0.98488050699234,30.8983936309814,0,30,4,200,-0.000546834548003972,-0.667683660984039,0.0860856026411057,3,,,,,,,,,,,,,,,,