File: PPMS_Data_and_Plotting/Data/RuCl3/Data/Magnetisation/Rotator/TB001_RuCl3_H-parra-ab_61p2_mg_14-06-25_ZFCW_200K.dat
[Header]
; MPMS3 Data File (default extension .dat)
; Copyright (c) 2007, Quantum Design, Inc. All rights reserved.
TITLE,
FILEOPENTIME,3959169611.26183,06/15/2025,5:19 pm
BYAPP,MPMS3 w/ AC,1.0,1.1
INFO,MPMS3 Measurement Release 1.2.2 Build 0, MultiVu Release 2.3.5.2,APPNAME
INFO,Linear Motor Servo Controller,MOTOR_MODULE_NAME
INFO,3101-100 N4,MOTOR_HW_VERSION
INFO,MMC1299,MOTOR_SERIAL_NUMBER
INFO,01.04.28,MOTOR_SOFTWARE_VERSION
INFO,Quantum Design Squid Module,SQUID_MODULE_NAME
INFO,3101-501 B0,SQUID_HW_VERSION
INFO,SQM364,SQUID_SERIAL_NUMBER
INFO,01.03.04,SQUID_SOFTWARE_VERSION
INFO,Quantum Design VSM Oven,OVEN_MODULE_NAME
INFO,3101-201 A3,OVEN_HW_VERSION
INFO,OVB387,OVEN_SERIAL_NUMBER
INFO,01.07.07,OVEN_SOFTWARE_VERSION
INFO,SQUID AC,AC_MODULE_NAME
INFO,3101-401 G0,AC_HW_VERSION
INFO,SAC242,AC_SERIAL_NUMBER
INFO,SQUID AC 00.95.11,AC_SOFTWARE_VERSION
INFO,TCI374,COIL_SERIAL_NUMBER
INFO,0,MOMENT_UNITS
INFO,RuCl3,SAMPLE_MATERIAL
INFO,single crystal,SAMPLE_COMMENT
INFO,61.2,SAMPLE_MASS
INFO,,SAMPLE_VOLUME
INFO,,SAMPLE_MOLECULAR_WEIGHT
INFO,,SAMPLE_SIZE
INFO,,SAMPLE_SHAPE
INFO,Rotator,SAMPLE_HOLDER
INFO,Standard,SAMPLE_HOLDER_DETAIL
INFO,67.44,SAMPLE_OFFSET
DATATYPE,COMMENT,1
DATATYPE,TIME,2
STARTUPAXIS,X,2
STARTUPAXIS,Y1,5
FIELDGROUP, VSM,2,3,4,5,6,8,9,10,11,14,15
FIELDGROUP, DC, 2,3,4,14,56,57,58,59,60,61,62,63,64,65,66,67,68,69
FIELDGROUP, AC, 2,3,4,11,16,17,18,19,20,21,22,23,24,25,26,27,28,29,30
STARTUPGROUP, All
[Data]
Comment,Time Stamp (sec),Temperature (K),Magnetic Field (Oe),Moment (emu),M. Std. Err. (emu),Transport Action,Averaging Time (sec),Frequency (Hz),Peak Amplitude (mm),Center Position (mm),Lockin Signal' (V),Lockin Signal (V),Range,M. Quad. Signal (emu),AC Moment (emu),AC M. Std Err. (emu),AC Phase (deg),AC Phase Std. Err. (deg),AC Susceptibility (emu/Oe),AC Suscept. Std Err. (emu/Oe),AC X' (emu/Oe),AC X' Std Err. (emu/Oe),AC X'' (emu/Oe),AC X'' Std Err. (emu/Oe),AC Drive (Oe),AC Frequency (Hz),AC Averaging Time (sec),AC Cycles,AC Range,AC Measure Type,AC Signal' (V),AC Signal'' (V),AC Trim Coil Ratio,AC Trim Coil Phase,Min. Temperature (K),Max. Temperature (K),Min. Field (Oe),Max. Field (Oe),Mass (grams),Motor Lag (deg),Pressure (Torr),Measure Count,Measurement Number,SQUID Status (code),Motor Status (code),Measure Status (code),Motor Current (amps),Motor Temp. (C),Temp. Status (code),Field Status (code),Chamber Status (code),Chamber Temp (K),Redirection State,Average Temp (K),Rotation Angle (deg),Rotator state,DC Moment Fixed Ctr (emu),DC Moment Err Fixed Ctr (emu),DC Moment Free Ctr (emu),DC Moment Err Free Ctr (emu),DC Fixed Fit,DC Free Fit,DC Calculated Center (mm),DC Calculated Center Err (mm),DC Scan Length (mm),DC Scan Time (s),DC Number of Points,DC Squid Drift,DC Min V (V),DC Max V (V),DC Scans per Measure,He3 temp,Map 02,Map 03,Map 04,Map 05,Map 06,Map 07,Map 08,Map 09,Map 10,Map 11,Map 12,Map 13,Map 14,Map 15,Map 16
,3959170815.04811,199.988380432129,999.929748535156,,,6,,,,30.9592328514771,,,10,,,,,,,,,,,,,,,,,,,,,,199.979858398438,199.996704101562,999.929748535156,999.929748535156,,,6.44611597061157,,1,0,0,0,0.0008392333984375,33.2355842590332,1,1,1,199.980056762695,0,199.990331013997,-299.995208740234,1,0.000702649758854309,3.46299164832224E-5,0.000702654517455546,3.46300886658626E-5,0.972767353057861,0.972833454608917,30.9663925170898,5.56474542617798,30,4,200,-0.000380584737285972,-0.310633599758148,0.0178610719740391,1,,,,,,,,,,,,,,,,
,3959170940.82385,199.989082336426,999.929748535156,,,6,,,,30.9592328514771,,,10,,,,,,,,,,,,,,,,,,,,,,199.974945068359,200.004806518555,999.929748535156,999.929748535156,,,6.44683456420898,,1,0,0,0,0.0003814697265625,35.190616607666,1,1,1,199.986129760742,0,199.990647452218,-295.996826171875,1,0.000701769356173938,1.9968293529618E-5,0.000701770401109239,1.99683148388447E-5,0.973214030265808,0.973229765892029,30.9627113342285,,30,4,200,-0.00020703965856228,-0.30962610244751,0.0188600458204746,3,,,,,,,,,,,,,,,,
,3959171069.64652,199.994873046875,999.929748535156,,,6,,,,30.9592328514771,,,10,,,,,,,,,,,,,,,,,,,,,,199.976608276367,200.013137817383,999.929748535156,999.929748535156,,,6.4476432800293,,1,0,0,0,0.0002288818359375,36.1681327819824,1,1,1,199.976608276367,0,199.997647094727,-289.996826171875,1,0.00070905036286905,3.49438539864153E-5,0.000709050664174057,3.49438601327796E-5,0.974397122859955,0.974406838417053,30.9619026184082,5.36918163299561,30,4,200,-0.000300381478155032,-0.312263399362564,0.0193363446742296,1,,,,,,,,,,,,,,,,
,3959171194.13238,199.993850708008,999.929748535156,,,6,,,,30.9592328514771,,,10,,,,,,,,,,,,,,,,,,,,,,199.983322143555,200.015472412109,999.929748535156,999.929748535156,,,6.44842290878296,,1,0,0,0,0.0008392333984375,35.6793746948242,1,1,1,199.989562988281,0,199.999757494245,-285.998413085938,1,0.000712312415132802,2.0267869756044E-5,0.000712313617982592,2.02678351818734E-5,0.974004983901978,0.97413581609726,30.9691047668457,0,30,4,200,-0.000120505632366985,-0.314439713954926,0.0196942277252674,3,,,,,,,,,,,,,,,,
,3959171322.25952,199.996528625488,999.929748535156,,,6,,,,30.9592328514771,,,10,,,,,,,,,,,,,,,,,,,,,,199.980758666992,200.013595581055,999.929748535156,999.929748535156,,,6.44910621643066,,1,0,0,0,0.0003814697265625,35.6793746948242,1,1,1,199.979675292969,0,200.002610948351,-279.998413085938,1,0.000720486854437473,3.55085659482585E-5,0.00072050504708324,3.55087688186286E-5,0.973222076892853,0.973961353302002,30.9829025268555,5.3559775352478,30,4,200,-0.00023620857973583,-0.317525804042816,0.0200291201472282,1,,,,,,,,,,,,,,,,
,3959171446.25459,199.995475769043,999.929748535156,,,6,,,,30.9592328514771,,,10,,,,,,,,,,,,,,,,,,,,,,199.982803344727,200.017120361328,999.929748535156,999.929748535156,,,6.45005226135254,,1,0,0,0,0.0003814697265625,36.1681327819824,1,1,1,199.992233276367,0,199.999910142687,-275.995208740234,1,0.000724089915740785,2.06043068879791E-5,0.000724123426884071,2.06043631436225E-5,0.971612453460693,0.973189115524292,30.9945602416992,,30,4,200,-0.000167539910762571,-0.319502085447311,0.0207177810370922,3,,,,,,,,,,,,,,,,
,3959171573.94277,200.001960754395,999.929748535156,,,6,,,,30.9592328514771,,,10,,,,,,,,,,,,,,,,,,,,,,199.983627319336,200.021408081055,999.929748535156,999.929748535156,,,6.45076990127564,,1,0,0,0,0.000457763671875,35.6793746948242,1,1,1,199.982513427734,0,200.007871839735,-269.995208740234,1,0.000730958752542055,3.60286869859022E-5,0.000731045428166469,3.60295704863618E-5,0.969350516796112,0.97258734703064,31.0110206604004,0,30,4,200,-0.000292037962935865,-0.321967095136642,0.0209263414144516,1,,,,,,,,,,,,,,,,
,3959171699.86901,199.997566223145,999.929748535156,,,6,,,,30.9592328514771,,,10,,,,,,,,,,,,,,,,,,,,,,199.983306884766,200.018966674805,999.929748535156,999.929748535156,,,6.45158243179321,,1,0,0,0,0.0003814697265625,35.190616607666,1,1,1,199.992660522461,0,200.002244262695,-265.996826171875,1,0.000734152162191344,2.08927039972216E-5,0.000734269906147748,2.08932759119996E-5,0.968336760997772,0.972855865955353,31.0208148956299,0.0977578237652779,30,4,200,-0.000288601673673838,-0.323875397443771,0.0213434603065252,3,,,,,,,,,,,,,,,,
,3959171828.44788,199.997413635254,999.929748535156,,,6,,,,30.9592328514771,,,10,,,,,,,,,,,,,,,,,,,,,,199.977813720703,200.017013549805,999.929748535156,999.929748535156,,,6.45307064056397,,1,0,0,0,0.000457763671875,35.190616607666,1,1,1,199.977813720703,0,200.001393127441,-259.996826171875,1,0.00074043172588066,3.65002418937798E-5,0.000740645825766147,3.65016426488588E-5,0.965454518795013,0.973686754703522,31.0438270568848,5.5716986656189,30,4,200,-0.000403430196456611,-0.325739800930023,0.0212636739015579,1,,,,,,,,,,,,,,,,
,3959171955.04053,199.996604919434,999.929748535156,,,6,,,,30.9592328514771,,,10,,,,,,,,,,,,,,,,,,,,,,199.982177734375,200.018173217773,999.929748535156,999.929748535156,,,6.45378828048706,,1,0,0,0,0.0006866455078125,35.6793746948242,1,1,1,199.990905761719,0,200.000544956752,-255.998413085938,1,0.000742508182067837,2.11340537473803E-5,0.000742761034260777,2.11341979267343E-5,0.963416039943695,0.974081993103027,31.0569686889648,0,30,4,200,-0.000135785536258481,-0.327538788318634,0.0210000239312649,3,,,,,,,,,,,,,,,,
,3959172082.46045,199.99829864502,999.929748535156,,,6,,,,30.9592328514771,,,10,,,,,,,,,,,,,,,,,,,,,,199.981170654297,200.017608642578,999.929748535156,999.929748535156,,,6.45413494110107,,1,0,0,0,0.0005340576171875,35.190616607666,1,1,1,199.981658935547,0,200.004208374023,-249.998413085938,1,0.000746665955955475,3.68135146359988E-5,0.000746995179518563,3.68137148796858E-5,0.961053788661957,0.97456431388855,31.0710258483887,0.0991183072328568,30,4,200,-0.00022139422071632,-0.329293310642242,0.0203876849263906,1,,,,,,,,,,,,,,,,
,3959172208.64582,199.99405670166,999.929748535156,,,6,,,,30.9592328514771,,,10,,,,,,,,,,,,,,,,,,,,,,199.981689453125,200.016220092773,999.929748535156,999.929748535156,,,6.45509052276611,,1,0,0,0,0.0003814697265625,33.7243423461914,1,1,1,199.990905761719,0,199.999099166305,-245.995208740234,1,0.000747594203032111,2.12823044449374E-5,0.000747985342508644,2.12826973798984E-5,0.959167420864105,0.974323570728302,31.0795650482178,0,30,4,200,-0.000256968312896788,-0.330165177583694,0.0209159813821316,3,,,,,,,,,,,,,,,,
,3959172336.48481,199.998756408691,999.929748535156,,,6,,,,30.9592328514771,,,10,,,,,,,,,,,,,,,,,,,,,,199.979019165039,200.019897460938,999.929748535156,999.929748535156,,,6.45597171783447,,1,0,0,0,0.0006866455078125,35.6793746948242,1,1,1,199.977615356445,0,200.004375881619,-239.995208740234,1,0.000749327426156153,3.69530160512081E-5,0.000749843941608706,3.69547752744926E-5,0.955685377120972,0.973874151706696,31.0948524475098,0,30,4,200,-0.000461807707324624,-0.330289989709854,0.0201071742922068,1,,,,,,,,,,,,,,,,
,3959172461.41587,199.995300292969,999.929748535156,,,6,,,,30.9592328514771,,,10,,,,,,,,,,,,,,,,,,,,,,199.984741210938,200.017364501953,999.929748535156,999.929748535156,,,6.45710182189941,,1,0,0,0,0.0002288818359375,36.1681327819824,1,1,1,199.991806030273,0,200.001117282444,-235.996810913086,1,0.000747101206596886,2.12743412357314E-5,0.000747722945218287,2.12760318580274E-5,0.952723443508148,0.97293484210968,31.1061496734619,INF,30,4,200,-0.000336533063091338,-0.330095291137695,0.019795186817646,3,,,,,,,,,,,,,,,,
,3959172589.14959,199.996238708496,999.929748535156,,,6,,,,30.9592328514771,,,10,,,,,,,,,,,,,,,,,,,,,,199.978851318359,200.014495849609,999.929748535156,999.929748535156,,,6.45770931243896,,1,0,0,0,0.00030517578125,35.190616607666,1,1,1,199.977981567383,0,200.003270467122,-229.996810913086,1,0.000745095483015113,3.67580901999721E-5,0.000745896262509149,3.67619549021095E-5,0.947924792766571,0.972122430801392,31.1263790130615,0,30,4,200,-0.000324264314258471,-0.329247385263443,0.0182569045573473,1,,,,,,,,,,,,,,,,
,3959172714.17571,199.99388885498,999.929748535156,,,6,,,,30.9592328514771,,,10,,,,,,,,,,,,,,,,,,,,,,199.983032226562,200.016723632813,999.929748535156,999.929748535156,,,6.45846891403198,,1,0,0,0,0.0003814697265625,35.6793746948242,1,1,1,199.989517211914,0,200.000552142108,-225.998413085938,1,0.000741739204013137,2.11294628637987E-5,0.000742538193820153,2.11297393200399E-5,0.945477724075317,0.97085028886795,31.1345558166504,5.57983493804932,30,4,200,-0.000162284777616151,-0.328782975673676,0.0176967345178127,3,,,,,,,,,,,,,,,,
,3959172840.83558,199.99592590332,999.929748535156,,,6,,,,30.9592328514771,,,10,,,,,,,,,,,,,,,,,,,,,,199.980194091797,200.016647338867,999.929748535156,999.929748535156,,,6.45865154266357,,1,0,0,0,0.0005340576171875,35.6793746948242,1,1,1,199.979217529297,0,200.005013359918,-219.998413085938,1,0.000738561757844129,3.64446529560046E-5,0.000739413901497569,3.64454973523828E-5,0.943448841571808,0.969294905662537,31.1403141021729,0,30,4,200,-0.000259903201367706,-0.327468007802963,0.0163127426058054,1,,,,,,,,,,,,,,,,
,3959172965.6644,199.996528625488,999.929748535156,,,6,,,,30.9592328514771,,,10,,,,,,,,,,,,,,,,,,,,,,199.982666015625,200.017288208008,999.929748535156,999.929748535156,,,6.45954990386963,,1,0,0,0,0.0002288818359375,35.6793746948242,1,1,1,199.991333007813,0,200.000422159831,-215.995208740234,1,0.000735740311513084,2.09616777745391E-5,0.000736578268455781,2.09619563153577E-5,0.942839443683624,0.968028664588928,31.1399593353271,9.27190113067627,30,4,200,-0.000167877820786089,-0.326861619949341,0.0162390023469925,3,,,,,,,,,,,,,,,,
,3959173093.65858,199.998580932617,999.929748535156,,,6,,,,30.9592328514771,,,10,,,,,,,,,,,,,,,,,,,,,,199.97883605957,200.019760131836,999.929748535156,999.929748535156,,,6.45988273620605,,1,0,0,0,0.0005340576171875,35.6793746948242,1,1,1,199.977401733398,0,200.003289794922,-209.995208740234,1,0.000732022849557249,3.6129059004436E-5,0.000732956437691647,3.61308179110469E-5,0.940095841884613,0.966197729110718,31.1480941772461,0,30,4,200,-0.000323265674524009,-0.325788885354996,0.0146634820848703,1,,,,,,,,,,,,,,,,
,3959173219.83831,199.994956970215,999.929748535156,,,6,,,,30.9592328514771,,,10,,,,,,,,,,,,,,,,,,,,,,199.985015869141,200.017150878906,999.929748535156,999.929748535156,,,6.46139764785767,,1,0,0,0,0.0003814697265625,36.6568908691406,1,1,1,199.991638183594,0,200.001433195891,-205.996810913086,1,0.000726218281508689,2.06972137317939E-5,0.000727344398886258,2.07015685719456E-5,0.937346577644348,0.964584708213806,31.1560554504395,0,30,4,200,-0.000293959194095805,-0.324590444564819,0.0140218520537019,3,,,,,,,,,,,,,,,,
,3959173347.61796,199.996635437012,999.929748535156,,,6,,,,30.9592328514771,,,10,,,,,,,,,,,,,,,,,,,,,,199.975875854492,200.017684936523,999.929748535156,999.929748535156,,,6.46254444122314,,1,0,0,0,0.0003814697265625,35.190616607666,1,1,1,199.9755859375,0,200.001617431641,-199.996810913086,1,0.000719318863932523,3.5516309256228E-5,0.000720482749399147,3.55211452560154E-5,0.933755457401276,0.962107837200165,31.1667003631592,0,30,4,200,-0.000332492141751572,-0.321766942739487,0.0124403424561024,1,,,,,,,,,,,,,,,,
,3959173472.57529,199.99437713623,999.929748535156,,,6,,,,30.9592328514771,,,10,,,,,,,,,,,,,,,,,,,,,,199.982727050781,200.017028808594,999.929748535156,999.929748535156,,,6.46287441253662,,1,0,0,0,0.0005340576171875,35.190616607666,1,1,1,199.989654541016,0,199.999732688621,-195.998413085938,1,0.000712810777170814,2.03230975292594E-5,0.000714033586798488,2.03252791751789E-5,0.931383311748505,0.961206912994385,31.1756210327148,0,30,4,200,-0.000284011737676337,-0.320689886808395,0.0116114970296621,3,,,,,,,,,,,,,,,,
,3959173599.54792,199.996429443359,999.929748535156,,,6,,,,30.9592328514771,,,10,,,,,,,,,,,,,,,,,,,,,,199.978118896484,200.017272949219,999.929748535156,999.929748535156,,,6.46271753311157,,1,0,0,0,0.0005340576171875,35.190616607666,1,1,1,199.977844238281,0,200.004170227051,-189.998413085938,1,0.000707374684992447,3.49355339329793E-5,0.000708555959313035,3.49358744919087E-5,0.930007457733154,0.960098505020142,31.1795425415039,0,30,4,200,-0.000211753969779238,-0.319179803133011,0.00944691151380539,1,,,,,,,,,,,,,,,,
,3959173724.61818,199.99568939209,999.929748535156,,,6,,,,30.9643070875728,,,10,,,,,,,,,,,,,,,,,,,,,,199.980224609375,200.017807006836,999.929748535156,999.929748535156,,,6.46338176727295,,1,0,0,0,0.0003814697265625,35.6793746948242,1,1,1,199.991912841797,0,199.999422426577,-186.000015258789,1,0.000704225250239272,2.00776561207273E-5,0.000705331336202082,2.00785207763745E-5,0.931861162185669,0.96000325679779,31.1754264831543,0,30,4,200,-0.000169134786119685,-0.318609893321991,0.0092430068179965,3,,,,,,,,,,,,,,,,
,3959173853.30773,199.996208190918,999.929748535156,,,6,,,,30.9643070875728,,,10,,,,,,,,,,,,,,,,,,,,,,199.974548339844,200.018371582031,999.929748535156,999.929748535156,,,6.46427822113037,,1,0,0,0,0.0142669677734375,35.6793746948242,1,1,1,199.974044799805,0,200.000949435764,-180.000015258789,1,0.000701173913832334,3.4625693650212E-5,0.000702311841310864,3.4628055336188E-5,0.931497633457184,0.960054993629456,31.1774082183838,1.89215588761726E-5,30,4,200,-0.000330623093759641,-0.317294239997864,0.0087474649772048,1,,,,,,,,,,,,,,,,
,3959173978.30841,199.99552154541,999.929748535156,,,6,,,,30.9643070875728,,,10,,,,,,,,,,,,,,,,,,,,,,199.984619140625,200.017959594727,999.929748535156,999.929748535156,,,6.4649772644043,,1,0,0,0,0.0003814697265625,35.6793746948242,1,1,1,199.9912109375,0,200.001306039316,-175.996810913086,1,0.000696203555155825,1.98508141791129E-5,0.00069744766001918,1.98544453543158E-5,0.930504024028778,0.959563791751862,31.1799297332764,0,30,4,200,-0.000354207848431543,-0.317347794771194,0.00756576005369425,3,,,,,,,,,,,,,,,,
,3959174105.09163,199.998947143555,999.929748535156,,,6,,,,30.9643070875728,,,10,,,,,,,,,,,,,,,,,,,,,,199.976898193359,200.019790649414,999.929748535156,999.929748535156,,,6.46519708633423,,1,0,0,0,0.0002288818359375,35.6793746948242,1,1,1,199.978103637695,0,200.001936340332,-169.996810913086,1,0.000691613801667428,3.41584683906609E-5,0.000692854592540938,3.41621441415464E-5,0.929453492164612,0.959772646427155,31.1857757568359,0,30,4,200,-0.000360690144589171,-0.315811485052109,0.00614373525604606,1,,,,,,,,,,,,,,,,
,3959174232.24918,199.996421813965,999.929748535156,,,6,,,,30.9643070875728,,,10,,,,,,,,,,,,,,,,,,,,,,199.979965209961,200.019180297852,999.929748535156,999.929748535156,,,6.46632480621338,,1,0,0,0,0.0002288818359375,36.1681327819824,1,1,1,199.991165161133,0,199.999696459089,-165.998413085938,1,0.000688073634683155,1.96198940243754E-5,0.000689306146709032,1.96217791555493E-5,0.929863810539246,0.960720360279083,31.1862640380859,0,30,4,200,-0.000285649206489325,-0.315887033939362,0.00544454390183091,3,,,,,,,,,,,,,,,,
,3959174360.20529,199.997894287109,999.929748535156,,,6,,,,30.9643070875728,,,10,,,,,,,,,,,,,,,,,,,,,,199.978256225586,200.017578125,999.929748535156,999.929748535156,,,6.46667766571045,,1,0,0,0,0.0005340576171875,35.6793746948242,1,1,1,199.978210449219,0,200.003829956055,-159.998413085938,1,0.000686923498155596,3.39230231841741E-5,0.000688028674357042,3.39210173128663E-5,0.931055307388306,0.962181448936462,31.1846809387207,0,30,4,200,-0.000222955990466289,-0.315942049026489,0.00423258310183883,1,,,,,,,,,,,,,,,,
,3959174486.16504,199.99373626709,999.929748535156,,,6,,,,30.9643070875728,,,10,,,,,,,,,,,,,,,,,,,,,,199.980697631836,200.017318725586,999.929748535156,999.929748535156,,,6.46753549575806,,1,0,0,0,0.0005340576171875,35.6793746948242,1,1,1,199.988616943359,0,199.998601096017,-155.995208740234,1,0.000685557446040882,1.95443157192976E-5,0.000686654014076427,1.95445919238929E-5,0.932700157165527,0.962981343269348,31.1789836883545,0,30,4,200,-0.000191241939319298,-0.316545873880386,0.00417595868930221,3,,,,,,,,,,,,,,,,
,3959174612.81553,199.996795654297,999.929748535156,,,6,,,,30.9643070875728,,,10,,,,,,,,,,,,,,,,,,,,,,199.976364135742,200.016677856445,999.929748535156,999.929748535156,,,6.46695232391357,,1,0,0,0,0.000152587890625,35.190616607666,1,1,1,199.977081298828,0,200.001034545898,-149.995208740234,1,0.000687640857782395,3.39512903351955E-5,0.000688711120730165,3.39516307726253E-5,0.934167742729187,0.96461433172226,31.1762466430664,5.58356904983521,30,4,200,-0.00027525145560503,-0.31778222322464,0.00351922889240086,1,,,,,,,,,,,,,,,,
,3959174737.60529,199.996055603027,999.929748535156,,,6,,,,30.9643070875728,,,10,,,,,,,,,,,,,,,,,,,,,,199.982681274414,200.016235351562,999.929748535156,999.929748535156,,,6.46735239028931,,1,0,0,0,0.0005340576171875,35.6793746948242,1,1,1,199.992904663086,0,200.000380339446,-145.996810913086,1,0.000687410894069359,1.95934672946875E-5,0.000688458033167219,1.95943095178881E-5,0.935534119606018,0.965280413627624,31.1709117889404,0,30,4,200,-0.000191008686670102,-0.318506985902786,0.00356625975109637,3,,,,,,,,,,,,,,,,
,3959174865.32601,199.996963500977,999.929748535156,,,6,,,,30.9643070875728,,,10,,,,,,,,,,,,,,,,,,,,,,199.977645874023,200.017837524414,999.929748535156,999.929748535156,,,6.46732521057129,,1,0,0,0,0.00030517578125,35.6793746948242,1,1,1,199.976089477539,0,200.003402709961,-139.996810913086,1,0.000689390744696862,3.40301594610118E-5,0.000690427764007876,3.40334972857019E-5,0.937598586082458,0.966971933841705,31.165548324585,0,30,4,200,-0.000474925735034049,-0.319535762071609,0.00301988376304507,1,,,,,,,,,,,,,,,,
,3959174991.20753,199.995529174805,999.929748535156,,,6,,,,30.9643070875728,,,10,,,,,,,,,,,,,,,,,,,,,,199.981079101562,200.018997192383,999.929748535156,999.929748535156,,,6.46814012527466,,1,0,0,0,0.000152587890625,34.7018585205078,1,1,1,199.989501953125,0,200.00023324149,-135.998413085938,1,0.000690258288318997,1.96695392579121E-5,0.000691217640165266,1.96708367611358E-5,0.939671158790588,0.968379259109497,31.1594333648682,0,30,4,200,-0.00021314863988664,-0.320955991744995,0.00271303323097527,3,,,,,,,,,,,,,,,,
,3959175119.61207,199.997650146484,999.929748535156,,,6,,,,30.9643070875728,,,10,,,,,,,,,,,,,,,,,,,,,,199.979598999023,200.017532348633,999.929748535156,999.929748535156,,,6.46792030334473,,1,0,0,0,0.000457763671875,33.2355842590332,1,1,1,199.977767944336,0,200.003874037001,-129.998413085938,1,0.000696303828910858,3.43622672081599E-5,0.000697141587855166,3.43600582865572E-5,0.942000448703766,0.971089065074921,31.1552867889404,0.186815693974495,30,4,200,-0.000244856317294762,-0.323357254266739,0.0027532521635294,1,,,,,,,,,,,,,,,,
,3959175245.04631,199.992866516113,999.929748535156,,,6,,,,30.9643070875728,,,10,,,,,,,,,,,,,,,,,,,,,,199.981246948242,200.016052246094,999.929748535156,999.929748535156,,,6.46835994720459,,1,0,0,0,0.000457763671875,35.190616607666,1,1,1,199.991409301758,0,199.999539410626,-125.995208740234,1,0.000698695575435298,1.99041191831639E-5,0.000699461196546892,1.99035954440689E-5,0.944732248783112,0.971436619758606,31.1440048217773,2.87830812339962E-6,30,4,200,-0.000114512804429978,-0.325225412845612,0.0030943329911679,3,,,,,,,,,,,,,,,,
,3959175374.69415,199.996589660645,999.929748535156,,,6,,,,30.9643070875728,,,10,,,,,,,,,,,,,,,,,,,,,,199.976760864258,200.017684936523,999.929748535156,999.929748535156,,,6.46844959259033,,1,0,0,0,0.000457763671875,35.190616607666,1,1,1,199.975494384766,0,200.003816392687,-119.995208740234,1,0.000707253280326549,3.48913092721564E-5,0.000707954969410835,3.48917859903363E-5,0.947870910167694,0.972343385219574,31.1316318511963,0,30,4,200,-0.0003245152765885,-0.328040242195129,0.00367970718070865,1,,,,,,,,,,,,,,,,
,3959175499.73767,199.99592590332,999.929748535156,,,6,,,,30.9643070875728,,,10,,,,,,,,,,,,,,,,,,,,,,199.984024047852,200.017211914062,999.929748535156,999.929748535156,,,6.46844434738159,,1,0,0,0,0.000457763671875,35.190616607666,1,1,1,199.991104125977,0,200.000381469727,-115.996803283691,1,0.000710977423261454,2.02480219336146E-5,0.000711563981549764,2.02476917564756E-5,0.950342953205109,0.971953213214874,31.1194019317627,0,30,4,200,-0.000326067151036113,-0.331041306257248,0.00352246453985572,3,,,,,,,,,,,,,,,,
,3959175627.39944,199.996047973633,999.929748535156,,,6,,,,30.9643070875728,,,10,,,,,,,,,,,,,,,,,,,,,,199.975921630859,200.016174316406,999.929748535156,999.929748535156,,,6.46889925003052,,1,0,0,0,0.0005340576171875,35.190616607666,1,1,1,199.975921630859,0,200.001322937012,-109.996803283691,1,0.000717292762346838,3.53750241738595E-5,0.000717808753505886,3.53775284440278E-5,0.954551517963409,0.972237110137939,31.1001243591309,2.1880171061639E-6,30,4,200,-0.000456824549473822,-0.333342969417572,0.003317566588521,1,,,,,,,,,,,,,,,,
,3959175752.35464,199.997207641602,999.929748535156,,,6,,,,30.9643070875728,,,10,,,,,,,,,,,,,,,,,,,,,,199.985107421875,200.020278930664,999.929748535156,999.929748535156,,,6.46894264221191,,1,0,0,0,0.000152587890625,35.6793746948242,1,1,1,199.992599487305,0,200.00252504702,-105.998405456543,1,0.000720726764966535,2.0517975846017E-5,0.000721106629255047,2.05185946046492E-5,0.958572089672089,0.973093450069427,31.0832672119141,0,30,4,200,-0.000257631239946932,-0.335710614919662,0.003242606529966,3,,,,,,,,,,,,,,,,
,3959175879.56363,199.996803283691,999.929748535156,,,6,,,,30.9643070875728,,,10,,,,,,,,,,,,,,,,,,,,,,199.974426269531,200.017715454102,999.929748535156,999.929748535156,,,6.46883535385132,,1,0,0,0,0.0002288818359375,35.190616607666,1,1,1,199.975891113281,0,200.00057220459,-99.998405456543,1,0.000729479805245803,3.59628668689911E-5,0.000729720084820474,3.59619061365224E-5,0.963487982749939,0.975065469741821,31.0650691986084,0.0976957157254219,30,4,200,-0.00027055197278969,-0.338365584611893,0.00357281626202166,1,,,,,,,,,,,,,,,,
,3959176003.92096,199.995262145996,999.929748535156,,,6,,,,30.9643070875728,,,10,,,,,,,,,,,,,,,,,,,,,,199.983901977539,200.018341064453,999.929748535156,999.929748535156,,,6.46860599517822,,1,0,0,0,0.0003814697265625,35.6793746948242,1,1,1,199.992446899414,0,200.000229426793,-96.0000076293945,1,0.000732755822653861,2.08542533310479E-5,0.000732918508231327,2.08533965687559E-5,0.966458857059479,0.975519299507141,31.0510368347168,1,30,4,200,-0.000111474699224345,-0.340380400419235,0.00433141319081187,3,,,,,,,,,,,,,,,,
,3959176132.92677,199.996963500977,999.929748535156,,,6,,,,30.9643070875728,,,10,,,,,,,,,,,,,,,,,,,,,,199.975219726562,200.017517089844,999.929748535156,999.929748535156,,,6.46919822692871,,1,0,0,0,0.00030517578125,35.6793746948242,1,1,1,199.976409912109,0,200.000061035156,-90.0000076293945,1,0.000740488357307196,3.64974303610782E-5,0.000740594815423206,3.64969689285732E-5,0.970220923423767,0.976037085056305,31.0311508178711,3.85254425054882E-5,30,4,200,-0.000302767992252484,-0.343030989170074,0.00383118819445372,1,,,,,,,,,,,,,,,,
,3959176258.31913,199.995956420898,999.929748535156,,,6,,,,30.9643070875728,,,10,,,,,,,,,,,,,,,,,,,,,,199.976593017578,200.019592285156,999.929748535156,999.929748535156,,,6.46966743469238,,1,0,0,0,0.00030517578125,35.6793746948242,1,1,1,199.991149902344,0,199.999459160699,-85.9968032836914,1,0.000743633958474573,2.11602765473733E-5,0.000743699149713184,2.11601067317626E-5,0.971908450126648,0.975548148155212,31.0165691375732,0,30,4,200,-0.000275895785307512,-0.345300048589706,0.00399947213009,3,,,,,,,,,,,,,,,,
,3959176386.64779,199.995780944824,999.929748535156,,,6,,,,30.9643070875728,,,10,,,,,,,,,,,,,,,,,,,,,,199.97395324707,200.017608642578,999.929748535156,999.929748535156,,,6.47006464004517,,1,0,0,0,0.000457763671875,35.190616607666,1,1,1,199.97395324707,0,200.000489807129,-79.9968032836914,1,0.000747665163607273,3.68469913341706E-5,0.000747708270004853,3.68477155394735E-5,0.974303543567657,0.975826561450958,30.9971809387207,3.34685523739608E-7,30,4,200,-0.000550103082787246,-0.346255421638489,0.00342292478308082,1,,,,,,,,,,,,,,,,
,3959176511.69922,199.994422912598,999.929748535156,,,6,,,,30.9643070875728,,,10,,,,,,,,,,,,,,,,,,,,,,199.983734130859,200.018051147461,999.929748535156,999.929748535156,,,6.47041893005371,,1,0,0,0,0.000152587890625,35.190616607666,1,1,1,199.989013671875,0,200.000331878662,-75.998405456543,1,0.000747631298343986,2.12722932879282E-5,0.000747641263458782,2.12723229394591E-5,0.974988043308258,0.975469529628754,30.9827690124512,1.87944184659727E-8,30,4,200,-0.000327615824062377,-0.346831023693085,0.00338509003631771,3,,,,,,,,,,,,,,,,
,3959176639.4441,199.996070861816,999.929748535156,,,6,,,,30.9643070875728,,,10,,,,,,,,,,,,,,,,,,,,,,199.975723266602,200.016418457031,999.929748535156,999.929748535156,,,6.47044038772583,,1,0,0,0,0.00030517578125,35.190616607666,1,1,1,199.975723266602,0,199.999597167969,-69.998405456543,1,0.000749289109714353,3.69251250560391E-5,0.000749289164177034,3.69251262621096E-5,0.976389944553375,0.976391673088074,30.9653797149658,0,30,4,200,-0.000219966575969011,-0.346699118614197,0.00282832584343851,1,,,,,,,,,,,,,,,,
,3959176764.75872,199.995506286621,999.929748535156,,,6,,,,30.9643070875728,,,10,,,,,,,,,,,,,,,,,,,,,,199.984085083008,200.017364501953,999.929748535156,999.929748535156,,,6.47108745574951,,1,0,0,0,0.0003814697265625,35.190616607666,1,1,1,199.991760253906,0,200.001034206814,-65.9952011108398,1,0.000747813938472486,2.12773478987336E-5,0.000747823009195501,2.12774871297472E-5,0.975257277488708,0.975483953952789,30.9516201019287,3.21567972605408E-6,30,4,200,-0.000119989475933835,-0.347180306911468,0.00236800755374134,3,,,,,,,,,,,,,,,,
,3959176894.49738,199.996109008789,999.929748535156,,,6,,,,30.9643070875728,,,10,,,,,,,,,,,,,,,,,,,,,,199.976806640625,200.015411376953,999.929748535156,999.929748535156,,,6.47074413299561,,1,0,0,0,0.0005340576171875,34.7018585205078,1,1,1,199.976806640625,0,200.0001953125,-59.9952011108398,1,0.000748393288745636,3.68840925631743E-5,0.000748426513042766,3.68846260773749E-5,0.973050534725189,0.974184155464172,30.9349231719971,0,30,4,200,-0.000302483444102108,-0.34699684381485,0.00154844368807971,1,,,,,,,,,,,,,,,,
,3959177021.66175,199.994201660156,999.929748535156,,,6,,,,30.9643070875728,,,10,,,,,,,,,,,,,,,,,,,,,,199.986312866211,200.019409179687,999.929748535156,999.929748535156,,,6.47109031677246,,1,0,0,0,7.62939453125E-5,35.190616607666,1,1,1,199.991241455078,0,200.002047947475,-55.9968032836914,1,0.000746522842690942,2.12434129115236E-5,0.000746582804823934,2.1243848358571E-5,0.970403730869293,0.972497403621674,30.9227313995361,0,30,4,200,-0.000227245021960698,-0.347182512283325,0.00134553236421198,3,,,,,,,,,,,,,,,,
,3959177149.33063,199.996284484863,999.929748535156,,,6,,,,30.9643070875728,,,10,,,,,,,,,,,,,,,,,,,,,,199.977355957031,200.0166015625,999.929748535156,999.929748535156,,,6.47068309783935,,1,0,0,0,0.0003814697265625,35.6793746948242,1,1,1,199.975967407227,0,200.003000895182,-49.9968032836914,1,0.000744082963121615,3.66784865864143E-5,0.000744134949403507,3.66772835697502E-5,0.966855227947235,0.970109283924103,30.9099426269531,0.0978535339236259,30,4,200,-0.000527274969499558,-0.34570637345314,0.000471359264338389,1,,,,,,,,,,,,,,,,
,3959177273.42616,199.996932983398,999.929748535156,,,6,,,,30.9643070875728,,,10,,,,,,,,,,,,,,,,,,,,,,199.981521606445,200.017959594727,999.929748535156,999.929748535156,,,6.47090864181519,,1,0,0,0,0.0006866455078125,35.190616607666,1,1,1,199.992172241211,0,200.000887835467,-45.9984016418457,1,0.000739071007536696,2.10364713406746E-5,0.000739176633178723,2.10365077635317E-5,0.963087916374207,0.967129111289978,30.9004230499268,,30,4,200,-0.000318761623930186,-0.345172613859177,-0.000970335328020155,3,,,,,,,,,,,,,,,,
,3959177402.13532,199.997276306152,999.929748535156,,,6,,,,30.9643070875728,,,10,,,,,,,,,,,,,,,,,,,,,,199.976425170898,200.018127441406,999.929748535156,999.929748535156,,,6.4708890914917,,1,0,0,0,0.000152587890625,35.190616607666,1,1,1,199.976425170898,0,200.001681518555,-39.9984016418457,1,0.000732694191018209,3.61261927290843E-5,0.000732813702979091,3.61261714903158E-5,0.959981799125671,0.964299142360687,30.8953647613525,,30,4,200,-0.000296318205073476,-0.342900156974793,-0.00252894009463489,1,,,,,,,,,,,,,,,,
,3959177527.13874,199.992614746094,999.929748535156,,,6,,,,30.9643070875728,,,10,,,,,,,,,,,,,,,,,,,,,,199.976776123047,200.015762329102,999.929748535156,999.929748535156,,,6.47066974639893,,1,0,0,0,0.000457763671875,35.6793746948242,1,1,1,199.987930297852,0,199.996469770159,-35.9952011108398,1,0.000727141022325374,2.07016957712433E-5,0.000727323076693351,2.07025384652775E-5,0.957283020019531,0.962501287460327,30.8861808776855,9.90453336271457E-5,30,4,200,-0.000171929365023971,-0.342464476823807,-0.00367772043682635,3,,,,,,,,,,,,,,,,
,3959177655.44831,199.995445251465,999.929748535156,,,6,,,,30.9643070875728,,,10,,,,,,,,,,,,,,,,,,,,,,199.9755859375,200.016220092773,999.929748535156,999.929748535156,,,6.47084903717041,,1,0,0,0,0.0006866455078125,35.6793746948242,1,1,1,199.974670410156,0,200.002366807726,-29.9952011108398,1,0.000722058534937126,3.56107152393611E-5,0.000722291837129282,3.56125284464417E-5,0.954157292842865,0.960525035858154,30.8751621246338,0.186694711446762,30,4,200,-0.000356222531991079,-0.34053835272789,-0.00535942288115621,1,,,,,,,,,,,,,,,,
,3959177780.37868,199.995811462402,999.929748535156,,,6,,,,30.9643070875728,,,10,,,,,,,,,,,,,,,,,,,,,,199.983856201172,200.017623901367,999.929748535156,999.929748535156,,,6.47061729431152,,1,0,0,0,0.0002288818359375,35.190616607666,1,1,1,199.991424560547,0,200.001525313766,-25.9968013763428,1,0.000718608295728812,2.0463478324346E-5,0.000718896258094904,2.04646941748476E-5,0.952207565307617,0.959962666034698,30.8645343780518,0,30,4,200,-0.00033511352376081,-0.340903848409653,-0.0061761774122715,3,,,,,,,,,,,,,,,,
,3959177907.26058,199.99592590332,999.929748535156,,,6,,,,30.9643070875728,,,10,,,,,,,,,,,,,,,,,,,,,,199.977554321289,200.016143798828,999.929748535156,999.929748535156,,,6.47054243087769,,1,0,0,0,0.0003814697265625,35.6793746948242,1,1,1,199.977722167969,0,200.003082275391,-19.9968013763428,1,0.00071374129239822,3.52071445124238E-5,0.000714071717480279,3.52096509270319E-5,0.950228989124298,0.958823800086975,30.8574142456055,1.66032859851839E-5,30,4,200,-0.000460676557850093,-0.339478343725204,-0.00805920176208019,1,,,,,,,,,,,,,,,,
,3959178032.93758,199.997764587402,999.929748535156,,,6,,,,30.9643070875728,,,10,,,,,,,,,,,,,,,,,,,,,,199.979919433594,200.018341064453,999.929748535156,999.929748535156,,,6.47098207473755,,1,0,0,0,0.0003814697265625,35.190616607666,1,1,1,199.99169921875,0,199.999413949472,-15.9984006881714,1,0.000708630755844715,2.01824547894008E-5,0.000708938969892241,2.01828418979701E-5,0.94910317659378,0.958036243915558,30.854434967041,0,30,4,200,-0.00027220684569329,-0.338710963726044,-0.00873489119112492,3,,,,,,,,,,,,,,,,
,3959178161.80159,199.998558044434,999.929748535156,,,6,,,,30.9643070875728,,,10,,,,,,,,,,,,,,,,,,,,,,199.978271484375,200.020095825195,999.929748535156,999.929748535156,,,6.4712347984314,,1,0,0,0,0.0002288818359375,35.190616607666,1,1,1,199.977020263672,0,200.005077785916,-9.99840068817139,1,0.00070168910532793,3.46152896920963E-5,0.000701989035224266,3.46159228151652E-5,0.948715031147003,0.957410633563995,30.8551788330078,5.55474376678467,30,4,200,-0.000345289648976177,-0.337073594331741,-0.0113738160580397,1,,,,,,,,,,,,,,,,
,3959178288.06102,199.995948791504,999.929748535156,,,6,,,,30.9643070875728,,,10,,,,,,,,,,,,,,,,,,,,,,199.979232788086,200.019180297852,999.929748535156,999.929748535156,,,6.47131252288818,,1,0,0,0,7.62939453125E-5,34.7018585205078,1,1,1,199.990921020508,0,199.999563711661,-6.00000047683716,1,0.000697157057138217,1.98557639230672E-5,0.000697473624002703,1.98564302713771E-5,0.94901305437088,0.958039820194244,30.8535938262939,0,30,4,200,-0.000300487910863012,-0.337198138236999,-0.0123111708089709,3,,,,,,,,,,,,,,,,
,3959178415.93472,199.996055603027,999.929748535156,,,6,,,,30.9643070875728,,,10,,,,,,,,,,,,,,,,,,,,,,199.972305297852,200.019424438477,999.929748535156,999.929748535156,,,6.4704966545105,,1,0,0,0,0.0006866455078125,35.6793746948242,1,1,1,199.972686767578,0,199.999385070801,0,1,0.00069393485120806,3.42318764097666E-5,0.000694306425277984,3.42351417748253E-5,0.949219703674316,0.958760976791382,30.8509349822998,,30,4,200,-0.000260270928265527,-0.336153715848923,-0.0139697687700391,1,,,,,,,,,,,,,,,,
,3959178541.77085,199.995269775391,999.929748535156,,,6,,,,30.9643070875728,,,10,,,,,,,,,,,,,,,,,,,,,,199.98258972168,200.018463134766,999.929748535156,999.929748535156,,,6.47119379043579,,1,0,0,0,0.0005340576171875,35.190616607666,1,1,1,199.991226196289,0,200.000532927337,3.99840021133423,1,0.000691347493653061,1.96897248139708E-5,0.000691720711672024,1.96911788160103E-5,0.949583530426025,0.959849655628204,30.8477840423584,0,30,4,200,-0.000333148665959015,-0.336605995893478,-0.0143305761739612,3,,,,,,,,,,,,,,,,
,3959178669.63432,199.996841430664,999.929748535156,,,6,,,,30.9643070875728,,,10,,,,,,,,,,,,,,,,,,,,,,199.976638793945,200.017044067383,999.929748535156,999.929748535156,,,6.47083330154419,,1,0,0,0,0.0003814697265625,35.6793746948242,1,1,1,199.976638793945,0,200.001240539551,9.99840068817139,1,0.000690622360708822,3.40658068642583E-5,0.000690994598040087,3.40685079408964E-5,0.95078718662262,0.961210906505585,30.8486671447754,1.2493477697717E-5,30,4,200,-0.000473845837404951,-0.336441487073898,0.0969619154930115,1,,,,,,,,,,,,,,,,
,3959178794.82114,199.99382019043,999.929748535156,,,6,,,,30.9643070875728,,,10,,,,,,,,,,,,,,,,,,,,,,199.983093261719,200.016830444336,999.929748535156,999.929748535156,,,6.47117519378662,,1,0,0,0,0.00030517578125,35.6793746948242,1,1,1,199.990097045898,0,199.999907882125,13.9968004226685,1,0.000688372802101797,1.96027553102963E-5,0.000688657006272498,1.96020492512491E-5,0.951910376548767,0.962361037731171,30.8502941131592,0,30,4,200,-0.000345157517585903,-0.336897224187851,0.096562035381794,3,,,,,,,,,,,,,,,,
,3959178922.49529,199.996940612793,999.929748535156,,,6,,,,30.9643070875728,,,10,,,,,,,,,,,,,,,,,,,,,,199.979125976562,200.015869140625,999.929748535156,999.929748535156,,,6.47183036804199,,1,0,0,0,0.000152587890625,35.190616607666,1,1,1,199.978012084961,0,200.003935072157,19.9968013763428,1,0.000687792043442215,3.39194726881232E-5,0.000688057383743719,3.3919539578876E-5,0.95497739315033,0.96449202299118,30.85888671875,0.0935354828834534,30,4,200,-0.000326499721268192,-0.337137550115585,0.0951863303780556,1,,,,,,,,,,,,,,,,
,3959179047.49441,199.994300842285,999.929748535156,,,6,,,,30.9643070875728,,,10,,,,,,,,,,,,,,,,,,,,,,199.984481811523,200.016311645508,999.929748535156,999.929748535156,,,6.47209167480469,,1,0,0,0,0.000152587890625,35.6793746948242,1,1,1,199.990341186523,0,200.000779893663,24.0000019073486,1,0.000687294393698527,1.95670720424621E-5,0.00068753737872174,1.9567358422116E-5,0.957515001296997,0.966409981250763,30.8652305603027,0,30,4,200,-0.000208533791010268,-0.337959676980972,0.0951872393488884,3,,,,,,,,,,,,,,,,
,3959179176.56977,199.996650695801,999.929748535156,,,6,,,,30.9643070875728,,,10,,,,,,,,,,,,,,,,,,,,,,199.97575378418,200.018081665039,999.929748535156,999.929748535156,,,6.47200393676758,,1,0,0,0,0.0005340576171875,35.6793746948242,1,1,1,199.975219726562,0,200.00185139974,29.9952011108398,1,0.000690257107683599,3.40315585157402E-5,0.000690491947379148,3.40343908525615E-5,0.961653232574463,0.969061076641083,30.8780555725098,0,30,4,200,-0.000329080154187977,-0.339471161365509,0.0944869145750999,1,,,,,,,,,,,,,,,,
,3959179301.14173,199.9951171875,999.929748535156,,,6,,,,30.9643070875728,,,10,,,,,,,,,,,,,,,,,,,,,,199.983703613281,200.018035888672,999.929748535156,999.929748535156,,,6.47261142730713,,1,0,0,0,0.0005340576171875,35.6793746948242,1,1,1,199.990493774414,0,200.00064262977,33.9984016418457,1,0.000691250052115113,1.96755101656635E-5,0.000691457922046398,1.96766981889233E-5,0.96285080909729,0.969999551773071,30.8809585571289,2.52682712016394E-5,30,4,200,-0.000206102748052217,-0.340492784976959,0.0949479416012764,3,,,,,,,,,,,,,,,,
,3959179429.21106,199.997123718262,999.929748535156,,,6,,,,30.9643070875728,,,10,,,,,,,,,,,,,,,,,,,,,,199.979644775391,200.016525268555,999.929748535156,999.929748535156,,,6.47259187698364,,1,0,0,0,0.0002288818359375,35.190616607666,1,1,1,199.978240966797,0,200.003757052951,39.9984016418457,1,0.000697231853289605,3.43700928298235E-5,0.000697379755031076,3.43717590460032E-5,0.965939939022064,0.971135497093201,30.8956623077393,5.55838680267334,30,4,200,-0.000496436026878655,-0.342990100383759,0.0950434505939484,1,,,,,,,,,,,,,,,,
,3959179555.16645,199.995323181152,999.929748535156,,,6,,,,30.9643070875728,,,10,,,,,,,,,,,,,,,,,,,,,,199.981307983398,200.017623901367,999.929748535156,999.929748535156,,,6.47239923477173,,1,0,0,0,0.000457763671875,35.6793746948242,1,1,1,199.990585327148,0,200.000094943576,43.9968032836914,1,0.000699862459838581,1.99172628282195E-5,0.000699954244793597,1.9917437866136E-5,0.967733144760132,0.971774578094482,30.9051094055176,0,30,4,200,-0.000280947744613513,-0.344803810119629,0.0954968109726906,3,,,,,,,,,,,,,,,,
,3959179683.56508,199.997497558594,999.929748535156,,,6,,,,30.9643070875728,,,10,,,,,,,,,,,,,,,,,,,,,,199.976181030273,200.018814086914,999.929748535156,999.929748535156,,,6.47244119644165,,1,0,0,0,0.000457763671875,35.190616607666,1,1,1,199.976181030273,0,200.000135803223,49.9968032836914,1,0.00070688092379827,3.48405476072124E-5,0.000706921343108726,3.48407308501549E-5,0.970633685588837,0.972456812858582,30.925760269165,0,30,4,200,-0.000375211908249185,-0.34712541103363,0.095833458006382,1,,,,,,,,,,,,,,,,
,3959179808.06574,199.993728637695,999.929748535156,,,6,,,,30.9643070875728,,,10,,,,,,,,,,,,,,,,,,,,,,199.982406616211,200.019226074219,999.929748535156,999.929748535156,,,6.4723048210144,,1,0,0,0,0.0002288818359375,35.6793746948242,1,1,1,199.992431640625,0,200.002885546003,53.9952011108398,1,0.000710602950369512,2.02199415085283E-5,0.000710615562188314,2.021993984738E-5,0.972694933414459,0.973355412483215,30.9417190551758,0,30,4,200,-0.000290548690827563,-0.2374626994133,0.096379891037941,3,,,,,,,,,,,,,,,,
,3959179938.09764,199.996368408203,999.929748535156,,,6,,,,30.9643070875728,,,10,,,,,,,,,,,,,,,,,,,,,,199.976638793945,200.017532348633,999.929748535156,999.929748535156,,,6.47261095046997,,1,0,0,0,0.0006866455078125,34.7018585205078,1,1,1,199.975280761719,0,200.002824571398,59.9952011108398,1,0.000718394520108286,3.54047988591015E-5,0.000718394154496317,3.54047800071336E-5,0.973932862281799,0.973933756351471,30.9651184082031,0,30,4,200,-0.000246662239078432,-0.240350723266602,0.0961658582091331,1,,,,,,,,,,,,,,,,
,3959180063.43439,199.99681854248,999.929748535156,,,6,,,,30.9643070875728,,,10,,,,,,,,,,,,,,,,,,,,,,199.980041503906,200.018280029297,999.929748535156,999.929748535156,,,6.472243309021,,1,0,0,0,0.0006866455078125,35.190616607666,1,1,1,199.992492675781,0,200.000291612413,63.9984016418457,1,0.000721543021383251,2.05308367881996E-5,0.000721542774361744,2.05307302845179E-5,0.973405599594116,0.973588287830353,30.9760818481445,0,30,4,200,-0.000179148148163222,-0.243039608001709,0.0958909094333649,3,,,,,,,,,,,,,,,,
,3959180191.43822,199.995910644531,999.929748535156,,,6,,,,30.9643070875728,,,10,,,,,,,,,,,,,,,,,,,,,,199.978500366211,200.017074584961,999.929748535156,999.929748535156,,,6.47234439849854,,1,0,0,0,0.0003814697265625,35.6793746948242,1,1,1,199.978424072266,0,200.003526306152,69.998405456543,1,0.000729980675193919,3.59780417104336E-5,0.000729994099278423,3.59776259817617E-5,0.971627473831177,0.972702443599701,30.9935665130615,5.3603892326355,30,4,200,-0.000295196805382147,-0.246628031134605,0.0958524793386459,1,,,,,,,,,,,,,,,,
,3959180316.55689,199.997276306152,999.929748535156,,,6,,,,30.9643070875728,,,10,,,,,,,,,,,,,,,,,,,,,,199.982452392578,200.019348144531,999.929748535156,999.929748535156,,,6.47220706939697,,1,0,0,0,0.0006103515625,35.190616607666,1,1,1,199.992080688477,0,200.000502995082,73.9968032836914,1,0.000734189044634388,2.08928496324512E-5,0.000734226938992352,2.08925597230943E-5,0.969714462757111,0.971958100795746,31.0075149536133,0,30,4,200,-0.000370178953744471,-0.249048352241516,0.096268005669117,3,,,,,,,,,,,,,,,,
,3959180445.4405,199.995994567871,999.929748535156,,,6,,,,30.9643070875728,,,10,,,,,,,,,,,,,,,,,,,,,,199.975540161133,200.016448974609,999.929748535156,999.929748535156,,,6.47234535217285,,1,0,0,0,0.0011444091796875,35.6793746948242,1,1,1,199.975540161133,0,200.000563049316,79.9968032836914,1,0.000740258966935812,3.64897905804682E-5,0.000740367097633339,3.64898076632732E-5,0.9670250415802,0.971778810024262,31.0286846160889,0,30,4,200,-0.000455470115412027,-0.251247316598892,0.0961028710007668,1,,,,,,,,,,,,,,,,
,3959180571.86716,199.9970703125,999.929748535156,,,6,,,,30.9643070875728,,,10,,,,,,,,,,,,,,,,,,,,,,199.981918334961,200.01872253418,999.929748535156,999.929748535156,,,6.47209978103638,,1,0,0,0,0.0003814697265625,35.190616607666,1,1,1,199.991500854492,0,200.001365379051,84.0000076293945,1,0.000742079762132456,2.11205916931434E-5,0.000742257082548622,2.11209129454732E-5,0.96509850025177,0.972230672836304,31.0441818237305,5.5717306137085,30,4,200,-0.000283477565972134,-0.25288587808609,0.095716692507267,3,,,,,,,,,,,,,,,,
,3959180700.26985,200.002838134766,999.929748535156,,,6,,,,30.9643070875728,,,10,,,,,,,,,,,,,,,,,,,,,,199.984283447266,200.023483276367,999.929748535156,999.929748535156,,,6.47277641296387,,1,0,0,0,0.0008392333984375,35.6793746948242,1,1,1,199.982192993164,0,200.009824964735,90.0000076293945,1,0.000746713680389354,3.68145581213244E-5,0.000746991881953346,3.68142905967429E-5,0.961978375911713,0.9737908244133,31.0685138702393,0.265655517578125,30,4,200,-0.000330518058035523,-0.254387557506561,0.0953821465373039,1,,,,,,,,,,,,,,,,
,3959180724.12702,199.997528076172,999.929748535156,,,6,,,,30.9643070875728,,,10,,,,,,,,,,,,,,,,,,,,,,199.984558105469,200.020538330078,999.929748535156,999.929748535156,,,6.47219610214233,,1,0,0,0,0.000457763671875,35.6793746948242,1,1,1,199.992446899414,0,200.002369068287,90.0000076293945,1,0.000745728806530973,2.12268912292937E-5,0.000746009772265904,2.12268796204518E-5,0.961949586868286,0.973653078079224,31.0682163238525,3.73512023088551E-7,30,4,200,-0.000202658906346187,-0.254496157169342,0.0957756191492081,3,,,,,,,,,,,,,,,,