File: PPMS_Data_and_Plotting/Data/RuCl3/Data/Magnetisation/27-01-2025_RUCL3_TB001_0.1T_00002.csv
[Header]
; VSM Data File (default extension .dat)
; Copyright (c) 2003-2013, Quantum Design, Inc. All rights reserved.
TITLE,27-01-2025_RUCL3_TB001_0.1T H PARA C
FILEOPENTIME,2346874.94,01/28/2025,10:59 am
BYAPP,VSM,2.0,2.0
INFO,PPMS VSM Option Release 1.4.10 Build 1,APPNAME
INFO,Quantum Design Linear Motor Servo Controller,MOTOR_MODULE_NAME
INFO,3101-100 M1,MOTOR_HW_VERSION
INFO,MMC920,MOTOR_SERIAL_NUMBER
INFO,SRV No X-over 01.03.11,MOTOR_SOFTWARE_VERSION
INFO,Quantum Design VSM Detection Module,VSM_MODULE_NAME
INFO,3101-150 F0,VSM_HW_VERSION
INFO,VSM672,VSM_SERIAL_NUMBER
INFO,VSM No X-over 01.02.05 May 20 2008 13:51:47,VSM_SOFTWARE_VERSION
INFO,659,PREAMP_SERIAL_NUMBER
INFO,749,COIL_SERIAL_NUMBER
INFO,0,MOMENT_UNITS
INFO,RuCl3,SAMPLE_MATERIAL
INFO,,SAMPLE_COMMENT
INFO,33,SAMPLE_MASS
INFO,,SAMPLE_VOLUME
INFO,,SAMPLE_MOLECULAR_WEIGHT
INFO,,SAMPLE_SIZE
INFO,,SAMPLE_SHAPE
DATATYPE,COMMENT,1
DATATYPE,TIME,2
STARTUPAXIS,X,2
STARTUPAXIS,Y1,5
[Data]
Comment,Time Stamp (sec),Temperature (K),Magnetic Field (Oe),Moment (emu),M. Std. Err. (emu),Transport Action,Averaging Time (sec),Frequency (Hz),Peak Amplitude (mm),Center Position (mm),Coil Signal' (mV),Coil Signal" (mV),Range (mV),M. Quad. Signal (emu),M. Raw' (emu),M. Raw" (emu),Min. Temperature (K),Max. Temperature (K),Min. Field (Oe),Max. Field (Oe),Mass (grams),Motor Lag (deg),Pressure (Torr),VSM Status (code),Motor Status (code),Measure Status (code),Measure Count,PPMS Status (code),System Temp. (K),System Field (Oe),Sample Position (deg),Bridge 1 Resistance (ohms),Bridge 1 Excitation (�A),Bridge 2 Resistance (ohms),Bridge 2 Excitation (�A),Bridge 3 Resistance (ohms),Bridge 3 Excitation (�A),Bridge 4 Resistance (ohms),Bridge 4 Excitation (�A),Signal 1 Vin (V),Signal 2 Vin (V),Digital Inputs (code),Drive 1 Iout (mA),Drive 1 Ipower (W),Drive 2 Iout (mA),Drive 2 Ipower (W),Pressure (),Map 20 (),Map 21 (),Map 22 (),Map 23 (),Map 24 (),Map 25 (),Map 26 (),Map 27 (),Map 28 (),Map 29 ()
,2354117.83,2.995997,999.777282714844,,,2,,,,20.4160001713634,,,,,,,2.995997,2.995997,999.777282714844,999.777282714844,,,5.154188,,,,-99999999,4885,2.9846,999.777282714844,,,,,,,,,,,,,,,,,,,,,,,2.995997,,,,
,2354963.695,3.3776802,999.777282714844,0.00346387766341939,2.03991619606008E-7,1,1.99850670813958,40.0298881530762,2.00758170342337,20.3600004315376,0.0393342553968712,0.00715084201755873,0.25,2.18511947772491E-5,0.00344535262027475,3.85963783226845E-5,3.3748515,3.3805089,999.777282714844,999.777282714844,61.8768400963912,20.8169623701323,4.781127,0,0,0,80,4886,3.03305,999.777282714844,,,,,,,,,,,,,0,,,,0.1752303,,,,,,3.3776802,,,,
,2355495.805,3.6956077,999.777282714844,0.00347543850391482,2.5940884677931E-7,1,1.99850670813958,40.0298881530762,1.98283791693803,20.3200001269579,0.0389994638362904,0.00710445941825439,0.25,2.31733217100997E-5,0.00345684567277352,3.99677519926398E-5,3.6893907,3.7018247,999.777282714844,999.777282714844,62.4904184839874,20.8228147899126,5.154188,0,0,0,80,4886,3.4011,999.777282714844,,,,,,,,,,,,,0,,,,0.19461185,,,,,,3.6956077,,,,
,2355809.47,4.20319625,999.777282714844,0.00348550963746618,2.33169832350331E-7,1,1.99850670813958,40.0298881530762,1.98270082581394,20.3200001269579,0.0391107973711445,0.00711944283580684,0.25,2.27834556917846E-5,0.00346686514719773,3.96289829609784E-5,4.199923,4.2064695,999.777282714844,999.777282714844,62.5232468817951,20.8315455500603,4.781127,0,0,0,80,4886,3.9362,999.777282714844,,,,,,,,,,,,,0,,,,0.21939755,,,,,,4.20319625,,,,
,2356027.665,4.5507393,999.777282714844,0.00350399443978236,1.54796308310519E-7,1,1.99850670813958,40.0298881530762,1.98273929829037,20.2500000596046,0.0393184965477443,0.00715986597685853,0.25,2.31298697288899E-5,0.0034852498280613,4.00635331757252E-5,4.5470219,4.5544567,999.777282714844,999.777282714844,62.3239316093912,20.8313676385951,4.781127,0,0,0,80,4886,4.3098,999.777282714844,,,,,,,,,,,,,0,,,,0.2306346,,,,,,4.5507393,,,,
,2356246.825,4.90005735,999.777282714844,0.00351921046398567,1.92637968636514E-7,1,1.99850670813958,40.0298881530762,1.98265261072523,20.2500000596046,0.0394872010936217,0.00719285703219454,0.25,2.34261411290928E-5,0.00350038323759786,4.04322943196933E-5,4.8994327,4.900682,999.777282714844,999.777282714844,62.5506038799682,20.8339960969302,5.154188,0,0,0,80,4886,4.69825,999.777282714844,,,,,,,,,,,,,0,,,,0.2388383,,,,,,4.90005735,,,,
,2356580.39,5.1675997,999.777282714844,,,2,,,,20.2660004261732,,,,,,,5.1675997,5.1675997,999.777282714844,999.777282714844,,,4.781127,,,,-99999999,4886,5.2399,999.777282714844,,,,,,,,,,,,,,,,,,,,,,,5.1675997,,,,
,2356888.565,5.92106055,999.777282714844,0.0036023920786993,2.48536652576763E-7,1,1.99850670813958,40.0298881530762,1.98258895508578,20.2500000596046,0.0404181231559183,0.00736926300533994,0.25,2.45692553753031E-5,0.00358311550311746,4.19742221666086E-5,5.9191775,5.9229436,999.777282714844,999.777282714844,62.5021429117758,20.8352158956254,4.781127,0,0,0,80,4886,5.76975,999.777282714844,,,,,,,,,,,,,0,,,,0.28877385,,,,,,5.92106055,,,,
,2357102.395,6.27257965,999.777282714844,0.00365505331926967,2.80322095375701E-7,1,1.99850670813958,40.0298881530762,1.9824998538662,20.2500000596046,0.0410070597017871,0.00747749987662833,0.25,2.50024885616226E-5,0.00363549383756266,4.26614855504533E-5,6.2701287,6.2750306,999.777282714844,999.777282714844,62.6795725856412,20.838464845096,4.781127,0,0,0,80,4886,6.13285,999.777282714844,,,,,,,,,,,,,0,,,,0.31122945,,,,,,6.27257965,,,,
,2357312.345,6.61165045,999.777282714844,0.00372484880322934,1.96735009891897E-7,1,1.99850670813958,40.0298881530762,1.99419224662925,20.2399995177984,0.04202580897643,0.00765873129138163,0.25,2.50909650570172E-5,0.00370491685687496,4.30892299620008E-5,6.6106977,6.6126032,999.777282714844,999.777282714844,62.6248585892951,20.8341607595905,4.781127,0,0,0,80,4882,6.4909,999.777282714844,,,,,,,,,,,,,0,,,,0.3371235,,,,,,6.61165045,,,,
,2357622.015,7.1219282,999.777282714844,0.00391358850043434,2.49204789538478E-7,1,1.99850670813958,40.0298881530762,1.99377841204504,20.2399995177984,0.0441462449709674,0.00804680665676834,0.25,2.65038899948559E-5,0.00389264431969747,4.54133634333129E-5,7.1202922,7.1235642,999.777282714844,999.777282714844,62.3966230616797,20.8342329210432,4.781127,0,0,0,80,4882,7.01005,999.777282714844,,,,,,,,,,,,,0,,,,0.3669959,,,,,,7.1219282,,,,
,2357837.815,7.4679232,999.777282714844,0.00424757863054399,6.21920902988706E-7,1,1.99850670813958,40.0298881530762,1.99447896972249,20.2300008386374,0.0479288288452392,0.0087417838793849,0.25,2.92377378226128E-5,0.00422484341603097,4.97584413814857E-5,7.4632974,7.472549,999.777282714844,999.777282714844,62.6131341615066,20.8340253832069,5.154188,0,0,0,80,4882,7.3762,999.777282714844,,,,,,,,,,,,,0,,,,0.3857926,,,,,,7.4679232,,,,
,2358043.67,7.814085,999.777282714844,0.00473557801685832,2.67925623539761E-7,1,1.99850670813958,40.0298881530762,1.9942468312088,20.2300008386374,0.0534291930360199,0.00974605079765003,0.25,3.26869301251002E-5,0.00471022869860453,5.55647349004388E-5,7.813375,7.814795,999.777282714844,999.777282714844,62.7913454638913,20.8326001985739,4.781127,0,0,0,80,4882,7.7255,999.777282714844,,,,,,,,,,,,,0,,,,0.4116801,,,,,,7.814085,,,,
,2358351.405,8.3236246,999.777282714844,0.00473404035336763,2.59644887597204E-7,1,1.99850670813958,40.0298881530762,1.99469513930171,20.2300008386374,0.0534235660778726,0.00974319260871837,0.25,3.25192157264554E-5,0.00470869733649428,5.53903959548978E-5,8.3220863,8.3251629,999.777282714844,999.777282714844,62.7311600679105,20.8335035075607,5.154188,0,0,0,80,4882,8.2403,999.777282714844,,,,,,,,,,,,,0,,,,0.4437041,,,,,,8.3236246,,,,
,2358561.27,8.6687174,999.777282714844,0.00471707517760614,2.61221901380409E-7,1,1.99850670813958,40.0298881530762,1.98284256908766,20.2200002968311,0.0529328151323101,0.00964015054701971,0.25,3.12347428005574E-5,0.00469182666182468,5.40301508053058E-5,8.6670876,8.6703472,999.777282714844,999.777282714844,62.4278882024489,20.8361973862107,4.781127,0,0,0,80,4882,8.59425,999.777282714844,,,,,,,,,,,,,0,,,,0.46877115,,,,,,8.6687174,,,,
,2358771.12,9.0157075,999.777282714844,0.00469194596477114,2.90723650733261E-7,1,1.99850670813958,40.0298881530762,1.98286879599662,20.2200002968311,0.052651702184028,0.00958756780037112,0.25,3.0948767823871E-5,0.00466683038120341,5.36233495766448E-5,9.014513,9.016902,999.777282714844,999.777282714844,62.4716593995258,20.8361743287723,5.154188,0,0,0,80,4882,8.94445,999.777282714844,,,,,,,,,,,,,0,,,,0.4952419,,,,,,9.0157075,,,,
,2359041.67,9.4103508,999.777282714844,,,2,,,,20.2159995797873,,,,,,,9.4103508,9.4103508,999.777282714844,999.777282714844,,,4.781127,,,,-99999999,4882,9.445,999.777282714844,,,,,,,,,,,,,,,,,,,,,,,9.4103508,,,,
,2359286.725,9.8708558,999.777282714844,0.0046240477804093,3.32162512504565E-7,1,1.99850670813958,40.0298881530762,1.99471707636733,20.1999992132187,0.0521819059343348,0.00952162737617251,0.25,3.21825370294598E-5,0.00459928159257498,5.45199726525495E-5,9.8690634,9.8726482,999.777282714844,999.777282714844,63.0305237907759,20.8390964075141,4.781127,0,0,0,80,4882,9.80895,999.777282714844,,,,,,,,,,,,,0,,,,0.54455155,,,,,,9.8708558,,,,
,2359494.61,10.21652985,999.777282714844,0.00459535610752272,2.59915503455933E-7,1,1.99850670813958,40.0298881530762,1.99475324687237,20.1999992132187,0.0518597312284774,0.00945847461855905,0.25,3.16084509090946E-5,0.00457074280028815,5.38092471770611E-5,10.2147732,10.2182865,999.777282714844,999.777282714844,62.4513370580258,20.8393714081682,5.154188,0,0,0,80,4882,10.15895,999.777282714844,,,,,,,,,,,,,0,,,,0.5667521,,,,,,10.21652985,,,,
,2359700.42,10.55758285,999.777282714844,0.00456921854449912,2.99741098693862E-7,1,1.99850670813958,40.0298881530762,1.98296792964543,20.1900005340576,0.0512764184250138,0.00933943599534007,0.25,3.03375644189234E-5,0.00454474783854211,5.24178628753398E-5,10.5572023,10.5579634,999.777282714844,999.777282714844,62.7100560978913,20.8363022311739,4.408067,0,0,0,80,4882,10.50395,999.777282714844,,,,,,,,,,,,,0,,,,0.5810775,,,,,,10.55758285,,,,
,2360012.21,11.07290365,999.777282714844,0.00452576280825533,3.2083779849227E-7,1,1.99850670813958,40.0298881530762,1.98352089835138,20.1900005340576,0.0508012974973019,0.00925827177738316,0.25,3.05124196820231E-5,0.00450151826098648,5.23802056694365E-5,11.0712557,11.0745516,999.777282714844,999.777282714844,62.9367283684682,20.8432255770988,5.154188,0,0,0,80,4882,11.02435,999.777282714844,,,,,,,,,,,,,0,,,,0.6078031,,,,,,11.07290365,,,,
,2360222.035,11.4198585,999.777282714844,0.00449797839709711,1.81851877962074E-7,1,1.99850670813958,40.0298881530762,1.98362705914791,20.1900005340576,0.0504919034244296,0.00920223318981938,0.25,3.03550071695413E-5,0.00447387947937145,5.20883482426785E-5,11.4179688,11.4217482,999.777282714844,999.777282714844,62.2465503859874,20.8414667827191,4.781127,0,0,0,80,4882,11.3749,999.777282714844,,,,,,,,,,,,,0,,,,0.62006895,,,,,,11.4198585,,,,
,2360427.87,11.7624321,999.777282714844,0.00447074747546473,2.78309135065961E-7,1,1.99850670813958,40.0298881530762,1.99491684128793,20.1799999922514,0.0504577440752622,0.00920007508543083,0.25,3.05200574108134E-5,0.00444678960638988,5.21199297275635E-5,11.7606096,11.7642546,999.777282714844,999.777282714844,63.1477680686605,20.8375865648598,5.154188,0,0,0,80,4882,11.72015,999.777282714844,,,,,,,,,,,,,0,,,,0.6294227,,,,,,11.7624321,,,,
,2360735.615,12.2738242,999.777282714844,0.0044304532816324,2.94980299659931E-7,1,1.99850670813958,40.0298881530762,1.99509579215829,20.1799999922514,0.0500068079006855,0.00912012746897738,0.25,3.04398593894372E-5,0.0044067054781225,5.18439595727806E-5,12.2718601,12.2757883,999.777282714844,999.777282714844,62.5693629644297,20.8380481548661,4.781127,0,0,0,80,4882,12.23585,999.777282714844,,,,,,,,,,,,,0,,,,0.6485717,,,,,,12.2738242,,,,
,2360945.49,12.6175685,999.777282714844,0.00440707656598842,2.45638477283921E-7,1,1.99850670813958,40.0298881530762,1.99523047761985,20.1600007712841,0.0497462541187086,0.00907178239594221,0.25,3.0208434420752E-5,0.00438345095218851,5.14999352091342E-5,12.6164265,12.6187105,999.777282714844,999.777282714844,62.7546089234874,20.8405685457083,4.781127,0,0,0,80,4882,12.58125,999.777282714844,,,,,,,,,,,,,0,,,,0.6616604,,,,,,12.6175685,,,,
,2361151.285,12.96407175,999.777282714844,0.00438107404125015,3.52303638689419E-7,1,1.99850670813958,40.0298881530762,1.99516852299238,20.1699994504452,0.0494518154984001,0.00901469114125454,0.25,2.97389101979944E-5,0.00435758563798595,5.09062971445145E-5,12.9624863,12.9656572,999.777282714844,999.777282714844,62.5177754821605,20.8400132242359,5.154188,0,0,0,80,4882,12.92895,999.777282714844,,,,,,,,,,,,,0,,,,0.6683034,,,,,,12.96407175,,,,
,2361459.04,13.4772115,999.777282714844,0.00434391205221304,3.03144748720997E-7,1,1.99850670813958,40.0298881530762,1.99497563278931,20.1600007712841,0.0490280131294175,0.00893598084087856,0.25,2.93619354555851E-5,0.00432061795152869,5.03503722645075E-5,13.4754305,13.4789925,999.777282714844,999.777282714844,63.2329655772567,20.8376820538164,4.781127,0,0,0,80,4882,13.44225,999.777282714844,,,,,,,,,,,,,0,,,,0.6886353,,,,,,13.4772115,,,,
,2361664.93,13.81837035,999.777282714844,0.00432122771811122,3.05650255375425E-7,1,1.99850670813958,40.0298881530762,1.98320871409605,20.1500002294779,0.0484987217671501,0.00883334576417136,0.25,2.86769315228757E-5,0.00429805401829411,4.95585540712085E-5,13.8169661,13.8197746,999.777282714844,999.777282714844,62.7983801205643,20.8351766215877,4.781127,0,0,0,80,4882,13.78545,999.777282714844,,,,,,,,,,,,,0,,,,0.6886353,,,,,,13.81837035,,,,
,2361874.755,14.16659785,999.777282714844,0.00429656905355139,3.36858267780606E-7,1,1.99850670813958,40.0298881530762,1.98323888216049,20.1500002294779,0.0482227731283441,0.00878220017568383,0.25,2.84369219120039E-5,0.00427352394015068,4.91997462666857E-5,14.1649017,14.168294,999.777282714844,999.777282714844,62.5255917673528,20.8326155794636,4.781127,0,0,0,80,4882,14.13745,999.777282714844,,,,,,,,,,,,,0,,,,0.6955491,,,,,,14.16659785,,,,
,2362120.42,14.5359879,999.777282714844,,,2,,,,20.1659996647239,,,,,,,14.5359879,14.5359879,999.777282714844,999.777282714844,,,5.154188,,,,-99999999,4882,14.5769,999.777282714844,,,,,,,,,,,,,,,,,,,,,,,14.5359879,,,,
,2362390.305,15.0223069,999.777282714844,0.00423723632130575,2.80779271072681E-7,1,1.99850670813958,40.0298881530762,1.98410876048881,20.1500002294779,0.0475762224237595,0.00866682173032143,0.25,2.82485017235368E-5,0.00421449812767556,4.87233970062888E-5,15.0206928,15.023921,999.777282714844,999.777282714844,62.9109346273336,20.8380259126084,5.154188,0,0,0,80,4882,15.0013,999.777282714844,,,,,,,,,,,,,0,,,,0.71671,,,,,,15.0223069,,,,
,2362598.315,15.36875155,999.777282714844,0.00421392040248326,3.01583927490568E-7,1,1.99850670813958,40.0298881530762,1.98354312249758,20.1500002294779,0.0473021334929563,0.00861325244809015,0.25,2.77792481455086E-5,0.00419130446995384,4.81431012167879E-5,15.366334,15.3711691,999.777282714844,999.777282714844,62.6021913622374,20.8336448083984,4.781127,0,0,0,80,4882,15.34725,999.777282714844,,,,,,,,,,,,,0,,,,0.72030785,,,,,,15.36875155,,,,
,2362803.995,15.71073915,999.777282714844,0.00419211852081184,2.39220221850393E-7,1,1.99850670813958,40.0298881530762,1.98355564937174,20.1399996876717,0.0470568016183454,0.00857349303756184,0.25,2.80591794535511E-5,0.00416961309962058,4.83153629556254E-5,15.7097578,15.7117205,999.777282714844,999.777282714844,62.4489921724681,20.8338792279076,5.154188,0,0,0,80,4882,15.69385,999.777282714844,,,,,,,,,,,,,0,,,,0.7311736,,,,,,15.71073915,,,,
,2363113.77,16.22465515,999.777282714844,0.00415832975736971,3.06508069921484E-7,1,1.99850670813958,40.0298881530762,1.98349188626088,20.1399996876717,0.0466766091568612,0.00850071005936038,0.25,2.75300070850775E-5,0.00413600035520095,4.76244623244958E-5,16.2238579,16.2254524,999.777282714844,999.777282714844,62.6592502441412,20.8334637604873,5.154188,0,0,0,80,4882,16.20775,999.777282714844,,,,,,,,,,,,,0,,,,0.73484405,,,,,,16.22465515,,,,
,2363323.645,16.57011315,999.777282714844,0.00413650816633104,2.52852670329212E-7,1,1.99850670813958,40.0298881530762,1.98390391486389,20.1399996876717,0.0464400628949599,0.00846202798550145,0.25,2.77646735722526E-5,0.00411428935513547,4.77516008171893E-5,16.5678253,16.572401,999.777282714844,999.777282714844,62.7264702967951,20.8388778613857,4.781127,0,0,0,80,4882,16.5601,999.777282714844,,,,,,,,,,,,,0,,,,0.7459292,,,,,,16.57011315,,,,
,2363531.425,16.9163685,999.777282714844,0.00411414211376654,2.46349147073919E-7,1,1.99850670813958,40.0298881530762,1.9956276007829,20.1399996876717,0.0464477442542673,0.00847112863502618,0.25,2.82747629346362E-5,0.00409203537129375,4.81500392795282E-5,16.9139309,16.9188061,999.777282714844,999.777282714844,62.9390732540259,20.8394271357621,4.781127,0,0,0,80,4882,16.9084,999.777282714844,,,,,,,,,,,,,0,,,,0.7534183,,,,,,16.9163685,,,,
,2363835.22,17.42560295,999.777282714844,0.00408249290988153,2.39892715745172E-7,1,1.99850670813958,40.0298881530762,1.99553306251593,20.1399996876717,0.0460884013989383,0.00840420018210398,0.25,2.79485339635535E-5,0.00406054038557937,4.76607713282357E-5,17.4235783,17.4276276,999.777282714844,999.777282714844,62.963303738122,20.8396949460258,4.781127,0,0,0,80,4882,17.4124,999.777282714844,,,,,,,,,,,,,0,,,,0.7648026,,,,,,17.42560295,,,,
,2364043.095,17.7710972,999.777282714844,0.0040630656248681,2.29523080593791E-7,1,1.99850670813958,40.0298881530762,1.99518881894674,20.1299991458654,0.0458624960458293,0.0083572495212595,0.25,2.7318408069894E-5,0.00404121787335384,4.69429432285357E-5,17.7690411,17.7731533,999.777282714844,999.777282714844,62.3598865212758,20.8406301803578,5.154188,0,0,0,80,4882,17.76535,999.777282714844,,,,,,,,,,,,,0,,,,0.7648026,,,,,,17.7710972,,,,
,2364250.96,18.115778,999.777282714844,0.0040426765519571,2.71980171195274E-7,1,1.99850670813958,40.0298881530762,1.99573248378319,20.1299991458654,0.0456433400625126,0.00832242213134954,0.25,2.76122577635146E-5,0.00402093711544416,4.71429462960003E-5,18.1140404,18.1175156,999.777282714844,999.777282714844,62.6772277000835,20.8391122188196,5.154188,0,0,0,80,4882,18.1074,999.777282714844,,,,,,,,,,,,,0,,,,0.7763397,,,,,,18.115778,,,,
,2364558.615,18.62897395,999.777282714844,0.00401354576314124,2.90227671181725E-7,1,1.99850670813958,40.0298881530762,1.99551897250779,20.1299991458654,0.0453091676601917,0.0082658043763817,0.25,2.7766102867907E-5,0.00399196796048749,4.71711921301649E-5,18.6275234,18.6304245,999.777282714844,999.777282714844,62.7319416964297,20.8391805637808,5.154188,0,0,0,80,4882,18.6197,999.777282714844,,,,,,,,,,,,,0,,,,0.7763397,,,,,,18.62897395,,,,
,2364766.57,18.9718199,999.777282714844,0.00399438649550766,3.21993350776345E-7,1,1.99850670813958,40.0298881530762,2.00838749598934,20.1200004667044,0.0453701462582466,0.0082752964446611,0.25,2.74783127254587E-5,0.0039729209182502,4.68077681618202E-5,18.9707489,18.9728909,999.777282714844,999.777282714844,62.8624736591413,20.8386476880148,4.408067,0,0,0,80,4882,18.9683,999.777282714844,,,,,,,,,,,,,0,,,,0.78807035,,,,,,18.9718199,,,,
,2364974.335,19.31935975,999.777282714844,0.00397587231814675,2.36195741874394E-7,1,1.99850670813958,40.0298881530762,1.99577966845769,20.1200004667044,0.044890310086619,0.00818570342558366,0.25,2.71534930611425E-5,0.00395451859201838,4.64141767691911E-5,19.3175926,19.3211269,999.777282714844,999.777282714844,62.6529972159874,20.8375914221777,4.781127,0,0,0,80,4882,19.315,999.777282714844,,,,,,,,,,,,,0,,,,0.7959825,,,,,,19.31935975,,,,
,2365200.2,19.6596966,999.777282714844,,,2,,,,20.1359999019504,,,,,,,19.6596966,19.6596966,999.777282714844,999.777282714844,,,5.154188,,,,-99999999,4882,19.712,999.777282714844,,,,,,,,,,,,,,,,,,,,,,,19.6596966,,,,
,2365591.795,22.8378067,999.777282714844,0.00379948387089756,2.77454002668897E-7,1,1.99850670813958,40.0298881530762,1.99567295980015,20.1200004667044,0.0428984534383467,0.00783297508664804,0.25,2.64144136372788E-5,0.00377939516393248,4.5252830135663E-5,22.8133507,22.8622627,999.777282714844,999.777282714844,62.9578323384874,20.8402314649868,4.781127,0,0,0,80,4882,23.02045,999.777282714844,,,,,,,,,,,,,0,,,,0.83261305,,,,,,22.8378067,,,,
touchdown = 14.9600002914667 mm,2365836.275,28.8894615,999.777282714844,0.00353552851090802,2.50025161924289E-7,1,1.99850670813958,40.0298881530762,1.99556595724224,20.1099999248981,0.0399283970720998,0.00731329863235317,0.25,2.4953295760446E-5,0.00351823934943095,4.40561728978952E-5,28.8894615,28.8894615,999.777282714844,999.777282714844,62.8265187472567,20.832159400429,4.781127,0,0,0,80,4882,29.1825,999.777282714844,,,,,,,,,,,,,0,,,,0.8928764,,,,,,28.8894615,,,,
,2366051.555,34.1951599,999.777282714844,0.00331819153994108,2.07195965793968E-7,1,1.99850670813958,40.0298881530762,1.99603841691264,20.1099999248981,0.0375051479009024,0.00689236352737203,0.25,2.33501166029116E-5,0.00330430575485193,4.33301077158737E-5,34.167717,34.2226028,999.777282714844,999.777282714844,62.8476227172759,20.836683026006,5.154188,0,0,0,80,4882,34.6238,999.777282714844,,,,,,,,,,,,,0,,,,0.9339426,,,,,,34.1951599,,,,
,2366281.815,39.886343,999.777282714844,0.00310278148288979,2.06861961061011E-7,1,1.99850670813958,40.0298881530762,1.99555285075716,20.0900007039309,0.0351003124102373,0.00647655114210061,0.25,2.18295985213208E-5,0.0030935302075072,4.27937174305429E-5,39.8740425,39.8986435,999.777282714844,999.777282714844,62.3630130353528,20.8320462411458,4.781127,0,0,0,80,4882,40.44505,999.777282714844,,,,,,,,,,,,,0,,,,0.98177705,,,,,,39.886343,,,,
,2366623.195,48.298954,999.777282714844,0.00280405958393422,1.70233652610886E-7,1,1.99850670813958,40.0298881530762,1.9958550834691,20.0900007039309,0.0318014149973928,0.00588974135344344,0.25,1.98158474557243E-5,0.00280269923167566,4.06362045705698E-5,48.273571,48.324337,999.777282714844,999.777282714844,62.5928118200066,20.8363334974156,5.154188,0,0,0,80,4882,49.0842,999.777282714844,,,,,,,,,,,,,0,,,,1.04242335,,,,,,48.298954,,,,
,2366852.915,53.94932365,999.777282714844,0.00260719302496633,1.85547581855687E-7,1,1.99850670813958,40.0298881530762,1.98484398322286,20.0699996203184,0.0294670737163154,0.00544870044036381,0.25,1.79940670730397E-5,0.00261057398598871,3.71041577927908E-5,53.9339294,53.9647179,999.777282714844,999.777282714844,62.648307444872,20.8294638317441,4.781127,0,0,0,80,4886,54.9035,999.777282714844,,,,,,,,,,,,,0,,,,1.0795023,,,,,,53.94932365,,,,
,2367368.455,56.99796295,999.777282714844,0.00249691157817246,1.73320563659553E-7,1,1.99850670813958,40.0298881530762,1.99613097621754,20.0800001621246,0.0283916862171574,0.00524026302329621,0.25,1.67823965872495E-5,0.00250160443628169,3.47381534698787E-5,56.9978828,56.9980431,999.777282714844,999.777282714844,62.7514824094105,20.8402868036865,4.781127,0,0,0,80,4881,57.0176,999.777282714844,,,,,,,,,,,,,0,,,,1.1012875,,,,,,56.99796295,,,,
,2367482.34,59.0625744,999.777282714844,0.00243909802019074,2.0490917551619E-7,1,1.99850670813958,40.0298881530762,1.99607773292287,20.0800001621246,0.0277578624113881,0.00511107705967863,0.25,1.6054347536878E-5,0.00244564263804277,3.29212109344589E-5,59.0349541,59.0901947,999.777282714844,999.777282714844,62.7061479552951,20.8385033634427,5.154188,0,0,0,80,4886,60.1163,999.777282714844,,,,,,,,,,,,,0,,,,1.1123443,,,,,,59.0625744,,,,
,2367725.66,65.0245361,999.777282714844,0.00226078735058517,2.23217783892857E-7,1,1.99850670813958,40.0298881530762,1.99621976328659,20.0800001621246,0.025768055513824,0.00471236162285552,0.25,1.37546881373265E-5,0.0022697040215345,2.77974284824111E-5,65.0245361,65.0245361,999.777282714844,999.777282714844,62.9859709651797,20.8363439646042,4.781127,0,0,0,80,4886,66.30965,999.777282714844,,,,,,,,,,,,,0,,,,1.14048875,,,,,,65.0245361,,,,
,2367885.45,68.9534378,999.777282714844,0.00215210648756453,1.90850067724006E-7,1,1.99850670813958,40.0298881530762,1.99629928175286,20.0399998575449,0.0245483038459746,0.00446920303339406,0.25,1.24576315315822E-5,0.00216189146105701,2.47640961401121E-5,68.9534378,68.9534378,999.777282714844,999.777282714844,62.6006281051989,20.8373002923136,5.154188,0,0,0,80,4886,70.3666,999.777282714844,,,,,,,,,,,,,0,,,,1.157693,,,,,,68.9534378,,,,
,2368049.945,72.9873161,999.777282714844,0.00204417363978543,1.89148483643319E-7,1,1.99850670813958,40.0298881530762,1.99565934951316,20.0399998575449,0.0233241621443103,0.0042265782297666,0.25,1.11623753444163E-5,0.00205442527096865,2.18479289065634E-5,72.9620132,73.012619,999.777282714844,999.777282714844,62.4833838273143,20.8340284067182,5.154188,0,0,0,80,4886,74.55365,999.777282714844,,,,,,,,,,,,,0,,,,1.1693162,,,,,,72.9873161,,,,
,2368243.38,77.7279739,999.777282714844,,,2,,,,20.0260004613399,,,,,,,77.7279739,77.7279739,999.777282714844,999.777282714844,,,4.781127,,,,-99999999,4886,79.4633,999.777282714844,,,,,,,,,,,,,,,,,,,,,,,77.7279739,,,,
,2368453.595,82.92152785,999.777282714844,0.00180914707811868,2.02243931755967E-7,1,1.99850670813958,40.0298881530762,1.98436984427383,20.0100000947714,0.0205511117179557,0.00368637554200541,0.25,8.52034697323662E-6,0.00181943493200487,1.61162362827412E-5,82.8907089,82.9523468,999.777282714844,999.777282714844,62.5404427092182,20.8274947216006,5.154188,0,0,0,80,4886,84.7851,999.777282714844,,,,,,,,,,,,,0,,,,1.2048905,,,,,,82.92152785,,,,
,2368617.52,86.96504595,999.777282714844,0.00172368596616387,1.99272929700926E-7,1,1.99850670813958,40.0298881530762,1.98486861754237,20.0100000947714,0.019589632938915,0.00350266461665651,0.25,7.74298793542441E-6,0.0017337330952708,1.43927715858338E-5,86.9524384,86.9776535,999.777282714844,999.777282714844,62.6834807282374,20.8291748826842,5.154188,0,0,0,80,4886,88.9376,999.777282714844,,,,,,,,,,,,,0,,,,1.229206,,,,,,86.96504595,,,,
,2368777.345,90.9156189,999.777282714844,0.00164690174833672,2.02156568305781E-7,1,1.99850670813958,40.0298881530762,1.9964515272325,19.9699997901917,0.0188245763956105,0.00335493044450436,0.25,6.94914976766105E-6,0.00165665019285436,1.28197127361897E-5,90.9018021,90.9294357,999.777282714844,999.777282714844,62.9148427699297,20.8378830807623,4.781127,0,0,0,80,4886,92.97555,999.777282714844,,,,,,,,,,,,,0,,,,1.229206,,,,,,90.9156189,,,,
,2369017.165,96.8435173,999.777282714844,0.00153849549863633,2.10990972952548E-7,1,1.99850670813958,40.0298881530762,1.99648498455386,19.9699997901917,0.0175892187997583,0.00312106884882802,0.25,5.90618966012193E-6,0.00154770912583584,1.08084994939826E-5,96.8295975,96.8574371,999.777282714844,999.777282714844,62.7475742668143,20.8401074690429,4.781127,0,0,0,80,4886,99.0379,999.777282714844,,,,,,,,,,,,,0,,,,1.2540121,,,,,,96.8435173,,,,
,2369179.08,100.8551712,999.777282714844,0.00147172763694636,1.88816670864028E-7,1,1.99850670813958,40.0298881530762,1.9959412795181,19.9400000274181,0.0168229003208559,0.00297797679087086,0.25,5.3656516549615E-6,0.00148055998773969,9.73243318400383E-6,100.8407822,100.8695602,999.777282714844,999.777282714844,62.7546089234874,20.8298557328456,4.781127,0,0,0,80,4886,103.135,999.777282714844,,,,,,,,,,,,,0,,,,1.2540121,,,,,,100.8551712,,,,
,2369340.98,104.87503435,999.777282714844,0.00140867261007686,2.05023819183909E-7,1,1.99850670813958,40.0298881530762,1.99657167321308,19.9400000274181,0.0161074634575036,0.00284757011114804,0.25,5.08907391631421E-6,0.00141711426402361,8.99454737337637E-6,104.8493958,104.9006729,999.777282714844,999.777282714844,63.0000402785259,20.8285328523792,5.154188,0,0,0,80,4886,107.25435,999.777282714844,,,,,,,,,,,,,0,,,,1.27296055,,,,,,104.87503435,,,,
,2369524,109.4339409,999.777282714844,0.00134377327630558,1.94723243883987E-7,1,1.99850670813958,40.0298881530762,1.99669300576786,19.8999997228384,0.0153671996567285,0.00270824815522389,0.25,4.39621037278396E-6,0.00135178560284312,7.8586938968247E-6,109.4043503,109.4635315,999.777282714844,999.777282714844,63.0062933066797,20.8319699131258,5.154188,0,0,0,80,4886,111.9047,999.777282714844,,,,,,,,,,,,,0,,,,1.2793188,,,,,,109.4339409,,,,
,2369738.65,114.7787476,999.777282714844,0.00127155355032786,1.83537812182721E-7,1,1.99850670813958,40.0298881530762,1.99676922307801,19.8999997228384,0.0145424675043133,0.00255400125733336,0.25,3.65309370634262E-6,0.00127906159427281,6.67662443618565E-6,114.749939,114.8075562,999.777282714844,999.777282714844,62.6623767582182,20.8336777173847,5.154188,0,0,0,80,4886,117.3239,999.777282714844,,,,,,,,,,,,,0,,,,1.3051363,,,,,,114.7787476,,,,
,2369900.455,118.824234,999.777282714844,0.00122108406075087,1.81616102283655E-7,1,1.99850670813958,40.0298881530762,1.9967708994909,19.8999997228384,0.0139648086985962,0.00245054197117837,0.25,3.49714541180537E-6,0.00122822426577444,6.23986285267438E-6,118.7997742,118.8486938,999.777282714844,999.777282714844,62.8757613439682,20.8349678371605,4.781127,0,0,0,80,4886,121.44775,999.777282714844,,,,,,,,,,,,,0,,,,1.3051363,,,,,,118.824234,,,,
,2370060.4,122.81191255,999.777282714844,0.00117519372165725,1.96978754394403E-7,1,1.99850670813958,40.0298881530762,1.99682939526195,19.8500007390976,0.0134400500469923,0.00235508050766669,0.25,3.21516914631606E-6,0.00118198892910864,5.7168378618061E-6,122.7993393,122.8244858,999.777282714844,999.777282714844,62.5529487655258,20.8264899494246,4.781127,0,0,0,80,4886,125.5069,999.777282714844,,,,,,,,,,,,,0,,,,1.3314749,,,,,,122.81191255,,,,
,2370298.195,128.74662015,999.777282714844,0.00111077854337152,1.52495198240218E-7,1,1.99850670813958,40.0298881530762,1.99690941519366,19.8500007390976,0.0127032742078516,0.00222097770603877,0.25,2.78255007292446E-6,0.00111707765174393,4.97638202591691E-6,128.7159576,128.7772827,999.777282714844,999.777282714844,62.6741011860066,20.8278982808649,4.781127,0,0,0,80,4886,131.50655,999.777282714844,,,,,,,,,,,,,0,,,,1.3448428,,,,,,128.74662015,,,,
,2370456.19,132.6980972,999.777282714844,0.00107213737462896,2.155559622767E-7,1,1.99850670813958,40.0298881530762,1.99697944664635,19.8100004345179,0.0122612482544522,0.0021408040870562,0.25,2.53640805723646E-6,0.00107812950383126,4.55611114787029E-6,132.6815948,132.7145996,999.777282714844,999.777282714844,63.0977438434298,20.8343814689444,5.154188,0,0,0,80,4886,135.5199,999.777282714844,,,,,,,,,,,,,0,,,,1.3448428,,,,,,132.6980972,,,,
,2370618.025,136.7537079,999.777282714844,0.00103383838153629,2.05455933902202E-7,1,1.99850670813958,40.0298881530762,1.99681093562202,19.8100004345179,0.0118214695903461,0.00206263275927098,0.25,2.41417018768175E-6,0.00103952325478274,4.27465850272205E-6,136.7264252,136.7809906,999.777282714844,999.777282714844,62.3583232642374,20.8232019782222,5.154188,0,0,0,80,4886,139.61075,999.777282714844,,,,,,,,,,,,,0,,,,1.35159385,,,,,,136.7537079,,,,
,2370776.79,140.73872375,999.777282714844,0.000999853335822835,2.03166589595021E-7,1,1.99850670813958,40.0298881530762,1.99713164087473,19.7599995881319,0.0114341466733977,0.00199147460507206,0.25,2.10592681644777E-6,0.00100525811275649,3.82851990345162E-6,140.7232666,140.7541809,999.777282714844,999.777282714844,62.5787425066605,20.8222932606448,5.154188,0,0,0,80,4886,143.63,999.777282714844,,,,,,,,,,,,,0,,,,1.3719826,,,,,,140.73872375,,,,
,2371013.86,146.66002655,999.777282714844,0.000950993576492276,2.18971833071898E-7,1,1.99850670813958,40.0298881530762,1.99693034287276,19.7599995881319,0.0108739354931141,0.00188684328523721,0.25,1.49890038794363E-6,0.000955995089583708,3.03842593949555E-6,146.6329346,146.6871185,999.777282714844,999.777282714844,62.6100076474297,20.8227808740998,5.154188,0,0,0,80,4886,149.61955,999.777282714844,,,,,,,,,,,,,0,,,,1.3857572,,,,,,146.66002655,,,,
touchdown = 14.5699996501207 mm,2371190.765,151.0695343,999.777282714844,0.000917105720244247,1.84925298125302E-7,1,1.99850670813958,40.0298881530762,1.99714249711305,19.7199992835522,0.0104856730683271,0.0018232852765227,0.25,1.83046477688643E-6,0.00092182266815708,3.25523114580133E-6,151.0695343,151.0695343,999.777282714844,999.777282714844,62.5083959399297,20.8210917655398,5.154188,0,0,0,80,4886,154.06635,999.777282714844,,,,,,,,,,,,,0,,,,1.3857572,,,,,,151.0695343,,,,
,2371333.5,154.6562805,999.777282714844,0.000891400810585202,1.89335721926507E-7,1,1.99850670813958,40.0298881530762,1.99731240679867,19.7199992835522,0.0101926071692146,0.00176639208093309,0.25,1.3191637231333E-6,0.000895899615143373,2.65737101665762E-6,154.6305847,154.6819763,999.777282714844,999.777282714844,62.6756644430451,20.8244609261857,4.781127,0,0,0,80,4886,157.60565,999.777282714844,,,,,,,,,,,,,0,,,,1.39967,,,,,,154.6562805,,,,
,2371586.67,160.9463654,999.777282714844,,,2,,,,19.6859997350574,,,,,,,160.9463654,160.9463654,999.777282714844,999.777282714844,,,5.154188,,,,-99999999,4886,163.9986,999.777282714844,,,,,,,,,,,,,,,,,,,,,,,160.9463654,,,,
,2371731.055,164.5692673,999.777282714844,0.000824942294612519,1.76889400765435E-7,1,1.99850670813958,40.0298881530762,1.99696680097608,19.6700002998114,0.009428918208117,0.0016315391901008,0.25,1.10910873563774E-6,0.000828873878065787,2.24479771914929E-6,164.5421753,164.5963593,999.777282714844,999.777282714844,62.6459625593143,20.8194501625005,4.781127,0,0,0,80,4886,167.6182,999.777282714844,,,,,,,,,,,,,0,,,,1.4066963,,,,,,164.5692673,,,,
,2371893,168.60056305,999.777282714844,0.000800385428950811,1.80262282066794E-7,1,1.99850670813958,40.0298881530762,1.99731782549538,19.6700002998114,0.00914903612276999,0.00158098629636247,0.25,9.30532097384214E-7,0.000804104582365723,1.99651643205641E-6,168.5850983,168.6160278,999.777282714844,999.777282714844,62.607662761872,20.8220895308295,5.154188,0,0,0,80,4886,171.6525,999.777282714844,,,,,,,,,,,,,0,,,,1.4137226,,,,,,168.60056305,,,,
,2372055.23,172.62727355,999.777282714844,0.000777423691406829,1.93202246419194E-7,1,1.99850670813958,40.0298881530762,1.99768346827964,19.6199994534254,0.00888744290424561,0.00153334830685767,0.25,7.29116919191357E-7,0.00078094170376178,1.73134174280523E-6,172.6101532,172.6443939,999.777282714844,999.777282714844,62.6443993022759,20.8181543422858,4.781127,0,0,0,80,4886,175.7457,999.777282714844,,,,,,,,,,,,,0,,,,1.4279163,,,,,,172.62727355,,,,
,2372290.65,178.5187683,999.777282714844,0.000745693745771845,1.95083859436627E-7,1,1.99850670813958,40.0298881530762,1.99747532369368,19.6199994534254,0.00852235426764071,0.00147010681863097,0.25,7.18692282969441E-7,0.000748931943491968,1.63879947165419E-6,178.4946136,178.542923,999.777282714844,999.777282714844,63.0023851640836,20.8180191675652,5.154188,0,0,0,80,4886,181.64955,999.777282714844,,,,,,,,,,,,,0,,,,1.4350844,,,,,,178.5187683,,,,
,2372450.54,182.4845276,999.777282714844,0.000725558049633472,2.34410269360329E-7,1,1.99850670813958,40.0298881530762,2.00956677224034,19.5700004696846,0.00833930201993699,0.00143658015781909,0.25,5.59320784878654E-7,0.000728617831895104,1.42887870182963E-6,182.4584198,182.5106354,999.777282714844,999.777282714844,62.5959383340835,20.8183101845648,4.781127,0,0,0,80,4886,185.63625,999.777282714844,,,,,,,,,,,,,0,,,,1.4422525,,,,,,182.4845276,,,,
,2372612.445,186.5417862,999.777282714844,0.000706274901726397,2.08154592516156E-7,1,1.99850670813958,40.0298881530762,1.9968759496237,19.5700004696846,0.00806785054894551,0.00138947588486179,0.25,5.38777266625024E-7,0.000709161155977153,1.36149708235526E-6,186.5279846,186.5555878,999.777282714844,999.777282714844,62.4802573132374,20.8190618105109,5.154188,0,0,0,80,4886,189.7474,999.777282714844,,,,,,,,,,,,,0,,,,1.4422525,,,,,,186.5417862,,,,
,2372840.53,192.2103577,999.777282714844,,,2,,,,19.5359999898672,,,,,,,192.2103577,192.2103577,999.777282714844,999.777282714844,,,5.154188,,,,-99999999,4886,195.433,999.777282714844,,,,,,,,,,,,,,,,,,,,,,,192.2103577,,,,
,2373010.07,196.4743118,999.777282714844,0.000662856409055715,2.0083291717615E-7,1,1.99850670813958,40.0298881530762,1.99753657381975,19.5199996232986,0.00757229669747685,0.00130107945213319,0.25,2.9446111041904E-7,0.000665348106668238,1.0170691681157E-6,196.4483032,196.5003204,999.777282714844,999.777282714844,62.7374130960643,20.8222641001138,5.154188,0,0,0,80,4886,199.69645,999.777282714844,,,,,,,,,,,,,0,,,,1.47874425,,,,,,196.4743118,,,,
,2373171.99,200.48236085,999.777282714844,0.000647009886427871,2.13319897350572E-7,1,1.99850670813958,40.0298881530762,1.99688162985868,19.5199996232986,0.00738841186825153,0.00126680443864716,0.25,7.70943899280208E-8,0.000649354752618487,7.6384285256349E-7,200.4558716,200.5088501,999.777282714844,999.777282714844,62.7507007808913,20.8191151075656,4.781127,0,0,0,80,4886,203.805,999.777282714844,,,,,,,,,,,,,0,,,,1.4861304,,,,,,200.48236085,,,,
,2373331.86,204.4906998,999.777282714844,0.000631605979850343,2.35926009246562E-7,1,1.99850670813958,40.0298881530762,1.99730662163082,19.4700006395578,0.00721291528604299,0.00123714834082108,0.25,1.2788542794951E-7,0.000633808465415338,7.82623274613031E-7,204.463028,204.5183716,999.777282714844,999.777282714844,62.4607166002566,20.8175690005608,4.781127,0,0,0,80,4886,207.75105,999.777282714844,,,,,,,,,,,,,0,,,,1.49359075,,,,,,204.4906998,,,,
,2373569.68,210.42799375,999.777282714844,0.000609841746233837,2.00431682858198E-7,1,1.99850670813958,40.0298881530762,1.99651397950846,19.4700006395578,0.00695969614027277,0.00119740814356467,0.25,4.59365086750443E-7,0.000611842750781469,1.07073264207614E-6,210.3985443,210.4574432,999.777282714844,999.777282714844,62.5623283077566,20.8238627488311,5.154188,0,0,0,80,4886,213.7589,999.777282714844,,,,,,,,,,,,,0,,,,1.4713581,,,,,,210.42799375,,,,
,2373727.515,214.37505345,999.777282714844,0.000596183599026417,2.03703414936414E-7,1,1.99850670813958,40.0298881530762,1.99659467211924,19.4099992513657,0.00680397454444499,0.00116565838024919,0.25,4.01439889647042E-8,0.000598057787072003,6.23283098242903E-7,214.3518372,214.3982697,999.777282714844,999.777282714844,62.780402664622,20.823465145544,5.154188,0,0,0,80,4886,217.6874,999.777282714844,,,,,,,,,,,,,0,,,,1.49359075,,,,,,214.37505345,,,,
,2373891.36,218.4083786,999.777282714844,0.000582935753750176,1.74661116318169E-7,1,1.99850670813958,40.0298881530762,1.99652702074424,19.4099992513657,0.00665141381205633,0.00114078317473022,0.25,1.59620910634461E-7,0.0005846851759523,7.17074764714132E-7,218.396637,218.4201202,999.777282714844,999.777282714844,63.0016035355644,20.8273677579379,5.154188,0,0,0,80,4886,221.8625,999.777282714844,,,,,,,,,,,,,0,,,,1.4861304,,,,,,218.4083786,,,,
,2374093.08,223.4696198,999.777282714844,,,2,,,,19.3759997028708,,,,,,,223.4696198,223.4696198,999.777282714844,999.777282714844,,,4.781127,,,,-99999999,4886,226.8205,999.777282714844,,,,,,,,,,,,,,,,,,,,,,,223.4696198,,,,
,2374289.06,228.3177719,999.777282714844,0.000552238936857577,1.95888060150944E-7,1,1.99850670813958,40.0298881530762,1.99660744739829,19.3600002676249,0.00629994987115662,0.00107580832914296,0.25,-2.21425909829602E-7,0.000553700602729774,2.78147296747214E-7,228.2917328,228.343811,999.777282714844,999.777282714844,62.6014097337182,20.8276042697071,5.154188,0,0,0,80,4886,231.85465,999.777282714844,,,,,,,,,,,,,0,,,,1.5010511,,,,,,228.3177719,,,,
,2374450.945,232.35930635,999.777282714844,0.000540315607098172,1.79421051334904E-7,1,1.99850670813958,40.0298881530762,1.99683439394561,19.3600002676249,0.00616347239178268,0.00105383969732583,0.25,-9.28358516786538E-8,0.000541666421412627,3.86259138666227E-7,232.3325806,232.3860321,999.777282714844,999.777282714844,62.228572930045,20.824298186027,5.154188,0,0,0,80,4886,235.8625,999.777282714844,,,,,,,,,,,,,0,,,,1.5010511,,,,,,232.35930635,,,,
,2374610.9,236.32647705,999.777282714844,0.000529460064049796,2.09711668942044E-7,1,1.99850670813958,40.0298881530762,1.99705230696743,19.3099994212389,0.00603950355034554,0.00103200540531406,0.25,-1.35890385724542E-7,0.000530707177549838,3.23980141004842E-7,236.2995605,236.3533936,999.777282714844,999.777282714844,62.8679450587759,20.8202627035089,4.781127,0,0,0,80,4886,239.8944,999.777282714844,,,,,,,,,,,,,0,,,,1.5313432,,,,,,236.32647705,,,,
,2374848.645,242.2652893,999.777282714844,0.000513911469400039,1.86285727490072E-7,1,1.99850670813958,40.0298881530762,1.99677065212705,19.3099994212389,0.00586062455615397,0.000998158327778267,0.25,-3.98529666636082E-7,0.000515010109382345,3.42312680175177E-8,242.2410583,242.2895203,999.777282714844,999.777282714844,62.8562206309874,20.822885880996,5.154188,0,0,0,80,4886,245.87935,999.777282714844,,,,,,,,,,,,,0,,,,1.5390305,,,,,,242.2652893,,,,
,2375008.49,246.2400055,999.777282714844,0.000504328833432446,2.18601411255197E-7,1,1.99850670813958,40.0298881530762,2.00926000435852,19.2399993538857,0.00578408053296826,0.000989141627859827,0.25,-4.22103655833018E-8,0.000505332659949721,3.74857819670979E-7,246.2111511,246.2688599,999.777282714844,999.777282714844,62.5779608781412,20.8293322018835,4.781127,0,0,0,80,4886,249.975,999.777282714844,,,,,,,,,,,,,0,,,,1.5390305,,,,,,246.2400055,,,,
,2375172.395,250.28957365,999.777282714844,0.000494847441835601,2.32354725469774E-7,1,1.99850670813958,40.0298881530762,1.99665439623765,19.2399993538857,0.0056405390664218,0.000964849739960486,0.25,-1.19270040838007E-8,0.000495758014248003,3.89555341594144E-7,250.2636871,250.3154602,999.777282714844,999.777282714844,62.5677997073912,20.8288174443721,5.154188,0,0,0,80,4886,254.0071,999.777282714844,,,,,,,,,,,,,0,,,,1.5467178,,,,,,250.28957365,,,,
,2375365.375,255.16459655,999.777282714844,0.000483543303600779,2.24604820806693E-7,1,1.99850670813958,40.0298881530762,1.99651475905078,19.1799998283386,0.00551101408968006,0.000938527906755257,0.25,-3.58112686676947E-7,0.000484345512109126,2.48347805973293E-8,255.14888,255.1803131,999.777282714844,999.777282714844,62.4872919699105,20.8268757202132,4.781127,0,0,0,80,4886,258.8358,999.777282714844,,,,,,,,,,,,,0,,,,1.5390305,,,,,,255.16459655,,,,
,2375568.075,260.1827545,999.777282714844,0.000472257235754431,2.18043784311306E-7,1,1.99850670813958,40.0298881530762,1.99651851235005,19.1799998283386,0.0053818481969961,0.000913751545143912,0.25,-5.78101608421846E-7,0.000472952270788228,-2.13133281057015E-7,260.1697998,260.1957092,999.777282714844,999.777282714844,62.4849470843528,20.8267066392766,5.154188,0,0,0,80,4886,263.98185,999.777282714844,,,,,,,,,,,,,0,,,,1.5467178,,,,,,260.1827545,,,,
,2375729.985,264.246048,999.777282714844,0.00046331290641421,2.66998917314168E-7,1,1.99850670813958,40.0298881530762,1.99642253045546,19.1799998283386,0.00527834754322373,0.000899339198649179,0.25,-2.91157255211061E-7,0.000463923924752803,6.08996588260908E-8,264.2171631,264.2749329,999.777282714844,999.777282714844,62.5037061688143,20.8262683703812,4.781127,0,0,0,80,4886,267.9862,999.777282714844,,,,,,,,,,,,,0,,,,1.5700891,,,,,,264.246048,,,,
,2375889.89,268.2415924,999.777282714844,0.000455434408325169,2.2496192923945E-7,1,1.99850670813958,40.0298881530762,2.00945815212594,19.1200003027916,0.00521984319959505,0.000890707106717201,0.25,-1.66816588466792E-7,0.000455966537302634,1.73264082606172E-7,268.2113342,268.2718506,999.777282714844,999.777282714844,62.4325779735643,20.8197859865862,5.154188,0,0,0,80,4886,272.0146,999.777282714844,,,,,,,,,,,,,0,,,,1.5622467,,,,,,268.2415924,,,,
,2376127.71,274.1190491,999.777282714844,0.000443864422695863,2.42030006357408E-7,1,1.99850670813958,40.0298881530762,1.99715801440655,19.1200003027916,0.00505687346538305,0.00086041472835713,0.25,-3.65918037179859E-7,0.000444284925423413,-4.32078375785529E-8,274.0885315,274.1495667,999.777282714844,999.777282714844,62.4849470843528,20.821839029741,5.154188,0,0,0,80,4886,277.99165,999.777282714844,,,,,,,,,,,,,0,,,,1.5700891,,,,,,274.1190491,,,,
,2376285.54,278.10458375,999.777282714844,0.000436277964673214,2.03027933665349E-7,1,1.99850670813958,40.0298881530762,1.99715706859594,19.0699994564056,0.00496882690103859,0.000850647866149392,0.25,9.03406933127157E-8,0.000436625353660483,4.02742301533824E-7,278.0762329,278.1329346,999.777282714844,999.777282714844,62.3192418382758,20.8208632733242,5.154188,0,0,0,80,4886,281.82815,999.777282714844,,,,,,,,,,,,,0,,,,1.5700891,,,,,,278.10458375,,,,
,2376447.39,282.13238525,999.777282714844,0.000429325574119678,2.08877213642622E-7,1,1.99850670813958,40.0298881530762,1.99716359359626,19.0699994564056,0.00488938577320452,0.000834230671407822,0.25,-1.4627095263647E-7,0.000429602341252377,1.55765071869271E-7,282.0994568,282.1653137,999.777282714844,999.777282714844,62.4099107465066,20.8183534625261,4.781127,0,0,0,80,4886,285.8643,999.777282714844,,,,,,,,,,,,,0,,,,1.5779315,,,,,,282.13238525,,,,
,2376622.29,286.44541935,999.777282714844,0.000421385587450964,2.26067444600883E-7,1,1.99850670813958,40.0298881530762,1.99737100989859,19.0099999308586,0.00479855220686804,0.000819353566306277,0.25,-8.50729939060334E-8,0.000421588630635168,2.05873265781274E-7,286.4292908,286.4615479,999.777282714844,999.777282714844,62.3387825512566,20.8150851051471,5.154188,0,0,0,80,4886,290.3911,999.777282714844,,,,,,,,,,,,,0,,,,1.58585265,,,,,,286.44541935,,,,
,2376847.095,292.06817625,999.777282714844,0.000411684372581247,2.44408208600729E-7,1,1.99850670813958,40.0298881530762,1.99736128158111,19.0099999308586,0.00468721772161947,0.00079941480104381,0.25,-1.55913353248011E-7,0.000411795481720948,1.21835883445123E-7,292.0420227,292.0943298,999.777282714844,999.777282714844,62.3763007201797,20.8155058170293,5.154188,0,0,0,80,4886,296.0303,999.777282714844,,,,,,,,,,,,,0,,,,1.58585265,,,,,,292.06817625,,,,
touchdown = 13.8100003823638 mm,2377038.1,296.8111267,999.777282714844,0.000404154622992105,2.40475534428325E-7,1,1.99850670813958,40.0298881530762,1.99847240798658,18.9599990844727,0.00460390903653386,0.00078035989341251,0.25,-5.61474553640121E-7,0.000404191758822657,-2.93943239086286E-7,296.8111267,296.8111267,999.777282714844,999.777282714844,62.5193387391989,20.810075345947,5.154188,0,0,0,80,4886,300.7567,999.777282714844,,,,,,,,,,,,,0,,,,1.5937738,,,,,,296.8111267,,,,
,2377370.805,299.77404785,999.777282714844,0.000398226077882542,2.56459024291701E-7,1,1.99850670813958,40.0298881530762,1.99811281549744,18.9599990844727,0.00453472208349022,0.000770837227341875,0.25,-3.64958220406705E-7,0.000398217898939638,-1.01433091909282E-7,299.7711792,299.7769165,999.777282714844,999.777282714844,62.4997980262182,20.8064794622361,5.154188,0,0,0,80,4881,300.8629,999.777282714844,,,,,,,,,,,,,0,,,,1.6097752,,,,,,299.77404785,,,,