File: PPMS Data and Plotting/Data/RuCl3 data/Data/27-01-2025_RUCL3_TB001_0.1T_FC.DAT
[Header]
; VSM Data File (default extension .dat)
; Copyright (c) 2003-2013, Quantum Design, Inc. All rights reserved.
TITLE,
FILEOPENTIME,2377377.33,01/28/2025,7:27 pm
BYAPP,VSM,2.0,2.0
INFO,PPMS VSM Option Release 1.4.10 Build 1,APPNAME
INFO,Quantum Design Linear Motor Servo Controller,MOTOR_MODULE_NAME
INFO,3101-100 M1,MOTOR_HW_VERSION
INFO,MMC920,MOTOR_SERIAL_NUMBER
INFO,SRV No X-over 01.03.11,MOTOR_SOFTWARE_VERSION
INFO,Quantum Design VSM Detection Module,VSM_MODULE_NAME
INFO,3101-150 F0,VSM_HW_VERSION
INFO,VSM672,VSM_SERIAL_NUMBER
INFO,VSM No X-over 01.02.05 May 20 2008 13:51:47,VSM_SOFTWARE_VERSION
INFO,659,PREAMP_SERIAL_NUMBER
INFO,749,COIL_SERIAL_NUMBER
INFO,0,MOMENT_UNITS
INFO,RuCl3,SAMPLE_MATERIAL
INFO,,SAMPLE_COMMENT
INFO,33,SAMPLE_MASS
INFO,,SAMPLE_VOLUME
INFO,,SAMPLE_MOLECULAR_WEIGHT
INFO,,SAMPLE_SIZE
INFO,,SAMPLE_SHAPE
DATATYPE,COMMENT,1
DATATYPE,TIME,2
STARTUPAXIS,X,2
STARTUPAXIS,Y1,5
[Data]
Comment,Time Stamp (sec),Temperature (K),Magnetic Field (Oe),Moment (emu),M. Std. Err. (emu),Transport Action,Averaging Time (sec),Frequency (Hz),Peak Amplitude (mm),Center Position (mm),Coil Signal' (mV),Coil Signal" (mV),Range (mV),M. Quad. Signal (emu),M. Raw' (emu),M. Raw" (emu),Min. Temperature (K),Max. Temperature (K),Min. Field (Oe),Max. Field (Oe),Mass (grams),Motor Lag (deg),Pressure (Torr),VSM Status (code),Motor Status (code),Measure Status (code),Measure Count,PPMS Status (code),System Temp. (K),System Field (Oe),Sample Position (deg),Bridge 1 Resistance (ohms),Bridge 1 Excitation (에),Bridge 2 Resistance (ohms),Bridge 2 Excitation (에),Bridge 3 Resistance (ohms),Bridge 3 Excitation (에),Bridge 4 Resistance (ohms),Bridge 4 Excitation (에),Signal 1 Vin (V),Signal 2 Vin (V),Digital Inputs (code),Drive 1 Iout (mA),Drive 1 Ipower (W),Drive 2 Iout (mA),Drive 2 Ipower (W),Pressure (),Map 20 (),Map 21 (),Map 22 (),Map 23 (),Map 24 (),Map 25 (),Map 26 (),Map 27 (),Map 28 (),Map 29 ()
,2377576.52,299.67774965,999.777282714844,0.000398361366249218,2.42883757149843E-7,1,1.99850670813958,40.0298881530762,1.99801697737297,18.9599990844727,0.00453619043191677,0.000770370194141802,0.25,-4.26754254859168E-7,0.000398354631263915,-1.62634556660517E-7,299.6772461,299.6782532,999.777282714844,999.777282714844,62.7038030697374,20.8089957454843,4.781127,0,0,0,80,4881,300.37805,999.777282714844,,,,,,,,,,,,,0,,,,1.6178562,,,,,,299.67774965,,,,
,2377694.355,297.9701538,999.777282714844,0.000399313869737638,2.71850440170193E-7,1,1.99850670813958,40.0298881530762,1.99792431236624,18.9299993216991,0.00454691219047573,0.000773470255354607,0.25,-3.23406617045316E-7,0.000399332414505408,-5.38415531719897E-8,297.9701538,297.9701538,999.777282714844,999.777282714844,62.7874373212951,20.8060833589023,5.154188,0,0,0,80,4886,295.8492,999.777282714844,,,,,,,,,,,,,0,,,,1.6097752,,,,,,297.9701538,,,,
,2377866.28,293.9153595,999.777282714844,0.000405783729587116,2.27609431625095E-7,1,1.99850670813958,40.0298881530762,1.99787978635972,18.9299993216991,0.00462128152649934,0.000785567716854056,0.25,-3.81059486487823E-7,0.000405864473757187,-1.01960869595459E-7,293.8851929,293.9455261,999.777282714844,999.777282714844,62.4794756847182,20.8060145064134,5.154188,0,0,0,80,4886,291.22825,999.777282714844,,,,,,,,,,,,,0,,,,1.6097752,,,,,,293.9153595,,,,
,2378074.58,288.8609619,999.777282714844,,,2,,,,18.9459996882677,,,,,,,288.8609619,288.8609619,999.777282714844,999.777282714844,,,5.154188,,,,-99999999,4886,285.9013,999.777282714844,,,,,,,,,,,,,,,,,,,,,,,288.8609619,,,,
,2378271.995,283.99426265,999.777282714844,0.000421889892972239,2.63862511252377E-7,1,1.99850670813958,40.0298881530762,1.99773471087773,18.9299993216991,0.00480639853650329,0.000815664406801324,0.25,-5.26013364105157E-7,0.000422131667773977,-2.23098655220735E-7,283.981842,284.0066833,999.777282714844,999.777282714844,62.3888067764874,20.808270374539,5.154188,0,0,0,80,4886,280.8523,999.777282714844,,,,,,,,,,,,,0,,,,1.6097752,,,,,,283.99426265,,,,
,2378436.01,279.92762755,999.777282714844,0.000429105574716591,2.19761462580502E-7,1,1.99850670813958,40.0298881530762,1.99791119373792,18.9299993216991,0.00488852911118999,0.000837034965797908,0.25,9.34209006536028E-8,0.000429416828477017,4.07514598330837E-7,279.896759,279.9584961,999.777282714844,999.777282714844,62.5560752796028,20.8043136328881,4.781127,0,0,0,80,4886,276.67235,999.777282714844,,,,,,,,,,,,,0,,,,1.6017745,,,,,,279.92762755,,,,
,2378597.805,275.937912,999.777282714844,0.000436501085973518,2.37785272712599E-7,1,1.99850670813958,40.0298881530762,1.99752849608373,18.9299993216991,0.00497261761803413,0.000851455315392166,0.25,9.12805194811065E-8,0.000436883354339923,4.16508334554323E-7,275.9075623,275.9682617,999.777282714844,999.777282714844,62.3403458082951,20.8091556533611,5.154188,0,0,0,80,4886,272.63515,999.777282714844,,,,,,,,,,,,,0,,,,1.6178562,,,,,,275.937912,,,,
,2378837.64,269.96769715,999.777282714844,0.000447527484604477,2.27246999736354E-7,1,1.99850670813958,40.0298881530762,1.99762985003926,18.9299993216991,0.00510008426102552,0.000870498527308762,0.25,-1.52759023904734E-7,0.000448020195804315,1.89614891128171E-7,269.9403076,269.9950867,999.777282714844,999.777282714844,62.6303299889297,20.8072187231149,4.781127,0,0,0,80,4886,266.55555,999.777282714844,,,,,,,,,,,,,0,,,,1.6097752,,,,,,269.96769715,,,,
,2378997.435,265.98539735,999.777282714844,0.000455461757466677,2.54005017751998E-7,1,1.99850670813958,40.0298881530762,1.9974561667362,18.9399998635054,0.00519104645521163,0.000884846168763128,0.25,-2.6215827039298E-7,0.000456031479613943,9.24380536744129E-8,265.9572449,266.0135498,999.777282714844,999.777282714844,62.353633493122,20.8089326914066,4.781127,0,0,0,80,4886,262.6151,999.777282714844,,,,,,,,,,,,,0,,,,1.6178562,,,,,,265.98539735,,,,
,2379161.305,261.9243927,999.777282714844,0.000463882095293809,2.12612082507682E-7,1,1.99850670813958,40.0298881530762,1.99733913346709,18.9399998635054,0.00528736937950104,0.000902202040713638,0.25,-1.94018539523723E-7,0.000464532960655927,1.74159290495293E-7,261.8922119,261.9565735,999.777282714844,999.777282714844,62.6021913622374,20.810292726061,5.154188,0,0,0,80,4886,258.4841,999.777282714844,,,,,,,,,,,,,0,,,,1.6259372,,,,,,261.9243927,,,,
,2379355.695,257.07951355,999.777282714844,0.000474023762136356,2.41966531410472E-7,1,1.99850670813958,40.0298881530762,1.9978149189434,18.9500004053116,0.00540460539035739,0.000925599310350816,0.25,8.22265956870699E-8,0.000474774553145299,4.67588864830821E-7,257.0616455,257.0973816,999.777282714844,999.777282714844,62.7843108072182,20.8029086747433,4.781127,0,0,0,80,4886,253.6084,999.777282714844,,,,,,,,,,,,,0,,,,1.6178562,,,,,,257.07951355,,,,
,2379561,251.9539871,999.777282714844,0.000485565053740297,2.4277893859771E-7,1,1.99850670813958,40.0298881530762,1.99743932531619,18.9500004053116,0.00553625798743153,0.000948148437169918,0.25,7.46782000675815E-8,0.00048642689628876,4.79247729870636E-7,251.9276886,251.9802856,999.777282714844,999.777282714844,62.5685813359105,20.8070165554157,5.154188,0,0,0,80,4886,248.4776,999.777282714844,,,,,,,,,,,,,0,,,,1.63409935,,,,,,251.9539871,,,,
,2379722.88,247.92131805,999.777282714844,0.000494960343056511,2.28009986443187E-7,1,1.99850670813958,40.0298881530762,1.99703967457564,18.9500004053116,0.0056437401485818,0.000962990372740287,0.25,-2.35988469086852E-7,0.000495913200803709,1.84178964309458E-7,247.8957825,247.9468536,999.777282714844,999.777282714844,62.7436661242182,20.8162493328669,5.154188,0,0,0,80,4886,244.3681,999.777282714844,,,,,,,,,,,,,0,,,,1.63409935,,,,,,247.92131805,,,,
,2379882.775,243.91678615,999.777282714844,0.0005044889298447,2.03370937951434E-7,1,1.99850670813958,40.0298881530762,1.99684782212884,18.9599990844727,0.00575284108330518,0.000980832995776064,0.25,-3.14926075755327E-7,0.000505534884280995,1.21723404585975E-7,243.9026031,243.9309692,999.777282714844,999.777282714844,62.5763976211028,20.8219723973348,5.154188,0,0,0,80,4886,240.3805,999.777282714844,,,,,,,,,,,,,0,,,,1.63409935,,,,,,243.91678615,,,,
,2380120.69,237.9617157,999.777282714844,0.000519703005263465,2.32845936046607E-7,1,1.99850670813958,40.0298881530762,1.99777481458139,18.9599990844727,0.00592945493844871,0.00101571166827507,0.25,6.77605158141023E-8,0.000520893885955138,5.32296776890755E-7,237.9352722,237.9881592,999.777282714844,999.777282714844,62.7936903494489,20.8048195712615,4.781127,0,0,0,80,4886,234.40665,999.777282714844,,,,,,,,,,,,,0,,,,1.6422615,,,,,,237.9617157,,,,
,2380280.5,233.97489925,999.777282714844,0.000530323290103462,2.05875805787327E-7,1,1.99850670813958,40.0298881530762,1.99781572152312,18.9800001680851,0.00605151503006486,0.00103726233055931,0.25,1.13943635988827E-7,0.000531615642887659,5.98030442139457E-7,233.9500732,233.9997253,999.777282714844,999.777282714844,62.5717078499874,20.8045767898303,4.781127,0,0,0,80,4886,230.4191,999.777282714844,,,,,,,,,,,,,0,,,,1.63409935,,,,,,233.97489925,,,,
,2380442.4,229.92089845,999.777282714844,0.000541463091767236,2.23133083050339E-7,1,1.99850670813958,40.0298881530762,1.9974578983207,18.9800001680851,0.00617850290764748,0.00105891284020465,0.25,9.5896387444152E-8,0.000542862261539417,6.00789560821247E-7,229.8926544,229.9491425,999.777282714844,999.777282714844,62.6240769607759,20.8075329057804,4.781127,0,0,0,80,4886,226.39375,999.777282714844,,,,,,,,,,,,,0,,,,1.63409935,,,,,,229.92089845,,,,
,2380604.135,225.87641905,999.777282714844,0.000552958908974394,2.04723693983282E-7,1,1.99850670813958,40.0298881530762,2.00927528789215,19.0099999308586,0.0063461451563432,0.00108763617531217,0.25,8.57678524032763E-8,0.000554468379317752,6.12929117356666E-7,225.8484192,225.9044189,999.777282714844,999.777282714844,62.3895884050066,20.8185157328763,5.154188,0,0,0,80,4886,222.3013,999.777282714844,,,,,,,,,,,,,0,,,,1.6505056,,,,,,225.87641905,,,,
,2380840.03,219.98477935,999.777282714844,0.000570416877561811,1.91500609563118E-7,1,1.99850670813958,40.0298881530762,1.99690953452709,19.0099999308586,0.00650951321999777,0.00111554626525225,0.25,6.29682560837084E-8,0.000572094057164491,6.24831625688607E-7,219.9532928,220.0162659,999.777282714844,999.777282714844,62.7639884657182,20.8180641697455,4.781127,0,0,0,80,4886,216.4221,999.777282714844,,,,,,,,,,,,,0,,,,1.6587497,,,,,,219.98477935,,,,
touchdown = 13.8999996706843 mm,2381021.205,215.4562836,999.777282714844,0.000585559608025425,2.09674918962207E-7,1,1.99850670813958,40.0298881530762,1.99678118608217,19.0500002354383,0.00668278892470006,0.00114637066118027,0.25,1.45694960239083E-7,0.000587374931651445,7.37991641211699E-7,215.4562836,215.4562836,999.777282714844,999.777282714844,62.3911516620451,20.8213326963967,5.154188,0,0,0,80,4886,211.8788,999.777282714844,,,,,,,,,,,,,0,,,,1.6587497,,,,,,215.4562836,,,,
,2381161.82,211.94272615,999.777282714844,0.000596922631348233,1.92997178064694E-7,1,1.99850670813958,40.0298881530762,1.9967375179747,19.0500002354383,0.00681279328013594,0.00117090661514687,0.25,3.26287409457142E-7,0.000598846463804198,9.43228278099685E-7,211.913208,211.9722443,999.777282714844,999.777282714844,62.6217320752182,20.8215695082119,4.781127,0,0,0,80,4886,208.38215,999.777282714844,,,,,,,,,,,,,0,,,,1.6587497,,,,,,211.94272615,,,,
,2381418.31,205.5461731,999.777282714844,,,2,,,,19.0960003647804,,,,,,,205.5461731,205.5461731,999.777282714844,999.777282714844,,,5.154188,,,,-99999999,4886,201.9405,999.777282714844,,,,,,,,,,,,,,,,,,,,,,,205.5461731,,,,
,2381561.45,201.96102145,999.777282714844,0.000632454872748088,2.11127815204962E-7,1,1.99850670813958,40.0298881530762,1.99653399139455,19.0799999982119,0.00722016050506728,0.00124056914424801,0.25,2.74735520137932E-7,0.000634710689580942,9.69730348846406E-7,201.9299164,201.9921265,999.777282714844,999.777282714844,62.6225137037374,20.8182604037247,5.154188,0,0,0,80,4886,198.3812,999.777282714844,,,,,,,,,,,,,0,,,,1.6587497,,,,,,201.96102145,,,,
,2381721.32,197.9357071,999.777282714844,0.000647786877569244,1.96222086102327E-7,1,1.99850670813958,40.0298881530762,1.99638986351712,19.0799999982119,0.00739532613001659,0.0012728246762659,0.25,4.46626465307633E-7,0.000650185273983198,1.17769840735323E-6,197.904892,197.9665222,999.777282714844,999.777282714844,62.6490890733912,20.8217054445058,4.781127,0,0,0,80,4886,194.39195,999.777282714844,,,,,,,,,,,,,0,,,,1.6754035,,,,,,197.9357071,,,,
,2381881.22,193.9363632,999.777282714844,0.000664127574210599,1.91725773789819E-7,1,1.99850670813958,40.0298881530762,1.99666737272069,19.1099997609854,0.00758325714869538,0.00130896001061909,0.25,7.60260796736845E-7,0.000666674694453272,1.53116075124933E-6,193.9065094,193.966217,999.777282714844,999.777282714844,62.6959867845451,20.8137730687093,5.154188,0,0,0,80,4886,190.39765,999.777282714844,,,,,,,,,,,,,0,,,,1.6670766,,,,,,193.9363632,,,,
,2382119.055,187.9589157,999.777282714844,0.000689264215809687,1.54764636498604E-7,1,1.99850670813958,40.0298881530762,1.99638089614057,19.1099997609854,0.00786845177184251,0.00137191449627561,0.25,1.92333551634466E-6,0.000692041483713059,2.76142592225795E-6,187.9315796,187.9862518,999.777282714844,999.777282714844,62.3364376656989,20.8226360486266,5.154188,0,0,0,80,4886,184.48825,999.777282714844,,,,,,,,,,,,,0,,,,1.6670766,,,,,,187.9589157,,,,
,2382278.89,183.96707155,999.777282714844,0.000709341633358925,1.90248555320605E-7,1,1.99850670813958,40.0298881530762,1.98506221132765,19.1399995237589,0.00805251802919971,0.00141839831724604,0.25,3.18458056052187E-6,0.000712289362116933,4.07725562877029E-6,183.9407654,183.9933777,999.777282714844,999.777282714844,62.7209988971605,20.8167839731296,5.154188,0,0,0,80,4886,180.5012,999.777282714844,,,,,,,,,,,,,0,,,,1.6587497,,,,,,183.96707155,,,,
,2382440.845,179.89124295,999.777282714844,0.000730527925155864,1.70495171493698E-7,1,1.99850670813958,40.0298881530762,1.98463322436177,19.1399995237589,0.00829480074811293,0.00144655317595441,0.25,2.01138276839539E-6,0.000733659467635039,2.95341863860973E-6,179.8646545,179.9178314,999.777282714844,999.777282714844,62.7124009834489,20.8193240331422,4.781127,0,0,0,80,4886,176.45655,999.777282714844,,,,,,,,,,,,,0,,,,1.6670766,,,,,,179.89124295,,,,
,2382665.45,174.2652893,999.777282714844,,,2,,,,19.185999653101,,,,,,,174.2652893,174.2652893,999.777282714844,999.777282714844,,,5.154188,,,,-99999999,4886,170.8963,999.777282714844,,,,,,,,,,,,,,,,,,,,,,,174.2652893,,,,
,2382836.475,169.9798279,999.777282714844,0.0007821169609503,1.7648243479962E-7,1,1.99850670813958,40.0298881530762,1.99643741322616,19.1699992865324,0.00893570685487787,0.00154573533071768,0.25,1.0033944251763E-6,0.000785708578431868,2.08856321077614E-6,169.948761,170.0108948,999.777282714844,999.777282714844,62.861692030622,20.8163806846362,5.154188,0,0,0,80,4886,166.598,999.777282714844,,,,,,,,,,,,,0,,,,1.6505056,,,,,,169.9798279,,,,
,2382998.345,165.90594485,999.777282714844,0.000805799559219602,1.85067108877424E-7,1,1.99850670813958,40.0298881530762,1.99648073557945,19.1699992865324,0.00920700491474158,0.00159608298184637,0.25,1.28614063172006E-6,0.000809596526419836,2.44381611822234E-6,165.8808289,165.9310608,999.777282714844,999.777282714844,62.6264218463335,20.8169071874262,5.154188,0,0,0,80,4886,162.5926,999.777282714844,,,,,,,,,,,,,0,,,,1.6505056,,,,,,165.90594485,,,,
,2383156.19,161.94007115,999.777282714844,0.000829633178190098,1.95620852138184E-7,1,1.99850670813958,40.0298881530762,1.99654519156558,19.2200001329184,0.00948125906858703,0.00164025254444765,0.25,9.96461341678964E-7,0.000833637725259197,2.22837642993791E-6,161.9254456,161.9546967,999.777282714844,999.777282714844,62.3575416357181,20.8275646891369,5.154188,0,0,0,80,4886,158.68175,999.777282714844,,,,,,,,,,,,,0,,,,1.6422615,,,,,,161.94007115,,,,
,2383394.01,155.95952605,999.777282714844,0.000868495008998683,1.78700027708466E-7,1,1.99850670813958,40.0298881530762,1.99633125500897,19.2200001329184,0.00992560035569531,0.00171960050747081,0.25,1.18190187794124E-6,0.000872831466455966,2.54464259237702E-6,155.9307556,155.9882965,999.777282714844,999.777282714844,62.6232953322566,20.8257713587131,5.154188,0,0,0,80,4886,152.75015,999.777282714844,,,,,,,,,,,,,0,,,,1.63409935,,,,,,155.95952605,,,,
,2383554.015,151.94384005,999.777282714844,0.000896621238689345,1.96093412892387E-7,1,1.99850670813958,40.0298881530762,1.99644160452391,19.2600004374981,0.0102476827443176,0.00178135940025813,0.25,1.67156673848614E-6,0.000901193742261189,3.13600772321307E-6,151.9115601,151.97612,999.777282714844,999.777282714844,62.5506038799682,20.8217794449532,5.154188,0,0,0,80,4886,148.77355,999.777282714844,,,,,,,,,,,,,0,,,,1.6178562,,,,,,151.94384005,,,,
,2383715.97,147.89431,999.777282714844,0.000926118592879855,1.85712984438147E-7,1,1.99850670813958,40.0298881530762,1.99660429974549,19.2600004374981,0.0105870857596164,0.00183827220676282,0.25,1.48757845380442E-6,0.000930938649767022,3.06148118793007E-6,147.8774567,147.9111633,999.777282714844,999.777282714844,62.7405396101413,20.8213141583128,5.154188,0,0,0,80,4886,144.76255,999.777282714844,,,,,,,,,,,,,0,,,,1.6097752,,,,,,147.89431,,,,
,2383910.28,143.0440063,999.777282714844,,,2,,,,19.3160001773238,,,,,,,143.0440063,143.0440063,999.777282714844,999.777282714844,,,4.781127,,,,-99999999,4886,139.9952,999.777282714844,,,,,,,,,,,,,,,,,,,,,,,143.0440063,,,,
,2384111.53,137.9785843,999.777282714844,0.00100827341310356,1.91704837282841E-7,1,1.99850670813958,40.0298881530762,1.99576596404272,19.3000007420778,0.011523091288613,0.0020083947539843,0.25,2.07421336893717E-6,0.00101375911512649,3.98289052478884E-6,137.9515381,138.0056305,999.777282714844,999.777282714844,62.4786940561989,20.8290902835117,5.154188,0,0,0,80,4886,134.9855,999.777282714844,,,,,,,,,,,,,0,,,,1.5779315,,,,,,137.9785843,,,,
,2384273.51,133.9451141,999.777282714844,0.00104478802708713,2.05625064501069E-7,1,1.99850670813958,40.0298881530762,1.99591279226637,19.3000007420778,0.0119419740162938,0.0020832103875749,0.25,2.20898612015536E-6,0.00105056352323154,4.28179103716697E-6,133.9114532,133.978775,999.777282714844,999.777282714844,62.6639400152566,20.8230474340994,4.781127,0,0,0,80,4886,131.01155,999.777282714844,,,,,,,,,,,,,0,,,,1.5779315,,,,,,133.9451141,,,,
,2384433.315,129.9322815,999.777282714844,0.00108305591380542,1.98277877819312E-7,1,1.99850670813958,40.0298881530762,1.99591340125128,19.3499997258186,0.0123788105622215,0.0021687854917799,0.25,2.97954890640832E-6,0.00108912905267256,5.23906463910649E-6,129.9216461,129.9429169,999.777282714844,999.777282714844,63.0133279633528,20.8231030262091,5.154188,0,0,0,80,4886,127.0702,999.777282714844,,,,,,,,,,,,,0,,,,1.5467178,,,,,,129.9322815,,,,
,2384671.05,123.96655275,999.777282714844,0.00114532971514088,1.93827680147146E-7,1,1.99850670813958,40.0298881530762,1.9956027802117,19.3499997258186,0.0130904852010446,0.0022907439769022,0.25,2.73210847420878E-6,0.00115187568476527,5.30799110304618E-6,123.9371872,123.9959183,999.777282714844,999.777282714844,62.946107910699,20.8234738811516,5.154188,0,0,0,80,4886,121.23905,999.777282714844,,,,,,,,,,,,,0,,,,1.5467178,,,,,,123.96655275,,,,
,2384828.945,119.986351,999.777282714844,0.00118937894004049,1.80622149680503E-7,1,1.99850670813958,40.0298881530762,1.99619016273249,19.4099992513657,0.0135971305465114,0.0023880798798585,0.25,3.42587213775004E-6,0.00119624785567048,6.25306014075269E-6,119.9626083,120.0100937,999.777282714844,999.777282714844,62.6303299889297,20.8277803782198,5.154188,0,0,0,80,4886,117.32875,999.777282714844,,,,,,,,,,,,,0,,,,1.52373235,,,,,,119.986351,,,,
,2384991.53,115.9165497,999.777282714844,0.00123877789403177,1.60975925538618E-7,1,1.99850670813958,40.0298881530762,1.99564774833433,19.4099992513657,0.0141583549942923,0.00249009689748442,0.25,3.68516162479282E-6,0.0012459959723709,6.80750385863591E-6,115.9013901,115.9317093,999.777282714844,999.777282714844,62.8882674002759,20.8312091174823,5.154188,0,0,0,80,4886,113.30935,999.777282714844,,,,,,,,,,,,,0,,,,1.5010511,,,,,,115.9165497,,,,
,2385176.04,111.2931328,999.777282714844,0.00129826741520657,1.8439672656551E-7,1,1.99850670813958,40.0298881530762,1.99526103571451,19.4600000977516,0.0148355400183525,0.00261310241699553,0.25,3.95962030992191E-6,0.00130588908778911,7.46821435148851E-6,111.2641678,111.3220978,999.777282714844,999.777282714844,62.414600517622,20.8325189205094,4.781127,0,0,0,80,4886,108.76875,999.777282714844,,,,,,,,,,,,,0,,,,1.5010511,,,,,,111.2931328,,,,
,2385388.5,105.96265415,999.777282714844,0.0013731588001688,2.15936085171547E-7,1,1.99850670813958,40.0298881530762,1.99544906546326,19.4600000977516,0.0156918841253506,0.00277158132611228,0.25,4.50932531582638E-6,0.00138125543496189,8.55181323167068E-6,105.9331284,105.9921799,999.777282714844,999.777282714844,62.2973562397374,20.8335024379985,5.154188,0,0,0,80,4886,103.5436,999.777282714844,,,,,,,,,,,,,0,,,,1.4861304,,,,,,105.96265415,,,,
,2385550.33,101.90184405,999.777282714844,0.00143461429074571,1.83626935009268E-7,1,1.99850670813958,40.0298881530762,1.9950708995614,19.4600000977516,0.0163905069574547,0.00289898239251804,0.25,4.75186543336599E-6,0.00144306957220686,9.27661497604792E-6,101.8750458,101.9286423,999.777282714844,999.777282714844,62.7780577790643,20.8367762486996,5.154188,0,0,0,80,4886,99.54865,999.777282714844,,,,,,,,,,,,,0,,,,1.46404535,,,,,,101.90184405,,,,
,2385708.21,97.9133835,999.777282714844,0.00149897034230816,1.55976495978399E-7,1,1.99850670813958,40.0298881530762,1.99540562403508,19.5199996232986,0.0171259200398446,0.00304198670559684,0.25,5.71963747415107E-6,0.00150776469719574,1.07964127188768E-5,97.8869629,97.9398041,999.777282714844,999.777282714844,62.3004827538143,20.8353157277809,5.154188,0,0,0,80,4886,95.65545,999.777282714844,,,,,,,,,,,,,0,,,,1.4422525,,,,,,97.9133835,,,,
,2385942.035,91.98778535,999.777282714844,0.00160437565423374,1.96286464635117E-7,1,1.99850670813958,40.0298881530762,1.99508496639368,19.5199996232986,0.0183235839218751,0.00326727256368781,0.25,6.55394866671894E-6,0.00161363661172169,1.26259371631793E-5,91.9657288,92.0098419,999.777282714844,999.777282714844,62.5185571106797,20.8384632035187,5.154188,0,0,0,80,4886,89.86525,999.777282714844,,,,,,,,,,,,,0,,,,1.4279163,,,,,,91.98778535,,,,
,2386099.915,87.99761585,999.777282714844,0.00168112505640485,1.78252224996629E-7,1,1.99850670813958,40.0298881530762,1.98357505737281,19.5799991488457,0.0190905267732242,0.00341517219909959,0.25,7.30007151633742E-6,0.00169063720843195,1.41850833382607E-5,87.9646912,88.0305405,999.777282714844,999.777282714844,62.6201688181797,20.8340453752964,5.154188,0,0,0,80,4886,85.96035,999.777282714844,,,,,,,,,,,,,0,,,,1.4066963,,,,,,87.99761585,,,,
,2386259.775,83.9391708,999.777282714844,0.00176523587410553,2.2318519434644E-7,1,1.99850670813958,40.0298881530762,1.98353650906589,19.5799991488457,0.0200400628094768,0.00359631148422255,0.25,8.00718543176238E-6,0.00177492497344237,1.58597771295899E-5,83.9286575,83.9496841,999.777282714844,999.777282714844,62.892175542872,20.8387964445777,5.154188,0,0,0,80,4886,82.0062,999.777282714844,,,,,,,,,,,,,0,,,,1.39967,,,,,,83.9391708,,,,
,2386417.655,79.9336319,999.777282714844,0.00185359445402719,1.82424471804593E-7,1,1.99850670813958,40.0298881530762,1.99461078704752,19.6299999952316,0.0211480628915283,0.00380820568043548,0.25,8.80312192421962E-6,0.00186333450901811,1.77642633573154E-5,79.9051285,79.9621353,999.777282714844,999.777282714844,62.4724410280451,20.8389010754347,5.154188,0,0,0,80,4886,78.1281,999.777282714844,,,,,,,,,,,,,0,,,,1.3788699,,,,,,79.9336319,,,,
,2386651.58,73.9937859,999.777282714844,0.00199696434763952,2.09999128363782E-7,1,1.99850670813958,40.0298881530762,1.99444692945454,19.6299999952316,0.0227663267782559,0.00412347868759889,0.25,1.02225220533682E-5,0.0020064225276865,2.11655626805034E-5,73.9675446,74.0200272,999.777282714844,999.777282714844,62.7819659216605,20.8451322835866,4.781127,0,0,0,80,4886,72.34235,999.777282714844,,,,,,,,,,,,,0,,,,1.36516375,,,,,,73.9937859,,,,
touchdown = 14.5399998873472 mm,2386822.875,69.64680095,999.777282714844,0.00210992915764788,2.32934983878565E-7,1,1.99850670813958,40.0298881530762,1.99495053583641,19.6899995207787,0.0240431709763823,0.00437755403125882,0.25,1.16636617393084E-5,0.0021187745164567,2.42970050991399E-5,69.6365356,69.6570663,999.777282714844,999.777282714844,62.8710715728528,20.8471242335036,5.154188,0,0,0,80,4886,68.1294,999.777282714844,,,,,,,,,,,,,0,,,,1.33815885,,,,,,69.64680095,,,,
,2386969.24,65.94543455,999.777282714844,0.00221431249216461,2.25770516208236E-7,1,1.99850670813958,40.0298881530762,1.99465740725397,19.6899995207787,0.0252106926934894,0.00460976378894621,0.25,1.29345976720296E-5,0.00222225782337595,2.71592342298878E-5,65.9179077,65.9729614,999.777282714844,999.777282714844,62.8296452613336,20.8523294886464,4.781127,0,0,0,80,4886,64.5245,999.777282714844,,,,,,,,,,,,,0,,,,1.32485735,,,,,,65.94543455,,,,
,2387210.89,59.7572975,999.777282714844,,,2,,,,19.7660003442168,,,,,,,59.7572975,59.7572975,999.777282714844,999.777282714844,,,4.781127,,,,-99999999,4886,58.6051,999.777282714844,,,,,,,,,,,,,,,,,,,,,,,59.7572975,,,,
,2387360.905,55.95383835,999.777282714844,0.00252244737727552,1.80077968234638E-7,1,1.99850670813958,40.0298881530762,1.99476396371713,19.7500009089708,0.0286469743530699,0.00528098015871003,0.25,1.60379683391205E-5,0.00252565293488883,3.45261820993606E-5,55.9316406,55.9760361,999.777282714844,999.777282714844,62.9914423648144,20.8481573686481,5.154188,0,0,0,80,4886,54.88865,999.777282714844,,,,,,,,,,,,,0,,,,1.2793188,,,,,,55.95383835,,,,
,2387518.855,51.9278469,999.777282714844,0.00266170475880376,1.68247621357775E-7,1,1.99850670813958,40.0298881530762,1.99478900150729,19.7500009089708,0.0301910992687613,0.00557982922791886,0.25,1.778579009746E-5,0.00266196503694532,3.76001279031042E-5,51.9110718,51.944622,999.777282714844,999.777282714844,62.8765429724874,20.8425214793945,5.154188,0,0,0,80,4882,51.00505,999.777282714844,,,,,,,,,,,,,0,,,,1.229206,,,,,,51.9278469,,,,
,2387674.72,47.9510803,999.777282714844,0.00280638498367923,1.5405404855007E-7,1,1.99850670813958,40.0298881530762,1.98328736432407,19.7999998927116,0.0316180761945571,0.00585239253341423,0.25,1.97142511351849E-5,0.00280332125521638,4.03542358788398E-5,47.9338722,47.9682884,999.777282714844,999.777282714844,62.9679935092374,20.8445726274539,5.154188,0,0,0,80,4882,47.18745,999.777282714844,,,,,,,,,,,,,0,,,,1.1989021,,,,,,47.9510803,,,,
,2387909.33,41.9813862,999.777282714844,0.00302760524383698,2.27266708739927E-7,1,1.99850670813958,40.0298881530762,1.98375252251568,19.7999998927116,0.0340633463488023,0.00629383771690756,0.25,2.17123924425797E-5,0.00301928502735868,4.25059160123031E-5,41.9655304,41.997242,999.777282714844,999.777282714844,63.0672603311798,20.8413564473158,5.154188,0,0,0,80,4882,41.4149,999.777282714844,,,,,,,,,,,,,0,,,,1.1519392,,,,,,41.9813862,,,,
,2388067.085,37.97832875,999.777282714844,0.00317845036349539,2.45403545024437E-7,1,1.99850670813958,40.0298881530762,1.99531914198121,19.8400001972914,0.0359296846717351,0.0066190917080668,0.25,2.26011350333964E-5,0.00316682684007576,4.29131707238382E-5,37.9460793,38.0105782,999.777282714844,999.777282714844,62.4575900861797,20.8432346433845,4.781127,0,0,0,80,4882,37.50815,999.777282714844,,,,,,,,,,,,,0,,,,1.1123998,,,,,,37.97832875,,,,
,2388227.23,33.9181557,999.777282714844,0.00333744346645435,2.46953456265488E-7,1,1.99850670813958,40.0298881530762,1.99531824902707,19.8400001972914,0.0377040031399886,0.00692408142538391,0.25,2.35068613488175E-5,0.00332289756017787,4.31624043262878E-5,33.8913422,33.9449692,999.777282714844,999.777282714844,62.6819174711989,20.8473614623,5.154188,0,0,0,80,4882,33.56355,999.777282714844,,,,,,,,,,,,,0,,,,1.0795023,,,,,,33.9181557,,,,
,2388442.08,28.4665546,999.777282714844,,,2,,,,19.8959999371171,,,,,,,28.4665546,28.4665546,999.777282714844,999.777282714844,,,4.781127,,,,-99999999,4882,28.2561,999.777282714844,,,,,,,,,,,,,,,,,,,,,,,28.4665546,,,,
,2388622.055,23.97619245,999.777282714844,0.00375724579720522,3.048934797201E-7,1,1.99850670813958,40.0298881530762,1.99494968600906,19.8800005018711,0.0424086014784671,0.00774042610729256,0.25,2.57175640290395E-5,0.00373748420447672,4.44861295169341E-5,23.9493408,24.0030441,999.777282714844,999.777282714844,62.1535365921989,20.8473679974747,4.781127,0,0,0,80,4882,23.7593,999.777282714844,,,,,,,,,,,,,0,,,,0.9720181,,,,,,23.97619245,,,,
,2388907.7,20.0157089,999.777282714844,0.00395537993735379,3.2641544702314E-7,1,1.99850670813958,40.0298881530762,1.99422548196614,19.8800005018711,0.0446258248186343,0.00813933725962509,0.25,2.71252942857325E-5,0.00393416565110512,4.63342237324094E-5,20.0145721,20.0168457,999.777282714844,999.777282714844,62.6201688181797,20.8626038078917,4.781127,0,0,0,80,4881,19.97775,999.777282714844,,,,,,,,,,,,,0,,,,0.9108952,,,,,,20.0157089,,,,
,2389089.645,19.9931364,999.777282714844,0.00395420585704256,2.54640779581348E-7,1,1.99850670813958,40.0298881530762,1.98307474870309,19.9100002646446,0.0443766621220954,0.00808237312412959,0.25,2.61281708734379E-5,0.00393299929006675,4.53322597394596E-5,19.9882698,19.998003,999.777282714844,999.777282714844,62.6303299889297,20.8566896035114,4.781127,0,0,0,80,4882,19.9242,999.777282714844,,,,,,,,,,,,,0,,,,0.9200405,,,,,,19.9931364,,,,
,2389387.395,19.48180005,999.777282714844,0.00398132262146047,2.6502277131857E-7,1,1.99850670813958,40.0298881530762,1.98165721283358,19.9100002646446,0.0446498694334083,0.00813437350175119,0.25,2.65383339750472E-5,0.00395994559967936,4.58352246688483E-5,19.4801731,19.483427,999.777282714844,999.777282714844,62.8507492313528,20.8646074154657,4.781127,0,0,0,80,4882,19.4138,999.777282714844,,,,,,,,,,,,,0,,,,0.9018408,,,,,,19.48180005,,,,
,2389595.21,19.13621905,999.777282714844,0.00399905962670883,2.22786746501104E-7,1,1.99850670813958,40.0298881530762,1.9826621135597,19.9100002646446,0.0448706211471907,0.00817291480129766,0.25,2.65330616352687E-5,0.00397757550376872,4.58955074281277E-5,19.1346684,19.1377697,999.777282714844,999.777282714844,63.2657939750644,20.8664735113413,4.781127,0,0,0,80,4882,19.0651,999.777282714844,,,,,,,,,,,,,0,,,,0.9018408,,,,,,19.13621905,,,,
,2389803.055,18.7940588,999.777282714844,0.00401748282765057,2.94939462986772E-7,1,1.99850670813958,40.0298881530762,1.99429195925386,19.9299994856119,0.0453272572101345,0.00826790576913963,0.25,2.7686189674753E-5,0.00399588548845916,4.7115199175306E-5,18.7920017,18.7961159,999.777282714844,999.777282714844,62.8976469425066,20.8573147129109,5.154188,0,0,0,80,4882,18.7208,999.777282714844,,,,,,,,,,,,,0,,,,0.8928764,,,,,,18.7940588,,,,
,2390108.79,18.2827282,999.777282714844,0.00404577382942141,3.11600089860843E-7,1,1.99850670813958,40.0298881530762,1.9932462370572,19.9299994856119,0.0456250663917905,0.00831329312311197,0.25,2.7133157650182E-5,0.00402401993703085,4.66841768309865E-5,18.2810116,18.2844448,999.777282714844,999.777282714844,62.749919152372,20.8653850124889,5.154188,0,0,0,80,4882,18.2073,999.777282714844,,,,,,,,,,,,,0,,,,0.875214,,,,,,18.2827282,,,,
,2390314.685,17.929245,999.777282714844,0.00406530820254172,2.7913974384926E-7,1,1.99850670813958,40.0298881530762,1.99356355120874,19.9400000274181,0.0458523553473501,0.00835433956976491,0.25,2.72411300201426E-5,0.00404344750493558,4.68781822822302E-5,17.9220524,17.9364376,999.777282714844,999.777282714844,62.5967199626028,20.8602021363416,5.154188,0,0,0,80,4882,17.8395,999.777282714844,,,,,,,,,,,,,0,,,,0.875214,,,,,,17.929245,,,,
,2390522.485,17.5913515,999.777282714844,0.00408719620838939,2.35872679095136E-7,1,1.99850670813958,40.0298881530762,1.99349609164966,19.9400000274181,0.0460966172563049,0.00840557391051199,0.25,2.79693627892011E-5,0.00406521659708893,4.77050369026681E-5,17.5896568,17.5930462,999.777282714844,999.777282714844,62.6506523304297,20.8554118639049,5.154188,0,0,0,80,4882,17.5229,999.777282714844,,,,,,,,,,,,,0,,,,0.86220765,,,,,,17.5913515,,,,
,2390830.295,17.07810115,999.777282714844,0.0041179149740418,2.7807513675953E-7,1,1.99850670813958,40.0298881530762,1.99389100974943,19.9400000274181,0.0464534562957529,0.00846220361501063,0.25,2.74455467950148E-5,0.0040957898077426,4.73435893456472E-5,17.076086,17.0801163,999.777282714844,999.777282714844,62.8491859743143,20.8566219352691,5.154188,0,0,0,80,4882,17.00875,999.777282714844,,,,,,,,,,,,,0,,,,0.8409305,,,,,,17.07810115,,,,
,2391038.06,16.73447035,999.777282714844,0.00413688344988944,2.09073866691492E-7,1,1.99850670813958,40.0298881530762,2.00687743130499,19.9599992483854,0.0469556320240836,0.00856142396701504,0.25,2.82321081090687E-5,0.00411465805891131,4.82183396440522E-5,16.7333393,16.7356014,999.777282714844,999.777282714844,62.7608619516413,20.862067742269,4.781127,0,0,0,80,4882,16.6602,999.777282714844,,,,,,,,,,,,,0,,,,0.8409305,,,,,,16.73447035,,,,
,2391245.925,16.38587475,999.777282714844,0.00416004164457133,3.17169048490557E-7,1,1.99850670813958,40.0298881530762,2.00585628241528,19.9599992483854,0.0471957671185823,0.00860463204587904,0.25,2.8341030419654E-5,0.00413769694816281,4.84394638106518E-5,16.384016,16.3877335,999.777282714844,999.777282714844,62.6975500415836,20.8537432913191,4.781127,0,0,0,80,4882,16.3139,999.777282714844,,,,,,,,,,,,,0,,,,0.8242956,,,,,,16.38587475,,,,
,2391522.66,15.8621883,999.777282714844,,,2,,,,19.9959997672439,,,,,,,15.8621883,15.8621883,999.777282714844,999.777282714844,,,4.781127,,,,-99999999,4882,15.8961,999.777282714844,,,,,,,,,,,,,,,,,,,,,,,15.8621883,,,,
,2391755.54,15.53525875,999.777282714844,0.00421567664198015,2.23270074968959E-7,1,1.99850670813958,40.0298881530762,1.99356772170418,19.9800003319979,0.0475500651868741,0.0086567750323493,0.25,2.76515166874681E-5,0.00419304980592524,4.80245753228308E-5,15.5334787,15.5370388,999.777282714844,999.777282714844,62.7788394075836,20.850132748036,5.154188,0,0,0,80,4882,15.46645,999.777282714844,,,,,,,,,,,,,0,,,,0.8039741,,,,,,15.53525875,,,,
,2391965.445,15.1869111,999.777282714844,0.00423859535499271,1.21958087902561E-7,1,1.99850670813958,40.0298881530762,1.9934159876865,19.9800003319979,0.0478049855549385,0.00870419206506727,0.25,2.78882906849278E-5,0.00421584958630371,4.83716987699168E-5,15.1850271,15.1887951,999.777282714844,999.777282714844,62.6209504466989,20.8511869889891,4.781127,0,0,0,80,4882,15.1158,999.777282714844,,,,,,,,,,,,,0,,,,0.7999583,,,,,,15.1869111,,,,
,2392165.275,14.83560895,999.777282714844,0.00426112291293335,2.25903337100521E-7,1,1.99850670813958,40.0298881530762,2.00702842386244,19.9999995529652,0.048370047365811,0.00881648186778714,0.25,2.88384617640549E-5,0.00423825677532254,4.94265101372428E-5,14.8340988,14.8371191,999.777282714844,999.777282714844,62.5326264240258,20.8550770404858,5.154188,0,0,0,80,4882,14.76035,999.777282714844,,,,,,,,,,,,,0,,,,0.784134,,,,,,14.83560895,,,,
,2392480.95,14.33000325,999.777282714844,0.00429609206712648,1.86314922892336E-7,1,1.99850670813958,40.0298881530762,2.00611615637101,19.9999995529652,0.0487458020914983,0.00888593135891805,0.25,2.91570256775771E-5,0.00427304405640951,4.99136664442841E-5,14.3282127,14.3317938,999.777282714844,999.777282714844,62.6842623567566,20.8542040391054,4.781127,0,0,0,80,4882,14.25295,999.777282714844,,,,,,,,,,,,,0,,,,0.784134,,,,,,14.33000325,,,,
,2392688.79,13.9858513,999.777282714844,0.00432026447029127,3.1416807285502E-7,1,1.99850670813958,40.0298881530762,2.00620471349608,19.9999995529652,0.0490219526408221,0.00893762124554066,0.25,2.94362392734625E-5,0.00429709028018187,5.03091029738165E-5,13.9844799,13.9872227,999.777282714844,999.777282714844,62.6952051560259,20.8503898179079,5.154188,0,0,0,80,4882,13.9052,999.777282714844,,,,,,,,,,,,,0,,,,0.7686227,,,,,,13.9858513,,,,
,2392896.63,13.638546,999.777282714844,0.00434525590580929,2.50210090364845E-7,1,1.99850670813958,40.0298881530762,1.99370762896622,20.0100000947714,0.0490143222455285,0.00892838891412916,0.25,2.89336915368587E-5,0.00432195492222985,4.99309313399851E-5,13.6364336,13.6406584,999.777282714844,999.777282714844,62.7507007808913,20.8534221462561,4.781127,0,0,0,80,4882,13.55935,999.777282714844,,,,,,,,,,,,,0,,,,0.7534183,,,,,,13.638546,,,,
,2393204.415,13.12987705,999.777282714844,0.0043817067386843,2.44382260304798E-7,1,1.99850670813958,40.0298881530762,1.99390135489845,20.0100000947714,0.0494305476996205,0.00900172977051215,0.25,2.89637679030333E-5,0.00435821696419392,5.01383444290106E-5,13.1288652,13.1308889,999.777282714844,999.777282714844,63.3642791684875,20.8479329267943,5.154188,0,0,0,80,4882,13.0467,999.777282714844,,,,,,,,,,,,,0,,,,0.7385145,,,,,,13.12987705,,,,
,2393416.26,12.7816925,999.777282714844,0.00440610204406994,2.75363872657842E-7,1,1.99850670813958,40.0298881530762,1.99365375850415,20.0200006365776,0.0497001707088114,0.009049320723423,0.25,2.89954718207335E-5,0.00438248582759212,5.02886714330083E-5,12.7776365,12.7857485,999.777282714844,999.777282714844,62.882014372122,20.8461904117693,5.154188,0,0,0,80,4882,12.69095,999.777282714844,,,,,,,,,,,,,0,,,,0.73484405,,,,,,12.7816925,,,,
,2393618.055,12.4393077,999.777282714844,0.00443170876781596,2.29709486533842E-7,1,1.99850670813958,40.0298881530762,1.993830097661,20.0200006365776,0.0499929235086299,0.00910463003237189,0.25,2.93360562593118E-5,0.00440795799334284,5.07521283491449E-5,12.4378433,12.4407721,999.777282714844,999.777282714844,62.7608619516413,20.8444807663321,4.781127,0,0,0,80,4882,12.358,999.777282714844,,,,,,,,,,,,,0,,,,0.7239057,,,,,,12.4393077,,,,
,2393925.83,11.92812395,999.777282714844,0.0044712597349939,2.7761998877171E-7,1,1.99850670813958,40.0298881530762,1.99368012567713,20.0200006365776,0.0504363465511017,0.00918057498942131,0.25,2.91850720749429E-5,0.00444730406305492,5.07945295331822E-5,11.9269104,11.9293375,999.777282714844,999.777282714844,62.8116678053913,20.8447434519168,4.781127,0,0,0,80,4882,11.8393,999.777282714844,,,,,,,,,,,,,0,,,,0.71671,,,,,,11.92812395,,,,
,2394131.695,11.5846505,999.777282714844,0.00449948436903684,1.59745973530135E-7,1,1.99850670813958,40.0298881530762,1.98258775988883,20.0299993157387,0.0504863226263664,0.00918491032855151,0.25,2.89585320097742E-5,0.0044753827227554,5.07066227338856E-5,11.5830841,11.5862169,999.777282714844,999.777282714844,62.4614982287758,20.8507816467363,4.781127,0,0,0,80,4882,11.49765,999.777282714844,,,,,,,,,,,,,0,,,,0.7025324,,,,,,11.5846505,,,,
,2394339.5,11.23887015,999.777282714844,0.00452828120268982,1.95486406825386E-7,1,1.99850670813958,40.0298881530762,1.98262132181331,20.0299993157387,0.0508096911830957,0.00924727963491815,0.25,2.94492008419919E-5,0.00450402696392574,5.13348898755696E-5,11.2379818,11.2397585,999.777282714844,999.777282714844,62.9007734565836,20.8513633360228,5.154188,0,0,0,80,4882,11.15145,999.777282714844,,,,,,,,,,,,,0,,,,0.6920922,,,,,,11.23887015,,,,
,2394607.22,10.7345972,999.777282714844,,,2,,,,20.0560002241135,,,,,,,10.7345972,10.7345972,999.777282714844,999.777282714844,,,4.781127,,,,-99999999,4882,10.7643,999.777282714844,,,,,,,,,,,,,,,,,,,,,,,10.7345972,,,,
,2394859.165,10.3823371,999.777282714844,0.00459753001282429,2.58353722564647E-7,1,1.99850670813958,40.0298881530762,1.98328496017055,20.0399998575449,0.051603341030953,0.00939118393530135,0.25,2.98530988623642E-5,0.00457291237332938,5.20738053969986E-5,10.3805456,10.3841286,999.777282714844,999.777282714844,62.7264702967951,20.846780648825,5.154188,0,0,0,80,4882,10.28135,999.777282714844,,,,,,,,,,,,,0,,,,0.6649819,,,,,,10.3823371,,,,
,2395068.965,10.03369045,999.777282714844,0.00462697480434627,2.91701781441348E-7,1,1.99850670813958,40.0298881530762,1.98227872340115,20.0399998575449,0.0519090384809906,0.00944502558966478,0.25,2.98897094896734E-5,0.00460220297849702,5.22535818735963E-5,10.0321646,10.0352163,999.777282714844,999.777282714844,62.7780577790643,20.8528859645074,5.154188,0,0,0,80,4882,9.9305,999.777282714844,,,,,,,,,,,,,0,,,,0.65182755,,,,,,10.03369045,,,,
,2395272.77,9.6914854,999.777282714844,0.0046532535668262,2.70384560631675E-7,1,1.99850670813958,40.0298881530762,1.99357188587643,20.0500003993511,0.052487114147806,0.00955178522481316,0.25,3.0194784443617E-5,0.00462834293413087,5.26849804988142E-5,9.6895752,9.6933956,999.777282714844,999.777282714844,62.7444477527374,20.8471450799813,4.781127,0,0,0,80,4882,9.58495,999.777282714844,,,,,,,,,,,,,0,,,,0.6357421,,,,,,9.6914854,,,,
,2395582.57,9.18056345,999.777282714844,0.00469654633390234,2.37102154710888E-7,1,1.99850670813958,40.0298881530762,1.99351289706713,20.0500003993511,0.0529733596050589,0.00964397547000876,0.25,3.07933801589493E-5,0.00467140595074694,5.34911698321754E-5,9.1786127,9.1825142,999.777282714844,999.777282714844,62.6420544167182,20.8535229763941,5.154188,0,0,0,80,4882,9.0672,999.777282714844,,,,,,,,,,,,,0,,,,0.5611185,,,,,,9.18056345,,,,
,2395796.4,8.83047105,999.777282714844,0.00472339382793634,2.7333019060146E-7,1,1.99850670813958,40.0298881530762,1.99371990744396,20.0500003993511,0.0532810372144007,0.0097025716499025,0.25,3.1191007739336E-5,0.00469811091481653,5.40173946849355E-5,8.8277273,8.8332148,999.777282714844,999.777282714844,62.8101045483528,20.8476110479218,4.781127,0,0,0,80,4882,8.70755,999.777282714844,,,,,,,,,,,,,0,,,,0.5002142,,,,,,8.83047105,,,,
,2396002.255,8.48258875,999.777282714844,0.00474804680171831,2.86381863455243E-7,1,1.99850670813958,40.0298881530762,1.98239881677116,20.0800001621246,0.0532705761905229,0.00969241005685187,0.25,3.0641455832665E-5,0.00472263750138939,5.35907953123344E-5,8.4801378,8.4850397,999.777282714844,999.777282714844,62.8249554902182,20.8547290309329,4.781127,0,0,0,80,4882,8.35705,999.777282714844,,,,,,,,,,,,,0,,,,0.4664297,,,,,,8.48258875,,,,
,2396313.95,7.97622915,999.777282714844,0.00477126435888991,3.42290618870229E-7,1,1.99850670813958,40.0298881530762,1.98248581991382,20.0800001621246,0.0535334256016756,0.00973971449408289,0.25,3.0746412740335E-5,0.00474573383032952,5.3808243126736E-5,7.9714417,7.9810166,999.777282714844,999.777282714844,62.4529003150643,20.8540033920004,4.781127,0,0,0,80,4882,7.86555,999.777282714844,,,,,,,,,,,,,0,,,,0.43711035,,,,,,7.97622915,,,,
,2396523.82,7.62741975,999.777282714844,0.00475256233806658,2.98585264002224E-7,1,1.99850670813958,40.0298881530762,1.98239828707134,20.1200004667044,0.0533212849938436,0.00970158088248351,0.25,3.06658102358891E-5,0.00472713342057407,5.36370520360506E-5,7.618444,7.6363955,999.777282714844,999.777282714844,62.6498707019105,20.8560824549496,4.781127,0,0,0,80,4886,7.464,999.777282714844,,,,,,,,,,,,,0,,,,0.41998805,,,,,,7.62741975,,,,
,2396727.67,7.28710795,999.777282714844,0.00415936499049711,2.35821350445798E-7,1,1.99850670813958,40.0298881530762,1.98221198802769,20.1200004667044,0.0466621330496223,0.00848772638324057,0.25,2.6644060982222E-5,0.00413711231054965,4.67491648693305E-5,7.2840223,7.2901936,999.777282714844,999.777282714844,62.5490406229297,20.8601142043774,5.154188,0,0,0,80,4886,7.1471,999.777282714844,,,,,,,,,,,,,0,,,,0.4015208,,,,,,7.28710795,,,,
,2397041.44,6.7720804,999.777282714844,0.00384108474327851,2.03221641742855E-7,1,1.99850670813958,40.0298881530762,1.98248187268895,20.1200004667044,0.0430963412277879,0.0078435715629938,0.25,2.49894812666109E-5,0.00382053465498311,4.35540904240416E-5,6.770699,6.7734618,999.777282714844,999.777282714844,62.7944719779682,20.8584747527616,5.154188,0,0,0,80,4886,6.64385,999.777282714844,,,,,,,,,,,,,0,,,,0.3669959,,,,,,6.7720804,,,,
,2397253.31,6.43106225,999.777282714844,0.00373819023919259,1.84200387371829E-7,1,1.99850670813958,40.0298881530762,1.99373623705278,20.1399996876717,0.0421685328984033,0.00767659656720717,0.25,2.44819823681513E-5,0.00371819077656263,4.2548434465084E-5,6.4254351,6.4366894,999.777282714844,999.777282714844,62.7530456664489,20.8503063698188,4.781127,0,0,0,80,4886,6.26605,999.777282714844,,,,,,,,,,,,,0,,,,0.34737985,,,,,,6.43106225,,,,
,2397463.105,6.07957575,999.777282714844,0.00367352455147698,2.9379498861949E-7,1,1.99850670813958,40.0298881530762,1.99388979803214,20.1399996876717,0.0414427892386993,0.00754056415606278,0.25,2.37226492085702E-5,0.00365387349925992,4.14783710650624E-5,6.0787463,6.0804052,999.777282714844,999.777282714844,62.8171392050259,20.8506124750163,4.781127,0,0,0,80,4886,5.91195,999.777282714844,,,,,,,,,,,,,0,,,,0.3255358,,,,,,6.07957575,,,,
,2397705.12,5.69504665,999.777282714844,0.00362618547711112,2.76449555606707E-7,1,1.99850670813958,40.0298881530762,1.98288915878364,20.1600007712841,0.0406938507501951,0.00740251987250587,0.25,2.32639209477033E-5,0.00360678914202802,4.0791654849676E-5,5.6899171,5.7001762,999.777282714844,999.777282714844,62.4708777710066,20.8491048504791,5.154188,0,0,0,80,4886,5.4893,999.777282714844,,,,,,,,,,,,,0,,,,0.3065967,,,,,,5.69504665,,,,
,2397982.72,5.2302923,999.777282714844,0.00358606015589909,2.00841393935366E-7,1,1.99850670813958,40.0298881530762,1.98271526175535,20.1600007712841,0.0402410161635629,0.00731532560903783,0.25,2.25906769436355E-5,0.00356688116417549,3.99266777785972E-5,5.2302475,5.2303371,999.777282714844,999.777282714844,62.7483558953336,20.8563897041083,4.781127,0,0,0,80,4886,5.0397,999.777282714844,,,,,,,,,,,,,0,,,,0.2830474,,,,,,5.2302923,,,,
,2398200.515,4.8847029,999.777282714844,0.00356651475032832,1.44490235882645E-7,1,1.99850670813958,40.0298881530762,1.98285648354469,20.1600007712841,0.0400249679343541,0.00727276686574052,0.25,2.21842829701191E-5,0.00354744204549734,3.94273063891161E-5,4.880208,4.8891978,999.777282714844,999.777282714844,62.8374615465259,20.8541549212107,4.781127,0,0,0,80,4886,4.6612,999.777282714844,,,,,,,,,,,,,0,,,,0.2665802,,,,,,4.8847029,,,,
,2398412.4,4.5386429,999.777282714844,0.0035518680740957,1.41071334357641E-7,1,1.99850670813958,40.0298881530762,2.00681473895891,20.1799999922514,0.0403172830937956,0.00733827806680369,0.25,2.31503091496838E-5,0.00353286880834002,4.03169020314262E-5,4.537416,4.5398698,999.777282714844,999.777282714844,62.5631099362759,20.8561756754899,4.781127,0,0,0,80,4886,4.2982,999.777282714844,,,,,,,,,,,,,0,,,,0.2485754,,,,,,4.5386429,,,,
,2398726.15,4.02856945,999.777282714844,0.00353880246937052,2.81064633445145E-7,1,1.99850670813958,40.0298881530762,2.00681383372776,20.1799999922514,0.0401700187125469,0.00730524141923709,0.25,2.25336569044175E-5,0.00351987584971484,3.96399302502433E-5,4.0265746,4.0305643,999.777282714844,999.777282714844,62.6803542141605,20.857474846312,5.154188,0,0,0,80,4886,3.76505,999.777282714844,,,,,,,,,,,,,0,,,,0.2216003,,,,,,4.02856945,,,,
,2398945.93,3.68089445,999.777282714844,0.00353332521295177,1.99064765029989E-7,1,1.99850670813958,40.0298881530762,1.99406958789891,20.1900005340576,0.0398666724079329,0.00724148801624698,0.25,2.17619965790095E-5,0.00351443144596067,3.88457107298012E-5,3.6794674,3.6823215,999.777282714844,999.777282714844,62.6850439852759,20.8529644595739,5.154188,0,0,0,80,4886,3.3789,999.777282714844,,,,,,,,,,,,,0,,,,0.2015342,,,,,,3.68089445,,,,
,2399171.765,3.33744075,999.777282714844,0.00353014667435812,1.64600257755709E-7,1,1.99850670813958,40.0298881530762,1.99431335468073,20.1900005340576,0.0398368835181417,0.00722762092719866,0.25,2.10169576794363E-5,0.00351127329356643,3.80891594966031E-5,3.3354297,3.3394518,999.777282714844,999.777282714844,62.8054147772374,20.8489609379211,5.154188,0,0,0,80,4886,2.9733,999.777282714844,,,,,,,,,,,,,0,,,,0.1805613,,,,,,3.33744075,,,,
,2400047.135,3.02284245,999.777282714844,0.00352448365660083,1.93450143809379E-7,1,1.99850670813958,40.0298881530762,1.99425780484515,20.2099997550249,0.0397727310587174,0.00721120417041728,0.25,2.05733459331049E-5,0.00350564231824804,3.76203378435285E-5,3.0207055,3.0249794,999.777282714844,999.777282714844,62.7764945220259,20.8546429096219,5.154188,0,0,0,80,4881,2.59935,999.777282714844,,,,,,,,,,,,,0,,,,0.1569948,,,,,,3.02284245,,,,