File: PPMS_Data_and_Plotting/Data/RuCl3/Data/RuCl3_TB001_HeatCapacity_1.csv
[Header]
TITLE,RuCl3_TB001_HeatCapacity_1.dat
BYAPP,HeatCapacity,3.9.6,1.7
INFO,33,MASS:Sample Mass (mg)
INFO,0.1,MASSERR:Sample Mass Error (mg)
INFO,207.43,MOLWGHT:Formula Weight (g/mole)
INFO,4,ATOMS:Atoms per Formula Unit
INFO,PPMS Heat Capacity Option 3.9.6 Build 3,APPNAME
DATATYPE,TIME,1
DATATYPE,COMMENT,2
STARTUPAXIS, X, 8, LINEAR, AUTO
STARTUPAXIS, Y1, 10, LINEAR, AUTO
#TB THE FOLLOWING 2 LINES WERE BELOW COLUMN HEADERS SO I HAD TO MOVE THEM HERE
3144097.61,Error: Temperature of platform does not match the system temperature : System = 16.006 K;  Platform = 17.025 K
3144936.58,CALFILE: C:\QdPpms\HEATCA~1\TempCal\Standard\Puck1960_9.cal|Addenda #3 measured on 05/02/2025 from 2.8972 to 302.75 K

[Data]
Time Stamp (Seconds),Comment (),System Status (Code),Puck Temp (Kelvin),System Temp (Kelvin),Field (Oersted),Pressure (Torr),Sample Temp (Kelvin),Temp Rise (Kelvin),Samp HC (J/mole-K),Samp HC Err (J/mole-K),Addenda HC (�J/K),Addenda HC Err (�J/K),Total HC (�J/K),Total HC Err (�J/K),Fit Deviation (ChiSquare),Time Const tau1 (seconds),Time Const tau2 (seconds),Sample Coupling (Percent),Debye Temp (Kelvin),Debye Temp Err (Kelvin),Cal Correction (Factor),Therm Resist (Ohms),Htr Resist (Ohms),Puck Resist (Ohms),Wire Cond (W/K),Meas Time (seconds),Temp Squared (K^2),Samp HC/Temp (J/mole-K/K),Addenda Offset HC (�J/K)
3144936.72,,5905,,15.9974,0.021,9.1E-6,15.449737,0.38809342,3.4097252,0.01169,43.838577,0.04798,586.29112,0.8708,0.17464073,24.516109,0.0030759311,99.818408,203.14146,0.317,1,,,,2.3951773E-5,41.511169,238.69438,0.22069794,0
3145309.38,,5905,,15.9956,0.021,9.2E-6,15.414538,0.31961599,3.4046658,0.0113,43.531198,0.04772,585.17884,0.7333,5.0720692,25.135865,0.0046743685,99.729399,202.77998,0.2993,1,,,,2.3334762E-5,49.857706,237.60797,0.22087369,0
3145811.48,,5905,,15.8686,0.021,9.1E-6,15.32988,0.32089027,3.3742317,0.01211,42.99228,0.04727,579.79817,1.033,0.46093336,25.490993,0.0063509158,99.636145,202.27673,0.3373,1,,,,2.2816435E-5,50.362937,235.00522,0.22010816,0
3146299.78,,5905,,15.7414,0.021,9E-6,15.254481,0.31683218,3.3419914,0.01185,42.502327,0.04686,574.17911,0.9779,0.31291308,25.183698,0.0058658814,99.65935,201.9332,0.3308,1,,,,2.2866472E-5,51.081345,232.6992,0.2190826,0
3146701.52,,5905,,15.7364,0.021,9.1E-6,15.287276,0.31875495,3.3536568,0.01139,42.715436,0.04704,576.24807,0.8181,1.0382194,25.087281,0.005164568,99.6994,202.13019,0.3104,1,,,,2.302911E-5,50.302601,233.7008,0.2193757,0
3147174.02,,5905,,15.6016,0.021,9.1E-6,15.179393,0.3108787,3.3025732,0.01081,42.024748,0.04646,567.4305,0.6509,2.6871205,24.546729,0.0037791569,99.775133,201.74288,0.2898,1,,,,2.3161013E-5,48.971013,230.41397,0.21756951,0
3147666.86,,5905,,15.4741,0.021,9.2E-6,15.058525,0.30486333,3.2483103,0.01049,41.257175,0.0458,558.03025,0.5779,5.0425603,24.253251,0.0032635574,99.803189,201.25463,0.2808,1,,,,2.3047389E-5,49.02827,226.75917,0.21571238,0
3148031.27,,5905,,15.4791,0.021,9.1E-6,15.060283,0.30645384,3.252213,0.01053,41.272737,0.04582,558.6667,0.5913,7.8710288,24.221451,0.0027241725,99.835424,201.19689,0.2824,1,,,,2.3097572E-5,48.376025,226.81214,0.21594634,0
3148517.7,,5905,,15.3439,0.021,9E-6,14.92915,0.30253891,3.1970453,0.01037,40.44986,0.04508,549.06721,0.5876,3.5641599,24.018968,0.0028536379,99.825687,200.59542,0.2823,1,,,,2.289399E-5,47.937103,222.87953,0.21414784,0
3148980.66,,5905,,15.2122,0.021,9.1E-6,14.789411,0.29647733,3.1410622,0.01029,39.579364,0.04424,539.29036,0.6219,0.54854344,23.720683,0.0023174512,99.85619,199.90098,0.2872,1,,,,2.2763143E-5,48.06041,218.72669,0.21238588,0
3149337.42,,5905,,15.2075,0.021,9E-6,14.785678,0.29773124,3.1365721,0.01028,39.561944,0.04423,538.55861,0.6219,0.25095851,23.821504,0.0031800781,99.803586,199.94658,0.2873,1,,,,2.2646287E-5,47.205792,218.61626,0.21213584,0
3149797,,5905,,15.0775,0.021,9.1E-6,14.655158,0.29379,3.0914275,0.01022,38.759388,0.04337,530.57401,0.6508,0.47265479,23.73656,0.0036517826,99.772431,199.14901,0.2912,1,,,,2.2396421E-5,46.873359,214.77367,0.21094466,0
3150257.34,,5905,,14.9465,0.021,9E-6,14.536659,0.29088279,3.0397653,0.009784,38.032271,0.04252,521.62796,0.5249,7.2017267,23.497789,0.0027509077,99.826588,198.65973,0.2746,1,,,,2.2232172E-5,47.576052,211.31446,0.20911031,0
3150612.88,,5905,,14.9512,0.021,9.1E-6,14.53843,0.29305945,3.0432875,0.009921,38.049657,0.04254,522.20569,0.5817,22.000302,23.697947,0.0036686737,99.770457,198.60671,0.2822,1,,,,2.2079491E-5,46.915619,211.36595,0.2093271,0
3151069.98,,5905,,14.8165,0.021,9.1E-6,14.413001,0.28255073,2.9989808,0.00985,37.304479,0.04158,514.41178,0.6032,0.42772588,23.156367,,,197.86494,0.2855,1,,,,2.2214701E-5,46.668419,207.7346,0.2080747,0
3151544.31,,5905,,14.6865,0.021,9.1E-6,14.287432,0.2835759,2.9473101,0.009458,36.534932,0.04049,505.42195,0.4952,4.6161423,23.143822,0.002771091,99.821224,197.28836,0.2706,1,,,,2.1871975E-5,46.69522,204.13071,0.2062869,0
3151895.3,,5905,,14.6865,0.021,9.1E-6,14.287716,0.28612179,2.9465825,0.009521,36.541939,0.0405,505.31319,0.5256,0.34351261,23.162116,0.0030207598,99.805322,197.30863,0.2749,1,,,,2.1852993E-5,46.346807,204.13883,0.20623188,0
3152347.05,,5905,,14.5519,0.021,9.1E-6,14.156158,0.27521368,2.9046495,0.009494,35.775162,0.03934,497.87531,0.5648,0.26575967,22.848612,,,196.43411,0.2804,1,,,,2.1790177E-5,45.695418,200.39681,0.20518629,0
3152798.08,,5905,,14.4225,0.021,9.1E-6,14.025671,0.26995654,2.8575354,0.009262,35.007094,0.03812,489.61187,0.5217,3.6093285,22.710228,,,195.69377,0.2744,1,,,,2.1559091E-5,45.701048,196.71945,0.20373609,0
3153166,,5905,,14.4271,0.021,9.1E-6,14.025625,0.27253615,2.8588603,0.00935,35.008602,0.03812,489.82415,0.5583,4.2997492,22.726433,,,195.66272,0.2796,1,,,,2.1553059E-5,45.476286,196.71817,0.20383121,0
3153611.95,,5905,,14.2923,0.021,9.1E-6,13.897876,0.26937942,2.8177963,0.009143,34.26915,0.03692,482.55184,0.5189,0.24163074,22.604812,,,194.82332,0.2738,1,,,,2.1347306E-5,45.215511,193.15095,0.20275015,0
3154061.16,,5905,,14.1637,0.021,9.1E-6,13.767945,0.26371552,2.7765934,0.008959,33.52034,0.03569,475.24806,0.4883,1.4112057,22.495235,,,193.95724,0.2691,1,,,,2.1126611E-5,45.105559,189.55631,0.20167087,0
3154380.88,,5905,,14.1637,0.021,9.1E-6,13.770676,0.27272579,2.7733214,0.008848,33.524036,0.03569,474.73122,0.4402,0.20220723,22.667231,0.0029494619,99.80145,194.07239,0.2621,1,,,,2.0979497E-5,44.979826,189.63151,0.20139327,0
3154824.11,,5905,,14.0335,0.021,9.1E-6,13.643369,0.27086862,2.7345375,0.008743,32.800788,0.03451,467.83785,0.4435,0.19970441,22.529013,0.0028964082,99.802519,193.18784,0.2622,1,,,,2.0801551E-5,45.11503,186.14153,0.20042978,0
3155292.13,,5905,,13.9015,0.021,9.1E-6,13.512337,0.2600453,2.6983675,0.008771,32.077111,0.03336,461.3599,0.5038,7.4707976,22.300181,,,192.1879,0.2709,1,,,,2.0688616E-5,45.253975,182.58326,0.19969658,0
3155635.16,,5905,,13.8971,0.021,9.1E-6,13.518785,0.26873631,2.6983902,0.008619,32.101534,0.0334,461.38793,0.4335,3.2941419,22.49778,0.0027609352,99.810163,192.27907,0.2603,1,,,,2.0541925E-5,45.097468,182.75754,0.19960302,0
3156076.63,,5905,,13.7671,0.021,9.1E-6,13.39204,0.26512224,2.6571874,0.008605,31.396892,0.03233,454.12834,0.483,0.24709885,22.328666,0.0025536413,99.822061,191.46063,0.2677,1,,,,2.0369773E-5,44.671,179.34673,0.19841543,0
3156518.17,,5905,,13.6362,0.021,9.1E-6,13.262223,0.26046619,2.6083035,0.008473,30.683848,0.03133,445.63837,0.4858,0.68881032,22.165351,0.0026075466,99.816262,190.78734,0.2684,1,,,,2.0137271E-5,44.65224,175.88656,0.19667167,0
3156834.19,,5905,,13.6362,0.021,9E-6,13.262369,0.26230577,2.6128187,0.008464,30.688904,0.03133,446.36174,0.4759,0.36028558,22.17663,0.0026795418,99.811023,190.67898,0.2666,1,,,,2.0160626E-5,44.364816,175.89044,0.19700995,0
3157295.58,,5905,,13.5062,0.021,9E-6,13.133662,0.2596319,2.566048,0.00834,29.992503,0.03044,438.2246,0.4795,2.0619306,22.065204,0.0028383887,99.797938,189.97387,0.2675,1,,,,1.9895337E-5,44.016674,172.49307,0.19537948,0
3157754.39,,5905,,13.3764,0.021,9E-6,13.002767,0.24929524,2.5222591,0.008329,29.304283,0.02969,430.57002,0.5256,1.9880696,21.685517,,,189.16721,0.2749,1,,,,1.9855188E-5,44.105355,169.07195,0.19397864,0
3158088.3,,5905,,13.3723,0.021,9.1E-6,13.002532,0.2508102,2.5238728,0.008305,29.304138,0.02969,430.82659,0.5143,0.46304392,21.721924,,,189.12331,0.2731,1,,,,1.9833721E-5,43.675576,169.06584,0.19410625,0
3158542.39,,5905,,13.2467,0.021,9.1E-6,12.873784,0.2471835,2.4757132,0.008158,28.628303,0.02907,422.48905,0.5092,1.9084918,21.53988,,,188.46179,0.2728,1,,,,1.9614271E-5,43.040103,165.73432,0.19230656,0
3158972.83,,5905,,13.1098,0.021,9.1E-6,12.746862,0.24230478,2.4282567,0.007966,27.967389,0.02859,414.27829,0.4846,1.7364471,21.32647,,,187.81601,0.2694,1,,,,1.9425545E-5,42.866364,162.4825,0.19049839,0
3159279.45,,5905,,13.1098,0.021,9.1E-6,12.746725,0.24404436,2.4297915,0.007974,27.967753,0.02859,414.52282,0.486,0.3539561,21.339605,,,187.77429,0.2695,1,,,,1.9425046E-5,42.573376,162.47899,0.19062085,0
3159705.61,,5905,,12.9799,0.021,9.1E-6,12.617632,0.24104918,2.3786422,0.007845,27.308497,0.02821,405.72624,0.4917,1.0158156,21.119118,,,187.20006,0.2712,1,,,,1.9211325E-5,42.057834,159.20464,0.18851732,0
3160150.7,,5905,,12.8488,0.021,9.1E-6,12.487485,0.23674983,2.3319149,0.007692,26.649446,0.02791,397.63335,0.4825,2.255759,20.944916,,,186.50244,0.2703,1,,,,1.8984719E-5,42.02397,155.93727,0.18674016,0
3160450.56,,5905,,12.848,0.021,9.1E-6,12.489276,0.24354687,2.329938,0.007581,26.648384,0.02791,397.31778,0.439,0.35795004,21.101673,0.0026211531,99.801192,186.5821,0.263,1,,,,1.8861383E-5,41.563482,155.98201,0.18655509,0
3160872.83,,5905,,12.7184,0.021,9.1E-6,12.361885,0.24255366,2.2856443,0.007523,26.013388,0.02769,389.63612,0.467,0.40158616,20.919185,0.0023109611,99.822462,185.86789,0.2681,1,,,,1.8654633E-5,41.767118,152.8162,0.18489448,0
3161296.31,,5905,,12.5879,0.021,9.2E-6,12.234831,0.23225087,2.2426343,0.007233,25.395616,0.02751,382.17589,0.3929,2.3793313,20.400897,,,185.12944,0.2559,1,,,,1.8733289E-5,41.831549,149.69108,0.18329917,0
3161593.19,,5905,,12.5849,0.021,9.1E-6,12.238349,0.24012372,2.2432907,0.007271,25.404506,0.02751,382.2892,0.4105,0.52025392,20.742924,0.0019194862,99.850671,185.16456,0.2588,1,,,,1.8453884E-5,41.496402,149.77719,0.1833001,0
3162011.31,,5905,,12.4549,0.021,9E-6,12.110422,0.23666272,2.1999737,0.00713,24.784084,0.02735,374.77749,0.4021,0.18288628,20.577751,0.0017575785,99.861554,184.42699,0.2576,1,,,,1.8234775E-5,40.966945,146.66232,0.18165954,0
3162431.41,,5905,,12.3217,0.021,9.1E-6,11.979249,0.2299301,2.1573344,0.00711,24.161519,0.02719,367.37145,0.4438,4.1783646,20.276258,,,183.62642,0.2655,1,,,,1.8118306E-5,41.857484,143.50241,0.18008929,0
3162745.7,,5905,,12.3217,0.021,9.1E-6,11.977582,0.22884471,2.1565363,0.007071,24.155671,0.02719,367.23863,0.4286,0.45814777,20.296164,,,183.62357,0.2628,1,,,,1.8093992E-5,40.615512,143.46247,0.18004771,0
3163158.69,,5905,,12.1929,0.021,9.1E-6,11.848751,0.22555158,2.1146015,0.007005,23.545521,0.02701,359.95708,0.4494,0.44734739,20.112933,,,182.84419,0.2669,1,,,,1.7896797E-5,40.189306,140.3929,0.1784662,0
3163571.13,,5905,,12.0602,0.021,9.2E-6,11.721507,0.22152372,2.0700883,0.00678,22.946801,0.02679,352.27676,0.4084,2.2036687,19.927652,,,182.17072,0.2601,1,,,,1.7677786E-5,40.188886,137.39372,0.17660599,0
3163860.59,,5905,,12.0603,0.021,9.2E-6,11.721356,0.22312579,2.0700924,0.006822,22.946947,0.02679,352.27757,0.4258,0.40882362,19.928764,,,182.16826,0.2633,1,,,,1.767684E-5,39.878977,137.3902,0.17660861,0
3164289.91,,5905,,11.9277,0.021,9.1E-6,11.593932,0.22079859,2.0265394,0.006698,22.355103,0.02652,344.75688,0.4248,6.7673523,19.783096,,,181.47214,0.2637,1,,,,1.7426842E-5,39.569394,134.41925,0.17479311,0
3164698.17,,5905,,11.7971,0.021,9.2E-6,11.465462,0.21661603,1.9860285,0.006509,21.7642,0.02619,337.72111,0.3935,1.7419687,19.6219,,,180.67556,0.2582,1,,,,1.7211438E-5,39.637699,131.45683,0.17321836,0
3164984.55,,5905,,11.8006,0.021,9.1E-6,11.465319,0.21802414,1.9870122,0.00656,21.764269,0.02619,337.87767,0.4134,0.4206143,19.624432,,,180.64342,0.2619,1,,,,1.7217194E-5,39.289714,131.45353,0.17330632,0
3165388.45,,5905,,11.6648,0.021,9E-6,11.336451,0.21525861,1.9450755,0.00637,21.181712,0.02579,330.62341,0.3834,0.34146763,19.458418,,,179.88978,0.2567,1,,,,1.6991279E-5,38.92445,128.51512,0.17157711,0
3165812.53,,5905,,11.5356,0.021,9.1E-6,11.206203,0.21144351,1.9050662,0.006235,20.597468,0.02534,323.6741,0.3738,2.3242114,19.312614,,,179.06119,0.2551,1,,,,1.6759725E-5,39.07372,125.57898,0.17000105,0
3166094.88,,5905,,11.5321,0.021,9.1E-6,11.205825,0.21285868,1.9060513,0.006271,20.596636,0.02534,323.82998,0.3877,0.51351452,19.343577,,,179.02425,0.2577,1,,,,1.6740957E-5,38.683384,125.57051,0.17009469,0
3166497.23,,5905,,11.4004,0.021,9.1E-6,11.079365,0.21014093,1.8679646,0.006144,20.037287,0.02486,317.21142,0.3793,0.45934979,19.209186,,,178.20063,0.2564,1,,,,1.6513528E-5,38.389793,122.75233,0.16859852,0
3166916.77,,5905,,11.2722,0.021,9.1E-6,10.954856,0.2119599,1.8270211,0.005842,19.485544,0.02433,310.14599,0.2964,2.7420457,19.211629,0.0022882937,99.797396,177.50631,0.24,1,,,,1.6172448E-5,38.763515,120.00886,0.16677729,0
3167215.98,,5905,,11.2722,0.021,9.1E-6,10.954983,0.21338218,1.8265233,0.005875,19.48655,0.02433,310.06781,0.3132,0.47551694,19.177731,0.0022760315,99.798184,177.52452,0.2435,1,,,,1.6196836E-5,38.435442,120.01166,0.16672991,0
3167615.83,,5905,,11.1417,0.021,9.1E-6,10.824721,0.2106634,1.790883,0.005735,18.926433,0.02374,303.83767,0.2948,0.42993209,19.090828,0.0020763783,99.813533,176.5711,0.2396,1,,,,1.594152E-5,38.181361,117.17458,0.1654438,0
3168016.73,,5905,,11.0137,0.021,9.1E-6,10.695012,0.20135708,1.7600399,0.005704,18.383939,0.02312,298.38837,0.3207,2.1847084,18.849016,,,175.46966,0.2447,1,,,,1.5830448E-5,38.226724,114.38327,0.16456644,0
3168310.34,,5905,,11.0105,0.021,9.1E-6,10.696472,0.20677625,1.758654,0.005641,18.385176,0.02313,298.16911,0.294,1.7412683,19.042124,0.0024526004,99.777011,175.53976,0.2391,1,,,,1.5689212E-5,37.64399,114.41451,0.1644144,0
3168706.53,,5905,,10.8792,0.021,9.1E-6,10.567988,0.20488095,1.7263968,0.005579,17.849277,0.02248,292.50142,0.3085,0.28162104,18.909968,0.0020077149,99.814442,174.50591,0.2419,1,,,,1.5493463E-5,37.740737,111.68238,0.16336097,0
3169102.2,,5905,,10.7478,0.021,9.1E-6,10.438334,0.20010189,1.6920362,0.005385,17.316108,0.02179,286.50183,0.262,2.5371154,18.780883,0.0018999117,99.821613,173.5251,0.2319,1,,,,1.527904E-5,37.684984,108.95882,0.16209829,0
3169377.42,,5905,,10.7446,0.021,9E-6,10.438895,0.20237756,1.6921896,0.005407,17.319559,0.02179,286.52968,0.2728,0.43752297,18.829139,0.0021822627,99.795606,173.52918,0.2342,1,,,,1.5244871E-5,37.562941,108.97054,0.16210428,0
3169789.92,,5905,,10.6139,0.021,9E-6,10.312952,0.19923653,1.6619878,0.005274,16.810935,0.0211,281.21627,0.2489,1.6785619,18.760274,0.0022940412,99.782074,172.46877,0.2286,1,,,,1.5018932E-5,37.239301,106.35697,0.1611554,0
3170183.58,,5905,,10.486,0.021,9.1E-6,10.182164,0.18996193,1.6349675,0.005252,16.297591,0.02037,276.40427,0.2764,1.8176271,18.560637,,,171.21531,0.234,1,,,,1.4891961E-5,37.207135,103.67646,0.16057172,0
3170456.19,,5905,,10.486,0.021,9E-6,10.1822,0.19173373,1.635582,0.00524,16.300431,0.02037,276.50487,0.27,0.28967838,18.55148,,,171.19444,0.2326,1,,,,1.4904734E-5,37.053486,103.67719,0.1606315,0
3170846.36,,5905,,10.3538,0.021,9.1E-6,10.056346,0.18890172,1.6097054,0.005211,15.808668,0.01964,271.8964,0.2908,0.55893544,18.50593,,,169.9804,0.2364,1,,,,1.4692393E-5,36.953316,101.1301,0.16006861,0
3171236.5,,5905,,10.2237,0.021,9.1E-6,9.9278425,0.18491825,1.5731336,0.005101,15.313928,0.01887,265.58347,0.2883,9.3902038,18.35946,,,169.10022,0.2361,1,,,,1.4465756E-5,36.956176,98.562057,0.15845675,0
3171505.48,,5905,,10.2207,0.021,9.1E-6,9.927996,0.18655798,1.5730947,0.005121,15.315279,0.01887,265.57861,0.2972,0.44920914,18.378011,,,169.10423,0.2381,1,,,,1.445089E-5,36.70574,98.565104,0.15845037,0
3171910.58,,5905,,10.0937,0.021,9.1E-6,9.8008026,0.18836412,1.537474,0.004877,14.828179,0.01809,259.42462,0.2293,2.3914111,18.412185,0.0020327714,99.794807,168.21799,0.2227,1,,,,1.411559E-5,36.512176,96.055732,0.15687225,0
3172299.03,,5905,,9.9603,0.021,9.1E-6,9.6713553,0.18392236,1.505621,0.004759,14.346208,0.01728,253.87517,0.2156,6.9284071,18.27722,0.0019025638,99.804459,167.15932,0.2192,1,,,,1.3914479E-5,36.5299,93.535113,0.15567838,0
3172567.73,,5905,,9.9603,0.021,9.1E-6,9.6699225,0.18164687,1.5089207,0.004898,14.347971,0.01728,254.40188,0.2786,0.24226398,18.213846,,,167.01256,0.2336,1,,,,1.3967499E-5,36.3857,93.507401,0.15604269,0
3172954.28,,5905,,9.8291,0.021,9.2E-6,9.5418027,0.17886349,1.4812987,0.004759,13.879522,0.01648,249.53906,0.2511,0.40801115,18.137517,,,165.81839,0.2267,1,,,,1.3758171E-5,36.257316,91.045999,0.15524307,0
3173342.22,,5905,,9.6984,0.021,9E-6,9.4138842,0.17454335,1.4540935,0.004665,13.419064,0.01566,244.75053,0.2433,1.4661327,18.112568,,,164.6099,0.2243,1,,,,1.3512746E-5,36.249826,88.621215,0.15446265,0
3173610.39,,5905,,9.6955,0.021,9.1E-6,9.4143536,0.17635066,1.4532439,0.004679,13.421317,0.01566,244.61761,0.2512,0.40295056,18.071622,,,164.6502,0.2262,1,,,,1.3536008E-5,36.159425,88.630053,0.1543647,0
3173997.7,,5905,,9.5644,0.021,9.1E-6,9.2870146,0.17399586,1.4287907,0.004552,12.971344,0.01485,240.27738,0.2232,0.41048136,18.077277,,,163.34494,0.2187,1,,,,1.329168E-5,36.168911,86.24864,0.15384822,0
3174384.63,,5905,,9.4318,0.021,9.1E-6,9.1594799,0.17351818,1.4037828,0.00438,12.522421,0.01404,235.84997,0.166,1.2662354,18.251563,0.0019855893,99.78324,162.05302,0.2038,1,,,,1.2947351E-5,36.19108,83.896072,0.1532601,0
3174670.2,,5905,,9.4318,0.021,9.1E-6,9.1604665,0.17669728,1.4046139,0.004407,12.526911,0.01405,235.98668,0.1816,0.23747174,18.260506,0.0018556246,99.797508,162.03849,0.2075,1,,,,1.2946852E-5,36.551035,83.914146,0.15333432,0
3175056.14,,5905,,9.3025,0.021,9.2E-6,9.0333781,0.17386114,1.3867055,0.004352,12.093455,0.01327,232.70417,0.18,0.19517579,18.301011,0.00202764,99.774717,160.47567,0.2059,1,,,,1.2741179E-5,36.644277,81.60192,0.15350907,0
3175445.23,,5905,,9.1736,0.021,9E-6,8.9044883,0.16898018,1.3689753,0.004235,11.661515,0.01254,229.45154,0.1354,2.4483866,18.395136,0.0018476268,99.791442,158.86625,0.1936,1,,,,1.2496979E-5,36.662155,79.289911,0.15373992,0
3175714.16,,5905,,9.171,0.021,9.1E-6,8.9051603,0.17154725,1.3689282,0.004263,11.664584,0.01255,229.44712,0.156,0.1359164,18.390624,0.0018695556,99.788967,158.88007,0.1986,1,,,,1.2500082E-5,36.810637,79.301881,0.15372303,0
3176103.56,,5905,,9.0401,0.021,9.2E-6,8.7770879,0.16888643,1.3565191,0.004229,11.244659,0.01189,227.05303,0.1584,0.15981074,18.54338,0.0018884418,99.783272,157.07132,0.1973,1,,,,1.2268454E-5,37.084631,77.037271,0.1545523,0
3176494.61,,5905,,8.9101,0.021,9.1E-6,8.6487828,0.16373895,1.3462249,0.004122,10.830613,0.01131,225.00128,0.09421,0.87274862,18.783191,0.0020994422,99.75557,155.16889,0.1797,1,,,,1.2005461E-5,37.149134,74.801445,0.15565484,0
3176768.97,,5905,,8.9101,0.021,9.1E-6,8.6498363,0.16665899,1.3468585,0.004171,10.834837,0.01131,225.10631,0.1369,0.0739752,18.767202,0.002060244,99.75992,155.16344,0.19,1,,,,1.2020822E-5,37.530411,74.819668,0.15570914,0
3177185.16,,5905,,8.7778,0.021,9.1E-6,8.5233487,0.1649575,1.3434254,0.004109,10.436613,0.01085,224.16191,0.0888,0.4266828,19.108641,0.0022081394,99.739124,153.02465,0.176,1,,,,1.1758814E-5,38.340043,72.647473,0.15761709,0
3177582.39,,5905,,8.6455,0.021,9E-6,8.3921337,0.15808679,1.3446909,0.004099,10.033815,0.01049,223.96043,0.07097,0.19351761,19.473736,0.0021755725,99.738378,150.62157,0.169,1,,,,1.1528168E-5,38.123007,70.427908,0.1602323,0
3177863.48,,5905,,8.6479,0.021,9E-6,8.3939351,0.16207716,1.3438597,0.004155,10.039111,0.01049,223.8335,0.1314,0.015501859,19.420304,0.0020533124,99.752688,150.68497,0.1833,1,,,,1.1551819E-5,38.928224,70.458147,0.16009889,0
3178266.55,,5905,,8.5145,0.021,9E-6,8.2680992,0.15975354,1.3531422,0.004198,9.6608666,0.01026,224.93201,0.1435,0.024352493,19.962449,0.0021155481,99.741628,148.0857,0.1827,1,,,,1.1294494E-5,39.885151,68.361465,0.1636582,0
3178676.55,,5905,,8.386,0.021,9.2E-6,8.1368517,0.15253957,1.3739105,0.004229,9.2754899,0.01013,227.85065,0.1181,1.2373821,20.706693,0.0021880543,99.728792,144.99664,0.1728,1,,,,1.103126E-5,39.929637,66.208356,0.16885038,0
3178994.94,,5905,,8.3834,0.021,9.2E-6,8.139421,0.15760517,1.3746548,0.004269,9.2820996,0.01013,227.97568,0.1485,0.097903543,20.647817,0.0020618841,99.743775,145.01623,0.1795,1,,,,1.1067255E-5,41.428363,66.250174,0.16888853,0
3179442.44,,5905,,8.2532,0.021,9.1E-6,8.0113867,0.15570622,1.4101801,0.004489,8.9147145,0.01009,233.26,0.2188,1.3216855,21.682852,0.0025202129,99.682934,141.52596,0.1891,1,,,,1.0789466E-5,43.412475,64.182317,0.17602197,0
3179896.05,,5905,,8.121,0.021,9.1E-6,7.8789844,0.14451573,1.4903471,0.005768,8.5448835,0.0101,245.64392,0.5708,4.918196,23.493464,0.0025012356,99.682036,136.64395,0.2477,1,,,,1.0486916E-5,42.967713,62.078395,0.18915472,0
3180274.81,,5905,,8.121,0.021,9.1E-6,7.8826399,0.15464639,1.4894393,0.005863,8.5545972,0.0101,245.50922,0.5954,6.489819,23.615217,0.0033628157,99.575009,136.73513,0.2526,1,,,,1.0437569E-5,47.046605,62.136012,0.18895184,0
3180784.95,,5905,,7.9898,0.021,9.2E-6,7.7569054,0.15578689,1.6741584,0.01028,8.2105992,0.01015,274.55215,1.423,112.94661,27.680895,0.0052419624,99.343438,129.4073,0.3606,1,,,,9.9801717E-6,54.986285,60.169581,0.21582813,0
3181322.77,,5905,,7.8591,0.021,9.1E-6,7.6126692,0.11865262,2.3192452,0.03016,7.8272994,0.01023,376.79559,4.666,20.593906,37.260014,,,113.90365,0.5927,1,,,,1.0112599E-5,54.579894,57.952733,0.30465599,0
3181906.44,,5905,,7.859,0.021,9.1E-6,7.6264354,0.16206071,2.1856747,0.02888,7.8644425,0.01022,355.58302,4.472,27.478294,39.48141,0.011380655,98.650566,116.3947,0.6135,1,,,,9.1241828E-6,76.868071,58.162518,0.28659191,0
3183793.48,,5905,,7.7262,0.021,9.1E-6,7.4947528,0.19388215,4.1493723,0.1327,7.5309181,0.01029,667.65379,21.01,181.71836,94.595315,0.048121342,95.219632,92.22336,1.069,1,,,,7.404574E-6,187.63478,56.171319,0.55363699,0
3186849.17,,5905,,7.5946,0.021,9.1E-6,7.3792714,0.13345751,12.498139,0.2926,7.2148492,0.0103,1995.5415,46.15,3883.9834,190.24572,0.0063058626,99.071397,61.338417,0.6132,1,,,,1.0586895E-5,387.52114,54.453646,1.693682,0
3189559.95,,5905,,7.5966,0.021,9.2E-6,7.378512,0.13008829,12.637643,0.2872,7.2124961,0.0103,2017.7327,45.29,13537.328,188.99557,0.0044533456,99.33407,61.069852,0.5963,1,,,,1.0747148E-5,378.35057,54.44244,1.7127631,0
3192171.45,,5905,,7.4652,0.021,9.1E-6,7.250296,0.13006004,4.5927358,0.06764,6.8948051,0.01019,737.55229,10.53,478.92841,72.548829,,,86.191153,0.5078,1,,,,1.0166288E-5,146.96968,52.566793,0.63345494,0
3193743.72,,5905,,7.3343,0.021,9.1E-6,7.1225642,0.13033909,3.1694836,0.03019,6.5825449,0.009896,510.8151,4.553,316.67123,52.343677,,,95.981159,0.3871,1,,,,9.7588693E-6,106.47785,50.730921,0.44499193,0
3194530.94,,5905,,7.3324,0.021,9.1E-6,7.1220406,0.1295272,3.1662935,0.02995,6.5815981,0.009894,510.30665,4.514,225.10838,52.273461,,,96.006584,0.385,1,,,,9.762251E-6,104.71301,50.723462,0.44457674,0
3195343.58,,5905,,7.2008,0.021,9.1E-6,6.9948808,0.12910242,2.4091904,0.0183,6.2777307,0.009345,389.55539,2.669,28.104461,41.287386,,,103.33676,0.3442,1,,,,9.4352155E-6,83.319825,48.928358,0.34442194,0
3196075.95,,5905,,7.0728,0.021,9.2E-6,6.8749548,0.13939246,1.9411724,0.01427,5.9958122,0.008527,314.81656,2.068,582.24103,34.238207,,,109.16678,0.3533,1,,,,9.1948904E-6,82.574438,47.265003,0.2823542,0
3196605.91,,5905,,7.071,0.021,9E-6,6.8682256,0.12729493,1.9198418,0.01288,5.9828202,0.008481,311.4101,1.827,17.089882,33.973667,,,109.463,0.3284,1,,,,9.1662197E-6,67.91914,47.172522,0.27952516,0
3197860.28,,5905,,6.9371,0.021,9.1E-6,6.6526698,0.1252418,1.4420195,0.007322,5.4972911,0.006234,234.90791,0.9346,1.8424875,26.918589,,,116.65161,0.2759,1,,,,8.7266054E-6,54.166899,44.258016,0.21675802,0
3198362.45,,5905,,6.8196,0.021,9.1E-6,6.5300058,0.12996186,1.2512829,0.00607,5.2295573,0.004906,204.29592,0.7541,35.098213,24.076029,,,120.04777,0.2725,1,,,,8.485449E-6,53.67289,42.640976,0.19162048,0
3198703.42,,5905,,6.8267,0.021,9.1E-6,6.5255777,0.12323045,1.2463316,0.005815,5.2207963,0.004867,203.49946,0.7034,6.7618988,23.76137,,,120.12506,0.2631,1,,,,8.5642984E-6,48.081359,42.583164,0.19099177,0
3199157.27,,5905,,6.6942,0.021,9.1E-6,6.3977463,0.12177275,1.0984387,0.005196,4.9500396,0.003926,179.70045,0.6348,3.2963994,21.629006,,,122.83761,0.2725,1,,,,8.3083085E-6,43.692374,40.931157,0.17169151,0
3199637.17,,5905,,6.5452,0.021,9E-6,6.2847433,0.12278549,0.9880457,0.004292,4.7160772,0.003764,161.90408,0.4892,15.634826,20.114421,,,125.00478,0.2557,1,,,,8.0491546E-6,42.748326,39.497998,0.15721337,0
3199928.83,,5905,,6.5402,0.021,9E-6,6.2835141,0.12088961,0.98244417,0.004283,4.7148635,0.003765,161.01172,0.4899,1.769824,20.083436,,,125.21748,0.2571,1,,,,8.0171404E-6,40.128024,39.48255,0.15635266,0
3200328.23,,5905,,6.4295,0.021,9.1E-6,6.1583587,0.11883572,0.87777433,0.003786,4.4625315,0.004659,144.10749,0.4285,6.947547,18.360856,,,127.41975,0.2588,1,,,,7.8486255E-6,36.869128,37.925382,0.14253381,0
3200736.03,,5905,,6.2773,0.021,9.1E-6,6.0347485,0.12102943,0.78587828,0.003355,4.2191688,0.006966,129.2444,0.376,8.0450726,16.948693,,,129.55101,0.2605,1,,,,7.6256263E-6,36.711457,36.418189,0.13022552,0
3200988.09,,5905,,6.2821,0.021,9E-6,6.0326928,0.11689826,0.78534766,0.003378,4.2162175,0.007003,129.15703,0.3814,3.1248741,16.931213,,,129.53604,0.2624,1,,,,7.6283388E-6,33.827979,36.393382,0.13018194,0
3201355.66,,5905,,6.161,0.021,9.1E-6,5.9070582,0.11543943,0.70477505,0.002897,3.9770782,0.01054,116.09961,0.3113,3.4753012,15.7266,,,131.49869,0.2544,1,,,,7.3823719E-6,31.374485,34.893336,0.11931067,0
3201712.14,,5905,,6.0146,0.021,9.1E-6,5.7826885,0.11716804,0.63231786,0.002682,3.7481638,0.01444,104.34349,0.2983,3.2023709,14.434755,,,133.47044,0.2666,1,,,,7.2286293E-6,31.455354,33.439486,0.10934669,0
3201936.67,,5905,,6.0113,0.021,9.1E-6,5.7816409,0.11541679,0.63215334,0.002687,3.7449011,0.0145,104.31406,0.2997,6.0097601,14.546595,0.00071835208,99.857147,133.45783,0.2671,1,,,,7.1805653E-6,28.850245,33.427371,0.10933805,0
3202269.78,,5905,,5.874,0.021,9.1E-6,5.6555011,0.11123303,0.57152481,0.002351,3.5260884,0.01796,94.449864,0.2524,2.3345538,13.478536,,,135.00819,0.2614,1,,,,7.0074274E-6,26.989158,31.984692,0.10105644,0
3202597.48,,5905,,5.771,0.021,9.1E-6,5.5314332,0.11255114,0.51403798,0.002229,3.3197532,0.02017,85.097959,0.253,8.2309359,12.560132,,,136.79598,0.2794,1,,,,6.775244E-6,26.933162,30.596753,0.092930342,0
3202800.42,,5905,,5.7752,0.021,9.1E-6,5.5304375,0.10975554,0.51113537,0.002304,3.3188722,0.02017,84.635303,0.2705,8.7938557,12.465796,,,137.02976,0.2905,1,,,,6.7894023E-6,25.149702,30.585739,0.09242223,0
3203112.45,,5905,,5.6232,0.021,9E-6,5.4039629,0.10685156,0.46218245,0.001951,3.1225164,0.02031,76.651036,0.2151,4.8578981,11.611363,,,138.46562,0.2752,1,,,,6.6013816E-6,23.273696,29.202815,0.085526578,0
3203408.63,,5905,,5.4832,0.021,9.1E-6,5.2801568,0.10747605,0.41645369,0.001787,2.9424559,0.0182,69.195996,0.2004,2.9510647,10.842954,,,140.07437,0.283,1,,,,6.3816553E-6,23.17216,27.880055,0.078871464,0
3203589.56,,5905,,5.4809,0.021,9.1E-6,5.2784863,0.105006,0.41468991,0.001841,2.9403521,0.01817,68.913292,0.2133,3.3361371,10.822075,,,140.22831,0.2929,1,,,,6.3678445E-6,21.701829,27.862418,0.078562277,0
3203878.81,,5905,,5.3667,0.021,9.1E-6,5.1533277,0.10253167,0.37439306,0.001614,2.7690399,0.01482,62.331162,0.182,1.7057736,10.121125,,,141.64871,0.2875,1,,,,6.1585211E-6,20.256946,26.556786,0.072650738,0
3204159.64,,5905,,5.2266,0.021,9.1E-6,5.0291334,0.10420022,0.33721344,0.001442,2.602628,0.01144,56.249852,0.1618,2.1536853,9.3740245,0.0003610855,99.912647,143.13934,0.2882,1,,,,6.0053808E-6,20.074458,25.292182,0.067051999,0
3204322.09,,5905,,5.2265,0.021,9.1E-6,5.02766,0.10153807,0.33610835,0.001343,2.6011704,0.01141,56.072585,0.1391,1.3440669,9.4276652,0.00092563578,99.777649,143.25407,0.2688,1,,,,5.9597182E-6,18.703901,25.277365,0.066851846,0
3204596.78,,5905,,5.1058,0.021,9.1E-6,4.9012062,0.096760803,0.30125159,0.001262,2.437336,0.009243,50.363396,0.1383,0.83328847,8.6294177,,,144.84183,0.2857,1,,,,5.836245E-6,17.488741,24.021822,0.061464787,0
3204860.69,,5905,,4.9626,0.021,9.1E-6,4.7771579,0.097145703,0.27106468,0.001202,2.275111,0.00906,45.398741,0.1394,1.9998481,8.0790551,,,146.23324,0.3053,1,,,,5.6193132E-6,17.544303,22.821237,0.056741831,0
3205007.52,,5905,,4.9873,0.021,9.1E-6,4.7757689,0.095208732,0.27060831,0.001121,2.2738285,0.009065,45.324855,0.1212,1.5319024,8.1405792,,,146.27285,0.2852,1,,,,5.5677678E-6,16.415008,22.807969,0.056662773,0
3205258.72,,5905,,4.8219,0.021,9.2E-6,4.6501312,0.0936671,0.2407068,0.000995,2.1090258,0.01012,40.403025,0.1077,1.4110065,7.5096678,0.0003641302,99.901918,148.09369,0.2881,1,,,,5.3848801E-6,15.070316,21.623721,0.051763441,0
3205505.63,,5905,,4.7202,0.021,9.1E-6,4.5274255,0.09143418,0.21764665,0.0009453,1.9502037,0.01127,36.575569,0.1071,0.38963556,6.9657486,,,149.10817,0.3049,1,,,,5.2507736E-6,15.147516,20.497582,0.048072939,0
3205638.58,,5905,,4.6981,0.021,9E-6,4.5260583,0.089402177,0.2160649,0.0009497,1.9481425,0.01128,36.321868,0.1089,0.67911151,6.9579037,,,149.45787,0.341,1,,,,5.2202315E-6,14.132261,20.485204,0.047737985,0
3205881.02,,5905,,4.5812,0.021,9E-6,4.4027085,0.087467501,0.19288359,0.0008076,1.7894547,0.0115,32.475269,0.0879,0.57457759,6.4875394,,,150.95818,0.2976,1,,,,5.0057914E-6,13.286402,19.383842,0.043810212,0
3206118.64,,5905,,4.4385,0.021,9.2E-6,4.2783687,0.086173774,0.17173346,0.0008092,1.6325588,0.01012,28.953603,0.09807,1.0284834,6.0204687,,,152.48503,0.337,1,,,,4.8091942E-6,12.894801,18.304438,0.04013994,0
3206239.23,,5905,,4.4338,0.021,9.1E-6,4.2776797,0.084468545,0.17147414,0.0007045,1.6309675,0.0101,28.910756,0.07567,0.47569189,5.9584894,0.00071451947,99.774328,152.5373,0.2949,1,,,,4.8618E-6,11.95117,18.298543,0.040085782,0
3206458.75,,5905,,4.3013,0.021,9E-6,4.1535895,0.082535743,0.15334053,0.0007505,1.4811826,0.007831,25.876098,0.09342,0.64914596,5.5809856,,,153.7347,0.3517,1,,,,4.6364746E-6,11.601267,17.252306,0.036917593,0
3206691.16,,5905,,4.1974,0.021,9E-6,4.0285501,0.082382372,0.13660647,0.0006877,1.3383476,0.005542,23.071046,0.08737,0.8700121,5.2475976,0.0011338518,99.603369,154.96215,0.3636,1,,,,4.4120351E-6,11.154378,16.229216,0.033909587,0
3206802.17,,5905,,4.1922,0.021,9E-6,4.0272117,0.080762058,0.13498092,0.0006458,1.3375568,0.005531,22.811646,0.0795,0.42099914,5.2441591,0.0013807274,99.521227,155.53003,0.3485,1,,,,4.3684642E-6,10.417168,16.218434,0.033517215,0
3207022.02,,5905,,4.0489,0.021,9.1E-6,3.8997121,0.074836938,0.12063216,0.0006054,1.2081856,0.004222,20.399534,0.07665,0.5242818,4.7386272,,,156.35517,0.3658,1,,,,4.3049459E-6,9.534752,15.207755,0.030933607,0
3207233.56,,5905,,3.9398,0.021,9.1E-6,3.7754108,0.07787257,0.10581082,0.0005959,1.0952369,0.004045,17.92866,0.07991,0.52752767,4.416791,0.00026632802,99.894786,158.13268,0.4091,1,,,,4.0629742E-6,9.6298424,14.253727,0.028026305,0
3207333.7,,5905,,3.9054,0.021,9.2E-6,3.7736492,0.07546034,0.10472433,0.0005095,1.0943546,0.004046,17.754928,0.06342,0.27393727,4.4349891,0.0012730323,99.501816,158.60362,0.3609,1,,,,4.0210302E-6,8.8740905,14.240428,0.027751474,0
3207538.47,,5905,,3.8059,0.021,9.1E-6,3.6479561,0.069962549,0.093335385,0.0006097,0.99314997,0.004318,15.841859,0.08583,0.56072914,4.0265345,,,159.31924,0.4669,1,,,,3.9343656E-6,8.0842605,13.307584,0.025585665,0
3207738.69,,5905,,3.6525,0.021,9.1E-6,3.5261406,0.073563885,0.081840151,0.0004593,0.90409703,0.00435,13.924031,0.06149,0.35368179,3.7997367,0.00067856153,99.705217,160.89583,0.4149,1,,,,3.6739473E-6,8.2972548,12.433667,0.023209554,0
3207831.94,,5905,,3.6513,0.021,9.1E-6,3.5241229,0.067215978,0.0815336,0.0005199,0.90322765,0.004347,13.874393,0.07265,0.31889321,3.6163513,,,161.00504,0.4625,1,,,,3.8365722E-6,7.4456347,12.419442,0.023135856,0
3208028.09,,5905,,3.518,0.021,9E-6,3.3994826,0.06758565,0.070581489,0.0004179,0.81950284,0.003819,12.048299,0.05712,0.3131481,3.3979084,0.00039699792,99.815441,162.96086,0.4399,1,,,,3.5514939E-6,6.8864139,11.556482,0.020762421,0
3208227.7,,5905,,3.4031,0.021,9E-6,3.2766252,0.065439243,0.062194848,0.0005356,0.74355983,0.003053,10.638127,0.07971,0.69881096,3.1193767,,,163.83584,0.6031,1,,,,3.4103373E-6,6.8123799,10.736273,0.018981374,0
3208312.5,,5905,,3.403,0.021,9.1E-6,3.2755884,0.065284429,0.061575636,0.0004256,0.74320506,0.003049,10.539262,0.06085,0.37316361,3.224322,0.001752925,99.165471,164.33119,0.5047,1,,,,3.2924532E-6,6.2686319,10.72948,0.018798343,0
3208495.89,,5905,,3.2535,0.021,9.1E-6,3.1500605,0.060446315,0.053829503,0.0004416,0.67019807,0.002363,9.2339236,0.06524,0.24114632,2.8951781,,,165.27718,0.5845,1,,,,3.1894147E-6,5.67566,9.9228814,0.017088403,0
3208752,,5905,,3.1268,0.021,9.1E-6,3.0255463,0.059899752,0.047109662,0.0004335,0.59996227,0.001945,8.0946296,0.06509,0.21216326,2.6454629,,,165.95918,0.6452,1,,,,3.059816E-6,5.65565,9.1539306,0.01557063,0
3208831.63,,5905,,3.1452,0.021,9.2E-6,3.0243398,0.057285303,0.046480025,0.0004191,0.59906666,0.001942,7.9935652,0.06277,0.38396993,2.5894445,,,166.63873,0.6371,1,,,,3.0869807E-6,5.1703143,9.1466313,0.015368652,0
3209021.5,,5905,,2.9904,0.021,9.1E-6,2.8995282,0.057138984,0.03988035,0.0003345,0.52992304,0.001796,6.8744804,0.04962,0.41336753,2.4985915,0.0022347468,98.731423,168.1287,0.6056,1,,,,2.7814808E-6,4.7850531,8.4072638,0.013754082,0
3209059.92,,5905,,3.0052,0.021,9.1E-6,2.9005834,0.058285299,0.039754364,0.0003704,0.53045959,0.001796,6.8549739,0.05572,0.28575655,2.435897,0.0016110971,99.067471,168.36737,0.6613,1,,,,2.8367114E-6,4.997183,8.4133841,0.013705644,0
3211261.48,Error: Temperature of platform does not match the system temperature : System = 8.0098 K;  Platform = 7.7025 K
3212844.23,,5905,,7.9998,0.021,9E-6,7.7642515,0.14825023,1.6781043,0.01034,8.2312268,0.01015,275.20053,1.432,13.51133,27.600218,0.0040808187,99.488112,129.42815,0.3616,1,,,,1.0019242E-5,51.586798,60.283601,0.21613214,0
3213063.34,,5905,,8,0.021,9.1E-6,7.7681241,0.1562024,1.6661116,0.009962,8.2403478,0.01015,273.30173,1.366,14.687366,27.198087,0.0046826048,99.408145,129.80295,0.3536,1,,,,1.0104848E-5,55.200436,60.343753,0.21448056,0
3213279.23,,5905,,7.9999,0.021,9.1E-6,7.7666918,0.15563546,1.6614128,0.0101,8.2374202,0.01015,272.55128,1.393,4.9432481,27.403371,0.0049641093,99.378545,129.90136,0.3589,1,,,,1.0004407E-5,54.396175,60.321502,0.21391512,0
3213576.23,,5905,,7.9566,0.021,9.1E-6,7.7208956,0.14740195,1.7829777,0.01297,8.1144303,0.01017,291.76802,1.876,76.089236,29.717743,0.0043831806,99.451812,126.12809,0.4046,1,,,,9.8691306E-6,54.806743,59.612229,0.23092887,0
3213811.09,,5905,,7.9569,0.021,9.2E-6,7.7249662,0.15719314,1.7660599,0.01333,8.1243897,0.01017,289.08653,1.943,19.184391,29.464839,0.0060863331,99.238582,126.59673,0.4186,1,,,,9.8823583E-6,59.435486,59.675103,0.22861717,0
3214041.89,,5905,,7.9569,0.021,9.1E-6,7.7263028,0.15672896,1.7618894,0.01304,8.1285511,0.01017,288.4272,1.892,67.889378,29.45556,0.0058549192,99.269493,126.71858,0.4121,1,,,,9.8600109E-6,58.929678,59.695754,0.22803783,0
3214362.72,,5905,,7.9187,0.021,9.1E-6,7.681006,0.14581765,1.9273287,0.01721,8.0072614,0.01019,314.62562,2.576,108.42885,32.247723,0.00434386,99.454215,122.25779,0.4645,1,,,,9.8073801E-6,58.91112,58.997854,0.25092138,0
3214614.41,,5905,,7.9184,0.021,9.1E-6,7.6895788,0.15848713,1.8877852,0.01685,8.0300851,0.01019,308.35749,2.522,132.3851,32.243309,0.0072054439,99.111833,123.24426,0.468,1,,,,9.64477E-6,64.495447,59.129622,0.24549917,0
3214866.39,,5905,,7.9184,0.021,9.1E-6,7.68978,0.15852158,1.8863255,0.01691,8.0306084,0.01019,308.12579,2.531,37.078743,32.198765,0.0075057147,99.07396,123.27932,0.4697,1,,,,9.6543549E-6,64.486619,59.132717,0.24530293,0
3215212.98,,5905,,7.8742,0.021,9E-6,7.6444289,0.14556531,2.1115565,0.0237,7.9101683,0.01021,343.83729,3.63,204.0566,36.0499,0.0050034848,99.378982,118.02193,0.5422,1,,,,9.5947142E-6,64.39753,58.437294,0.27622161,0
3215491.55,,5905,,7.8745,0.021,9E-6,7.650313,0.16023028,2.0685571,0.02359,7.9262765,0.01021,337.01264,3.618,50.215659,36.129541,0.0090093524,98.903287,118.92733,0.5537,1,,,,9.4265482E-6,72.099801,58.527289,0.27038856,0
3215770.39,,5905,,7.8745,0.021,9.2E-6,7.6508781,0.16042056,2.0641869,0.02351,7.9276582,0.01021,336.31877,3.605,62.411818,35.983774,0.0089669535,98.906449,119.02017,0.5534,1,,,,9.4449489E-6,72.259083,58.535936,0.26979738,0
3216142.67,,5905,,7.8329,0.021,9.1E-6,7.6012238,0.14202838,2.4420738,0.03714,7.7964206,0.01024,396.30548,5.79,184.77209,42.086783,0.0042652708,99.471937,111.78628,0.6648,1,,,,9.464434E-6,71.967548,57.778604,0.32127376,0
3216464.5,,5905,,7.8326,0.021,9.1E-6,7.6084268,0.16326346,2.3512234,0.03641,7.8166484,0.01023,381.87233,5.681,64.45701,42.614949,0.012196126,98.553354,113.32009,0.6842,1,,,,9.0872383E-6,84.173565,57.888159,0.30902884,0
3216789.64,,5905,,7.8347,0.021,9E-6,7.6089541,0.16464856,2.3448662,0.03619,7.8180058,0.01023,380.86233,5.646,56.351392,42.658966,0.012968945,98.46627,113.43059,0.6829,1,,,,9.0615281E-6,85.229898,57.896183,0.30817194,0
3217203.5,,5905,,7.7917,0.021,9.1E-6,7.5610113,0.14043522,2.9399991,0.05939,7.6910733,0.01026,475.41497,9.341,108.34027,51.214511,0.0038595953,99.524384,104.49345,0.7968,1,,,,9.3257588E-6,85.317933,57.168892,0.38883675,0
3217642.69,,5905,,7.7917,0.021,9.1E-6,7.5681723,0.16742039,2.777237,0.05745,7.7134077,0.01025,449.54353,9.04,18684.138,52.888608,0.016551831,98.110899,106.60907,0.8291,1,,,,8.6579618E-6,102.42902,57.277233,0.36696271,0
3218040.2,,5905,,7.7917,0.021,9.1E-6,7.5698981,0.17185782,2.7463216,0.05687,7.7180288,0.01025,444.62982,8.95,136.53102,52.861508,0.01920208,97.826263,107.03416,0.8331,1,,,,8.5917562E-6,105.77722,57.303357,0.36279506,0
3218533.84,,5905,,7.7509,0.021,9.1E-6,7.5146482,0.12957338,3.9331502,0.106,7.5722239,0.01028,633.29635,16.76,50.084409,66.641733,,,94.158707,0.9341,1,,,,9.5029995E-6,105.72302,56.469937,0.52339778,0
3219096.77,,5905,,7.7489,0.021,9.1E-6,7.5235901,0.1695696,3.5600107,0.09768,7.5990575,0.01028,573.9605,15.44,343.09621,70.723387,0.021230971,97.649743,97.497304,0.9794,1,,,,8.3058165E-6,133.28347,56.604408,0.47317978,0
3219617.98,,5905,,7.7509,0.021,9.1E-6,7.5261113,0.17945586,3.4685284,0.09526,7.6071706,0.01027,559.41471,15.06,123.57364,71.529912,0.029221615,96.860943,98.389235,0.9884,1,,,,8.0674205E-6,141.44677,56.642352,0.46086594,0
3220317.72,,5905,,7.7085,0.021,9.2E-6,7.4732235,0.12659659,5.486018,0.178,7.4650224,0.0103,880.23461,28.2,93.289642,93.595901,,,83.598343,0.9976,1,,,,9.4046278E-6,143.05982,55.849069,0.73408992,0
3221096.59,,5905,,7.7065,0.021,9E-6,7.4830764,0.1769273,4.7319541,0.1617,7.4977475,0.01029,760.30344,25.63,330.31298,100.51992,0.030702231,96.771593,88.057731,1.091,1,,,,7.811169E-6,187.1918,55.996433,0.63235411,0
3221929.5,,5905,,7.7085,0.021,9.1E-6,7.484621,0.19083021,4.5817867,0.1562,7.5054117,0.01029,736.421,24.75,708.05585,104.40473,0.045195847,95.515305,89.049139,1.098,1,,,,7.3781336E-6,201.03983,56.019552,0.61216014,0
3223003.77,,5905,,7.6665,0.021,9.1E-6,7.4334352,0.12615071,7.9919959,0.2932,7.362725,0.0103,1278.8079,46.49,193.06264,136.8653,,,72.896043,1.009,1,,,,9.3435508E-6,208.80946,55.255959,1.0751417,0
3224133.69,,5905,,7.6663,0.021,9.1E-6,7.4421965,0.18197489,6.6763382,0.266,7.3960527,0.0103,1069.5335,42.19,452.65327,150.75794,0.040496306,95.926902,77.769539,1.136,1,,,,7.3915374E-6,273.7306,55.386289,0.89709244,0
3225376.38,,5905,,7.6683,0.021,9.1E-6,7.4423358,0.20201287,6.4150916,0.2543,7.4033321,0.0103,1027.9791,40.34,447.1061,162.19171,0.066570454,93.896766,78.862624,1.143,1,,,,6.7442839E-6,301.51588,55.388362,0.86197288,0
3226802.7,,5905,,7.6256,0.021,9.1E-6,7.3889298,0.12250181,12.109715,0.3225,7.2444979,0.0103,1933.7768,50.98,49.293572,186.50523,,,62.168271,0.6922,1,,,,1.0368486E-5,324.38341,54.596284,1.6388998,0
3228139.73,,5905,,7.6257,0.021,9E-6,7.3927465,0.14646971,11.343851,0.3466,7.2565524,0.0103,1811.9476,54.87,899.0414,201.60183,0.014745409,98.131981,63.765157,0.7921,1,,,,9.1574879E-6,373.01046,54.652701,1.5344569,0
3229579.92,,5905,,7.6256,0.021,9E-6,7.3976767,0.16642711,10.404277,0.3624,7.2743879,0.0103,1662.4888,57.43,4761.9611,208.75272,0.032159293,96.331403,65.90776,0.9062,1,,,,8.2646046E-6,403.20366,54.725621,1.4064249,0
3231157.39,,5905,,7.5835,0.021,9E-6,7.3745665,0.13333418,12.829953,0.2962,7.1987959,0.0103,2048.3136,46.72,10240.697,182.36766,0.0031546236,99.503641,60.681303,0.6029,1,,,,1.1287417E-5,417.50545,54.384231,1.7397569,0
3232461.06,,5905,,7.5815,0.021,9E-6,7.3684092,0.11659099,13.279863,0.3208,7.1864654,0.01029,2119.8774,50.63,7033.4923,179.76096,,,59.822221,0.6238,1,,,,1.1792758E-5,364.73533,54.293455,1.80227,0
3233748.42,,5905,,7.5835,0.021,9.2E-6,7.3677916,0.11541804,13.317685,0.3258,7.1849649,0.01029,2125.893,51.43,12728.802,179.75768,,,59.750693,0.6305,1,,,,1.1826437E-5,359.52192,54.284353,1.8075545,0
3235125.61,,5905,,7.5414,0.021,9.2E-6,7.3412736,0.1204417,11.310207,0.5975,7.1130159,0.01028,1806.4518,94.9,49074.981,142.79605,,,63.392239,1.296,1,,,,1.2650573E-5,359.51537,53.894299,1.5406329,0
3236157.22,,5905,,7.5435,0.021,9.1E-6,7.3343005,0.11061079,10.676134,0.5696,7.0982526,0.01028,1705.5624,90.47,62283.023,137.34739,,,64.718524,1.32,1,,,,1.2417873E-5,285.5921,53.791964,1.4556445,0
3237151.25,,5905,,7.5415,0.021,9.1E-6,7.3333769,0.10937698,10.557284,0.563,7.0964021,0.01028,1686.6528,89.42,37399.124,136.56607,,,64.980981,1.322,1,,,,1.2350453E-5,274.69477,53.778417,1.4396211,0
3238916.02,,5905,,7.5014,0.021,9E-6,7.2883896,0.12903828,5.7926955,0.1729,6.9873103,0.01024,928.54616,27.36,8203.0719,86.760367,,,80.015522,0.889,1,,,,1.0702423E-5,187.32353,53.120624,0.79478401,0
3239549.08,,5905,,7.4994,0.021,9.1E-6,7.2861529,0.12613341,5.6603622,0.1533,6.9827767,0.01024,907.48874,24.23,1514.7883,85.566498,,,80.631778,0.8197,1,,,,1.0605655E-5,173.52073,53.088023,0.77686569,0
3240176.39,,5905,,7.5014,0.021,9.1E-6,7.2859147,0.12552008,5.6426062,0.1505,6.9823147,0.01024,904.66349,23.78,1624.7016,85.41839,,,80.716568,0.8092,1,,,,1.0590969E-5,171.133,53.084552,0.77445407,0
3240896.03,,5905,,7.4572,0.021,9E-6,7.250175,0.14013507,4.5720808,0.07321,6.8920815,0.01019,734.26357,11.44,2138.7223,71.896927,,,86.32209,0.5462,1,,,,1.0212725E-5,170.83678,52.565037,0.63061662,0
3241427.67,,5905,,7.4591,0.021,9.1E-6,7.2443728,0.1304746,4.4639076,0.0602,6.8801996,0.01018,717.04243,9.332,582.88435,70.831139,,,86.958532,0.4746,1,,,,1.0123266E-5,143.79385,52.480938,0.61618966,0
3241951.95,,5905,,7.4572,0.021,9.1E-6,7.2439125,0.12973871,4.4566708,0.05953,6.8792859,0.01018,715.89022,9.223,265.3429,70.810727,,,87.000991,0.471,1,,,,1.0109912E-5,141.66228,52.474268,0.6152298,0
3242566.09,,5905,,7.4172,0.021,9.1E-6,7.2065185,0.13652123,3.9479575,0.04499,6.7856277,0.01011,634.86546,6.901,1367.9502,63.423409,,,90.183141,0.425,1,,,,1.0009955E-5,141.62145,51.933909,0.54783146,0
3243038.05,,5905,,7.4172,0.021,9.2E-6,7.2027492,0.13016017,3.9117179,0.04222,6.7781179,0.01011,629.09259,6.447,84.225053,63.096287,,,90.417528,0.4071,1,,,,9.9703584E-6,126.84682,51.879596,0.54308679,0
3243508.19,,5905,,7.4172,0.021,9.1E-6,7.202534,0.1299027,3.9097672,0.04222,6.7774937,0.01011,628.78162,6.447,94.063989,63.041235,,,90.430078,0.4073,1,,,,9.9741323E-6,126.19257,51.876495,0.54283217,0
3244068.47,,5905,,7.375,0.021,9E-6,7.1652289,0.13512462,3.5284804,0.0379,6.6849359,0.01002,568.03023,5.784,276.32023,57.485164,,,93.13216,0.4161,1,,,,9.8813362E-6,126.08247,51.340505,0.4924449,0
3244499.97,,5905,,7.375,0.021,9.1E-6,7.1622155,0.13006444,3.4998551,0.03627,6.6789863,0.01001,563.47028,5.518,107.27158,57.193084,,,93.348849,0.4048,1,,,,9.8520701E-6,114.97033,51.29733,0.48865537,0
3244926.8,,5905,,7.375,0.021,9.1E-6,7.1620774,0.12977767,3.5009888,0.03599,6.6788584,0.01001,563.65052,5.471,93.775581,57.231007,,,93.336864,0.402,1,,,,9.8486913E-6,114.38617,51.295353,0.4888231,0
3245451.63,,5905,,7.3333,0.021,9.1E-6,7.1237167,0.13463485,3.1682259,0.0309,6.5841297,0.009898,510.61659,4.673,1507.0949,52.242852,,,96.009494,0.3949,1,,,,9.7739035E-6,114.46201,50.747339,0.44474338,0
3245843.05,,5905,,7.3333,0.021,9E-6,7.1209376,0.12968206,3.148835,0.02986,6.578868,0.009891,507.52643,4.501,66.483706,52.077822,,,96.170216,0.3863,1,,,,9.7455388E-6,104.4857,50.707752,0.44219387,0
3246234.47,,5905,,7.3333,0.021,9.1E-6,7.1208434,0.12954175,3.1494371,0.02965,6.5785994,0.00989,507.62196,4.466,94.210291,52.072133,,,96.162766,0.384,1,,,,9.7484381E-6,104.15564,50.70641,0.44228428,0
3246715.94,,5905,,7.2912,0.021,9.1E-6,7.0836097,0.13363526,2.884497,0.02603,6.4878358,0.009756,465.38192,3.9,1479.4237,48.24121,,,98.523596,0.3792,1,,,,9.6469787E-6,104.14427,50.177526,0.40720721,0
3247081.25,,5905,,7.2912,0.021,9.1E-6,7.0813277,0.12951386,2.8723944,0.02506,6.4836258,0.00975,463.45231,3.738,79.004477,48.054467,,,98.630835,0.3692,1,,,,9.6443127E-6,96.482419,50.145202,0.40562935,0
3247443.73,,5905,,7.2931,0.021,9.1E-6,7.0812238,0.12937282,2.8714519,0.02485,6.4833378,0.009749,463.30209,3.702,65.504911,48.052855,,,98.640242,0.3668,1,,,,9.6415102E-6,96.108934,50.14373,0.40550222,0
3247897.25,,5905,,7.2497,0.021,9.1E-6,7.0430395,0.13303622,2.6429882,0.02191,6.3910429,0.009586,426.86354,3.244,236.28595,44.736403,,,100.87236,0.3616,1,,,,9.5417492E-6,96.105709,49.604405,0.37526244,0
3248236.84,,5905,,7.2515,0.021,9.1E-6,7.0409718,0.12921445,2.6353056,0.02142,6.3870075,0.009578,425.63728,3.162,149.19701,44.602483,,,100.94111,0.356,1,,,,9.5429056E-6,89.472806,49.575283,0.37428152,0
3248575.94,,5905,,7.2496,0.021,9.1E-6,7.0408488,0.1291003,2.6342569,0.02126,6.3870073,0.009578,425.47044,3.134,44.602763,44.587206,,,100.9528,0.3539,1,,,,9.5424332E-6,89.204966,49.573552,0.3741391,0
3249006.44,,5905,,7.2076,0.021,9.2E-6,7.0018187,0.13216269,2.4385485,0.01895,6.2934205,0.009381,394.24164,2.776,635.2325,41.694151,,,103.02099,0.3498,1,,,,9.4555622E-6,89.174413,49.025466,0.34827358,0
3249325.94,,5905,,7.2095,0.021,9.1E-6,7.0000744,0.12878589,2.4302593,0.01841,6.290081,0.009374,392.91958,2.684,102.04584,41.563707,,,103.11271,0.3428,1,,,,9.4534296E-6,83.388303,49.001042,0.34717621,0
3249644.72,,5905,,7.2076,0.021,9.1E-6,6.9999967,0.12872402,2.429628,0.01848,6.2899207,0.009373,392.81898,2.696,40.614639,41.622022,,,103.12053,0.3439,1,,,,9.4377678E-6,83.127413,48.999954,0.34708987,0
3250055.36,,5905,,7.1663,0.021,9.2E-6,6.9619302,0.13137256,2.2635163,0.01697,6.1993761,0.009151,366.30176,2.47,1589.8194,39.120088,,,105.01751,0.3459,1,,,,9.3635208E-6,83.244045,48.468473,0.32512769,0
3250317.13,,5905,,7.1663,0.021,9.2E-6,6.9606578,0.12822077,2.2597471,0.01644,6.1973097,0.009146,365.70005,2.377,9.5499363,38.972764,,,105.05683,0.3375,1,,,,9.3834776E-6,78.240176,48.450757,0.32464563,0
3250616.41,,5905,,7.1662,0.021,9.1E-6,6.9605176,0.12812045,2.2589449,0.01658,6.1969876,0.009145,365.57212,2.403,70.777928,39.017946,,,105.06718,0.3401,1,,,,9.3693326E-6,77.945527,48.448806,0.32453692,0
3251011.34,,5905,,7.126,0.021,9E-6,6.9214293,0.13069013,2.1039052,0.01544,6.1047755,0.008884,340.81466,2.237,539.21014,36.694954,,,106.98925,0.346,1,,,,9.28778E-6,78.035893,47.906183,0.30396976,0
3251293.06,,5905,,7.1261,0.021,9.1E-6,6.9200478,0.12781338,2.0993073,0.0152,6.1027049,0.008878,340.08112,2.197,62.963678,36.62094,,,107.0461,0.3424,1,,,,9.2865205E-6,73.389908,47.887061,0.30336602,0
3251574.44,,5905,,7.1242,0.021,9E-6,6.9199188,0.12779327,2.098656,0.01508,6.1023954,0.008877,339.97718,2.175,44.729628,36.614521,,,107.0552,0.3402,1,,,,9.2853102E-6,73.241881,47.885277,0.30327754,0
3251951.05,,5905,,7.0828,0.021,9.2E-6,6.8810071,0.13019613,1.9600201,0.01379,6.0114609,0.008582,317.8307,1.98,30.218739,34.638688,,,108.91094,0.3401,1,,,,9.1755988E-6,73.229041,47.348259,0.28484495,0
3252184.8,,5905,,7.0829,0.021,9.1E-6,6.8798938,0.12762349,1.9567911,0.01357,6.0097743,0.008576,317.31531,1.942,16.921667,34.521676,,,108.95328,0.3361,1,,,,9.1917701E-6,69.277375,47.332938,0.28442171,0
3252452.94,,5905,,7.0847,0.021,9.2E-6,6.8796851,0.12735633,1.958709,0.01342,6.0092318,0.008574,317.61987,1.915,342.34556,34.531142,,,108.91435,0.3327,1,,,,9.1980705E-6,69.043353,47.330067,0.2847091,0
3252809.31,,5905,,7.0434,0.021,9.1E-6,6.8412349,0.12942727,1.8372933,0.01173,5.9200748,0.008246,298.21472,1.642,453.65732,32.751068,,,110.64426,0.3185,1,,,,9.1054961E-6,69.062283,46.802495,0.26856164,0
3253064.31,,5905,,7.0416,0.021,9.1E-6,6.8399614,0.12714928,1.8347086,0.01148,5.9178326,0.008238,297.80128,1.597,26.722107,32.717516,,,110.67566,0.3133,1,,,,9.1021969E-6,65.502137,46.785072,0.26823376,0
3253319.78,,5905,,7.0416,0.021,9.1E-6,6.8398846,0.12709986,1.8348846,0.01159,5.9176443,0.008237,297.8291,1.617,75.286917,32.717277,,,110.67087,0.3158,1,,,,9.1031139E-6,65.435033,46.784022,0.26826251,0
3253665.61,,5905,,6.9997,0.021,9.1E-6,6.8001972,0.12883065,1.7301011,0.01038,5.8265001,0.007859,281.06796,1.425,57.232105,31.246294,,,112.20927,0.3066,1,,,,8.9952414E-6,65.434554,46.242682,0.25441925,0
3253910.92,,5905,,6.9997,0.021,9E-6,6.7993126,0.1269371,1.7277285,0.01019,5.8252484,0.007853,280.68925,1.39,215.61741,31.141991,,,110.80536,1.138,1,,,,9.0132083E-6,62.492588,46.230652,0.25410341,0
3254156.06,,5905,,6.9997,0.021,9E-6,6.7990833,0.12678672,1.7273685,0.01024,5.8247026,0.007851,280.63144,1.4,38.781317,31.155871,,,112.29656,0.3501,1,,,,9.0073373E-6,62.283983,46.227534,0.25405903,0