File: PPMS_Data_and_Plotting/Data/NbTi/0004.DAT
[Header]
; VSM Data File (default extension .dat)
; Copyright (c) 2003-2013, Quantum Design, Inc. All rights reserved.
TITLE,
FILEOPENTIME,3949021273.91818,02/18/2025,6:24 am
BYAPP,VSM,1.0,1.0
INFO,DYNACOOL VSM Option Release 1.4.10 Build 1,APPNAME
INFO,Quantum Design Linear Motor Servo Controller,MOTOR_MODULE_NAME
INFO,3101-100 L2,MOTOR_HW_VERSION
INFO,MMC884,MOTOR_SERIAL_NUMBER
INFO,SRV No X-over 01.03.11,MOTOR_SOFTWARE_VERSION
INFO,Quantum Design VSM Detection Module,VSM_MODULE_NAME
INFO,3101-150 F0,VSM_HW_VERSION
INFO,VSM641,VSM_SERIAL_NUMBER
INFO,VSM No X-over 01.02.05 May 20 2008 13:51:47,VSM_SOFTWARE_VERSION
INFO,VPA645,PREAMP_SERIAL_NUMBER
INFO,740,COIL_SERIAL_NUMBER
INFO,0,MOMENT_UNITS
INFO,NbTi,SAMPLE_MATERIAL
INFO,,SAMPLE_COMMENT
INFO,4.3,SAMPLE_MASS
INFO,,SAMPLE_VOLUME
INFO,,SAMPLE_MOLECULAR_WEIGHT
INFO,,SAMPLE_SIZE
INFO,,SAMPLE_SHAPE
DATATYPE,COMMENT,1
DATATYPE,TIME,2
STARTUPAXIS,X,2
STARTUPAXIS,Y1,5
[Data]
Comment,Time Stamp (sec),Temperature (K),Magnetic Field (Oe),Moment (emu),M. Std. Err. (emu),Transport Action,Averaging Time (sec),Frequency (Hz),Peak Amplitude (mm),Center Position (mm),Coil Signal' (mV),Coil Signal" (mV),Range (mV),M. Quad. Signal (emu),M. Raw' (emu),M. Raw" (emu),Min. Temperature (K),Max. Temperature (K),Min. Field (Oe),Max. Field (Oe),Mass (grams),Motor Lag (deg),Pressure (Torr),VSM Status (code),Motor Status (code),Measure Status (code),Measure Count,System Temp. (K),Temp. Status (code),Field Status (code),Chamber Status (code),Motor Current (amps),Motor Heatsink Temp. (C),Map 01,Map 02,Map 03,Map 04,Map 05,Map 06,Map 07,Map 08,Map 09,Map 10,Map 11,Map 12,Map 13,Map 14,Map 15,Map 16
sample offset = 33.45 mm,3949023440.0785,1.8950572013855,-0.198127150535583,1.69915647244546E-5,2.24559583779759E-7,1,0.999253354069792,40.0298881530762,1.99975402877849,17.8900007158518,0.00018685191252033,2.77941438143734E-5,0.25,-4.63479766848912E-7,1.68799828183498E-5,-3.78555627138093E-7,1.8950572013855,1.8950572013855,-0.198127150535583,-0.198127150535583,55.636317998852,20.58955794547,2.10288000106812,0,0,0,40,1.8951381444931,1,4,1,2.249755859375,29.8142719268799,,,,,,,,,,,,,,,,
,3949023512.7635,1.89947080612183,6379.98266601562,-0.137576708838338,0.000302989085567199,1,0.999253354069792,40.0298881530762,1.9996981941228,17.8900007158518,-1.50410832870199,-0.277816025823753,25,-0.00100455170963197,-0.136701191853281,-0.00171664057476646,1.89942026138306,1.89942026138306,6329.94580078125,6430.01953125,55.260354681102,20.5976133867162,2.13713264465332,0,0,0,40,1.90358078479767,1,6,1,2.24533081054687,35.6793746948242,,,,,,,,,,,,,,,,
,3949023575.7255,1.89936947822571,12683.6357421875,-0.102660966527542,0.000300821974536275,1,0.999253354069792,40.0298881530762,1.99980437523536,17.8999993950129,-1.12298099105714,-0.20753529395442,25,-0.000712211416869548,-0.102058961974493,-0.00129175275250335,1.89938461780548,1.89938461780548,12633.62109375,12733.650390625,55.8145293012367,20.5985625746166,2.13732004165649,0,0,0,40,1.91341745853424,1,6,1,2.25234985351562,38.1231689453125,,,,,,,,,,,,,,,,
,3949023638.735,1.89976578950882,18985.693359375,-0.0879547669796897,0.000331714264754115,1,0.999253354069792,40.0298881530762,1.99987936554469,17.8999993950129,-0.962773069295021,-0.177531787633701,25,-0.00053666645139859,-0.087489816370921,-0.00107255732883879,1.89954674243927,1.89954674243927,18935.73046875,19035.65625,56.0529259996021,20.5997453827207,2.13521814346313,0,0,0,40,1.92525482177734,1,6,1,2.24411010742187,38.6119270324707,,,,,,,,,,,,,,,,
,3949023701.653,1.89948731660843,25279.1591796875,-0.123363900297571,0.00133349963711154,1,0.999253354069792,40.0298881530762,1.9998820526683,17.8900007158518,-1.35141427667369,-0.248070626643212,25,-0.000605974317954314,-0.122789525481806,-0.00140640555980652,1.89950847625732,1.89950847625732,25229.16796875,25329.150390625,55.5909835447367,20.5979213547674,2.13523840904236,0,0,0,40,1.93471455574036,1,6,1,2.252197265625,39.1006851196289,,,,,,,,,,,,,,,,
,3949023765.594,1.89928936958313,31682.90234375,-0.066663161744989,0.000299116437420688,1,0.999253354069792,40.0298881530762,1.99978694911658,17.8900007158518,-0.730591781378913,-0.134915121169076,2.5,-0.00037701192143661,-0.0663967543516891,-0.000831263233685121,1.89934694766998,1.89934694766998,31632.85546875,31732.94921875,56.1287439659675,20.602194667423,2.13349294662476,0,0,0,40,1.94197952747345,1,6,1,2.23800659179687,39.5894432067871,,,,,,,,,,,,,,,,
,3949023832.573,1.89987814426422,38376.349609375,-0.0912795298345097,0.000249283922755965,1,0.999253354069792,40.0298881530762,1.99964505600824,17.8900007158518,-1.00092363167062,-0.185385623491393,2.5,-0.000541164642667279,-0.0909791601548842,-0.00118733136992378,1.89985847473145,1.89985847473145,38326.33984375,38426.359375,57.0026046504676,20.6056388286146,2.13246202468872,0,0,0,40,1.9480288028717,1,6,1,2.236328125,40.0782012939453,,,,,,,,,,,,,,,,
,3949023899.4735,1.89942103624344,45068.958984375,-0.0416691564385508,0.000288698103649956,1,0.999253354069792,40.0298881530762,1.99953199221008,17.8900007158518,-0.457450780600347,-0.0833996441811146,2.5,-0.000122699803223399,-0.0415622358452053,-0.000425776956894434,1.89948666095734,1.89948666095734,45018.9765625,45118.94140625,56.086536025929,20.6034959047563,2.13131213188171,0,0,0,40,1.95162725448608,1,6,1,2.23785400390625,40.5669593811035,,,,,,,,,,,,,,,,
,3949023966.453,1.8998094201088,51777.681640625,-0.102679738819421,0.000210306781720841,1,0.999253354069792,40.0298881530762,1.99952682070579,17.8999993950129,-1.12736159345763,-0.209256702676423,2.5,-0.000619602706671251,-0.102484363859464,-0.00137729362848613,1.89986050128937,1.89986050128937,51732.66796875,51822.6953125,56.0482362284867,20.6031793848412,2.13013768196106,0,0,0,40,1.95538187026978,1,6,1,2.2540283203125,40.0782012939453,,,,,,,,,,,,,,,,
,3949024032.4025,1.90003991127014,58375.615234375,-0.157414256174344,8.69700617288714E-5,1,0.999253354069792,40.0298881530762,1.999525712923,17.8900007158518,-1.7292188815325,-0.322190785791862,25,-0.0010510340925154,-0.157215567784544,-0.00222002165087114,1.90011668205261,1.90011668205261,58325.60546875,58425.625,55.7629418189674,20.5980951350305,2.12800765037537,0,0,0,40,1.95777702331543,1,6,1,2.2509765625,40.5669593811035,,,,,,,,,,,,,,,,
,3949024099.3455,1.90003877878189,65078.837890625,-0.125225344122332,0.000100919693109741,1,0.999253354069792,40.0298881530762,1.99931503833903,17.8900007158518,-1.37661061661749,-0.254897625388731,25,-0.000697802661004643,-0.125145822507453,-0.00162701157451655,1.89995098114014,1.89995098114014,65028.81640625,65128.859375,55.5823856310251,20.5969756055246,2.12796401977539,0,0,0,40,1.96036100387573,1,6,1,2.2564697265625,41.055721282959,,,,,,,,,,,,,,,,
,3949024166.2925,1.89985537528992,71772.18359375,-0.0993940490359778,0.000108598258169945,1,0.999253354069792,40.0298881530762,1.99939565514456,17.8900007158518,-1.09343679969453,-0.201776946123735,2.5,-0.000499497641778359,-0.0993886701878227,-0.00123172568246197,1.89986133575439,1.89986133575439,71722.1015625,71822.265625,56.3616692646983,20.6036946560467,2.12715172767639,0,0,0,40,1.96207749843597,1,6,1,2.24136352539062,41.055721282959,,,,,,,,,,,,,,,,
,3949024230.2295,1.89996069669724,78165.7421875,-0.0977426694777037,8.36550373720858E-5,1,0.999253354069792,40.0298881530762,1.99961071710153,17.8999993950129,-1.07599732662379,-0.198160588471566,25,-0.000465227691498707,-0.0977874982103266,-0.00117688035625529,1.90004026889801,1.90004026889801,78115.7265625,78215.7578125,55.7402745919097,20.6017209922061,2.12681221961975,0,0,0,40,1.96400892734528,1,6,1,2.25265502929687,41.5444793701172,,,,,,,,,,,,,,,,
,3949024295.2125,1.8998549580574,84668.5234375,-0.0769129357178422,6.80770623881379E-5,1,0.999253354069792,40.0298881530762,1.9992745126206,17.8900007158518,-0.847144378851087,-0.154970914778585,25,-0.000283718680689293,-0.0769856521595007,-0.000834815348255588,1.89982450008392,1.89982450008392,84618.4765625,84718.5703125,55.5933284302943,20.5980416402181,2.12555193901062,0,0,0,40,1.96642315387726,1,6,1,2.24014282226562,41.5444793701172,,,,,,,,,,,,,,,,
,3949024358.16,1.90006756782532,90967.16796875,-0.0589164543267157,7.29492328630831E-5,1,0.999253354069792,40.0298881530762,1.99929748091382,17.8999993950129,-0.649543403959611,-0.116887293169382,25,-5.53398101659298E-5,-0.0589983987999115,-0.000469522708069068,1.90007162094116,1.90007162094116,90912.046875,91022.2890625,56.2506780149675,20.6007833095285,2.12506628036499,0,0,0,40,1.96866679191589,1,6,1,2.2412109375,41.5444793701172,,,,,,,,,,,,,,,,
,3949024422.094,1.89975792169571,97365.29296875,-0.0429839902905906,9.4102586754579E-5,1,0.999253354069792,40.0298881530762,1.99932281746679,17.8900007158518,-0.474150318559209,-0.0849386811416873,25,-1.30005565687453E-5,-0.0430609845051486,-0.000308717948900558,1.89982175827026,1.89982175827026,97315.296875,97415.2890625,56.1435949078329,20.6022585597618,2.12335753440857,0,0,0,40,1.97068238258362,1,6,1,2.24090576171875,40.5669593811035,,,,,,,,,,,,,,,,
,3949024486.042,1.89992552995682,103767.359375,-0.0291538685422513,7.44909795225138E-5,1,0.999253354069792,40.0298881530762,1.99924134041874,17.8900007158518,-0.321865128148834,-0.0566785791805271,2.5,7.25072870351161E-5,-0.029217176953813,-0.000123232330578823,1.89989912509918,1.89989912509918,103717.390625,103817.328125,56.5813068786021,20.6014355352732,2.12188053131104,0,0,0,40,1.97383165359497,1,6,1,2.24105834960938,42.0332374572754,,,,,,,,,,,,,,,,
,3949024549.9895,1.89997309446335,110165.67578125,-0.0172333191913288,8.00261166281073E-5,1,0.999253354069792,40.0298881530762,1.9992231413417,17.8900007158518,-0.190556433169485,-0.0321907546256572,2.5,0.000159858998316778,-0.0172771742474461,4.73231733383198E-5,1.90005683898926,1.90005683898926,110120.640625,110210.7109375,55.527671634679,20.6041937969502,2.12054753303528,0,0,0,40,1.97670805454254,1,6,1,2.24334716796875,42.0332374572754,,,,,,,,,,,,,,,,
,3949024612.979,1.89995527267456,116468.875,-0.00809697381439629,6.97681583809986E-5,1,0.999253354069792,40.0298881530762,1.99909920958768,17.8900007158518,-0.0898177677820888,-0.0136416194413625,2.5,0.000208368141081304,-0.00812080884031514,0.00015724047611683,1.9000072479248,1.9000072479248,116423.8984375,116513.8515625,55.6574219688713,20.6044451115899,2.11937928199768,0,0,0,40,1.97963631153107,1,6,1,2.23968505859375,42.0332374572754,,,,,,,,,,,,,,,,
,3949024676.9025,1.8995760679245,122866.8671875,-0.00121645792990947,6.20663697142791E-5,1,0.999253354069792,40.0298881530762,1.99921254689145,17.8999993950129,-0.0139353141792928,0.00040373955858051,0.25,0.000253243730339592,-0.00122174481792729,0.000246456481311713,1.89963662624359,1.89963662624359,122816.859375,122916.875,55.974763147679,20.6045123439817,2.11949372291565,0,0,0,40,1.98265218734741,1,6,1,2.23724365234375,42.0332374572754,,,,,,,,,,,,,,,,
,3949024739.8195,1.9000483751297,129159.11328125,0.0019985629788281,4.41745510961642E-5,1,0.999253354069792,40.0298881530762,1.99903962414559,17.8999993950129,0.0216929025199507,0.00610666503227831,0.25,0.000197068137066471,0.00200395983568051,0.000209803755153265,1.90000200271606,1.90000200271606,129109.2265625,129209,55.954440806179,20.6001740360563,2.11848211288452,0,0,0,40,1.98681354522705,1,6,1,2.25341796875,43.0107536315918,,,,,,,,,,,,,,,,
,3949024802.79,1.89975863695145,135462.2421875,0.00216598537890021,3.35861114759766E-6,1,0.999253354069792,40.0298881530762,1.99905808094489,17.8900007158518,0.0239044359283125,0.00443472391771776,0.25,1.62093790791515E-5,0.00217351373285358,2.90052012524758E-5,1.89982509613037,1.89982509613037,135412.265625,135512.21875,55.9653836054482,20.6021251164518,2.11776781082153,0,0,0,40,1.99021255970001,1,6,1,2.23724365234375,42.0332374572754,,,,,,,,,,,,,,,,
,3949024875.7875,1.90012812614441,138500.9140625,0.00222670440260791,3.81059361859573E-6,1,0.999253354069792,40.0298881530762,1.99891449512683,17.8900007158518,0.0245678020371535,0.00460158334432537,0.25,2.06766193937183E-5,0.00223464534942966,3.36712947632737E-5,1.9001088142395,1.9001088142395,138451.75,138550.078125,54.921909532275,20.6044899764013,2.1175582408905,0,0,0,40,1.99258661270142,1,6,1,2.25418090820313,43.0107536315918,,,,,,,,,,,,,,,,
,3949024938.72,1.89991915225983,132292.4765625,0.00211443978706041,9.27307316653887E-6,1,0.999253354069792,40.0298881530762,1.99878200709663,17.8999993950129,0.0232975796460792,0.00451016916225159,0.25,3.2122258925083E-5,0.00212145873082385,4.48433240417714E-5,1.89993929862976,1.89993929862976,132243.171875,132341.78125,55.6941585092751,20.6006900602414,2.11779046058655,0,0,0,40,1.98844695091248,1,6,1,2.22915649414062,42.5219955444336,,,,,,,,,,,,,,,,
,3949025001.6865,1.90012586116791,126074.26171875,0.00258556142491321,5.51397900470127E-5,1,0.999253354069792,40.0298881530762,1.99882421706624,17.8900007158518,0.0280557662922314,0.00791088455301786,0.25,0.000255858028080036,0.00259221449242584,0.000272519371521334,1.90022563934326,1.90022563934326,126024.78125,126123.7421875,55.6613301114674,20.6023452766024,2.11766409873962,0,0,0,40,1.98494493961334,1,6,1,2.24029541015625,42.5219955444336,,,,,,,,,,,,,,,,
,3949025064.632,1.90026754140854,119862.09765625,0.00686202537220897,7.04844415373495E-5,1,0.999253354069792,40.0298881530762,1.99875631977969,17.8900007158518,0.0749072392408564,0.0183511970740875,0.25,0.000438995220875744,0.00687934918474298,0.000483478709179536,1.90016341209412,1.90016341209412,119807.8515625,119916.34375,55.9317735791213,20.6026644140145,2.11792802810669,0,0,0,40,1.98222386837006,1,6,1,2.24395751953125,42.5219955444336,,,,,,,,,,,,,,,,
,3949025128.569,1.90034574270248,113552.05859375,0.0144047810289978,6.84071552106185E-5,1,0.999253354069792,40.0298881530762,1.99884565288949,17.8900007158518,0.158144950724272,0.0332527533499459,2.5,0.000442547724763715,0.0144400369349636,0.000536825531120136,1.90027749538422,1.90027749538422,113502.6015625,113601.515625,55.7996783593713,20.6037369627078,2.1190881729126,0,0,0,40,1.97881948947906,1,6,1,2.23373413085938,42.5219955444336,,,,,,,,,,,,,,,,
,3949025191.525,1.90008467435837,107339.89453125,0.0240730213396999,7.49592892701864E-5,1,0.999253354069792,40.0298881530762,1.99905080653283,17.8999993950129,0.264539035340569,0.0538499812473459,2.5,0.000580677577040151,0.0241255619917309,0.000741573880149823,1.90010857582092,1.90010857582092,107295.3984375,107384.390625,56.1670437634098,20.6048425809504,2.11998271942139,0,0,0,40,1.97545921802521,1,6,1,2.24334716796875,43.0107536315918,,,,,,,,,,,,,,,,
,3949025254.4575,1.90031141042709,101126.91015625,0.0352138807005761,8.41304590135515E-5,1,0.999253354069792,40.0298881530762,1.99890716667141,17.8999993950129,0.387133563092815,0.0769313461640916,2.5,0.000679817397797315,0.0352800385836577,0.000920154286255977,1.90030384063721,1.90030384063721,101077.7890625,101176.03125,55.8379781568136,20.608902129591,2.1208815574646,0,0,0,40,1.97278368473053,1,6,1,2.24029541015625,42.5219955444336,,,,,,,,,,,,,,,,
,3949025317.427,1.90024268627167,94915.83203125,0.0483950428770262,7.56479733538949E-5,1,0.999253354069792,40.0298881530762,1.99889983776973,17.8900007158518,0.532123340023083,0.104151641293092,2.5,0.000787417676394515,0.0484692368762411,0.00112447066170387,1.90022432804108,1.90022432804108,94861.3984375,94970.265625,56.4023139476983,20.6076833466663,2.12070870399475,0,0,0,40,1.97045481204987,1,6,1,2.23617553710938,42.5219955444336,,,,,,,,,,,,,,,,
,3949025380.366,1.90011668205261,88704.234375,0.0632346947050486,6.75387793622914E-5,1,0.999253354069792,40.0298881530762,1.99897648511558,17.8900007158518,0.695289228563106,0.134647141498738,2.5,0.000893548485599548,0.0633073344533742,0.00134226025042331,1.90011155605316,1.90011155605316,88654.78125,88753.6875,55.8504842131213,20.6054098699325,2.12110590934753,0,0,0,40,1.96793460845947,1,6,1,2.24395751953125,42.5219955444336,,,,,,,,,,,,,,,,
,3949025443.295,1.90029579401016,82498.609375,0.0797534366626665,7.57930055830908E-5,1,0.999253354069792,40.0298881530762,1.99886506823507,17.8900007158518,0.876706463286033,0.168549596547689,2.5,0.00100886466127275,0.0798113008085698,0.00158417044819182,1.90024590492249,1.90024590492249,82449.4375,82547.78125,55.9481877780252,20.6081201726266,2.1218478679657,0,0,0,40,1.96607732772827,1,6,1,2.2283935546875,42.0332374572754,,,,,,,,,,,,,,,,
,3949025506.2535,1.90011876821518,76279.90234375,0.0981847929112984,8.53719787153704E-5,1,0.999253354069792,40.0298881530762,1.99870816247888,17.8999993950129,1.07879745194134,0.207009957257284,2.5,0.00119699621776471,0.0982101033627179,0.00191491340754003,1.90013074874878,1.90013074874878,76230.2578125,76329.546875,55.7519990196982,20.6116151561732,2.12151169776917,0,0,0,40,1.96372759342194,1,6,1,2.23892211914062,42.0332374572754,,,,,,,,,,,,,,,,
,3949025570.226,1.90032255649567,69931.57421875,0.119314118075961,7.99284356124132E-5,1,0.999253354069792,40.0298881530762,1.99865383263126,17.8999993950129,1.31054594766554,0.249719879594472,25,0.00129009872309418,0.119284141162759,0.00217120383241711,1.9003574848175,1.9003574848175,69882.1171875,69981.03125,55.9763264047175,20.6088912303868,2.12191605567932,0,0,0,40,1.96182382106781,1,6,1,2.23861694335938,40.5669593811035,,,,,,,,,,,,,,,,
,3949025636.178,1.89955854415894,63393.318359375,0.0462330171569812,0.000253211870407151,1,0.999253354069792,40.0298881530762,1.99894585327991,17.8999993950129,0.507176461023429,0.0990934201913604,2.5,0.000713247000814641,0.0461932504249105,0.00105627269900006,1.89959621429443,1.89959621429443,63343.8046875,63442.83203125,55.9114512376213,20.6100840627307,2.12142705917358,0,0,0,40,1.95910584926605,1,6,1,2.24212646484375,42.0332374572754,,,,,,,,,,,,,,,,
,3949025703.078,1.90015649795532,56747.154296875,0.125833076480164,0.000157233801997349,1,0.999253354069792,40.0298881530762,1.9988259718855,17.8900007158518,1.38082117354222,0.261878534691614,25,0.00124577952438566,0.125651585900936,0.00217886698196632,1.90006589889526,1.90006589889526,56697.44140625,56796.8671875,55.9958671176982,20.6129060917803,2.12020754814148,0,0,0,40,1.95770061016083,1,6,1,2.22732543945313,41.5444793701172,,,,,,,,,,,,,,,,
,3949025769.067,1.89976090192795,50199.615234375,0.0685710314924064,0.000243085945846452,1,0.999253354069792,40.0298881530762,1.99894604003552,17.8900007158518,0.751795618078672,0.143840903799035,2.5,0.000793410606092704,0.0684268597740866,0.00129723656493222,1.89971244335175,1.89971244335175,50150.37890625,50248.8515625,56.3773018350829,20.6121172383592,2.12008237838745,0,0,0,40,1.95507490634918,1,6,1,2.24090576171875,42.0332374572754,,,,,,,,,,,,,,,,
,3949025837.007,1.90039652585983,43463.986328125,0.141477936324194,0.000172440896542154,1,0.999253354069792,40.0298881530762,1.99878061390558,17.8900007158518,1.55055149012026,0.293068107554516,25,0.00133732468671592,0.141084551566313,0.00235857296935155,1.90041303634644,1.90041303634644,43414.359375,43513.61328125,55.8160925582751,20.6098373611437,2.11824727058411,0,0,0,40,1.95192646980286,1,6,1,2.24334716796875,41.5444793701172,,,,,,,,,,,,,,,,
,3949025902.953,1.89933514595032,36917.744140625,0.0516469712932562,0.000293502205144103,1,0.999253354069792,40.0298881530762,1.99886658526146,17.8999993950129,0.565371456656539,0.108554107189874,2.5,0.000647424559909778,0.0514666407629119,0.00100923271051399,1.89919567108154,1.89919567108154,36863.10546875,36972.3828125,55.9560040632175,20.6138463797712,2.11804604530334,0,0,0,40,1.94718873500824,1,6,1,2.23770141601562,42.0332374572754,,,,,,,,,,,,,,,,
,3949025968.8995,1.90047025680542,30357.2880859375,0.109269974456732,0.000255869916985107,1,0.999253354069792,40.0298881530762,1.99877880356685,17.8999993950129,1.19600438413754,0.225452122195163,2.5,0.00102999347473347,0.108815300001529,0.00176608831640466,1.90045642852783,1.90045642852783,30307.279296875,30407.296875,55.7691948471213,20.6112040423564,2.11731195449829,0,0,0,40,1.942342877388,1,6,1,2.2467041015625,44.9657897949219,,,,,,,,,,,,,,,,
,3949026034.8515,1.90038913488388,23791.2392578125,0.11870689131619,0.000260427056960949,1,0.999253354069792,40.0298881530762,1.99899819406542,17.8900007158518,1.29881559437947,0.243278067836846,25,0.00102287816594082,0.118133481889281,0.00178072991698424,1.90035939216614,1.90035939216614,23741.33203125,23841.146484375,56.3851181202752,20.6129275868417,2.11662578582764,0,0,0,40,1.93424773216248,1,6,1,2.24578857421875,41.5444793701172,,,,,,,,,,,,,,,,
,3949026099.815,1.89997404813766,17327.7470703125,0.108885148001909,0.000290954665221247,1,0.999253354069792,40.0298881530762,1.99918652943663,17.8999993950129,1.19077097635611,0.222655154521778,25,0.000948841170749337,0.108290800694561,0.00159849799289693,1.8999537229538,1.8999537229538,17277.80859375,17377.685546875,56.5789619930445,20.6213370810231,2.11518359184265,0,0,0,40,1.92396819591522,1,6,1,2.24761962890625,41.5444793701172,,,,,,,,,,,,,,,,
,3949026163.759,1.90055996179581,10933.6010742187,0.111605444099992,0.002927889059684,1,0.999253354069792,40.0298881530762,1.99903834222461,17.8900007158518,1.22013794323071,0.225837002895803,25,0.000819180465668939,0.110934335015492,0.001434543480651,1.900475025177,1.900475025177,10883.748046875,10983.4541015625,55.8332883856982,20.6183154845309,2.1147243976593,0,0,0,40,1.91317534446716,1,6,1,2.24365234375,41.5444793701172,,,,,,,,,,,,,,,,
,3949026226.6965,1.90008264780045,4645.46875,0.123654498343199,0.000293330012211461,1,0.999253354069792,40.0298881530762,1.99896975260464,17.8900007158518,1.35109177171653,0.250585351158588,25,0.00100966526304604,0.122852306704257,0.00163349568050172,1.90009021759033,1.90009021759033,4595.37353515625,4695.56396484375,56.1037318533521,20.6141377324561,2.11351728439331,0,0,0,40,1.90396094322205,1,6,1,2.24105834960938,41.5444793701172,,,,,,,,,,,,,,,,
,3949026289.671,1.90161752700806,-1651.50964355469,0.130613952300498,0.000317355459657886,1,0.999253354069792,40.0298881530762,1.99906117508188,17.8999993950129,1.42709176197966,0.263775398289927,25,0.00101236672914659,0.129743514149283,0.00164550909313039,1.90123319625854,1.90123319625854,-1701.44519042969,-1601.57409667969,56.6735390438714,20.6184927263631,2.11153101921082,0,0,0,40,1.90389943122864,1,6,1,2.24945068359375,41.5444793701172,,,,,,,,,,,,,,,,
,3949026352.621,1.89928996562958,-7947.794921875,0.121594813102653,0.000293766342975758,1,0.999253354069792,40.0298881530762,1.99923149205854,17.8900007158518,1.32919992376014,0.245748283282537,25,0.000894974651897172,0.120834960050985,0.00153838330186702,1.89938104152679,1.89938104152679,-7992.748046875,-7902.841796875,55.8598637553521,20.6225787789076,2.11114597320557,0,0,0,40,1.90525829792023,1,6,1,2.2564697265625,41.5444793701172,,,,,,,,,,,,,,,,
,3949026415.6305,1.89946979284286,-14250.68359375,0.111357712911662,0.000301888765624567,1,0.999253354069792,40.0298881530762,1.99902390817468,17.8900007158518,1.21780309371364,0.225212659947154,25,0.000773561137698497,0.110719901269951,0.00141487324469632,1.8995532989502,1.8995532989502,-14305.71484375,-14195.65234375,55.9630387198905,20.619942335594,2.11033797264099,0,0,0,40,1.91622924804687,1,6,1,2.24655151367187,41.055721282959,,,,,,,,,,,,,,,,
,3949026478.5045,1.89989256858826,-20539.373046875,0.0619061398473231,0.000315322760646389,1,0.999253354069792,40.0298881530762,1.99893145637533,17.8900007158518,0.677498442289487,0.124570262501578,25,0.000339870324013431,0.0615884003232026,0.000723549743050297,1.90022671222687,1.90022671222687,-20589.41015625,-20489.3359375,56.4539014299675,20.6205743658306,2.10948777198791,0,0,0,40,1.92745554447174,1,6,1,2.23968505859375,41.5444793701172,,,,,,,,,,,,,,,,
,3949026544.228,1.89987820386887,-27122.220703125,0.11528455296771,0.000259365718787714,1,0.999253354069792,40.0298881530762,1.99903877759736,17.8900007158518,1.26238250619756,0.233234074706464,25,0.000687799456285594,0.114768778842831,0.0014470223034209,1.89984846115112,1.89984846115112,-27252.380859375,-26992.060546875,56.231918930506,20.6202017946805,2.10850095748901,0,0,0,40,1.9375194311142,1,6,1,2.24258422851562,41.5444793701172,,,,,,,,,,,,,,,,
,3949026608.4295,1.89946711063385,-33546.015625,0.102292397986828,0.000248114561010902,1,0.999253354069792,40.0298881530762,1.99889168635941,17.8900007158518,1.12088441234743,0.206584461385479,25,0.000534658641972618,0.101904001224793,0.00124025276950765,1.89944386482239,1.89944386482239,-33596.03515625,-33495.99609375,56.0959155681598,20.6195338360655,2.10905861854553,0,0,0,40,1.94394171237946,1,6,1,2.2412109375,41.5444793701172,,,,,,,,,,,,,,,,
,3949026675.329,1.89967733621597,-40239.23828125,0.166975515562593,0.000156597193645701,1,0.999253354069792,40.0298881530762,1.99905637607118,17.8900007158518,1.83081892689995,0.339084949218782,25,0.000979533893376202,0.166458993798263,0.00217156444169287,1.89961433410645,1.89961433410645,-40289.32421875,-40189.15234375,56.0724667125828,20.6280507795574,2.10878944396973,0,0,0,40,1.94941139221191,1,6,1,2.24075317382813,41.055721282959,,,,,,,,,,,,,,,,
,3949026741.3255,1.89971250295639,-46842.306640625,0.0972101311503453,0.000228279015621232,1,0.999253354069792,40.0298881530762,1.99912900265261,17.8999993950129,1.06675856564031,0.196920561118016,2.5,0.000497617148587875,0.0969770080677085,0.00120770024575549,1.89970314502716,1.89970314502716,-46892.3359375,-46792.27734375,55.6308465992174,20.629565312392,2.10897898674011,0,0,0,40,1.95295786857605,1,6,1,2.2430419921875,41.5444793701172,,,,,,,,,,,,,,,,
,3949026808.261,1.89983677864075,-53539.83203125,0.0630973721327327,0.000240309784667256,1,0.999253354069792,40.0298881530762,1.99903077775907,17.8900007158518,0.693232814587866,0.125779115630412,2.5,0.000124699350868823,0.0629902844969915,0.000591909913035512,1.89981734752655,1.89981734752655,-53594.875,-53484.7890625,56.5070521692752,20.6248988846038,2.10969519615173,0,0,0,40,1.95590329170227,1,6,1,2.2406005859375,40.5669593811035,,,,,,,,,,,,,,,,
,3949026877.2095,1.90015238523483,-60438.02734375,0.131311308618216,0.000121294869016904,1,0.999253354069792,40.0298881530762,1.99895086358073,17.8900007158518,1.44281078631757,0.266241320788007,25,0.00064915911181054,0.131172816411345,0.00162499217008624,1.90008997917175,1.90008997917175,-60488.05859375,-60387.99609375,56.5258112537367,20.626175371821,2.10995244979858,0,0,0,40,1.95861709117889,1,6,1,2.24319458007813,41.055721282959,,,,,,,,,,,,,,,,
,3949026943.1435,1.90034294128418,-67034.91796875,0.0771529158480764,0.000182224394689065,1,0.999253354069792,40.0298881530762,1.99913586066207,17.8900007158518,0.848410712235413,0.156006400079842,2.5,0.000335278195593873,0.0771179680786722,0.000906947156287121,1.90044856071472,1.90044856071472,-67089.9140625,-66979.921875,56.5500417378329,20.6303492242669,2.10901880264282,0,0,0,40,1.96072101593018,1,6,1,2.24105834960938,41.055721282959,,,,,,,,,,,,,,,,
,3949027007.1245,1.89993172883987,-73437.71875,0.114628218929988,7.83564487561753E-5,1,0.999253354069792,40.0298881530762,1.99919306314307,17.8900007158518,1.26130864167784,0.231435458217549,25,0.000462472974412027,0.114638540611721,0.00130468792513738,1.89990139007568,1.89990139007568,-73482.703125,-73392.734375,56.1482846789482,20.6318238117241,2.10852551460266,0,0,0,40,1.96260237693787,1,6,1,2.22976684570313,41.055721282959,,,,,,,,,,,,,,,,
,3949027071.0635,1.89965844154358,-79835.69140625,0.0914466593137282,8.15859325903537E-5,1,0.999253354069792,40.0298881530762,1.99881888858815,17.8999993950129,1.00661973178136,0.184332065565603,2.5,0.000345456833725176,0.091500856644954,0.00100873439868843,1.89963984489441,1.89963984489441,-79885.734375,-79785.6484375,56.9252234270637,20.6276485932698,2.10718560218811,0,0,0,40,1.96451735496521,1,6,1,2.24090576171875,41.5444793701172,,,,,,,,,,,,,,,,
,3949027134.045,1.89998215436935,-86133.1484375,0.0722492924371294,7.77659232821883E-5,1,0.999253354069792,40.0298881530762,1.99908030215438,17.8900007158518,0.79593547725942,0.144737457829457,2.5,0.000192641130180421,0.0723255214423669,0.000708146457464357,1.89993619918823,1.89993619918823,-86188.171875,-86078.125,56.272563613506,20.6352731457404,2.10762023925781,0,0,0,40,1.96701085567474,1,6,1,2.24105834960938,40.5669593811035,,,,,,,,,,,,,,,,
,3949027196.9685,1.9001197218895,-92430.02734375,0.0550967418908103,7.4332452687449E-5,1,0.999253354069792,40.0298881530762,1.99904744462108,17.8900007158518,0.607460330833415,0.10906095325315,2.5,3.13465119956358E-5,0.0551786793200882,0.00041682911227853,1.90012454986572,1.90012454986572,-92479.9921875,-92380.0625,56.3616692646983,20.6295819084102,2.10863471031189,0,0,0,40,1.96906244754791,1,6,1,2.239990234375,41.055721282959,,,,,,,,,,,,,,,,
,3949027259.89,1.89984160661697,-98727.5546875,0.0401173575974642,5.71065415550361E-5,1,0.999253354069792,40.0298881530762,1.99908731537684,17.8999993950129,0.442551761257652,0.0790635913772533,2.5,-5.358945808656E-6,0.0401925361187191,0.000269269775080746,1.89990258216858,1.89990258216858,-98772.609375,-98682.5,55.676962681852,20.6302414589475,2.10790109634399,0,0,0,40,1.9713739156723,1,6,1,2.25250244140625,40.5669593811035,,,,,,,,,,,,,,,,
,3949027322.8965,1.89998769760132,-105030.6328125,0.0265396395869665,9.58241013735313E-5,1,0.999253354069792,40.0298881530762,1.99895480752205,17.8900007158518,0.293251632232277,0.0500902980633733,2.5,-0.000201284708172451,0.0265999638651548,-2.42621000616111E-5,1.89993119239807,1.89993119239807,-105085.6015625,-104975.6640625,55.7011931659482,20.6295793175671,2.10836911201477,0,0,0,40,1.97449159622192,1,6,1,2.264404296875,40.5669593811035,,,,,,,,,,,,,,,,
,3949027386.7985,1.89988702535629,-111417.76171875,0.0154140946362202,6.55243022233364E-5,1,0.999253354069792,40.0298881530762,1.99887830229595,17.8900007158518,0.170548051033945,0.0280879405611677,2.5,-0.000206035096394621,0.0154546649291466,-0.000106057224822238,1.89980614185333,1.89980614185333,-111467.7890625,-111367.734375,55.1642143732366,20.6363417699958,2.10806775093079,0,0,0,40,1.97736752033234,1,6,1,2.24227905273438,40.5669593811035,,,,,,,,,,,,,,,,
,3949027449.7855,1.90005856752396,-117725.3828125,0.00632858253417408,6.82172987073917E-5,1,0.999253354069792,40.0298881530762,1.99895254605515,17.8900007158518,0.0705178397326259,0.00888133256985314,2.5,-0.000323919067112428,0.00634858186003644,-0.000284635726804529,1.90001714229584,1.90001714229584,-117770.375,-117680.390625,55.3588398745251,20.6334993811351,2.10868334770203,0,0,0,40,1.98037350177765,1,6,1,2.24319458007813,42.5219955444336,,,,,,,,,,,,,,,,
,3949027513.7155,1.89977753162384,-124122.42578125,7.31425316661527E-5,5.87143364876704E-5,1,0.999253354069792,40.0298881530762,1.99886972296533,17.8900007158518,0.00153117431015634,-0.00391748342803617,0.25,-0.000367715672239722,7.5642486086563E-5,-0.000368404530042965,1.89977288246155,1.89977288246155,-124172.3515625,-124072.5,55.5542470043328,20.6365128860266,2.10763478279114,0,0,0,40,1.9835592508316,1,6,1,2.23052978515625,41.055721282959,,,,,,,,,,,,,,,,
,3949027576.6775,1.89982903003693,-130419.21875,-0.00212395343633076,2.69370342556758E-5,1,0.999253354069792,40.0298881530762,1.99892783379516,17.8999993950129,-0.0232076242088127,-0.00562542442818001,0.25,-0.000131269087253593,-0.00213026422054092,-0.000144481237505218,1.89988422393799,1.89988422393799,-130464.34375,-130374.09375,55.913796123179,20.6384633628624,2.10685205459595,0,0,0,40,1.98683667182922,1,6,1,2.24777221679687,40.5669593811035,,,,,,,,,,,,,,,,
,3949027639.606,1.89972472190857,-136715.8125,-0.00219062017479023,3.18259419776192E-6,1,0.999253354069792,40.0298881530762,1.99892106901226,17.8900007158518,-0.0241622238704251,-0.00456117062315304,0.25,-2.33531518394945E-5,-0.00219828588813618,-3.62483394609649E-5,1.89972424507141,1.89972424507141,-136765.765625,-136665.859375,55.7027564229867,20.641641827975,2.10791945457458,0,0,0,40,1.99104452133179,1,6,1,2.2430419921875,40.5669593811035,,,,,,,,,,,,,,,,
,3949027712.5615,1.89992040395737,-137240.671875,-0.00220141052402858,2.41912410692701E-6,1,0.999253354069792,40.0298881530762,1.99898243845363,17.8999993950129,-0.0242891753215228,-0.00454555088615508,0.25,-2.00327499949123E-5,-0.00220917252978934,-3.29495018774825E-5,1.89993321895599,1.89993321895599,-137290.171875,-137191.171875,55.3439889326597,20.6352414324564,2.10724711418152,0,0,0,40,1.99138128757477,1,6,1,2.24655151367187,40.5669593811035,,,,,,,,,,,,,,,,
,3949027775.5415,1.90037125349045,-131009.33984375,-0.00211252195686869,1.84561449043785E-5,1,0.999253354069792,40.0298881530762,1.99880695817427,17.8900007158518,-0.0231548197356355,-0.00518510941617128,0.25,-9.34985274392287E-5,-0.00211906828708688,-0.000106484699716343,1.90035629272461,1.90035629272461,-131058.8671875,-130959.8125,56.096697196679,20.6359434906596,2.10762786865234,0,0,0,40,1.98793721199036,1,6,1,2.24395751953125,40.0782012939453,,,,,,,,,,,,,,,,
,3949027839.498,1.90011370182037,-124678.59375,-0.00319087985659255,6.97905051863697E-5,1,0.999253354069792,40.0298881530762,1.9989192569441,17.8999993950129,-0.034584369186522,-0.00998306337849347,0.25,-0.000335577965163731,-0.00319878200638812,-0.000356303408680549,1.90014684200287,1.90014684200287,-124728.0859375,-124629.1015625,55.5393960624674,20.6395071159019,2.10817050933838,0,0,0,40,1.98392975330353,1,6,1,2.23098754882813,40.5669593811035,,,,,,,,,,,,,,,,
,3949027903.4285,1.8998030424118,-118352.42578125,-0.00862247720814541,7.68354926067433E-5,1,0.999253354069792,40.0298881530762,1.99889939766352,17.8900007158518,-0.0941982872725026,-0.0226467367784957,2.5,-0.00051391242975406,-0.00864390233588866,-0.000570012387819002,1.89982843399048,1.89982843399048,-118406.796875,-118298.0546875,56.0951339396406,20.6319261279955,2.10860013961792,0,0,0,40,1.98056602478027,1,6,1,2.25936889648438,40.5669593811035,,,,,,,,,,,,,,,,
,3949027967.401,1.90030819177628,-112025.93359375,-0.0168557137160504,5.02633566527459E-5,1,0.999253354069792,40.0298881530762,1.99905669201865,17.8900007158518,-0.185138313952644,-0.0384610823175387,2.5,-0.000476340284903972,-0.0168960028600286,-0.000587197092476428,1.90025353431702,1.90025353431702,-112075.53125,-111976.3359375,55.8340700142174,20.6372183738415,2.10782265663147,0,0,0,40,1.97807884216309,1,6,1,2.24349975585938,40.5669593811035,,,,,,,,,,,,,,,,
,3949028030.325,1.90019673109055,-105803.82421875,-0.02674369100219,7.36664977011792E-5,1,0.999253354069792,40.0298881530762,1.99892175324098,17.8900007158518,-0.294033391586118,-0.0587642098492524,2.5,-0.000548735357164152,-0.0268005521923218,-0.000728278108299824,1.90007472038269,1.90007472038269,-105853.265625,-105754.3828125,56.0795013692559,20.6394838161609,2.10803365707397,0,0,0,40,1.97505438327789,1,6,1,2.2564697265625,40.5669593811035,,,,,,,,,,,,,,,,
,3949028094.3075,1.89992463588715,-99467.98828125,-0.0387629295802851,6.93087954781882E-5,1,0.999253354069792,40.0298881530762,1.99877986037859,17.8900007158518,-0.426328284180316,-0.0833113588429238,2.5,-0.000623368093415741,-0.038832933249609,-0.000889220630318346,1.8999559879303,1.8999559879303,-99512.4765625,-99423.5,55.7629418189674,20.6277319813334,2.10858869552612,0,0,0,40,1.97189819812775,1,6,1,2.24533081054687,39.5894432067871,,,,,,,,,,,,,,,,
,3949028157.258,1.9000723361969,-93240.828125,-0.0522467710069321,6.04822050271612E-5,1,0.999253354069792,40.0298881530762,1.99876651055206,17.8999993950129,-0.574514714580449,-0.111661628241754,2.5,-0.000779025266035766,-0.0523219126110352,-0.0011447515332314,1.90010762214661,1.90010762214661,-93290.265625,-93191.390625,55.873151440179,20.6277920532138,2.10900712013245,0,0,0,40,1.9694766998291,1,6,1,2.25799560546875,40.5669593811035,,,,,,,,,,,,,,,,
,3949028221.181,1.90009224414825,-86920.015625,-0.0678320282598641,5.42409762930663E-5,1,0.999253354069792,40.0298881530762,1.99883588179838,17.8900007158518,-0.745642139894767,-0.144726209898765,2.5,-0.00098465463599891,-0.0679015496632375,-0.00146846051028548,1.90010929107666,1.90010929107666,-86969.3984375,-86870.6328125,56.1404683937559,20.6293693249822,2.10853409767151,0,0,0,40,1.96715843677521,1,6,1,2.24822998046875,40.5669593811035,,,,,,,,,,,,,,,,
,3949028284.1375,1.90018349885941,-80688.76171875,-0.0610684826636443,0.000124511330700208,1,0.999253354069792,40.0298881530762,1.99886327585205,17.8900007158518,-0.671155646309299,-0.129393733422465,2.5,-0.000802204772428572,-0.0611044352837806,-0.00124464565887758,1.90013015270233,1.90013015270233,-80738.0859375,-80639.4375,55.700411537429,20.6308828710156,2.10908889770508,0,0,0,40,1.9655168056488,1,6,1,2.24334716796875,41.055721282959,,,,,,,,,,,,,,,,
,3949028348.3455,1.90000420808792,-74323.94140625,-0.104594901099759,5.55371129909742E-5,1,0.999253354069792,40.0298881530762,1.99869615212627,17.8900007158518,-1.14930207187251,-0.219042419608533,25,-0.00114071912649853,-0.104606549738966,-0.00190817132294245,1.90002751350403,1.90002751350403,-74343.8203125,-74304.0625,55.1509266884097,20.6218802575915,2.10896182060242,0,0,0,40,1.96296668052673,1,6,1,2.25250244140625,41.055721282959,,,,,,,,,,,,,,,,
,3949028414.084,1.90011858940125,-67788.5625,-0.115654008366458,9.21543599383563E-5,1,0.999253354069792,40.0298881530762,1.99858869019013,17.8900007158518,-1.27024261415461,-0.241048093579941,25,-0.00116096949731759,-0.11560434109889,-0.00201705431188175,1.90016877651215,1.90016877651215,-67838.3515625,-67738.7734375,55.5847305165828,20.619923050911,2.10924863815308,0,0,0,40,1.96091532707214,1,6,1,2.25143432617187,41.5444793701172,,,,,,,,,,,,,,,,
,3949028479.988,1.90051317214966,-61232.341796875,-0.0906349294902363,0.000184394035917154,1,0.999253354069792,40.0298881530762,1.99850124927311,17.8900007158518,-0.994627399318235,-0.189897197109756,2.5,-0.00100793413227704,-0.0905418807362227,-0.00168094207289005,1.90058422088623,1.90058422088623,-61281.9921875,-61182.69140625,55.761378561929,20.6167637937643,2.10812425613403,0,0,0,40,1.95939993858337,1,6,1,2.22915649414062,41.055721282959,,,,,,,,,,,,,,,,
,3949028545.945,1.90008080005646,-54667.4765625,-0.140258526471985,0.000132492685037681,1,0.999253354069792,40.0298881530762,1.99872821581033,17.8999993950129,-1.53875678917499,-0.291702617653047,25,-0.00137870787603263,-0.140027908681168,-0.00241681904494615,1.90003311634064,1.90003311634064,-54717.23046875,-54617.72265625,55.9161410087367,20.6213828496356,2.10782694816589,0,0,0,40,1.95684289932251,1,6,1,2.24227905273438,41.5444793701172,,,,,,,,,,,,,,,,
,3949028610.898,1.90004009008408,-48205.65625,-0.174915475574112,0.000104014572994713,1,0.999253354069792,40.0298881530762,1.99866140646402,17.8900007158518,-1.91788485889183,-0.362308210250396,25,-0.00162039968918766,-0.174515191273067,-0.00290082146933153,1.90010368824005,1.90010368824005,-48250.42578125,-48160.88671875,56.0990420822367,20.6214262310591,2.10907196998596,0,0,0,40,1.95392262935638,1,6,1,2.24594116210938,41.5444793701172,,,,,,,,,,,,,,,,
,3949028678.8465,1.90125966072083,-41445.767578125,-0.0476183147021485,0.00833298037039421,1,0.999253354069792,40.0298881530762,1.99856192059688,17.8900007158518,-0.52197431085796,-0.0971672564459001,25,-0.000321180552855839,-0.047476764405703,-0.000662692069352543,1.90013194084167,1.90013194084167,-41495.48046875,-41396.0546875,56.2280107879098,20.6202319022445,2.10791516304016,0,0,0,40,1.95112597942352,1,6,1,2.24319458007813,41.5444793701172,,,,,,,,,,,,,,,,
,3949028748.068,1.90048086643219,-34539.25390625,-0.129634503826601,0.000220089276938371,1,0.999253354069792,40.0298881530762,1.99864297827173,17.8900007158518,-1.41946400999701,-0.267433830399437,25,-0.001186061937229,-0.129152366462682,-0.00208373254820897,1.90048086643219,1.90048086643219,-34559.234375,-34519.2734375,56.6813553290637,20.6188189758515,2.10804176330566,0,0,0,40,1.94608318805695,1,6,1,2.2509765625,42.0332374572754,,,,,,,,,,,,,,,,
,3949028810.764,1.90035974979401,-28285.6025390625,-0.141308628629406,0.000227708840715557,1,0.999253354069792,40.0298881530762,1.99864560561295,17.8900007158518,-1.54645552384543,-0.290306004806246,25,-0.00123970554571974,-0.140690782722688,-0.00217728770973951,1.90029549598694,1.90029549598694,-28335.447265625,-28235.7578125,56.4406137451406,20.6168938007366,2.10740756988525,0,0,0,40,1.94025123119354,1,6,1,2.24014282226562,41.5444793701172,,,,,,,,,,,,,,,,
,3949028875.651,1.90019780397415,-21811.7724609375,-0.0814371415214282,0.000291752100399793,1,0.999253354069792,40.0298881530762,1.99858914824552,17.8900007158518,-0.89069050813689,-0.166793284863856,25,-0.000707893250692891,-0.0810276769148697,-0.0012178990691172,1.90027403831482,1.90027403831482,-21861.724609375,-21761.8203125,55.873151440179,20.6195018478566,2.10689377784729,0,0,0,40,1.93116533756256,1,6,1,2.23007202148438,41.055721282959,,,,,,,,,,,,,,,,
,3949028939.645,1.90078097581863,-15427.0307617188,-0.071289405107955,0.00031628676727277,1,0.999253354069792,40.0298881530762,1.99864708656584,17.8999993950129,-0.779209070002873,-0.146147683923639,25,-0.000670192827579734,-0.0708875589357612,-0.00108576980306669,1.9008811712265,1.9008811712265,-15471.935546875,-15382.1259765625,55.8028048734482,20.6176957103036,2.10657548904419,0,0,0,40,1.92084503173828,1,6,1,2.2454833984375,37.1456527709961,,,,,,,,,,,,,,,,
,3949029004.5955,1.90119731426239,-8936.90771484375,-0.0724797948698317,0.00032001388018811,1,0.999253354069792,40.0298881530762,1.99851486887092,17.8900007158518,-0.791873886698146,-0.147699009476943,25,-0.000642666146954981,-0.0720317696667531,-0.00103085239713644,1.90133678913116,1.90133678913116,-8986.896484375,-8886.9189453125,56.1709519060059,20.6204802158015,2.10670590400696,0,0,0,40,1.90996336936951,1,6,1,2.232666015625,41.5444793701172,,,,,,,,,,,,,,,,
,3949029067.523,1.90004545450211,-2643.2880859375,-0.10461456436513,0.00032063721552231,1,0.999253354069792,40.0298881530762,1.99842892664713,17.8900007158518,-1.14265705303086,-0.211698785181528,25,-0.00084828623493167,-0.103922925857636,-0.00136171386284376,1.90011084079742,1.90011084079742,-2698.02368164062,-2588.55249023438,56.1240541948521,20.6128533854649,2.10511589050293,0,0,0,40,1.90254056453705,1,6,1,2.2283935546875,41.5444793701172,,,,,,,,,,,,,,,,
,3949029130.4725,1.90006947517395,3648.31188964844,-0.114583467871259,0.00032598361428802,1,0.999253354069792,40.0298881530762,1.99862449964289,17.8999993950129,-1.25184104833016,-0.231310933793031,25,-0.00086686554351415,-0.113833150653196,-0.00143737757478538,1.90051853656769,1.90051853656769,3598.32934570313,3698.29443359375,56.1584458496982,20.6206522734068,2.10452008247375,0,0,0,40,1.90133380889893,1,6,1,2.25921630859375,42.0332374572754,,,,,,,,,,,,,,,,
,3949029193.4465,1.89937108755112,9952.2646484375,-0.103537928141998,0.000302711032128967,1,0.999253354069792,40.0298881530762,1.99866962780872,17.8900007158518,-1.13169319154224,-0.209214259268448,25,-0.000745128488753441,-0.102907162887072,-0.00130854630086101,1.89933288097382,1.89933288097382,9902.2724609375,10002.2568359375,55.8411046708905,20.6228966625123,2.10391139984131,0,0,0,40,1.90855765342712,1,6,1,2.23007202148438,41.5444793701172,,,,,,,,,,,,,,,,
,3949029256.4055,1.90016788244247,16250.0141601562,-0.055162283612532,0.000331563258019415,1,0.999253354069792,40.0298881530762,1.99849746808232,17.8999993950129,-0.603252443114759,-0.111323471816918,25,-0.000354377973563992,-0.0548564429432354,-0.00068005774629718,1.89959967136383,1.89959967136383,16195.0224609375,16305.005859375,56.1553193356213,20.6122530262318,2.1021556854248,0,0,0,40,1.92025983333588,1,6,1,2.24334716796875,42.0332374572754,,,,,,,,,,,,,,,,
,3949029319.389,1.89977842569351,22553.3427734375,-0.0822893050369144,0.000292813799343405,1,0.999253354069792,40.0298881530762,1.99891959842339,17.8900007158518,-0.900623670425384,-0.166305545784393,25,-0.000504212673795178,-0.0818829343319981,-0.00102438791681381,1.89967858791351,1.89967858791351,22508.328125,22598.357421875,56.9603967104291,20.6271990716625,2.1014552116394,0,0,0,40,1.93130683898926,1,6,1,2.2406005859375,41.5444793701172,,,,,,,,,,,,,,,,
,3949029384.287,1.90058445930481,29041.5771484375,-0.0842279487831558,0.00867424068026356,1,0.999253354069792,40.0298881530762,1.99875406442634,17.8900007158518,-0.922829839767286,-0.167832448412379,25,-0.000258755211885822,-0.0838695106210041,-0.000822916350223779,1.89967381954193,1.89967381954193,28991.638671875,29091.515625,56.2225393882752,20.6238369347006,2.10123658180237,0,0,0,40,1.93938028812408,1,6,1,2.22885131835938,40.5669593811035,,,,,,,,,,,,,,,,
,3949029449.2275,1.89996004104614,35545,-0.144959967789292,0.000201229304595468,1,0.999253354069792,40.0298881530762,1.99882160523473,17.8900007158518,-1.58842749750525,-0.294362194009953,25,-0.00088810220658905,-0.144439306914703,-0.00189928901467766,1.89991056919098,1.89991056919098,35494.76953125,35595.23046875,55.9177042657751,20.627874863433,2.10242581367493,0,0,0,40,1.94610238075256,1,6,1,2.25494384765625,41.5444793701172,,,,,,,,,,,,,,,,
,3949029514.6095,1.89988607168198,42088.13671875,-0.166806351932206,0.000169076663417997,1,0.999253354069792,40.0298881530762,1.99859028401877,17.8900007158518,-1.82876496886519,-0.33958335285324,25,-0.00104754362141842,-0.166322322988866,-0.00224706416921931,1.89991533756256,1.89991533756256,42078.1328125,42098.140625,55.7449643630251,20.6166962906482,2.1016891002655,0,0,0,40,1.95033240318298,1,6,1,2.22549438476562,42.0332374572754,,,,,,,,,,,,,,,,
,3949029581.1465,1.899857878685,48746.68359375,-0.133359811028963,0.00017562365040125,1,0.999253354069792,40.0298881530762,1.99876087162202,17.8900007158518,-1.46328912553931,-0.271259604161481,25,-0.000778986147248984,-0.133065352437109,-0.00175743507867251,1.8998532295227,1.8998532295227,48691.41015625,48801.95703125,55.7559071622943,20.6244718318345,2.10053539276123,0,0,0,40,1.95395791530609,1,6,1,2.23419189453125,42.0332374572754,,,,,,,,,,,,,,,,
,3949029648.1555,1.89994269609451,55449.716796875,-0.12894567787914,0.000144357987559372,1,0.999253354069792,40.0298881530762,1.99853929865525,17.8999993950129,-1.41579060640678,-0.261684331717417,25,-0.000676658174250878,-0.128747915153143,-0.0016326863325039,1.89988052845001,1.89988052845001,55404.74609375,55494.6875,56.1052951103906,20.6177318352367,2.10114288330078,0,0,0,40,1.95695161819458,1,6,1,2.236328125,42.5219955444336,,,,,,,,,,,,,,,,
,3949029714.0665,1.90013444423676,62047.818359375,-0.111063901528092,0.000140152607200414,1,0.999253354069792,40.0298881530762,1.99871620202724,17.8900007158518,-1.22033449006234,-0.225476883840011,2.5,-0.000574821092227375,-0.110963161989488,-0.00140004978329528,1.90011620521545,1.90011620521545,61997.76171875,62097.875,55.6042712295636,20.6259396277257,2.10162091255188,0,0,0,40,1.95920598506927,1,6,1,2.24655151367187,42.5219955444336,,,,,,,,,,,,,,,,
,3949029781.0175,1.90006190538406,68741.32421875,-0.0669611578338367,0.000200072195084216,1,0.999253354069792,40.0298881530762,1.99849014897443,17.8900007158518,-0.736237470421018,-0.135282405487824,2.5,-0.000283400080492868,-0.0669407890163918,-0.000778682345721594,1.900066614151,1.900066614151,68691.2890625,68791.359375,56.1240541948521,20.6172961427085,2.10072135925293,0,0,0,40,1.96145367622375,1,6,1,2.24197387695313,42.5219955444336,,,,,,,,,,,,,,,,
,3949029844.957,1.89991039037704,75144.8984375,-0.108312570569362,8.74749128988772E-5,1,0.999253354069792,40.0298881530762,1.99871707462488,17.8900007158518,-1.19149592753477,-0.21985356615615,25,-0.000547546509682115,-0.108336406395777,-0.00134097199750035,1.9000358581543,1.9000358581543,75094.859375,75194.9375,56.0834095118521,20.6158857170673,2.10090303421021,0,0,0,40,1.96269750595093,1,6,1,2.2442626953125,42.5219955444336,,,,,,,,,,,,,,,,
,3949029907.872,1.89979290962219,81437.8671875,-0.0868498227188132,8.67884727978252E-5,1,0.999253354069792,40.0298881530762,1.99852517348893,17.8900007158518,-0.956005369992853,-0.175029567034458,25,-0.000327620989074453,-0.0869116522250879,-0.000955150160623656,1.89982175827026,1.89982175827026,81387.9609375,81487.7734375,55.9356817217174,20.6141414553085,2.10084533691406,0,0,0,40,1.96496343612671,1,6,1,2.22930908203125,42.0332374572754,,,,,,,,,,,,,,,,
,3949029970.867,1.89981979131699,87740.2734375,-0.0678859810512821,7.97064130630848E-5,1,0.999253354069792,40.0298881530762,1.99850358356543,17.8900007158518,-0.747708722158911,-0.136173001043834,25,-0.000201370820447608,-0.0679649277328196,-0.000683522635676007,1.89982867240906,1.89982867240906,87690.1796875,87790.3671875,56.0771564836982,20.6222890073982,2.10211491584778,0,0,0,40,1.96725618839264,1,6,1,2.23892211914062,42.5219955444336,,,,,,,,,,,,,,,,
,3949030033.812,1.89992570877075,94033.8671875,-0.0510924758555635,7.68960445525158E-5,1,0.999253354069792,40.0298881530762,1.99865238572808,17.8900007158518,-0.563110137616236,-0.101978947346235,25,-0.00010836464975596,-0.0511730434741402,-0.000464066885194604,1.89996302127838,1.89996302127838,93983.8203125,94083.9140625,56.3218062102175,20.618545896522,2.10101294517517,0,0,0,40,1.96979761123657,1,6,1,2.25753784179687,42.5219955444336,,,,,,,,,,,,,,,,
,3949030097.779,1.89970755577087,100441.63671875,-0.0358934839984323,8.46476686612652E-5,1,0.999253354069792,40.0298881530762,1.99850613000568,17.8900007158518,-0.396030290215022,-0.0699187146807377,2.5,7.64940876488184E-5,-0.0359647573953649,-0.000167553271486882,1.89969289302826,1.89969289302826,100396.6015625,100486.671875,56.5945945634291,20.623492139952,2.10110187530518,0,0,0,40,1.97211313247681,1,6,1,2.2393798828125,41.055721282959,,,,,,,,,,,,,,,,
,3949030160.711,1.89963936805725,106734.51953125,-0.023401904566243,8.7587695217607E-5,1,0.999253354069792,40.0298881530762,1.99862070540008,17.8900007158518,-0.25846888158427,-0.0446911594508287,2.5,0.000128768507421765,-0.023456848962945,-2.63907717836144E-5,1.89957249164581,1.89957249164581,106679.2890625,106789.75,56.3819916061983,20.6183252968263,2.10056233406067,0,0,0,40,1.97505664825439,1,6,1,2.2467041015625,43.0107536315918,,,,,,,,,,,,,,,,
,3949030223.686,1.89995491504669,113033.06640625,-0.0130231733769385,5.86842404874419E-5,1,0.999253354069792,40.0298881530762,1.99858667824948,17.8900007158518,-0.144090097860509,-0.0237004122588221,2.5,0.000176164317449674,-0.0130584582289895,9.22701462887928E-5,1.89999973773956,1.89999973773956,112983.0546875,113083.078125,55.3072523922559,20.620565498346,2.10096192359924,0,0,0,40,1.97784328460693,1,6,1,2.24212646484375,42.5219955444336,,,,,,,,,,,,,,,,
,3949030286.5965,1.89994513988495,119335.58984375,-0.00477419999707191,5.55474462693821E-5,1,0.999253354069792,40.0298881530762,1.99849563476919,17.8900007158518,-0.053197094776384,-0.0066578989942904,2.5,0.000247871842399664,-0.00478963226585739,0.000218469717221357,1.89995110034943,1.89995110034943,119285.59375,119385.5859375,55.6003630869674,20.6229060828054,2.10125374794006,0,0,0,40,1.98128950595856,1,6,1,2.24212646484375,42.5219955444336,,,,,,,,,,,,,,,,
,3949030350.5765,1.89998644590378,125728.1953125,0.000875480714676074,7.81265921249858E-5,1,0.999253354069792,40.0298881530762,1.99856421046361,17.8900007158518,0.00914424079845091,0.00466777385617763,0.25,0.000266767922087621,0.000876615126409289,0.000272986770392372,1.90003955364227,1.90003955364227,125678.1640625,125778.2265625,56.066213684429,20.6308260707431,2.10112619400024,0,0,0,40,1.98463582992554,1,6,1,2.23251342773438,42.5219955444336,,,,,,,,,,,,,,,,
,3949030413.5285,1.89971905946732,132031.421875,0.0020895356500355,1.01924957291305E-5,1,0.999253354069792,40.0298881530762,1.99862404060295,17.8900007158518,0.0229906541165296,0.00462860857546958,0.25,4.72932047735222E-5,0.00209635951532754,5.99314049894898E-5,1.89970123767853,1.89970123767853,131981.40625,132081.4375,55.4862453231597,20.6301054642672,2.10030698776245,0,0,0,40,1.98800206184387,1,6,1,2.24212646484375,43.0107536315918,,,,,,,,,,,,,,,,
,3949030476.4475,1.89944618940353,138329.6953125,0.00222150079326738,3.38405049159048E-6,1,0.999253354069792,40.0298881530762,1.99864000291036,17.8900007158518,0.0245124514770478,0.004559877830498,0.25,1.78737222792714E-5,0.002229426782515,3.08378125629002E-5,1.89943265914917,1.89943265914917,138274.46875,138384.921875,55.8739330686982,20.6331539120928,2.10012292861938,0,0,0,40,1.99210834503174,1,6,1,2.24365234375,44.4770278930664,,,,,,,,,,,,,,,,
,3949030496.4505,1.89870876073837,139999.671875,0.0022507886925088,2.69489085681931E-6,1,0.999253354069792,40.0298881530762,1.99878406727161,17.8999993950129,0.024830842461743,0.00466445679737443,0.25,2.21791875601401E-5,0.00225891675874938,3.52329580238148E-5,1.8986793756485,1.8986793756485,139999.59375,139999.75,56.2366087016213,20.6288476911251,2.09903335571289,0,0,0,40,1.99277174472809,1,4,1,2.25418090820313,42.5219955444336,,,,,,,,,,,,,,,,