File: PPMS_Data_and_Plotting/Data/NbTi/0005.DAT
[Header]
; VSM Data File (default extension .dat)
; Copyright (c) 2003-2013, Quantum Design, Inc. All rights reserved.
TITLE,
FILEOPENTIME,3949032684.06665,02/18/2025,9:34 am
BYAPP,VSM,1.0,1.0
INFO,DYNACOOL VSM Option Release 1.4.10 Build 1,APPNAME
INFO,Quantum Design Linear Motor Servo Controller,MOTOR_MODULE_NAME
INFO,3101-100 L2,MOTOR_HW_VERSION
INFO,MMC884,MOTOR_SERIAL_NUMBER
INFO,SRV No X-over 01.03.11,MOTOR_SOFTWARE_VERSION
INFO,Quantum Design VSM Detection Module,VSM_MODULE_NAME
INFO,3101-150 F0,VSM_HW_VERSION
INFO,VSM641,VSM_SERIAL_NUMBER
INFO,VSM No X-over 01.02.05 May 20 2008 13:51:47,VSM_SOFTWARE_VERSION
INFO,VPA645,PREAMP_SERIAL_NUMBER
INFO,740,COIL_SERIAL_NUMBER
INFO,0,MOMENT_UNITS
INFO,NbTi,SAMPLE_MATERIAL
INFO,,SAMPLE_COMMENT
INFO,4.3,SAMPLE_MASS
INFO,,SAMPLE_VOLUME
INFO,,SAMPLE_MOLECULAR_WEIGHT
INFO,,SAMPLE_SIZE
INFO,,SAMPLE_SHAPE
DATATYPE,COMMENT,1
DATATYPE,TIME,2
STARTUPAXIS,X,2
STARTUPAXIS,Y1,5
[Data]
Comment,Time Stamp (sec),Temperature (K),Magnetic Field (Oe),Moment (emu),M. Std. Err. (emu),Transport Action,Averaging Time (sec),Frequency (Hz),Peak Amplitude (mm),Center Position (mm),Coil Signal' (mV),Coil Signal" (mV),Range (mV),M. Quad. Signal (emu),M. Raw' (emu),M. Raw" (emu),Min. Temperature (K),Max. Temperature (K),Min. Field (Oe),Max. Field (Oe),Mass (grams),Motor Lag (deg),Pressure (Torr),VSM Status (code),Motor Status (code),Measure Status (code),Measure Count,System Temp. (K),Temp. Status (code),Field Status (code),Chamber Status (code),Motor Current (amps),Motor Heatsink Temp. (C),Map 01,Map 02,Map 03,Map 04,Map 05,Map 06,Map 07,Map 08,Map 09,Map 10,Map 11,Map 12,Map 13,Map 14,Map 15,Map 16
sample offset = 33.45 mm,3949034841.958,2.99771189689636,0.180115595459938,5.98488683327171E-5,1.62387665571301E-7,1,0.999253354069792,40.0298881530762,1.99885145499427,17.8900007158518,0.000654580234933492,0.00011642069067825,0.25,6.45081391264282E-8,5.9447697358696E-5,3.52266973338461E-7,2.99771189689636,2.99771189689636,0.180115595459938,0.180115595459938,55.1298227183905,20.6106161306307,2.83460068702698,0,0,0,40,3.00257730484009,1,4,1,2.24075317382813,29.8142719268799,,,,,,,,,,,,,,,,
,3949034916.4805,2.99860119819641,6580.94897460937,-0.0304604126401287,0.000319055536518528,1,0.999253354069792,40.0298881530762,1.99911890641161,17.8900007158518,-0.332920967739921,-0.0615635619737099,2.5,-0.000228290539463129,-0.0302669858374759,-0.000386364336529741,2.9986937046051,2.9986937046051,6570.916015625,6590.98193359375,55.6793075674097,20.6191259371752,2.86639833450317,0,0,0,40,3.00513434410095,1,6,1,2.24578857421875,35.6793746948242,,,,,,,,,,,,,,,,
,3949034983.788,2.99964678287506,13313.8579101562,-0.169857787406802,0.000250042641140853,1,0.999253354069792,40.0298881530762,1.99894427117817,17.8900007158518,-1.85732137403171,-0.343553032254876,25,-0.0011977179967771,-0.168870925266998,-0.00216430577250357,2.99976682662964,2.99976682662964,13183.89453125,13443.8212890625,55.8184374438328,20.6200272643215,2.86547589302063,0,0,0,40,3.01032996177673,1,6,1,2.24288940429687,37.1456527709961,,,,,,,,,,,,,,,,
,3949035050.966,2.99863767623901,20036.9501953125,-0.0525603328352663,0.000297462813784329,1,0.999253354069792,40.0298881530762,1.99894281195782,17.8900007158518,-0.575189342702818,-0.105781684949454,2.5,-0.000292263733884399,-0.0522879937686998,-0.000616291323060043,2.99834704399109,2.99834704399109,19986.9609375,20086.939453125,56.0005568888136,20.6181792889128,2.86502480506897,0,0,0,40,3.01527309417725,1,6,1,2.2393798828125,38.6119270324707,,,,,,,,,,,,,,,,
,3949035115.936,2.99955034255981,26540.267578125,-0.311683214687914,0.000101107265295126,1,0.999253354069792,40.0298881530762,1.99901982261164,17.8900007158518,-3.41190735997182,-0.635195349884237,25,-0.00229501326171765,-0.310267351432104,-0.00433583478765441,2.99948453903198,2.99948453903198,26490.306640625,26590.228515625,56.2162863601213,20.6168852091826,2.86481046676636,0,0,0,40,3.02101469039917,1,6,1,2.24288940429687,39.1006851196289,,,,,,,,,,,,,,,,
,3949035181.856,2.99975633621216,33139.009765625,-0.260746209112174,7.67659559533491E-5,1,0.999253354069792,40.0298881530762,1.99889507374969,17.8900007158518,-2.85628033877827,-0.530859349064063,25,-0.00175856099617388,-0.259742332635931,-0.0035511055346727,2.99978947639465,2.99978947639465,33083.99609375,33194.0234375,56.2506780149675,20.6219360946992,2.86469602584839,0,0,0,40,3.02490544319153,1,6,1,2.24899291992187,39.5894432067871,,,,,,,,,,,,,,,,
,3949035245.802,2.99998331069946,39536.564453125,-0.263392094366666,7.19337271649791E-5,1,0.999253354069792,40.0298881530762,1.99892426988075,17.8900007158518,-2.88716238661776,-0.537210368239367,25,-0.00176943100889596,-0.262556278273859,-0.00364332681274759,2.99999928474426,2.99999928474426,39486.73828125,39586.390625,55.9263021794867,20.6258379708298,2.8629207611084,0,0,0,40,3.02726745605469,1,6,1,2.23922729492187,40.0782012939453,,,,,,,,,,,,,,,,
,3949035309.7775,3.00037813186646,45939.1484375,-0.211516053092155,7.70302181745438E-5,1,0.999253354069792,40.0298881530762,1.99892265410404,17.8900007158518,-2.32022733572498,-0.430904545120091,25,-0.00131526217806171,-0.210987446873735,-0.00285591463002499,3.00033497810364,3.00033497810364,45889.14453125,45989.15234375,56.5234663681791,20.6233965015935,2.86256051063538,0,0,0,40,3.02946090698242,1,6,1,2.23129272460938,40.0782012939453,,,,,,,,,,,,,,,,
,3949035375.7385,2.99978423118591,52533,-0.168369818995911,6.68098045817006E-5,1,0.999253354069792,40.0298881530762,1.99884151272034,17.8999993950129,-1.84817560539541,-0.34283944563104,25,-0.000996052842643208,-0.168062372890346,-0.0022399523168958,2.99981284141541,2.99981284141541,52482.90625,52583.09375,55.9630387198905,20.6247154333737,2.86185455322266,0,0,0,40,3.02886891365051,1,6,1,2.239990234375,40.5669593811035,,,,,,,,,,,,,,,,
,3949035439.665,2.99987363815308,58930.861328125,-0.134552204814222,5.46146949856434E-5,1,0.999253354069792,40.0298881530762,1.99885653538309,17.8900007158518,-1.47792625786399,-0.27398205741965,25,-0.000776185981184852,-0.134390429065525,-0.00177573335223322,2.99994301795959,2.99994301795959,58875.91015625,58985.8125,56.4836033136983,20.62643184054,2.86189937591553,0,0,0,40,3.02846932411194,1,6,1,2.24349975585938,40.5669593811035,,,,,,,,,,,,,,,,
,3949035503.6095,3.00053977966309,65329.03125,-0.105901958634982,8.877092325556E-5,1,0.999253354069792,40.0298881530762,1.99881187864531,17.8999993950129,-1.16447108661895,-0.212535026711939,25,-0.000319139607962056,-0.105839122504676,-0.00110498883963735,3.0005259513855,3.0005259513855,65278.984375,65379.078125,55.4588883249866,20.6250680026554,2.86242628097534,0,0,0,40,3.02816295623779,1,6,1,2.24441528320313,41.055721282959,,,,,,,,,,,,,,,,
,3949035567.5765,3.00023746490479,71731.921875,-0.0823564022166582,7.12736421115983E-5,1,0.999253354069792,40.0298881530762,1.99867199142099,17.8900007158518,-0.905901122134304,-0.165962550024842,25,-0.000307642869466553,-0.0823524834154881,-0.000914394854004095,3.00032019615173,3.00032019615173,71681.8125,71782.03125,55.7793560178713,20.6165654200414,2.86246800422668,0,0,0,40,3.0268189907074,1,6,1,2.25631713867187,41.055721282959,,,,,,,,,,,,,,,,
,3949035631.545,2.99996566772461,78135.69140625,-0.0621275424882635,8.82902591209963E-5,1,0.999253354069792,40.0298881530762,1.9986346322572,17.8900007158518,-0.683895553818486,-0.124311273225941,25,-0.000151689782932656,-0.0621569646895605,-0.000603991792792262,2.99988698959351,2.99988698959351,78085.7890625,78185.59375,55.7465276200636,20.6178336875518,2.86263751983643,0,0,0,40,3.02543163299561,1,6,1,2.24517822265625,41.5444793701172,,,,,,,,,,,,,,,,
,3949035695.5155,2.99983024597168,84533.41796875,-0.0450533025178565,7.63740909300482E-5,1,0.999253354069792,40.0298881530762,1.99867734566907,17.8900007158518,-0.496312676394259,-0.0894897945163883,25,-5.16261195721655E-5,-0.0450963052483919,-0.00037445023084582,2.99964547157288,2.99964547157288,84478.390625,84588.4453125,56.3585427506213,20.6196130394815,2.86255288124084,0,0,0,40,3.02428770065308,1,6,1,2.23007202148438,41.055721282959,,,,,,,,,,,,,,,,
,3949035760.427,2.99989211559296,91032.30078125,-0.0302025229410229,6.64489839835457E-5,1,0.999253354069792,40.0298881530762,1.99874775655841,17.8900007158518,-0.333086241878009,-0.0588203868111586,2.5,6.99686876000479E-5,-0.0302453599040388,-0.000142173502037978,2.99988341331482,2.99988341331482,90982.28125,91082.3203125,55.5315797772751,20.6231236248456,2.86238956451416,0,0,0,40,3.02323246002197,1,6,1,2.24136352539062,41.5444793701172,,,,,,,,,,,,,,,,
,3949035825.4155,3.00006449222565,97525.10546875,-0.0181088993451302,5.90721398168752E-5,1,0.999253354069792,40.0298881530762,1.99868315761931,17.8900007158518,-0.199918047836531,-0.0345433939901123,2.5,0.000106007110526287,-0.0181422806607553,-1.83056539919714E-5,3.00001859664917,3.00001859664917,97475.2265625,97574.984375,55.8614270123905,20.6234809664195,2.86250734329224,0,0,0,40,3.02306509017944,1,6,1,2.22579956054687,42.0332374572754,,,,,,,,,,,,,,,,
,3949035889.307,2.99984037876129,103917.51953125,-0.00829033317779541,7.13974255937195E-5,1,0.999253354069792,40.0298881530762,1.99845429942483,17.8900007158518,-0.0921209226553504,-0.012600726387779,2.5,0.000338842897205775,-0.00831054293010676,0.000283901830268973,2.99975299835205,2.99975299835205,103867.53125,103967.5078125,56.2670922138713,20.6148455436492,2.86150717735291,0,0,0,40,3.02278089523315,1,6,1,2.24456787109375,41.5444793701172,,,,,,,,,,,,,,,,
,3949035954.323,2.99969208240509,110430.80859375,-0.00168596147143528,4.7720080761171E-5,1,0.999253354069792,40.0298881530762,1.99878469868767,17.8900007158518,-0.0190251094019987,-0.000984150641098072,0.25,0.000211740432612348,-0.00169155800436517,0.000201232594055644,2.99968314170837,2.99968314170837,110390.7265625,110470.890625,55.6167772858713,20.6274990369474,2.86115097999573,0,0,0,40,3.02295470237732,1,6,1,2.23175048828125,42.0332374572754,,,,,,,,,,,,,,,,
,3949036018.2145,2.99993884563446,116824.33203125,0.00166460207802905,5.97466651248158E-5,1,0.999253354069792,40.0298881530762,1.99853622047543,17.8900007158518,0.0180097004410011,0.00533144902878834,0.25,0.00018614787558077,0.00166806864754024,0.00019728253174967,2.99971318244934,2.99971318244934,116774.3203125,116874.34375,56.1154562811405,20.6298683188353,2.86098217964172,0,0,0,40,3.02399873733521,1,6,1,2.24899291992187,42.0332374572754,,,,,,,,,,,,,,,,
,3949036082.2045,2.99994850158691,123227.14453125,0.00196443932670263,2.51787817547606E-6,1,0.999253354069792,40.0298881530762,1.99871571565007,17.8900007158518,0.0216582638619651,0.00406759459805631,0.25,1.8406959409653E-5,0.00197035059886257,3.06534022256314E-5,3.00002598762512,3.00002598762512,123177.0703125,123277.21875,55.8035865019674,20.6302772514711,2.86095833778381,0,0,0,40,3.02478837966919,1,6,1,2.24197387695313,42.0332374572754,,,,,,,,,,,,,,,,
,3949036147.1445,2.99990582466126,129719.3984375,0.00209471423725356,2.09065858350845E-6,1,0.999253354069792,40.0298881530762,1.99875627851353,17.8900007158518,0.023108454145876,0.00429544203568713,0.25,1.60929074888992E-5,0.00210156682131187,2.87826005178175E-5,2.99995350837708,2.99995350837708,129669.3671875,129769.4296875,55.9817978043521,20.6311156518539,2.86014699935913,0,0,0,40,3.02675533294678,1,6,1,2.24456787109375,42.5219955444336,,,,,,,,,,,,,,,,
,3949036211.069,2.99955630302429,136113.1328125,0.00219476623789559,2.2117442753637E-6,1,0.999253354069792,40.0298881530762,1.99830427920866,17.8900007158518,0.0242117309805199,0.00450460004112468,0.25,1.75897548011045E-5,0.00220243691137883,3.05227981775003E-5,2.9995596408844,2.9995596408844,136063.109375,136163.15625,55.8450128134867,20.6201465670684,2.85911321640015,0,0,0,40,3.02886056900024,1,6,1,2.2308349609375,42.0332374572754,,,,,,,,,,,,,,,,
,3949036284.9985,3.00009167194366,137799.703125,0.00222160928594261,2.16977881281133E-6,1,0.999253354069792,40.0298881530762,1.99868131598,17.8900007158518,0.0245115459525627,0.00457232677972902,0.25,1.89492524410343E-5,0.00222949170998216,3.19480807370455E-5,2.99995422363281,2.99995422363281,137750.390625,137849.015625,55.6050528580828,20.6274443372209,2.8580002784729,0,0,0,40,3.03028202056885,1,6,1,2.24380493164062,42.5219955444336,,,,,,,,,,,,,,,,
,3949036348.976,2.99971318244934,131489.3203125,0.0021241301622053,2.11273401564504E-6,1,0.999253354069792,40.0298881530762,1.99859637116434,17.8900007158518,0.0234353259912515,0.00434088278578509,0.25,1.50764910819707E-5,0.00213122356585871,2.78417999375191E-5,2.99967622756958,2.99967622756958,131445.234375,131533.40625,55.8520474701598,20.6302196860921,2.86010694503784,0,0,0,40,3.02740979194641,1,6,1,2.2454833984375,42.5219955444336,,,,,,,,,,,,,,,,
,3949036412.9165,3.00021588802338,125179.921875,0.00201019942307405,2.16219615770781E-6,1,0.999253354069792,40.0298881530762,1.99853742000931,17.8900007158518,0.0221607748412786,0.00417271111855854,0.25,1.98822997431458E-5,0.00201639946943443,3.23139697278678E-5,3.00014472007751,3.00014472007751,125130.2734375,125229.5703125,56.2342638160636,20.6270106786505,2.86098980903626,0,0,0,40,3.02603936195374,1,6,1,2.22885131835938,42.0332374572754,,,,,,,,,,,,,,,,
,3949036476.894,2.99992477893829,118864.3984375,0.00191396828730238,3.10710587849153E-5,1,0.999253354069792,40.0298881530762,1.99872971408862,17.8900007158518,0.0208229465009016,0.00550612249680108,0.25,0.000157521625195909,0.00191849417068282,0.000170076101863368,2.99988722801209,2.99988722801209,118815.1953125,118913.6015625,56.0427648288521,20.6288116746171,2.86118030548096,0,0,0,40,3.02425789833069,1,6,1,2.22991943359375,43.0107536315918,,,,,,,,,,,,,,,,
,3949036540.8235,3.00023806095123,112554.62890625,0.0032337413571607,5.35116602889368E-5,1,0.999253354069792,40.0298881530762,1.99848980319986,17.8999993950129,0.035125477001182,0.00953120163186765,0.25,0.000286624700856705,0.0032402874391603,0.000308356998108736,3.00027060508728,3.00027060508728,112500.203125,112609.0546875,55.4956248653905,20.6242763084278,2.86163187026978,0,0,0,40,3.02350854873657,1,6,1,2.23220825195313,42.5219955444336,,,,,,,,,,,,,,,,
,3949036605.779,3.00009441375732,106138.92578125,0.00820062609727578,7.90728978202732E-5,1,0.999253354069792,40.0298881530762,1.99841226834619,17.8900007158518,0.0896999246600195,0.0204881741293185,2.5,0.000392480278075556,0.0082167168856772,0.000447978197346403,3.00010824203491,3.00010824203491,106094.375,106183.4765625,56.465625857756,20.6225420495992,2.86148810386658,0,0,0,40,3.02294611930847,1,6,1,2.22686767578125,43.0107536315918,,,,,,,,,,,,,,,,
,3949036669.726,3.00014209747314,99835.58984375,0.0162558470957115,6.12182313603139E-5,1,0.999253354069792,40.0298881530762,1.99890970734526,17.8900007158518,0.178391713139119,0.0372379488153193,2.5,0.00046981113141819,0.0162841335624297,0.000581561751390632,3.00028657913208,3.00028657913208,99791.15625,99880.0234375,56.2053435608521,20.6326528002044,2.86169147491455,0,0,0,40,3.02261304855347,1,6,1,2.24472045898438,42.5219955444336,,,,,,,,,,,,,,,,
,3949036734.702,2.99992489814758,93421.66015625,0.0263989649929478,6.64825271033107E-5,1,0.999253354069792,40.0298881530762,1.99864669831717,17.8900007158518,0.28988255800008,0.0586081878908649,2.5,0.000592458137624444,0.026435855930432,0.000777453485914774,2.9999668598175,2.9999668598175,93367.375,93475.9453125,56.7243448976214,20.6249533138867,2.86198663711548,0,0,0,40,3.02327919006348,1,6,1,2.24349975585938,42.0332374572754,,,,,,,,,,,,,,,,
,3949036798.602,2.99985706806183,87116.2578125,0.0388592244765697,5.39080207697178E-5,1,0.999253354069792,40.0298881530762,1.9987844970467,17.8900007158518,0.427018962951403,0.083666951829082,2.5,0.000633014617054451,0.0388990988510002,0.0009101025556537,2.99979281425476,2.99979281425476,87062.0390625,87170.4765625,56.2545861575636,20.6258928451081,2.86177754402161,0,0,0,40,3.0239622592926,1,6,1,2.24288940429687,42.0332374572754,,,,,,,,,,,,,,,,
,3949036862.597,3.00000941753387,80796.93359375,0.0534359075877089,4.67761052401988E-5,1,0.999253354069792,40.0298881530762,1.9988217082761,17.8999993950129,0.587391066507499,0.112518918046249,2.5,0.000638375752948961,0.0534682768489213,0.00102537875202435,3.00010538101196,3.00010538101196,80747.5,80846.3671875,55.7832641604674,20.6342543434304,2.86192297935486,0,0,0,40,3.02495169639587,1,6,1,2.22930908203125,42.0332374572754,,,,,,,,,,,,,,,,
,3949036927.5515,2.99997866153717,74376.12890625,0.0703342558401055,5.60361199711889E-5,1,0.999253354069792,40.0298881530762,1.99856844121051,17.8900007158518,0.772610932871439,0.148331356074073,2.5,0.0008621126027422,0.0703417136906489,0.00137815456041513,2.99990463256836,2.99990463256836,74321.46875,74430.7890625,56.2835064127752,20.6272875724205,2.86210799217224,0,0,0,40,3.02641534805298,1,6,1,2.24594116210938,41.5444793701172,,,,,,,,,,,,,,,,
,3949036991.553,3.00011730194092,68030.71484375,0.089786753839748,5.82771138951436E-5,1,0.999253354069792,40.0298881530762,1.9987354442469,17.8999993950129,0.986210660101606,0.187254520205672,2.5,0.000910798748609266,0.0897500437899577,0.00157525267511636,3.00018572807312,3.00018572807312,67981.3828125,68080.046875,55.4119906138328,20.6319539502323,2.8623354434967,0,0,0,40,3.02748656272888,1,6,1,2.23236083984375,41.5444793701172,,,,,,,,,,,,,,,,
,3949037056.4355,3.00017845630646,61592.173828125,0.112574608728163,5.42960713738426E-5,1,0.999253354069792,40.0298881530762,1.99853655725664,17.8900007158518,1.23564414892839,0.234826769811521,25,0.00115650900901134,0.112463540191017,0.00199250647186403,3.00016117095947,3.00016117095947,61542.8203125,61641.52734375,56.3577611221021,20.6254315109595,2.86312580108643,0,0,0,40,3.02878999710083,1,6,1,2.24716186523438,41.5444793701172,,,,,,,,,,,,,,,,
,3949037120.413,3.0000319480896,55243.216796875,0.138480076385881,4.42035267822988E-5,1,0.999253354069792,40.0298881530762,1.99877215190763,17.8900007158518,1.51959652416096,0.286728692311975,25,0.00124268736922146,0.138261120651633,0.00226843165930753,3.00004100799561,3.00004100799561,55193.55859375,55292.875,56.2905410694483,20.636474419131,2.86276412010193,0,0,0,40,3.02962017059326,1,6,1,2.24395751953125,41.5444793701172,,,,,,,,,,,,,,,,
,3949037184.346,2.99992144107819,48905.619140625,0.168665711945007,5.11696162744329E-5,1,0.999253354069792,40.0298881530762,1.99864069270712,17.8900007158518,1.84962074416154,0.348564442453372,25,0.00148601741217716,0.168292414106147,0.00272286271232464,2.99998641014099,2.99998641014099,48855.953125,48955.28515625,55.6472607981213,20.6302580390868,2.86277341842651,0,0,0,40,3.02949261665344,1,6,1,2.2454833984375,41.055721282959,,,,,,,,,,,,,,,,
,3949037248.29,3.00000095367432,42555.06640625,0.20430508098816,6.50246528795452E-5,1,0.999253354069792,40.0298881530762,1.99859040075095,17.8900007158518,2.23889744082855,0.422039044817771,25,0.00183591973299363,0.203718334901171,0.00330611165274284,3,3,42505.60546875,42604.52734375,56.1701702774867,20.6267676041726,2.86262941360474,0,0,0,40,3.02883315086365,1,6,1,2.24288940429687,42.0332374572754,,,,,,,,,,,,,,,,
,3949037312.222,2.99985134601593,36205.64453125,0.24727991862762,5.86955011530139E-5,1,0.999253354069792,40.0298881530762,1.99871621244575,17.8900007158518,2.70884386590999,0.50678949974505,25,0.00193203732704845,0.246406206195713,0.00366176472928708,2.99974060058594,2.99974060058594,36160.73828125,36250.55078125,56.1865844763906,20.6375201755091,2.86356329917908,0,0,0,40,3.02718496322632,1,6,1,2.23098754882813,41.5444793701172,,,,,,,,,,,,,,,,
,3949037376.1885,3.00011610984802,29843.05859375,0.299339646739403,7.01347316540295E-5,1,0.999253354069792,40.0298881530762,1.9986723185926,17.8900007158518,3.27691609181697,0.612720518879639,25,0.00238834514273814,0.298081046193829,0.00439910343911862,3.00011992454529,3.00011992454529,29793.435546875,29892.681640625,56.3030471257559,20.6342273913895,2.86283016204834,0,0,0,40,3.0244312286377,1,6,1,2.25784301757813,41.5444793701172,,,,,,,,,,,,,,,,
,3949037441.1275,3.00039041042328,23380.595703125,0.368667653343245,7.42417866369086E-5,1,0.999253354069792,40.0298881530762,1.99863430335694,17.8999993950129,4.03348534756993,0.75191163976529,25,0.00286848598002209,0.366873745499388,0.00521454266930943,3.00037455558777,3.00037455558777,23326.21875,23434.97265625,55.9763264047175,20.6304310677163,2.8633017539978,0,0,0,40,3.01983213424683,1,6,1,2.25677490234375,41.5444793701172,,,,,,,,,,,,,,,,
,3949037509.076,3.00059127807617,16609.0166015625,0.0823055678382261,0.000281866727145589,1,0.999253354069792,40.0298881530762,1.9988170338321,17.8999993950129,0.899821434530851,0.168580992486318,2.5,0.000750324741216666,0.0818506605264543,0.00123710977550052,3.00044727325439,3.00044727325439,16559.080078125,16658.953125,56.3530713509867,20.6389402648804,2.86313343048096,0,0,0,40,3.01528787612915,1,6,1,2.23968505859375,42.0332374572754,,,,,,,,,,,,,,,,
,3949037575.0595,2.99785602092743,10015.486328125,0.0463933330178899,0.000304809031848491,1,0.999253354069792,40.0298881530762,1.99866968129092,17.8999993950129,0.506843325401784,0.0951497613109528,2.5,0.000461984051858016,0.0461102484825593,0.000713884473483438,2.99769592285156,2.99769592285156,9965.4912109375,10065.4814453125,56.8071975206598,20.6293810219144,2.86243867874146,0,0,0,40,3.00813126564026,1,6,1,2.24807739257813,41.5444793701172,,,,,,,,,,,,,,,,
,3949037642.013,3.00015342235565,3326.1787109375,0.192432412957587,0.000277014332525978,1,0.999253354069792,40.0298881530762,1.99887102305417,17.8900007158518,2.10245501592908,0.389077328040693,25,0.00151250895449168,0.191168295030269,0.00246602337478671,3.00003981590271,3.00003981590271,3276.06396484375,3376.29345703125,56.8494054606983,20.6369899534507,2.86203837394714,0,0,0,40,3.00725293159485,1,6,1,2.24639892578125,41.5444793701172,,,,,,,,,,,,,,,,
,3949037705.9235,3.00012910366058,-3064.73486328125,0.185323424145733,0.000280632410568668,1,0.999253354069792,40.0298881530762,1.99886154638744,17.8900007158518,2.0248200404974,0.374260911764859,25,0.0014201142021041,0.184103265802531,0.00233537046027501,3.00006055831909,3.00006055831909,-3109.69653320313,-3019.77319335937,56.0333852866213,20.638333717692,2.86037755012512,0,0,0,40,3.00649952888489,1,6,1,2.24319458007813,41.5444793701172,,,,,,,,,,,,,,,,
,3949037770.913,2.99641835689545,-9567.9443359375,0.0367809696910058,0.000313165132419634,1,0.999253354069792,40.0298881530762,1.99878473898815,17.8900007158518,0.402061018656946,0.0741713340811444,2.5,0.000251853339533576,0.036555852388104,0.00045102845452701,2.99653768539429,2.99653768539429,-9622.8720703125,-9513.0166015625,56.4671891147944,20.6379269310278,2.8583242893219,0,0,0,40,3.00460267066956,6,6,1,2.24197387695313,41.5444793701172,,,,,,,,,,,,,,,,
,3949037837.8555,2.99968111515045,-16266.3950195313,0.188917668169719,0.000236076212217679,1,0.999253354069792,40.0298881530762,1.99892606746719,17.8900007158518,2.06620631869507,0.382534952977156,25,0.00132305919398875,0.187869940452987,0.00243805007704643,2.99966716766357,2.99966716766357,-16316.3955078125,-16216.39453125,56.2881961838906,20.6429041670103,2.85729432106018,0,0,0,40,3.01290559768677,1,6,1,2.24685668945313,41.5444793701172,,,,,,,,,,,,,,,,
,3949037903.7525,3.00001466274262,-22859.740234375,0.292800037940211,0.000143715938690186,1,0.999253354069792,40.0298881530762,1.99880197161664,17.8900007158518,3.20390436522972,0.595074657757137,25,0.00209392791350265,0.291361233494359,0.00394883425038838,2.99999308586121,2.99999308586121,-22909.794921875,-22809.685546875,56.4843849422175,20.6330524764761,2.85686731338501,0,0,0,40,3.01853632926941,1,6,1,2.24166870117187,41.5444793701172,,,,,,,,,,,,,,,,
,3949037969.7135,2.99988448619843,-29462.3125,0.195461769074997,0.000169698405456433,1,0.999253354069792,40.0298881530762,1.99860301726217,17.8999993950129,2.14022937281711,0.396504268467829,25,0.00123848679401027,0.194634329316104,0.00254911821729793,2.99993181228638,2.99993181228638,-29512.29296875,-29412.33203125,55.9263021794867,20.6378147801477,2.85723447799683,0,0,0,40,3.02306914329529,1,6,1,2.24411010742187,41.5444793701172,,,,,,,,,,,,,,,,
,3949038033.6975,3.00010919570923,-35861.3125,0.286094898207565,5.69884567641898E-5,1,0.999253354069792,40.0298881530762,1.9988707238053,17.8900007158518,3.134648229152,0.583632859971128,25,0.00199026888568769,0.285075335663012,0.00398861405045133,3.00013613700867,3.00013613700867,-35906.3203125,-35816.3046875,55.7988967308521,20.6378494211742,2.85689282417297,0,0,0,40,3.0261607170105,1,6,1,2.24395751953125,40.0782012939453,,,,,,,,,,,,,,,,
,3949038098.6715,2.99988734722137,-42369.724609375,0.101674338494318,0.000208474064749995,1,0.999253354069792,40.0298881530762,1.99883548006586,17.8900007158518,1.11486859903221,0.206969120587732,2.5,0.000633298323661224,0.101382386548495,0.001365237977726,2.99988102912903,2.99988102912903,-42419.734375,-42319.71484375,56.3788650921214,20.6430096882074,2.85600233078003,0,0,0,40,3.02862048149109,1,6,1,2.24090576171875,41.5444793701172,,,,,,,,,,,,,,,,
,3949038163.578,3.00006103515625,-48857.443359375,0.188147342585084,5.47810240995052E-5,1,0.999253354069792,40.0298881530762,1.99885369007677,17.8900007158518,2.06442763112805,0.383458318010091,25,0.00116581131622214,0.187733618654873,0.00254642766711838,2.999924659729,2.999924659729,-48912.45703125,-48802.4296875,55.832506757179,20.6451317577427,2.85640716552734,0,0,0,40,3.02951192855835,1,6,1,2.2442626953125,41.055721282959,,,,,,,,,,,,,,,,
,3949038229.5165,2.9999703168869,-55454.578125,0.149504319204496,5.66639439635452E-5,1,0.999253354069792,40.0298881530762,1.99888572458168,17.8900007158518,1.64167762985019,0.304085432110415,25,0.000841757289023927,0.149274727602196,0.00195013121344601,2.9999885559082,2.9999885559082,-55504.59375,-55404.5625,56.7282530402175,20.6411818224568,2.85654997825623,0,0,0,40,3.02892851829529,1,6,1,2.25799560546875,41.055721282959,,,,,,,,,,,,,,,,
,3949038294.486,3.00006139278412,-61957.484375,0.120304413248179,7.26206662866211E-5,1,0.999253354069792,40.0298881530762,1.99890295109217,17.8900007158518,1.32203537029901,0.243907934663002,25,0.000590948935114722,0.120194571371925,0.00148488113376037,3.00007605552673,3.00007605552673,-62007.7265625,-61907.2421875,55.9349000931982,20.6394586057896,2.8567361831665,0,0,0,40,3.02823758125305,1,6,1,2.25631713867187,41.5444793701172,,,,,,,,,,,,,,,,
,3949038358.4655,3.00037467479706,-68355.0546875,0.0944842895639753,7.23855818905868E-5,1,0.999253354069792,40.0298881530762,1.99897702198061,17.8999993950129,1.03906570993831,0.190893615973654,25,0.000396647852848408,0.0944524663112757,0.00109580952888901,3.00040626525879,3.00040626525879,-68410.0625,-68300.046875,56.851750346256,20.6398218339472,2.85698223114014,0,0,0,40,3.02722978591919,1,6,1,2.26242065429687,41.5444793701172,,,,,,,,,,,,,,,,
,3949038422.375,3.00029182434082,-74752.62890625,0.0723410987316536,7.56234048000973E-5,1,0.999253354069792,40.0298881530762,1.99868902533618,17.8900007158518,0.79622543892103,0.144210381135853,25,0.00012718499303198,0.0723565257638073,0.000657436062243522,3.00024175643921,3.00024175643921,-74802.546875,-74702.7109375,56.3804283491598,20.6391739564022,2.85743975639343,0,0,0,40,3.02629828453064,1,6,1,2.24594116210938,41.055721282959,,,,,,,,,,,,,,,,
,3949038486.3585,3.00049102306366,-81150.73828125,0.0538157478547465,5.81941792069634E-5,1,0.999253354069792,40.0298881530762,1.99892318244662,17.8900007158518,0.592627617080367,0.107650631129008,25,0.000128002910335545,0.0538534821644147,0.000517065430168881,3.00038266181946,3.00038266181946,-81195.7421875,-81105.734375,56.7681160946983,20.652462038323,2.85768032073975,0,0,0,40,3.02535057067871,1,6,1,2.24227905273438,41.055721282959,,,,,,,,,,,,,,,,
,3949038551.2625,2.99979817867279,-87647.515625,0.0374870531729545,6.65118647874572E-5,1,0.999253354069792,40.0298881530762,1.99889044030051,17.8900007158518,0.413295790788098,0.0733486128059109,2.5,-5.7658415500242E-5,0.0375316254416657,0.000208462595014612,2.99990797042847,2.99990797042847,-87697.640625,-87597.390625,56.5312826533714,20.6458923844321,2.85721349716187,0,0,0,40,3.023353099823,1,6,1,2.2491455078125,41.055721282959,,,,,,,,,,,,,,,,
,3949038616.289,3.00028204917908,-94150.296875,0.0241185499031195,6.11790303783225E-5,1,0.999253354069792,40.0298881530762,1.99885886493732,17.8900007158518,0.266087029994538,0.0468089501894477,2.5,-6.99375206552662E-5,0.024157607681344,9.7715284027187E-5,3.00030946731567,3.00030946731567,-94200.3046875,-94100.2890625,56.2069068178906,20.6563577116707,2.8571400642395,0,0,0,40,3.02317953109741,1,6,1,2.24212646484375,40.5669593811035,,,,,,,,,,,,,,,,
,3949038680.197,3.00014841556549,-100548.234375,0.0130950922631007,5.63927954537845E-5,1,0.999253354069792,40.0298881530762,1.99883713894312,17.8900007158518,0.144937006652044,0.0231134515759701,2.5,-0.000245375841056525,0.0131226577119316,-0.000156804612295882,3.00006794929504,3.00006794929504,-100593.203125,-100503.265625,56.4124751184483,20.6476037223369,2.85782480239868,0,0,0,40,3.0226788520813,1,6,1,2.24594116210938,41.055721282959,,,,,,,,,,,,,,,,
,3949038744.1435,2.9999121427536,-106945.91015625,0.00468812989004368,7.78730692991294E-5,1,0.999253354069792,40.0298881530762,1.99881836551069,17.8900007158518,0.0523468356387863,0.00580659808436001,2.5,-0.00031098476514157,0.00470108254889433,-0.000280589928916765,2.99996900558472,2.99996900558472,-106995.96875,-106895.8515625,56.4163832610444,20.6447993794378,2.85671544075012,0,0,0,40,3.02259612083435,1,6,1,2.23785400390625,40.5669593811035,,,,,,,,,,,,,,,,
,3949038809.1135,2.99993336200714,-113442.703125,-0.00063045203142227,9.60392798676491E-5,1,0.999253354069792,40.0298881530762,1.99869429908182,17.8900007158518,-0.00638335731261152,-0.00446889328321422,0.25,-0.00029238354947207,-0.000630226577506901,-0.000297232661919669,3,3,-113487.6953125,-113397.7109375,56.4374872310637,20.6486865802068,2.8572473526001,0,0,0,40,3.02313899993897,1,6,1,2.24563598632813,40.5669593811035,,,,,,,,,,,,,,,,
,3949038873.027,3.00009620189667,-119839.984375,-0.00193552541076242,2.18776773578979E-5,1,0.999253354069792,40.0298881530762,1.99872600429213,17.8900007158518,-0.0212250659193245,-0.00463296424470299,0.25,-7.46328583371392E-5,-0.00194072035349229,-8.70371237249602E-5,3.00011730194092,3.00011730194092,-119889.9296875,-119790.0390625,55.4799922950059,20.6513404577197,2.85648036003113,0,0,0,40,3.02418112754822,1,6,1,2.24456787109375,40.5669593811035,,,,,,,,,,,,,,,,
,3949038936.9925,2.9999623298645,-126237.8203125,-0.00203198311325019,1.95262338515592E-6,1,0.999253354069792,40.0298881530762,1.99883382827444,17.8900007158518,-0.0224048886590496,-0.00421930146088902,0.25,-2.02101882311468E-5,-0.00203833405444578,-3.27204560963966E-5,3.00002360343933,3.00002360343933,-126292.765625,-126182.875,55.9309919506021,20.6576215800176,2.85746121406555,0,0,0,40,3.02554798126221,1,6,1,2.26150512695313,40.5669593811035,,,,,,,,,,,,,,,,
,3949039000.941,2.99984133243561,-132639.296875,-0.00214415586643696,2.08315893201692E-6,1,0.999253354069792,40.0298881530762,1.998795362248,17.8900007158518,-0.0236469123351978,-0.00445297335579728,0.25,-2.16716184740286E-5,-0.00215136572307136,-3.45149774782817E-5,2.99985551834106,2.99985551834106,-132694.34375,-132584.25,56.1146746526213,20.6547743045877,2.85691285133362,0,0,0,40,3.02776956558228,1,6,1,2.25845336914062,40.0782012939453,,,,,,,,,,,,,,,,
,3949039064.9185,3.00014615058899,-139036.25,-0.00223821780562917,2.24672528897916E-6,1,0.999253354069792,40.0298881530762,1.99878811949467,17.8900007158518,-0.0246912925024922,-0.00463921293298507,0.25,-2.20844445598989E-5,-0.00224623196061573,-3.51204095211224E-5,3.00010752677918,3.00010752677918,-139086.28125,-138986.21875,55.598799829929,20.6588441490292,2.85654735565186,0,0,0,40,3.03009080886841,1,6,1,2.23114013671875,39.1006851196289,,,,,,,,,,,,,,,,
,3949039138.813,2.9998631477356,-134846.2265625,-0.00218108489214744,2.2460451940231E-6,1,0.999253354069792,40.0298881530762,1.99880623291503,17.8999993950129,-0.024056909081745,-0.00452575813888664,0.25,-2.17845621085245E-5,-0.00218858847980112,-3.47235151393073E-5,2.99981784820557,2.99981784820557,-134895.6875,-134796.765625,55.0547863805443,20.656869884183,2.85621047019958,0,0,0,40,3.02889060974121,1,6,1,2.24594116210938,40.5669593811035,,,,,,,,,,,,,,,,
,3949039203.836,3.00011897087097,-128413.0859375,-0.00207433785370699,2.17187862744726E-6,1,0.999253354069792,40.0298881530762,1.99881599408032,17.8900007158518,-0.0228766541369823,-0.00429039310371322,0.25,-1.91972942708485E-5,-0.00208100288417017,-3.18453155695582E-5,3.00023007392883,3.00023007392883,-128467.28125,-128358.890625,55.9575673202559,20.6556359646125,2.85893297195435,0,0,0,40,3.02634310722351,1,6,1,2.257080078125,40.0782012939453,,,,,,,,,,,,,,,,
,3949039269.7385,3.0003570318222,-121894.62109375,-0.00194353942008022,5.38555332675682E-6,1,0.999253354069792,40.0298881530762,1.99881803912913,17.8900007158518,-0.0214094044325747,-0.00412706396564503,0.25,-2.74472800002221E-5,-0.00194922369919961,-3.96594860078282E-5,3.0002908706665,3.0002908706665,-121949.1015625,-121840.140625,55.3775989589866,20.6553071091213,2.85938692092896,0,0,0,40,3.02484560012817,1,6,1,2.24594116210938,40.5669593811035,,,,,,,,,,,,,,,,
,3949039333.6905,3.00004947185516,-115568.1875,-0.00199979351805679,4.72516977613341E-5,1,0.999253354069792,40.0298881530762,1.9989306709502,17.8999993950129,-0.021465267565589,-0.00737982355109261,0.25,-0.000311781506975188,-0.00200327282738292,-0.000325454134543117,3.00010657310486,3.00010657310486,-115617.625,-115518.75,55.5112574357751,20.6533415032826,2.85990071296692,0,0,0,40,3.02357196807861,1,6,1,2.22869873046875,40.5669593811035,,,,,,,,,,,,,,,,
,3949039398.6495,2.99999439716339,-109137.9296875,-0.00554891830712675,5.9894244745289E-5,1,0.999253354069792,40.0298881530762,1.9988677001061,17.8900007158518,-0.0606640532508108,-0.014168542647715,0.25,-0.000293205402816995,-0.00556049253938505,-0.000330431821504211,3.00007009506226,3.00007009506226,-109187.3203125,-109088.5390625,55.6738361677751,20.6532805790616,2.86047172546387,0,0,0,40,3.0228590965271,1,6,1,2.2296142578125,40.5669593811035,,,,,,,,,,,,,,,,
,3949039463.599,3.00042843818665,-102718.609375,-0.0120878897199305,6.76314138617749E-5,1,0.999253354069792,40.0298881530762,1.99870475402493,17.8999993950129,-0.132498386660796,-0.0286030909329174,2.5,-0.000432824091880387,-0.0121103331023663,-0.000515278255985601,3.00048899650574,3.00048899650574,-102768.0546875,-102669.1640625,55.5495572332174,20.6518074314905,2.86046528816223,0,0,0,40,3.02298426628113,1,6,1,2.24639892578125,40.5669593811035,,,,,,,,,,,,,,,,
,3949039527.551,3.00002551078796,-96392.8984375,-0.0214155767655247,8.45709394575497E-5,1,0.999253354069792,40.0298881530762,1.99889906058412,17.8900007158518,-0.23524356241602,-0.0474940321999723,2.5,-0.000476257165730928,-0.02144946262596,-0.000624908109019103,3.00001406669617,3.00001406669617,-96437.4296875,-96348.3671875,55.7699764756405,20.6481179919799,2.86060118675232,0,0,0,40,3.02284908294678,1,6,1,2.244873046875,40.5669593811035,,,,,,,,,,,,,,,,
,3949039592.502,3.00013637542725,-89957.8125,-0.0329430271262717,6.06577651296372E-5,1,0.999253354069792,40.0298881530762,1.99878988192594,17.8900007158518,-0.361888547023377,-0.0719926503660051,2.5,-0.000633945111365847,-0.0329824398143071,-0.00086707323854992,3.0002167224884,3.0002167224884,-90007.2734375,-89908.3515625,55.903634952429,20.6420505945844,2.86077332496643,0,0,0,40,3.02348685264587,1,6,1,2.24334716796875,40.5669593811035,,,,,,,,,,,,,,,,
,3949039656.4405,2.99982237815857,-83637.375,-0.0464146842918602,6.16882673724118E-5,1,0.999253354069792,40.0298881530762,1.99870552329554,17.8900007158518,-0.509905751441327,-0.0998838777756196,2.5,-0.000750734927898082,-0.046451021111997,-0.00108474573271218,2.99974679946899,2.99974679946899,-83686.8828125,-83587.8671875,56.8791073444291,20.6417382515156,2.86115479469299,0,0,0,40,3.0245316028595,1,6,1,2.25265502929687,41.055721282959,,,,,,,,,,,,,,,,
,3949039720.388,2.99987924098969,-77311.42578125,-0.062271769498967,6.39708143182264E-5,1,0.999253354069792,40.0298881530762,1.99861744908448,17.8999993950129,-0.68437280271358,-0.130511183728554,2.5,-0.000688825000483607,-0.0622933837474071,-0.00114320711156594,2.99988985061646,2.99988985061646,-77365.828125,-77257.0234375,55.7488725056213,20.6452822822263,2.86074328422546,0,0,0,40,3.02554225921631,1,6,1,2.24288940429687,40.5669593811035,,,,,,,,,,,,,,,,
,3949039784.3445,3.00019204616547,-70952.109375,-0.0804471342285613,5.5501178600064E-5,1,0.999253354069792,40.0298881530762,1.9986645179309,17.8999993950129,-0.883472779476323,-0.169721426275801,2.5,-0.000991876846066521,-0.080432975403985,-0.00158517811213123,3.00021052360535,3.00021052360535,-71001.8828125,-70902.3359375,55.7191706218905,20.6384818206303,2.86118078231812,0,0,0,40,3.027099609375,1,6,1,2.24746704101562,41.055721282959,,,,,,,,,,,,,,,,
,3949039849.3025,3.0002349615097,-64491.173828125,-0.101963915565204,4.8915632429674E-5,1,0.999253354069792,40.0298881530762,1.99861678108138,17.8999993950129,-1.11959060247853,-0.212350278734957,25,-0.00101159108015599,-0.101890541293572,-0.00176817485989203,3.00016045570374,3.00016045570374,-64536.0390625,-64446.30859375,56.3139899250252,20.6421780386448,2.86184287071228,0,0,0,40,3.02847743034363,1,6,1,2.2479248046875,41.055721282959,,,,,,,,,,,,,,,,
,3949039913.304,3.00010347366333,-58119.4765625,-0.126330548379334,4.53943825894531E-5,1,0.999253354069792,40.0298881530762,1.99879217495752,17.8900007158518,-1.38657842013242,-0.262180470135446,25,-0.00118073260981258,-0.126165548820715,-0.00211836949224994,3.00014901161194,3.00014901161194,-58169.15234375,-58069.80078125,56.1443765363521,20.6447645470272,2.86124801635742,0,0,0,40,3.02920985221863,1,6,1,2.24197387695313,41.055721282959,,,,,,,,,,,,,,,,
,3949039978.2225,2.99990952014923,-51657.529296875,-0.154982809710117,4.72519749590359E-5,1,0.999253354069792,40.0298881530762,1.99869003004629,17.8900007158518,-1.70007044482495,-0.320469133345746,25,-0.00136776513872654,-0.154682909097723,-0.00251037929869304,2.99998807907105,2.99998807907105,-51712.234375,-51602.82421875,56.8118872917752,20.6372240658733,2.86138868331909,0,0,0,40,3.02940106391907,1,6,1,2.24609375,41.5444793701172,,,,,,,,,,,,,,,,
,3949040042.143,3.00007200241089,-45306.75390625,-0.188040249057645,6.10034647835049E-5,1,0.999253354069792,40.0298881530762,1.99857680516025,17.8999993950129,-2.06136317160176,-0.38785447979077,25,-0.00161462257502773,-0.187554736987601,-0.00298061766747789,3.00009536743164,3.00009536743164,-45356.515625,-45256.9921875,56.2749084990636,20.6402506017023,2.86184668540955,0,0,0,40,3.02960300445557,1,6,1,2.24441528320313,41.055721282959,,,,,,,,,,,,,,,,
,3949040107.0915,3.00016248226166,-38841.3125,-0.228311129093438,5.10389122719236E-5,1,0.999253354069792,40.0298881530762,1.99887889807528,17.8900007158518,-2.50173657091183,-0.469236124944008,25,-0.00186863313256118,-0.227567482409746,-0.00348673554296726,3.00007820129395,3.00007820129395,-38891.125,-38791.5,56.5179949685444,20.6397511593659,2.86209392547607,0,0,0,40,3.02821826934814,1,6,1,2.25051879882813,40.5669593811035,,,,,,,,,,,,,,,,
,3949040172.038,2.99995028972626,-32367.41796875,-0.277790923737878,5.92340028157107E-5,1,0.999253354069792,40.0298881530762,1.99860679093419,17.8900007158518,-3.04175646078503,-0.568628191218131,25,-0.00217364687361712,-0.276696767327923,-0.00407278872318799,2.99992084503174,2.99992084503174,-32417.3828125,-32317.453125,56.5859966497175,20.6366766666619,2.86215162277222,0,0,0,40,3.02538967132568,1,6,1,2.23236083984375,41.055721282959,,,,,,,,,,,,,,,,
,3949040235.9875,2.99989783763886,-25983.9013671875,-0.338953481140717,6.67099978657922E-5,1,0.999253354069792,40.0298881530762,1.99859660465241,17.8900007158518,-3.70935789964967,-0.691215108620484,25,-0.00256286641025891,-0.337393978285634,-0.00477148225405663,2.99984359741211,2.99984359741211,-26033.72265625,-25934.080078125,56.0787197407367,20.634931531532,2.86155009269714,0,0,0,40,3.02175688743591,1,6,1,2.2430419921875,41.5444793701172,,,,,,,,,,,,,,,,
,3949040301.9455,3.00012183189392,-19406.125,-0.199029082947575,0.000214993020125047,1,0.999253354069792,40.0298881530762,1.99851893923829,17.8900007158518,-2.17652947184335,-0.4058228463005,25,-0.00160488802271356,-0.197982649935021,-0.00282105063155386,3.00013089179993,3.00013089179993,-19461.005859375,-19351.244140625,56.5359724244868,20.6352349995635,2.86090421676636,0,0,0,40,3.01707673072815,5,6,1,2.24838256835938,41.5444793701172,,,,,,,,,,,,,,,,
,3949040368.898,3.00026738643646,-12717.65625,-0.190285740907923,0.000235149236632321,1,0.999253354069792,40.0298881530762,1.99860169605625,17.8900007158518,-2.07979950846486,-0.387300672200562,25,-0.00157952925698031,-0.189169053675844,-0.00265269452107119,3.00021076202393,3.00021076202393,-12767.61328125,-12667.69921875,55.9943038606598,20.6269487983688,2.86132788658142,0,0,0,40,3.01176190376282,1,6,1,2.23098754882813,41.5444793701172,,,,,,,,,,,,,,,,
,3949040434.856,3.00032722949982,-6120.57348632813,-0.114904654268019,0.00795345719028157,1,0.999253354069792,40.0298881530762,1.99851667824734,17.8900007158518,-1.25585820200257,-0.229938316857212,25,-0.00066197600778181,-0.114172268618909,-0.00125565701144815,3.00025129318237,3.00025129318237,-6170.56591796875,-6070.5810546875,55.8911288961213,20.6295150375321,2.86010241508484,0,0,0,40,3.00807404518127,5,6,1,2.25006103515625,41.5444793701172,,,,,,,,,,,,,,,,
,3949040498.8105,3.00087451934814,271.949409484863,-0.194560374559135,0.00029609188035399,1,0.999253354069792,40.0298881530762,1.9987501545028,17.8900007158518,-2.12534465901552,-0.392711677676359,25,-0.00151135955748703,-0.193251540737808,-0.0024399971692546,3.00044679641724,3.00044679641724,217.094131469727,326.8046875,56.3186796961406,20.6355854001553,2.85967969894409,0,0,0,40,3.00771808624268,1,6,1,2.24365234375,41.5444793701172,,,,,,,,,,,,,,,,
,3949040564.712,2.99975275993347,6867.91357421875,-0.206239066317645,0.00025679044631473,1,0.999253354069792,40.0298881530762,1.99876699810522,17.8999993950129,-2.25384647651768,-0.416434383761256,25,-0.00151077520420828,-0.20493388530324,-0.00258562688704998,2.999844789505,2.999844789505,6817.94970703125,6917.87744140625,55.1563980880443,20.6377788750763,2.85860204696655,0,0,0,40,3.00669097900391,1,6,1,2.24212646484375,41.5444793701172,,,,,,,,,,,,,,,,
,3949040632.078,2.99909806251526,13600.9697265625,-0.031981925073039,0.000311187020589397,1,0.999253354069792,40.0298881530762,1.99889818420756,17.8900007158518,-0.349751174924045,-0.0644531956706782,2.5,-0.00020353315742795,-0.031797038210505,-0.00038632243588824,2.99909806251526,2.99909806251526,13591.0234375,13610.916015625,55.8176558153136,20.6331331545526,2.85658979415894,0,0,0,40,3.01008772850037,1,6,1,2.22869873046875,41.5444793701172,,,,,,,,,,,,,,,,
,3949040699.6335,2.99973368644714,20364.240234375,-0.177499959535885,0.00022747819041759,1,0.999253354069792,40.0298881530762,1.99874479775437,17.8900007158518,-1.94181032220842,-0.36015370495703,25,-0.00125200757633441,-0.176584239505846,-0.00234868544552253,2.99973106384277,2.99973106384277,20314.205078125,20414.275390625,57.1284468420637,20.6374562168768,2.8555862903595,0,0,0,40,3.01642537117004,1,6,1,2.24624633789062,41.5444793701172,,,,,,,,,,,,,,,,
,3949040765.5775,2.99977338314056,26962.728515625,-0.205077592384675,0.000178702759040242,1,0.999253354069792,40.0298881530762,1.99856305612883,17.8900007158518,-2.24463970050547,-0.417295138474088,25,-0.00145333091005177,-0.204155279015796,-0.00280111117903844,2.99976778030396,2.99976778030396,26917.685546875,27007.771484375,56.5508233663521,20.6280997527805,2.85592889785767,0,0,0,40,3.02159738540649,1,6,1,2.23464965820313,41.5444793701172,,,,,,,,,,,,,,,,
,3949040829.58,2.99951386451721,33366.458984375,-0.307841788935647,4.86620979466181E-5,1,0.999253354069792,40.0298881530762,1.99873224231681,17.8900007158518,-3.3718697516179,-0.62742745041195,25,-0.0021387720201716,-0.306663550562257,-0.00425785865117729,2.99955129623413,2.99955129623413,33321.41796875,33411.5,55.7738846182367,20.6380518695318,2.85550093650818,0,0,0,40,3.02498984336853,1,6,1,2.24639892578125,41.5444793701172,,,,,,,,,,,,,,,,
,3949040894.488,2.99993097782135,39863.912109375,-0.262338338820835,7.46372163702317E-5,1,0.999253354069792,40.0298881530762,1.99868007464533,17.8999993950129,-2.87530441669138,-0.535430838119016,25,-0.00179741086428842,-0.261514681754216,-0.00366640469021522,2.99987053871155,2.99987053871155,39813.921875,39913.90234375,56.0795013692559,20.6343426795944,2.85483503341675,0,0,0,40,3.02771186828613,1,6,1,2.24319458007813,41.5444793701172,,,,,,,,,,,,,,,,
,3949040958.476,3.00009977817535,46262.36328125,-0.209366741642718,7.13499044745673E-5,1,0.999253354069792,40.0298881530762,1.99870790663183,17.8900007158518,-2.29642221723029,-0.426894637489754,25,-0.00133682619565706,-0.208850253408283,-0.00286313223356073,3.00010395050049,3.00010395050049,46207.34765625,46317.37890625,56.2194128741983,20.6351523190899,2.85433721542358,0,0,0,40,3.02899026870728,1,6,1,2.25051879882813,41.5444793701172,,,,,,,,,,,,,,,,
,3949041022.413,3.00002348423004,52665.6484375,-0.167585271325298,5.70231349259746E-5,1,0.999253354069792,40.0298881530762,1.9987447861863,17.8900007158518,-1.83943268196437,-0.341626531506701,25,-0.00102721983229129,-0.167281208080451,-0.00226549600335756,3.00003290176392,3.00003290176392,52620.55859375,52710.73828125,57.0369963053137,20.6324227461261,2.85472583770752,0,0,0,40,3.02938365936279,1,6,1,2.24517822265625,42.0332374572754,,,,,,,,,,,,,,,,
,3949041088.368,3.00010991096497,59258.759765625,-0.132834057188205,5.60808562604654E-5,1,0.999253354069792,40.0298881530762,1.99859673506311,17.8900007158518,-1.45899918599757,-0.270014661655934,25,-0.000725869437730084,-0.132678769606538,-0.00171278522444893,2.99998354911804,2.99998354911804,59203.54296875,59313.9765625,55.9677284910059,20.6322260102697,2.85525417327881,0,0,0,40,3.02909898757935,1,6,1,2.25021362304687,42.0332374572754,,,,,,,,,,,,,,,,
,3949041153.3145,2.99997699260712,65756.87890625,-0.104535000953723,8.24935825768223E-5,1,0.999253354069792,40.0298881530762,1.99863919369827,17.8900007158518,-1.14906572400676,-0.211589478647262,25,-0.00047956230008667,-0.104475730644794,-0.00125493571236659,2.99998450279236,2.99998450279236,65706.8671875,65806.890625,55.8028048734482,20.6334511277829,2.85507678985596,0,0,0,40,3.02758026123047,1,6,1,2.24380493164062,41.5444793701172,,,,,,,,,,,,,,,,
,3949041217.261,2.99989402294159,72159.90234375,-0.0809638906296018,7.69890553154306E-5,1,0.999253354069792,40.0298881530762,1.99866045943595,17.8999993950129,-0.890565043145607,-0.163414620197702,25,-0.000325878115073851,-0.0809627348436802,-0.00092198147719637,3.00002121925354,3.00002121925354,72109.828125,72209.9765625,56.0771564836982,20.6303277006899,2.85456466674805,0,0,0,40,3.02617120742798,1,6,1,2.24517822265625,42.0332374572754,,,,,,,,,,,,,,,,
,3949041281.2235,3.00005352497101,78553.58203125,-0.0608384525667227,8.0349114559732E-5,1,0.999253354069792,40.0298881530762,1.99862490200321,17.8900007158518,-0.669828664977807,-0.121149321894511,25,-9.57644176096798E-5,-0.0608695952732318,-0.000538247227627259,3.00016641616821,3.00016641616821,78503.5859375,78603.578125,56.1623539922944,20.6336528722209,2.85514712333679,0,0,0,40,3.02521538734436,1,6,1,2.24868774414062,42.5219955444336,,,,,,,,,,,,,,,,
,3949041345.135,2.99981653690338,84951.1875,-0.0438697078341896,8.94846418937522E-5,1,0.999253354069792,40.0298881530762,1.99865135904518,17.8900007158518,-0.483464941899511,-0.0861204750163828,25,4.19134786539157E-5,-0.0439135316714141,-0.000271977706684282,2.99977540969849,2.99977540969849,84906.0546875,84996.3203125,56.1623539922944,20.638585557376,2.85505747795105,0,0,0,40,3.02408385276794,1,6,1,2.22732543945313,42.0332374572754,,,,,,,,,,,,,,,,
,3949041411.0735,3.00010991096497,91550.14453125,-0.0292890809709279,6.43654890178705E-5,1,0.999253354069792,40.0298881530762,1.99856735230184,17.8999993950129,-0.322843025566295,-0.057890326544353,2.5,-9.77512310493068E-6,-0.0293310537407576,-0.000215269696163814,3.00007367134094,3.00007367134094,91500.109375,91600.1796875,55.9216124083713,20.6402486000174,2.85488963127136,0,0,0,40,3.02352952957153,1,6,1,2.23968505859375,42.5219955444336,,,,,,,,,,,,,,,,
,3949041475.067,2.99991571903229,97952.71484375,-0.0172403838126302,5.9369740819581E-5,1,0.999253354069792,40.0298881530762,1.9986056053092,17.8900007158518,-0.190424644467883,-0.0323434744969921,2.5,0.000149960789964323,-0.0172729331505775,3.18819348211221E-5,2.99992227554321,2.99992227554321,97902.6328125,98002.796875,55.9669468624867,20.6387874398955,2.85431241989136,0,0,0,40,3.02268767356873,1,6,1,2.25051879882813,42.0332374572754,,,,,,,,,,,,,,,,
,3949041539.976,2.9996052980423,104445.70703125,-0.00802615509896142,5.20548404797544E-5,1,0.999253354069792,40.0298881530762,1.998699248382,17.8900007158518,-0.0888333805697644,-0.0142433784209734,2.5,0.000142813880479733,-0.00804470207557126,8.93354893927995E-5,2.99948477745056,2.99948477745056,104395.6484375,104495.765625,55.9997752602944,20.6384007947086,2.85361528396606,0,0,0,40,3.0226936340332,1,6,1,2.24273681640625,42.5219955444336,,,,,,,,,,,,,,,,
,3949041604.9745,2.99978530406952,110949.1015625,-0.00129542798522687,4.57135541300114E-5,1,0.999253354069792,40.0298881530762,1.99856639894797,17.8900007158518,-0.0146625035839487,-0.000501094114211594,0.25,0.000185783459884553,-0.00129990945409907,0.000177789696753246,2.9998288154602,2.9998288154602,110899.1484375,110999.0546875,55.8379781568136,20.6378102784487,2.85394835472107,0,0,0,40,3.02305006980896,1,6,1,2.2418212890625,42.5219955444336,,,,,,,,,,,,,,,,
,3949041668.8825,3.00008964538574,117342.45703125,0.00172549268828912,5.06325663295346E-5,1,0.999253354069792,40.0298881530762,1.99855405165577,17.8900007158518,0.0187051050242965,0.00532471715565547,0.25,0.000174689673211505,0.00172924457329615,0.000186160705600791,3.00000739097595,3.00000739097595,117292.390625,117392.5234375,55.8348516427367,20.6330592292334,2.8524923324585,0,0,0,40,3.02412819862366,1,6,1,2.22808837890625,42.5219955444336,,,,,,,,,,,,,,,,
,3949041732.8575,3.00004231929779,123744.8359375,0.00197797227973921,2.72889552317826E-6,1,0.999253354069792,40.0298881530762,1.9985328509947,17.8900007158518,0.021800378503684,0.00412707216901363,0.25,2.14342741303128E-5,0.00198394783933597,3.37470720532756E-5,3.00002431869507,3.00002431869507,123694.9140625,123794.7578125,56.0810646262944,20.6339472470574,2.85341167449951,0,0,0,40,3.0258412361145,1,6,1,2.24227905273438,42.5219955444336,,,,,,,,,,,,,,,,
,3949041796.8465,3.00007212162018,130152.171875,0.00210037399845202,2.08892201851843E-6,1,0.999253354069792,40.0298881530762,1.99862314746742,17.8900007158518,0.0231628251980339,0.00434601169212181,0.25,1.97063202058963E-5,0.00210725709011116,3.24183831312611E-5,2.99997282028198,2.99997282028198,130107.2421875,130197.1015625,56.5578580230252,20.6366224091479,2.85291981697083,0,0,0,40,3.02751016616821,1,6,1,2.24838256835938,42.5219955444336,,,,,,,,,,,,,,,,
,3949041860.789,2.99957966804504,136546.0625,0.00220294626531463,1.62922968110491E-6,1,0.999253354069792,40.0298881530762,1.99872169857619,17.8999993950129,0.0243071795845192,0.00452209390483133,0.25,1.76571146342018E-5,0.00221067752156263,3.06137572627922E-5,2.9996235370636,2.9996235370636,136501.09375,136591.03125,56.1443765363521,20.6457411845714,2.85247468948364,0,0,0,40,3.0290093421936,1,6,1,2.242431640625,42.5219955444336,,,,,,,,,,,,,,,,
,3949041897.7075,2.99896681308746,140002.3984375,0.00225194286695972,1.92679258296089E-6,1,0.999253354069792,40.0298881530762,1.99864770223025,17.8999993950129,0.0248546104291284,0.00459545464290403,0.25,1.57572619436838E-5,0.00226011321501702,2.87939826953974E-5,2.99911117553711,2.99911117553711,139999.890625,140004.90625,55.9591305772944,20.6411575634643,2.85215950012207,0,0,0,40,3.02993321418762,1,4,1,2.2430419921875,42.5219955444336,,,,,,,,,,,,,,,,