File: PPMS_Data_and_Plotting/Data/NbTi/0006.csv
[Header]
; VSM Data File (default extension .dat)
; Copyright (c) 2003-2013, Quantum Design, Inc. All rights reserved.
TITLE,
FILEOPENTIME,3949044084.4954,02/18/2025,12:44 pm
BYAPP,VSM,1.0,1.0
INFO,DYNACOOL VSM Option Release 1.4.10 Build 1,APPNAME
INFO,Quantum Design Linear Motor Servo Controller,MOTOR_MODULE_NAME
INFO,3101-100 L2,MOTOR_HW_VERSION
INFO,MMC884,MOTOR_SERIAL_NUMBER
INFO,SRV No X-over 01.03.11,MOTOR_SOFTWARE_VERSION
INFO,Quantum Design VSM Detection Module,VSM_MODULE_NAME
INFO,3101-150 F0,VSM_HW_VERSION
INFO,VSM641,VSM_SERIAL_NUMBER
INFO,VSM No X-over 01.02.05 May 20 2008 13:51:47,VSM_SOFTWARE_VERSION
INFO,VPA645,PREAMP_SERIAL_NUMBER
INFO,740,COIL_SERIAL_NUMBER
INFO,0,MOMENT_UNITS
INFO,NbTi,SAMPLE_MATERIAL
INFO,,SAMPLE_COMMENT
INFO,4.3,SAMPLE_MASS
INFO,,SAMPLE_VOLUME
INFO,,SAMPLE_MOLECULAR_WEIGHT
INFO,,SAMPLE_SIZE
INFO,,SAMPLE_SHAPE
DATATYPE,COMMENT,1
DATATYPE,TIME,2
STARTUPAXIS,X,2
STARTUPAXIS,Y1,5
[Data]
Comment,Time Stamp (sec),Temperature (K),Magnetic Field (Oe),Moment (emu),M. Std. Err. (emu),Transport Action,Averaging Time (sec),Frequency (Hz),Peak Amplitude (mm),Center Position (mm),Coil Signal' (mV),Coil Signal" (mV),Range (mV),M. Quad. Signal (emu),M. Raw' (emu),M. Raw" (emu),Min. Temperature (K),Max. Temperature (K),Min. Field (Oe),Max. Field (Oe),Mass (grams),Motor Lag (deg),Pressure (Torr),VSM Status (code),Motor Status (code),Measure Status (code),Measure Count,System Temp. (K),Temp. Status (code),Field Status (code),Chamber Status (code),Motor Current (amps),Motor Heatsink Temp. (C),Map 01,Map 02,Map 03,Map 04,Map 05,Map 06,Map 07,Map 08,Map 09,Map 10,Map 11,Map 12,Map 13,Map 14,Map 15,Map 16
sample offset = 33.45 mm,3949046243.107,4.20092105865479,-0.342219620943069,7.22463422322878E-5,2.12310262662988E-7,1,0.999253354069792,40.0298881530762,1.99877846564872,17.8900007158518,0.000790608316680077,0.000137920988636407,0.25,-1.60815336392662E-7,7.17632262412039E-5,1.88150517949574E-7,4.20092105865479,4.20092105865479,-0.342219620943069,-0.342219620943069,55.7230787644867,20.6129546374545,3.56188726425171,0,0,0,40,4.20883655548096,1,4,1,2.2406005859375,30.3030319213867,,,,,,,,,,,,,,,,
,3949046316.341,4.19959545135498,6390.05419921875,-0.348391578919565,0.000189387067125116,1,0.999253354069792,40.0298881530762,1.99897715485504,17.8900007158518,-3.80752263970808,-0.70384752042606,25,-0.00259491989351016,-0.34617461262321,-0.0043981104775611,4.19964027404785,4.19964027404785,6340.06982421875,6440.03857421875,55.9177042657751,20.630718243122,3.58701658248901,0,0,0,40,4.21023082733154,1,6,1,2.24151611328125,36.6568908691406,,,,,,,,,,,,,,,,
,3949046380.2825,4.1999659538269,12788.6909179688,-0.502132334980525,7.51009904087277E-5,1,0.999253354069792,40.0298881530762,1.99897634674464,17.8900007158518,-5.48998514422823,-1.01809419695953,25,-0.00378959105413247,-0.499190841402895,-0.00662631223761278,4.19991588592529,4.19991588592529,12743.693359375,12833.6884765625,55.8411046708905,20.6337500033527,3.5866527557373,0,0,0,40,4.21219921112061,1,6,1,2.2467041015625,38.1231689453125,,,,,,,,,,,,,,,,
,3949046448.296,4.19950604438782,19590.8818359375,-0.24412383146515,0.00014652346927158,1,0.999253354069792,40.0298881530762,1.99898883677282,17.8900007158518,-2.67080950533076,-0.495127127601014,25,-0.00171321206120771,-0.242846230465125,-0.00320923232025994,4.19956636428833,4.19956636428833,19545.921875,19635.841796875,56.2936675835252,20.6284655186652,3.58614039421082,0,0,0,40,4.21334266662598,5,6,1,2.242431640625,38.6119270324707,,,,,,,,,,,,,,,,
,3949046512.182,4.1998233795166,25984.1884765625,-0.314075013645544,6.31190132077972E-5,1,0.999253354069792,40.0298881530762,1.99900244833335,17.8900007158518,-3.43814787841383,-0.638438915559902,25,-0.00217714353582455,-0.312631307417127,-0.00422455650489155,4.1997389793396,4.1997389793396,25939.21484375,26029.162109375,56.0771564836982,20.631887424396,3.58538460731506,0,0,0,40,4.2147741317749,1,6,1,2.24273681640625,39.5894432067871,,,,,,,,,,,,,,,,
,3949046576.158,4.19975352287292,32387.9443359375,-0.246536171060635,8.50808159899406E-5,1,0.999253354069792,40.0298881530762,1.99889723382283,17.8900007158518,-2.70039979796962,-0.50193363763039,25,-0.00167465370767351,-0.245567422932618,-0.00336133420832138,4.19968509674072,4.19968509674072,32332.873046875,32443.015625,56.384336491756,20.633691090019,3.5845901966095,0,0,0,40,4.21575975418091,1,6,1,2.2454833984375,40.0782012939453,,,,,,,,,,,,,,,,
,3949046640.123,4.20008373260498,38786.107421875,-0.184152924640206,5.79138799715756E-5,1,0.999253354069792,40.0298881530762,1.99887010075325,17.8900007158518,-2.01853353696565,-0.374657675758629,25,-0.00115955655704348,-0.183554523646221,-0.00246547481337018,4.20023393630981,4.20023393630981,38736.05078125,38836.1640625,56.2569310431213,20.6319940289537,3.58407258987427,0,0,0,40,4.21545124053955,1,6,1,2.23953247070313,40.0782012939453,,,,,,,,,,,,,,,,
,3949046704.0675,4.19995045661926,45183.359375,-0.139146515927777,6.69203523612924E-5,1,0.999253354069792,40.0298881530762,1.99884306044878,17.8900007158518,-1.52635273376818,-0.282539069936991,25,-0.000785411683770181,-0.138788457516284,-0.00179687939117319,4.19994401931763,4.19994401931763,45128.3515625,45238.3671875,56.8298647477175,20.6355209125111,3.58266854286194,0,0,0,40,4.21406936645508,1,6,1,2.22808837890625,40.5669593811035,,,,,,,,,,,,,,,,
,3949046768.0065,4.20016551017761,51582.23046875,-0.104610309605903,6.2846429578865E-5,1,0.999253354069792,40.0298881530762,1.99888465005797,17.8999993950129,-1.14852157087571,-0.211252786433793,25,-0.000461342723192177,-0.104410514722212,-0.0012333545939082,4.20009899139404,4.20009899139404,51532.23828125,51632.22265625,56.4718788859098,20.6340131225405,3.58263516426086,0,0,0,40,4.21216773986816,1,6,1,2.24533081054687,41.055721282959,,,,,,,,,,,,,,,,
,3949046831.976,4.20046424865723,57985.130859375,-0.0776436124145734,5.94802451494695E-5,1,0.999253354069792,40.0298881530762,1.99880116069451,17.8900007158518,-0.852977735727356,-0.156764315262282,25,-0.000328021605073077,-0.0775441695569919,-0.000904758800206397,4.20039701461792,4.20039701461792,57935.16796875,58035.09375,56.1013869677944,20.6331652926836,3.58199143409729,0,0,0,40,4.20943689346313,1,6,1,2.24349975585938,41.055721282959,,,,,,,,,,,,,,,,
,3949046895.866,4.20018696784973,64377.76171875,-0.0558344872816563,4.93257488760997E-5,1,0.999253354069792,40.0298881530762,1.99869271886495,17.8900007158518,-0.613750949664358,-0.112618090729904,25,-0.000220639944639733,-0.055796219187625,-0.000635180368900145,4.20025873184204,4.20025873184204,64327.76171875,64427.76171875,55.2783321370443,20.629272985104,3.58111119270325,0,0,0,40,4.2053542137146,1,6,1,2.24395751953125,42.0332374572754,,,,,,,,,,,,,,,,
,3949046961.127,4.20021986961365,70906.78125,-0.037754121949322,7.10567570991734E-5,1,0.999253354069792,40.0298881530762,1.99874343664456,17.8999993950129,-0.415498270073298,-0.0748172243399764,2.5,-2.60753180054934E-5,-0.0377505784750245,-0.000304569326426785,4.20028305053711,4.20028305053711,70881.765625,70931.796875,55.6879054811213,20.6242692499735,3.58028817176819,0,0,0,40,4.20168972015381,1,6,1,2.24319458007813,41.5444793701172,,,,,,,,,,,,,,,,
,3949047024.7915,4.20011520385742,77279.62890625,-0.0237025386251799,4.90434805368937E-5,1,0.999253354069792,40.0298881530762,1.99865772681445,17.8900007158518,-0.26113950517178,-0.0460963699951456,2.5,6.30121242979593E-5,-0.0237130807881072,-0.000109812336815717,4.20010232925415,4.20010232925415,77224.5546875,77334.703125,56.1318704800444,20.6277043639284,3.5805332660675,0,0,0,40,4.19793653488159,1,6,1,2.23358154296875,42.0332374572754,,,,,,,,,,,,,,,,
,3949047089.7725,4.20035839080811,83777.73046875,-0.0124784024750106,5.38497725181809E-5,1,0.999253354069792,40.0298881530762,1.99886572473012,17.8900007158518,-0.137689546499978,-0.0235532136423432,2.5,9.78480099485624E-5,-0.0124904496366522,8.35464444808256E-6,4.20035839080811,4.20035839080811,83727.6640625,83827.796875,55.4073008427174,20.6299637315896,3.58057069778442,0,0,0,40,4.19384527206421,1,6,1,2.24853515625,42.0332374572754,,,,,,,,,,,,,,,,
,3949047153.6925,4.20022702217102,90176.0078125,-0.00445951697967722,5.62403334997136E-5,1,0.999253354069792,40.0298881530762,1.99872571314872,17.8900007158518,-0.0494449175365201,-0.00719451617876335,2.5,0.000145585314412008,-0.00446654738463567,0.000114358392542487,4.20025968551636,4.20025968551636,90130.96875,90221.046875,56.0787197407367,20.6298261232697,3.57988166809082,0,0,0,40,4.19008541107178,1,6,1,2.2283935546875,42.0332374572754,,,,,,,,,,,,,,,,
,3949047219.7045,4.20012831687927,96779.546875,0.000627424398299601,7.91612336312723E-5,1,0.999253354069792,40.0298881530762,1.99856209623872,17.8999993950129,0.00645018926629426,0.00385677616821746,0.25,0.000237545830357119,0.000626890557625409,0.000242288727533134,4.20015048980713,4.20015048980713,96734.4921875,96824.6015625,55.7027564229867,20.6351360908616,3.57958149909973,0,0,0,40,4.18617725372314,1,6,1,2.24273681640625,41.055721282959,,,,,,,,,,,,,,,,
,3949047283.6085,4.20044827461243,103176.60546875,0.00165830786404156,1.3863485540624E-5,1,0.999253354069792,40.0298881530762,1.9987782357629,17.8900007158518,0.0181935091368675,0.00383866900645828,0.25,5.16428348148866E-5,0.00166148117376967,6.29202777487312E-5,4.20044374465942,4.20044374465942,103126.5546875,103226.65625,55.9591305772944,20.632244289536,3.57794737815857,0,0,0,40,4.18312931060791,1,6,1,2.22854614257813,42.5219955444336,,,,,,,,,,,,,,,,
,3949047347.5965,4.20029449462891,109574.98046875,0.00178120069846458,2.39421545332197E-6,1,0.999253354069792,40.0298881530762,1.99868082165895,17.8900007158518,0.0196308411000351,0.00365707564181426,0.25,1.34290346549127E-5,0.00178548595239396,2.51621969631915E-5,4.20042896270752,4.20042896270752,109519.9609375,109630,55.9122328661405,20.6253501082645,3.57805466651916,0,0,0,40,4.18024444580078,1,6,1,2.24136352539062,42.5219955444336,,,,,,,,,,,,,,,,
,3949047411.548,4.19974160194397,115973.34375,0.00189235989347671,2.88319364669506E-6,1,0.999253354069792,40.0298881530762,1.9985013334177,17.8900007158518,0.020865826674462,0.00385602781011256,0.25,1.186260756639E-5,0.00189750232891474,2.40048353246621E-5,4.19957590103149,4.19957590103149,115923.2109375,116023.4765625,56.1998721612175,20.6297336052735,3.57769370079041,0,0,0,40,4.17826366424561,1,6,1,2.24258422851562,41.5444793701172,,,,,,,,,,,,,,,,
,3949047475.46,4.20047760009766,122370.80859375,0.00199434194463134,2.04252248763582E-6,1,0.999253354069792,40.0298881530762,1.9986810048647,17.8999993950129,0.0219869026500174,0.00412883125485221,0.25,1.85987770292696E-5,0.002000273974226,3.10763588934373E-5,4.20040798187256,4.20040798187256,122325.6953125,122415.921875,55.1595246021212,20.6267028027037,3.57776021957397,0,0,0,40,4.17677640914917,1,6,1,2.2442626953125,42.5219955444336,,,,,,,,,,,,,,,,
,3949047540.42,4.19994020462036,128868.95703125,0.00208745191739354,2.38430359610529E-6,1,0.999253354069792,40.0298881530762,1.99871213924519,17.8900007158518,0.0230211755016672,0.0043138113877003,0.25,1.90211528011718E-5,0.00209419684827017,3.17232277506016E-5,4.20010375976562,4.20010375976562,128819.046875,128918.8671875,56.0224424873521,20.6358332911473,3.57641839981079,0,0,0,40,4.17505168914795,1,6,1,2.24838256835938,42.5219955444336,,,,,,,,,,,,,,,,
,3949047604.3445,4.19996619224548,135266.9609375,0.00218136679958343,1.94426527301055E-6,1,0.999253354069792,40.0298881530762,1.99844722179776,17.8900007158518,0.0240549390309672,0.00453310139379338,0.25,2.24871261336839E-5,0.00218889886236594,3.54065109909196E-5,4.20007658004761,4.20007658004761,135212,135321.921875,55.4385659834866,20.6304144302047,3.57604241371155,0,0,0,40,4.17474126815796,1,6,1,2.24411010742187,42.5219955444336,,,,,,,,,,,,,,,,
,3949047678.291,4.19999861717224,138600.4140625,0.00222918207601739,2.5413023882216E-6,1,0.999253354069792,40.0298881530762,1.9987780242718,17.8900007158518,0.0246015579983362,0.00456184663632337,0.25,1.66717015787571E-5,0.00223716346929582,2.96605787282817E-5,4.19981384277344,4.19981384277344,138550.984375,138649.84375,55.1696857728712,20.6396553959733,3.57503843307495,0,0,0,40,4.17534971237183,1,6,1,2.23342895507813,43.0107536315918,,,,,,,,,,,,,,,,
,3949047743.2405,4.1997013092041,132190.515625,0.00213628807420491,1.93959293179792E-6,1,0.999253354069792,40.0298881530762,1.99875762791598,17.8900007158518,0.0235628131967398,0.00441700939353734,0.25,1.98039787994436E-5,0.00214344822242685,3.26190342327865E-5,4.19964027404785,4.19964027404785,132145.984375,132235.046875,55.6910319951982,20.6429210857358,3.57571887969971,0,0,0,40,4.17515325546265,1,6,1,2.24349975585938,42.5219955444336,,,,,,,,,,,,,,,,
,3949047808.236,4.20066332817078,125776.609375,0.00204110169700565,2.49344688890558E-6,1,0.999253354069792,40.0298881530762,1.9986121826989,17.8999993950129,0.0225058376951092,0.0042198896437658,0.25,1.86617034977659E-5,0.00204745458780227,3.12476443862224E-5,4.20059871673584,4.20059871673584,125722.1640625,125831.0546875,56.0279138869867,20.6383475845662,3.57726526260376,0,0,0,40,4.17657470703125,1,6,1,2.2454833984375,43.0107536315918,,,,,,,,,,,,,,,,
,3949047872.1205,4.19984841346741,119476.55859375,0.00194734492117329,2.34608711289008E-6,1,0.999253354069792,40.0298881530762,1.99860461607019,17.8900007158518,0.0214656859327443,0.00402930169612648,0.25,1.78639548866011E-5,0.0019529016885743,3.01951338585691E-5,4.19990921020508,4.19990921020508,119427.453125,119525.6640625,55.7988967308521,20.6348432183882,3.5773503780365,0,0,0,40,4.17693614959717,1,6,1,2.2418212890625,43.0107536315918,,,,,,,,,,,,,,,,
,3949047937.087,4.19991827011108,113063.44921875,0.0018470346759142,2.30082957839311E-6,1,0.999253354069792,40.0298881530762,1.99865119556334,17.8900007158518,0.0203590892561156,0.00379535073203285,0.25,1.43258194258776E-5,0.00185178789166692,2.63258664207788E-5,4.20001268386841,4.20001268386841,113014.3515625,113112.546875,56.0497994855252,20.6349757741383,3.57838129997253,0,0,0,40,4.17854261398315,1,6,1,2.24716186523438,43.9882698059082,,,,,,,,,,,,,,,,
,3949048001.054,4.20003724098206,106748.15234375,0.00172265072040744,2.41208033752269E-6,1,0.999253354069792,40.0298881530762,1.99863647947152,17.8999993950129,0.018980341211365,0.00354808104730878,0.25,1.39281293916344E-5,0.00172654178966204,2.54031585529977E-5,4.20016479492188,4.20016479492188,106698.484375,106797.8203125,55.8059313875251,20.6367742639093,3.57821297645569,0,0,0,40,4.18132209777832,1,6,1,2.24319458007813,42.5219955444336,,,,,,,,,,,,,,,,
,3949048066.028,4.19968342781067,100334.83984375,0.00157444994593603,4.00906038532882E-5,1,0.999253354069792,40.0298881530762,1.99863541236086,17.8999993950129,0.0170366774064347,0.00494664492084046,0.25,0.000167043063527987,0.00157640779681836,0.000178087236214374,4.19962930679321,4.19962930679321,100285.359375,100384.3203125,55.5417409480251,20.6340360447861,3.57752895355225,0,0,0,40,4.18447971343994,1,6,1,2.2320556640625,43.0107536315918,,,,,,,,,,,,,,,,
,3949048129.9555,4.19962573051453,94030.2890625,0.00350934867299015,7.59947945193471E-5,1,0.999253354069792,40.0298881530762,1.99868594730273,17.8999993950129,0.0382545624260629,0.00937437724523267,0.25,0.000222368444336333,0.00351338781980326,0.000247142729603693,4.19960403442383,4.19960403442383,93980.875,94079.703125,56.4539014299675,20.6370490449354,3.57768869400024,0,0,0,40,4.18769407272339,1,6,1,2.24197387695313,41.055721282959,,,,,,,,,,,,,,,,
,3949048193.885,4.19960403442383,87719.79296875,0.00898923164926662,5.11435958030008E-5,1,0.999253354069792,40.0298881530762,1.99875253529875,17.8900007158518,0.0984836533130399,0.0210327596146728,0.25,0.000298776750238532,0.00899774540408583,0.000362947476632097,4.19967937469482,4.19967937469482,87665.703125,87773.8828125,56.2241026453136,20.6429213070868,3.57808113098145,0,0,0,40,4.19102144241333,1,6,1,2.236328125,42.5219955444336,,,,,,,,,,,,,,,,
,3949048258.89,4.19985914230347,81307.41796875,0.0175908582908948,6.48042073168326E-5,1,0.999253354069792,40.0298881530762,1.99905248248152,17.8900007158518,0.193063544466161,0.0388957193967869,2.5,0.000378185883379847,0.0176009675267654,0.000505556164882294,4.19990587234497,4.19990587234497,81253.2890625,81361.546875,56.6743206723906,20.6444582706554,3.57829308509827,0,0,0,40,4.19494199752808,1,6,1,2.23037719726562,42.5219955444336,,,,,,,,,,,,,,,,
,3949048322.78,4.19986128807068,74997.625,0.0285599901984593,6.87989710300031E-5,1,0.999253354069792,40.0298881530762,1.99883201554898,17.8900007158518,0.31337348904283,0.062520354790305,2.5,0.000557230722109223,0.0285629282568089,0.000766600785908445,4.19992733001709,4.19992733001709,74948.0078125,75047.2421875,56.5899047923137,20.6377634183674,3.57852482795715,0,0,0,40,4.19899606704712,1,6,1,2.26119995117187,43.49951171875,,,,,,,,,,,,,,,,
,3949048386.7575,4.19959998130798,68648.45703125,0.0425306522251421,6.21863675436258E-5,1,0.999253354069792,40.0298881530762,1.99888410186252,17.8900007158518,0.467067531417755,0.0895118465841107,2.5,0.000504468504382128,0.0425149946157548,0.000818991464961694,4.19982242584229,4.19982242584229,68598.984375,68697.9296875,56.211596589006,20.6346598308979,3.57803344726562,0,0,0,40,4.20240879058838,1,6,1,2.22900390625,42.5219955444336,,,,,,,,,,,,,,,,
,3949048450.702,4.19975900650024,62299.083984375,0.0593673799228069,4.38457015451108E-5,1,0.999253354069792,40.0298881530762,1.99895454029991,17.8900007158518,0.651688320747306,0.12450168250687,2.5,0.000667346398924176,0.0593122536927105,0.00110812982581715,4.19971466064453,4.19971466064453,62249.34375,62348.82421875,56.4070037188137,20.6405538227306,3.57806921005249,0,0,0,40,4.20701885223389,1,6,1,2.24227905273438,42.5219955444336,,,,,,,,,,,,,,,,
,3949048514.663,4.19984364509583,55954.705078125,0.0796454942667223,4.35638730499178E-5,1,0.999253354069792,40.0298881530762,1.99886650194888,17.8999993950129,0.874020389060346,0.165267921170202,2.5,0.000745338506390235,0.0795248653321852,0.00133562510354276,4.19992446899414,4.19992446899414,55900.05859375,56009.3515625,56.5703640793329,20.6421908740453,3.57805871963501,0,0,0,40,4.21021509170532,1,6,1,2.2418212890625,42.5219955444336,,,,,,,,,,,,,,,,
,3949048578.653,4.20006966590881,49606.421875,0.103995937560894,4.72206795505578E-5,1,0.999253354069792,40.0298881530762,1.99872055719764,17.8900007158518,1.14046680147626,0.215485822339021,2.5,0.000964764741904678,0.10377283769777,0.0017284357237501,4.20002698898315,4.20002698898315,49561.98046875,49650.86328125,56.3249327242944,20.6412052563364,3.57861137390137,0,0,0,40,4.21378803253174,1,6,1,2.24319458007813,42.5219955444336,,,,,,,,,,,,,,,,
,3949048643.5535,4.19958782196045,43167.517578125,0.134128764034046,4.84507096893509E-5,1,0.999253354069792,40.0298881530762,1.99893834620126,17.8900007158518,1.47041499282656,0.275942555098747,25,0.00109445081492627,0.133752973768996,0.0020621108062647,4.19967889785767,4.19967889785767,43123.125,43211.91015625,56.3155531820637,20.6464065270896,3.57886695861816,0,0,0,40,4.21490716934204,1,6,1,2.22885131835938,42.5219955444336,,,,,,,,,,,,,,,,
,3949048707.519,4.20009255409241,36813.83203125,0.170527338498481,3.92799010356398E-5,1,0.999253354069792,40.0298881530762,1.9989362675471,17.8900007158518,1.8682220542898,0.350367871210437,25,0.00140340982355136,0.169935304524338,0.00259987382734628,4.2000937461853,4.2000937461853,36759.015625,36868.6484375,57.2292769210445,20.6356247850814,3.57932758331299,0,0,0,40,4.21668243408203,1,6,1,2.25845336914062,42.5219955444336,,,,,,,,,,,,,,,,
,3949048771.4895,4.19979286193848,30447.00390625,0.216343862801225,5.53316924678081E-5,1,0.999253354069792,40.0298881530762,1.99874859508064,17.8900007158518,2.36864891633343,0.442524387119748,25,0.00168751350045973,0.215448166128824,0.003147288617908,4.19959259033203,4.19959259033203,30402.1796875,30491.828125,56.1693886489675,20.6447732807023,3.57886385917664,0,0,0,40,4.21682071685791,1,6,1,2.23220825195313,42.0332374572754,,,,,,,,,,,,,,,,
,3949048835.4075,4.20032954216003,24087.9560546875,0.275267053283537,5.6121288055748E-5,1,0.999253354069792,40.0298881530762,1.99888711329479,17.8900007158518,3.01233206260443,0.560751595596484,25,0.00205976535089826,0.273947739416629,0.0038234721697107,4.20033073425293,4.20033073425293,24033.45703125,24142.455078125,56.0302587725444,20.649651072719,3.57896518707275,0,0,0,40,4.2160120010376,1,6,1,2.23098754882813,42.0332374572754,,,,,,,,,,,,,,,,
,3949048900.367,4.20031666755676,17619.6396484375,0.353791087020776,8.2045144872498E-5,1,0.999253354069792,40.0298881530762,1.99906133884152,17.8999993950129,3.86984895309316,0.718367120358716,25,0.00261360812543749,0.351872556477274,0.00473411381012993,4.20022010803223,4.20022010803223,17569.69921875,17669.580078125,55.3627480171212,20.6495601363931,3.57838487625122,0,0,0,40,4.21461009979248,1,6,1,2.26394653320313,42.5219955444336,,,,,,,,,,,,,,,,
,3949048964.297,4.20034503936768,11235.646484375,0.454226208965852,0.000100796439578844,1,0.999253354069792,40.0298881530762,1.99889076979801,17.8900007158518,4.9654321819871,0.920351054037017,25,0.00343823452177414,0.451505793078892,0.00595227149671045,4.20029830932617,4.20029830932617,11185.6826171875,11285.6103515625,55.8348516427367,20.6465570514364,3.5780131816864,0,0,0,40,4.21307563781738,1,6,1,2.24777221679687,41.5444793701172,,,,,,,,,,,,,,,,
,3949049032.2495,4.20049262046814,4437.7109375,0.134160250443903,0.000269195737753066,1,0.999253354069792,40.0298881530762,1.99900552715491,17.8999993950129,1.46592530931185,0.271657683180446,25,0.0010774398249266,0.133288232394902,0.00175241250180291,4.20052051544189,4.20052051544189,4387.69677734375,4487.72509765625,55.8489209560828,20.645644468845,3.57720875740051,0,0,0,40,4.21065759658814,1,6,1,2.24624633789062,42.0332374572754,,,,,,,,,,,,,,,,
,3949049100.221,4.19977450370789,-2358.962890625,0.151690204263403,0.000281042383336271,1,0.999253354069792,40.0298881530762,1.99910495240629,17.8900007158518,1.65747328686121,0.306345547253814,25,0.00116795996218449,0.150685249800198,0.00191003231661245,4.19983625411987,4.19983625411987,-2408.87109375,-2309.0546875,56.391371148429,20.6476742329513,3.5771849155426,0,0,0,40,4.20954990386963,1,6,1,2.25936889648438,41.5444793701172,,,,,,,,,,,,,,,,
,3949049164.151,4.19986033439636,-8750.7607421875,0.431708291687002,0.000150764784841004,1,0.999253354069792,40.0298881530762,1.99893126888997,17.8900007158518,4.71869890622742,0.872963754080554,25,0.00320056003224556,0.429037093202388,0.00551056071096055,4.19991493225098,4.19991493225098,-8800.755859375,-8700.765625,56.2522412720059,20.645451436266,3.57541799545288,0,0,0,40,4.21125984191895,1,6,1,2.257080078125,42.0332374572754,,,,,,,,,,,,,,,,
,3949049229.1155,4.1944944858551,-15254.3588867188,0.0494722454383882,0.000293421497711237,1,0.999253354069792,40.0298881530762,1.99898544563772,17.8900007158518,0.541067234242827,0.10005251561582,2.5,0.000339355030226111,0.0491933702445951,0.000627845787683957,4.19428110122681,4.19428110122681,-15304.4033203125,-15204.314453125,56.7141837268714,20.647595729786,3.57265901565552,0,0,0,40,4.20889806747437,5,6,1,2.25845336914062,42.0332374572754,,,,,,,,,,,,,,,,
,3949049294.06,4.20021796226501,-21747.40234375,0.299191547904336,7.47909612300094E-5,1,0.999253354069792,40.0298881530762,1.99908430288191,17.8999993950129,3.27389040847358,0.608225604748744,25,0.00217333100544858,0.297688151306978,0.0040479584987973,4.20025205612183,4.20025205612183,-21797.498046875,-21697.306640625,56.9291315696599,20.6453962053219,3.57307386398315,0,0,0,40,4.21451473236084,1,6,1,2.24685668945313,42.0332374572754,,,,,,,,,,,,,,,,
,3949049358.0145,4.20034003257751,-28150.986328125,0.297510106916475,7.16077041225864E-5,1,0.999253354069792,40.0298881530762,1.99887813669308,17.8900007158518,3.25738207190517,0.604709979819044,25,0.00201393114991016,0.296209261363047,0.00398839969642323,4.20029830932617,4.20029830932617,-28200.830078125,-28101.142578125,56.3819916061983,20.6424267320651,3.57303428649902,0,0,0,40,4.21519041061401,1,6,1,2.24441528320313,41.5444793701172,,,,,,,,,,,,,,,,
,3949049421.959,4.200110912323,-34543.87890625,0.22296421647058,6.02714338655574E-5,1,0.999253354069792,40.0298881530762,1.99897467882485,17.8900007158518,2.44284367950228,0.454137131014017,25,0.00150140769905899,0.222138925936929,0.00304736385396097,4.20005035400391,4.20005035400391,-34593.87109375,-34493.88671875,56.2405168442175,20.6456526500543,3.57274603843689,0,0,0,40,4.21570205688477,1,6,1,2.24319458007813,41.5444793701172,,,,,,,,,,,,,,,,
,3949049485.9455,4.2004075050354,-40952.779296875,0.16736948111929,6.6065684992632E-5,1,0.999253354069792,40.0298881530762,1.99889665952269,17.8900007158518,1.83504248706938,0.340424460728719,25,0.00102757816311544,0.166864078734931,0.00222584783300073,4.20045852661133,4.20045852661133,-41007.82421875,-40897.734375,56.2600575571983,20.6463364245739,3.57265949249268,0,0,0,40,4.21508598327637,1,6,1,2.24639892578125,42.5219955444336,,,,,,,,,,,,,,,,
,3949049549.88,4.200110912323,-47350.17578125,0.126545351833905,5.50096746995334E-5,1,0.999253354069792,40.0298881530762,1.99913917698912,17.8900007158518,1.38862005350141,0.257117701653289,25,0.000715599342334265,0.126248060256797,0.00164102259122884,4.20015573501587,4.20015573501587,-47400.1640625,-47300.1875,55.7434011059867,20.649763632752,3.57204580307007,0,0,0,40,4.21354961395264,1,6,1,2.24014282226562,43.0107536315918,,,,,,,,,,,,,,,,
,3949049613.8205,4.20004844665527,-53747.7109375,0.0948538286892008,6.36178285493794E-5,1,0.999253354069792,40.0298881530762,1.99903215870982,17.8900007158518,1.04161274105912,0.192107286760962,25,0.000462109298583475,0.0946928044559523,0.00116418035129023,4.20001029968262,4.20001029968262,-53802.69140625,-53692.73046875,56.8236117195637,20.6510419336465,3.57248139381409,0,0,0,40,4.21130466461182,1,6,1,2.24502563476562,41.5444793701172,,,,,,,,,,,,,,,,
,3949049677.7655,4.20016694068909,-60145.9140625,0.0696598675543366,7.21900230687539E-5,1,0.999253354069792,40.0298881530762,1.99903975797125,17.8900007158518,0.765625089949837,0.140066287821742,25,0.000237492170818486,0.0695853203767652,0.000755268378751096,4.20028781890869,4.20028781890869,-60195.9453125,-60095.8828125,56.4288893173521,20.6498662689755,3.57238388061523,0,0,0,40,4.20791101455688,1,6,1,2.24105834960938,41.5444793701172,,,,,,,,,,,,,,,,
,3949049741.7165,4.20003485679626,-66537.4765625,0.0494816393078095,4.82256982429057E-5,1,0.999253354069792,40.0298881530762,1.99887411750301,17.8999993950129,0.544149661194846,0.0993865921960816,25,0.000155713700905741,0.0494575288729651,0.000522540603964612,4.20003890991211,4.20003890991211,-66587.6015625,-66487.3515625,56.7462304961599,20.6520828695956,3.57272434234619,0,0,0,40,4.2040581703186,1,6,1,2.24395751953125,41.5444793701172,,,,,,,,,,,,,,,,
,3949049806.661,4.20024251937866,-73040.25390625,0.0326141036286928,6.42272240189896E-5,1,0.999253354069792,40.0298881530762,1.99908991807279,17.8999993950129,0.359116857894714,0.0642958367985377,2.5,-9.09164337001044E-6,0.0326170324490993,0.000230682672167522,4.20027160644531,4.20027160644531,-73090.2265625,-72990.28125,56.4468667732944,20.6545330201945,3.57294058799744,0,0,0,40,4.20045328140259,1,6,1,2.24319458007813,41.5444793701172,,,,,,,,,,,,,,,,
,3949049871.631,4.20032620429993,-79543.18359375,0.0192863586635432,5.4152649255118E-5,1,0.999253354069792,40.0298881530762,1.9989799532269,17.8900007158518,0.212667229552136,0.0368884212803696,2.5,-0.000107879013968521,0.0192986844950903,3.19944239830549E-5,4.20033693313599,4.20033693313599,-79593.1875,-79493.1796875,56.7141837268714,20.6548995578247,3.57334041595459,0,0,0,40,4.19666481018066,1,6,1,2.24639892578125,41.5444793701172,,,,,,,,,,,,,,,,
,3949049936.635,4.20016646385193,-86040.94140625,0.00915445903888736,6.79918572403943E-5,1,0.999253354069792,40.0298881530762,1.99907866352819,17.8900007158518,0.101245034849998,0.0161309280015093,2.5,-0.000175952944923183,0.00916549297428677,-0.000110831971840924,4.20020341873169,4.20020341873169,-86095.9609375,-85985.921875,56.2819431557367,20.6604859586368,3.57324838638306,0,0,0,40,4.19220018386841,1,6,1,2.24090576171875,41.5444793701172,,,,,,,,,,,,,,,,
,3949050001.5155,4.2000527381897,-92532.90234375,0.00217559107708734,5.32647015699232E-5,1,0.999253354069792,40.0298881530762,1.99903059646945,17.8999993950129,0.0243765837906084,0.0021271627740379,0.25,-0.000196399390620735,0.00218022383792406,-0.000181479123461772,4.20027637481689,4.20027637481689,-92587.890625,-92477.9140625,55.9841426899098,20.657238873887,3.57307505607605,0,0,0,40,4.18801641464233,1,6,1,2.2442626953125,41.055721282959,,,,,,,,,,,,,,,,
,3949050065.474,4.20009160041809,-98930.98828125,-0.0013562872166531,5.15161872200758E-5,1,0.999253354069792,40.0298881530762,1.99887277765467,17.8900007158518,-0.0146002985296052,-0.00468713554942988,0.25,-0.000182451264128599,-0.00135759608378446,-0.000192073434744486,4.20007753372192,4.20007753372192,-98980.9375,-98881.0390625,55.9528775491405,20.6614057630946,3.57288193702698,0,0,0,40,4.18497037887573,1,6,1,2.24563598632813,41.055721282959,,,,,,,,,,,,,,,,
,3949050131.441,4.20006203651428,-105533.38671875,-0.00169208603584106,3.96029233298152E-6,1,0.999253354069792,40.0298881530762,1.99897912896197,17.8900007158518,-0.0186396816000822,-0.00351765989655697,0.25,-1.65438289690684E-5,-0.00169578152687559,-2.7874053795493E-5,4.20013284683228,4.20013284683228,-105583.40625,-105483.3671875,56.5422254526406,20.6634369064015,3.57275104522705,0,0,0,40,4.18176507949829,1,6,1,2.230224609375,41.5444793701172,,,,,,,,,,,,,,,,
,3949050195.386,4.20059251785278,-111930.78125,-0.00182887445385622,2.71607647471898E-6,1,0.999253354069792,40.0298881530762,1.99883443035507,17.8999993950129,-0.0201578590771946,-0.00376785325277653,0.25,-1.50077658546505E-5,-0.00183347693665051,-2.69460674322955E-5,4.20062875747681,4.20062875747681,-111985.7890625,-111875.7734375,56.1435949078329,20.6584422269175,3.57297372817993,0,0,0,40,4.17912673950195,1,6,1,2.24288940429687,41.055721282959,,,,,,,,,,,,,,,,
,3949050259.337,4.20024108886719,-118333.57421875,-0.00193336232844774,2.27701545576851E-6,1,0.999253354069792,40.0298881530762,1.99904163182454,17.8900007158518,-0.0213138720682847,-0.00400690753672865,0.25,-1.82109296768012E-5,-0.00193878033676129,-3.05131215461433E-5,4.20026969909668,4.20026969909668,-118378.53125,-118288.6171875,55.6550770833136,20.6766454119798,3.57352876663208,0,0,0,40,4.17715835571289,1,6,1,2.24639892578125,41.055721282959,,,,,,,,,,,,,,,,
,3949050323.277,4.20004177093506,-124730.67578125,-0.00202698986891491,2.74890883742628E-6,1,0.999253354069792,40.0298881530762,1.99891281632678,17.8900007158518,-0.0223513838121872,-0.00419745021716883,0.25,-1.90471038113894E-5,-0.00203321191223176,-3.1603422971955E-5,4.20001268386841,4.20001268386841,-124780.7265625,-124680.625,55.7434011059867,20.6680795957695,3.57353281974793,0,0,0,40,4.17558526992798,1,6,1,2.24929809570313,41.055721282959,,,,,,,,,,,,,,,,
,3949050387.2035,4.20012950897217,-131122.6015625,-0.00212101388534819,1.94089938364457E-6,1,0.999253354069792,40.0298881530762,1.99903061649296,17.8999993950129,-0.0233972646552401,-0.0043814216269786,0.25,-1.92034171524954E-5,-0.00212804413083335,-3.19843212556859E-5,4.20012331008911,4.20012331008911,-131172.703125,-131072.5,55.7426194774674,20.6664297998207,3.57303357124329,0,0,0,40,4.17506837844849,1,6,1,2.230224609375,41.055721282959,,,,,,,,,,,,,,,,
,3949050452.173,4.20024490356445,-137614.0078125,-0.00221378911352029,3.05014838496865E-6,1,0.999253354069792,40.0298881530762,1.99922331245229,17.8900007158518,-0.0244269088078679,-0.004582643917206,0.25,-2.11579142322524E-5,-0.00222161721426805,-3.41297198668889E-5,4.20028257369995,4.20028257369995,-137663.9375,-137564.078125,55.3236665911597,20.670692892272,3.57235264778137,0,0,0,40,4.17465591430664,1,6,1,2.24563598632813,40.5669593811035,,,,,,,,,,,,,,,,
,3949050526.1615,4.19982409477234,-136221.0234375,-0.00219621491090339,2.33421947111377E-6,1,0.999253354069792,40.0298881530762,1.99883225903253,17.8999993950129,-0.0242340673150027,-0.00450762246790381,0.25,-1.75082974689315E-5,-0.00220389936608016,-3.04434332629276E-5,4.19988536834717,4.19988536834717,-136270.5,-136171.546875,55.781700903429,20.6697614630444,3.57182908058167,0,0,0,40,4.17452192306519,1,6,1,2.24334716796875,40.5669593811035,,,,,,,,,,,,,,,,
,3949050590.0905,4.19983315467834,-129885.71875,-0.00210280725671105,2.18841817955131E-6,1,0.999253354069792,40.0298881530762,1.99900200372473,17.8900007158518,-0.0231986151141013,-0.00432362466174902,0.25,-1.71652396412476E-5,-0.00210969333029242,-2.98981540710455E-5,4.19988870620728,4.19988870620728,-129940.125,-129831.3125,55.8762779542559,20.6631129526866,3.57355308532715,0,0,0,40,4.17510986328125,1,6,1,2.22991943359375,40.5669593811035,,,,,,,,,,,,,,,,
,3949050654.0615,4.19992733001709,-123560.7109375,-0.00200897706724211,2.29935061885373E-6,1,0.999253354069792,40.0298881530762,1.9989521784654,17.8900007158518,-0.0221555744500559,-0.00414074550220028,0.25,-1.70684095500424E-5,-0.0020150606361451,-2.95694476802236E-5,4.19994068145752,4.19994068145752,-123610.1171875,-123511.3046875,55.2595730525828,20.6627732926421,3.57488465309143,0,0,0,40,4.17579936981201,1,6,1,2.23007202148438,40.5669593811035,,,,,,,,,,,,,,,,
,3949050718.0175,4.19957947731018,-117238.859375,-0.00190989714247711,2.53395661280442E-6,1,0.999253354069792,40.0298881530762,1.99908003739491,17.8999993950129,-0.0210610708549663,-0.00392163894151532,0.25,-1.46264599238606E-5,-0.00191517859675898,-2.68248630605324E-5,4.19965028762817,4.19965028762817,-117288.34375,-117189.375,55.8567372412751,20.6674839835608,3.57541823387146,0,0,0,40,4.1768684387207,1,6,1,2.2613525390625,40.5669593811035,,,,,,,,,,,,,,,,
,3949050781.9275,4.19971489906311,-110912.8125,-0.00180436737294261,2.93131392954526E-6,1,0.999253354069792,40.0298881530762,1.99889889038035,17.8900007158518,-0.0198832241360514,-0.00374056237995453,0.25,-1.68655931862268E-5,-0.00180880584975126,-2.86969178079628E-5,4.19969367980957,4.19969367980957,-110967.2578125,-110858.3671875,56.6446187886598,20.6575410878202,3.57608890533447,0,0,0,40,4.17965364456177,1,6,1,2.2308349609375,41.055721282959,,,,,,,,,,,,,,,,
,3949050845.849,4.19963669776916,-104587.07421875,-0.00167709519361527,5.57565516749319E-6,1,0.999253354069792,40.0298881530762,1.99869471825677,17.8999993950129,-0.0184511852687836,-0.00359749409306808,0.25,-2.64749749464729E-5,-0.00168060610917683,-3.77670238922004E-5,4.19960117340088,4.19960117340088,-104636.5703125,-104537.578125,55.6152140288328,20.6545708926414,3.57547307014465,0,0,0,40,4.18178796768188,1,6,1,2.25418090820313,40.5669593811035,,,,,,,,,,,,,,,,
,3949050909.8145,4.1997697353363,-98260.828125,-0.00174544933188294,4.37190439452513E-5,1,0.999253354069792,40.0298881530762,1.99887036412507,17.8999993950129,-0.0189091705179618,-0.00535856538020895,0.25,-0.000173737115053949,-0.00174748070294598,-0.000186027036579597,4.19977998733521,4.19977998733521,-98315.296875,-98206.359375,55.9434980069098,20.6562827470334,3.57604742050171,0,0,0,40,4.18512916564941,1,6,1,2.2613525390625,41.5444793701172,,,,,,,,,,,,,,,,
,3949050973.756,4.19983601570129,-91935.49609375,-0.00490533428191131,7.56213847999876E-5,1,0.999253354069792,40.0298881530762,1.99868073111187,17.8900007158518,-0.0534933420761663,-0.0129407398238692,0.25,-0.000295989074878109,-0.00491042282448657,-0.000330792373777614,4.19982528686523,4.19982528686523,-91984.90625,-91886.0859375,56.279598270179,20.6479548623068,3.57599830627441,0,0,0,40,4.18854713439941,1,6,1,2.24441528320313,41.055721282959,,,,,,,,,,,,,,,,
,3949051038.7035,4.19973731040955,-85505.671875,-0.0116610192918857,5.5973056120383E-5,1,0.999253354069792,40.0298881530762,1.99897189244385,17.8900007158518,-0.127852861327004,-0.0267017376385047,2.5,-0.000334310240119543,-0.0116706532545166,-0.000417972253475001,4.19969654083252,4.19969654083252,-85555.1640625,-85456.1796875,56.292885955006,20.6534438741258,3.57574272155762,0,0,0,40,4.19275045394897,1,6,1,2.25723266601562,41.5444793701172,,,,,,,,,,,,,,,,
,3949051103.7065,4.19991540908814,-79076.58984375,-0.0211257137844235,5.88524592861298E-5,1,0.999253354069792,40.0298881530762,1.9988995749605,17.8900007158518,-0.231962379434302,-0.0458156226645299,2.5,-0.000373001470496068,-0.0211349030421062,-0.000526661030949455,4.19985342025757,4.19985342025757,-79126.2734375,-79026.90625,55.9536591776598,20.6568763739604,3.57586526870728,0,0,0,40,4.1968412399292,1,6,1,2.24700927734375,41.5444793701172,,,,,,,,,,,,,,,,
,3949051167.641,4.19959926605225,-72731.31640625,-0.0331720417327008,6.170108275872E-5,1,0.999253354069792,40.0298881530762,1.99885208577903,17.8900007158518,-0.364170738505307,-0.0711815796183313,2.5,-0.00051699348600831,-0.0331703110097935,-0.000761028942453482,4.19960403442383,4.19960403442383,-72781.078125,-72681.5546875,56.1920558760252,20.6505041782287,3.57634878158569,0,0,0,40,4.2003345489502,1,6,1,2.24639892578125,41.055721282959,,,,,,,,,,,,,,,,
,3949051231.6,4.19958543777466,-66368.89453125,-0.0481704749185464,5.12650910160136E-5,1,0.999253354069792,40.0298881530762,1.99888126538495,17.8900007158518,-0.528796653829956,-0.101925190798826,2.5,-0.000621692129638942,-0.048142802123933,-0.000978625466131023,4.1995964050293,4.1995964050293,-66423.578125,-66314.2109375,56.035730172179,20.6478884515186,3.57684278488159,0,0,0,40,4.20414924621582,1,6,1,2.24197387695313,41.5444793701172,,,,,,,,,,,,,,,,
,3949051296.5215,4.19927525520325,-59908.037109375,-0.0665728764102756,4.67207282261982E-5,1,0.999253354069792,40.0298881530762,1.99904443285298,17.8999993950129,-0.730713213879362,-0.139253377710644,2.5,-0.000717699805584516,-0.0664964973873866,-0.00121199689295198,4.19930744171143,4.19930744171143,-59957.82421875,-59858.25,56.0380750577367,20.6510937370302,3.57640433311462,0,0,0,40,4.20819425582886,1,6,1,2.24227905273438,41.5444793701172,,,,,,,,,,,,,,,,
,3949051360.5215,4.19996285438538,-53540.638671875,-0.0883249425110632,5.13160819234783E-5,1,0.999253354069792,40.0298881530762,1.99886717955473,17.8900007158518,-0.969073852010545,-0.183035031034388,2.5,-0.000809739838662827,-0.0881703816579823,-0.00146268301412379,4.19998264312744,4.19998264312744,-53590.34765625,-53490.9296875,55.8246904719867,20.6523787539248,3.57719922065735,0,0,0,40,4.2114839553833,1,6,1,2.24578857421875,41.5444793701172,,,,,,,,,,,,,,,,
,3949051425.4295,4.19992256164551,-47080.77734375,-0.115185769906655,4.68621994212569E-5,1,0.999253354069792,40.0298881530762,1.99896447043452,17.8999993950129,-1.26316683616968,-0.237698536982034,25,-0.000987633396677735,-0.114909509399422,-0.00182861725202866,4.19995975494385,4.19995975494385,-47135.4296875,-47026.125,55.8583004983136,20.6472599627085,3.57722306251526,0,0,0,40,4.21412706375122,1,6,1,2.24777221679687,41.5444793701172,,,,,,,,,,,,,,,,
,3949051489.4055,4.19986534118652,-40719.845703125,-0.14719644330871,4.83634223143848E-5,1,0.999253354069792,40.0298881530762,1.99883558355983,17.8900007158518,-1.61318984039673,-0.302661643159014,25,-0.00120395312535311,-0.146746191937111,-0.00225588542728224,4.19983053207397,4.19983053207397,-40769.65625,-40670.03515625,56.8298647477175,20.6469814870311,3.57778716087341,0,0,0,40,4.21567392349243,1,6,1,2.24227905273438,41.5444793701172,,,,,,,,,,,,,,,,
,3949051553.3415,4.19978260993958,-34346.400390625,-0.187042407030933,3.96287968444893E-5,1,0.999253354069792,40.0298881530762,1.99888432421276,17.8900007158518,-2.0487064541122,-0.383401671340613,25,-0.00148479424808912,-0.186344608321553,-0.00277934370759166,4.19977378845215,4.19977378845215,-34391.2109375,-34301.58984375,56.2053435608521,20.642286889054,3.57779717445374,0,0,0,40,4.21637439727783,1,6,1,2.25265502929687,41.5444793701172,,,,,,,,,,,,,,,,
,3949051617.3,4.19994306564331,-27963.794921875,-0.237499517131865,4.35621301015961E-5,1,0.999253354069792,40.0298881530762,1.99882932205486,17.8900007158518,-2.59977939944922,-0.48521592922904,25,-0.00183824959704409,-0.236454924011834,-0.0034111220654036,4.19986772537231,4.19986772537231,-28008.62109375,-27918.96875,56.3890262628713,20.6423860479403,3.57745862007141,0,0,0,40,4.21669149398804,1,6,1,2.24395751953125,42.0332374572754,,,,,,,,,,,,,,,,
,3949051682.2175,4.19992828369141,-21484.7822265625,-0.30426267946678,7.6656519009139E-5,1,0.999253354069792,40.0298881530762,1.99888512989695,17.8900007158518,-3.32882190362304,-0.619344853769265,25,-0.00229587531480987,-0.302725395424214,-0.00419681607933444,4.20004081726074,4.20004081726074,-21534.6484375,-21434.916015625,56.2545861575636,20.6395177392401,3.5773868560791,0,0,0,40,4.2150993347168,1,6,1,2.24258422851562,41.5444793701172,,,,,,,,,,,,,,,,
,3949051746.2205,4.19988965988159,-15098.7583007813,-0.390532755562665,8.76058120660945E-5,1,0.999253354069792,40.0298881530762,1.99875045014165,17.8900007158518,-4.27008103445189,-0.792831606298988,25,-0.0029679744679649,-0.388324158929143,-0.00523936678388693,4.19983100891113,4.19983100891113,-15143.70703125,-15053.8095703125,55.8090579016021,20.6395733583993,3.57712435722351,0,0,0,40,4.2141056060791,1,6,1,2.24349975585938,41.5444793701172,,,,,,,,,,,,,,,,
,3949051810.2095,4.19988918304443,-8703.47509765625,-0.499514656850642,0.000118294114076505,1,0.999253354069792,40.0298881530762,1.99872136643669,17.8900007158518,-5.45910510040347,-1.01094983998079,25,-0.00379438448067263,-0.496421587601633,-0.00646488612806599,4.19977140426636,4.19977140426636,-8748.4033203125,-8658.546875,56.1975272756598,20.6438549750511,3.57679963111877,0,0,0,40,4.2116904258728,1,6,1,2.24349975585938,42.0332374572754,,,,,,,,,,,,,,,,
,3949051876.1045,4.20041012763977,-2115.12487792969,-0.253765979510005,0.000246939379956933,1,0.999253354069792,40.0298881530762,1.99880988171239,17.8999993950129,-2.77240615671144,-0.512369574807348,25,-0.00195380831678449,-0.252081322127795,-0.00319129246759956,4.20028638839722,4.20028638839722,-2160.07177734375,-2070.17797851562,56.0888809114867,20.6434851367643,3.57626175880432,0,0,0,40,4.21047782897949,1,6,1,2.25021362304687,41.5444793701172,,,,,,,,,,,,,,,,
,3949051943.065,4.19964504241943,4577.57373046875,-0.269914814930226,0.000225720050278558,1,0.999253354069792,40.0298881530762,1.99895530194566,17.8900007158518,-2.94945940167728,-0.54522960831213,25,-0.00204566250990545,-0.268163505304196,-0.00340708932153043,4.19988059997559,4.19988059997559,4527.48486328125,4627.66259765625,56.272563613506,20.641387215314,3.57540726661682,0,0,0,40,4.20945501327515,1,6,1,2.23037719726562,41.5444793701172,,,,,,,,,,,,,,,,
,3949052007.0525,4.19996953010559,10986.3662109375,-0.479772658017963,8.58310163090474E-5,1,0.999253354069792,40.0298881530762,1.99896296952059,17.8900007158518,-5.24484623626584,-0.97167976755337,25,-0.00359961019812465,-0.476889544534729,-0.00624636490150043,4.20002841949463,4.20002841949463,10931.2880859375,11041.4443359375,56.0505811140444,20.6440447191104,3.57344746589661,0,0,0,40,4.2119026184082,1,6,1,2.23098754882813,43.49951171875,,,,,,,,,,,,,,,,
,3949052072.9455,4.1999626159668,17574.65625,-0.172713550111274,0.000210779873199503,1,0.999253354069792,40.0298881530762,1.998768817592,17.8900007158518,-1.88903904246193,-0.349920746602728,25,-0.00121057987641462,-0.171776629865237,-0.00224558647424828,4.19999647140503,4.19999647140503,17524.66796875,17624.64453125,56.3046103827944,20.6395557927916,3.57162404060364,0,0,0,40,4.21369791030884,5,6,1,2.242431640625,42.0332374572754,,,,,,,,,,,,,,,,
,3949052136.9005,4.19990611076355,23977.0732421875,-0.317249217638943,5.36719503903133E-5,1,0.999253354069792,40.0298881530762,1.99897800013227,17.8900007158518,-3.47219260323966,-0.644466435601027,25,-0.00220910175297253,-0.315726206650962,-0.00424050061337576,4.19989728927612,4.19989728927612,23927.107421875,24027.0390625,56.353852979506,20.6489285757667,3.57181978225708,0,0,0,40,4.21480894088745,1,6,1,2.24685668945313,42.0332374572754,,,,,,,,,,,,,,,,
,3949052200.8545,4.19913482666016,30371.0166015625,-0.270971509366527,7.58521709932291E-5,1,0.999253354069792,40.0298881530762,1.99892685067674,17.8900007158518,-2.96747545046379,-0.551472301634405,25,-0.00185615180110414,-0.269849235579144,-0.00368458673421865,4.19915151596069,4.19915151596069,30320.982421875,30421.05078125,55.7519990196982,20.6410736916977,3.57116985321045,0,0,0,40,4.21526288986206,1,6,1,2.24563598632813,42.0332374572754,,,,,,,,,,,,,,,,
,3949052264.8315,4.20021653175354,36774.3046875,-0.201480412818206,6.81698211012931E-5,1,0.999253354069792,40.0298881530762,1.99880114645003,17.8900007158518,-2.20777231629003,-0.410624753502359,25,-0.00135659083983814,-0.200782197766943,-0.00277096730876733,4.20020437240601,4.20020437240601,36724.28515625,36824.32421875,56.5453519667175,20.6422776796056,3.57097601890564,0,0,0,40,4.21585464477539,1,6,1,2.24151611328125,41.5444793701172,,,,,,,,,,,,,,,,
,3949052329.771,4.19993734359741,43272.041015625,-0.151227429686041,4.87908253502713E-5,1,0.999253354069792,40.0298881530762,1.99860476412565,17.8900007158518,-1.65825168431784,-0.307541355934281,25,-0.000911796138031878,-0.150807719679746,-0.00200409707930246,4.19997119903564,4.19997119903564,43226.98046875,43317.1015625,55.6027079725251,20.6342920318418,3.57051730155945,0,0,0,40,4.21473217010498,1,6,1,2.24578857421875,42.0332374572754,,,,,,,,,,,,,,,,
,3949052393.6965,4.20015740394592,49670.95703125,-0.114237508081506,5.29511713728924E-5,1,0.999253354069792,40.0298881530762,1.99868598781228,17.8900007158518,-1.25362643491626,-0.231919587292991,25,-0.000624060294537831,-0.113996394060288,-0.00146395317346118,4.20026350021362,4.20026350021362,49620.96484375,49720.94921875,56.0443280858905,20.6373042240077,3.57048296928406,0,0,0,40,4.21286869049072,1,6,1,2.24594116210938,42.0332374572754,,,,,,,,,,,,,,,,
,3949052457.6585,4.20017862319946,56073.482421875,-0.0851139138185016,5.06220848525093E-5,1,0.999253354069792,40.0298881530762,1.99862654330321,17.8900007158518,-0.934756001187703,-0.172019081472572,25,-0.000379953079461909,-0.0849890775547881,-0.0010114288464798,4.20012760162354,4.20012760162354,56023.47265625,56123.4921875,56.0654320559098,20.6410208708194,3.57025694847107,0,0,0,40,4.21030378341675,1,6,1,2.22900390625,42.0332374572754,,,,,,,,,,,,,,,,
,3949052522.606,4.20010542869568,62571.576171875,-0.0614988353759708,5.76957023814036E-5,1,0.999253354069792,40.0298881530762,1.99871081994306,17.8999993950129,-0.675919116059695,-0.123974232931177,25,-0.000238045064733647,-0.0614466368098833,-0.00069500179380726,4.20014047622681,4.20014047622681,62516.50390625,62626.6484375,55.6785259388905,20.6416372332844,3.5701584815979,0,0,0,40,4.20634269714355,1,6,1,2.25997924804687,42.0332374572754,,,,,,,,,,,,,,,,
,3949052586.538,4.200035572052,68969.86328125,-0.0427854000014394,5.36159253075574E-5,1,0.999253354069792,40.0298881530762,1.99876772398638,17.8900007158518,-0.470729090458192,-0.0851567277059498,25,-6.33885883587402E-5,-0.0427741141564607,-0.000379799853696063,4.20008754730225,4.20008754730225,68919.796875,69019.9296875,56.3147715535444,20.6331701823804,3.56997656822205,0,0,0,40,4.20266199111938,1,6,1,2.24212646484375,42.5219955444336,,,,,,,,,,,,,,,,
,3949052651.484,4.20027732849121,75463.70703125,-0.0273789825904402,5.39621444029155E-5,1,0.999253354069792,40.0298881530762,1.9987144177062,17.8900007158518,-0.301503187270255,-0.0538328915979685,2.5,1.97189629828071E-5,-0.0273868724121686,-0.00018067678131707,4.20028162002563,4.20028162002563,75413.671875,75513.7421875,55.676962681852,20.6394292772951,3.57023882865906,0,0,0,40,4.19901990890503,1,6,1,2.24334716796875,42.5219955444336,,,,,,,,,,,,,,,,
,3949052715.4625,4.20025277137756,81866.0390625,-0.0152363758900676,7.29606117304171E-5,1,0.999253354069792,40.0298881530762,1.99866684404055,17.8900007158518,-0.168141845665358,-0.0284221211924792,2.5,0.000150005984332867,-0.0152492059378567,4.01928064607573E-5,4.20023107528687,4.20023107528687,81816.0234375,81916.0546875,56.4030955762175,20.6365742505618,3.57040286064148,0,0,0,40,4.1947193145752,1,6,1,2.2601318359375,42.5219955444336,,,,,,,,,,,,,,,,
,3949052779.3985,4.20028901100159,88264.1875,-0.00642564184712784,6.3110221159007E-5,1,0.999253354069792,40.0298881530762,1.99875856677658,17.8900007158518,-0.0710890644658023,-0.011189068584366,2.5,0.000135305687842868,-0.00643443859064562,8.99273614175949E-5,4.20030784606934,4.20030784606934,88218.953125,88309.421875,56.8220484625252,20.6491079540813,3.57055497169495,0,0,0,40,4.19110107421875,1,6,1,2.24746704101562,42.5219955444336,,,,,,,,,,,,,,,,
,3949052844.365,4.20003199577332,94762.84375,-0.000561936962473727,4.76300638596845E-5,1,0.999253354069792,40.0298881530762,1.9987230391899,17.8900007158518,-0.00659589939197673,0.00112594458951665,0.25,0.000202638758240301,-0.000564263496265404,0.000199069833550858,4.19999504089355,4.19999504089355,94712.90625,94812.78125,56.0740299696213,20.6486536510579,3.56995606422424,0,0,0,40,4.18766403198242,1,6,1,2.26165771484375,42.5219955444336,,,,,,,,,,,,,,,,
,3949052908.3025,4.19994330406189,101160.55859375,0.00153750282178607,2.75947284125994E-5,1,0.999253354069792,40.0298881530762,1.99883986524001,17.8900007158518,0.016727126937383,0.00433988799964401,0.25,0.000118612523449791,0.00153979160101952,0.000129283787672019,4.19988489151001,4.19988489151001,101115.53125,101205.5859375,55.7027564229867,20.6484506684592,3.56949687004089,0,0,0,40,4.18398952484131,1,6,1,2.24960327148438,43.0107536315918,,,,,,,,,,,,,,,,
,3949052972.2765,4.20043754577637,107563.6953125,0.00173688727810407,3.0495521905432E-6,1,0.999253354069792,40.0298881530762,1.99876174875957,17.8999993950129,0.019133838945967,0.00360744189146677,0.25,1.67697241763433E-5,0.001740865400469,2.83097390098362E-5,4.20044231414795,4.20044231414795,107508.6875,107618.703125,55.9419347498713,20.6418194314795,3.56955361366272,0,0,0,40,4.18108606338501,1,6,1,2.24609375,42.5219955444336,,,,,,,,,,,,,,,,
,3949053036.1855,4.20033931732178,113956.39453125,0.00185851032137726,2.14727682241097E-6,1,0.999253354069792,40.0298881530762,1.99870985226038,17.8900007158518,0.0204910824350064,0.003796330476513,0.25,1.23878259429508E-5,0.00186338400947985,2.44135564026201E-5,4.20034885406494,4.20034885406494,113911.3359375,114001.453125,56.4601544581214,20.653445044566,3.56952404975891,0,0,0,40,4.17909240722656,1,6,1,2.25662231445313,43.49951171875,,,,,,,,,,,,,,,,
,3949053102.1275,4.20056700706482,120554.84765625,0.00196311848890487,2.51476860944386E-6,1,0.999253354069792,40.0298881530762,1.99880673262128,17.8900007158518,0.0216480506868343,0.00403205661118489,0.25,1.53074764150127E-5,0.00196882754693984,2.76747730812755E-5,4.20064401626587,4.20064401626587,120504.6796875,120605.015625,55.8497025846021,20.6506107073569,3.56956076622009,0,0,0,40,4.17743062973022,1,6,1,2.227783203125,43.0107536315918,,,,,,,,,,,,,,,,
,3949053166.1115,4.20026898384094,126957.03515625,0.00205701871068196,2.21281938995169E-6,1,0.999253354069792,40.0298881530762,1.99858728551547,17.8900007158518,0.0226848766593607,0.00423739237312591,0.25,1.74645091266354E-5,0.0020635237074401,3.00804605374649E-5,4.20028352737427,4.20028352737427,126907.0859375,127006.984375,55.8207823293905,20.6477171658915,3.56924891471863,0,0,0,40,4.17597150802612,1,6,1,2.2308349609375,43.0107536315918,,,,,,,,,,,,,,,,
,3949053230.0345,4.19987416267395,133351.078125,0.00215509921226389,2.07863206049563E-6,1,0.999253354069792,40.0298881530762,1.99869452096434,17.8999993950129,0.0237714883255378,0.00445069171652837,0.25,1.95684044878209E-5,0.00216241333821951,3.24298748791761E-5,4.19994354248047,4.19994354248047,133301.0625,133401.09375,55.7801376463905,20.6490329423727,3.56834959983826,0,0,0,40,4.17480611801147,1,6,1,2.24334716796875,42.5219955444336,,,,,,,,,,,,,,,,
,3949053293.989,4.20008754730225,139753.609375,0.00224460428500811,1.84834618064582E-6,1,0.999253354069792,40.0298881530762,1.99874678558046,17.8900007158518,0.0247683265144056,0.00461589562744314,0.25,1.88799907754141E-5,0.00225271211966516,3.19001225611218E-5,4.20004415512085,4.20004415512085,139703.671875,139803.546875,55.9731998906405,20.6545195311955,3.56828284263611,0,0,0,40,4.17523622512817,1,6,1,2.23434448242187,41.5444793701172,,,,,,,,,,,,,,,,
,3949053299.074,4.19912195205688,140000.875,0.00224869850512265,2.67304946827634E-6,1,0.999253354069792,40.0298881530762,1.99863681451686,17.8900007158518,0.0248172855623911,0.00459663325095998,0.25,1.64423726556484E-5,0.00225685310192562,2.94629982604332E-5,4.1993350982666,4.1993350982666,139999.953125,140001.796875,56.0818462548136,20.6491688204535,3.5685338973999,0,0,0,40,4.17385768890381,1,4,1,2.2430419921875,43.0107536315918,,,,,,,,,,,,,,,,