File: PPMS_Data_and_Plotting/Data/NbTi/0007.DAT
[Header]
; VSM Data File (default extension .dat)
; Copyright (c) 2003-2013, Quantum Design, Inc. All rights reserved.
TITLE,
FILEOPENTIME,3949055483.99035,02/18/2025,3:54 pm
BYAPP,VSM,1.0,1.0
INFO,DYNACOOL VSM Option Release 1.4.10 Build 1,APPNAME
INFO,Quantum Design Linear Motor Servo Controller,MOTOR_MODULE_NAME
INFO,3101-100 L2,MOTOR_HW_VERSION
INFO,MMC884,MOTOR_SERIAL_NUMBER
INFO,SRV No X-over 01.03.11,MOTOR_SOFTWARE_VERSION
INFO,Quantum Design VSM Detection Module,VSM_MODULE_NAME
INFO,3101-150 F0,VSM_HW_VERSION
INFO,VSM641,VSM_SERIAL_NUMBER
INFO,VSM No X-over 01.02.05 May 20 2008 13:51:47,VSM_SOFTWARE_VERSION
INFO,VPA645,PREAMP_SERIAL_NUMBER
INFO,740,COIL_SERIAL_NUMBER
INFO,0,MOMENT_UNITS
INFO,NbTi,SAMPLE_MATERIAL
INFO,,SAMPLE_COMMENT
INFO,4.3,SAMPLE_MASS
INFO,,SAMPLE_VOLUME
INFO,,SAMPLE_MOLECULAR_WEIGHT
INFO,,SAMPLE_SIZE
INFO,,SAMPLE_SHAPE
DATATYPE,COMMENT,1
DATATYPE,TIME,2
STARTUPAXIS,X,2
STARTUPAXIS,Y1,5
[Data]
Comment,Time Stamp (sec),Temperature (K),Magnetic Field (Oe),Moment (emu),M. Std. Err. (emu),Transport Action,Averaging Time (sec),Frequency (Hz),Peak Amplitude (mm),Center Position (mm),Coil Signal' (mV),Coil Signal" (mV),Range (mV),M. Quad. Signal (emu),M. Raw' (emu),M. Raw" (emu),Min. Temperature (K),Max. Temperature (K),Min. Field (Oe),Max. Field (Oe),Mass (grams),Motor Lag (deg),Pressure (Torr),VSM Status (code),Motor Status (code),Measure Status (code),Measure Count,System Temp. (K),Temp. Status (code),Field Status (code),Chamber Status (code),Motor Current (amps),Motor Heatsink Temp. (C),Map 01,Map 02,Map 03,Map 04,Map 05,Map 06,Map 07,Map 08,Map 09,Map 10,Map 11,Map 12,Map 13,Map 14,Map 15,Map 16
sample offset = 33.45 mm,3949057641.068,6.00260782241821,-0.072046235203743,6.26915640172388E-5,1.96455237337367E-7,1,0.999253354069792,40.0298881530762,1.99878850078712,17.8900007158518,0.000686656904626828,0.000116253620645469,0.25,-4.52871499582974E-7,6.22738205895882E-5,-1.4795886229022E-7,6.00260782241821,6.00260782241821,-0.072046235203743,-0.072046235203743,55.2142385984674,20.6304849216136,4.50429964065552,0,0,0,40,6.01606941223145,1,4,1,2.22808837890625,30.3030319213867,,,,,,,,,,,,,,,,
,3949057714.6305,5.99992561340332,6530.76123046875,-0.280033906185919,0.00010266687676476,1,0.999253354069792,40.0298881530762,1.99907031042149,17.8900007158518,-3.0606569210236,-0.565546715655106,25,-0.00206189397947101,-0.278254740250403,-0.00351432366595467,5.99993085861206,5.99993085861206,6480.498046875,6581.0244140625,56.5985027060252,20.6410947824936,4.52250385284424,0,0,0,40,6.01564216613769,1,6,1,2.25982666015625,36.6568908691406,,,,,,,,,,,,,,,,
,3949057779.575,6.00018644332886,13024.0859375,-0.29331506853962,7.75912426311902E-5,1,0.999253354069792,40.0298881530762,1.99893415925323,17.8900007158518,-3.20712546820148,-0.593519681083287,25,-0.00210006013844024,-0.291603279008323,-0.00376280668200243,6.0001916885376,6.0001916885376,12974.076171875,13074.095703125,55.0868331498328,20.6311493634237,4.52368068695068,0,0,0,40,6.01747226715088,1,6,1,2.25204467773438,38.1231689453125,,,,,,,,,,,,,,,,
,3949057844.4995,5.9998095035553,19526.3037109375,-0.189123514463711,7.68391828207014E-5,1,0.999253354069792,40.0298881530762,1.99891828094488,17.8900007158518,-2.06907279917175,-0.383160778320585,25,-0.00129147333648653,-0.188132710125494,-0.00244982448779417,5.99980115890503,5.99980115890503,19476.291015625,19576.31640625,55.7402745919097,20.6384149660968,4.52314281463623,0,0,0,40,6.01756286621094,1,6,1,2.24212646484375,40.0782012939453,,,,,,,,,,,,,,,,
,3949057909.449,6.0001528263092,26024.6064453125,-0.11612607185891,5.06172418431262E-5,1,0.999253354069792,40.0298881530762,1.99903407423013,17.8900007158518,-1.27140102599556,-0.235182966373267,25,-0.000724633291302933,-0.115593228076844,-0.00148227040870347,6.00013875961304,6.00013875961304,25979.640625,26069.572265625,55.852829098679,20.6354873248551,4.52198553085327,0,0,0,40,6.01681137084961,1,6,1,2.25677490234375,39.5894432067871,,,,,,,,,,,,,,,,
,3949057974.4015,6.00023508071899,32523.3525390625,-0.071978113884465,4.59913729695656E-5,1,0.999253354069792,40.0298881530762,1.99899947686437,17.8999993950129,-0.788669385560115,-0.145334278198738,25,-0.000377430509312163,-0.0716970398411641,-0.00087073397540434,6.00010871887207,6.00010871887207,32473.392578125,32573.3125,55.3478970752559,20.6430133511775,4.52132368087769,0,0,0,40,6.01454830169678,1,6,1,2.24884033203125,40.0782012939453,,,,,,,,,,,,,,,,
,3949058039.3675,6.00049948692322,39021.66015625,-0.0432997888666378,4.24087826160908E-5,1,0.999253354069792,40.0298881530762,1.99894701556047,17.8900007158518,-0.474882912479059,-0.0867746204422168,25,-0.000151692883399479,-0.0431610059549439,-0.000459472117463267,6.00061273574829,6.00061273574829,38966.66796875,39076.65234375,56.1045134818713,20.6351436563301,4.52041912078857,0,0,0,40,6.01085519790649,1,6,1,2.2412109375,40.5669593811035,,,,,,,,,,,,,,,,
,3949058105.2925,6.00034046173096,45619.166015625,-0.0235576769996077,4.4499712986681E-5,1,0.999253354069792,40.0298881530762,1.99887276879368,17.8900007158518,-0.258677227738676,-0.0464505968710843,2.5,-6.50537691349638E-6,-0.0234990341056969,-0.000178285009598349,6.00034379959106,6.00034379959106,45569.15625,45669.17578125,55.9208307798521,20.637588181624,4.51990699768066,0,0,0,40,6.00680780410767,1,6,1,2.24655151367187,41.055721282959,,,,,,,,,,,,,,,,
,3949058170.272,6.00074911117554,52122.857421875,-0.0105118446675758,5.14045621448314E-5,1,0.999253354069792,40.0298881530762,1.9988875874009,17.8900007158518,-0.115673328075352,-0.0197968842673325,2.5,8.40371635658806E-5,-0.0104932966399963,6.15759143117001E-6,6.00073194503784,6.00073194503784,52072.78515625,52172.9296875,55.5769142313905,20.6402379095718,4.51870679855347,0,0,0,40,6.00243425369263,1,6,1,2.24380493164062,41.055721282959,,,,,,,,,,,,,,,,
,3949058236.23,6.00054836273193,58720.79296875,-0.00246979189546271,4.8138447169267E-5,1,0.999253354069792,40.0298881530762,1.99879653672181,17.8900007158518,-0.0274833553601368,-0.00304251364803088,0.25,0.000166414058250334,-0.00246811546319693,0.000147854804782866,6.00055265426636,6.00055265426636,58665.78125,58775.8046875,55.7942069597367,20.6375257001767,4.51781129837036,0,0,0,40,5.99660348892212,1,6,1,2.242431640625,41.055721282959,,,,,,,,,,,,,,,,
,3949058301.1715,6.00091576576233,65218.92578125,0.000908309117586493,3.88889028869439E-5,1,0.999253354069792,40.0298881530762,1.99876530343735,17.8900007158518,0.0097606543293011,0.00308567158672481,0.25,0.000117526430203114,0.000906908855120097,0.000124200374232141,6.00085687637329,6.00085687637329,65168.84375,65269.0078125,55.7684132186021,20.6310657186156,4.51739406585693,0,0,0,40,5.99106454849243,1,6,1,2.24502563476562,41.5444793701172,,,,,,,,,,,,,,,,
,3949058366.118,6.00078058242798,71721.953125,0.00118537766195623,3.74568607717422E-6,1,0.999253354069792,40.0298881530762,1.99877934828314,17.8900007158518,0.0130114784319143,0.00254524619332324,0.25,1.8634657224813E-5,0.00118521515674686,2.73676239908723E-5,6.00075769424439,6.00075769424439,71671.8828125,71772.0234375,56.2334821875444,20.6417918794992,4.51682329177856,0,0,0,40,5.98447704315186,1,6,1,2.24227905273438,41.5444793701172,,,,,,,,,,,,,,,,
,3949058431.094,6.00094270706177,78215.59375,0.00130969354142105,4.65911302115406E-6,1,0.999253354069792,40.0298881530762,1.99870645982268,17.8900007158518,0.0143877094017418,0.00278736081979528,0.25,1.83344946295171E-5,0.00131021115464014,2.78752050232278E-5,6.00097894668579,6.00097894668579,78165.625,78265.5625,56.435142345506,20.6382225128348,4.51664018630981,0,0,0,40,5.97765731811523,1,6,1,2.24533081054687,41.5444793701172,,,,,,,,,,,,,,,,
,3949058496.005,6.00076770782471,84718.3515625,0.00141458430126293,3.9065540269036E-6,1,0.999253354069792,40.0298881530762,1.99880111727541,17.8900007158518,0.0155642937424113,0.00292194520803355,0.25,1.17851383899241E-5,0.00141587963961577,2.19259522923678E-5,6.00090169906616,6.00090169906616,84668.375,84768.328125,56.3444734372752,20.6359061291468,4.51601648330688,0,0,0,40,5.97015619277954,1,6,1,2.24441528320313,42.5219955444336,,,,,,,,,,,,,,,,
,3949058560.981,6.00064039230347,91217.3828125,0.00152427039780665,3.20223781756121E-6,1,0.999253354069792,40.0298881530762,1.99875838708322,17.8900007158518,0.0167804282054579,0.0031370771397113,0.25,1.17565880198339E-5,0.00152634255440099,2.24782905432028E-5,6.00071001052856,6.00071001052856,91162.359375,91272.40625,56.1787681911983,20.6370265113524,4.51539468765259,0,0,0,40,5.96342992782593,1,6,1,2.2442626953125,42.0332374572754,,,,,,,,,,,,,,,,
,3949058625.9175,6.00050592422485,97715.08203125,0.0016173516821271,2.87282882235454E-6,1,0.999253354069792,40.0298881530762,1.99865972061293,17.8900007158518,0.0178035086077681,0.0033741201795976,0.25,1.67419771425452E-5,0.00162017040877281,2.7884624828744E-5,6.00052642822266,6.00052642822266,97665.0859375,97765.078125,55.903634952429,20.63740888548,4.51454496383667,0,0,0,40,5.95621824264526,1,6,1,2.22976684570313,42.5219955444336,,,,,,,,,,,,,,,,
,3949058690.8685,6.00059866905212,104212.92578125,0.00171225034169488,3.21196762168708E-6,1,0.999253354069792,40.0298881530762,1.99860417550097,17.8900007158518,0.0188583010493168,0.00355210588264235,0.25,1.60848649498868E-5,0.00171587299442328,2.76056448912667E-5,6.00056886672974,6.00056886672974,104167.875,104257.9765625,55.7770111323136,20.6320069342681,4.51349925994873,0,0,0,40,5.95007276535034,1,6,1,2.25677490234375,42.0332374572754,,,,,,,,,,,,,,,,
,3949058755.812,6.00051093101501,110711.234375,0.00181426566794377,2.53547332835112E-6,1,0.999253354069792,40.0298881530762,1.99859034015437,17.8900007158518,0.0199920927346633,0.00374409770698925,0.25,1.54627812287378E-5,0.00181871954541072,2.73647217181489E-5,6.00056743621826,6.00056743621826,110661.078125,110761.390625,55.3775989589866,20.6328738360042,4.51290798187256,0,0,0,40,5.94400453567505,1,6,1,2.23342895507813,42.0332374572754,,,,,,,,,,,,,,,,
,3949058821.7715,6.00053572654724,117314.6953125,0.00190988665772112,2.49595657121635E-6,1,0.999253354069792,40.0298881530762,1.99861312246713,17.8900007158518,0.0210527196995545,0.00394112582269012,0.25,1.64750044207238E-5,0.00191516184353997,2.86747168752892E-5,6.00056409835815,6.00056409835815,117264.609375,117364.78125,56.0060282884482,20.6411822351637,4.51231384277344,0,0,0,40,5.9384388923645,1,6,1,2.24288940429687,42.5219955444336,,,,,,,,,,,,,,,,
,3949058886.7385,6.0002715587616,123807.26953125,0.00200583900311218,2.24263056372825E-6,1,0.999253354069792,40.0298881530762,1.99868456940067,17.8900007158518,0.0221180011447112,0.00413584501262305,0.25,1.72409726025053E-5,0.00201193087098652,2.97100448754705E-5,6.00023508071899,6.00023508071899,123757.4140625,123857.125,56.8032893780637,20.6376810534699,4.51199197769165,0,0,0,40,5.93351316452026,1,6,1,2.24700927734375,42.5219955444336,,,,,,,,,,,,,,,,
,3949058952.651,6.0003182888031,130399.8671875,0.00210431053261696,2.42015232924609E-6,1,0.999253354069792,40.0298881530762,1.99864982267598,17.8900007158518,0.0232090139268718,0.00434142113797714,0.25,1.85958033834291E-5,0.00211123175270577,3.13142275340833E-5,6.00029277801514,6.00029277801514,130349.671875,130450.0625,56.4484300303329,20.6404755123027,4.51144409179687,0,0,0,40,5.92923641204834,1,6,1,2.24212646484375,38.1231689453125,,,,,,,,,,,,,,,,
,3949059017.6125,6.00028610229492,136903.4765625,0.00220262546715522,1.8342092296389E-6,1,0.999253354069792,40.0298881530762,1.99868768458036,17.8900007158518,0.0243050228772028,0.0045129924542477,0.25,1.69129519273225E-5,0.00221038535693301,2.98447591381539E-5,6.00028800964355,6.00028800964355,136853.546875,136953.40625,56.1451581648713,20.6435796759277,4.51027870178223,0,0,0,40,5.92522716522217,1,6,1,2.24166870117187,42.5219955444336,,,,,,,,,,,,,,,,
,3949059092.591,5.99994373321533,136813.703125,0.00219936264500659,2.1976336451648E-6,1,0.999253354069792,40.0298881530762,1.99855538876086,17.8900007158518,0.0242645965219976,0.00452191594387174,0.25,1.83222432895455E-5,0.00220709608189282,3.12450968253774E-5,5.99998378753662,5.99998378753662,136764.296875,136863.109375,55.8872207535252,20.6367879393587,4.5098991394043,0,0,0,40,5.92537021636963,1,6,1,2.24655151367187,43.0107536315918,,,,,,,,,,,,,,,,
,3949059157.547,5.99976491928101,130399.46875,0.00210630915317225,2.2411636892977E-6,1,0.999253354069792,40.0298881530762,1.99862438160645,17.8900007158518,0.023238122009105,0.0043042079484957,0.25,1.48761495161966E-5,0.00211325939461231,2.75941843768786E-5,5.99976682662964,5.99976682662964,130349.9296875,130449.0078125,55.9755447761982,20.6375987156967,4.51086235046387,0,0,0,40,5.92894744873047,1,6,1,2.24594116210938,38.1231689453125,,,,,,,,,,,,,,,,
,3949059223.4545,5.99958419799805,123897.97265625,0.00200694319150572,2.48323002097651E-6,1,0.999253354069792,40.0298881530762,1.99862648772168,17.8900007158518,0.0221275191559659,0.00414997133006494,0.25,1.83373179853816E-5,0.0020130390269504,3.08118181297453E-5,5.99955368041992,5.99955368041992,123848.734375,123947.2109375,55.8668984120251,20.6443319219839,4.51154184341431,0,0,0,40,5.93302297592163,1,6,1,2.22854614257813,42.5219955444336,,,,,,,,,,,,,,,,
,3949059288.394,5.99933171272278,117495.0546875,0.00191538120223862,2.32082934672849E-6,1,0.999253354069792,40.0298881530762,1.99854419703446,17.8999993950129,0.0211147698776079,0.00394111138634083,0.25,1.5512219517472E-5,0.00192069330169916,2.77350815440957E-5,5.99927520751953,5.99927520751953,117445.5625,117544.546875,55.5816040025059,20.6465227475616,4.51260566711426,0,0,0,40,5.93771839141846,1,6,1,2.24853515625,43.0107536315918,,,,,,,,,,,,,,,,
,3949059353.3905,5.9993679523468,111074.484375,0.00181455444064018,2.99361178158583E-6,1,0.999253354069792,40.0298881530762,1.9986555548804,17.8900007158518,0.0200038213084671,0.00370242609265921,0.25,1.16366037489009E-5,0.00181906617440017,2.35136416057357E-5,5.99932956695557,5.99932956695557,111020.125,111128.84375,56.1600091067367,20.6351039942257,4.51289224624634,0,0,0,40,5.94311666488647,1,6,1,2.24227905273438,43.0107536315918,,,,,,,,,,,,,,,,
,3949059418.303,5.9994044303894,104665.74609375,0.00172058489244105,3.12977604957243E-6,1,0.999253354069792,40.0298881530762,1.99875343689984,17.8900007158518,0.0189614355907912,0.00351632954292423,0.25,1.13430011948103E-5,0.00172429922336814,2.28896427150404E-5,5.99933910369873,5.99933910369873,104616.3359375,104715.15625,56.0646504273905,20.6355152771874,4.51258134841919,0,0,0,40,5.94887971878052,1,6,1,2.24563598632813,42.5219955444336,,,,,,,,,,,,,,,,
,3949059483.2665,5.99944639205933,98263.32421875,0.00162744355018934,3.52545919066585E-6,1,0.999253354069792,40.0298881530762,1.99886681636115,17.8900007158518,0.0179198170423571,0.00337949045221046,0.25,1.54064938018355E-5,0.00163034223446335,2.65947629384005E-5,5.99949073791504,5.99949073791504,98213.875,98312.7734375,56.3929344054675,20.641933703166,4.51270151138306,0,0,0,40,5.95489645004273,1,6,1,2.24746704101562,42.5219955444336,,,,,,,,,,,,,,,,
,3949059548.2165,5.99903798103332,91850.4453125,0.00153208237401804,3.95787414873542E-6,1,0.999253354069792,40.0298881530762,1.99880027616525,17.8999993950129,0.0168799998392392,0.00308321246779799,0.25,5.47769633883666E-6,0.00153427200067126,1.62237363774307E-5,5.99906253814697,5.99906253814697,91800.953125,91899.9375,55.9083247235444,20.6397492525937,4.51311159133911,0,0,0,40,5.9620189666748,1,6,1,2.2467041015625,43.0107536315918,,,,,,,,,,,,,,,,
,3949059613.1855,5.99934387207031,85435.2265625,0.00142805598989096,3.72939258029595E-6,1,0.999253354069792,40.0298881530762,1.99882286506584,17.8900007158518,0.0157209105735971,0.00290841120105138,0.25,8.1487400678344E-6,0.00142946240104099,1.83624958210216E-5,5.99931478500366,5.99931478500366,85385.65625,85484.796875,55.9380266072751,20.6503067876877,4.51323413848877,0,0,0,40,5.96910429000855,1,6,1,2.25860595703125,42.0332374572754,,,,,,,,,,,,,,,,
,3949059678.086,5.99929141998291,79033.4453125,0.00131824650872998,4.67148744394428E-6,1,0.999253354069792,40.0298881530762,1.99877624255751,17.8999993950129,0.0145239095694941,0.00257787542045946,0.25,-2.22400598057231E-6,0.00131900020182363,7.35095264074481E-6,5.9992504119873,5.9992504119873,78984.078125,79082.8125,56.035730172179,20.6475841145352,4.51355648040771,0,0,0,40,5.97582292556763,1,6,1,2.24822998046875,42.5219955444336,,,,,,,,,,,,,,,,
,3949059743.09,5.9992995262146,72601.35546875,0.00119759305654702,4.12118564695903E-6,1,0.999253354069792,40.0298881530762,1.99885635824177,17.8999993950129,0.0131485540066203,0.00256308205349889,0.25,1.80517839628774E-5,0.00119752171594258,2.68637152526188E-5,5.99931383132935,5.99931383132935,72556.65625,72646.0546875,55.852829098679,20.6473504825051,4.51379060745239,0,0,0,40,5.98229885101318,1,6,1,2.2454833984375,42.5219955444336,,,,,,,,,,,,,,,,
,3949059808.041,5.99932813644409,66157.2421875,0.00108787993890353,3.0723494245941E-5,1,0.999253354069792,40.0298881530762,1.99870464728809,17.8900007158518,0.0117819984615097,0.00318845070616154,0.25,9.46437594924005E-5,0.00108663627428576,0.000102665807432127,5.99923849105835,5.99923849105835,66107.640625,66206.84375,55.9599122058136,20.6416618955519,4.51419639587402,0,0,0,40,5.98887491226196,1,6,1,2.26821899414062,42.0332374572754,,,,,,,,,,,,,,,,
,3949059874.484,5.99950480461121,59560.46484375,0.00330554643914566,5.11523836193742E-5,1,0.999253354069792,40.0298881530762,1.99870864762572,17.8900007158518,0.0359141456090606,0.00892509272836957,0.25,0.000218629547435489,0.00330028355587625,0.000242969597683221,5.99944877624512,5.99944877624512,59461.5234375,59659.40625,55.8192190723521,20.6439631244975,4.51367282867432,0,0,0,40,5.99567890167236,1,6,1,2.24456787109375,42.0332374572754,,,,,,,,,,,,,,,,
,3949059939.907,5.99984264373779,53073.08984375,0.0101158773348444,3.02668551029816E-5,1,0.999253354069792,40.0298881530762,1.99877780520248,17.8900007158518,0.110669215192788,0.0226844019250341,0.25,0.000249595875742436,0.010096540534722,0.000324059330684131,5.99988222122192,5.99988222122192,53023.55859375,53122.62109375,56.1803314482367,20.6499317583963,4.51382541656494,0,0,0,40,6.00091314315796,1,6,1,2.24441528320313,42.5219955444336,,,,,,,,,,,,,,,,
,3949060005.8345,5.99957823753357,46524.552734375,0.0213427957409471,3.2850031958301E-5,1,0.999253354069792,40.0298881530762,1.99877849472605,17.8900007158518,0.23380206111918,0.045242334408589,2.5,0.000292993581022821,0.0212895694479306,0.00044832231075962,5.99966955184937,5.99966955184937,46475.21484375,46573.890625,55.9794529187944,20.654324792422,4.51404190063477,0,0,0,40,6.00563716888428,1,6,1,2.24319458007813,42.5219955444336,,,,,,,,,,,,,,,,
,3949060070.8425,5.999596118927,40075.6953125,0.0375064904779814,4.20422302415505E-5,1,0.999253354069792,40.0298881530762,1.99893672140978,17.8900007158518,0.410876263783281,0.0780402581274203,2.5,0.000391473754414531,0.0373885942907652,0.000658517116283825,5.99949502944946,5.99949502944946,40026.30078125,40125.08984375,55.8356332712559,20.6464185981288,4.51408004760742,0,0,0,40,6.01012229919434,1,6,1,2.24411010742187,42.0332374572754,,,,,,,,,,,,,,,,
,3949060135.761,5.99950623512268,33625.337890625,0.0602852479253865,3.09279019863211E-5,1,0.999253354069792,40.0298881530762,1.99883716607539,17.8900007158518,0.660081977356799,0.124492493867959,2.5,0.000565238288745431,0.0600551228298153,0.000980338261150385,5.9995265007019,5.9995265007019,33575.70703125,33674.96875,56.1224909378136,20.6390570121871,4.51381921768188,0,0,0,40,6.01377010345459,1,6,1,2.24502563476562,41.5444793701172,,,,,,,,,,,,,,,,
,3949060201.714,5.99979066848755,27062.86328125,0.0925793092528077,3.01475761202136E-5,1,0.999253354069792,40.0298881530762,1.99899080786759,17.8900007158518,1.01335750198062,0.189364947863905,2.5,0.000741620432689827,0.0921632984514832,0.00135017796505932,5.99978876113892,5.99978876113892,27008.009765625,27117.716796875,56.6837002146214,20.6508715379886,4.51412677764893,0,0,0,40,6.01682233810425,1,6,1,2.244873046875,42.0332374572754,,,,,,,,,,,,,,,,
,3949060267.6665,6.00006699562073,20500.6650390625,0.138611393652457,4.45275690894991E-5,1,0.999253354069792,40.0298881530762,1.99896989675132,17.8900007158518,1.51636078112774,0.28239727137785,25,0.00107838593017135,0.137897457774769,0.00193550106241792,6.00010251998901,6.00010251998901,20450.818359375,20550.51171875,55.6339731132944,20.6484866484218,4.51469755172729,0,0,0,40,6.01837158203125,1,6,1,2.24441528320313,42.0332374572754,,,,,,,,,,,,,,,,
,3949060333.715,6.0002760887146,13907.0024414062,0.203317093576707,5.99345495141929E-5,1,0.999253354069792,40.0298881530762,1.99895022177377,17.8999993950129,2.22315110883644,0.412122864709569,25,0.00150469579695302,0.202145880860301,0.00267003220435075,6.00032424926758,6.00032424926758,13852.060546875,13961.9443359375,55.9278654365251,20.6537528661793,4.51411390304565,0,0,0,40,6.01859521865845,1,6,1,2.23052978515625,42.0332374572754,,,,,,,,,,,,,,,,
,3949060398.5645,6.00047945976257,7422.07568359375,0.288906074522721,6.92265053854943E-5,1,0.999253354069792,40.0298881530762,1.99896667444928,17.8900007158518,3.15761894076235,0.583810456626303,25,0.00213905223536473,0.287089255505352,0.00365642707839472,6.0004186630249,6.0004186630249,7377.05859375,7467.0927734375,56.5047072837175,20.6560015771303,4.51343202590942,0,0,0,40,6.01694250106812,1,6,1,2.24212646484375,42.0332374572754,,,,,,,,,,,,,,,,
,3949060464.481,5.99972009658813,827.921997070312,0.0844932382614063,0.00027524974752357,1,0.999253354069792,40.0298881530762,1.99900086564641,17.8900007158518,0.923089382631382,0.170747329262307,2.5,0.000670262586511556,0.0839266769068485,0.00107575083707328,5.99970483779907,5.99970483779907,777.801818847656,878.042175292969,55.9833610613905,20.6470147587016,4.51294469833374,0,0,0,40,6.01375913619995,1,6,1,2.24090576171875,41.5444793701172,,,,,,,,,,,,,,,,
,3949060530.486,5.99975872039795,-5770.29711914062,0.333333014582876,7.29323935431486E-5,1,0.999253354069792,40.0298881530762,1.99879349583734,17.8900007158518,3.64238960049436,0.673788902813945,25,0.00253912105209513,0.331196879609225,0.00424892088438584,5.99970960617065,5.99970960617065,-5820.30078125,-5720.29345703125,56.353852979506,20.6437698168976,4.51195240020752,0,0,0,40,6.01551389694214,1,6,1,2.24655151367187,41.055721282959,,,,,,,,,,,,,,,,
,3949060596.4885,6.00012946128845,-12369.0756835938,0.0902125928461616,0.000226998020962181,1,0.999253354069792,40.0298881530762,1.99896308316811,17.8900007158518,0.986351279649422,0.182516532056586,2.5,0.000648381507986818,0.0896810344725533,0.00115543598954767,6.00011253356934,6.00011253356934,-12424.142578125,-12314.0087890625,55.7238603930059,20.6572782839309,4.50893449783325,0,0,0,40,6.01778173446655,1,6,1,2.2467041015625,42.0332374572754,,,,,,,,,,,,,,,,
,3949060662.371,5.9998607635498,-18966.8310546875,0.190440852914783,5.59531963127793E-5,1,0.999253354069792,40.0298881530762,1.99889627506677,17.8900007158518,2.08334787389908,0.385819340015798,25,0.00130876902654204,0.189432892190244,0.0024680771876282,5.9998254776001,5.9998254776001,-19016.845703125,-18916.81640625,55.913796123179,20.6482065043319,4.50771760940552,0,0,0,40,6.01805305480957,1,6,1,2.2314453125,41.5444793701172,,,,,,,,,,,,,,,,
,3949060727.336,5.99985456466675,-25460.328125,0.12106324758485,4.40278449797244E-5,1,0.999253354069792,40.0298881530762,1.99883728918305,17.8900007158518,1.32520197303522,0.245440261615967,25,0.000786171841078164,0.12050057079676,0.00157203769293991,5.99984788894653,5.99984788894653,-25510.267578125,-25410.388671875,55.9700733765636,20.6470434000723,4.50758171081543,0,0,0,40,6.0169095993042,1,6,1,2.24624633789062,41.5444793701172,,,,,,,,,,,,,,,,
,3949060792.26,6.00056886672974,-31953.6533203125,0.0750948729619468,4.23250779683902E-5,1,0.999253354069792,40.0298881530762,1.99903066974067,17.8900007158518,0.822739867689362,0.151858326150907,25,0.000417319419440412,0.0747969591492016,0.000929979335868836,6.00061130523682,6.00061130523682,-32003.646484375,-31903.66015625,56.689171614256,20.649407609238,4.5076117515564,0,0,0,40,6.01482009887695,1,6,1,2.2509765625,41.5444793701172,,,,,,,,,,,,,,,,
,3949060857.242,6.00035929679871,-38462.798828125,0.0453902723511688,3.95245591428662E-5,1,0.999253354069792,40.0298881530762,1.99893061873105,17.8900007158518,0.497700799759796,0.0913803803406392,25,0.00019832115639437,0.0452418257941749,0.000519999714100948,6.00035762786865,6.00035762786865,-38507.80078125,-38417.796875,56.5820885071214,20.6581129635984,4.50762939453125,0,0,0,40,6.01131010055542,1,6,1,2.2430419921875,41.5444793701172,,,,,,,,,,,,,,,,
,3949060923.16,6.0006217956543,-45059.96875,0.024930914316672,3.99779457906244E-5,1,0.999253354069792,40.0298881530762,1.99888394503825,17.8900007158518,0.273668111754241,0.0495659883021898,2.5,4.45337689401524E-5,0.0248671297899541,0.000225935294516806,6.00059652328491,6.00059652328491,-45109.94921875,-45009.98828125,56.8806706014676,20.6569375518801,4.50744152069092,0,0,0,40,6.00725126266479,1,6,1,2.24151611328125,41.5444793701172,,,,,,,,,,,,,,,,
,3949060988.1205,6.00050449371338,-51552.65234375,0.0114839422907702,5.24111740293164E-5,1,0.999253354069792,40.0298881530762,1.99905328636077,17.8900007158518,0.126329020554769,0.0218736451652251,2.5,-6.93939464567115E-5,0.0114628564708719,1.55778422479018E-5,6.0006308555603,6.0006308555603,-51602.69140625,-51502.61328125,56.5906864208329,20.6551186737936,4.50715970993042,0,0,0,40,6.00229263305664,1,6,1,2.24334716796875,41.5444793701172,,,,,,,,,,,,,,,,
,3949061054.087,6.00072646141052,-58155.802734375,0.00309835897660178,3.79721893672618E-5,1,0.999253354069792,40.0298881530762,1.99895771015603,17.8900007158518,0.0342684375764443,0.00498883565987168,0.25,-0.000102179617281882,0.0030952966376587,-7.9021175675411E-5,6.00060415267944,6.00060415267944,-58205.859375,-58105.74609375,56.4968909985252,20.662012357651,4.50774335861206,0,0,0,40,5.99749851226807,1,6,1,2.24838256835938,41.055721282959,,,,,,,,,,,,,,,,
,3949061120.0115,6.00092768669128,-64753.423828125,-0.00078115398018287,3.95362247520933E-5,1,0.999253354069792,40.0298881530762,1.99897775791943,17.8999993950129,-0.0083622992114782,-0.00283470538276555,0.25,-0.000117509029415467,-0.00077979495755485,-0.000123236119485633,6.00093460083008,6.00093460083008,-64808.4140625,-64698.43359375,56.1709519060059,20.6549360583425,4.50738573074341,0,0,0,40,5.9916672706604,1,6,1,2.2467041015625,41.5444793701172,,,,,,,,,,,,,,,,
,3949061184.9745,6.00050616264343,-71255.328125,-0.00116614798843524,5.1749103092818E-6,1,0.999253354069792,40.0298881530762,1.99884037582469,17.8900007158518,-0.0128054523601704,-0.00247505846282889,0.25,-1.57029341123921E-5,-0.00116596213342243,-2.42997631008446E-5,6.00047636032104,6.00047636032104,-71310.2578125,-71200.3984375,56.6391473890252,20.6547096907267,4.50752449035645,0,0,0,40,5.98446321487427,1,6,1,2.24563598632813,41.5444793701172,,,,,,,,,,,,,,,,
,3949061249.933,6.00055861473084,-77748.1328125,-0.00129825200313184,4.06539392006312E-6,1,0.999253354069792,40.0298881530762,1.99892005467467,17.8999993950129,-0.0142800245763674,-0.00266793745949573,0.25,-9.51582677232791E-6,-0.00129878136843476,-1.89782238704375E-5,6.00062990188599,6.00062990188599,-77803.390625,-77692.875,56.8025077495445,20.657290461142,4.5081992149353,0,0,0,40,5.97776079177856,1,6,1,2.26119995117187,41.5444793701172,,,,,,,,,,,,,,,,
,3949061314.867,6.00093698501587,-84250.9453125,-0.00141197868973894,4.12150064734842E-6,1,0.999253354069792,40.0298881530762,1.998925370829,17.8900007158518,-0.0155448244074582,-0.00286753246889035,0.25,-7.29382522463869E-6,-0.00141325694034524,-1.74243140920812E-5,6.00090026855469,6.00090026855469,-84295.96875,-84205.921875,56.4914195988906,20.657859281027,4.50789403915405,0,0,0,40,5.97128772735596,1,6,1,2.24761962890625,41.055721282959,,,,,,,,,,,,,,,,
,3949061379.8035,6.00094532966614,-90743.41796875,-0.00151572174511857,3.30450162604816E-6,1,0.999253354069792,40.0298881530762,1.99901361985301,17.8900007158518,-0.016683544806467,-0.00314369137456303,0.25,-1.38444281286405E-5,-0.00151772054232929,-2.45246818615641E-5,6.00089168548584,6.00089168548584,-90788.421875,-90698.4140625,56.3069552683521,20.6631243276582,4.5079836845398,0,0,0,40,5.96439504623413,1,6,1,2.24655151367187,41.5444793701172,,,,,,,,,,,,,,,,
,3949061445.7795,6.00057363510132,-97346.38671875,-0.00161576795316793,3.09702596726724E-6,1,0.999253354069792,40.0298881530762,1.99879148367233,17.8900007158518,-0.0177984344944817,-0.00330589716907929,0.25,-1.08120270046284E-5,-0.00161858932414623,-2.19472841118938E-5,6.00058317184448,6.00058317184448,-97391.390625,-97301.3828125,56.3718304354483,20.6576373301876,4.50812387466431,0,0,0,40,5.956955909729,1,6,1,2.24411010742187,41.5444793701172,,,,,,,,,,,,,,,,
,3949061510.707,6.00023007392883,-103843.62109375,-0.00171043737681805,2.69944419118087E-6,1,0.999253354069792,40.0298881530762,1.99903905197831,17.8900007158518,-0.0188509874096577,-0.00349784800201596,0.25,-1.14151405566128E-5,-0.00171405338402607,-2.29295257385164E-5,6.00014209747314,6.00014209747314,-103893.59375,-103793.6484375,56.2936675835252,20.6693166083453,4.50784969329834,0,0,0,40,5.9499888420105,1,6,1,2.24533081054687,41.055721282959,,,,,,,,,,,,,,,,
,3949061575.672,6.00061750411987,-110336.484375,-0.00180445976925041,2.39111590990865E-6,1,0.999253354069792,40.0298881530762,1.99884212279744,17.8900007158518,-0.0198895313660078,-0.00370473324075447,0.25,-1.35940286623524E-5,-0.00180886810410787,-2.54447304409702E-5,6.00056028366089,6.00056028366089,-110386.4765625,-110286.4921875,55.6097426291982,20.6617097326753,4.50767278671265,0,0,0,40,5.94416189193726,1,6,1,2.2296142578125,41.055721282959,,,,,,,,,,,,,,,,
,3949061640.629,6.00019288063049,-116838.92578125,-0.00190474308847583,2.21890489028678E-6,1,0.999253354069792,40.0298881530762,1.9989271658731,17.8999993950129,-0.0209948408446868,-0.00395270731548194,0.25,-1.83709078627622E-5,-0.00190995133199279,-3.05670368623907E-5,6.00011205673218,6.00011205673218,-116888.953125,-116788.8984375,56.0630871703521,20.6603395043496,4.50789308547974,0,0,0,40,5.93862199783325,1,6,1,2.24136352539062,41.055721282959,,,,,,,,,,,,,,,,
,3949061705.5435,6.00062274932861,-123331.79296875,-0.0019997093487989,2.15567089101415E-6,1,0.999253354069792,40.0298881530762,1.99876416333928,17.8900007158518,-0.0220564859066264,-0.00409148507383279,0.25,-1.42834821035654E-5,-0.00200576212790097,-2.67305982132339E-5,6.00063276290894,6.00063276290894,-123381.78125,-123281.8046875,55.2986544785443,20.6715479345632,4.5080075263977,0,0,0,40,5.93398761749268,1,6,1,2.25296020507813,41.055721282959,,,,,,,,,,,,,,,,
,3949061772.5175,6.00026869773865,-130032.921875,-0.00209843907670403,2.50802051612427E-6,1,0.999253354069792,40.0298881530762,1.99900635345626,17.8900007158518,-0.0231481475262103,-0.00432837661264879,0.25,-1.83781129919281E-5,-0.00210531370998512,-3.10806313206958E-5,6.00025177001953,6.00025177001953,-130082.8671875,-129982.9765625,56.0208792303136,20.6712076174223,4.50815391540527,0,0,0,40,5.92941904067993,1,6,1,2.2467041015625,40.5669593811035,,,,,,,,,,,,,,,,
,3949061837.47,6.00062465667725,-136534.8515625,-0.0021988127334721,1.77858286645739E-6,1,0.999253354069792,40.0298881530762,1.99878489419771,17.8900007158518,-0.0242557519452204,-0.00455046294400717,0.25,-2.09466121357003E-5,-0.00220650837081505,-3.38913816051104E-5,6.00063037872314,6.00063037872314,-136584.96875,-136484.734375,56.0920074255636,20.6659202350431,4.50801944732666,0,0,0,40,5.92576789855957,1,6,1,2.25051879882813,41.055721282959,,,,,,,,,,,,,,,,
,3949061912.404,5.99970102310181,-137240.2109375,-0.00220778929549797,2.45255433651675E-6,1,0.999253354069792,40.0298881530762,1.99890515813535,17.8900007158518,-0.0243627145778759,-0.004535751888045,0.25,-1.80273353346308E-5,-0.00221558577986413,-3.09741553379124E-5,5.99964046478271,5.99964046478271,-137289.6875,-137190.734375,55.402611071602,20.6710310811666,4.50714254379272,0,0,0,40,5.92481517791748,1,6,1,2.24472045898438,41.055721282959,,,,,,,,,,,,,,,,
,3949061977.362,5.99950098991394,-130810.57421875,-0.00210916180463684,2.33445359001238E-6,1,0.999253354069792,40.0298881530762,1.99897032970865,17.8900007158518,-0.0232651314773068,-0.00435930792633494,0.25,-1.93089851395513E-5,-0.00211612658432148,-3.20363477943853E-5,5.99960136413574,5.99960136413574,-130859.734375,-130761.4140625,55.8590821268328,20.6736879555188,4.50825119018555,0,0,0,40,5.9279088973999,1,6,1,2.244873046875,40.5669593811035,,,,,,,,,,,,,,,,
,3949062042.316,5.99965453147888,-124386.18359375,-0.00201529323188924,2.37712600186416E-6,1,0.999253354069792,40.0298881530762,1.99893996304906,17.8900007158518,-0.022229841445936,-0.00413131990761994,0.25,-1.51247376424593E-5,-0.00202147424438807,-2.761498802401E-5,5.99965143203735,5.99965143203735,-124440.6484375,-124331.71875,54.8515629655443,20.6661536625887,4.50987195968628,0,0,0,40,5.93236684799194,1,6,1,2.24105834960938,41.055721282959,,,,,,,,,,,,,,,,
,3949062107.283,5.99928855895996,-117956.71484375,-0.00191778020658511,2.20062883187107E-6,1,0.999253354069792,40.0298881530762,1.99896849980092,17.8999993950129,-0.0211454292750498,-0.00394956382178347,0.25,-1.57947316911042E-5,-0.00192313633809141,-2.80103161477072E-5,5.99924755096436,5.99924755096436,-118001.4453125,-117911.984375,55.7340215637559,20.6659017448064,4.51044511795044,0,0,0,40,5.93724060058594,1,6,1,2.24380493164062,41.055721282959,,,,,,,,,,,,,,,,
,3949062173.2155,5.99946165084839,-111437.33984375,-0.00181933940116038,2.5042492043237E-6,1,0.999253354069792,40.0298881530762,1.99894911281072,17.8900007158518,-0.0200415788238545,-0.0038144047190406,0.25,-2.08920840081898E-5,-0.00182383488055252,-3.2806695222516E-5,5.99945545196533,5.99945545196533,-111491.796875,-111382.8828125,55.8739330686982,20.664641470629,4.51079034805298,0,0,0,40,5.94238519668579,1,6,1,2.24502563476562,40.5669593811035,,,,,,,,,,,,,,,,
,3949062238.1495,5.99934077262878,-105012.8515625,-0.00172160179426378,2.4883353715382E-6,1,0.999253354069792,40.0298881530762,1.9989340000944,17.8900007158518,-0.0189696428162926,-0.00354661653488403,0.25,-1.38884883473091E-5,-0.00172533314871868,-2.5432435930851E-5,5.99939775466919,5.99939775466919,-105062.34375,-104963.359375,55.9677284910059,20.6601907773031,4.51143264770508,0,0,0,40,5.94777011871338,1,6,1,2.24884033203125,41.055721282959,,,,,,,,,,,,,,,,
,3949062303.136,5.99958848953247,-98582.4140625,-0.00163198986881371,3.09873712184313E-6,1,0.999253354069792,40.0298881530762,1.99894685288398,17.8900007158518,-0.0179700584491465,-0.00339378824245429,0.25,-1.58854535807112E-5,-0.00163492410334088,-2.70933074944988E-5,5.99954271316528,5.99954271316528,-98631.8359375,-98532.9921875,55.9294286935636,20.6607803863985,4.51158428192139,0,0,0,40,5.95486307144165,1,6,1,2.25250244140625,41.055721282959,,,,,,,,,,,,,,,,
,3949062368.0715,5.99905562400818,-92158.1796875,-0.00153252184450527,3.23319277233362E-6,1,0.999253354069792,40.0298881530762,1.9989168189997,17.8900007158518,-0.016873980925214,-0.00315208175298169,0.25,-1.16353379926353E-5,-0.00153469910458646,-2.23829296835242E-5,5.9990029335022,5.9990029335022,-92202.6171875,-92113.7421875,56.7688977232175,20.6646272281186,4.51157760620117,0,0,0,40,5.96161603927612,1,6,1,2.25921630859375,41.5444793701172,,,,,,,,,,,,,,,,
,3949062433.994,5.9993999004364,-85634.609375,-0.00143240184906189,4.23399193897435E-6,1,0.999253354069792,40.0298881530762,1.99891094391872,17.8900007158518,-0.0157697304330409,-0.00291686466550712,0.25,-8.12862752964434E-6,-0.00143383279479518,-1.8367783571884E-5,5.99942636489868,5.99942636489868,-85684.1875,-85585.03125,55.2955279644674,20.6498939109522,4.51165342330933,0,0,0,40,5.96825695037842,1,6,1,2.23403930664062,40.5669593811035,,,,,,,,,,,,,,,,
,3949062498.933,5.99927759170532,-79214.4765625,-0.0013373652550655,4.79350890489427E-6,1,0.999253354069792,40.0298881530762,1.99894983438363,17.8900007158518,-0.0147196593280329,-0.00270650425951286,0.25,-6.00823825883161E-6,-0.00133808821139259,-1.57227337156228E-5,5.99923944473267,5.99923944473267,-79263.9453125,-79165.0078125,56.0982604537175,20.6542755768454,4.51193046569824,0,0,0,40,5.97519588470459,1,6,1,2.24533081054687,41.5444793701172,,,,,,,,,,,,,,,,
,3949062563.928,5.99917840957642,-72762.16015625,-0.00121322574421509,4.63738730620068E-6,1,0.999253354069792,40.0298881530762,1.99882566770112,17.8999993950129,-0.0133332150329635,-0.00252379034308323,0.25,-1.16820554123644E-5,-0.00121321809991001,-2.06064574669929E-5,5.9992527961731,5.9992527961731,-72811.828125,-72712.4921875,55.3713459308328,20.648804873487,4.51237916946411,0,0,0,40,5.98182153701782,1,6,1,2.2442626953125,41.055721282959,,,,,,,,,,,,,,,,
,3949062628.8535,5.99904584884644,-66300.1640625,-0.00109720030617553,3.0577815651803E-5,1,0.999253354069792,40.0298881530762,1.99887027813994,17.8900007158518,-0.0118763447201206,-0.00325887275389228,0.25,-9.93466501659796E-5,-0.00109593104521576,-0.000107435734792892,5.99909210205078,5.99909210205078,-66354.8515625,-66245.4765625,55.8231272149482,20.6493783069095,4.51291990280151,0,0,0,40,5.98837423324585,1,6,1,2.25143432617187,41.055721282959,,,,,,,,,,,,,,,,
,3949062693.8235,5.9994056224823,-59839.23046875,-0.00310800185617565,4.99571563417607E-5,1,0.999253354069792,40.0298881530762,1.99883718789527,17.8900007158518,-0.0337372860102131,-0.00857927531260814,0.25,-0.000222554023370165,-0.00310300865811577,-0.000245427232572607,5.99933528900146,5.99933528900146,-59889.02734375,-59789.43359375,56.2209761312367,20.6483536069007,4.51288604736328,0,0,0,40,5.99493312835693,1,6,1,2.24761962890625,41.055721282959,,,,,,,,,,,,,,,,
,3949062758.762,5.99929308891296,-53377.154296875,-0.00961770254011269,5.18319368379518E-5,1,0.999253354069792,40.0298881530762,1.99872664732007,17.8900007158518,-0.105121505690469,-0.022114926456752,0.25,-0.000287105516787604,-0.00959923879807938,-0.00035785120302483,5.99934339523315,5.99934339523315,-53422.03515625,-53332.2734375,56.2311373019867,20.642802843781,4.51304626464844,0,0,0,40,6.00036573410034,1,6,1,2.2479248046875,41.055721282959,,,,,,,,,,,,,,,,
,3949062824.7335,5.99977898597717,-46812.107421875,-0.0207408062686456,3.19475589011931E-5,1,0.999253354069792,40.0298881530762,1.99872660788269,17.8900007158518,-0.227147681601397,-0.0443065664877618,2.5,-0.000315589978163502,-0.0206894700943119,-0.000466586572907091,5.9998049736023,5.9998049736023,-46856.97265625,-46767.2421875,56.0912257970444,20.6509212689832,4.51238489151001,0,0,0,40,6.00572776794434,1,6,1,2.254638671875,41.5444793701172,,,,,,,,,,,,,,,,
,3949062889.6495,5.99969887733459,-40352.1328125,-0.0366502134873512,3.23989654294887E-5,1,0.999253354069792,40.0298881530762,1.99898946451636,17.8900007158518,-0.401476651638882,-0.0764919546360305,2.5,-0.000403124691224763,-0.0365359289100808,-0.000664322646698953,5.99972438812256,5.99972438812256,-40401.49609375,-40302.76953125,55.9661652339675,20.6542472354089,4.51271104812622,0,0,0,40,6.01001358032227,1,6,1,2.24166870117187,41.5444793701172,,,,,,,,,,,,,,,,
,3949062955.606,5.99968981742859,-33784.044921875,-0.0596396876128504,2.96451510126041E-5,1,0.999253354069792,40.0298881530762,1.99888863771002,17.8999993950129,-0.653105350456925,-0.122801933927495,2.5,-0.000525745842416572,-0.0594132570814913,-0.000936927743568951,5.99965000152588,5.99965000152588,-33833.9453125,-33734.14453125,56.1029502248329,20.645842474292,4.51282835006714,0,0,0,40,6.01375150680542,1,6,1,2.25616455078125,41.055721282959,,,,,,,,,,,,,,,,
,3949063020.533,5.9997980594635,-27299.96484375,-0.0911750072399798,3.34072741217443E-5,1,0.999253354069792,40.0298881530762,1.99886136787934,17.8999993950129,-0.997863955801145,-0.186964830858016,2.5,-0.000772946412960983,-0.0907672519278521,-0.00137325122673478,5.99980020523071,5.99980020523071,-27349.791015625,-27250.138671875,56.1725151630444,20.6537872046231,4.51300382614136,0,0,0,40,6.01681613922119,1,6,1,2.24166870117187,41.5444793701172,,,,,,,,,,,,,,,,
,3949063087.4915,6.00025320053101,-20627.0087890625,-0.137495974141292,3.71700544005495E-5,1,0.999253354069792,40.0298881530762,1.9989509926408,17.8900007158518,-1.50417108606275,-0.280083995700339,25,-0.00106479245331554,-0.136789503831536,-0.00191615715803752,6.000319480896,6.000319480896,-20676.921875,-20577.095703125,56.0302587725444,20.6454885461887,4.51324844360352,0,0,0,40,6.0184154510498,1,6,1,2.23724365234375,41.055721282959,,,,,,,,,,,,,,,,
,3949063152.4745,5.99964618682861,-14135.1171875,-0.201870520783669,5.78102644762873E-5,1,0.999253354069792,40.0298881530762,1.99882572682454,17.8900007158518,-2.20726411868623,-0.409084779974371,25,-0.00148247415460388,-0.2007117615529,-0.00264291341640467,5.99965858459473,5.99965858459473,-14185.0693359375,-14085.1650390625,56.2131598460444,20.6479953882814,4.51268577575684,0,0,0,40,6.0179648399353,1,6,1,2.24502563476562,41.5444793701172,,,,,,,,,,,,,,,,
,3949063217.4155,5.99997711181641,-7639.9716796875,-0.284605873978243,6.86161107960956E-5,1,0.999253354069792,40.0298881530762,1.99874877873854,17.8999993950129,-3.1102230214426,-0.575781729772286,25,-0.0021676186593987,-0.282820389587396,-0.00366662868211163,5.99998664855957,5.99998664855957,-7689.9736328125,-7589.9697265625,55.8387597853328,20.6351219045225,4.51244831085205,0,0,0,40,6.0167932510376,1,6,1,2.2454833984375,41.5444793701172,,,,,,,,,,,,,,,,
,3949063283.3585,5.99975323677063,-1050.89575195312,-0.0752357708433401,0.000275654485466664,1,0.999253354069792,40.0298881530762,1.99890963612206,17.8900007158518,-0.821908811475045,-0.152123134214165,2.5,-0.000604018774934342,-0.0747320262580351,-0.000965946744530945,5.99967050552368,5.99967050552368,-1100.82958984375,-1000.9619140625,55.8379781568136,20.6499591601538,4.51207971572876,0,0,0,40,6.01418590545654,1,6,1,2.24990844726562,41.5444793701172,,,,,,,,,,,,,,,,
,3949063349.301,5.99958229064941,5547.52905273438,-0.331924160816614,8.26247558871619E-5,1,0.999253354069792,40.0298881530762,1.99877564867067,17.8999993950129,-3.62700844404829,-0.670355335453235,25,-0.00248166539732375,-0.329792183168935,-0.00417916977346899,5.99952125549316,5.99952125549316,5497.5029296875,5597.55517578125,55.9810161758329,20.6336086237144,4.51113748550415,0,0,0,40,6.01551675796509,1,6,1,2.24960327148438,41.5444793701172,,,,,,,,,,,,,,,,
,3949063417.2745,5.99960875511169,12346.5322265625,-0.0821831095496164,0.000239343784536968,1,0.999253354069792,40.0298881530762,1.99876929882392,17.8900007158518,-0.89849282185564,-0.166158378857348,2.5,-0.000581905393163218,-0.0816987552719176,-0.00104374404590245,5.99954557418823,5.99954557418823,12291.5087890625,12401.5556640625,55.7254236500444,20.6374692172923,4.50825452804565,0,0,0,40,6.01764059066772,1,6,1,2.25875854492187,41.5444793701172,,,,,,,,,,,,,,,,
,3949063483.23,5.99992895126343,18943.822265625,-0.190038103677454,4.58845399565308E-5,1,0.999253354069792,40.0298881530762,1.99877234401074,17.8900007158518,-2.07883956348085,-0.38484261949607,25,-0.00129375388583346,-0.189031932426902,-0.00245038284682394,5.99996185302734,5.99996185302734,18893.8046875,18993.83984375,55.9083247235444,20.6488477433658,4.50669431686401,0,0,0,40,6.01807022094727,1,6,1,2.24609375,42.0332374572754,,,,,,,,,,,,,,,,
,3949063548.1845,5.99981069564819,25447.376953125,-0.121070964878214,5.05288971001393E-5,1,0.999253354069792,40.0298881530762,1.99877602108717,17.8900007158518,-1.32531865660227,-0.245042310678089,25,-0.000749248833594248,-0.120508333484406,-0.00153524613660036,5.99983024597168,5.99983024597168,25397.353515625,25497.400390625,56.3561978650637,20.6408601345475,4.50646543502808,0,0,0,40,6.01656246185303,1,6,1,2.23175048828125,41.5444793701172,,,,,,,,,,,,,,,,
,3949063613.088,6.00023627281189,31941.1337890625,-0.0752739784599438,3.61199299008501E-5,1,0.999253354069792,40.0298881530762,1.99874546180452,17.8900007158518,-0.824484125441852,-0.152788779047998,25,-0.000472076162579307,-0.0749748867471176,-0.000985704857618446,6.0001802444458,6.0001802444458,31891.173828125,31991.09375,55.8801860968521,20.6438467172392,4.50654363632202,0,0,0,40,6.0148286819458,1,6,1,2.2296142578125,41.5444793701172,,,,,,,,,,,,,,,,
,3949063678.054,6.00031232833862,38444.48046875,-0.0454661099802282,4.34834381413083E-5,1,0.999253354069792,40.0298881530762,1.99885217740754,17.8999993950129,-0.498523445020445,-0.0914701975338882,25,-0.000193277519687447,-0.0453173654302421,-0.00051548311484513,6.00033950805664,6.00033950805664,38394.421875,38494.5390625,55.8411046708905,20.646935539268,4.50603532791138,0,0,0,40,6.01127529144287,1,6,1,2.25143432617187,42.0332374572754,,,,,,,,,,,,,,,,
,3949063745.0435,6.00042033195496,45141.998046875,-0.0247449703762331,3.76892224410382E-5,1,0.999253354069792,40.0298881530762,1.99878036027337,17.8900007158518,-0.27163676168462,-0.0490783456522631,2.5,-3.35979100840516E-5,-0.0246819499327899,-0.000213717549181128,6.00036287307739,6.00036287307739,45087.05078125,45196.9453125,56.5179949685444,20.6464824609277,4.50534105300903,0,0,0,40,6.00714206695557,1,6,1,2.2479248046875,41.5444793701172,,,,,,,,,,,,,,,,
,3949063809.9925,6.00080132484436,51640.923828125,-0.0112980709977359,5.10840997210294E-5,1,0.999253354069792,40.0298881530762,1.99882524759453,17.8900007158518,-0.124328768917742,-0.021201029076427,2.5,9.70822218210585E-5,-0.0112776395361539,1.34209502636314E-5,6.0007700920105,6.0007700920105,51590.9765625,51690.87109375,56.821266834006,20.6384407967235,4.50549030303955,0,0,0,40,6.00283813476563,1,6,1,2.25051879882813,42.0332374572754,,,,,,,,,,,,,,,,
,3949063875.9225,6.00048398971558,58243.828125,-0.00293060812987307,4.78387034509443E-5,1,0.999253354069792,40.0298881530762,1.99883444071951,17.8900007158518,-0.0324324248665265,-0.00460163959336319,0.25,0.000107276325165845,-0.0029278152373016,8.53588583954329E-5,6.00044059753418,6.00044059753418,58193.8359375,58293.8203125,56.7368509539291,20.6462452491817,4.50551557540894,0,0,0,40,5.99723958969116,1,6,1,2.2442626953125,42.0332374572754,,,,,,,,,,,,,,,,
,3949063940.8515,6.00059604644775,64737.072265625,0.000797252979446034,3.36948623365527E-5,1,0.999253354069792,40.0298881530762,1.9987531269521,17.8900007158518,0.00844924615279387,0.00336365008634015,0.25,0.000162730921032073,0.00079554696510226,0.000168549212801799,6.00061845779419,6.00061845779419,64687.09765625,64787.046875,56.4390504881021,20.6476475663901,4.50522565841675,0,0,0,40,5.99112796783447,1,6,1,2.2589111328125,40.5669593811035,,,,,,,,,,,,,,,,
,3949064005.8175,6.00086641311646,71235.1953125,0.00117138317104332,4.81999132606756E-6,1,0.999253354069792,40.0298881530762,1.99862683778634,17.8900007158518,0.0128775975279883,0.0023967997652108,0.25,7.67662721880264E-6,0.00117125420804581,1.63127825867645E-5,6.00082635879517,6.00082635879517,71180.2421875,71290.1484375,56.0669953129482,20.638726163655,4.50515079498291,0,0,0,40,5.98503017425537,1,6,1,2.23129272460938,42.0332374572754,,,,,,,,,,,,,,,,
,3949064070.745,6.0006148815155,77733.5625,0.00130298285050386,5.3619627415489E-6,1,0.999253354069792,40.0298881530762,1.99874972627535,17.8900007158518,0.0143211370114605,0.00273183133583729,0.25,1.44890190108276E-5,0.00130347669905537,2.39884582041898E-5,6.00069570541382,6.00069570541382,77683.328125,77783.796875,56.7165286124291,20.6451791869404,4.50497198104858,0,0,0,40,5.97807502746582,1,6,1,2.24288940429687,42.0332374572754,,,,,,,,,,,,,,,,
,3949064135.6925,6.0006160736084,84226.5390625,0.00140986505843487,4.68367833496837E-6,1,0.999253354069792,40.0298881530762,1.99864622104636,17.8900007158518,0.0155147753906456,0.00288907708970258,0.25,9.66208246549356E-6,0.00141112189326147,1.97803032242425E-5,6.00055742263794,6.00055742263794,84176.5625,84276.515625,56.3046103827944,20.6428479326329,4.50529146194458,0,0,0,40,5.97124719619751,1,6,1,2.26089477539062,42.5219955444336,,,,,,,,,,,,,,,,
,3949064200.655,6.00109386444092,90729.984375,0.00151184947124719,3.80702830367383E-6,1,0.999253354069792,40.0298881530762,1.99859415012238,17.8900007158518,0.0166431440696791,0.00310404031911355,0.25,1.09968837190163E-5,0.00151386162056633,2.16464058077166E-5,6.0009446144104,6.0009446144104,90679.953125,90780.015625,55.9520959206213,20.6400194777268,4.50514888763428,0,0,0,40,5.964674949646,1,6,1,2.24288940429687,42.5219955444336,,,,,,,,,,,,,,,,
,3949064265.623,6.00046253204346,97233.63671875,0.00161206713207406,2.93949223671116E-6,1,0.999253354069792,40.0298881530762,1.99862447227585,17.8999993950129,0.0177673870778798,0.00323516528025497,0.25,5.08109677976009E-6,0.00161491052840444,1.61849967350373E-5,6.00062370300293,6.00062370300293,97183.6953125,97283.578125,55.7332399352367,20.6398162127442,4.50473260879517,0,0,0,40,5.95655012130737,1,6,1,2.25875854492187,42.5219955444336,,,,,,,,,,,,,,,,
,3949064331.559,6.00067782402039,103830.72265625,0.00170654788656828,2.91728829829035E-6,1,0.999253354069792,40.0298881530762,1.99856310720691,17.8900007158518,0.0188143764264346,0.00343024590826381,0.25,6.0533425917689E-6,0.00171019032681326,1.75305832488807E-5,6.00062990188599,6.00062990188599,103785.7578125,103875.6875,56.1592274782175,20.6439099277361,4.50438785552978,0,0,0,40,5.95086050033569,1,6,1,2.242431640625,43.0107536315918,,,,,,,,,,,,,,,,
,3949064396.5215,6.00054597854614,110329.12109375,0.00180623409689189,2.37154337125235E-6,1,0.999253354069792,40.0298881530762,1.99860494159017,17.8900007158518,0.0199055098697486,0.00371541677913983,0.25,1.42829475778746E-5,0.0018106416887581,2.61473310170748E-5,6.00047922134399,6.00047922134399,110279.125,110379.1171875,55.8559556127559,20.6478295521095,4.50441837310791,0,0,0,40,5.94464540481567,1,6,1,2.24746704101562,42.5219955444336,,,,,,,,,,,,,,,,
,3949064461.471,6.0003650188446,116827.57421875,0.00189684379723435,2.99434295802267E-6,1,0.999253354069792,40.0298881530762,1.99856187289255,17.8900007158518,0.0209115109228246,0.00389427818804326,0.25,1.45482717920729E-5,0.00190205336676628,2.66839142417445E-5,6.00028419494629,6.00028419494629,116772.609375,116882.5390625,56.1795498197175,20.6550770352063,4.50435161590576,0,0,0,40,5.93877363204956,1,6,1,2.24609375,43.0107536315918,,,,,,,,,,,,,,,,
,3949064526.404,6.00031280517578,123325.45703125,0.00199491977535787,2.46816532798771E-6,1,0.999253354069792,40.0298881530762,1.99868601231449,17.8900007158518,0.0220024064209745,0.00408394549852106,0.25,1.44673837055319E-5,0.00200095619165521,2.68856911342183E-5,6.00033140182495,6.00033140182495,123275.4375,123375.4765625,55.923957293929,20.6438789266019,4.50383186340332,0,0,0,40,5.93401050567627,1,6,1,2.24746704101562,43.0107536315918,,,,,,,,,,,,,,,,
,3949064591.36,6.00032615661621,129822.62890625,0.00209839665409056,2.43337513360087E-6,1,0.999253354069792,40.0298881530762,1.99870092073856,17.8900007158518,0.0231455222115775,0.00431990230620849,0.25,1.76665682012198E-5,0.00210525916543695,3.03780130249362E-5,6.0003457069397,6.0003457069397,129767.578125,129877.6796875,55.7371480778328,20.645691721196,4.50384855270386,0,0,0,40,5.92960786819458,1,6,1,2.22900390625,43.0107536315918,,,,,,,,,,,,,,,,
,3949064656.319,6.00006055831909,136326.4609375,0.00219236412619716,1.66673822839449E-6,1,0.999253354069792,40.0298881530762,1.99861685341388,17.8900007158518,0.0241901668911452,0.00449370483731908,0.25,1.69797244816267E-5,0.00220004474895439,2.98844330369673E-5,6.00009155273437,6.00009155273437,136271.4375,136381.484375,56.4265444317944,20.646254669188,4.50326728820801,0,0,0,40,5.92572164535522,1,6,1,2.24502563476562,43.49951171875,,,,,,,,,,,,,,,,
,3949064695.2885,5.99976825714111,140007.359375,0.00224740740407962,2.00986205346305E-6,1,0.999253354069792,40.0298881530762,1.99865811939682,17.8900007158518,0.024795410715925,0.00463833573093573,0.25,2.04417639092977E-5,0.0022555336134233,3.34692329320312E-5,5.99988508224487,5.99988508224487,140000.015625,140014.703125,56.4296709458714,20.6501401681877,4.50256395339966,0,0,0,40,5.92348384857178,1,4,1,2.25662231445313,43.0107536315918,,,,,,,,,,,,,,,,