File: PPMS_Data_and_Plotting/Data/NbTi/0008.csv
[Header]
; VSM Data File (default extension .dat)
; Copyright (c) 2003-2013, Quantum Design, Inc. All rights reserved.
TITLE,
FILEOPENTIME,3949066880.3983,02/18/2025,7:04 pm
BYAPP,VSM,1.0,1.0
INFO,DYNACOOL VSM Option Release 1.4.10 Build 1,APPNAME
INFO,Quantum Design Linear Motor Servo Controller,MOTOR_MODULE_NAME
INFO,3101-100 L2,MOTOR_HW_VERSION
INFO,MMC884,MOTOR_SERIAL_NUMBER
INFO,SRV No X-over 01.03.11,MOTOR_SOFTWARE_VERSION
INFO,Quantum Design VSM Detection Module,VSM_MODULE_NAME
INFO,3101-150 F0,VSM_HW_VERSION
INFO,VSM641,VSM_SERIAL_NUMBER
INFO,VSM No X-over 01.02.05 May 20 2008 13:51:47,VSM_SOFTWARE_VERSION
INFO,VPA645,PREAMP_SERIAL_NUMBER
INFO,740,COIL_SERIAL_NUMBER
INFO,0,MOMENT_UNITS
INFO,NbTi,SAMPLE_MATERIAL
INFO,,SAMPLE_COMMENT
INFO,4.3,SAMPLE_MASS
INFO,,SAMPLE_VOLUME
INFO,,SAMPLE_MOLECULAR_WEIGHT
INFO,,SAMPLE_SIZE
INFO,,SAMPLE_SHAPE
DATATYPE,COMMENT,1
DATATYPE,TIME,2
STARTUPAXIS,X,2
STARTUPAXIS,Y1,5
[Data]
Comment,Time Stamp (sec),Temperature (K),Magnetic Field (Oe),Moment (emu),M. Std. Err. (emu),Transport Action,Averaging Time (sec),Frequency (Hz),Peak Amplitude (mm),Center Position (mm),Coil Signal' (mV),Coil Signal" (mV),Range (mV),M. Quad. Signal (emu),M. Raw' (emu),M. Raw" (emu),Min. Temperature (K),Max. Temperature (K),Min. Field (Oe),Max. Field (Oe),Mass (grams),Motor Lag (deg),Pressure (Torr),VSM Status (code),Motor Status (code),Measure Status (code),Measure Count,System Temp. (K),Temp. Status (code),Field Status (code),Chamber Status (code),Motor Current (amps),Motor Heatsink Temp. (C),Map 01,Map 02,Map 03,Map 04,Map 05,Map 06,Map 07,Map 08,Map 09,Map 10,Map 11,Map 12,Map 13,Map 14,Map 15,Map 16
sample offset = 33.45 mm,3949069039.185,8.00202655792236,-0.090057797729969,6.78997424253688E-5,2.20216603118806E-7,1,0.999253354069792,40.0298881530762,1.99872705640298,17.8900007158518,0.000742824312397199,0.000130743778854678,0.25,-4.83835469079619E-8,6.74450725930464E-5,2.78898335396578E-7,8.00202655792236,8.00202655792236,-0.090057797729969,-0.090057797729969,55.0923045494674,20.6225655734457,6.49063587188721,0,0,0,40,8.02154636383057,1,4,1,2.24563598632813,29.8142719268799,,,,,,,,,,,,,,,,
,3949069112.922,7.99967527389526,6545.79833984375,-0.00828911482540153,1.23092602127845E-5,1,0.999253354069792,40.0298881530762,1.99888886921435,17.8900007158518,-0.0906426797527432,-0.0164350649772233,2.5,-3.32527088705056E-5,-0.00823659380875099,-7.64296552684189E-5,7.99965190887451,7.99965190887451,6490.54150390625,6601.05517578125,55.2673893377751,20.6342761113477,6.50446033477783,0,0,0,40,8.02077198028564,1,6,1,2.25830078125,35.6793746948242,,,,,,,,,,,,,,,,
,3949069178.858,7.99989795684814,13139.0073242187,-0.000295791506700858,9.66440281978374E-6,1,0.999253354069792,40.0298881530762,1.99892364501489,17.8900007158518,-0.00330569157232211,-0.000196246655293654,0.25,3.46298021708793E-5,-0.000294277941161909,3.27379009062693E-5,7.99994421005249,7.99994421005249,13084.1953125,13193.8193359375,56.2655289568329,20.6378440560407,6.50805330276489,0,0,0,40,8.02408218383789,1,6,1,2.24365234375,37.6344108581543,,,,,,,,,,,,,,,,
,3949069243.822,7.99970197677612,19636.365234375,0.00037628347722234,2.59160613352051E-6,1,0.999253354069792,40.0298881530762,1.99902171446616,17.8900007158518,0.00411542397521941,0.000770696435494904,0.25,3.32531827970703E-6,0.000374310961904707,5.6287950330245E-6,7.99969625473022,7.99969625473022,19586.38671875,19686.34375,56.1693886489675,20.6375229203272,6.50827169418335,0,0,0,40,8.02458953857422,1,6,1,2.24349975585938,38.6119270324707,,,,,,,,,,,,,,,,
,3949069309.7735,8.00008678436279,26239.7880859375,0.000491163504545714,3.54279565235396E-6,1,0.999253354069792,40.0298881530762,1.99880775153092,17.8999993950129,0.00537189134383777,0.00102333952201936,0.25,5.67803896345269E-6,0.000488902801948043,8.87655414679847E-6,8.00008201599121,8.00008201599121,26189.748046875,26289.828125,56.0693401985059,20.6319312069489,6.50780010223389,0,0,0,40,8.0248441696167,1,6,1,2.24807739257813,39.1006851196289,,,,,,,,,,,,,,,,
,3949069374.7235,8.0005989074707,32733.4443359375,0.00060019070557787,3.58412637010319E-6,1,0.999253354069792,40.0298881530762,1.99865838553132,17.8900007158518,0.00657784597986854,0.00119806215484203,0.25,1.89799172320209E-6,0.000597868037345093,6.02175431466738E-6,8.00054836273193,8.00054836273193,32683.353515625,32783.53515625,56.5992843345444,20.6269687859114,6.50640058517456,0,0,0,40,8.02259063720703,1,6,1,2.24441528320313,40.5669593811035,,,,,,,,,,,,,,,,
,3949069439.659,8.0002589225769,39236.751953125,0.00070150921166901,4.84334785294313E-6,1,0.999253354069792,40.0298881530762,1.99887871887548,17.8900007158518,0.00768648194192641,0.00144555893425067,0.25,6.07234725162541E-6,0.000699249995697132,1.10521664629119E-5,8.00027847290039,8.00027847290039,39186.70703125,39286.796875,56.2373903301406,20.6400671125449,6.50595140457153,0,0,0,40,8.01861000061035,1,6,1,2.24212646484375,40.0782012939453,,,,,,,,,,,,,,,,
,3949069504.592,8.00054693222046,45729.193359375,0.000810305267678955,6.79063457369766E-6,1,0.999253354069792,40.0298881530762,1.9989032875795,17.8900007158518,0.00889265459733169,0.00162676086161242,0.25,2.86067522996492E-6,0.000808277051960049,8.76462164792686E-6,8.00064945220947,8.00064945220947,45679.25,45779.13671875,56.3819916061983,20.6378264924957,6.50546836853027,0,0,0,40,8.01328277587891,1,6,1,2.24380493164062,40.0782012939453,,,,,,,,,,,,,,,,
,3949069569.5565,8.00172185897827,52232.978515625,0.000912244454574365,5.24303063279752E-6,1,0.999253354069792,40.0298881530762,1.99883437253305,17.8900007158518,0.00999297021833693,0.00197050986297024,0.25,1.56865002329912E-5,0.000910473668036544,2.24043917383906E-5,8.00176906585693,8.00176906585693,52182.97265625,52282.984375,56.9181887703906,20.6405021118043,6.5042986869812,0,0,0,40,8.00693893432617,1,6,1,2.24472045898438,41.055721282959,,,,,,,,,,,,,,,,
,3949069634.538,8.0009036064148,58735.818359375,0.00100155489244347,5.07816018872386E-6,1,0.999253354069792,40.0298881530762,1.99881972662958,17.8999993950129,0.0110010821431592,0.00203720868854965,0.25,5.5839793679915E-6,0.00100033184697398,1.30239807550174E-5,8.00093364715576,8.00093364715576,58685.80078125,58785.8359375,56.3937160339867,20.6378267118319,6.5035457611084,0,0,0,40,7.9996075630188,1,6,1,2.24639892578125,41.055721282959,,,,,,,,,,,,,,,,
,3949069699.4675,8.00114250183105,65229.060546875,0.00110849460541785,6.24439670463254E-6,1,0.999253354069792,40.0298881530762,1.99874235693333,17.8999993950129,0.0121849922450198,0.00224238866264497,0.25,4.96180658707192E-6,0.00110781302730652,1.31870429620798E-5,8.001145362854,8.001145362854,65178.953125,65279.16796875,56.2037803038136,20.6434456951978,6.50240659713745,0,0,0,40,7.9921441078186,1,6,1,2.24716186523438,41.5444793701172,,,,,,,,,,,,,,,,
,3949069764.401,8.00108337402344,71722.03125,0.00119927857304642,6.49728692441E-6,1,0.999253354069792,40.0298881530762,1.99866343445722,17.8900007158518,0.0131723518637471,0.00252459875947259,0.25,1.42788205129269E-5,0.00119914621901589,2.31142631487036E-5,8.00123691558838,8.00123691558838,71671.953125,71772.109375,56.1693886489675,20.6338613624955,6.50141000747681,0,0,0,40,7.98444509506226,1,6,1,2.24349975585938,41.5444793701172,,,,,,,,,,,,,,,,
,3949069831.3455,8.00131416320801,78426.0390625,0.00130716957270639,5.24588293807857E-6,1,0.999253354069792,40.0298881530762,1.99858823312397,17.8900007158518,0.0143619323858556,0.00276768163286282,0.25,1.70150250417327E-5,0.00130771485320404,2.65325003069641E-5,8.00136947631836,8.00136947631836,78376.03125,78476.046875,56.0771564836982,20.6339062893798,6.50098657608032,0,0,0,40,7.97606420516968,1,6,1,2.24288940429687,41.055721282959,,,,,,,,,,,,,,,,
,3949069896.264,8.00091409683228,84918.47265625,0.00143294677143718,4.77712219842378E-6,1,0.999253354069792,40.0298881530762,1.99865705075468,17.8900007158518,0.0157571592031123,0.00300601602361796,0.25,1.61465026057993E-5,0.0014342470521968,2.64175729614587E-5,8.00091361999512,8.00091361999512,84868.4765625,84968.46875,55.7011931659482,20.6296122712187,6.49961042404175,0,0,0,40,7.96720218658447,1,6,1,2.23068237304687,45.4545478820801,,,,,,,,,,,,,,,,
,3949069961.254,8.00101661682129,91427.46875,0.00151399473375078,3.36183355399211E-6,1,0.999253354069792,40.0298881530762,1.99865017005337,17.8900007158518,0.0166769819543517,0.00305808622918994,0.25,6.44853872991848E-6,0.00151610805861697,1.70834846717553E-5,8.00103092193603,8.00103092193603,91382.4375,91472.5,55.6433526555251,20.6369824988827,6.4994797706604,0,0,0,40,7.95969820022583,1,6,1,2.24288940429687,41.5444793701172,,,,,,,,,,,,,,,,
,3949070027.205,8.00116682052612,98025.125,0.0016103868370707,3.29153500003161E-6,1,0.999253354069792,40.0298881530762,1.99860812264419,17.8900007158518,0.0177404016848343,0.00328296423548776,0.25,9.73637377341015E-6,0.00161326821207059,2.08064303967474E-5,8.00101852416992,8.00101852416992,97975.1015625,98075.1484375,56.2663105853521,20.6310660188216,6.49896335601807,0,0,0,40,7.95162153244019,1,6,1,2.24273681640625,41.5444793701172,,,,,,,,,,,,,,,,
,3949070092.146,8.00062274932861,104518.19140625,0.00171274253978447,2.88269905534073E-6,1,0.999253354069792,40.0298881530762,1.99868602955261,17.8999993950129,0.0188788839348512,0.00347412001770008,0.25,8.92469459865157E-6,0.00171643993161125,2.04198850166338E-5,8.00063705444336,8.00063705444336,104468.171875,104568.2109375,55.5714428317559,20.6363086975798,6.49737691879272,0,0,0,40,7.94300222396851,1,6,1,2.259521484375,42.0332374572754,,,,,,,,,,,,,,,,
,3949070157.1035,8.0011715888977,111021.6953125,0.0018108364994447,2.77986373505306E-6,1,0.999253354069792,40.0298881530762,1.99857977803542,17.8900007158518,0.0199767669194089,0.00361216119799166,0.25,4.13202466196243E-6,0.00181538069250754,1.59683041307181E-5,8.00124168395996,8.00124168395996,110971.7421875,111071.6484375,55.9520959206213,20.6344942055509,6.49688386917114,0,0,0,40,7.93442726135254,1,6,1,2.22976684570313,40.5669593811035,,,,,,,,,,,,,,,,
,3949070222.082,8.00120449066162,117525.109375,0.00190405826481307,2.63227532089906E-6,1,0.999253354069792,40.0298881530762,1.99855916296256,17.8900007158518,0.0209954601575257,0.0038877527301264,0.25,1.26966460586993E-5,0.00190935617759939,2.48380111586771E-5,8.00125217437744,8.00125217437744,117475.1171875,117575.1015625,56.1514111930252,20.6383357681347,6.49564933776855,0,0,0,40,7.9262752532959,1,6,1,2.26150512695313,42.5219955444336,,,,,,,,,,,,,,,,
,3949070287.0095,8.00145387649536,124022.109375,0.0020040503042642,2.69876488573217E-6,1,0.999253354069792,40.0298881530762,1.99857081173513,17.8900007158518,0.0220968502979929,0.00413417457295022,0.25,1.74373737461151E-5,0.00201014999863885,2.98845921060274E-5,8.00124549865723,8.00124549865723,123977.046875,124067.171875,55.7027564229867,20.6325313929081,6.49493360519409,0,0,0,40,7.92016839981079,1,6,1,2.2576904296875,42.5219955444336,,,,,,,,,,,,,,,,
,3949070351.956,8.00047445297241,130520.3515625,0.00209961456552405,2.33848709706586E-6,1,0.999253354069792,40.0298881530762,1.99857247385417,17.8999993950129,0.0231597782031451,0.00431282647217284,0.25,1.6862686824027E-5,0.0021065368617629,2.95404154355619E-5,8.00059700012207,8.00059700012207,130470.3125,130570.390625,55.534706291352,20.6334629117103,6.49430322647095,0,0,0,40,7.91254901885986,1,6,1,2.242431640625,42.0332374572754,,,,,,,,,,,,,,,,
,3949070416.887,8.00034999847412,137013.7421875,0.00219652770081172,2.26196321098888E-6,1,0.999253354069792,40.0298881530762,1.99840147824081,17.8900007158518,0.0242278667790568,0.00453721492924873,0.25,2.02501446267951E-5,0.00220425135652505,3.31519505896523E-5,8.00035572052002,8.00035572052002,136963.671875,137063.8125,55.497188122429,20.6282111856799,6.49232578277588,0,0,0,40,7.90699529647827,1,6,1,2.26181030273438,42.5219955444336,,,,,,,,,,,,,,,,
,3949070491.816,7.99931669235229,136719.7890625,0.00219217986475374,2.20059177482254E-6,1,0.999253354069792,40.0298881530762,1.99853612179783,17.8900007158518,0.0241884022980366,0.00448807285698565,0.25,1.65361273203869E-5,0.00219988824544498,2.94158912342178E-5,7.99927568435669,7.99927568435669,136665.53125,136774.046875,55.0532231235058,20.6400143159598,6.49138975143433,0,0,0,40,7.90602970123291,1,6,1,2.22885131835938,42.5219955444336,,,,,,,,,,,,,,,,
,3949070556.825,7.99902009963989,130305.4453125,0.00210057099257826,2.47467055421541E-6,1,0.999253354069792,40.0298881530762,1.99856006655261,17.8900007158518,0.0231673191993646,0.00432985974767104,0.25,1.82278738407804E-5,0.00210747175832078,3.0927720168275E-5,7.99909210205078,7.99909210205078,130260.890625,130350,55.547993976179,20.6472552200962,6.49261951446533,0,0,0,40,7.91167306900024,1,6,1,2.24945068359375,42.0332374572754,,,,,,,,,,,,,,,,
,3949070621.727,7.99887919425964,123896.96875,0.0020004280079267,2.5361561253802E-6,1,0.999253354069792,40.0298881530762,1.99857364717054,17.8900007158518,0.0220550045409177,0.00413693594334293,0.25,1.83272076862893E-5,0.0020065009047746,3.07613750218236E-5,7.99885177612305,7.99885177612305,123847.734375,123946.203125,55.9888324610252,20.6459526252026,6.49349594116211,0,0,0,40,7.91793727874756,1,6,1,2.2271728515625,43.0107536315918,,,,,,,,,,,,,,,,
,3949070686.681,7.99883961677551,117494.22265625,0.00190192152762117,2.71047053353992E-6,1,0.999253354069792,40.0298881530762,1.9986146846531,17.8900007158518,0.0209715093540205,0.00388861245859391,0.25,1.3145081111349E-5,0.00190720796032718,2.5275679240288E-5,7.99891710281372,7.99891710281372,117444.7109375,117543.734375,56.0247873729098,20.6344460372769,6.49477529525757,0,0,0,40,7.92495632171631,1,6,1,2.2454833984375,42.5219955444336,,,,,,,,,,,,,,,,
,3949070751.634,7.99867630004883,111080.20703125,0.00181477510911262,3.01603605858725E-6,1,0.999253354069792,40.0298881530762,1.99830021427,17.8900007158518,0.0199934477570529,0.00375498172761887,0.25,1.64171358191169E-5,0.00181925418810136,2.83073924471077E-5,7.99860286712647,7.99860286712647,111030.7265625,111129.6875,55.2525383959097,20.6349432320557,6.49547100067139,0,0,0,40,7.93240404129028,1,6,1,2.25021362304687,42.5219955444336,,,,,,,,,,,,,,,,
,3949070817.5865,7.99900269508362,104573.61328125,0.00171503617484669,3.01545674021979E-6,1,0.999253354069792,40.0298881530762,1.99854095090924,17.8900007158518,0.0188916919022447,0.00354139778462978,0.25,1.46365165336837E-5,0.0017187054160946,2.61572075723987E-5,7.99907159805298,7.99907159805298,104519.4296875,104627.796875,55.9528775491405,20.6412641094156,6.49622917175293,0,0,0,40,7.94061756134033,1,6,1,2.24365234375,43.0107536315918,,,,,,,,,,,,,,,,
,3949070882.5845,7.99850606918335,98159.60546875,0.00162327153756884,4.06988443831285E-6,1,0.999253354069792,40.0298881530762,1.99859673218547,17.8999993950129,0.0178797012172139,0.00332425628631134,0.25,1.11813770830624E-5,0.00162617939407399,2.23372597196074E-5,7.9984016418457,7.9984016418457,98105.25,98213.9609375,55.9372449787559,20.6354067117836,6.49717378616333,0,0,0,40,7.94938659667969,1,6,1,2.239990234375,42.5219955444336,,,,,,,,,,,,,,,,
,3949070947.526,7.99899435043335,91751.52734375,0.00152705679048328,4.09227637997502E-6,1,0.999253354069792,40.0298881530762,1.99857784997616,17.8999993950129,0.0168055745104612,0.00316858080941507,0.25,1.41494953615003E-5,0.00152916653306206,2.48762196171132E-5,7.99890613555908,7.99890613555908,91702.046875,91801.0078125,55.5472123476597,20.6357438543423,6.49767827987671,0,0,0,40,7.95708751678467,1,6,1,2.24853515625,42.5219955444336,,,,,,,,,,,,,,,,
,3949071012.4555,7.99859523773193,85342.22265625,0.00142193190588054,4.45162606524035E-6,1,0.999253354069792,40.0298881530762,1.99863193960236,17.8900007158518,0.0156606563167793,0.00284705537118131,0.25,3.70058382389712E-6,0.00142335262427362,1.3868622515397E-5,7.9985818862915,7.9985818862915,85287.8828125,85396.5625,55.4878085801982,20.6410922379175,6.49731397628784,0,0,0,40,7.96464014053345,1,6,1,2.22854614257813,42.5219955444336,,,,,,,,,,,,,,,,
,3949071077.394,7.99850964546204,78935.56640625,0.00131786996427494,6.03363965494587E-6,1,0.999253354069792,40.0298881530762,1.99859111406152,17.8900007158518,0.0144761498216999,0.00281238144166051,0.25,1.9157069589974E-5,0.00131845648649559,2.8743212852278E-5,7.99851226806641,7.99851226806641,78886.1171875,78985.015625,55.5941100588136,20.6480665805557,6.49797344207764,0,0,0,40,7.97319412231445,1,6,1,2.249755859375,42.0332374572754,,,,,,,,,,,,,,,,
,3949071143.3205,7.99922895431519,72408.28125,0.00122065444867333,5.90606119597927E-6,1,0.999253354069792,40.0298881530762,1.99866824718138,17.8900007158518,0.0133811359417637,0.00271913852169044,0.25,2.81149452232387E-5,0.00122048913054878,3.70993944315753E-5,7.99926948547363,7.99926948547363,72358.796875,72457.765625,56.2514596434867,20.6443300773516,6.49814128875732,0,0,0,40,7.98189115524292,1,6,1,2.24609375,42.0332374572754,,,,,,,,,,,,,,,,
,3949071208.3115,7.9985716342926,65954.65234375,0.00112737628059165,7.26315134444693E-6,1,0.999253354069792,40.0298881530762,1.99862586648629,17.8999993950129,0.0123949276319147,0.00226797008347658,0.25,3.90304915311022E-6,0.00112676426006346,1.22645754998454E-5,7.99845552444458,7.99845552444458,65910.1875,65999.1171875,55.7582520478521,20.6463782567645,6.49866151809692,0,0,0,40,7.99046325683594,1,6,1,2.24456787109375,42.0332374572754,,,,,,,,,,,,,,,,
,3949071273.2445,7.99853730201721,59518,0.00102475068491525,6.42248205050566E-6,1,0.999253354069792,40.0298881530762,1.9986846192686,17.8999993950129,0.011255299829686,0.00208818637929711,0.25,6.05613038760129E-6,0.00102357259903762,1.36696063003386E-5,7.99864768981934,7.99864768981934,59463.578125,59572.421875,55.9505326635828,20.6396433045475,6.49891519546509,0,0,0,40,7.99799346923828,1,6,1,2.24365234375,41.055721282959,,,,,,,,,,,,,,,,
,3949071338.186,7.99948573112488,53073.998046875,0.000924803661147562,5.3542320272453E-6,1,0.999253354069792,40.0298881530762,1.99875537518068,17.8900007158518,0.010142557188296,0.00193340476441149,0.25,1.00413709239172E-5,0.000923129279999916,1.68709697023238E-5,7.9994649887085,7.9994649887085,53024.39453125,53123.6015625,56.1858028478713,20.6439806669643,6.4991660118103,0,0,0,40,8.0050573348999,1,6,1,2.24594116210938,42.0332374572754,,,,,,,,,,,,,,,,
,3949071404.1425,7.99920177459717,46531.333984375,0.000823224197066163,5.76836227264555E-6,1,0.999253354069792,40.0298881530762,1.99873342270891,17.8900007158518,0.0090594615057359,0.00151325071897798,0.25,-9.80518564179685E-6,0.000821324926751878,-3.76329522622339E-6,7.99926614761353,7.99926614761353,46486.89453125,46575.7734375,56.3374387806021,20.6400128264403,6.49976015090942,0,0,0,40,8.01104736328125,1,6,1,2.22930908203125,41.5444793701172,,,,,,,,,,,,,,,,
,3949071470.0675,7.99916219711304,39989.0078125,0.000715305868566243,4.49959394422023E-6,1,0.999253354069792,40.0298881530762,1.99878497732971,17.8999993950129,0.00782629567248333,0.00153898411650201,0.25,1.20931722011392E-5,0.000713016810345992,1.71698899052565E-5,7.99914121627808,7.99914121627808,39939.3359375,40038.6796875,55.8434495564482,20.6424431565879,6.49977159500122,0,0,0,40,8.01780986785889,1,6,1,2.24594116210938,41.5444793701172,,,,,,,,,,,,,,,,
,3949071535.053,7.99911212921143,33527.587890625,0.000613433138997245,4.2162072871407E-6,1,0.999253354069792,40.0298881530762,1.99852772862051,17.8900007158518,0.00671949551655734,0.00124483119968162,0.25,3.77132789762867E-6,0.000611098028956413,8.00006085942906E-6,7.99914503097534,7.99914503097534,33477.83984375,33577.3359375,55.9395898643136,20.6384834629961,6.49978590011597,0,0,0,40,8.02123832702637,1,6,1,2.244873046875,41.5444793701172,,,,,,,,,,,,,,,,
,3949071599.9885,7.99985456466675,27069.6162109375,0.000504400691021542,3.0112073415511E-6,1,0.999253354069792,40.0298881530762,1.99895043950672,17.8900007158518,0.00551788390049826,0.00104900881555583,0.25,5.61963653545698E-6,0.000502123357994857,8.92840730691757E-6,7.999831199646,7.999831199646,27019.794921875,27119.4375,56.2498963864483,20.6482276021885,6.49948740005493,0,0,0,40,8.02536487579346,1,6,1,2.24655151367187,41.5444793701172,,,,,,,,,,,,,,,,
,3949071664.9435,8.00076198577881,20601.880859375,0.000396494125421671,2.12188776285892E-6,1,0.999253354069792,40.0298881530762,1.99883509097217,17.8900007158518,0.00434193244196856,0.000781572929706643,0.25,6.92923827017856E-7,0.000394470190807416,3.15944603457722E-6,8.00080966949463,8.00080966949463,20552.107421875,20651.654296875,55.8254721005059,20.6482813145893,6.49927282333374,0,0,0,40,8.02585601806641,1,6,1,2.2308349609375,42.0332374572754,,,,,,,,,,,,,,,,
,3949071729.8925,7.99949264526367,14118.4228515625,0.00045371763352197,7.64727129020398E-6,1,0.999253354069792,40.0298881530762,1.99885118184155,17.8900007158518,0.0049043516218432,0.00123827089036866,0.25,3.24522997091883E-5,0.000450943374526446,3.48939116495172E-5,7.9994626045227,7.9994626045227,14073.51953125,14163.326171875,55.9450612639482,20.6459585389038,6.49888849258423,0,0,0,40,8.02539825439453,1,6,1,2.2314453125,42.5219955444336,,,,,,,,,,,,,,,,
,3949071795.875,8.0005784034729,7523.64038085938,0.0057683510307592,9.72281279613205E-6,1,0.999253354069792,40.0298881530762,1.99867123130908,17.8900007158518,0.0629783935682488,0.0119863876489775,0.25,7.2958907759439E-5,0.00573195118441666,0.000103109542960009,8.00048828125,8.00048828125,7478.65380859375,7568.626953125,56.0544892566406,20.647862105488,6.49792003631592,0,0,0,40,8.02336025238037,1,6,1,2.24273681640625,41.5444793701172,,,,,,,,,,,,,,,,
,3949071861.793,8.00101089477539,934.297515869141,0.01479312676228,6.55553782220492E-6,1,0.999253354069792,40.0298881530762,1.99870224530464,17.8900007158518,0.161607003699207,0.0298096133389024,2.5,0.000109878814539677,0.0146940208095629,0.000181006261811971,8.00089550018311,8.00089550018311,889.354797363281,979.240234375,56.7313795542945,20.651374387782,6.49808168411255,0,0,0,40,8.01958847045898,1,6,1,2.25967407226562,41.5444793701172,,,,,,,,,,,,,,,,
,3949071926.766,7.99917721748352,-5563.61669921875,0.0105483746621314,1.30497096541321E-5,1,0.999253354069792,40.0298881530762,1.9987684553125,17.8900007158518,0.115308764762353,0.0210506502328474,2.5,5.57485023915039E-5,0.010480738140808,0.00010985400629635,7.9991626739502,7.9991626739502,-5618.6689453125,-5508.564453125,56.0404199432944,20.6411956164627,6.49552059173584,0,0,0,40,8.02086734771729,1,6,1,2.24685668945313,41.5444793701172,,,,,,,,,,,,,,,,
,3949071992.681,7.99995756149292,-12162.4453125,0.000760873920932589,7.79560949231458E-6,1,0.999253354069792,40.0298881530762,1.99892936394312,17.8900007158518,0.00839142913158125,0.00113052349076536,0.25,-3.18634940600595E-5,0.000756587087696944,-2.73792913757391E-5,7.9999852180481,7.9999852180481,-12212.447265625,-12112.443359375,55.8520474701598,20.6460817972218,6.49285840988159,0,0,0,40,8.02472686767578,1,6,1,2.24533081054687,40.5669593811035,,,,,,,,,,,,,,,,
,3949072057.674,8.00018382072449,-18665.3046875,-0.00035801777724403,1.94335834493242E-6,1,0.999253354069792,40.0298881530762,1.99875619957786,17.8900007158518,-0.00391519966002981,-0.000730832680433841,0.25,-2.97747983166986E-6,-0.000356108942822305,-5.14695096444154E-6,7.99997186660767,7.99997186660767,-18715.255859375,-18615.353515625,55.9614754628521,20.6488212959572,6.49136590957642,0,0,0,40,8.02643394470215,1,6,1,2.247314453125,41.5444793701172,,,,,,,,,,,,,,,,
,3949072122.6385,8.00101709365845,-25163.7275390625,-0.000474130704791035,2.41715349756386E-6,1,0.999253354069792,40.0298881530762,1.99883862919898,17.8900007158518,-0.00519268540842615,-0.000945288694127056,0.25,-1.63402971783178E-6,-0.000471921472917806,-4.7104646258404E-6,8.00106811523437,8.00106811523437,-25208.76953125,-25118.685546875,56.3874630058329,20.6438502235878,6.49087047576904,0,0,0,40,8.02513313293457,1,6,1,2.24441528320313,41.5444793701172,,,,,,,,,,,,,,,,
,3949072187.557,8.00097036361694,-31661.849609375,-0.000588195011881716,4.00337620829456E-6,1,0.999253354069792,40.0298881530762,1.99878321747255,17.8999993950129,-0.00644620448270015,-0.00117305814299092,0.25,-1.79683290343172E-6,-0.000585852736957141,-5.81035175042658E-6,8.00097179412842,8.00097179412842,-31711.970703125,-31611.728515625,56.2686554709098,20.6523200083474,6.49082899093628,0,0,0,40,8.02253532409668,1,6,1,2.2442626953125,41.5444793701172,,,,,,,,,,,,,,,,
,3949072252.486,8.00110721588135,-38155.603515625,-0.000686852499952371,5.32254507324606E-6,1,0.999253354069792,40.0298881530762,1.99891928874697,17.8900007158518,-0.00750348190860231,-0.00153631723186801,0.25,-1.70048584789658E-5,-0.000684483609046005,-2.18195893413387E-5,8.00106048583984,8.00106048583984,-38205.74609375,-38105.4609375,55.7402745919097,20.6480674697667,6.49116659164429,0,0,0,40,8.01990509033203,1,6,1,2.22763061523438,41.5444793701172,,,,,,,,,,,,,,,,
,3949072317.4275,8.00085926055908,-44648.83203125,-0.000795893299636606,5.74187852191648E-6,1,0.999253354069792,40.0298881530762,1.99893259769694,17.8999993950129,-0.00873946513298454,-0.00156510759789481,0.25,1.37863248508871E-7,-0.000793833221267411,-5.64996526569791E-6,8.000807762146,8.000807762146,-44698.859375,-44598.8046875,56.3053920113137,20.651221030532,6.49108695983887,0,0,0,40,8.01414489746094,1,6,1,2.25128173828125,41.5444793701172,,,,,,,,,,,,,,,,
,3949072382.409,8.00099563598633,-51150.615234375,-0.000882479648543673,5.64491593993606E-6,1,0.999253354069792,40.0298881530762,1.99891080823282,17.8900007158518,-0.00968702449986372,-0.00179008540043948,0.25,-4.62795855547856E-6,-0.000880748859024292,-1.11344498533937E-5,8.00106716156006,8.00106716156006,-51200.58984375,-51100.640625,57.2707032325638,20.6566746450427,6.49113512039185,0,0,0,40,8.00753498077393,1,6,1,2.24777221679687,41.055721282959,,,,,,,,,,,,,,,,
,3949072447.3675,8.00100564956665,-57653.744140625,-0.000993601255609289,6.60782615008331E-6,1,0.999253354069792,40.0298881530762,1.99882937238271,17.8999993950129,-0.0108990604730212,-0.00209652415544206,0.25,-1.24266172218285E-5,-0.000992234184457806,-1.97953876383745E-5,8.00105667114258,8.00105667114258,-57703.7265625,-57603.76171875,56.4093486043714,20.6522066016015,6.49078464508057,0,0,0,40,8.00144004821777,1,6,1,2.24395751953125,41.055721282959,,,,,,,,,,,,,,,,
,3949072512.303,8.00107908248901,-64151.29296875,-0.00109175068017265,5.92811411687136E-6,1,0.999253354069792,40.0298881530762,1.99885700463462,17.8900007158518,-0.0119818482625571,-0.00231199027746857,0.25,-1.42948553561938E-5,-0.00109090398478524,-2.23947173818396E-5,8.00110054016113,8.00110054016113,-64196.27734375,-64106.30859375,55.6542954547943,20.6508782855918,6.49076557159424,0,0,0,40,7.99376106262207,1,6,1,2.23388671875,41.5444793701172,,,,,,,,,,,,,,,,
,3949072577.249,8.00194454193115,-70649.1640625,-0.00120233685166478,6.14522789258688E-6,1,0.999253354069792,40.0298881530762,1.99894579242185,17.8999993950129,-0.0132338220558595,-0.00237897086790575,0.25,-4.75433881957968E-7,-0.00120219841046494,-9.34777872186645E-6,8.00198554992676,8.00198554992676,-70699.1796875,-70599.1484375,56.8462789466214,20.654229784905,6.49017381668091,0,0,0,40,7.98647117614746,1,6,1,2.24594116210938,41.055721282959,,,,,,,,,,,,,,,,
,3949072642.239,8.00095129013062,-77151.26953125,-0.00130025506038018,5.51051666863746E-6,1,0.999253354069792,40.0298881530762,1.99874792411705,17.8900007158518,-0.014327091973583,-0.00252174546539296,0.25,4.09961908544126E-6,-0.00130082270465138,-5.38338398796042E-6,8.00098705291748,8.00098705291748,-77201.2734375,-77101.265625,56.1052951103906,20.65558456212,6.49070262908936,0,0,0,40,7.97696304321289,1,6,1,2.24227905273438,41.055721282959,,,,,,,,,,,,,,,,
,3949072707.1425,8.00188541412354,-83644.2109375,-0.00139912122156181,5.87834259434986E-6,1,0.999253354069792,40.0298881530762,1.99890982843743,17.8900007158518,-0.0154090143654308,-0.00280476631620871,0.25,-3.89741038479268E-6,-0.00140034930868405,-1.39487626597997E-5,8.00189208984375,8.00189208984375,-83694.265625,-83594.15625,56.0630871703521,20.658653524308,6.49053144454956,0,0,0,40,7.969069480896,1,6,1,2.2406005859375,41.055721282959,,,,,,,,,,,,,,,,
,3949072773.1495,8.00147485733032,-90251.6875,-0.00150030446541979,4.74874491918464E-6,1,0.999253354069792,40.0298881530762,1.99882784397144,17.8900007158518,-0.0165090155170153,-0.00312711804362058,0.25,-1.51184888538551E-5,-0.00150222270671295,-2.57079112121287E-5,8.00143337249756,8.00143337249756,-90296.78125,-90206.59375,56.3374387806021,20.6500265938232,6.49071741104126,0,0,0,40,7.96016788482666,1,6,1,2.2589111328125,41.055721282959,,,,,,,,,,,,,,,,
,3949072839.064,8.00124502182007,-96844.78515625,-0.00160021729643096,4.28538079174492E-6,1,0.999253354069792,40.0298881530762,1.99892052479904,17.8900007158518,-0.0176278046629224,-0.00327341473225439,0.25,-1.06189670834878E-5,-0.00160296216015306,-2.16659761975394E-5,8.00111961364746,8.00111961364746,-96899.921875,-96789.6484375,56.3053920113137,20.658459412472,6.49024534225464,0,0,0,40,7.95299863815308,1,6,1,2.23236083984375,41.055721282959,,,,,,,,,,,,,,,,
,3949072904.0315,8.00159311294556,-103346.94140625,-0.00169686884159406,3.49741853569979E-6,1,0.999253354069792,40.0298881530762,1.99882022639862,17.8900007158518,-0.0187088135090078,-0.00341459791846121,0.25,-6.3136595741178E-6,-0.00170044186598438,-1.77472048240288E-5,8.00162982940674,8.00162982940674,-103391.90625,-103301.9765625,55.9974303747367,20.6575366834093,6.49000930786133,0,0,0,40,7.94419527053833,1,6,1,2.24441528320313,40.5669593811035,,,,,,,,,,,,,,,,
,3949072968.969,8.00195121765137,-109844.703125,-0.00179130599965647,3.7030420762515E-6,1,0.999253354069792,40.0298881530762,1.99872454983031,17.8900007158518,-0.0197484209834682,-0.00364672274318664,0.25,-1.06892992574033E-5,-0.00179565468159491,-2.2469515439367E-5,8.00188636779785,8.00188636779785,-109894.828125,-109794.578125,55.8160925582751,20.6525960084558,6.49001502990723,0,0,0,40,7.93589353561401,1,6,1,2.24411010742187,41.055721282959,,,,,,,,,,,,,,,,
,3949073033.9205,8.00133514404297,-116337.078125,-0.0018838687141191,2.59347377036469E-6,1,0.999253354069792,40.0298881530762,1.99892817378961,17.8900007158518,-0.0207695344489531,-0.00387978432083104,0.25,-1.54710817381529E-5,-0.00188899207679737,-2.75508498970464E-5,8.00129413604736,8.00129413604736,-116387.0625,-116287.09375,55.9012900668713,20.6593992361562,6.49015760421753,0,0,0,40,7.92749547958374,1,6,1,2.23037719726562,40.5669593811035,,,,,,,,,,,,,,,,
,3949073098.849,8.00094795227051,-122835.11328125,-0.0019873867458408,2.12834427408951E-6,1,0.999253354069792,40.0298881530762,1.99886259430811,17.8900007158518,-0.0219226319199518,-0.00405790267300321,0.25,-1.3401775909712E-5,-0.00199336420572398,-2.57958230201544E-5,8.00091457366943,8.00091457366943,-122880.0859375,-122790.140625,55.6238119425444,20.6619778065647,6.48981952667236,0,0,0,40,7.92046308517456,1,6,1,2.24655151367187,40.0782012939453,,,,,,,,,,,,,,,,
,3949073163.8365,8.00150775909424,-129336.28125,-0.00208267976984171,1.90203524048385E-6,1,0.999253354069792,40.0298881530762,1.9988328078876,17.8900007158518,-0.0229686411963935,-0.00431311629141046,0.25,-1.98050751715563E-5,-0.00208943674737522,-3.24552977643045E-5,8.00146675109863,8.00146675109863,-129391.2890625,-129281.2734375,56.0982604537175,20.6642554476297,6.48957872390747,0,0,0,40,7.91414356231689,1,6,1,2.24517822265625,40.5669593811035,,,,,,,,,,,,,,,,
,3949073228.7535,8.00167894363403,-135823.1875,-0.00218270428595904,2.13018105705623E-6,1,0.999253354069792,40.0298881530762,1.99889606195847,17.8900007158518,-0.0240841148885014,-0.00448690116718025,0.25,-1.80059579167072E-5,-0.00219030458859782,-3.08860279921173E-5,8.00169467926025,8.00169467926025,-135873.25,-135773.125,55.9896140895444,20.6705432921661,6.4893102645874,0,0,0,40,7.90851497650146,1,6,1,2.24716186523438,40.0782012939453,,,,,,,,,,,,,,,,
,3949073303.671,7.9992561340332,-137912.171875,-0.0022097052923184,2.51521946498996E-6,1,0.999253354069792,40.0298881530762,1.99884306496414,17.8900007158518,-0.0243833568548264,-0.00454124729234975,0.25,-1.82264202234656E-5,-0.0022175533573083,-3.11469247703228E-5,7.99930572509766,7.99930572509766,-137961.59375,-137862.75,55.5261083776405,20.6674168074996,6.48847103118897,0,0,0,40,7.90516328811646,1,6,1,2.24502563476562,40.5669593811035,,,,,,,,,,,,,,,,
,3949073368.6225,7.99904298782349,-131483.1640625,-0.00211738200911137,2.33049659213837E-6,1,0.999253354069792,40.0298881530762,1.99878800204915,17.8900007158518,-0.0233553711177733,-0.00437009270303335,0.25,-1.88856167214764E-5,-0.00212442558844663,-3.1623699979078E-5,7.99902725219727,7.99902725219727,-131532.625,-131433.703125,55.9231756654098,20.6601911853522,6.48918151855469,0,0,0,40,7.91043138504028,1,6,1,2.24395751953125,40.0782012939453,,,,,,,,,,,,,,,,
,3949073433.6175,7.99920272827148,-125053.3515625,-0.00201663791388891,2.37995883504466E-6,1,0.999253354069792,40.0298881530762,1.99879720321314,17.8999993950129,-0.0222395630900543,-0.00415725912798748,0.25,-1.72859016602397E-5,-0.00202286053203325,-2.97556934683167E-5,7.99927043914795,7.99927043914795,-125102.8359375,-125003.8671875,55.4307496982943,20.6580721826311,6.49074029922485,0,0,0,40,7.91667604446411,1,6,1,2.24655151367187,40.0782012939453,,,,,,,,,,,,,,,,
,3949073498.581,7.99931025505066,-118633.3671875,-0.00192502390484596,2.5087833495981E-6,1,0.999253354069792,40.0298881530762,1.99867518229067,17.8999993950129,-0.0212131101613203,-0.0040191831312307,0.25,-2.08837374966531E-5,-0.001930422756006,-3.31255326676309E-5,7.99936056137085,7.99936056137085,-118682.640625,-118584.09375,55.5917651732559,20.6559141621529,6.49190616607666,0,0,0,40,7.92331314086914,1,6,1,2.24166870117187,41.055721282959,,,,,,,,,,,,,,,,
,3949073563.4835,7.99889349937439,-112208.75,-0.00182515253290687,2.85041570067751E-6,1,0.999253354069792,40.0298881530762,1.99874787243799,17.8900007158518,-0.0201103386506429,-0.00379314241073921,0.25,-1.79867068861841E-5,-0.00182974702417252,-2.98952019264504E-5,7.99886989593506,7.99886989593506,-112263.1484375,-112154.3515625,55.3908866438135,20.6596005391043,6.492919921875,0,0,0,40,7.93105792999268,1,6,1,2.23114013671875,39.5894432067871,,,,,,,,,,,,,,,,
,3949073628.4685,7.99876189231873,-105778.63671875,-0.00172780472409346,3.37467130580698E-6,1,0.999253354069792,40.0298881530762,1.99876193625696,17.8999993950129,-0.0190511984321134,-0.00348073288254317,0.25,-6.85781891978621E-6,-0.00173166425720501,-1.83937540965228E-5,7.99872350692749,7.99872350692749,-105823.140625,-105734.1328125,55.7543439052559,20.6539084537936,6.49350214004517,0,0,0,40,7.93885278701782,1,6,1,2.24533081054687,40.5669593811035,,,,,,,,,,,,,,,,
,3949073693.396,7.99901366233826,-99354.53125,-0.0016260184950729,3.08019113123856E-6,1,0.999253354069792,40.0298881530762,1.9987349420419,17.8900007158518,-0.0179187199509535,-0.0032948127028973,0.25,-8.02860700220045E-6,-0.00162906584263015,-1.91503003462637E-5,7.99884366989136,7.99884366989136,-99404.046875,-99305.015625,55.8684616690636,20.6555952076476,6.49389886856079,0,0,0,40,7.94735622406006,1,6,1,2.24395751953125,40.5669593811035,,,,,,,,,,,,,,,,
,3949073758.3805,7.99867582321167,-92933.63671875,-0.00153827390099364,5.40531944430251E-6,1,0.999253354069792,40.0298881530762,1.99870595748551,17.8900007158518,-0.0169278860417709,-0.00321147744390912,0.25,-1.60361054295216E-5,-0.00154050247430633,-2.68039010826211E-5,7.99868440628052,7.99868440628052,-92983.1640625,-92884.109375,56.0318220295829,20.6534104373263,6.49493312835693,0,0,0,40,7.95537042617798,1,6,1,2.24365234375,41.055721282959,,,,,,,,,,,,,,,,
,3949073823.2575,7.99894237518311,-86514.765625,-0.00144265324333757,4.46907190868575E-6,1,0.999253354069792,40.0298881530762,1.99874756710599,17.8999993950129,-0.0158845512985846,-0.00292513598299574,0.25,-7.07438788435025E-6,-0.00144418835247945,-1.73601991558583E-5,7.99883317947388,7.99883317947388,-86564.296875,-86465.234375,55.7222971359674,20.649385636833,6.49473905563354,0,0,0,40,7.96361112594605,1,6,1,2.24517822265625,40.5669593811035,,,,,,,,,,,,,,,,
,3949073888.2345,7.99874877929688,-80080.12109375,-0.00134128949273167,4.88160921964287E-6,1,0.999253354069792,40.0298881530762,1.99871919794382,17.8900007158518,-0.0147557803031578,-0.00275001236270694,0.25,-9.28642914856072E-6,-0.00134207660057285,-1.90121491867809E-5,7.99868965148926,7.99868965148926,-80134.484375,-80025.7578125,56.3773018350829,20.6551536323749,6.49467039108276,0,0,0,40,7.97174882888794,1,6,1,2.24166870117187,42.5219955444336,,,,,,,,,,,,,,,,
,3949073953.1845,7.99915266036987,-73635.75,-0.00124123083150588,5.97620734941177E-6,1,0.999253354069792,40.0298881530762,1.99870937109662,17.8999993950129,-0.0136503989013258,-0.00253072115408236,0.25,-7.30035315318247E-6,-0.00124134401723084,-1.64173436799523E-5,7.99908399581909,7.99908399581909,-73685.4453125,-73586.0546875,55.9810161758329,20.652739929252,6.49586248397827,0,0,0,40,7.97976875305176,1,6,1,2.244873046875,41.055721282959,,,,,,,,,,,,,,,,
,3949074018.158,7.99839496612549,-67174.0703125,-0.00114345167810611,6.48519494807385E-6,1,0.999253354069792,40.0298881530762,1.99858756087178,17.8900007158518,-0.0125483339794863,-0.00243683082450401,0.25,-1.6358834218365E-5,-0.00114286165832951,-2.48255201047329E-5,7.99830913543701,7.99830913543701,-67228.84375,-67119.296875,55.5870754021405,20.6454992111079,6.49596261978149,0,0,0,40,7.98870182037353,1,6,1,2.25677490234375,41.5444793701172,,,,,,,,,,,,,,,,
,3949074083.1095,7.99874377250671,-60712.685546875,-0.00103394881935419,6.86670348113488E-6,1,0.999253354069792,40.0298881530762,1.99870912473153,17.8900007158518,-0.0113539620221977,-0.0021282065340963,0.25,-8.02223429583896E-6,-0.00103286176746143,-1.57030979959351E-5,7.99881649017334,7.99881649017334,-60762.359375,-60663.01171875,55.7887355601021,20.640965364372,6.49584865570068,0,0,0,40,7.99555683135986,1,6,1,2.22824096679687,41.055721282959,,,,,,,,,,,,,,,,
,3949074148.0505,7.99982118606567,-54252.037109375,-0.000934362259661646,6.36452949290309E-6,1,0.999253354069792,40.0298881530762,1.99867955931595,17.8900007158518,-0.0102296831097667,-0.00205685054627797,0.25,-1.95368402342084E-5,-0.000932709755387531,-2.64324529832482E-5,7.999755859375,7.999755859375,-54296.6484375,-54207.42578125,56.2936675835252,20.6496875913488,6.49682474136353,0,0,0,40,8.00371265411377,1,6,1,2.25860595703125,41.055721282959,,,,,,,,,,,,,,,,
,3949074213.0035,7.99915099143982,-47786.029296875,-0.000835290361677396,4.89502585145774E-6,1,0.999253354069792,40.0298881530762,1.99874003132649,17.8900007158518,-0.00915913677013612,-0.00172710439799276,0.25,-7.46623666597763E-6,-0.000833343773616787,-1.35750842365149E-5,7.99921894073486,7.99921894073486,-47830.71484375,-47741.34375,56.5047072837175,20.6448292551707,6.49688196182251,0,0,0,40,8.01030349731445,1,6,1,2.24624633789062,41.055721282959,,,,,,,,,,,,,,,,
,3949074277.9455,7.99955677986145,-41326.220703125,-0.000735457693881912,4.33135723709966E-6,1,0.999253354069792,40.0298881530762,1.99883001358513,17.8999993950129,-0.00807357809717053,-0.0014403441721814,0.25,5.54387326712538E-7,-0.000733300847837735,-4.73388592713935E-6,7.9995436668396,7.9995436668396,-41375.91796875,-41276.5234375,56.0576157707175,20.6450168300895,6.49676275253296,0,0,0,40,8.01627731323242,1,6,1,2.24639892578125,41.5444793701172,,,,,,,,,,,,,,,,
,3949074343.9175,7.9988420009613,-34755.2734375,-0.000634315031802545,3.65541057081451E-6,1,0.999253354069792,40.0298881530762,1.99863397366015,17.8999993950129,-0.00694175806929485,-0.00133065601139968,0.25,-7.80875176922507E-6,-0.000631955515365249,-1.21994301463567E-5,7.99873924255371,7.99873924255371,-34800.2109375,-34710.3359375,55.9419347498713,20.6381542967569,6.49770021438599,0,0,0,40,8.02045249938965,1,6,1,2.24609375,41.055721282959,,,,,,,,,,,,,,,,
,3949074408.8605,7.99955582618713,-28277.951171875,-0.000528919713111296,3.50267945667909E-6,1,0.999253354069792,40.0298881530762,1.99867294599379,17.8999993950129,-0.00579232055773164,-0.00106503284459116,0.25,-2.67007389322714E-6,-0.000526619105668732,-6.18773489855763E-6,7.99940872192383,7.99940872192383,-28327.849609375,-28228.052734375,56.1263990804098,20.6362436275256,6.49710607528686,0,0,0,40,8.02417373657227,1,6,1,2.22885131835938,41.055721282959,,,,,,,,,,,,,,,,
,3949074474.7825,7.99951720237732,-21703.4296875,-0.00041584059115625,2.54556643463061E-6,1,0.999253354069792,40.0298881530762,1.99854096494284,17.8900007158518,-0.0045499366747742,-0.000840536041237182,0.25,-2.60167983923271E-6,-0.000413751120770161,-5.20811858213204E-6,7.99944353103638,7.99944353103638,-21753.349609375,-21653.509765625,56.5039256551983,20.6326253348857,6.49650526046753,0,0,0,40,8.02570056915283,1,6,1,2.2296142578125,41.055721282959,,,,,,,,,,,,,,,,
,3949074539.727,8.00034713745117,-15213.6430664062,-0.000347903458389493,4.92912985282088E-6,1,0.999253354069792,40.0298881530762,1.99861925066618,17.8900007158518,-0.00377389420000208,-0.00087424592203317,0.25,-1.79857549952705E-5,-0.000345848890182985,-1.99261002946382E-5,8.00036811828613,8.00036811828613,-15263.6201171875,-15163.666015625,55.7770111323136,20.644799022071,6.49634838104248,0,0,0,40,8.02535724639893,1,6,1,2.24868774414062,41.5444793701172,,,,,,,,,,,,,,,,
,3949074604.6915,8.00048685073853,-8718.50927734375,-0.00402535394181816,9.68814771326746E-6,1,0.999253354069792,40.0298881530762,1.99864134415005,17.8900007158518,-0.0439276637848158,-0.00850169848116875,0.25,-6.30353658860616E-5,-0.00400025054540521,-8.43604178743006E-5,8.00045680999756,8.00045680999756,-8768.5166015625,-8668.501953125,56.1084216244675,20.6440180823421,6.49624252319336,0,0,0,40,8.02333831787109,1,6,1,2.2296142578125,41.055721282959,,,,,,,,,,,,,,,,
,3949074670.641,8.00056934356689,-2130.16906738281,-0.0159141738692228,2.2234754209301E-6,1,0.999253354069792,40.0298881530762,1.99869969009172,17.8900007158518,-0.173849490438322,-0.0321548794030066,2.5,-0.000124785383360586,-0.015808498428633,-0.00020239035487461,8.00052261352539,8.00052261352539,-2180.208984375,-2080.12915039062,55.6410077699674,20.6371836768194,6.49463891983032,0,0,0,40,8.02016925811768,1,6,1,2.2442626953125,41.5444793701172,,,,,,,,,,,,,,,,
,3949074735.588,7.99971318244934,4362.49731445313,-0.0134400882648729,1.13222238850531E-5,1,0.999253354069792,40.0298881530762,1.99880088178952,17.8900007158518,-0.14689335612831,-0.0269114106331857,2.5,-8.05652925236935E-5,-0.0133527786427441,-0.000148288910088082,7.99974870681763,7.99974870681763,4307.48779296875,4417.5068359375,55.8043681304867,20.6379242699968,6.49363613128662,0,0,0,40,8.02078151702881,1,6,1,2.24334716796875,41.5444793701172,,,,,,,,,,,,,,,,
,3949074801.553,7.9995744228363,10966.4008789062,-0.00160794244420915,9.16646817715414E-6,1,0.999253354069792,40.0298881530762,1.99867074993298,17.8900007158518,-0.0176299117563688,-0.00294918853394095,0.25,1.59741023450392E-5,-0.00159843007645797,6.93859228952937E-6,7.99966812133789,7.99966812133789,10921.369140625,11011.4326171875,55.4573250679482,20.6382483794254,6.49049377441406,0,0,0,40,8.02242279052734,1,6,1,2.24029541015625,41.5444793701172,,,,,,,,,,,,,,,,
,3949074868.5005,7.99947929382324,17664.6455078125,0.000338916580953098,2.25811042315849E-6,1,0.999253354069792,40.0298881530762,1.99874307034234,17.8900007158518,0.00370812596711244,0.000679474878271656,0.25,1.71851360772256E-6,0.000337084256228548,3.75512364100612E-6,7.99943399429321,7.99943399429321,17614.63671875,17714.654296875,55.629283342179,20.6420266115799,6.48834466934204,0,0,0,40,8.02505874633789,1,6,1,2.24197387695313,41.5444793701172,,,,,,,,,,,,,,,,
,3949074933.4485,7.99984502792358,24162.166015625,0.000454714058428921,2.4691996819491E-6,1,0.999253354069792,40.0298881530762,1.99876259788207,17.8900007158518,0.00497797176262862,0.000914142478566845,0.25,2.29497203227927E-6,0.000452544387242815,5.21567133017062E-6,7.9997410774231,7.9997410774231,24107.1328125,24217.19921875,55.923957293929,20.6458289389978,6.48765182495117,0,0,0,40,8.02542972564697,1,6,1,2.247314453125,41.5444793701172,,,,,,,,,,,,,,,,
,3949074998.3715,8.00025510787964,30661.2119140625,0.000562466540030997,3.75351960360762E-6,1,0.999253354069792,40.0298881530762,1.99882319417232,17.8900007158518,0.0061637163281091,0.0011215712611013,0.25,1.73673997276295E-6,0.0005601674179401,5.54851463147199E-6,8.00019931793213,8.00019931793213,30611.205078125,30711.21875,55.6183405429097,20.6440424740263,6.48854446411133,0,0,0,40,8.02349472045898,1,6,1,2.22869873046875,42.5219955444336,,,,,,,,,,,,,,,,
,3949075063.373,8.00030040740967,37164.3359375,0.000669173730166592,4.19418437524256E-6,1,0.999253354069792,40.0298881530762,1.99877211870307,17.8900007158518,0.00733804187182008,0.00133472476803748,0.25,1.84300124935919E-6,0.000666899940826236,6.55900679211126E-6,8.00025463104248,8.00025463104248,37114.36328125,37214.30859375,56.0091548025252,20.641212658358,6.48834371566772,0,0,0,40,8.02044486999512,1,6,1,2.2576904296875,42.0332374572754,,,,,,,,,,,,,,,,
,3949075128.323,8.00080108642578,43657.7890625,0.000773317273670438,5.02326401019036E-6,1,0.999253354069792,40.0298881530762,1.99867919111514,17.8900007158518,0.00848649109589565,0.00153805723707086,0.25,1.49427769624655E-6,0.000771223775494285,7.09582216355542E-6,8.00076007843018,8.00076007843018,43607.76953125,43707.80859375,56.0380750577367,20.6388035921702,6.48836755752563,0,0,0,40,8.01507663726807,1,6,1,2.2589111328125,42.0332374572754,,,,,,,,,,,,,,,,
,3949075193.242,8.00155401229858,50155.720703125,0.000874099268159968,5.39657592820302E-6,1,0.999253354069792,40.0298881530762,1.99874162905637,17.8900007158518,0.00957813922082541,0.00185727005611202,0.25,1.22870363112596E-5,0.000872240351498292,1.87044990347601E-5,8.00164031982422,8.00164031982422,50100.66796875,50210.7734375,56.353852979506,20.6389601904548,6.48809814453125,0,0,0,40,8.00909328460693,1,6,1,2.2442626953125,42.0332374572754,,,,,,,,,,,,,,,,
,3949075258.17,8.00097846984863,56653.908203125,0.000971010470833865,6.10216869653411E-6,1,0.999253354069792,40.0298881530762,1.99860624016601,17.8900007158518,0.0106367156793466,0.0021174838832582,0.25,1.8428349393477E-5,0.000969534398957213,2.56159935494598E-5,8.00092124938965,8.00092124938965,56603.64453125,56704.171875,56.343691808756,20.64218049285,6.48694610595703,0,0,0,40,8.00294971466065,1,6,1,2.23159790039062,41.055721282959,,,,,,,,,,,,,,,,
,3949075323.1615,8.00109481811523,63156.908203125,0.00107410867146748,6.18408948924368E-6,1,0.999253354069792,40.0298881530762,1.99866465443562,17.8900007158518,0.0117839452223642,0.00228617236786307,0.25,1.51460612738549E-5,0.00107317077682601,2.31169656253192E-5,8.0011739730835,8.0011739730835,63106.890625,63206.92578125,56.0857543974098,20.6361651653488,6.48709106445313,0,0,0,40,7.99485397338867,1,6,1,2.26028442382813,41.5444793701172,,,,,,,,,,,,,,,,
,3949075388.1215,8.00100040435791,69660.39453125,0.00118448683450235,5.73717225169514E-6,1,0.999253354069792,40.0298881530762,1.99873473595366,17.8900007158518,0.0129802066497017,0.00264846778675338,0.25,2.81916318126065E-5,0.0011840466342811,3.69385658775339E-5,8.00102519989014,8.00102519989014,69610.3671875,69710.421875,55.4456006401597,20.6411306596115,6.48653364181519,0,0,0,40,7.98716688156128,1,6,1,2.24319458007813,42.0332374572754,,,,,,,,,,,,,,,,
,3949075454.0315,8.00182723999023,76254.21875,0.00128604724982036,6.82137830607465E-6,1,0.999253354069792,40.0298881530762,1.99862331965615,17.8900007158518,0.0141298705872898,0.00271052244004431,0.25,1.56032175716733E-5,0.0012863749356909,2.50070605792632E-5,8.00177955627441,8.00177955627441,76204.140625,76304.296875,55.4627964675828,20.634851280588,6.48646688461304,0,0,0,40,7.97930717468262,1,6,1,2.2296142578125,42.0332374572754,,,,,,,,,,,,,,,,
,3949075519.03,8.00100040435791,82756.5625,0.0013843991721063,4.6065719251138E-6,1,0.999253354069792,40.0298881530762,1.99865529951979,17.8900007158518,0.0152365262426546,0.00281681033468898,0.25,7.65105194253174E-6,0.00138549861980728,1.76228848696239E-5,8.0009298324585,8.0009298324585,82706.5703125,82806.5546875,55.7754478752751,20.63758625479,6.48613882064819,0,0,0,40,7.96987962722778,1,6,1,2.24212646484375,42.5219955444336,,,,,,,,,,,,,,,,
,3949075583.9615,8.00131845474243,89255.00390625,0.00147957775087777,4.52738658983517E-6,1,0.999253354069792,40.0298881530762,1.99854345261502,17.8900007158518,0.0162786286002831,0.00307799724665634,0.25,1.43956690886976E-5,0.00148137578307966,2.48694667620772E-5,8.00125122070312,8.00125122070312,89200,89310.0078125,56.2819431557367,20.6410764035213,6.48553037643433,0,0,0,40,7.96261262893677,1,6,1,2.24273681640625,42.0332374572754,,,,,,,,,,,,,,,,
,3949075648.945,8.00100898742676,95753.6640625,0.00158192418543325,3.5437554377038E-6,1,0.999253354069792,40.0298881530762,1.99871036722039,17.8900007158518,0.0174258607684534,0.0032217784722227,0.25,9.21478517364967E-6,0.00158454268341852,2.01740670391122E-5,8.00089740753174,8.00089740753174,95703.5703125,95803.7578125,55.487026951679,20.6416512514445,6.48535680770874,0,0,0,40,7.95410060882568,1,6,1,2.24624633789062,42.0332374572754,,,,,,,,,,,,,,,,
,3949075713.8635,8.00122833251953,102251.8046875,0.00167501321571532,3.43285863646215E-6,1,0.999253354069792,40.0298881530762,1.99857698878809,17.8900007158518,0.0184753824786103,0.00330975580672563,0.25,7.21212973007913E-7,0.00167847703311927,1.20422913270857E-5,8.00127696990967,8.00127696990967,102206.7890625,102296.8203125,55.7770111323136,20.6363958749503,6.48575162887573,0,0,0,40,7.94574880599976,1,6,1,2.24472045898438,42.0332374572754,,,,,,,,,,,,,,,,
,3949075779.8295,8.0010495185852,108849.23046875,0.00177803014743795,2.94728487554486E-6,1,0.999253354069792,40.0298881530762,1.99856438138709,17.8900007158518,0.0195991245898454,0.00362192807119525,0.25,1.08065388593473E-5,0.00178225712241155,2.25458592327803E-5,8.00098323822022,8.00098323822022,108799.1484375,108899.3125,56.4062220902944,20.6390335430119,6.48482036590576,0,0,0,40,7.93753051757812,1,6,1,2.24044799804687,41.055721282959,,,,,,,,,,,,,,,,
,3949075844.7485,8.00145530700684,115347.93359375,0.00187591004947958,2.48102187021408E-6,1,0.999253354069792,40.0298881530762,1.99867845104562,17.8900007158518,0.0206780360439143,0.00386491023168203,0.25,1.55502929589116E-5,0.00188092669645301,2.7628204044877E-5,8.00152587890625,8.00152587890625,115302.8828125,115392.984375,55.3189768200443,20.6397555545094,6.48461723327637,0,0,0,40,7.9290885925293,1,6,1,2.2607421875,42.5219955444336,,,,,,,,,,,,,,,,
,3949075909.7135,8.00055408477783,121845.51953125,0.00196849765364867,2.20205467520451E-6,1,0.999253354069792,40.0298881530762,1.99869701241537,17.8900007158518,0.0217135910234423,0.00400815407933729,0.25,1.22528539435485E-5,0.00197434447786152,2.45775604431338E-5,8.00053215026855,8.00053215026855,121795.3984375,121895.640625,55.9513142921021,20.6438532452359,6.48401165008545,0,0,0,40,7.92126035690308,1,6,1,2.24212646484375,42.5219955444336,,,,,,,,,,,,,,,,
,3949075974.6335,8.00122165679932,128348.6484375,0.00206847391957613,2.34576838827021E-6,1,0.999253354069792,40.0298881530762,1.99857897549868,17.8900007158518,0.0228174637578953,0.00423203086271917,0.25,1.49988169422437E-5,0.00207513657962137,2.76009903063676E-5,8.0011157989502,8.0011157989502,128298.6328125,128398.6640625,56.1482846789482,20.6437312339997,6.48288202285767,0,0,0,40,7.9152398109436,1,6,1,2.2442626953125,42.0332374572754,,,,,,,,,,,,,,,,
,3949076039.635,8.0006251335144,134846.640625,0.00216534496107878,2.09446186000469E-6,1,0.999253354069792,40.0298881530762,1.99848572127169,17.8900007158518,0.0238906610571242,0.00443035144815134,0.25,1.60103606763569E-5,0.00217282373415218,2.88362100177629E-5,8.00052261352539,8.00052261352539,134801.625,134891.65625,55.6066161151213,20.635867531344,6.48232269287109,0,0,0,40,7.90902233123779,1,6,1,2.26043701171875,43.0107536315918,,,,,,,,,,,,,,,,
,3949076093.586,8.00067329406738,140002.6015625,0.00223845958707486,2.11587915582812E-6,1,0.999253354069792,40.0298881530762,1.99874389638249,17.8900007158518,0.0247032034310693,0.00458883593750511,0.25,1.75356343774004E-5,0.00224656628699122,3.05011038387196E-5,8.00076484680176,8.00076484680176,140000.046875,140005.15625,55.6574219688713,20.6487478747508,6.48162603378296,0,0,0,40,7.90327835083008,1,4,1,2.24090576171875,42.5219955444336,,,,,,,,,,,,,,,,