File: PPMS_Data_and_Plotting/Data/RuCl3/Data/Heat Capacity/28-03-2025_RuCl3_TB001_9T _001_1.csv
[Header]
TITLE,RuCl3_TB001_9T_HparraC_Heat_Capacity
BYAPP,HeatCapacity,3.9.6,1.7
INFO,0,MASS:Sample Mass (mg)
INFO,0,MASSERR:Sample Mass Error (mg)
INFO,0,MOLWGHT:Formula Weight (g/mole)
INFO,0,ATOMS:Atoms per Formula Unit
INFO,PPMS Heat Capacity Option 3.9.6 Build 3,APPNAME
DATATYPE,TIME,1
DATATYPE,COMMENT,2
STARTUPAXIS, X, 8, LINEAR, AUTO
STARTUPAXIS, Y1, 10, LINEAR, AUTO
[Data]
Time Stamp (Seconds),Comment (),System Status (Code),Puck Temp (Kelvin),System Temp (Kelvin),Field (Oersted),Pressure (Torr),Sample Temp (Kelvin),Temp Rise (Kelvin),Samp HC (µJ/K),Samp HC Err (µJ/K),Addenda HC (µJ/K),Addenda HC Err (µJ/K),Total HC (µJ/K),Total HC Err (µJ/K),Fit Deviation (ChiSquare),Time Const tau1 (seconds),Time Const tau2 (seconds),Sample Coupling (Percent),Debye Temp (Kelvin),Debye Temp Err (Kelvin),Cal Correction (Factor),Therm Resist (Ohms),Htr Resist (Ohms),Puck Resist (Ohms),Wire Cond (W/K),Meas Time (seconds),Temp Squared (K^2),Samp HC/Temp (µJ/K/K),Addenda Offset HC (µJ/K)
8150581.58,Error: Warning: Current field is 90000.328 Oe;
8150581.78,Error: but addenda was obtained at 0.021 Oe.
8150601,Error: Temperature of platform does not match the system temperature : System = 3.0076 K;  Platform = 2.8635 K
8150694.88,,5905,,2.9945,90000.328,9.1E-6,2.8787231,0.031047132,18.471378,0.1745,0.51694587,0.001798,18.988324,0.1745,0.65275115,6.6058284,,,,,1,,,,2.8744804E-6,16.206902,8.2870466,6.4165179,0
8151602.64,,5905,,3.0065,90000.328,9.1E-6,2.8758339,0.026824862,19.126592,0.2052,0.51545776,0.001799,19.64205,0.2052,0.23289592,6.717251,,,,,1,,,,2.9241203E-6,13.211657,8.2704205,6.6507987,0
8152443.47,,5905,,3.0134,90000.328,9E-6,2.8754185,0.027652924,18.27633,0.1561,0.51520601,0.001799,18.791536,0.1561,0.79254076,6.3741736,,,,,1,,,,2.9480741E-6,13.434502,8.2680318,6.3560591,0
8152671.41,,5905,,3.2209,90000.328,9E-6,3.0740728,0.027900865,22.798265,0.226,0.62512037,0.002065,23.423385,0.226,0.27906736,8.0070482,0.001804184,99.125706,,,1,,,,2.9497943E-6,12.748347,9.4499234,7.4163061,0
8153112.77,,5905,,3.22,90000.328,9E-6,3.0767318,0.031095563,23.314532,0.1738,0.62635736,0.002071,23.940889,0.1738,0.73165774,7.6299447,0.00048960754,99.747569,,,1,,,,3.1452851E-6,16.014096,9.4662785,7.5776939,0
8153184.36,,5905,,3.2039,90000.328,9.1E-6,3.0763006,0.030545146,23.299029,0.1783,0.62613086,0.00207,23.92516,0.1783,0.32592832,7.7824389,0.0012022406,99.390513,,,1,,,,3.0921307E-6,15.259889,9.4636253,7.5737168,0
8153387.8,,5905,,3.4472,90000.328,9E-6,3.277819,0.030882635,28.197946,0.2631,0.74245463,0.003041,28.940401,0.2631,0.33150455,8.5651211,1.6264315E-6,99.99924,,,1,,,,3.3788909E-6,15.564878,10.744097,8.6026551,0
8153708.83,,5905,,3.4165,90000.328,9.1E-6,3.2780933,0.032509917,27.8182,0.2113,0.74254371,0.003042,28.560744,0.2113,0.2118584,8.236444,0.00045640232,99.780744,,,1,,,,3.4748351E-6,17.130242,10.745895,8.4860917,0
8153792.98,,5905,,3.4218,90000.328,9.1E-6,3.278025,0.032460068,27.971441,0.2574,0.74269226,0.003044,28.714133,0.2574,0.2534248,8.9119843,0.0028289103,98.725556,,,1,,,,3.2614498E-6,16.472888,10.745448,8.5330163,0
8154084.28,,5905,,3.6505,90000.328,9.2E-6,3.4761263,0.032137727,33.609543,0.2506,0.86791757,0.004184,34.47746,0.2506,0.48997958,8.9943151,,,,,1,,,,3.8332502E-6,17.823969,12.083454,9.6686773,0
8154164.27,,5905,,3.6265,90000.328,9.1E-6,3.4762761,0.032647117,33.491181,0.2115,0.86806805,0.004185,34.359249,0.2115,0.40785703,9.0455571,,,,,1,,,,3.7984668E-6,17.98863,12.084495,9.634212,0
8154253.91,,5905,,3.6578,90000.328,9.1E-6,3.4764809,0.033479863,32.840308,0.2463,0.86828219,0.004186,33.70859,0.2462,0.49940902,9.1043036,,,,,1,,,,3.7024897E-6,18.091114,12.08592,9.4464225,0
8154488.47,,5905,,3.8681,90000.328,9.1E-6,3.682682,0.033142172,39.718229,0.2276,1.0168968,0.004248,40.735126,0.2276,0.9873681,10.024137,0.0013341529,99.450474,,,1,,,,4.0850542E-6,18.208607,13.562147,10.785137,0
8154574.73,,5905,,3.8563,90000.328,9.2E-6,3.6835321,0.036266471,39.434128,0.1852,1.0176133,0.004246,40.451741,0.1852,0.24882015,10.341074,0.0011696174,99.536858,,,1,,,,3.9290534E-6,20.048274,13.568408,10.705521,0
8154663.31,,5905,,3.8658,90000.328,9.2E-6,3.6837875,0.035454766,40.114948,0.2169,1.0178846,0.004245,41.132833,0.2169,0.81666295,10.149053,,,,,1,,,,4.0528741E-6,20.682148,13.57029,10.889593,0
8154869.06,,5905,,4.0866,90000.328,9.2E-6,3.8861648,0.035005142,47.937866,0.2913,1.1910571,0.004143,49.128923,0.2913,0.344987,11.199429,0.00099204296,99.624269,,,1,,,,4.4024881E-6,20.298105,15.102277,12.335521,0
8154962.73,,5905,,4.0798,90000.328,9.1E-6,3.8863549,0.037344269,47.102912,0.223,1.191547,0.004145,48.294459,0.223,0.091809477,11.15102,,,,,1,,,,4.3309454E-6,22.398857,15.103755,12.120075,0
8155054.88,,5905,,4.0847,90000.328,9.1E-6,3.8874775,0.037991332,47.577244,0.2765,1.1924098,0.004148,48.769654,0.2765,0.36562577,11.611762,0.0017253314,99.373507,,,1,,,,4.2252253E-6,22.30204,15.112481,12.23859,0
8155276.31,,5905,,4.2734,90000.328,9.1E-6,4.0921848,0.039188033,53.823263,0.2178,1.4046809,0.006564,55.227944,0.2178,0.29870528,11.866154,0.00050472688,99.828135,,,1,,,,4.661852E-6,23.223524,16.745977,13.152696,0
8155374.11,,5905,,4.2853,90000.328,9.1E-6,4.0923414,0.039436091,53.817321,0.2458,1.4052961,0.006574,55.222617,0.2457,0.23241563,12.02018,,,,,1,,,,4.5941591E-6,23.732308,16.747258,13.150741,0
8155471.86,,5905,,4.2718,90000.328,9.1E-6,4.0921457,0.040939343,53.355025,0.2137,1.4048694,0.006567,54.759895,0.2137,0.33356435,12.303552,0.0025397107,99.167984,,,1,,,,4.4861961E-6,24.040359,16.745657,13.038398,0
8155699.7,,5905,,4.493,90000.328,9.1E-6,4.2934706,0.040650384,61.176598,0.2156,1.6454917,0.01029,62.822089,0.2154,0.42116266,12.847023,,,,,1,,,,4.8900115E-6,24.607104,18.433889,14.248752,0
8155803.14,,5905,,4.5053,90000.328,9.1E-6,4.2946476,0.043033663,61.641742,0.3443,1.64668,0.0103,63.288422,0.3443,0.56500384,13.379292,0.001610702,99.522898,,,1,,,,4.7518412E-6,25.694046,18.443998,14.353155,0
8155909.5,,5905,,4.4996,90000.328,9E-6,4.2947429,0.043995555,61.772439,0.3709,1.6468008,0.0103,63.41924,0.3709,0.61000501,13.493992,0.0028427988,99.160733,,,1,,,,4.7375599E-6,26.758585,18.444817,14.383268,0
8156147.33,,5905,,4.726,90000.328,9E-6,4.493432,0.043876218,68.057096,0.2874,1.8999493,0.0115,69.957045,0.2872,0.39115365,13.451264,,,,,1,,,,5.2007787E-6,26.987984,20.190931,15.145906,0
8156254.77,,5905,,4.6983,90000.328,9.1E-6,4.4940918,0.044353704,69.395206,0.1649,1.9002891,0.01149,71.295495,0.1649,0.20911107,13.702081,0.0011875041,99.664936,,,1,,,,5.2198346E-6,26.902527,20.196862,15.44143,0
8156362.2,,5905,,4.7208,90000.328,9.2E-6,4.4942879,0.044896158,69.682931,0.167,1.9006267,0.01149,71.583558,0.167,0.31238253,13.799693,0.00047218092,99.867457,,,1,,,,5.1938538E-6,27.404162,20.198624,15.504777,0
8156596.09,,5905,,4.9259,90000.328,9.1E-6,4.6953858,0.046510535,76.578522,0.2026,2.1621345,0.009715,78.740657,0.2026,0.19043533,14.960839,0.0026609188,99.329977,,,1,,,,5.2967026E-6,27.599386,22.046648,16.309314,0
8156711.31,,5905,,4.9431,90000.328,9.1E-6,4.6970921,0.048551687,76.774668,0.2321,2.1637247,0.009703,78.938392,0.2321,0.23825046,14.438891,0.0011905073,99.68986,,,1,,,,5.4831576E-6,29.921679,22.062674,16.345148,0
8156825.58,,5905,,4.9408,90000.328,9.1E-6,4.6960735,0.045960771,78.076322,0.2594,2.1629928,0.009709,80.239314,0.2592,0.39381905,14.44039,,,,,1,,,,5.5565892E-6,28.877782,22.053106,16.625873,0
8157066.36,,5905,,5.1439,90000.328,9.2E-6,4.8990499,0.047990608,85.663334,0.2754,2.4272392,0.009176,88.090574,0.2754,0.27468509,15.262909,0.00047381586,99.884023,,,1,,,,5.7778831E-6,28.880779,24.00069,17.485703,0
8157183.72,,5905,,5.1464,90000.328,9.1E-6,4.8998825,0.049944289,85.880432,0.3144,2.4284845,0.009184,88.308916,0.3144,0.53628039,15.450537,0.001640881,99.601471,,,1,,,,5.73722E-6,30.525817,24.008848,17.527039,0
8157303.22,,5905,,5.1256,90000.328,9.1E-6,4.8996167,0.04915204,86.145276,0.2047,2.428528,0.009184,88.573804,0.2045,0.16582259,15.319248,,,,,1,,,,5.7818637E-6,30.901074,24.006244,17.582044,0
8157549.02,,5905,,5.3536,90000.328,9.1E-6,5.1027867,0.050531081,94.596535,0.196,2.6933554,0.01323,97.28989,0.196,0.24989362,16.041951,0.00054781942,99.87299,,,1,,,,6.0720084E-6,30.638496,26.038432,18.538211,0
8157671.61,,5905,,5.3484,90000.328,9.1E-6,5.103518,0.052374354,94.072926,0.2412,2.6941277,0.01324,96.767054,0.2412,0.36772603,15.93389,0.001474801,99.656985,,,1,,,,6.0927913E-6,32.083903,26.045896,18.432957,0
8157793.13,,5905,,5.3486,90000.328,9.1E-6,5.1033252,0.052030172,94.630271,0.2126,2.6938138,0.01324,97.324085,0.2126,0.14994135,15.968497,0.00057936801,99.865024,,,1,,,,6.1025435E-6,31.867779,26.043929,18.542865,0
8158041.88,,5905,,5.5781,90000.328,9.1E-6,5.3055675,0.052344056,103.73948,0.2553,2.9696205,0.01864,106.7091,0.2553,0.50752521,16.544048,0.00045389464,99.898501,,,1,,,,6.4561933E-6,31.936995,28.149046,19.552947,0
8158166.52,,5905,,5.5641,90000.328,9.1E-6,5.3063458,0.054367155,103.03521,0.1953,2.9709083,0.01866,106.00612,0.1953,0.3031873,16.745998,0.0014899484,99.672422,,,1,,,,6.3498927E-6,33.088095,28.157306,19.417358,0
8158293.38,,5905,,5.5696,90000.328,9.1E-6,5.3062978,0.054803031,102.93121,0.2398,2.970875,0.01866,105.90209,0.2398,0.17669109,16.717753,0.0010706326,99.76463,,,1,,,,6.3488273E-6,33.491996,28.156796,19.397933,0
8158550.58,,5905,,5.7893,90000.328,9.1E-6,5.5097149,0.055431479,111.45405,0.2181,3.2756229,0.02041,114.72967,0.2181,0.25286968,17.528202,0.0026766298,99.446711,,,1,,,,6.5798051E-6,33.435507,30.356959,20.228641,0
8158682.53,,5905,,5.7982,90000.328,9.2E-6,5.5110941,0.056968966,111.36068,0.2202,3.2771859,0.0204,114.63787,0.2202,0.25092043,16.970329,0.00074365917,99.841978,,,1,,,,6.7652836E-6,35.056404,30.372158,20.206638,0
8158809.14,,5905,,5.7923,90000.328,9.2E-6,5.5101944,0.055720475,112.81811,0.2045,3.2763897,0.02041,116.0945,0.2045,0.24582247,17.491558,0.0021093586,99.558552,,,1,,,,6.6649686E-6,33.940658,30.362242,20.474434,0
8159069.81,,5905,,6.0038,90000.328,9.1E-6,5.7132333,0.057201974,121.47453,0.2169,3.6144112,0.01665,125.08894,0.2169,0.25956388,17.988042,0.0015339648,99.695266,,,1,,,,6.9740527E-6,34.983116,32.641034,21.261959,0
8159221.25,,5905,,5.993,90000.328,9.1E-6,5.71375,0.058442251,121.30289,0.3203,3.6151447,0.01664,124.91803,0.3203,1.1577739,17.791496,0.0016177377,99.675511,,,1,,,,7.0427766E-6,35.976083,32.646939,21.229996,0
8159353.69,,5905,,6.0084,90000.328,9.2E-6,5.7139216,0.057762037,121.53762,0.2293,3.615171,0.01664,125.15279,0.2293,0.68621482,17.581569,0.00065355048,99.86733,,,1,,,,7.1273269E-6,35.582993,32.6489,21.270439,0
8159356.2,Error: Warning: Current field is 90000.328 Oe;
8159356.3,Error: but addenda was obtained at 0.021 Oe.
8159438.73,Error: Temperature of platform does not match the system temperature : System = 6.0025 K;  Platform = 5.6846 K
8159612.13,,5905,,6.0022,90000.328,9.1E-6,5.7143575,0.059295646,121.70408,0.2354,3.616183,0.01662,125.32027,0.2354,0.17623659,18.007996,0.001595399,99.68296,,,1,,,,6.9800219E-6,36.450316,32.653882,21.297947,0
8159745.48,,5905,,5.993,90000.328,9.1E-6,5.7135579,0.0589573,120.80578,0.283,3.6150579,0.01664,124.42083,0.283,0.21363633,18.03111,0.0022523724,99.555455,,,1,,,,6.9293936E-6,36.015993,32.644744,21.143704,0
8159879.55,,5905,,5.9822,90000.328,9E-6,5.7134486,0.057185406,121.02027,0.2939,3.6151533,0.01664,124.63543,0.2935,0.93066645,17.483631,,,,,1,,,,7.1286922E-6,36.06222,32.643495,21.181651,0
8160125.75,,5905,,6.0568,90000.328,9.1E-6,5.7615897,0.057512497,123.47096,0.2736,3.6994723,0.01527,127.17043,0.2736,0.68637838,18.115355,0.0012067097,99.763662,,,1,,,,7.035713E-6,34.967263,33.195915,21.430016,0
8160260.45,,5905,,6.0428,90000.328,9.1E-6,5.762686,0.059090236,123.07397,0.1976,3.7009716,0.01524,126.77495,0.1976,0.15126998,17.874993,0.00071520945,99.858643,,,1,,,,7.1017699E-6,36.23071,33.20855,21.35705,0
8160393.67,,5905,,6.0474,90000.328,9.1E-6,5.7622061,0.058547783,123.46708,0.2966,3.7004956,0.01525,127.16758,0.2966,0.39449787,18.091967,0.0022013578,99.567672,,,1,,,,7.0577257E-6,35.749986,33.203019,21.427051,0
8160660.06,,5905,,6.1003,90000.328,9.1E-6,5.8121429,0.058835638,125.32319,0.2759,3.7896025,0.01373,129.11279,0.2759,0.30153218,18.092366,0.0013935807,99.728985,,,1,,,,7.154586E-6,36.183934,33.781005,21.562304,0
8160795.3,,5905,,6.1155,90000.328,9.1E-6,5.8124178,0.059134738,125.46074,0.2625,3.7900849,0.01372,129.25083,0.2625,0.36581521,18.019422,0.00076167733,99.8513,,,1,,,,7.182927E-6,36.184733,33.784201,21.584949,0
8160928.22,,5905,,6.121,90000.328,9E-6,5.8123405,0.05885291,126.02827,0.2629,3.7902251,0.01372,129.81849,0.2629,0.16940391,18.093583,0.0006755806,99.868114,,,1,,,,7.1837664E-6,36.038844,33.783303,21.682878,0
8161185.39,,5905,,6.1543,90000.328,9.1E-6,5.8600979,0.05942965,126.53162,0.2241,3.8771521,0.01222,130.40877,0.2241,0.31514069,18.273337,0.0020300747,99.613561,,,1,,,,7.1626269E-6,36.187166,34.340748,21.592066,0
8161320.64,,5905,,6.1621,90000.328,9.1E-6,5.860683,0.060007303,127.05603,0.2673,3.8782506,0.01221,130.93428,0.2673,0.50900376,18.218609,0.00086773665,99.834047,,,1,,,,7.1980928E-6,36.546674,34.347605,21.679389,0
8161457.17,,5905,,6.1421,90000.328,9.1E-6,5.8599391,0.058026152,128.07593,0.2668,3.8777117,0.01222,131.95364,0.2666,0.30767947,18.012858,,,,,1,,,,7.3255248E-6,36.437217,34.338886,21.856187,0
8161699.39,,5905,,6.2073,90000.328,9.2E-6,5.9086116,0.058904286,129.72842,0.3103,3.9670411,0.01071,133.69546,0.3103,0.5841456,18.269097,0.0011738294,99.776397,,,1,,,,7.3335632E-6,36.025716,34.911691,21.955821,0
8161834.8,,5905,,6.2119,90000.328,9.1E-6,5.9085735,0.058386745,129.45054,0.1724,3.967705,0.0107,133.41825,0.1721,0.16458386,17.942628,,,,,1,,,,7.4358254E-6,36.538194,34.911241,21.908933,0
8161967.89,,5905,,6.215,90000.328,9E-6,5.9088126,0.059115821,129.10562,0.2656,3.9673311,0.0107,133.07295,0.2656,0.18473352,18.039881,0.0013165535,99.747122,,,1,,,,7.3942022E-6,35.885255,34.914066,21.849673,0
8162216.67,,5905,,6.2591,90000.328,9.1E-6,5.9570118,0.058971263,132.00418,0.2816,4.0575645,0.009252,136.06174,0.2816,0.11327269,18.277105,0.00078017548,99.852269,,,1,,,,7.4547487E-6,36.079761,35.48599,22.159462,0
8162353.06,,5905,,6.2607,90000.328,9.1E-6,5.9573548,0.060104305,131.61785,0.2603,4.0585122,0.009237,135.67636,0.2603,0.14490721,18.397732,0.001116104,99.790555,,,1,,,,7.3891915E-6,36.55421,35.490076,22.093338,0
8162487.73,,5905,,6.2707,90000.328,9E-6,5.9577886,0.060322661,131.21414,0.2742,4.0592593,0.009226,135.27339,0.2742,0.22068994,18.225926,0.00082492772,99.844289,,,1,,,,7.4329226E-6,36.795463,35.495245,22.023966,0
8162747.09,,5905,,6.3157,90000.328,9.2E-6,6.0063128,0.060102144,133.40241,0.3114,4.152033,0.007857,137.55444,0.3114,0.64712876,18.841472,0.0038765715,99.292745,,,1,,,,7.349541E-6,36.451852,36.075793,22.210367,0
8162885.56,,5905,,6.3188,90000.328,9.1E-6,6.0070486,0.060249377,132.7398,0.3405,4.1540493,0.007829,136.89385,0.3404,0.3168339,18.175818,,,,,1,,,,7.5316472E-6,37.682943,36.084633,22.097341,0
8163021.19,,5905,,6.3005,90000.328,9E-6,6.006681,0.058531425,134.06685,0.2297,4.1533234,0.007839,138.22018,0.2296,0.19928969,18.252818,,,,,1,,,,7.5725389E-6,36.351636,36.080217,22.319623,0
8163271.09,,5905,,6.3533,90000.328,9.1E-6,6.0555851,0.060085533,134.76534,0.2686,4.2465005,0.006631,139.01184,0.2686,0.20528534,18.292174,0.0012350802,99.771546,,,1,,,,7.615881E-6,36.505637,36.670111,22.254719,0
8163406.33,,5905,,6.3652,90000.328,9E-6,6.0556504,0.060475178,135.66305,0.2855,4.2468441,0.006627,139.90989,0.2855,0.48155258,18.518693,0.0013369432,99.754182,,,1,,,,7.5725685E-6,36.584348,36.670902,22.402721,0
8163543.03,,5905,,6.3726,90000.328,9E-6,6.0557355,0.061129662,135.25411,0.2012,4.2472276,0.006623,139.50133,0.2012,0.39895635,18.609953,0.0020900389,99.618256,,,1,,,,7.5230663E-6,37.037386,36.671932,22.334877,0
8163803.36,,5905,,6.4092,90000.328,9.1E-6,6.1036757,0.060977947,137.34018,0.2122,4.3402276,0.005622,141.68041,0.2122,0.22467012,18.572383,0.0012540434,99.772162,,,1,,,,7.6449235E-6,37.219907,37.254858,22.501224,0
8163940.27,,5905,,6.409,90000.328,9.1E-6,6.1038011,0.06123145,138.03654,0.2274,4.3406131,0.005619,142.37716,0.2274,0.13139355,18.723129,0.0012229409,99.778584,,,1,,,,7.6202086E-6,37.144765,37.256388,22.61485,0
8164079.73,,5905,,6.4037,90000.328,9.1E-6,6.1038075,0.059970745,138.79516,0.24,4.3417632,0.005608,143.13692,0.24,0.33143107,18.657946,,,,,1,,,,7.6716336E-6,37.446259,37.256466,22.739112,0
8164337.98,,5905,,6.4528,90000.328,9.1E-6,6.152599,0.061330085,139.90335,0.2755,4.4368721,0.004829,144.34022,0.2755,0.59531146,18.923577,0.0019972051,99.644656,,,1,,,,7.6530906E-6,37.315892,37.854474,22.738903,0
8164477.55,,5905,,6.4424,90000.328,9.2E-6,6.1537682,0.062223873,139.74639,0.2308,4.4393016,0.004812,144.18569,0.2308,0.26479886,18.839125,0.0017517268,99.687544,,,1,,,,7.6760601E-6,37.847154,37.868863,22.709075,0
8164616.98,,5905,,6.4678,90000.328,9E-6,6.1528688,0.060204139,141.06302,0.225,4.4384308,0.004818,145.50145,0.2249,0.086561972,18.659008,,,,,1,,,,7.7979197E-6,37.67825,37.857794,22.926382,0
8164875.55,,5905,,6.5094,90000.328,9E-6,6.2010263,0.059694484,142.93451,0.2353,4.534166,0.004268,147.46868,0.2352,0.42130805,18.714309,,,,,1,,,,7.8799959E-6,37.318017,38.452727,23.050137,0
8165014.33,,5905,,6.5129,90000.328,9.1E-6,6.2018845,0.061843989,141.81212,0.3449,4.534818,0.004265,146.34694,0.3449,0.26634707,18.697252,0.00042773659,99.92376,,,1,,,,7.8327975E-6,37.428617,38.463371,22.865973,0
8165153.58,,5905,,6.5165,90000.328,9.1E-6,6.2016668,0.061689347,142.13505,0.2769,4.5344942,0.004267,146.66954,0.2769,0.30599553,18.816944,0.0019018753,99.661642,,,1,,,,7.8194009E-6,37.394505,38.460672,22.918847,0
8165420.41,,5905,,6.5639,90000.328,9.2E-6,6.2505602,0.061902683,143.79787,0.2659,4.6327607,0.003915,148.43063,0.2659,0.29971837,18.820073,0.00058217212,99.897606,,,1,,,,7.8944128E-6,37.633889,39.069503,23.005597,0
8165559.67,,5905,,6.5656,90000.328,9.1E-6,6.2501379,0.060608664,144.3446,0.2389,4.6330413,0.003914,148.97764,0.2389,0.17732595,18.629291,,,,,1,,,,7.9969569E-6,37.640146,39.064224,23.094626,0
8165698.16,,5905,,6.5692,90000.328,9.2E-6,6.2497866,0.060144303,144.93264,0.25,4.6322885,0.003916,149.56493,0.25,0.60627139,18.731473,,,,,1,,,,7.984686E-6,37.258582,39.059832,23.190014,0
8165959.48,,5905,,6.6088,90000.328,9.2E-6,6.2991795,0.06182293,146.4362,0.1864,4.731586,0.003749,151.16779,0.1864,0.25213808,18.989445,0.00050675243,99.911919,,,1,,,,7.9672073E-6,37.462946,39.679663,23.246869,0
8166099.36,,5905,,6.6217,90000.328,9.2E-6,6.2996003,0.062654704,146.40289,0.2522,4.7326504,0.003748,151.13554,0.2522,0.38306467,18.986545,0.0012697068,99.779109,,,1,,,,7.9766759E-6,37.97889,39.684964,23.240028,0
8166240.11,,5905,,6.6101,90000.328,9.1E-6,6.2990009,0.061144412,146.87536,0.2019,4.7325382,0.003748,151.6079,0.2019,0.22375967,18.850601,,,,,1,,,,8.0426027E-6,37.97309,39.677413,23.317246,0
8166507.25,,5905,,6.6725,90000.328,9.2E-6,6.3486362,0.062463165,148.16276,0.2291,4.8333814,0.003749,152.99615,0.2291,0.25462768,19.197936,0.0016142903,99.724484,,,1,,,,7.9900564E-6,37.701202,40.305181,23.337731,0
8166649.47,,5905,,6.6612,90000.328,9.1E-6,6.3491816,0.063335275,148.33258,0.2228,4.8342911,0.00375,153.16687,0.2228,0.48408584,19.093139,0.001823047,99.686762,,,1,,,,8.0457329E-6,38.395871,40.312107,23.362473,0
8166790.45,,5905,,6.6599,90000.328,9.1E-6,6.3490041,0.062968623,148.64429,0.2018,4.833729,0.003749,153.47802,0.2018,0.29821906,18.990676,0.00062588192,99.89185,,,1,,,,8.0899644E-6,38.186279,40.309853,23.412222,0
8167054.19,,5905,,6.7204,90000.328,9.1E-6,6.3960114,0.061444032,150.14427,0.2831,4.9327473,0.00389,155.07702,0.2831,0.63894864,18.972165,,,,,1,,,,8.1739233E-6,37.981351,40.908962,23.474673,0
8167193.45,,5905,,6.7043,90000.328,9.1E-6,6.3964979,0.061554558,150.56104,0.2837,4.9337508,0.003892,155.49479,0.2837,0.34506693,18.914684,,,,,1,,,,8.2208505E-6,37.94433,40.915185,23.538043,0
8167335.06,,5905,,6.704,90000.328,9.1E-6,6.3965762,0.061483396,150.81043,0.233,4.9339603,0.003892,155.74439,0.2329,0.17545398,19.015763,,,,,1,,,,8.190278E-6,37.829369,40.916187,23.576742,0
8167596.05,,5905,,6.7567,90000.328,9.1E-6,6.4452295,0.062996757,152.68708,0.2214,5.0348076,0.004153,157.72188,0.2214,0.29282223,19.317624,0.0013780975,99.768685,,,1,,,,8.1824044E-6,38.031527,41.540984,23.689936,0
8167737.41,,5905,,6.7658,90000.328,9.1E-6,6.4459378,0.064008444,152.35366,0.2683,5.0360391,0.004157,157.3897,0.2683,0.33778348,19.16178,0.00087738651,99.851977,,,1,,,,8.2251405E-6,38.635249,41.550115,23.635608,0
8167879.45,,5905,,6.7713,90000.328,9.1E-6,6.4450066,0.06226063,152.4002,0.2381,5.0352363,0.004155,157.43543,0.2381,0.52960188,19.028091,,,,,1,,,,8.2738425E-6,38.32356,41.53811,23.646243,0
8168142.02,,5905,,6.8172,90000.328,9.1E-6,6.4942321,0.061846019,154.86281,0.2531,5.1397322,0.004525,160.00255,0.2531,0.42139334,19.235999,,,,,1,,,,8.3178703E-6,38.056183,42.175051,23.846209,0
8168283.11,,5905,,6.8063,90000.328,9.1E-6,6.4952495,0.064076284,154.60002,0.3096,5.1405762,0.004529,159.74059,0.3096,0.55102909,19.394223,0.0018709922,99.689409,,,1,,,,8.2605427E-6,38.471999,42.188266,23.802014,0
8168426.16,,5905,,6.825,90000.328,9.1E-6,6.4948463,0.062768181,154.66418,0.2733,5.140803,0.00453,159.80498,0.2732,0.54657256,19.047779,,,,,1,,,,8.389691E-6,38.788446,42.183028,23.813371,0
8168679.8,,5905,,6.8849,90000.328,9E-6,6.5437024,0.063681525,156.41496,0.2546,5.244451,0.004974,161.65941,0.2546,0.11826731,19.501669,0.0015771952,99.741764,,,1,,,,8.3096105E-6,38.095559,42.820041,23.903128,0
8168822.38,,5905,,6.8693,90000.328,9.1E-6,6.5441292,0.063234378,156.54642,0.2267,5.2462718,0.004982,161.79269,0.2266,0.1503503,19.085774,,,,,1,,,,8.4771356E-6,39.003337,42.825627,23.921658,0
8168963.28,,5905,,6.8755,90000.328,9.1E-6,6.543873,0.064064683,157.09595,0.3457,5.244602,0.004974,162.34055,0.3457,0.10436979,19.585067,0.0016054519,99.737187,,,1,,,,8.3094518E-6,38.171548,42.822274,24.006571,0
8169234.45,,5905,,6.9155,90000.328,9.2E-6,6.5930662,0.065104837,157.58016,0.2381,5.3509195,0.005484,162.93108,0.2381,0.21816703,19.418217,0.001723156,99.719938,,,1,,,,8.4126748E-6,39.170134,43.468521,23.900891,0
8169375.84,,5905,,6.9177,90000.328,9.1E-6,6.5930408,0.064816898,158.82238,0.2679,5.350955,0.005484,164.17333,0.2679,0.29539051,19.564059,0.0028031243,99.543776,,,1,,,,8.4275771E-6,38.836433,43.468187,24.089397,0
8169517.77,,5905,,6.9317,90000.328,9.1E-6,6.593365,0.065125238,158.90522,0.3101,5.351674,0.005488,164.25689,0.3101,0.57355537,19.539821,0.0020744225,99.662186,,,1,,,,8.4329341E-6,39.128118,43.472463,24.100776,0
8169786.02,,5905,,6.9785,90000.328,9.1E-6,6.6409851,0.065357248,160.12539,0.2133,5.4557545,0.006018,165.58115,0.2133,0.84739521,19.785425,0.0025082085,99.600756,,,1,,,,8.4002205E-6,39.079642,44.102683,24.111693,0
8169930.19,,5905,,6.9709,90000.328,9E-6,6.6417623,0.065847794,160.55057,0.2168,5.4569448,0.006025,166.00752,0.2168,0.53141654,19.492812,0.001449135,99.765677,,,1,,,,8.535056E-6,39.57085,44.113006,24.172888,0
8170072.47,,5905,,6.9558,90000.328,9.1E-6,6.6414366,0.065071328,161.11699,0.2916,5.4564057,0.006022,166.57339,0.2916,0.23222298,19.484843,0.0011405018,99.814961,,,1,,,,8.5636979E-6,38.985624,44.10868,24.259358,0
8170332.88,,5905,,7.0203,90000.328,9.1E-6,6.6902239,0.065351941,162.62268,0.2001,5.5641945,0.006582,168.18687,0.2001,0.17575514,19.823999,0.0019670287,99.688973,,,1,,,,8.5087533E-6,38.969685,44.759096,24.307509,0
8170477.02,,5905,,7.0319,90000.328,9.2E-6,6.6912278,0.06609581,162.90189,0.2358,5.5659882,0.006591,168.46788,0.2358,0.302823,19.565956,0.0010616642,99.829904,,,1,,,,8.6239736E-6,39.647997,44.772529,24.34559,0
8170619.98,,5905,,7.0337,90000.328,9.1E-6,6.6904927,0.06415574,162.61093,0.3024,5.5658683,0.00659,168.1768,0.3023,0.28856447,19.334387,,,,,1,,,,8.6983257E-6,39.131911,44.762693,24.304776,0
8170880.02,,5905,,7.0746,90000.328,9.1E-6,6.7389194,0.065364136,164.3314,0.1995,5.6725596,0.007133,170.00396,0.1995,0.19860266,19.858409,0.0022688196,99.644682,,,1,,,,8.589331E-6,38.668774,45.413035,24.385422,0
8171024.92,,5905,,7.0648,90000.328,9.1E-6,6.7395588,0.066916024,163.59837,0.254,5.6738958,0.00714,169.27227,0.254,1.0237037,19.72892,0.0027495265,99.568184,,,1,,,,8.6146676E-6,39.716818,45.421652,24.274344,0
8171170.14,,5905,,7.0785,90000.328,9.1E-6,6.7390515,0.064517955,164.83194,0.2361,5.673619,0.007139,170.50556,0.236,0.28453928,19.307481,,,,,1,,,,8.8310622E-6,39.45784,45.414815,24.45922,0
8171434.78,,5905,,7.1419,90000.328,9.1E-6,6.7872779,0.065279289,166.60061,0.2218,5.7810019,0.007654,172.38161,0.2218,0.13960524,19.686665,0.0010975751,99.827728,,,1,,,,8.7703778E-6,38.614961,46.067141,24.546013,0
8171578.92,,5905,,7.114,90000.328,9.1E-6,6.7875458,0.064630005,167.05366,0.3108,5.7826583,0.007662,172.83631,0.3107,0.81431342,19.381049,,,,,1,,,,8.9178E-6,39.37333,46.070778,24.611791,0
8171721.88,,5905,,7.126,90000.328,9.1E-6,6.7878328,0.065744184,166.59899,0.2979,5.7822609,0.00766,172.38126,0.2979,0.25884699,19.572298,0.00072137016,99.886196,,,1,,,,8.816783E-6,38.762097,46.074674,24.543768,0
8171982.75,,5905,,7.1792,90000.328,9.1E-6,6.8366303,0.066005064,168.75595,0.3169,5.8932012,0.00814,174.64915,0.3169,1.4670546,19.744702,0.0013044335,99.797017,,,1,,,,8.8621662E-6,39.144597,46.739514,24.684082,0
8172125.92,,5905,,7.1782,90000.328,9.1E-6,6.8371727,0.066977449,168.27048,0.2937,5.8942939,0.008144,174.16477,0.2937,0.59542755,19.746802,0.0016051251,99.750866,,,1,,,,8.8404616E-6,39.489404,46.74693,24.61112,0
8172271.11,,5905,,7.1784,90000.328,9.1E-6,6.8369402,0.064912948,169.09389,0.2364,5.8948076,0.008146,174.9887,0.2363,0.16992344,19.363115,,,,,1,,,,9.0372186E-6,39.493604,46.743752,24.732393,0
8172534.59,,5905,,7.226,90000.328,9.1E-6,6.8858602,0.065968386,170.40156,0.413,6.0060359,0.008563,176.4076,0.413,0.69463529,19.771835,0.0014014544,99.784067,,,1,,,,8.9401826E-6,38.72623,47.41507,24.74659,0
8172680.13,,5905,,7.2314,90000.328,9.1E-6,6.8862232,0.065619194,171.29487,0.2441,6.0082097,0.008571,177.30308,0.244,0.41542002,19.734095,,,,,1,,,,8.9846065E-6,39.54367,47.420069,24.87501,0
8172824.3,,5905,,7.2325,90000.328,9.1E-6,6.8867965,0.067396662,170.10724,0.2632,6.0082337,0.008571,176.11547,0.2632,0.17472207,19.879997,0.0017569202,99.731172,,,1,,,,8.8812086E-6,39.468191,47.427966,24.700489,0
8173101.91,,5905,,7.2824,90000.328,9.1E-6,6.9342028,0.065787645,172.23469,0.2906,6.1192059,0.008927,178.3539,0.2905,0.45109064,19.601939,,,,,1,,,,9.0987883E-6,39.759993,48.083168,24.838427,0
8173246.22,,5905,,7.2903,90000.328,9.1E-6,6.9349259,0.067286264,172.23184,0.3412,6.1196257,0.008928,178.35147,0.3412,0.26150181,19.893017,0.0019956911,99.696436,,,1,,,,8.9909917E-6,39.203879,48.093198,24.835427,0
8173390.94,,5905,,7.2863,90000.328,9.1E-6,6.935034,0.068079756,171.85449,0.2216,6.1201218,0.00893,177.97462,0.2216,0.26130964,19.955677,0.0022353662,99.661662,,,1,,,,8.9467292E-6,39.786035,48.094697,24.780627,0
8173642.98,,5905,,7.3268,90000.328,9E-6,6.9833805,0.068088924,173.76933,0.2418,6.2332889,0.009238,180.00262,0.2418,0.40709515,20.122679,0.0034542306,99.484208,,,1,,,,8.98849E-6,39.911354,48.767604,24.883268,0
8173791.03,,5905,,7.3227,90000.328,9E-6,6.983479,0.066855475,175.13249,0.2403,6.2343843,0.009241,181.36687,0.2401,0.20266989,19.775296,,,,,1,,,,9.171386E-6,40.245359,48.768979,25.078114,0
8173935.94,,5905,,7.3349,90000.328,9.1E-6,6.9836336,0.068031707,174.5008,0.2926,6.2337262,0.009239,180.73453,0.2926,0.28652941,20.062129,0.0015661082,99.76511,,,1,,,,9.0285152E-6,39.550591,48.771139,24.987107,0
8174200.48,,5905,,7.3801,90000.328,9.2E-6,7.0330904,0.068341443,176.4285,0.2705,6.3505407,0.009505,182.77904,0.2705,0.84191711,20.069162,0.0024666186,99.632356,,,1,,,,9.1387731E-6,40.124258,49.464361,25.085487,0
8174345.77,,5905,,7.378,90000.328,9.1E-6,7.0336429,0.069024644,175.93206,0.2581,6.3519816,0.009508,182.28404,0.2581,0.20144827,20.04493,0.0021958295,99.673364,,,1,,,,9.1215361E-6,40.138325,49.472132,25.012936,0
8174491.34,,5905,,7.3904,90000.328,9.1E-6,7.0335065,0.068963028,175.85012,0.271,6.3517492,0.009508,182.20187,0.271,0.16481859,20.102964,0.0033510448,99.502423,,,1,,,,9.1056581E-6,40.089861,49.470214,25.001771,0
8174757.67,,5905,,7.4408,90000.328,9.1E-6,7.0811513,0.067163262,178.49556,0.3154,6.4664437,0.009721,184.96201,0.3153,0.38618018,19.8408,,,,,1,,,,9.3223061E-6,40.205928,50.142704,25.207139,0
8174902.91,,5905,,7.4407,90000.328,9E-6,7.0820766,0.068864423,177.88627,0.3282,6.4674004,0.009723,184.35367,0.3282,0.061812471,20.118043,0.0026301984,99.612485,,,1,,,,9.1967942E-6,39.681599,50.155809,25.117812,0
8175050.02,,5905,,7.4408,90000.328,9E-6,7.0823111,0.069443178,177.95031,0.3393,6.4675506,0.009723,184.41786,0.3393,0.61490139,20.034154,0.0012060576,99.821831,,,1,,,,9.2204723E-6,40.236086,50.159131,25.126023,0
8175316.5,,5905,,7.4778,90000.328,9.1E-6,7.1311521,0.069096772,179.84906,0.2741,6.5854531,0.009899,186.43451,0.2741,0.43633025,20.125666,0.0023232494,99.660236,,,1,,,,9.2929131E-6,40.068307,50.85333,25.220196,0
8175463.73,,5905,,7.4819,90000.328,9.1E-6,7.1315657,0.069681009,179.56092,0.2548,6.5860474,0.0099,186.14697,0.2548,0.14561587,19.972541,0.0021735189,99.680255,,,1,,,,9.3479656E-6,40.251332,50.85923,25.178331,0
8175609.06,,5905,,7.4905,90000.328,9.2E-6,7.1315504,0.069255129,180.34311,0.2653,6.5863737,0.009901,186.92948,0.2653,0.3496516,20.062985,0.0017344333,99.745125,,,1,,,,9.3392933E-6,39.945083,50.859012,25.288064,0
8175880.84,,5905,,7.5428,90000.328,9E-6,7.1797221,0.069448209,182.03209,0.3067,6.7035812,0.01004,188.73568,0.3067,0.51248177,20.265468,0.003252207,99.529632,,,1,,,,9.3541152E-6,40.125971,51.548409,25.353641,0
8176029.73,,5905,,7.5297,90000.328,9.2E-6,7.1798531,0.068450132,182.93618,0.3347,6.7049149,0.01004,189.6411,0.3346,0.65442996,19.939374,,,,,1,,,,9.5108853E-6,40.530935,51.550291,25.479098,0
8176174.45,,5905,,7.5491,90000.328,9.1E-6,7.1800645,0.069704844,182.18467,0.3344,6.7045061,0.01004,188.88917,0.3344,0.27123769,20.315694,0.002991035,99.568339,,,1,,,,9.3352008E-6,39.878748,51.553326,25.373681,0
8176442.94,,5905,,7.5993,90000.328,9.1E-6,7.22935,0.070443986,183.95011,0.3122,6.8249538,0.01014,190.77506,0.3122,0.33806147,20.314652,0.0022242445,99.681722,,,1,,,,9.4188891E-6,40.631388,52.263501,25.444903,0
8176590.92,,5905,,7.5993,90000.328,9.1E-6,7.2296586,0.070735238,183.73973,0.2716,6.8256361,0.01014,190.56537,0.2716,0.30197605,20.119105,0.0024367787,99.648225,,,1,,,,9.5029497E-6,40.629304,52.267963,25.414718,0
8176738.97,,5905,,7.595,90000.328,9.1E-6,7.22912,0.068504004,184.12953,0.2599,6.8255036,0.01014,190.95503,0.2597,0.20052683,19.789014,,,,,1,,,,9.6495477E-6,40.23821,52.260175,25.470532,0
8176992.64,,5905,,7.6376,90000.328,9.1E-6,7.2775807,0.069673971,185.16892,0.3403,6.9442593,0.01022,192.11318,0.3403,0.82315481,20.131434,0.0020391741,99.708534,,,1,,,,9.5688638E-6,39.578028,52.963182,25.443747,0
8177140.78,,5905,,7.6312,90000.328,9.1E-6,7.2783899,0.070320914,186.39265,0.2819,6.9458968,0.01022,193.33854,0.2819,0.33549641,20.028127,0.0017101716,99.75294,,,1,,,,9.6755749E-6,40.262868,52.974959,25.60905,0
8177286.23,,5905,,7.6333,90000.328,9.1E-6,7.2781656,0.070583609,185.45276,0.2605,6.9459316,0.01022,192.39869,0.2605,0.12232459,20.137094,0.0017797498,99.745462,,,1,,,,9.5770969E-6,40.056253,52.971694,25.480701,0
8177552.52,,5905,,7.6811,90000.328,9.1E-6,7.3266556,0.070513961,187.9945,0.2729,7.0665358,0.01027,195.06103,0.2729,0.21156032,20.236129,0.0021171974,99.699569,,,1,,,,9.6662293E-6,40.274188,53.679882,25.658979,0
8177699.39,,5905,,7.6898,90000.328,9.1E-6,7.3271798,0.07123902,187.50542,0.3045,7.068056,0.01027,194.57348,0.3045,0.59030688,20.200503,0.0031573305,99.551786,,,1,,,,9.6723905E-6,40.472258,53.687564,25.590394,0
8177846.67,,5905,,7.6964,90000.328,9.1E-6,7.3270868,0.071231388,187.42754,0.3328,7.0676203,0.01027,194.49516,0.3328,0.48038155,20.088143,0.0011681145,99.833706,,,1,,,,9.6970654E-6,40.401005,53.686201,25.580091,0
8178116.95,,5905,,7.7516,90000.328,9.1E-6,7.3765496,0.071537663,188.36687,0.2622,7.1929416,0.0103,195.55981,0.2622,0.42309602,20.390029,0.001899274,99.736489,,,1,,,,9.6144657E-6,40.176286,54.413484,25.535905,0
8178265.53,,5905,,7.7427,90000.328,9.1E-6,7.3770195,0.072011191,189.71329,0.2725,7.1937317,0.0103,196.90702,0.2725,0.18612191,20.284396,0.0022288234,99.686995,,,1,,,,9.7356114E-6,40.780057,54.420417,25.716794,0
8178413.05,,5905,,7.7405,90000.328,9.1E-6,7.3771804,0.071909585,188.80334,0.3705,7.1939947,0.0103,195.99733,0.3705,0.51437466,20.142709,0.0022950414,99.676855,,,1,,,,9.7597112E-6,40.568793,54.42279,25.592886,0
8178681.45,,5905,,7.8035,90000.328,9.1E-6,7.4251945,0.07174793,190.97235,0.3046,7.3162282,0.0103,198.28858,0.3046,0.49843479,20.4781,0.0030690109,99.576725,,,1,,,,9.7211419E-6,40.285417,55.133513,25.719508,0
8178830.22,,5905,,7.8012,90000.328,9.1E-6,7.4255961,0.070723892,191.98859,0.2904,7.3187054,0.0103,199.3073,0.2902,0.4989643,20.015796,,,,,1,,,,9.9575006E-6,40.9562,55.139477,25.854974,0
8178996.8,,5905,,7.7944,90000.328,9E-6,7.4247945,0.069817144,193.32681,0.2882,7.3171133,0.0103,200.64392,0.2881,0.35913206,20.360681,,,,,1,,,,9.8544802E-6,40.031591,55.127573,26.038002,0
8179267.69,,5905,,7.8517,90000.328,9.1E-6,7.4746527,0.072432888,193.32893,0.2572,7.4431427,0.0103,200.77207,0.2572,0.058347213,20.511897,0.0028435851,99.61036,,,1,,,,9.8235852E-6,40.721361,55.870433,25.864603,0
8179415.92,,5905,,7.8475,90000.328,9.1E-6,7.474998,0.07311409,193.2237,0.2387,7.4439921,0.0103,200.66769,0.2387,0.21293,20.313884,0.0020665098,99.714508,,,1,,,,9.9045776E-6,41.023794,55.875595,25.849331,0
8179564.08,,5905,,7.8489,90000.328,9E-6,7.4749877,0.072638304,193.20586,0.2463,7.4438699,0.0103,200.64973,0.2463,0.1321114,20.305175,0.0026867607,99.628411,,,1,,,,9.9158811E-6,40.627768,55.875442,25.846981,0
8179828.22,,5905,,7.9059,90000.328,9E-6,7.5232607,0.072344548,195.5735,0.217,7.5684191,0.01028,203.14192,0.217,0.37349906,20.249633,0.00092698619,99.872234,,,1,,,,1.0043777E-5,40.61035,56.599452,25.995842,0
8179975.77,,5905,,7.9036,90000.328,9.1E-6,7.523444,0.07307921,194.51301,0.1997,7.5690629,0.01028,202.08207,0.1997,0.18213774,20.221124,0.00099808353,99.862932,,,1,,,,1.0006321E-5,40.499266,56.60221,25.854251,0
8180123.08,,5905,,7.8958,90000.328,9.1E-6,7.523528,0.073009081,194.37667,0.2575,7.5692158,0.01028,201.94589,0.2575,0.061146579,20.178669,0.00082974234,99.88591,,,1,,,,1.001848E-5,40.442248,56.603474,25.835841,0
8180380.78,,5905,,7.9514,90000.328,9E-6,7.5725438,0.072906532,196.57759,0.2359,7.6972081,0.01026,204.2748,0.2359,0.4978432,20.395226,0.0015125601,99.795117,,,1,,,,1.0034858E-5,40.357339,57.34342,25.959254,0
8180528.67,,5905,,7.9447,90000.328,9.1E-6,7.5731693,0.07343841,197.02873,0.1719,7.6988506,0.01026,204.72758,0.1719,0.25935772,20.220622,0.0019017168,99.739556,,,1,,,,1.0149182E-5,40.790452,57.352893,26.016681,0
8180676.66,,5905,,7.9404,90000.328,9.1E-6,7.5721263,0.071244768,198.61341,0.2503,7.6978119,0.01026,206.31122,0.2501,0.099987284,20.24696,,,,,1,,,,1.0189738E-5,40.441244,57.337096,26.229543,0
8180946.77,,5905,,8.0084,90000.328,9E-6,7.6212604,0.073283895,198.74643,0.1984,7.8254477,0.01023,206.57188,0.1984,0.20910776,20.416032,0.0018959646,99.744648,,,1,,,,1.0142101E-5,40.49392,58.08361,26.077895,0
8181094.45,,5905,,8.0063,90000.328,9E-6,7.6220302,0.074180267,198.3678,0.2159,7.8277184,0.01023,206.19552,0.2159,0.13064822,20.367047,0.002681392,99.638404,,,1,,,,1.0157986E-5,40.832063,58.095345,26.025586,0
8181242.64,,5905,,8.0063,90000.328,9.1E-6,7.6219939,0.074196381,198.47309,0.355,7.8276596,0.01023,206.30075,0.355,0.31026099,20.436144,0.0021508162,99.71097,,,1,,,,1.0121983E-5,40.734093,58.094791,26.039524,0
8181245.67,Error: Warning: Current field is 90000.328 Oe;
8181246.02,Error: but addenda was obtained at 0.021 Oe.
8181332.95,Error: Temperature of platform does not match the system temperature : System = 8.0042 K;  Platform = 7.5846 K
8181541.41,,5905,,7.9946,90000.328,9.1E-6,7.6233514,0.07632918,199.52449,0.2923,7.832183,0.01023,207.35668,0.2921,0.71629646,20.219444,,,,,1,,,,1.0255311E-5,44.547682,58.115487,26.172805,0
8181687.91,,5905,,8.0015,90000.328,9.1E-6,7.620987,0.071911786,199.44817,0.2379,7.8264934,0.01023,207.27466,0.2377,0.20212411,20.24587,,,,,1,,,,1.0237874E-5,40.438888,58.079444,26.17091,0
8181835.61,,5905,,8.0018,90000.328,9.2E-6,7.621106,0.072217448,199.40239,0.2787,7.8270105,0.01023,207.2294,0.2785,0.2917808,20.375639,,,,,1,,,,1.0170449E-5,40.49174,58.081257,26.164494,0
8182120.61,,5905,,8.221,90000.328,9.1E-6,7.8390407,0.07551276,206.87208,0.2695,8.4125362,0.01012,215.28462,0.2695,0.16427407,20.671347,0.0023357865,99.698301,,,1,,,,1.0443744E-5,40.751279,61.45056,26.389974,0
8182271.17,,5905,,8.2228,90000.328,9.1E-6,7.8400907,0.076812717,206.20544,0.18,8.415068,0.01012,214.6205,0.18,0.15983764,20.481599,0.0020341681,99.735771,,,1,,,,1.0504328E-5,41.342693,61.467022,26.30141,0
8182418.92,,5905,,8.2329,90000.328,9.2E-6,7.8398953,0.076330376,206.74141,0.2626,8.4151789,0.01012,215.15659,0.2626,0.062024332,20.668955,0.0035327366,99.543443,,,1,,,,1.045374E-5,40.963198,61.463959,26.37043,0
8182700.55,,5905,,8.4585,90000.328,9.1E-6,8.0573108,0.078109286,214.34514,0.2796,9.0233731,0.01009,223.36851,0.2796,0.54925947,20.646755,0.0025054499,99.686133,,,1,,,,1.0849947E-5,41.33791,64.920257,26.602565,0
8182849.98,,5905,,8.4583,90000.328,9E-6,8.0581552,0.078854842,214.42292,0.2601,9.0262095,0.01009,223.44913,0.2601,0.20685032,20.794957,0.0035586718,99.556866,,,1,,,,1.0789402E-5,41.293509,64.933866,26.60943,0
8183001.45,,5905,,8.4559,90000.328,9.1E-6,8.0582997,0.078796205,215.19347,0.2567,9.0264725,0.01009,224.21994,0.2567,0.29127343,20.684711,0.0032409737,99.59307,,,1,,,,1.0880691E-5,41.589914,64.936194,26.704575,0
8183286.98,,5905,,8.6782,90000.328,9.1E-6,8.2746614,0.07971158,223.65941,0.2349,9.655981,0.01026,233.31539,0.2349,0.60387128,20.665602,0.0012950642,99.841831,,,1,,,,1.1306473E-5,41.369421,68.470022,27.029434,0
8183435.64,,5905,,8.6782,90000.328,9.1E-6,8.2760628,0.080586397,223.18389,0.244,9.6605227,0.01026,232.84441,0.244,0.22898109,20.74349,0.0019825534,99.759182,,,1,,,,1.1249837E-5,41.331203,68.493216,26.967399,0
8183585.91,,5905,,8.6808,90000.328,9.2E-6,8.2758351,0.081294682,222.28701,0.3127,9.6601632,0.01026,231.94718,0.3127,0.084772686,20.842494,0.0019577076,99.764204,,,1,,,,1.1152731E-5,41.486979,68.489447,26.859768,0
8183874.17,,5905,,8.9065,90000.328,9.1E-6,8.493282,0.082762423,230.45036,0.3104,10.318697,0.01073,240.76905,0.3104,0.47083809,20.962292,0.0028056108,99.67283,,,1,,,,1.1520361E-5,41.684987,72.135839,27.133252,0
8184026.56,,5905,,8.9093,90000.328,9.1E-6,8.4943056,0.083445872,230.62595,0.2712,10.321953,0.01073,240.9479,0.2712,0.34539226,20.828764,0.0034248112,99.597647,,,1,,,,1.1610858E-5,41.924584,72.153228,27.150653,0
8184176.97,,5905,,8.9093,90000.328,9.2E-6,8.4937495,0.081224448,230.09736,0.3097,10.322003,0.01073,240.41936,0.3095,0.820318,20.407555,,,,,1,,,,1.17809E-5,41.657528,72.143781,27.090198,0
8184461.44,,5905,,9.1317,90000.328,9.1E-6,8.7106341,0.083152974,240.43434,0.2869,11.00298,0.01154,251.43732,0.2869,0.27738065,21.048704,0.0025085093,99.714522,,,1,,,,1.1976777E-5,40.815109,75.875146,27.602393,0
8184613.25,,5905,,9.1208,90000.328,9.1E-6,8.7127294,0.085748596,239.11202,0.2738,11.00973,0.01155,250.12175,0.2738,0.125661,20.935451,0.0022385104,99.745365,,,1,,,,1.1975159E-5,42.097409,75.911654,27.443985,0
8184766.09,,5905,,9.1371,90000.328,9.1E-6,8.7120983,0.083050934,239.13695,0.3017,11.009405,0.01155,250.14635,0.3014,0.24711729,20.41103,,,,,1,,,,1.225545E-5,41.870902,75.900657,27.448835,0
8185050.55,,5905,,9.368,90000.328,9E-6,8.9309664,0.0855812,248.225,0.315,11.722419,0.01264,259.94742,0.315,0.37008852,21.260776,0.0024046189,99.73678,,,1,,,,1.2256046E-5,40.82206,79.762161,27.793744,0
8185203.89,,5905,,9.3619,90000.328,9.1E-6,8.9329548,0.088640192,246.86304,0.2994,11.72859,0.01265,258.59163,0.2994,0.11842848,21.133402,0.0035945644,99.605891,,,1,,,,1.2280287E-5,42.521552,79.797681,27.635094,0
8185356.52,,5905,,9.3726,90000.328,9.2E-6,8.9326125,0.087774494,247.53507,0.2602,11.727511,0.01265,259.26258,0.2602,0.10882496,20.910815,0.0028188528,99.687061,,,1,,,,1.2433977E-5,42.266804,79.791567,27.711385,0
[...]
8189864.3,,5905,,10.9528,90000.328,9E-6,10.58631,0.11268561,315.55384,0.591,17.8839,0.02252,333.43774,0.591,8.1798619,23.050921,0.0062333533,99.464976,,,1,,,,1.4534973E-5,48.706089,112.06996,29.807728,0
8190030.23,,5905,,10.9549,90000.328,9.1E-6,10.583046,0.10551256,316.57612,0.3227,17.872944,0.02251,334.44906,0.3219,0.10246413,21.730168,,,,,1,,,,1.5391002E-5,46.101842,112.00087,29.913516,0
8190231.25,,5905,,10.9556,90000.328,9.2E-6,10.580002,0.10469766,315.24748,0.2497,17.857113,0.02249,333.10459,0.2497,0.27337672,21.949633,0.0028615147,99.742514,,,1,,,,1.5210955E-5,43.460337,111.93644,29.796543,0
8190529.25,,5905,,11.1819,90000.328,9E-6,10.800818,0.10625479,324.32158,0.3208,18.781728,0.02358,343.10331,0.3208,0.09579819,21.978083,0.0031929965,99.718609,,,1,,,,1.5650525E-5,43.899266,116.65766,30.027503,0
8190731.72,,5905,,11.1823,90000.328,9E-6,10.799123,0.10752695,324.38428,0.2294,18.775305,0.02357,343.15958,0.2294,1.5613661,22.08396,0.0033220216,99.708479,,,1,,,,1.5579463E-5,43.956166,116.62105,30.038021,0
8190912.45,,5905,,11.1819,90000.328,9E-6,10.800474,0.10845817,324.43448,0.4014,18.782172,0.02358,343.21665,0.4014,0.066826717,22.438064,0.0038277391,99.669361,,,1,,,,1.5341528E-5,44.167921,116.65025,30.03891,0
8191258.5,,5905,,11.4099,90000.328,9E-6,11.018414,0.10940785,336.2752,0.6546,19.717019,0.02455,355.99222,0.6546,0.065841355,22.414211,0.0046779649,99.599829,,,1,,,,1.5939385E-5,44.876129,121.40545,30.519384,0
8191419.42,,5905,,11.4087,90000.328,9.2E-6,11.019385,0.10647694,334.53307,0.5516,19.722967,0.02456,354.25604,0.5511,0.15358832,21.207913,,,,,1,,,,1.6703956E-5,44.828421,121.42684,30.358599,0
8191573.45,,5905,,11.409,90000.328,9.1E-6,11.015069,0.10689559,334.61304,0.2648,19.702804,0.02454,354.31585,0.2648,0.033272241,22.16145,0.0025662186,99.779119,,,1,,,,1.6019506E-5,42.415826,121.33175,30.377753,0
8191915.34,,5905,,11.634,90000.328,9E-6,11.237875,0.10883694,341.64958,0.7692,20.687268,0.02542,362.33685,0.7688,0.53147226,22.03855,,,,,1,,,,1.6441048E-5,44.3229,126.28983,30.401617,0
8192073.58,,5905,,11.6376,90000.328,9.1E-6,11.235008,0.11140991,344.82257,0.3049,20.67069,0.0254,365.49326,0.3049,0.056253943,22.426798,0.002795106,99.765991,,,1,,,,1.6331196E-5,44.0771,126.2254,30.691796,0
8192234.86,,5905,,11.6347,90000.328,9.1E-6,11.236199,0.1132723,351.61681,0.5946,20.679151,0.02541,372.29596,0.5946,1.4343476,23.977508,0.0054543962,99.564886,,,1,,,,1.5587423E-5,44.853595,126.25218,31.293215,0
8192545.55,,5905,,11.8648,90000.328,9.1E-6,11.454578,0.11485679,355.62189,0.2874,21.660244,0.02612,377.28213,0.2862,0.066333483,22.292685,,,,,1,,,,1.6924032E-5,47.955017,131.20736,31.046267,0
8192706.41,,5905,,11.8654,90000.328,9.1E-6,11.454696,0.11396908,354.77084,0.2568,21.658085,0.02612,376.42892,0.2568,0.19058912,22.590265,0.0034294685,99.719423,,,1,,,,1.6704976E-5,44.585371,131.21006,30.97165,0
8192867.78,,5905,,11.861,90000.328,9.2E-6,11.455622,0.11491848,354.67051,0.2815,21.662592,0.02612,376.3331,0.2815,0.063183199,22.547069,0.0030455613,99.750524,,,1,,,,1.6728081E-5,45.180531,131.23128,30.960388,0
8193194.38,,5905,,12.0907,90000.328,9.1E-6,11.672497,0.11190272,366.45497,0.2958,22.6611,0.02667,389.11607,0.2946,0.069121605,22.154343,,,,,1,,,,1.7563873E-5,45.094137,136.24718,31.394738,0
8193354.39,,5905,,12.0907,90000.328,9E-6,11.674489,0.11308963,361.12432,0.48,22.67184,0.02667,383.79616,0.4793,0.74677967,22.046747,,,,,1,,,,1.740829E-5,44.308687,136.29369,30.932774,0
8193512.2,,5905,,12.0878,90000.328,9.1E-6,11.673818,0.11515098,364.46161,0.225,22.664683,0.02667,387.12629,0.225,0.16301718,22.628996,0.0024668251,99.801919,,,1,,,,1.7137631E-5,44.093493,136.27802,31.22043,0
8193809.69,,5905,,12.319,90000.328,9.2E-6,11.892394,0.118522,375.90742,0.447,23.688946,0.02705,399.59636,0.447,0.23573133,23.40752,0.0040822359,99.68652,,,1,,,,1.7118797E-5,45.257992,141.42902,31.609063,0
8193977.44,,5905,,12.3222,90000.328,9.1E-6,11.895181,0.11782102,375.61242,0.2746,23.703702,0.02706,399.31612,0.2733,0.29652361,22.41528,,,,,1,,,,1.781446E-5,46.81504,141.49533,31.576856,0
8194137.72,,5905,,12.319,90000.328,9E-6,11.894081,0.11818791,376.35361,0.3282,23.696136,0.02705,400.04975,0.3282,0.19605696,23.126977,0.0042761644,99.667336,,,1,,,,1.7349078E-5,44.83056,141.46917,31.642092,0
8194468.98,,5905,,12.5448,90000.328,9.1E-6,12.112825,0.11769664,387.77142,0.2855,24.743643,0.02734,412.51507,0.2842,0.077011044,22.748648,,,,,1,,,,1.8133608E-5,46.253954,146.72054,32.013293,0
8194631.67,,5905,,12.5449,90000.328,9.1E-6,12.114121,0.12095024,386.1711,0.2637,24.745504,0.02734,410.9166,0.2637,0.12271118,23.099681,0.0033913172,99.740067,,,1,,,,1.7829794E-5,45.497297,146.75194,31.877764,0
8194796.39,,5905,,12.5449,90000.328,9.1E-6,12.117554,0.12239838,386.47323,0.3703,24.763267,0.02734,411.23649,0.3703,0.079959753,23.307686,0.0035690336,99.728849,,,1,,,,1.7686189E-5,46.199361,146.83511,31.893667,0
8195103.8,,5905,,12.775,90000.328,9.1E-6,12.33406,0.12388851,397.97071,0.4098,25.818063,0.02763,423.78877,0.4098,0.15948127,23.661996,0.0042767926,99.683303,,,1,,,,1.796029E-5,46.615372,152.12905,32.265993,0
8195296.34,,5905,,12.775,90000.328,9.1E-6,12.332832,0.12209046,397.4095,0.4318,25.816093,0.02763,423.22559,0.4309,0.078208944,22.778891,,,,,1,,,,1.8579728E-5,47.323992,152.09875,32.223702,0
8195458.88,,5905,,12.7709,90000.328,9.1E-6,12.331023,0.12258086,397.97068,0.3434,25.802683,0.02762,423.77336,0.3434,0.056117026,23.281626,0.0028766434,99.783557,,,1,,,,1.8236877E-5,45.557782,152.05413,32.273938,0
8195760.55,,5905,,12.9989,90000.328,9.1E-6,12.549231,0.12569488,408.39924,0.3825,26.890019,0.02801,435.28926,0.3825,0.36830842,23.900575,0.0047304339,99.657622,,,1,,,,1.8267591E-5,46.563252,157.48319,32.543767,0
8195929.38,,5905,,12.9989,90000.328,9.1E-6,12.552718,0.1280448,409.20118,0.2824,26.906398,0.02802,436.10758,0.2824,0.10510464,23.586879,0.0028411645,99.791594,,,1,,,,1.8523415E-5,47.80115,157.57072,32.598613,0
8196095.77,,5905,,12.9989,90000.328,9.1E-6,12.552588,0.12704807,408.21503,0.3289,26.906444,0.02802,435.12147,0.3289,0.057459591,23.483778,0.0038933505,99.713596,,,1,,,,1.8575447E-5,47.173758,157.56747,32.520387,0
8196403.48,,5905,,13.2269,90000.328,9.1E-6,12.769574,0.12785186,420.33996,0.4401,28.012406,0.02862,448.35236,0.4401,0.14232582,24.085255,0.0045747734,99.674929,,,1,,,,1.8668593E-5,46.967555,163.06202,32.917305,0
8196572.88,,5905,,13.2269,90000.328,9E-6,12.772841,0.13037464,420.1516,0.2591,28.02817,0.02863,448.17977,0.2591,0.21790825,23.766361,0.0034432643,99.752413,,,1,,,,1.8898876E-5,48.170511,163.14546,32.894138,0
8196740.58,,5905,,13.2269,90000.328,9.1E-6,12.772737,0.12937512,420.09228,0.2961,28.028446,0.02863,448.12073,0.2961,0.097357361,23.742225,0.0033651307,99.757827,,,1,,,,1.8914693E-5,47.532721,163.1428,32.889763,0
8197043.84,,5905,,13.4512,90000.328,9.1E-6,12.993524,0.13048612,431.85543,0.4557,29.180794,0.02956,461.03622,0.4557,0.14169675,24.353354,0.0049260099,99.657945,,,1,,,,1.8988141E-5,47.48445,168.83166,33.236206,0
8197216.41,,5905,,13.4556,90000.328,9.1E-6,12.997136,0.13310211,432.28793,0.2773,29.197382,0.02958,461.48531,0.2773,2.6289912,24.062332,0.0034080385,99.760585,,,1,,,,1.9219137E-5,48.706709,168.92554,33.260246,0
8197387.02,,5905,,13.4588,90000.328,9.1E-6,12.997328,0.13207958,429.85498,0.2763,29.19815,0.02958,459.05313,0.2763,0.090100046,23.685197,0.0025465684,99.819233,,,1,,,,1.9412215E-5,48.124664,168.93052,33.072566,0
8197747.91,,5905,,13.6831,90000.328,9.1E-6,13.214017,0.12904295,438.76574,0.568,30.362306,0.0309,469.12804,0.5671,0.23693735,23.65102,,,,,1,,,,1.9835425E-5,47.370393,174.61023,33.20457,0
8197915.56,,5905,,13.6831,90000.328,9E-6,13.217408,0.13256606,442.81142,0.6088,30.375258,0.03092,473.18667,0.6088,3.7172062,24.092601,0.0018813046,99.869885,,,1,,,,1.9662742E-5,47.30204,174.69988,33.502137,0
8198158.14,,5905,,13.6833,90000.328,9.1E-6,13.217205,0.13533018,441.01784,1.107,30.375225,0.03092,471.39307,1.107,0.032947497,24.430549,0.0026688714,99.818541,,,1,,,,1.9325936E-5,48.185202,174.69452,33.366951,0
8198469.03,,5905,,13.9092,90000.328,9E-6,13.435944,0.13597778,456.98007,0.4815,31.569433,0.03259,488.5495,0.4815,0.13024273,24.830991,0.0046482568,99.689571,,,1,,,,1.9728605E-5,48.861097,180.52459,34.011758,0
8198644.7,,5905,,13.9087,90000.328,9.1E-6,13.439374,0.13801772,456.87023,0.3096,31.587039,0.03262,488.45727,0.3096,0.22008865,24.543654,0.0038623347,99.739317,,,1,,,,1.9947084E-5,49.661982,180.61679,33.994903,0
8198842.45,,5905,,13.9086,90000.328,9.1E-6,13.439453,0.13715379,456.8189,0.303,31.588538,0.03262,488.40744,0.303,1.488854,24.547973,0.0038426655,99.740729,,,1,,,,1.9941292E-5,49.087307,180.6189,33.990885,0
8199153.59,,5905,,14.1363,90000.328,9E-6,13.653852,0.1380151,469.27668,0.4879,32.786273,0.03449,502.06295,0.4879,0.17254329,25.069684,0.0051623908,99.661781,,,1,,,,2.0086086E-5,49.095946,186.42769,34.369544,0
8199354.83,,5905,,14.1363,90000.328,9.1E-6,13.657895,0.14066017,469.18882,0.377,32.808178,0.03453,501.997,0.377,1.010603,24.820678,0.0047544555,99.685673,,,1,,,,2.0280671E-5,50.139368,186.5381,34.352937,0
8199530.94,,5905,,14.1379,90000.328,9E-6,13.657735,0.1394565,471.28753,0.4979,32.806703,0.03452,504.09423,0.4979,0.41097576,24.869073,0.0044080381,99.708048,,,1,,,,2.0321812E-5,49.641357,186.53372,34.507006,0
8199850.39,,5905,,14.3689,90000.328,9.1E-6,13.878602,0.14077152,482.92082,0.4994,34.065586,0.03658,516.98641,0.4994,0.1782454,25.338666,0.0049029598,99.684889,,,1,,,,2.045935E-5,49.738146,192.61559,34.796071,0
8200028.75,,5905,,14.3641,90000.328,9E-6,13.882263,0.14323029,482.4847,0.3614,34.085307,0.03662,516.57,0.3614,0.19870461,25.022,0.003777888,99.754569,,,1,,,,2.0688951E-5,50.677332,192.71722,34.755479,0
8200204.98,,5905,,14.3594,90000.328,9.1E-6,13.881925,0.14198708,483.00635,0.3878,34.084075,0.03661,517.09043,0.3878,0.10321962,24.976628,0.0033254206,99.783407,,,1,,,,2.0742187E-5,50.043999,192.70784,34.793903,0
8200524.39,,5905,,14.591,90000.328,9.1E-6,14.102892,0.14296199,496.24266,0.4802,35.368165,0.0387,531.61083,0.4802,0.15958889,25.593178,0.0048629574,99.693346,,,1,,,,2.0827268E-5,49.953255,198.89156,35.187298,0
8200704.27,,5905,,14.591,90000.328,9.2E-6,14.106624,0.14584079,496.12434,0.3579,35.389059,0.03873,531.5134,0.3579,0.18187708,25.311491,0.0040984717,99.738954,,,1,,,,2.104679E-5,51.186355,198.99685,35.169601,0
8200881.72,,5905,,14.5915,90000.328,9.1E-6,14.106682,0.1448054,496.11345,0.3965,35.390207,0.03873,531.50366,0.3965,0.078960442,25.244229,0.0037569426,99.760119,,,1,,,,2.1098578E-5,50.622982,198.99848,35.168684,0
8201226.58,,5905,,14.8154,90000.328,9.1E-6,14.321986,0.14426688,516.09663,1.145,36.664612,0.04068,552.76124,1.145,0.13663688,26.237076,0.0099779129,99.383088,,,1,,,,2.1181991E-5,50.488459,205.11928,36.03527,0
8201410.02,,5905,,14.8155,90000.328,9E-6,14.328901,0.15105416,509.30127,1.021,36.705465,0.04073,546.00674,1.021,0.02977775,26.087469,0.0059461335,99.635525,,,1,,,,2.0996477E-5,52.474152,205.31742,35.543637,0
8201620,,5905,,14.8204,90000.328,9.2E-6,14.32612,0.15227955,510.19932,0.7636,36.69286,0.04072,546.89218,0.7636,9.7540515,26.987241,0.0082221994,99.511472,,,1,,,,2.0351452E-5,52.174939,205.23772,35.613223,0
8201951.52,,5905,,15.0477,90000.328,9.1E-6,14.546477,0.15324299,523.66171,0.4757,38.008806,0.04249,561.67051,0.4757,0.2989,26.107138,0.0047091978,99.713492,,,1,,,,2.1567802E-5,53.974482,211.59998,35.999213,0
8202160.75,,5905,,15.0479,90000.328,9.1E-6,14.548186,0.15134968,523.32075,0.4687,38.020418,0.04251,561.34117,0.4687,0.067307824,25.812281,0.004146145,99.745138,,,1,,,,2.179536E-5,52.214276,211.64973,35.971545,0
8202367.09,,5905,,15.0426,90000.328,9.1E-6,14.548861,0.14974081,522.65758,0.7833,38.023662,0.04251,560.68125,0.7833,0.015308184,25.397477,0.0024480976,99.847353,,,1,,,,2.2105589E-5,51.624562,211.66936,35.924295,0
8202683.14,,5905,,15.273,90000.328,9.1E-6,14.76865,0.15023645,537.0211,0.5403,39.367418,0.04403,576.38852,0.5403,0.30627368,26.481438,0.0054347901,99.676719,,,1,,,,2.1827048E-5,50.794954,218.11302,36.362233,0
8202868.88,,5905,,15.273,90000.328,9.1E-6,14.773731,0.15495393,537.00897,0.3896,39.396561,0.04406,576.40553,0.3896,0.14929374,26.119283,0.0040245137,99.757593,,,1,,,,2.2114751E-5,52.962876,218.26312,36.348908,0
8203078.41,,5905,,15.273,90000.328,9.1E-6,14.773475,0.15365872,537.05975,0.3486,39.395973,0.04406,576.45573,0.3486,0.4563043,26.11412,0.0040116036,99.758301,,,1,,,,2.2120913E-5,52.238566,218.25556,36.352974,0
8203398.64,,5905,,15.5016,90000.328,9E-6,14.986651,0.15477739,550.65429,0.5053,40.718322,0.04533,591.37261,0.5053,0.18005521,26.727098,0.0055779709,99.673697,,,1,,,,2.2189148E-5,52.228241,224.59972,36.742984,0
8203585.45,,5905,,15.5016,90000.328,9E-6,14.990884,0.15775728,551.08287,0.394,40.743081,0.04535,591.82595,0.394,0.14943652,26.331931,0.0034277051,99.79663,,,1,,,,2.2515318E-5,53.454196,224.72662,36.761198,0
8203769.14,,5905,,15.502,90000.328,9.1E-6,14.997153,0.15714309,550.81252,0.7087,40.78517,0.04539,591.59769,0.7087,0.054692868,26.695515,0.0051323134,99.699821,,,1,,,,2.2218791E-5,52.663863,224.91461,36.727805,0
8204099.63,,5905,,15.7256,90000.328,9E-6,15.214514,0.15870011,565.96624,0.5025,42.151574,0.04657,608.11782,0.5025,1.1424643,26.882389,0.0047662952,99.724601,,,1,,,,2.267554E-5,53.39103,231.48143,37.199102,0
8204289.02,,5905,,15.7308,90000.328,9.2E-6,15.217602,0.16078896,565.36598,0.3832,42.17165,0.04658,607.53763,0.3832,0.14447624,26.676958,0.0041212346,99.76042,,,1,,,,2.2821243E-5,53.764779,231.57542,37.152107,0
8204475.69,,5905,,15.7308,90000.328,9E-6,15.217963,0.16005639,565.26321,0.4242,42.173127,0.04659,607.43633,0.4242,0.16187689,26.6143,0.0032733316,99.809368,,,1,,,,2.2861436E-5,53.353916,231.58641,37.144472,0
8204800.03,,5905,,15.956,90000.328,9E-6,15.429026,0.16315946,577.75738,0.8564,43.528489,0.04772,621.28587,0.8564,0.40598391,28.050535,0.0076424386,99.580542,,,1,,,,2.2229509E-5,53.228601,238.05484,37.446134,0
8205022.08,,5905,,15.956,90000.328,9E-6,15.429916,0.16759812,578.36979,0.3502,43.526828,0.04771,621.89661,0.3502,0.54792428,26.975273,0.0041022149,99.765971,,,1,,,,2.3101104E-5,56.10107,238.08231,37.483664,0
8205210.02,,5905,,15.9558,90000.328,9.1E-6,15.428602,0.16357986,577.98331,0.5345,43.519069,0.04771,621.50238,0.5345,0.10776603,26.843485,0.003126942,99.820882,,,1,,,,2.3188755E-5,53.950546,238.04177,37.461807,0
8205540.41,,5905,,16.182,90000.328,9E-6,15.651289,0.16442752,593.63958,0.5873,44.968467,0.04896,638.60804,0.5873,0.10488297,27.625987,0.0054277855,99.699187,,,1,,,,2.3176489E-5,53.686971,244.96285,37.929117,0
8205731.92,,5905,,16.1819,90000.328,9.1E-6,15.656017,0.16856278,593.75888,0.466,44.996971,0.04899,638.75585,0.466,0.15329968,27.3446,0.0047789985,99.732583,,,1,,,,2.3413619E-5,55.251975,245.11088,37.925283,0
8205921.94,,5905,,16.182,90000.328,9.1E-6,15.656226,0.1675138,593.41187,0.4926,44.999199,0.04899,638.41107,0.4926,0.084646889,27.245304,0.0043197774,99.757575,,,1,,,,2.3481173E-5,54.689199,245.11741,37.902613,0
8206257.48,,5905,,16.4058,90000.328,9.1E-6,15.871899,0.16861975,607.24792,0.6349,46.4234,0.05036,653.67132,0.6349,0.31549585,27.917367,0.0065773242,99.641967,,,1,,,,2.3487129E-5,54.490608,251.91718,38.259311,0
8206480.27,,5905,,16.4113,90000.328,9.1E-6,15.876116,0.17235608,608.67262,0.4213,46.450993,0.05039,655.12361,0.4213,0.85105074,27.747446,0.0051636666,99.716927,,,1,,,,2.3668098E-5,55.834733,252.05105,38.338888,0
8206673.22,,5905,,16.4113,90000.328,9E-6,15.878794,0.17308794,606.86388,0.7146,46.470485,0.05041,653.33436,0.7146,0.2807181,28.055545,0.0052914463,99.713937,,,1,,,,2.3344827E-5,55.494892,252.1361,38.218512,0
8207008,,5905,,16.6391,90000.328,9.1E-6,16.096823,0.17401808,623.35386,0.6075,47.929019,0.05204,671.28288,0.6075,0.11300592,28.24647,0.0061136186,99.672776,,,1,,,,2.3832487E-5,56.11109,259.1077,38.725273,0
8207231.56,,5905,,16.6335,90000.328,9E-6,16.100586,0.17648506,623.13138,0.419,47.955109,0.05207,671.08649,0.419,0.486327,28.039659,0.0052299653,99.71832,,,1,,,,2.3991776E-5,56.49294,259.22887,38.702404,0
8207426.36,,5905,,16.6335,90000.328,9.1E-6,16.10087,0.17551121,622.9638,0.5232,47.95551,0.05207,670.91931,0.5232,0.077198205,27.856232,0.0044423217,99.759295,,,1,,,,2.4135182E-5,56.079318,259.23801,38.691314,0
8207766.86,,5905,,16.864,90000.328,9E-6,16.320362,0.17737749,638.07084,0.8763,49.456534,0.05406,687.52738,0.8763,0.91187884,29.046971,0.0073914827,99.617773,,,1,,,,2.3747746E-5,55.712464,266.35422,39.096611,0
8207968.06,,5905,,16.864,90000.328,9.1E-6,16.327915,0.18208963,638.44434,0.4911,49.501276,0.05412,687.94562,0.4911,0.2400657,28.221339,0.0045879913,99.756118,,,1,,,,2.4428125E-5,58.093941,266.60081,39.101401,0
8208191.22,,5905,,16.8658,90000.328,9.2E-6,16.324307,0.17898269,638.10075,0.5385,49.478398,0.05409,687.57915,0.5385,0.058338234,28.129122,0.004781641,99.744987,,,1,,,,2.4497509E-5,56.442678,266.48299,39.088995,0
8208528.45,,5905,,17.0909,90000.328,9E-6,16.544598,0.1795297,648.61102,0.7117,51.000338,0.05642,699.61136,0.7117,0.18854689,28.170214,0.0058167558,99.6938,,,1,,,,2.4900722E-5,56.258244,273.72372,39.203795,0
8208724.14,,5905,,17.0945,90000.328,9E-6,16.548971,0.181859,653.88766,0.4822,51.033998,0.05647,704.92165,0.4822,0.25928186,28.586754,0.0048415246,99.747344,,,1,,,,2.4712784E-5,56.340427,273.86845,39.512284,0
8208923,,5905,,17.0909,90000.328,9.1E-6,16.547393,0.18336632,653.50878,0.5796,51.021024,0.05645,704.52981,0.5796,0.060239245,28.417322,0.004202875,99.779477,,,1,,,,2.4839417E-5,57.173508,273.8162,39.493157,0
8209264.95,,5905,,17.3201,90000.328,9.1E-6,16.762292,0.18425364,668.83973,0.5781,52.533389,0.05903,721.37312,0.5781,0.3457925,29.164624,0.0066301343,99.662491,,,1,,,,2.480655E-5,56.834645,280.97444,39.901448,0
8209526.56,,5905,,17.3201,90000.328,9.1E-6,16.77358,0.18898442,656.92009,1.638,52.605167,0.05916,709.52526,1.638,0.032226789,27.781636,0.0032107316,99.831436,,,1,,,,2.5576332E-5,58.329248,281.35299,39.163976,0
8209747.66,,5905,,17.3143,90000.328,9.1E-6,16.771847,0.18024533,660.37227,1.464,52.6105,0.05917,712.98277,1.463,0.73474881,28.093701,,,,,1,,,,2.5378741E-5,55.563272,281.29485,39.373855,0
8210090.39,,5905,,17.5472,90000.328,9.1E-6,16.98656,0.18644559,684.48964,0.7401,54.131213,0.06198,738.62085,0.7401,0.22901661,29.735653,0.0073048142,99.637345,,,1,,,,2.4917234E-5,56.187402,288.54323,40.295954,0
8210294.91,,5905,,17.5507,90000.328,9.1E-6,16.994321,0.19399559,683.71745,0.4471,54.181667,0.06208,737.89911,0.4471,0.85056036,29.044302,0.0041255631,99.790907,,,1,,,,2.5451695E-5,59.471306,288.80693,40.232114,0
8210495.88,,5905,,17.5448,90000.328,9.1E-6,16.993606,0.19088687,684.50754,0.567,54.176204,0.06207,738.68374,0.567,0.12685847,28.919896,0.0045826336,99.766451,,,1,,,,2.5593759E-5,58.088603,288.78264,40.2803,0
8210843.13,,5905,,17.7736,90000.328,9.2E-6,17.211269,0.19201539,701.28931,0.7107,55.751802,0.06515,757.04112,0.7107,0.22269881,29.789398,0.0062241212,99.693058,,,1,,,,2.5480263E-5,57.839792,296.22779,40.745938,0
8211077.2,,5905,,17.773,90000.328,9.1E-6,17.217212,0.19742907,701.09204,0.4981,55.792479,0.06523,756.88452,0.4981,1.1362589,29.487485,0.0048065017,99.760864,,,1,,,,2.5720793E-5,59.578797,296.43239,40.720416,0
8211309.06,,5905,,17.773,90000.328,9E-6,17.217127,0.19622348,701.00074,0.4844,55.793376,0.06523,756.79411,0.4844,0.75269814,29.472259,0.0050794696,99.747159,,,1,,,,2.5734041E-5,58.97497,296.42947,40.715314,0
8211654.25,,5905,,18.0005,90000.328,9.1E-6,17.435314,0.19754505,716.7705,0.7582,57.390165,0.06848,774.16067,0.7582,0.19709222,30.129819,0.0065289706,99.68357,,,1,,,,2.5764102E-5,58.944518,303.99016,41.110273,0
8211863.06,,5905,,17.9999,90000.328,9.1E-6,17.440972,0.20202641,717.37932,0.5893,57.428299,0.06856,774.80761,0.5893,0.15279348,29.786729,0.0051424569,99.747974,,,1,,,,2.606819E-5,60.259637,304.18749,41.131843,0
8212098.83,,5905,,18.0005,90000.328,9.1E-6,17.44064,0.20067219,717.02487,0.5378,57.427252,0.06856,774.45212,0.5378,0.7831797,29.773412,0.0050697347,99.751535,,,1,,,,2.6067082E-5,59.573457,304.17591,41.112303,0