File: PPMS_Data_and_Plotting/Data/RuCl3/Data/Heat Capacity/28-03-2025_RuCl3_TB001_0T _001_110-180K1.csv
[Header]
TITLE,28-03-2025_RuCl3_TB001_0T _001_110-180K
BYAPP,HeatCapacity,3.9.6,1.7
INFO,33,MASS:Sample Mass (mg)
INFO,0.1,MASSERR:Sample Mass Error (mg)
INFO,207.43,MOLWGHT:Formula Weight (g/mole)
INFO,4,ATOMS:Atoms per Formula Unit
INFO,PPMS Heat Capacity Option 3.9.6 Build 3,APPNAME
DATATYPE,TIME,1
DATATYPE,COMMENT,2
STARTUPAXIS, X, 8, LINEAR, AUTO
STARTUPAXIS, Y1, 10, LINEAR, AUTO
[Data]
Time Stamp (Seconds),Comment (),System Status (Code),Puck Temp (Kelvin),System Temp (Kelvin),Field (Oersted),Pressure (Torr),Sample Temp (Kelvin),Temp Rise (Kelvin),Samp HC (J/mole-K),Samp HC Err (J/mole-K),Addenda HC (µJ/K),Addenda HC Err (µJ/K),Total HC (µJ/K),Total HC Err (µJ/K),Fit Deviation (ChiSquare),Time Const tau1 (seconds),Time Const tau2 (seconds),Sample Coupling (Percent),Debye Temp (Kelvin),Debye Temp Err (Kelvin),Cal Correction (Factor),Therm Resist (Ohms),Htr Resist (Ohms),Puck Resist (Ohms),Wire Cond (W/K),Meas Time (seconds),Temp Squared (K^2),Samp HC/Temp (J/mole-K/K),Addenda Offset HC (µJ/K)
7803812.73,,5905,,130.004,0.316,9.1E-6,129.57584,2.6755718,68.418991,0.2159,3109.9363,2.502,13994.701,9.597,9.8311308,125.85666,0.14832527,99.317144,370.86022,2.09,1,,,,0.00011165859,192.3246,16789.899,0.52802274,0
7804850.59,,5905,,130.004,0.316,9.1E-6,129.80393,3.1325085,68.68698,0.221,3118.7377,2.506,14046.136,11.81,3.9029016,125.63029,0.15063067,99.304841,369.42282,2.209,1,,,,0.0001122796,251.71331,16849.061,0.52915947,0
7805886.44,,5905,,130.005,0.316,9.1E-6,129.79857,3.1221286,68.653151,0.2183,3118.4496,2.506,14040.467,10.55,3.5732993,125.13075,0.14238198,99.340484,369.67139,2.146,1,,,,0.00011265765,251.26058,16847.668,0.52892072,0
7806973.59,,5905,,131.373,0.316,9E-6,131.0434,3.0902223,69.390299,0.2474,3172.0736,2.533,14211.363,20.74,1.0507516,129.19232,0.20981815,99.061449,367.41145,2.692,1,,,,0.00011063152,250.2615,17172.373,0.52952151,0
7808035.44,,5905,,131.414,0.316,9.1E-6,131.20814,3.2170744,69.222138,0.2275,3178.9544,2.536,14191.491,14,2.0113457,126.66018,0.16656737,99.242259,369.19953,2.356,1,,,,0.00011255966,258.38463,17215.577,0.52757501,0
7808951.03,,5905,,131.373,0.316,9.1E-6,131.20348,3.1828499,69.118284,0.2225,3178.7906,2.536,14174.806,11.93,4.7348796,126.05037,0.15344889,99.29921,370.00534,2.25,1,,,,0.00011293168,253.32036,17214.353,0.52680222,0
7810048.58,,5905,,132.761,0.316,9.1E-6,132.45146,3.1037618,69.282085,0.2151,3231.3777,2.56,14253.452,7.433,0.62064236,122.20277,0.10711135,99.499533,372.2208,2.05,1,,,,0.00011698884,252.10073,17543.389,0.52307528,0
7810932.61,,5905,,132.761,0.316,9.1E-6,132.54192,3.1243095,69.140878,0.2152,3235.5845,2.562,14235.194,7.835,8.0767561,121.31136,0.089648264,99.578889,373.59989,2.068,1,,,,0.00011764079,244.40553,17567.361,0.5216529,0
7811809.25,,5905,,132.757,0.316,9E-6,132.52368,3.1348215,69.511246,0.2211,3235.4824,2.562,14294.014,10.69,6.6542898,125.12882,0.15004102,99.314318,370.59826,2.221,1,,,,0.00011470701,242.62272,17562.527,0.52451942,0
7812902.45,,5905,,134.115,0.316,9.1E-6,133.81332,3.1392194,70.295499,0.2296,3290.3091,2.586,14473.607,13.62,0.9916806,125.65779,0.16923691,99.232084,367.89329,2.412,1,,,,0.0001157156,250.25763,17906.005,0.52532512,0
7814066.31,,5905,,134.116,0.316,9E-6,133.93635,3.2205775,70.10367,0.2264,3295.6392,2.588,14448.419,12.47,0.097028043,124.03646,0.13924256,99.361617,369.77728,2.351,1,,,,0.00011693168,251.31558,17938.946,0.52341034,0
7814962.27,,5905,,134.154,0.316,9.1E-6,134.00622,3.1894557,69.703155,0.2195,3298.3077,2.589,14387.37,9.485,0.17507933,121.14682,0.090150602,99.578515,373.19799,2.189,1,,,,0.00011905862,248.07293,17957.666,0.52014866,0
7816022.05,,5905,,135.543,0.316,9.1E-6,135.21535,3.1064841,70.32203,0.2197,3350.1986,2.611,14537.717,8.532,0.34275826,122.68523,0.12646196,99.418125,371.53202,2.177,1,,,,0.00011890721,242.29364,18283.19,0.52007433,0
7816910.5,,5905,,135.502,0.316,9.1E-6,135.34803,3.1931009,70.159951,0.2312,3355.7126,2.614,14517.446,14.46,0.039643303,120.03992,0.08272154,99.611968,373.21646,2.479,1,,,,0.00012121716,245.37046,18319.089,0.518367,0
7817780.67,,5905,,135.503,0.316,9E-6,135.36492,3.1720907,70.052707,0.2181,3356.8072,2.614,14501.479,7.953,2.4302701,121.38957,0.099357575,99.539512,374.13632,2.142,1,,,,0.000119789,240.07984,18323.662,0.51751004,0
7818970.25,,5905,,136.921,0.316,9.1E-6,136.61692,3.1516414,70.988507,0.2242,3410.5989,2.637,14704.147,10.05,1.3473312,124.11119,0.15186685,99.312269,369.90114,2.298,1,,,,0.00011896017,242.77913,18664.182,0.51961725,0
7819992.16,,5905,,136.88,0.316,9.1E-6,136.72893,3.2637296,70.898571,0.2332,3415.2673,2.639,14694.508,14.42,0.021304327,122.13388,0.11971141,99.450031,370.94517,2.524,1,,,,0.00012070716,248.22238,18694.8,0.5185338,0
7820877.3,,5905,,136.921,0.316,9.2E-6,136.79035,3.2431113,70.625679,0.2191,3418.0065,2.64,14653.833,7.498,18.053226,121.98637,0.11252333,99.483755,373.3597,2.158,1,,,,0.00012049362,244.26776,18711.601,0.51630599,0
7821949.03,,5905,,138.276,0.316,9.1E-6,137.9838,3.1928252,71.024695,0.2223,3468.8593,2.662,14768.165,8.863,0.34646635,121.51078,0.10840015,99.503174,373.30125,2.26,1,,,,0.00012189346,243.97274,19039.53,0.51473212,0
7822829.34,,5905,,138.277,0.316,9.2E-6,138.10702,3.2792502,71.037136,0.2286,3474.8385,2.664,14776.123,12.22,0.1414026,123.38246,0.13741092,99.380141,373.53108,2.439,1,,,,0.00012019615,243.02156,19073.548,0.51436297,0
7823724.98,,5905,,138.273,0.316,9E-6,138.08807,3.3078278,71.361044,0.2275,3474.0553,2.664,14826.87,11.25,0.22690811,123.86741,0.1490579,99.328462,370.78401,2.397,1,,,,0.00012017456,246.76491,19068.316,0.51677919,0
7824803.5,,5905,,139.666,0.316,9.1E-6,139.36183,3.2587181,71.84625,0.2255,3528.3554,2.688,14958.362,9.345,3.178228,123.38515,0.15201904,99.315625,370.12468,2.334,1,,,,0.00012172146,247.73482,19421.719,0.51553751,0
7825698.3,,5905,,139.666,0.316,9.1E-6,139.52262,3.3195273,71.463526,0.226,3535.1139,2.691,14904.233,10.29,0.1288024,120.3119,0.095638115,99.560328,373.77373,2.375,1,,,,0.00012419854,246.7703,19466.563,0.51220027,0
7826569.91,,5905,,139.624,0.316,9.1E-6,139.49755,3.2999491,71.765572,0.2275,3534.8839,2.691,14952.055,10.65,6.642867,124.26317,0.16024343,99.284789,371.16449,2.403,1,,,,0.00012083176,240.62381,19459.567,0.51445757,0
7827651.03,,5905,,141.021,0.316,9.1E-6,140.77721,3.3235372,72.663649,0.2474,3589.8668,2.718,15149.913,17.94,18.856444,127.02851,0.21622232,99.057077,366.92839,2.847,1,,,,0.00011992601,248.52635,19818.222,0.51616061,0
7828696.47,,5905,,141.022,0.316,9.1E-6,140.9272,3.4411265,72.522051,0.24,3596.2968,2.721,15133.816,15.33,0.65826093,125.39533,0.18929423,99.16557,368.52681,2.705,1,,,,0.00012127997,254.05702,19860.476,0.51460648,0
7829731.22,,5905,,141.021,0.316,9.1E-6,140.93823,3.429708,72.350229,0.2383,3596.9273,2.721,15107.112,14.87,0.77011631,125.71262,0.18537276,99.186045,370.0202,2.674,1,,,,0.00012074512,250.79066,19863.586,0.51334707,0
7830822.2,,5905,,142.441,0.316,9E-6,142.21623,3.3576543,72.617415,0.2263,3651.0074,2.749,15203.698,8.431,1.2959495,122.2215,0.14427475,99.352425,371.07706,2.358,1,,,,0.00012486333,251.42525,20225.456,0.51061271,0
7831708.94,,5905,,142.4,0.316,9.1E-6,142.29664,3.3651583,72.393804,0.2431,3654.4596,2.751,15171.576,16.66,0.024714985,119.2465,0.092170532,99.577015,373.21165,2.799,1,,,,0.00012754038,244.44301,20248.334,0.50875273,0
7832573.33,,5905,,142.399,0.316,9.2E-6,142.30007,3.3221954,72.175728,0.2313,3654.7019,2.751,15137.125,11.96,0.16304474,118.72947,0.08239472,99.620865,375.09648,2.536,1,,,,0.00012777195,238.49299,20249.31,0.50720796,0
7833735.94,,5905,,143.796,0.316,9.1E-6,143.49497,3.2770405,72.823303,0.225,3706.3352,2.78,15291.781,7.005,0.61715216,120.96896,0.12746643,99.425675,372.62513,2.308,1,,,,0.00012683036,237.45895,20590.807,0.50749725,0
7834614.77,,5905,,143.796,0.316,9.1E-6,143.63865,3.4001101,72.639044,0.227,3712.7679,2.783,15268.9,8.833,2.2787738,120.93878,0.13221788,99.405415,374.6005,2.405,1,,,,0.00012668618,241.93791,20632.063,0.5057068,0
7835493.19,,5905,,143.791,0.316,9E-6,143.60985,3.4144338,73.055774,0.2307,3711.9517,2.783,15334.381,10.33,3.1191547,123.44765,0.16523414,99.269643,370.90081,2.501,1,,,,0.00012474339,241.87756,20623.788,0.50871006,0
7836569.7,,5905,,145.17,0.316,9.1E-6,144.87053,3.4018285,73.415164,0.2326,3765.9058,2.815,15445.511,10.82,0.72287401,122.9562,0.17157428,99.242305,370.99878,2.563,1,,,,0.00012616716,246.89531,20987.469,0.50676398,0
7837459.61,,5905,,145.17,0.316,9E-6,145.03376,3.4531993,73.056153,0.2313,3772.6301,2.819,15395.12,10.66,0.15424467,119.24931,0.099042243,99.550774,374.57501,2.544,1,,,,0.00012943259,245.9124,21034.792,0.50371826,0
7838325.52,,5905,,145.163,0.316,9.1E-6,145.00112,3.4313104,73.229042,0.2332,3772.2484,2.819,15422.243,11.39,3.2156332,123.67835,0.17506443,99.233067,372.97073,2.591,1,,,,0.0001252471,238.49862,21025.325,0.50502397,0
7839403.53,,5905,,146.544,0.316,9.1E-6,146.36377,3.438144,74.049669,0.2374,3830.4051,2.855,15610.953,12.35,2.5341567,123.21073,0.18338397,99.195248,369.17799,2.701,1,,,,0.00012728749,247.35671,21422.354,0.50592895,0
7840420.58,,5905,,146.576,0.316,9.1E-6,146.47619,3.5089956,74.081998,0.2414,3835.5385,2.858,15621.23,14.1,0.10317333,122.72133,0.17079293,99.24792,369.17328,2.803,1,,,,0.00012784009,246.42146,21455.276,0.50576135,0
7841432.16,,5905,,146.586,0.316,9.1E-6,146.47142,3.5200502,74.061643,0.2396,3835.6334,2.858,15618.086,13.36,1.2023498,124.00216,0.1881272,99.180191,369.34276,2.76,1,,,,0.00012654353,245.44265,21453.878,0.50563886,0
7842510.45,,5905,,147.965,0.316,9.1E-6,147.73086,3.4956251,74.606512,0.2556,3889.9746,2.893,15759.111,18.96,1.5758976,125.47499,0.245872,98.944419,367.61185,3.126,1,,,,0.00012635719,248.00433,21824.407,0.50501643,0
7843542.41,,5905,,147.922,0.316,9.1E-6,147.8661,3.6136154,74.561844,0.2572,3896.171,2.897,15758.201,19.54,1.7290944,125.96355,0.23360311,99.002184,368.3515,3.16,1,,,,0.00012581706,250.94999,21864.383,0.50425246,0
7844579.03,,5905,,147.922,0.316,9.1E-6,147.8744,3.6050449,74.625003,0.2556,3896.2388,2.897,15768.317,18.97,1.3127601,124.42052,0.23127183,98.999463,367.80211,3.13,1,,,,0.00012746148,251.9271,21866.838,0.50465126,0
7845662.17,,5905,,149.323,0.316,9.2E-6,149.09746,3.5068302,75.014709,0.2655,3948.2533,2.93,15882.329,21.83,0.033615113,121.67948,0.17704787,99.220243,367.29319,3.339,1,,,,0.00013110596,248.84104,22230.053,0.50312532,0
7846913.02,,5905,,149.308,0.316,9.1E-6,149.17718,3.5656586,75.113455,0.2495,3952.7157,2.933,15902.501,16.27,11.336012,124.70097,0.21924008,99.057514,366.58808,3.025,1,,,,0.00012821142,243.35896,22253.832,0.50351839,0
7847941.48,,5905,,149.308,0.316,9.2E-6,149.21892,3.6301465,74.812953,0.2493,3954.3818,2.934,15856.361,16.5,2.2345406,124.41217,0.22026507,99.053035,369.43323,3.025,1,,,,0.00012813796,249.40194,22266.285,0.50136374,0
7849029.53,,5905,,150.689,0.316,9.1E-6,150.49581,3.5462508,74.857208,0.2317,4008.3861,2.97,15917.405,7.512,2.6853041,120.14193,0.14613076,99.353913,372.18749,2.531,1,,,,0.0001329712,248.82434,22648.99,0.49740392,0
7849899.41,,5905,,150.689,0.316,9.1E-6,150.61591,3.5684143,74.647054,0.2358,4014.2392,2.973,15889.825,10.62,0.21330625,120.70942,0.15011788,99.340801,374.41819,2.704,1,,,,0.00013212552,240.28387,22685.153,0.49561201,0
7850776.53,,5905,,150.693,0.316,9.1E-6,150.58331,3.5815519,74.997377,0.2372,4012.9872,2.973,15944.306,10.8,0.34425563,121.62435,0.17039622,99.255448,371.11316,2.729,1,,,,0.00013164614,241.41883,22675.334,0.49804574,0
7851841.38,,5905,,152.069,0.316,9E-6,151.85084,3.5334393,75.26202,0.2331,4066.9365,3.008,16040.357,7.674,2.0736923,119.96515,0.15239675,99.328251,371.77671,2.581,1,,,,0.00013421297,243.24869,23058.677,0.49563124,0
7852710.84,,5905,,152.069,0.316,9.1E-6,152.00314,3.5883956,74.930225,0.2345,4073.7465,3.012,15994.382,9.307,0.37658111,119.02634,0.12882916,99.429449,375.23665,2.665,1,,,,0.00013480561,239.9303,23104.955,0.49295182,0
7853572.75,,5905,,152.069,0.316,9E-6,151.955,3.5919558,75.430914,0.2404,4072.3773,3.011,16072.667,11.84,6.4276712,122.37141,0.19144616,99.172189,370.45848,2.835,1,,,,0.00013195544,238.05268,23090.322,0.49640297,0
7854643.28,,5905,,153.427,0.316,9E-6,153.26938,3.589133,76.014487,0.2444,4128.4179,3.047,16221.548,13.01,2.8395234,121.98969,0.20106384,99.130416,368.16682,2.957,1,,,,0.00013362411,244.74282,23491.502,0.49595352,0
7855526.31,,5905,,153.44,0.316,9E-6,153.4323,3.6404305,75.44613,0.2462,4134.8652,3.051,16137.576,14.52,0.044371994,117.43858,0.11208459,99.498919,373.91686,3.023,1,,,,0.00013779609,243.97938,23541.47,0.4917226,0
7856375.73,,5905,,153.471,0.316,9.1E-6,153.42835,3.5857159,75.338386,0.2344,4135.3349,3.051,16120.905,8.473,0.91331797,119.1814,0.14075247,99.380346,374.92089,2.658,1,,,,0.00013573035,234.87716,23540.26,0.49103301,0
7857547.83,,5905,,154.817,0.316,9.1E-6,154.70537,3.5623198,76.166564,0.2392,4190.0611,3.085,16307.385,10,19.3841,120.51232,0.18330218,99.202643,370.167,2.811,1,,,,0.0001359186,238.3628,23933.751,0.49233304,0
7858421.89,,5905,,154.818,0.316,9E-6,154.82507,3.6482097,75.961056,0.2527,4194.8733,3.088,16279.504,16.58,0.015772913,117.564,0.12810979,99.42997,372.41294,3.2,1,,,,0.00013891147,241.02464,23970.804,0.49062503,0
7859274.41,,5905,,154.818,0.316,9E-6,154.81931,3.6001457,75.785296,0.2453,4194.7238,3.088,16251.392,13.73,0.047726357,117.04109,0.11671746,99.478947,374.07272,3.019,1,,,,0.00013925272,235.128,23969.018,0.48950805,0
7860429.44,,5905,,156.232,0.316,9E-6,156.03943,3.5577364,76.409116,0.2359,4247.2664,3.119,16403.178,7.162,1.4145871,119.67723,0.16748761,99.270116,371.02453,2.675,1,,,,0.00013761604,234.08218,24348.305,0.48967824,0
7861295.73,,5905,,156.185,0.316,9.1E-6,156.19878,3.6772308,75.992377,0.2367,4253.91,3.122,16343.523,8.711,13.05971,117.37144,0.13715949,99.392689,375.41612,2.752,1,,,,0.00013971228,239.35446,24398.06,0.48651068,0
7862148.28,,5905,,156.184,0.316,9.1E-6,156.15851,3.6655177,76.489665,0.2447,4253.1053,3.122,16421.832,12.5,1.8202963,121.66088,0.20581962,99.11769,370.53091,3.006,1,,,,0.00013564127,234.74287,24385.479,0.48982067,0
7863336.16,,5905,,157.589,0.316,9.1E-6,157.40081,3.6283472,76.451754,0.2791,4305.0482,3.151,16467.743,24.77,0.56463346,116.6506,0.3111909,98.616467,373.84717,3.782,1,,,,0.00014225483,243.32176,24775.015,0.48571386,0
7864183.11,,5905,,157.583,0.316,9.1E-6,157.46181,3.5745176,76.558715,0.448,4308.7992,3.153,16488.511,60.96,30.154151,117.24834,0.64562941,97.138688,372.95158,6.019,1,,,,0.00014290193,233.3012,24794.223,0.48620496,0
7865031.91,,5905,,157.589,0.316,9E-6,157.4883,3.6798132,76.902182,0.2637,4310.1511,3.153,16544.505,19.63,17.280365,121.35573,0.28366101,98.785212,369.66697,3.494,1,,,,0.00013724957,234.49668,24802.565,0.48830409,0
7866092.95,,5905,,158.968,0.316,9E-6,158.75166,3.5816128,79.740608,0.4138,4362.1376,3.18,17048.056,53.44,14.804411,116.67196,0.16666241,99.249134,344.35476,5.874,1,,,,0.00014673256,242.71146,25202.09,0.50229778,0
7866940.08,,5905,,158.967,0.316,9.1E-6,158.91752,3.6763116,76.739599,0.2403,4370.1744,3.184,16578.663,9.624,1.9668151,116.63762,0.16321175,99.278681,374.6217,2.894,1,,,,0.00014269903,233.34393,25254.78,0.48288947,0
7867785.02,,5905,,158.963,0.316,9.1E-6,158.89474,3.7111175,77.21829,0.2481,4370.0061,3.184,16654.649,13.12,6.1139778,120.7219,0.21859517,99.063606,369.85206,3.137,1,,,,0.0001386696,233.27523,25247.538,0.48597134,0
7868843.39,,5905,,160.308,0.316,9.1E-6,160.21056,3.7114543,78.240738,0.2765,4425.4618,3.21,16872.766,22.63,3.0224107,121.00379,0.27006535,98.845267,362.69457,3.828,1,,,,0.0001403285,241.4438,25667.423,0.48836193,0
7869965.73,,5905,,160.308,0.316,9.1E-6,160.34423,3.8085376,77.865126,0.2541,4431.2471,3.212,16818.795,15.02,0.41283831,120.05205,0.2199331,99.05514,366.76561,3.324,1,,,,0.00014082213,242.00758,25710.273,0.48561226,0
7870968.36,,5905,,160.355,0.316,9.1E-6,160.35287,3.7890615,77.655478,0.2544,4431.3746,3.212,16785.57,15.36,0.044528762,118.52924,0.17925914,99.22112,368.88328,3.333,1,,,,0.00014221854,240.10411,25713.041,0.4842787,0
7872015.27,,5905,,161.75,0.316,9.1E-6,161.59634,3.6991679,77.998946,0.2444,4483.7106,3.235,16892.548,9.881,2.4154794,117.70727,0.18713499,99.184041,368.27804,3.03,1,,,,0.0001441513,237.05848,26113.376,0.48267769,0
7872867.67,,5905,,161.75,0.316,9.1E-6,161.77213,3.7736218,77.663544,0.2408,4491.4186,3.238,16846.897,8.145,3.2545785,116.97356,0.15412806,99.325748,372.06686,2.903,1,,,,0.00014454968,235.41454,26170.223,0.48007987,0
7873715.91,,5905,,161.75,0.316,9.1E-6,161.75974,3.7764778,77.88418,0.2446,4491.2773,3.238,16881.857,10.21,0.9545071,118.67997,0.18762969,99.189805,369.81083,3.047,1,,,,0.00014287379,233.94712,26166.212,0.48148063,0
7874762.83,,5905,,163.07,0.316,9.1E-6,163.03354,3.7428424,78.041989,0.2428,4544.3227,3.259,16960.008,8.737,1.0372067,116.73921,0.16481112,99.279858,371.11447,2.985,1,,,,0.00014584671,237.35995,26579.934,0.47868672,0
7875609.73,,5905,,163.102,0.316,9.1E-6,163.16117,3.7883589,77.843588,0.242,4550.0132,3.261,16934.135,8.568,8.5768876,116.01523,0.14181101,99.377643,373.42845,2.965,1,,,,0.00014645425,233.47842,26621.568,0.47709628,0
7876454.75,,5905,,163.07,0.316,9.2E-6,163.13951,3.8012329,78.251432,0.2484,4549.8128,3.261,16998.819,11.75,25.854555,119.34875,0.20569538,99.120146,369.21596,3.194,1,,,,0.00014310906,232.03045,26614.5,0.4796596,0
7877504.72,,5905,,164.484,0.316,9.1E-6,164.32904,3.7664886,78.608981,0.2479,4598.4981,3.279,17104.386,10.9,0.044679932,115.02623,0.13484676,99.403356,368.21871,3.185,1,,,,0.00014917757,238.6975,27004.034,0.47836329,0
7878339.77,,5905,,164.484,0.316,9E-6,164.45777,3.7950165,78.089093,0.2462,4604.7985,3.281,17027.978,10.8,0.2112439,116.38061,0.15709523,99.31551,373.87172,3.149,1,,,,0.00014685032,230.05247,27046.36,0.47482762,0
7879185.69,,5905,,164.483,0.316,9.1E-6,164.42876,3.8379475,78.838434,0.2536,4604.104,3.281,17146.496,13.51,2.4716007,119.58621,0.211569,99.098661,366.06627,3.373,1,,,,0.00014408091,232.76122,27036.816,0.47946865,0
7880232.81,,5905,,165.863,0.316,9.2E-6,165.72968,3.8265917,78.675986,0.2443,4657.5693,3.299,17174.117,8.478,0.88708151,116.20694,0.17518101,99.236905,370.65846,3.057,1,,,,0.00014839362,239.17243,27466.328,0.47472477,0
7881074.94,,5905,,165.866,0.316,9E-6,165.86225,3.8450314,78.609277,0.2428,4663.5552,3.301,17169.49,7.494,1.1400867,115.79679,0.14902625,99.349227,371.65116,2.99,1,,,,0.00014878854,232.41389,27510.288,0.47394313,0
7881918.13,,5905,,165.863,0.316,9.1E-6,165.82842,3.8602853,78.92524,0.2536,4662.7568,3.301,17218.958,13.4,1.0965838,118.6104,0.22394845,99.043199,368.27438,3.4,1,,,,0.00014591957,231.59358,27499.064,0.47594521,0
7882959.63,,5905,,167.249,0.316,9.1E-6,167.18856,3.834315,79.270284,0.2488,4718.5894,3.319,17329.684,10.33,1.355785,116.04036,0.19148495,99.166759,367.64829,3.246,1,,,,0.0001500075,237.2208,27952.014,0.47413702,0
7883802.98,,5905,,167.249,0.316,9.1E-6,167.31539,3.857242,78.545867,0.2503,4723.6371,3.321,17219.485,12.32,0.61832631,112.45517,0.11102729,99.503901,375.57435,3.333,1,,,,0.00015352553,232.08072,27994.439,0.46944796,0
7884621.47,,5905,,167.233,0.316,9E-6,167.27806,3.8249997,78.873461,0.2522,4723.1436,3.321,17271.108,12.8,0.19535241,116.49693,0.17706388,99.234669,372.04018,3.386,1,,,,0.00014885822,224.91034,27981.95,0.47151109,0
7885767.94,,5905,,168.621,0.316,9.1E-6,168.60708,3.8251788,79.246849,0.2473,4777.4261,3.338,17384.793,9.388,0.19623645,114.33028,0.15816642,99.305551,371.01784,3.208,1,,,,0.00015261764,232.99385,28428.349,0.47000901,0
7886597.94,,5905,,168.638,0.316,9E-6,168.71301,3.883994,78.993172,0.2472,4782.3686,3.34,17349.378,9.797,0.47965119,114.52657,0.15815671,99.308117,373.95706,3.221,1,,,,0.00015204233,228.66057,28464.079,0.46821033,0
7887428.95,,5905,,168.607,0.316,9.1E-6,168.70656,3.9064135,79.559528,0.2524,4782.6875,3.34,17439.798,11.87,0.55495972,117.42377,0.20130878,99.138215,367.89116,3.4,1,,,,0.00014920138,229.05313,28461.904,0.47158526,0
7888461.02,,5905,,170.015,0.316,9E-6,169.96927,3.8766504,79.892156,0.2474,4833.932,3.356,17543.96,8.079,0.8977239,114.7411,0.18161098,99.206739,367.04608,3.19,1,,,,0.00015354311,234.84753,28889.552,0.47003883,0
7889296.02,,5905,,170.015,0.316,9.1E-6,170.11425,3.9216069,79.643466,0.255,4840.344,3.358,17510.808,13.08,0.23408805,114.54492,0.14764508,99.355345,370.05324,3.517,1,,,,0.00015339284,229.4822,28938.857,0.46817635,0
7890129.75,,5905,,170.015,0.316,9.1E-6,170.10605,3.9303456,79.520567,0.2526,4840.3253,3.358,17491.238,12.06,0.47479379,115.17955,0.19880262,99.137259,371.36391,3.438,1,,,,0.00015255316,229.08985,28936.067,0.46747643,0
7891527.92,,5905,,170.015,0.316,9.1E-6,169.85681,3.5366246,79.965945,0.2587,4830.7157,3.355,17552.483,14.4,0.016746925,114.76827,0.15120755,99.339269,366.00361,3.627,1,,,,0.00015347354,191.31243,28851.338,0.47078444,0
7892479.97,,5905,,169.965,0.316,9.1E-6,170.07638,3.9376897,79.887973,0.2512,4839.1512,3.357,17548.514,10.69,0.26698518,116.06683,0.1871028,99.192494,367.32277,3.37,1,,,,0.00015183983,229.53654,28925.976,0.46971821,0
7893443.33,,5905,,170.015,0.316,9.1E-6,170.04516,3.9434694,80.02149,0.2705,4837.6441,3.357,17568.248,19.06,0.029477314,115.17341,0.19509413,99.15069,365.8064,3.955,1,,,,0.00015322463,232.13367,28915.357,0.47058963,0
7894438.23,,5905,,168.607,0.316,9.1E-6,168.66251,3.9264084,79.692175,0.2609,4781.0978,3.339,17459.311,15.72,0.77593321,118.55774,0.23085917,99.020197,366.37267,3.67,1,,,,0.00014803409,230.34683,28447.042,0.4724949,0
7895418.91,,5905,,168.656,0.316,9.1E-6,168.68295,3.9987574,79.665748,0.2691,4781.8657,3.339,17455.875,18.92,0.50236373,119.06071,0.25074404,98.940483,366.70067,3.886,1,,,,0.00014744264,237.11548,28453.939,0.47228097,0
7896403.83,,5905,,168.638,0.316,9.1E-6,168.69836,3.998366,79.719504,0.2606,4782.3133,3.34,17464.874,15.57,6.8722409,118.41405,0.23762923,98.99018,366.15716,3.663,1,,,,0.00014828489,238.12142,28459.136,0.47255649,0
7897421.44,,5905,,167.233,0.316,9.1E-6,167.30855,3.9594307,79.396419,0.261,4724.6561,3.321,17355.818,16.1,2.7434585,119.26605,0.24225033,98.974086,366.57475,3.644,1,,,,0.00014632244,236.8281,27992.151,0.47455087,0
7898405,,5905,,167.249,0.316,9.1E-6,167.29242,3.9643775,79.467374,0.2576,4723.8266,3.321,17366.276,14.55,1.5069238,118.67853,0.22916023,99.02427,365.78634,3.545,1,,,,0.00014709602,238.5321,27986.754,0.47502077,0
7899386.34,,5905,,167.233,0.316,9E-6,167.29506,3.9361706,79.452332,0.2554,4723.6639,3.321,17363.721,13.53,0.2412944,117.35994,0.20871505,99.10145,365.9518,3.476,1,,,,0.00014866486,237.35706,27987.636,0.47492337,0
7900393.08,,5905,,165.85,0.316,9E-6,165.91148,3.9006649,79.042073,0.2576,4666.2762,3.302,17241.065,15.06,1.2190314,119.23166,0.22664656,99.036388,367.23497,3.52,1,,,,0.00014535126,234.71988,27526.621,0.4764111,0
7901377.25,,5905,,165.866,0.316,9.1E-6,165.92852,3.9370538,78.963781,0.2562,4666.9363,3.303,17229.27,14.55,8.7705577,119.23023,0.22863964,99.028408,368.09308,3.481,1,,,,0.00014525938,238.46332,27532.275,0.47589034,0
7902361.58,,5905,,165.866,0.316,9E-6,165.93696,3.9150072,79.044318,0.2531,4666.946,3.303,17242.092,12.99,0.38229734,117.73454,0.20702493,99.108714,367.26783,3.383,1,,,,0.00014715067,238.46047,27535.075,0.47635148,0
7903372.52,,5905,,164.489,0.316,9.1E-6,164.54231,3.8677622,78.938516,0.2611,4608.9303,3.283,17167.244,16.65,0.73356214,119.86847,0.22804614,99.030599,365.28032,3.588,1,,,,0.00014396901,235.46908,27074.17,0.47974602,0
7904360.14,,5905,,164.444,0.316,9.1E-6,164.50769,3.9156333,78.882634,0.2601,4607.4362,3.282,17156.86,16.32,0.5846433,120.24983,0.2202346,99.066969,365.78349,3.562,1,,,,0.00014339705,239.73693,27062.781,0.47950726,0
7905353.95,,5905,,164.491,0.316,9.1E-6,164.51609,3.8954774,78.746082,0.258,4607.2441,3.282,17134.943,15.59,0.075045122,117.76174,0.19445108,99.159522,367.21813,3.504,1,,,,0.00014616552,240.49967,27065.545,0.47865276,0
7906363.95,,5905,,163.107,0.316,9.1E-6,163.13929,3.8441056,78.357687,0.2587,4549.9893,3.261,17015.899,16.32,0.87385314,120.43249,0.23460996,99.004785,368.12831,3.497,1,,,,0.00014205371,235.52349,26614.428,0.48031156,0
7907358.39,,5905,,163.107,0.316,9.1E-6,163.12961,3.8746944,78.37687,0.25,4548.9755,3.261,17017.937,12.41,0.35873589,118.67044,0.19608956,99.155757,367.9101,3.245,1,,,,0.00014406159,240.86498,26611.27,0.48045765,0
7908217.95,,5905,,163.076,0.316,9E-6,163.20101,3.8281502,78.142466,0.2438,4551.7432,3.262,16983.413,9.244,0.17340748,116.92638,0.15955614,99.304062,370.46931,3.027,1,,,,0.00014579494,237.34089,26634.568,0.47881118,0
7909222.61,,5905,,161.694,0.316,9.1E-6,161.73649,3.7939514,78.029198,0.2537,4490.6943,3.238,16904.345,14.63,2.6391179,120.57605,0.22124027,99.058702,368.29142,3.338,1,,,,0.00014091628,233.85276,26158.693,0.48244646,0
7910220.2,,5905,,161.724,0.316,9.1E-6,161.73331,3.8445623,78.087007,0.2507,4490.061,3.237,16912.908,13.17,0.28121078,119.22258,0.19581097,99.157157,367.69916,3.248,1,,,,0.00014251158,241.1521,26157.665,0.48281337,0
7911206.64,,5905,,161.724,0.316,9.1E-6,161.70505,3.7995451,77.995175,0.2633,4488.5691,3.237,16896.807,18.46,0.015693326,117.41722,0.16286694,99.288547,368.56394,3.58,1,,,,0.00014446084,238.44516,26148.524,0.48232986,0
7912209.44,,5905,,160.347,0.316,9.1E-6,160.34133,3.7666401,77.690441,0.252,4431.5141,3.212,16791.272,14.32,3.7341432,120.84886,0.2157499,99.080259,368.50715,3.269,1,,,,0.00013964449,234.83444,25709.341,0.48453161,0
7913207.42,,5905,,160.347,0.316,9.1E-6,160.34657,3.8232121,77.714616,0.2489,4431.4643,3.212,16795.068,12.84,3.9852261,120.21279,0.20513456,99.120782,368.27742,3.177,1,,,,0.00014038388,241.69771,25711.023,0.48466653,0
7914198.69,,5905,,160.347,0.316,9E-6,160.35067,3.7932635,77.528837,0.2481,4431.2118,3.212,16765.26,12.67,0.070362106,118.10005,0.16579942,99.27757,370.14363,3.155,1,,,,0.00014251801,240.42557,25712.337,0.48349557,0
7915212.91,,5905,,158.967,0.316,9.1E-6,158.95935,3.7487796,77.272014,0.2501,4372.7621,3.185,16665.952,13.97,4.9218673,121.21302,0.21313057,99.090709,369.47183,3.195,1,,,,0.00013818077,236.2001,25268.074,0.48611179,0
7916091.06,,5905,,159.011,0.316,9.1E-6,158.97025,3.791471,77.365193,0.248,4372.8213,3.185,16680.835,12.85,0.37642939,120.14771,0.19379872,99.165438,368.57625,3.13,1,,,,0.00013947322,242.42603,25271.54,0.4866646,0
7917082.08,,5905,,158.967,0.316,9E-6,158.95993,3.766016,77.295559,0.2459,4372.2883,3.185,16669.224,11.93,0.17980512,119.44465,0.18063629,99.217873,369.24056,3.069,1,,,,0.00014015566,240.29542,25268.261,0.48625812,0
7918103.91,,5905,,157.585,0.316,9.1E-6,157.60504,3.736716,77.021612,0.2528,4314.848,3.156,16568.202,15.44,0.84367437,121.22364,0.20756753,99.11022,368.77411,3.244,1,,,,0.00013734697,238.8893,24839.349,0.48870018,0
7918983.67,,5905,,157.557,0.316,9.1E-6,157.53429,3.7804721,77.171481,0.2558,4312.0555,3.154,16589.252,16.48,2.8125683,122.88728,0.21867082,99.074116,367.14338,3.316,1,,,,0.00013568789,242.44728,24817.052,0.48987101,0
7920000.7,,5905,,157.588,0.316,9.1E-6,157.58623,3.7867171,77.148151,0.2455,4313.7745,3.155,16587.259,11.9,1.7785214,120.90513,0.18917884,99.186229,367.49271,3.032,1,,,,0.00013780959,245.77456,24833.42,0.4895615,0
7921028.81,,5905,,156.203,0.316,9.1E-6,156.21744,3.7432084,76.565484,0.2484,4255.6218,3.123,16436.41,14.13,3.6641555,122.08411,0.20789883,99.111688,369.9389,3.111,1,,,,0.00013529571,241.81026,24403.889,0.49012123,0
7921912.83,,5905,,156.216,0.316,9E-6,156.20097,3.7487618,76.730834,0.2494,4254.6854,3.123,16461.779,14.36,0.56593002,121.78922,0.20045086,99.140469,368.3026,3.133,1,,,,0.00013581161,244.16821,24398.742,0.49123149,0
7922918.19,,5905,,156.216,0.316,9.1E-6,156.21682,3.739982,76.628242,0.2466,4255.3591,3.123,16446.132,13.23,8.8804393,121.46932,0.20367953,99.124948,369.33136,3.059,1,,,,0.00013605113,243.57844,24403.695,0.49052491,0
7923955.89,,5905,,154.829,0.316,9E-6,154.85438,3.7127049,76.246105,0.2466,4197.017,3.089,16326.996,13.7,3.9389976,122.07005,0.20393821,99.124384,369.76422,3.041,1,,,,0.00013440426,242.93863,23979.878,0.49237295,0
7924842.16,,5905,,154.816,0.316,9.1E-6,154.84277,3.7114524,76.256393,0.2446,4196.3407,3.089,16327.956,12.74,0.7484815,121.47363,0.18983771,99.180856,369.63827,2.983,1,,,,0.00013502946,244.14011,23976.284,0.49247628,0
7925846.98,,5905,,154.816,0.316,9.2E-6,154.83091,3.7070884,76.191593,0.243,4195.9455,3.088,16317.252,12.06,16.612932,121.88068,0.19624884,99.15631,370.22853,2.939,1,,,,0.00013450853,242.94726,23972.61,0.4920955,0
7926883.73,,5905,,153.468,0.316,9.1E-6,153.43297,3.6960467,75.894791,0.2513,4136.1368,3.052,16210.225,16.12,0.75528687,123.12791,0.209614,99.10332,369.68998,3.14,1,,,,0.00013231553,243.76136,23541.676,0.49464461,0
7927903.39,,5905,,153.422,0.316,9.2E-6,153.40094,3.699171,75.950663,0.245,4134.4408,3.051,16217.418,13.38,6.1446821,122.28966,0.19555436,99.157306,369.08547,2.979,1,,,,0.00013324144,246.25583,23531.848,0.49511211,0
7928790.58,,5905,,153.467,0.316,9.1E-6,153.43415,3.6536258,75.642016,0.2453,4135.175,3.051,16169.049,13.88,0.023811601,118.52487,0.12807727,99.431925,372.07668,2.994,1,,,,0.00013685123,244.57931,23542.039,0.49299334,0
7929801.09,,5905,,152.095,0.316,9.2E-6,152.01716,3.5992687,75.481725,0.2483,4075.3113,3.013,16083.685,15.37,0.84537845,123.46145,0.20512698,99.120828,370.13621,3.047,1,,,,0.00013091811,237.04974,23109.218,0.49653423,0
7930820.84,,5905,,152.052,0.316,9E-6,152.02803,3.6744399,75.526099,0.2428,4075.3835,3.013,16090.817,12.88,12.362322,122.56716,0.19280694,99.167414,369.74871,2.902,1,,,,0.00013189719,246.92291,23112.52,0.49679064,0
7931835.72,,5905,,152.052,0.316,9.1E-6,152.04095,3.6332585,75.355886,0.2445,4075.3522,3.013,16063.706,13.89,0.027626967,119.70446,0.14083125,99.37817,371.36749,2.954,1,,,,0.00013466295,245.13432,23116.45,0.49562889,0
7932858.78,,5905,,150.671,0.316,9.1E-6,150.65615,3.5780526,75.284505,0.2435,4016.5135,2.975,15993.511,13.56,11.983823,123.42573,0.19647563,99.152661,368.64419,2.905,1,,,,0.00013020205,239.40892,22697.277,0.49971079,0
7933754.33,,5905,,150.657,0.316,9.1E-6,150.60753,3.6506357,75.217469,0.2512,4014.4339,2.974,15980.767,16.81,2.0183374,124.30938,0.21384031,99.084418,369.14375,3.09,1,,,,0.00012922362,246.85146,22682.628,0.49942702,0
7934781.41,,5905,,150.701,0.316,9.1E-6,150.6402,3.6430712,75.138445,0.2388,4015.3208,2.974,15969.082,11.47,0.86474623,122.09746,0.17566424,99.234886,369.95283,2.776,1,,,,0.0001313555,248.61876,22692.469,0.49879413,0
7935823.48,,5905,,149.344,0.316,9.1E-6,149.28853,3.5969261,74.717583,0.2388,3957.3984,2.936,15844.205,12.07,1.4568862,123.75451,0.18550182,99.199236,370.47545,2.767,1,,,,0.00012861188,244.19492,22287.066,0.50049111,0
7936720.17,,5905,,149.302,0.316,9.1E-6,149.27152,3.6142434,74.761496,0.2417,3956.5346,2.936,15850.327,13.4,5.1280193,123.53664,0.19079604,99.174566,370.03279,2.845,1,,,,0.00012890689,247.50903,22281.985,0.50084235,0
7937614.83,,5905,,149.344,0.316,9.1E-6,149.27335,3.6039334,74.764338,0.2404,3956.5878,2.936,15850.832,12.8,2.2385372,123.24644,0.1864189,99.191612,370.01141,2.811,1,,,,0.00012920196,247.07328,22282.532,0.50085524,0
7938661.08,,5905,,147.896,0.316,9.1E-6,147.9159,3.5798778,74.213713,0.2383,3897.9845,2.898,15704.63,12.53,0.63798706,123.38702,0.17448362,99.241393,371.61535,2.747,1,,,,0.00012783011,246.49289,21879.114,0.50172911,0
7939555.45,,5905,,147.896,0.316,9.1E-6,147.85596,3.5684055,74.43018,0.2411,3895.4033,2.896,15736.487,13.55,0.94183323,123.59642,0.18655875,99.188735,369.5139,2.813,1,,,,0.00012791205,246.77404,21861.384,0.50339655,0
7940577.8,,5905,,147.937,0.316,9.1E-6,147.88903,3.5521504,74.169616,0.2341,3896.2566,2.897,15695.887,10.39,0.093318478,120.86095,0.13791075,99.38804,371.9451,2.623,1,,,,0.00013031974,247.19285,21871.166,0.50152209,0
7941611.16,,5905,,146.536,0.316,9E-6,146.49324,3.5059947,73.909837,0.2435,3836.819,2.859,15595.121,15.2,0.45646734,124.44343,0.18977854,99.17692,370.75107,2.858,1,,,,0.0001259111,241.7219,21460.271,0.50452727,0
7942638.69,,5905,,146.588,0.316,9E-6,146.50634,3.5463774,73.915207,0.2337,3836.8773,2.859,15596.034,10.58,3.1212751,122.8401,0.165394,99.273395,370.73636,2.599,1,,,,0.00012749107,248.88686,21464.108,0.50451882,0
7943527.09,,5905,,146.587,0.316,9E-6,146.54111,3.5033758,73.673502,0.2311,3838.0091,2.859,15558.713,9.484,0.11044699,120.52762,0.12416292,99.445214,372.97783,2.528,1,,,,0.00012949746,245.6802,21474.296,0.50274973,0
7944557.89,,5905,,145.141,0.316,9.1E-6,145.11098,3.4667612,73.509827,0.2361,3777.0351,2.822,15471.7,12.45,0.63799761,124.46145,0.1715661,99.252157,370.78059,2.662,1,,,,0.00012484506,241.05525,21057.196,0.50657661,0
7945584.63,,5905,,145.171,0.316,9.2E-6,145.10214,3.5197293,73.622039,0.2395,3776.4873,2.821,15489.004,13.87,1.0591188,124.48013,0.18574928,99.18968,369.76907,2.745,1,,,,0.00012501165,248.92291,21054.631,0.5073808,0
7946611.66,,5905,,145.224,0.316,9.2E-6,145.07262,3.5152629,73.688423,0.2401,3775.2031,2.82,15498.281,14.06,3.8108683,124.46765,0.1895926,99.172278,369.10869,2.758,1,,,,0.00012511207,248.96027,21046.066,0.50794161,0
7947669.95,,5905,,143.801,0.316,9.1E-6,143.76031,3.4958946,73.198619,0.2371,3718.6067,2.787,15363.761,13.34,0.50362432,124.83372,0.17724477,99.225134,370.04438,2.674,1,,,,0.00012362676,248.93529,20667.027,0.50917126,0
7948700.69,,5905,,143.802,0.316,9E-6,143.69131,3.5031373,72.812423,0.2394,3715.5799,2.785,15299.295,14.79,1.2746924,124.50667,0.18283218,99.200438,373.22964,2.739,1,,,,0.00012344792,249.66744,20647.192,0.5067281,0
7949601.25,,5905,,143.802,0.316,9.1E-6,143.70829,3.4753783,72.694449,0.233,3715.8962,2.785,15280.843,12.07,0.16261182,122.11172,0.14786723,99.34139,374.3002,2.585,1,,,,0.000125614,249.01335,20652.074,0.50584728,0
7950637.83,,5905,,142.403,0.316,9.1E-6,142.355,3.417774,72.629949,0.2341,3657.9467,2.753,15212.632,12.69,0.31430197,124.3643,0.1665984,99.26567,371.33115,2.592,1,,,,0.00012284589,244.22344,20264.945,0.51020302,0
7951538.2,,5905,,142.413,0.316,9.1E-6,142.32612,3.4410337,72.694336,0.239,3656.5686,2.752,15221.497,14.73,0.44997345,124.15494,0.17955015,99.206646,370.70119,2.705,1,,,,0.00012316761,248.7286,20256.724,0.51075893,0
7952562.73,,5905,,142.403,0.316,9E-6,142.33212,3.424045,72.722149,0.2333,3656.5829,2.752,15225.936,12.2,0.91870816,122.99144,0.1625589,99.274865,370.47719,2.569,1,,,,0.00012431949,248.30987,20258.433,0.5109328,0
7953607.44,,5905,,141.04,0.316,9E-6,140.96982,3.4015417,72.238625,0.2333,3598.3536,2.722,15090.783,12.82,0.96394861,125.01251,0.17209461,99.240964,371.05416,2.56,1,,,,0.00012125039,245.98288,19872.489,0.51244037,0
7954637.97,,5905,,141,0.316,9.1E-6,140.94182,3.4214653,72.265788,0.2373,3597.0089,2.721,15093.76,14.56,0.99014416,124.94365,0.18073914,99.20203,370.74906,2.655,1,,,,0.00012136913,250.02501,19864.595,0.5127349,0
7955670.22,,5905,,141.04,0.316,9.2E-6,140.95254,3.4045002,72.13177,0.2257,3597.0445,2.721,15072.474,8.953,0.42532769,122.73996,0.1336778,99.4,371.91884,2.349,1,,,,0.0001232302,249.88729,19867.619,0.51174509,0
7956718.2,,5905,,139.648,0.316,9.1E-6,139.60123,3.360955,71.676147,0.2317,3539.3356,2.693,14942.281,12.81,0.24671582,124.61094,0.15623276,99.305585,372.19371,2.517,1,,,,0.00012040041,245.47992,19488.502,0.51343494,0
7957620.95,,5905,,139.648,0.316,9.1E-6,139.59961,3.3834447,71.55702,0.2264,3538.9711,2.693,14922.964,10.37,0.48962368,123.83669,0.12386539,99.446599,373.19275,2.383,1,,,,0.00012089582,249.22187,19488.051,0.51258753,0
7958519.3,,5905,,139.648,0.316,9.1E-6,139.58677,3.3722997,71.609694,0.2361,3538.6781,2.693,14931.051,14.79,0.15688252,124.81605,0.16033352,99.288788,372.71487,2.619,1,,,,0.00012012394,247.67338,19484.468,0.51301202,0
7959580.61,,5905,,138.3,0.316,9E-6,138.21452,3.3546951,71.176615,0.2298,3479.5608,2.666,14803.035,12.62,0.1889071,124.42742,0.14687034,99.342779,372.66015,2.466,1,,,,0.00011943032,249.63209,19103.254,0.51497204,0
7960480.72,,5905,,138.3,0.316,9E-6,138.16596,3.3319782,71.465676,0.2291,3477.523,2.665,14846.984,11.91,1.6460993,124.84048,0.16491109,99.262559,370.12139,2.436,1,,,,0.00011944645,248.85484,19089.833,0.51724516,0
7961512.23,,5905,,138.26,0.316,9.1E-6,138.17695,3.3256356,71.370365,0.2272,3477.6491,2.666,14831.947,11.07,0.11403739,123.02988,0.13666751,99.380449,370.945,2.389,1,,,,0.00012099659,249.68095,19092.871,0.51651424,0
7962555.88,,5905,,136.87,0.316,9E-6,136.7996,3.2908414,70.755149,0.2239,3418.8099,2.64,14675.233,10.27,0.81902576,124.30129,0.14253711,99.357535,372.31853,2.306,1,,,,0.00011851146,246.05975,18714.131,0.51721751,0
7963456.47,,5905,,136.907,0.316,9E-6,136.75283,3.2945245,71.067123,0.2299,3416.8764,2.639,14722.932,12.81,1.6687208,125.35398,0.16846214,99.244883,369.6214,2.446,1,,,,0.00011797855,248.60259,18701.337,0.51967569,0
7964492.13,,5905,,136.868,0.316,9E-6,136.76627,3.2976799,70.959262,0.2259,3417.1033,2.639,14705.999,10.99,0.18150105,123.61591,0.1405078,99.362016,370.54649,2.349,1,,,,0.00011941589,250.70795,18705.013,0.51883597,0
7965545.48,,5905,,135.519,0.316,9.2E-6,135.41105,3.2589805,70.289238,0.2218,3359.1426,2.615,14541.444,9.856,0.70407485,124.22929,0.13589568,99.383497,372.33694,2.248,1,,,,0.00011748313,247.23182,18336.152,0.51908052,0
7966445.97,,5905,,135.519,0.316,9.1E-6,135.35758,3.2547417,70.521675,0.225,3356.868,2.614,14576.148,11.18,0.46003183,124.76189,0.15118913,99.315481,370.29648,2.321,1,,,,0.00011730938,248.45857,18321.673,0.52100279,0
7967347.86,,5905,,135.52,0.316,9.1E-6,135.42524,3.246597,70.309686,0.221,3359.3402,2.615,14544.895,9.329,0.13343389,122.35747,0.11626921,99.46448,372.20932,2.221,1,,,,0.00011925102,249.52378,18339.994,0.51917714,0