File: PPMS_Data_and_Plotting/Data/RuCl3/Data/Heat Capacity/28-03-2025_RuCl3_TB001_0T _001_300-3K.csv
[Header]
TITLE,28-03-2025_RuCl3_TB001_0T _001_300-3K
BYAPP,HeatCapacity,3.9.6,1.7
INFO,33,MASS:Sample Mass (mg)
INFO,0.1,MASSERR:Sample Mass Error (mg)
INFO,207.43,MOLWGHT:Formula Weight (g/mole)
INFO,4,ATOMS:Atoms per Formula Unit
INFO,PPMS Heat Capacity Option 3.9.6 Build 3,APPNAME
DATATYPE,TIME,1
DATATYPE,COMMENT,2
STARTUPAXIS, X, 8, LINEAR, AUTO
STARTUPAXIS, Y1, 10, LINEAR, AUTO
[Data]
Time Stamp (Seconds),Comment (),System Status (Code),Puck Temp (Kelvin),System Temp (Kelvin),Field (Oersted),Pressure (Torr),Sample Temp (Kelvin),Temp Rise (Kelvin),Samp HC (J/mole-K),Samp HC Err (J/mole-K),Addenda HC (µJ/K),Addenda HC Err (µJ/K),Total HC (µJ/K),Total HC Err (µJ/K),Fit Deviation (ChiSquare),Time Const tau1 (seconds),Time Const tau2 (seconds),Sample Coupling (Percent),Debye Temp (Kelvin),Debye Temp Err (Kelvin),Cal Correction (Factor),Therm Resist (Ohms),Htr Resist (Ohms),Puck Resist (Ohms),Wire Cond (W/K),Meas Time (seconds),Temp Squared (K^2),Samp HC/Temp (J/mole-K/K),Addenda Offset HC (µJ/K)
7464604.19,CALFILE: C:\QdPpms\HEATCA~1\TempCal\Standard\Puck1960_9.cal|Addenda #3 measured on 05/02/2025 from 2.8972 to 302.75 K
7464604.59,,5905,,300.052,0.316,9.1E-6,300.82786,5.9346809,94.645348,0.7655,9366.2137,7.742,24423.324,112.6,3.2492247,58.603487,,,310.82359,32.97,1,,,,0.00041675548,86.04668,90497.404,0.31461629,0
7466387.03,,5905,,293.113,0.316,9.1E-6,294.51269,7.2151499,94.931404,0.6052,9218.5066,8.293,24321.126,84.31,3.258301,64.049976,,,295.37188,27.09,1,,,,0.00037972108,122.17695,86737.724,0.32233383,0
7468271.27,,5905,,286.384,0.316,9.1E-6,287.82253,7.2017465,94.917993,0.5805,9049.0259,8.553,24149.512,79.76,2.528973,66.909222,,,289.07623,25.48,1,,,,0.00036092949,129.00858,82841.808,0.32977958,0
7470201.31,,5905,,279.848,0.316,9E-6,281.24976,7.1145828,94.551663,0.5577,8870.0002,8.517,23912.207,75.64,2.3715295,69.506376,,,293.29951,23.15,1,,,,0.00034402897,134.57122,79101.428,0.33618398,0
7472178.89,,5905,,273.491,0.316,9.1E-6,274.80967,6.9758419,93.883401,0.5381,8683.3697,8.232,23619.263,72.2,5.4695834,72.103472,,,305.13914,20.67,1,,,,0.00032757455,139.10952,75520.357,0.34163063,0
7474209.75,,5905,,267.221,0.316,9.1E-6,268.5306,6.8125722,93.15424,0.4964,8490.7324,7.749,23310.623,64.49,3.4430522,74.367299,,,316.96235,17.83,1,,,,0.0003134526,143.70646,72108.685,0.34690363,0
7476359.38,,5905,,261.086,0.316,9.1E-6,262.30983,6.6170871,92.651229,0.476,8291.5225,7.135,23031.389,60.74,5.270157,76.849641,,,321.78713,16.22,1,,,,0.00029969417,147.9964,68806.449,0.35321294,0
7478582.5,,5905,,255.115,0.316,9.1E-6,256.25679,6.4452589,92.149447,0.4581,8092.3501,6.5,22752.388,57.41,4.2756054,79.263392,,,325.87476,14.85,1,,,,0.00028704788,153.5966,65667.54,0.35959808,0
7480869.28,,5905,,249.297,0.316,9.1E-6,250.32806,6.2309784,91.739709,0.4406,7894.9373,5.935,22489.791,54.05,3.0735109,81.787644,,,327.29478,13.67,1,,,,0.00027497785,158.28886,62664.14,0.36647792,0
7483144.36,,5905,,243.589,0.316,9.1E-6,244.56015,6.0550925,91.247497,0.4188,7703.0235,5.52,22219.571,49.73,0.92140031,84.103254,,,330.0323,12.41,1,,,,0.00026419395,164.31747,59809.666,0.37310861,0
7485472.63,,5905,,237.993,0.316,9E-6,238.88288,5.8393125,90.719194,0.4071,7516.2009,5.307,21948.701,47.48,0.99189003,86.600556,,,332.89292,11.5,1,,,,0.00025344757,168.77532,57065.031,0.37976432,0
7487839.8,,5905,,232.605,0.316,9.1E-6,233.34788,5.6443102,90.226749,0.4002,7333.8082,5.247,21687.965,46.19,1.3492809,89.106167,,,334.55002,10.81,1,,,,0.00024339466,173.76742,54451.234,0.38666196,0
7490266.47,,5905,,227.247,0.316,9E-6,227.97762,5.4473335,89.553394,0.3851,7152.4175,5.25,21399.45,43.14,1.4558479,91.322041,,,339.07911,9.895,1,,,,0.00023432952,178.95759,51973.795,0.3928166,0
7492658.06,,5905,,222.092,0.316,9.1E-6,222.68491,5.2491459,88.997026,0.3725,6965.9007,5.24,21124.421,40.54,0.97791402,93.445318,,,340.85349,9.154,1,,,,0.00022606185,183.39239,49588.57,0.39965449,0
7495095.58,,5905,,216.985,0.316,9.1E-6,217.5598,5.0739335,88.380695,0.3639,6774.7967,5.15,20835.265,38.86,1.0008033,95.455147,,,343.24132,8.549,1,,,,0.00021827283,187.81016,47332.266,0.40623634,0
7497594.2,,5905,,212.022,0.316,9.1E-6,212.54434,5.0232598,86.914239,0.2779,6575.6491,4.95,20402.819,14.1,0.13748203,99.50118,0.26323529,98.789896,358.36789,5.46,1,,,,0.00020620771,191.97941,45175.097,0.40892285,0
7500254.78,,5905,,207.134,0.316,9.1E-6,207.66648,4.9226362,86.172578,0.2688,6374.8108,4.682,20083.99,10.12,0.80077628,101.19378,0.24385096,98.888561,361.1892,4.826,1,,,,0.00019951248,200.04361,43125.366,0.41495661,0
7502952.36,,5905,,202.462,0.316,9.1E-6,202.86015,4.767955,85.655068,0.2712,6173.5404,4.39,19800.389,12.51,0.25751435,103.73635,0.24748742,98.888758,360.24343,4.849,1,,,,0.00019189058,203.52167,41152.239,0.42223704,0
7505695.17,,5905,,197.791,0.316,9.1E-6,198.20242,4.6125564,84.984177,0.2674,5978.2946,4.115,19498.411,11.42,0.45584635,105.57233,0.23516459,98.952609,361.23681,4.545,1,,,,0.00018563447,206.36376,39284.199,0.42877467,0
7508379.09,,5905,,193.295,0.316,9.1E-6,193.62018,4.4954772,84.267816,0.266,5789.3174,3.888,19195.469,11.86,0.35877472,107.48708,0.22941086,98.986938,362.40888,4.382,1,,,,0.00017947736,210.60745,37488.772,0.43522229,0
7511188.92,,5905,,188.872,0.316,9.1E-6,189.12644,4.3246695,83.466598,0.2654,5607.603,3.72,18886.289,12.77,0.089012372,108.70848,0.20953934,99.076718,364.25013,4.258,1,,,,0.00017453522,210.3191,35768.809,0.44132697,0
7514037.88,,5905,,184.546,0.316,9.2E-6,184.74142,4.2155755,82.658568,0.2596,5432.2683,3.597,18582.404,10.83,0.48184402,110.9136,0.2125474,99.073625,365.76147,3.921,1,,,,0.00016832549,213.01752,34129.394,0.44742844,0
7517065.45,,5905,,180.289,0.316,9.1E-6,180.48647,4.1415665,81.824734,0.2597,5262.2547,3.508,18279.736,12.3,1.6269265,112.09314,0.22137589,99.036457,367.24309,3.86,1,,,,0.00016388252,218.64631,32575.366,0.45335661,0
7519995.16,,5905,,176.16,0.316,9E-6,176.38766,4.0610179,81.1313,0.2534,5097.3952,3.441,18004.559,9.754,0.85975701,113.738,0.19420554,99.158492,366.86171,3.525,1,,,,0.00015899012,222.12643,31112.605,0.45996019,0
7523227.53,,5905,,172.171,0.316,9.1E-6,172.36399,4.0184458,80.203468,0.2498,4933.3427,3.386,17692.897,9.175,0.47638293,114.77982,0.17121583,99.257938,368.78923,3.334,1,,,,0.00015474666,228.47711,29709.344,0.46531453,0
7526112.91,,5905,,168.209,0.316,9.1E-6,168.35849,3.9136697,79.531201,0.2624,4768.4067,3.335,17421.011,16.51,0.13104199,117.64387,0.2054005,99.121277,367.43508,3.705,1,,,,0.0001487763,227.27696,28344.582,0.47239197,0
7529312.45,,5905,,164.372,0.316,9.2E-6,164.5284,3.8920063,78.353381,0.244,4607.8453,3.282,17073.07,8.967,0.87975015,117.0649,0.15799356,99.314757,371.30732,3.047,1,,,,0.00014637991,236.04209,27069.593,0.47623014,0
7532243.19,,5905,,160.64,0.316,9.1E-6,160.73231,3.7943859,77.384135,0.2411,4447.7863,3.219,16758.814,8.933,1.951483,118.33087,0.15097641,99.345222,372.47226,2.918,1,,,,0.00014213109,234.2935,25834.877,0.48144728,0
7535326.11,,5905,,156.938,0.316,9E-6,157.03079,3.7194597,76.800784,0.245,4290.1435,3.143,16508.366,12.16,0.065729262,119.69492,0.14500696,99.369751,369.57931,3.019,1,,,,0.00013840012,236.30721,24658.67,0.48908104,0
7538217.22,,5905,,153.334,0.316,9E-6,153.44086,3.6918623,75.744707,0.2389,4136.0788,3.052,16186.29,10.56,0.52127003,121.05079,0.15764487,99.314896,371.12494,2.802,1,,,,0.00013422677,243.0686,23544.099,0.49364103,0
7541365.72,,5905,,149.812,0.316,9.1E-6,149.90902,3.5922903,74.609962,0.2347,3983.632,2.953,15853.317,9.999,0.67493514,119.99379,0.095670687,99.575997,373.00038,2.654,1,,,,0.00013243343,241.63311,22472.715,0.49770162,0
7544379.47,,5905,,146.376,0.316,9.1E-6,146.45681,3.5301784,73.173355,0.2328,3834.128,2.857,15475.263,11.3,3.9462299,118.45244,0.075011351,99.660066,377.20966,2.61,1,,,,0.00013089769,245.33694,21449.598,0.49962411,0
7547286.77,,5905,,143.082,0.316,9.2E-6,143.07106,3.4417415,72.835432,0.2278,3688.4766,2.77,15275.852,8.997,0.4266072,121.93796,0.11759459,99.473039,371.41924,2.411,1,,,,0.00012565783,244.822,20469.33,0.50908569,0
7550323.97,,5905,,139.814,0.316,9.2E-6,139.77597,3.3288519,71.441536,0.2241,3546.3628,2.697,14911.983,9.187,0.55887867,120.74337,0.093318063,99.573321,374.63779,2.319,1,,,,0.00012380914,241.85837,19537.321,0.51111459,0
7553360.05,,5905,,136.59,0.316,9.2E-6,136.52406,3.2389217,70.317045,0.2242,3406.4098,2.635,14593.135,11.1,0.36862593,119.68215,0.06795743,99.682496,375.16893,2.331,1,,,,0.00012216079,241.81354,18638.819,0.5150524,0
7556395.06,,5905,,133.45,0.316,9E-6,133.38523,3.1925288,69.415209,0.2179,3272.0831,2.578,14315.336,9.074,0.29065404,122.47756,0.097380678,99.548689,373.77759,2.151,1,,,,0.00011719688,244.38527,17791.619,0.52041152,0
7559591.75,,5905,,130.379,0.316,9.1E-6,130.28754,3.0980464,68.299992,0.2195,3138.8263,2.517,14004.659,11.64,0.20214956,120.01327,0.059680575,99.713863,373.82877,2.2,1,,,,0.00011689427,245.60051,16974.842,0.52422506,0
7562657.06,,5905,,127.443,0.316,9.1E-6,127.29698,3.0497876,67.184723,0.213,3010.7126,2.447,13699.118,9.955,0.38721343,121.19304,0.068826816,99.668565,373.78033,2.043,1,,,,0.00011326446,248.80416,16204.521,0.52777939,0
7565581.52,,5905,,124.538,0.316,9E-6,124.38328,2.9751641,66.015965,0.2096,2885.8459,2.364,13388.314,9.965,1.5840786,121.4877,0.060832959,99.703658,373.97067,1.973,1,,,,0.0001104047,247.78958,15471.2,0.5307463,0
7568521.53,,5905,,121.654,0.316,9.1E-6,121.5119,2.8822981,64.957618,0.2081,2762.8329,2.271,13096.928,10.72,0.46005388,120.08353,0.050156567,99.748912,373.08901,1.943,1,,,,0.00010923615,248.4389,14765.143,0.53457822,0
7572079.22,,5905,,118.884,0.316,9E-6,118.599,2.8635811,64.178298,0.2153,2640.404,2.17,12850.517,14.71,1.0669409,128.0779,0.14267128,99.316413,369.72848,2.063,1,,,,0.00010077005,248.85574,14065.723,0.54113693,0
7575050.55,,5905,,116.185,0.316,9.1E-6,115.95292,2.7257685,62.506549,0.2109,2528.0907,2.075,12472.246,14.76,0.12002883,118.72484,0.036505,99.809645,373.23484,1.995,1,,,,0.0001051791,247.70964,13445.08,0.53906835,0
7578314.05,,5905,,113.511,0.316,9.1E-6,113.20504,2.6910008,62.074411,0.1995,2415.3966,1.979,12290.803,10.57,1.136722,125.74658,0.1205444,99.3918,367.3685,1.76,1,,,,9.812914E-5,247.74321,12815.381,0.5483361,0
7581620.92,,5905,,110.89,0.316,9.2E-6,110.58619,2.5802206,60.705771,0.1979,2308.5715,1.891,11966.241,11.62,0.044280371,122.03953,0.084625024,99.554047,368.12362,1.748,1,,,,9.8338469E-5,243.70032,12229.304,0.54894533,0
7584888.8,,5905,,108.391,0.316,9.2E-6,108.01578,2.5249145,59.653835,0.195,2205.9108,1.807,11696.228,11.64,0.13588683,123.12849,0.098833137,99.474592,366.55807,1.697,1,,,,9.5322648E-5,244.15082,11667.408,0.55226964,0
7588321.95,,5905,,105.885,0.316,9.1E-6,105.55399,2.4510085,58.417786,0.1864,2108.8758,1.73,11402.551,9.295,0.12733917,121.55789,0.082067885,99.55146,366.28621,1.549,1,,,,9.4084417E-5,243.8357,11141.645,0.55343986,0
7591603.39,,5905,,103.485,0.316,9.1E-6,103.06735,2.3701236,57.237609,0.1842,2012.4908,1.656,11118.411,9.888,0.086081194,120.74576,0.079313698,99.55622,365.25382,1.526,1,,,,9.235667E-5,240.24388,10622.879,0.5553418,0
7594780.45,,5905,,101.127,0.316,9E-6,100.73796,2.3752387,56.169988,0.1821,1923.7856,1.588,10859.858,10.29,0.16399355,121.02595,0.086080405,99.511203,363.77201,1.5,1,,,,9.0030302E-5,241.54448,10148.136,0.55758515,0
7597927.78,,5905,,98.7886,0.316,9.2E-6,98.386104,2.2717895,54.917196,0.1789,1835.1315,1.523,10571.898,10.44,0.080971735,119.65442,0.076840064,99.551601,363.11576,1.462,1,,,,8.862556E-5,239.5821,9679.8255,0.55818041,0
7601168.73,,5905,,96.5361,0.316,9E-6,96.102986,2.2105476,53.759136,0.1714,1750.7571,1.462,10303.288,8.481,0.7605158,119.32862,0.078539926,99.532534,361.84166,1.345,1,,,,8.6623412E-5,235.27074,9235.7838,0.5593909,0
7604292.13,,5905,,94.3023,0.316,9.1E-6,93.890859,2.164395,52.592682,0.171,1670.1218,1.406,10037.082,9.84,0.046060713,116.7123,0.0583177,99.639258,360.63059,1.361,1,,,,8.6214959E-5,235.43978,8815.4933,0.56014699,0
7607382.94,,5905,,92.1407,0.316,9E-6,91.707798,2.115465,51.500933,0.1675,1592.2109,1.353,9785.4848,9.683,0.10503025,116.67322,0.067279646,99.576002,358.82964,1.318,1,,,,8.4121383E-5,232.53957,8410.3202,0.56157638,0
7610465.19,,5905,,90.0602,0.316,9E-6,89.603317,2.0768572,50.291884,0.1625,1518.3357,1.304,9519.262,8.949,0.072293277,114.88927,0.055321532,99.640282,357.81166,1.256,1,,,,8.3067388E-5,231.48595,8028.7545,0.56127256,0
7613288.33,,5905,,87.9995,0.316,9.1E-6,87.561831,2.0198742,48.988132,0.1603,1447.8202,1.258,9241.3329,9.61,0.046542616,111.58,0.03389838,99.769836,357.3789,1.249,1,,,,8.2958415E-5,228.58313,7667.0742,0.55946902,0
7616081.72,,5905,,85.9805,0.316,9.1E-6,85.549794,1.985821,47.857144,0.1574,1379.6685,1.213,8993.2526,9.743,0.042540135,110.54376,0.032598343,99.772721,355.81207,1.223,1,,,,8.1487549E-5,227.33112,7318.7672,0.55940688,0
7619077.59,,5905,,84.0153,0.316,9.2E-6,83.547136,1.9732012,46.871647,0.1559,1313.425,1.168,8770.2266,10.21,6.8648856,114.65634,0.079252645,99.455822,353.21951,1.211,1,,,,7.6794188E-5,225.05731,6980.124,0.56102039,0
7621844.91,,5905,,82.0978,0.316,9.1E-6,81.632206,1.9010526,45.525258,0.1519,1250.2207,1.124,8492.8255,10.1,0.035203591,107.98355,0.028449058,99.789937,352.91497,1.178,1,,,,7.8769686E-5,220.90652,6663.8171,0.55768746,0
7624781.95,,5905,,80.2341,0.316,9.2E-6,79.739076,1.8929608,44.532475,0.1447,1189.5558,1.079,8274.219,8.296,2.656296,110.70315,0.060272047,99.556791,350.43928,1.086,1,,,,7.4986475E-5,220.05854,6358.3202,0.55847745,0
7627704.28,,5905,,78.3729,0.316,9.1E-6,77.891438,1.8571467,43.385606,0.1415,1131.4749,1.034,8033.6828,8.338,3.2897137,109.49671,0.058840285,99.554963,348.87168,1.063,1,,,,7.36114E-5,217.347,6067.0762,0.55700096,0
7630603.27,,5905,,76.6051,0.316,9E-6,76.074773,1.8138536,42.238721,0.1379,1075.9996,0.9881,7795.7498,8.158,7.1989765,108.18182,0.057096957,99.555417,347.26273,1.032,1,,,,7.2300781E-5,213.45151,5787.3712,0.55522637,0
7633470.13,,5905,,74.8394,0.316,9.2E-6,74.306466,1.7827103,41.126914,0.1346,1023.8298,0.9427,7566.7029,8.077,9.2350731,106.89879,0.055346308,99.556501,345.49776,1.007,1,,,,7.1019691E-5,211.37121,5521.4509,0.55347692,0
7636199.69,,5905,,73.1213,0.316,9E-6,72.579405,1.7635361,40.103732,0.1511,975.00736,0.8978,7355.1026,14.29,0.22299391,108.21708,0.074539702,99.399157,343.25156,1.208,1,,,,6.8275536E-5,209.07106,5267.7701,0.55254975,0
7638919.19,,5905,,71.4512,0.316,9E-6,70.911716,1.7325895,39.073985,0.151,929.45925,0.8556,7145.7322,14.92,0.22333935,107.28139,0.075324714,99.377492,341.16797,1.209,1,,,,6.6923356E-5,206.47777,5028.4715,0.55102297,0
7641460.61,,5905,,69.7879,0.316,9E-6,69.290543,1.6658335,37.934833,0.1214,886.25165,0.8172,6921.2972,6.226,0.070695141,99.062489,0.024614129,99.777199,339.78361,0.8796,1,,,,6.998664E-5,203.23112,4801.1794,0.5474749,0
7643912.72,,5905,,68.2109,0.316,9.2E-6,67.715305,1.6311379,36.975737,0.1205,845.98368,0.785,6728.4467,7.05,0.043606059,97.937297,0.025875931,99.759336,337.45922,0.8914,1,,,,6.8828292E-5,199.46684,4585.3625,0.54604697,0
7646479.55,,5905,,66.6667,0.316,9.1E-6,66.142925,1.6098009,36.071992,0.1183,806.99882,0.7593,6545.6853,7.187,0.5200808,99.286503,0.043937121,99.589675,334.6991,0.8779,1,,,,6.6136116E-5,197.73642,4374.8865,0.54536433,0
7648928.3,,5905,,65.1384,0.316,9.1E-6,64.608256,1.5651007,35.062693,0.1158,769.66587,0.7407,6347.7832,7.31,0.039524307,95.653596,0.027169868,99.733023,332.59701,0.8656,1,,,,6.6499419E-5,194.33012,4174.2267,0.54269679,0
7651427.48,,5905,,63.6561,0.316,9.1E-6,63.103147,1.5464224,34.176648,0.1142,734.25525,0.7271,6171.4119,7.646,1.6922955,97.012536,0.04513349,99.555068,329.81975,0.8612,1,,,,6.3835364E-5,191.44636,3982.0071,0.54159975,0
7653910.52,,5905,,62.2051,0.316,9.1E-6,61.637211,1.525657,33.229332,0.1191,700.55608,0.7166,5987.0043,10.13,0.58640433,96.90899,0.053549621,99.463567,327.47275,0.9347,1,,,,6.2039583E-5,188.70466,3799.1458,0.53911155,0
7656360.64,,5905,,60.7723,0.316,9E-6,60.212795,1.4855047,32.304533,0.1086,668.48642,0.7072,5807.8086,7.47,0.64737763,93.682532,0.041318508,99.565905,325.10247,0.8253,1,,,,6.2206315E-5,185.52354,3625.5807,0.53650612,0
7658671.25,,5905,,59.3727,0.316,9.1E-6,58.866404,1.474291,31.252118,0.1048,639.00292,0.698,5610.8966,7.136,0.20496881,91.016363,0.0310526,99.661265,323.77797,0.8012,1,,,,6.1811699E-5,182.58498,3465.2536,0.53089905,0
7660844.61,,5905,,58.0244,0.316,9.1E-6,57.491409,1.4271961,30.265767,0.1011,609.51802,0.6875,5424.4932,6.777,0.065635287,85.707062,0.0079784733,99.906616,321.82201,0.7757,1,,,,6.3337704E-5,179.39344,3305.2621,0.52643982,0
7663234.23,,5905,,56.6941,0.316,9.1E-6,56.154837,1.4294283,29.513833,0.1082,582.15229,0.6767,5277.5025,9.685,0.2205145,90.015208,0.042408968,99.518585,318.62777,0.8678,1,,,,5.8853611E-5,176.66245,3153.3657,0.52557953,0
7665532.45,,5905,,55.4006,0.316,9.1E-6,54.84582,1.399645,28.717824,0.1024,555.95114,0.6653,5124.6644,8.594,3.5562614,89.02347,0.04507693,99.474827,315.74413,0.8162,1,,,,5.7806992E-5,173.2824,3008.064,0.52361008,0
7667709.36,,5905,,54.1236,0.316,9.1E-6,53.639456,1.3527356,27.723502,0.08819,532.41155,0.6541,4942.9383,4.265,12.530347,83.143332,0.016048792,99.798921,314.51826,0.649,1,,,,5.9546196E-5,169.83485,2877.1913,0.51684905,0
7669737.59,,5905,,52.8841,0.316,9E-6,52.348812,1.3201607,26.981827,0.09669,508.26019,0.6419,4800.794,8.21,0.012032339,80.507213,0.012341722,99.837898,311.24047,0.7821,1,,,,5.9709267E-5,167.7162,2740.3981,0.51542387,0
7672238.78,,5905,,51.6767,0.316,9.1E-6,51.175366,1.3080506,26.085372,0.08734,487.13775,0.6309,4637.0547,5.908,0.21976214,81.443578,0.023889938,99.687413,309.48523,0.6886,1,,,,5.7078826E-5,164.12699,2618.9181,0.50972516,0
7674281.33,,5905,,50.5064,0.316,9.1E-6,49.982767,1.2732121,25.255392,0.08276,465.96673,0.6203,4483.8424,5.01,0.11788782,77.760935,0.0098159382,99.864332,307.15077,0.6457,1,,,,5.7724797E-5,160.86082,2498.277,0.505282,0
7676370.81,,5905,,49.3356,0.316,9E-6,48.851097,1.224745,24.502435,0.08048,446.49623,0.6114,4344.584,4.903,1.4289881,76.292739,,,304.65829,0.6341,1,,,,5.6946233E-5,158.38966,2386.4297,0.5015739,0
7678248.64,,5905,,48.2141,0.316,9.1E-6,47.664257,1.2060767,23.70041,0.08436,425.81941,0.6033,4196.3132,7.042,0.025589525,73.556101,0.0044523293,99.933586,302.04405,0.7051,1,,,,5.7079763E-5,153.01037,2271.8814,0.49723653,0
7680095.98,,5905,,47.1135,0.316,9.1E-6,46.563552,1.1881445,22.914947,0.07961,407.03903,0.5969,4052.5736,6.196,0.035963625,72.168915,0.0046411815,99.928791,299.80758,0.6656,1,,,,5.6186388E-5,150.79368,2168.1644,0.49212197,0
7682059.17,,5905,,46.0379,0.316,9.1E-6,45.531691,1.1493929,22.237884,0.07404,389.95507,0.5902,3927.7759,4.844,2.1171221,72.377537,,,297.29031,0.6074,1,,,,5.4267885E-5,147.84085,2073.1349,0.48840452,0
7683989.28,,5905,,44.9759,0.316,9.1E-6,44.462914,1.1294697,21.516945,0.07395,372.40574,0.5808,3795.5326,5.522,0.33100149,71.441604,,,294.74451,0.6265,1,,,,5.3127762E-5,144.69453,1976.9507,0.48393017,0
7685956.42,,5905,,43.9403,0.316,9.1E-6,43.453817,1.104661,20.809659,0.07072,356.28846,0.5682,3666.8932,5.062,0.78358924,69.858654,,,292.45467,0.6022,1,,,,5.2490179E-5,141.73614,1888.2342,0.4788914,0
7687821.58,,5905,,42.9437,0.316,9.1E-6,42.448532,1.0828007,20.099717,0.06857,340.8274,0.5508,3538.4876,4.98,0.69723644,68.418881,,,290.15989,0.5931,1,,,,5.1717998E-5,138.85853,1801.8779,0.47350793,0
7689652.34,,5905,,41.9618,0.316,9.1E-6,41.446216,1.0879714,19.352474,0.06458,325.83672,0.5294,3404.6181,4.303,0.3367192,67.514889,0.015362067,99.736648,288.08347,0.5592,1,,,,5.0536575E-5,135.96819,1717.7888,0.4669298,0
7691456.64,,5905,,40.9974,0.316,9E-6,40.480429,1.0410828,18.744927,0.06442,312.09153,0.5078,3294.2185,4.809,0.46534687,65.580069,,,285.30644,0.575,1,,,,5.0232007E-5,133.24116,1638.6651,0.46306148,0
7693227.69,,5905,,40.0608,0.316,9E-6,39.541136,1.0188489,18.076737,0.06198,298.94322,0.4874,3174.768,4.586,0.42598751,64.060566,,,283.07281,0.5611,1,,,,4.955885E-5,130.09382,1563.5015,0.45716282,0
7695021.2,,5905,,39.1507,0.316,9.2E-6,38.636539,1.0010904,17.407132,0.0611,286.54477,0.4703,3055.8421,4.884,0.42845084,62.755425,,,281.06818,0.57,1,,,,4.8694469E-5,127.32355,1492.7822,0.45053548,0
7696782.72,,5905,,38.2476,0.316,9.1E-6,37.744533,0.97875134,16.841227,0.05781,274.49731,0.4569,2953.7649,4.296,0.5311494,61.223269,,,278.41653,0.5402,1,,,,4.8245789E-5,124.55565,1424.6498,0.44618983,0
7698508.97,,5905,,37.3745,0.316,9.1E-6,36.867839,0.98408337,16.196467,0.05529,262.71418,0.4454,2839.4071,4.05,0.29098948,60.520745,0.013664026,99.730634,276.39321,0.5252,1,,,,4.7020639E-5,121.74382,1359.2375,0.43931155,0
7700204.47,,5905,,36.5239,0.316,9.1E-6,36.016165,0.96382662,15.616378,0.05298,251.52659,0.4336,2735.9332,3.789,0.34012119,59.055629,0.012349424,99.749101,274.0809,0.51,1,,,,4.6424176E-5,118.85723,1297.1642,0.43359357,0
7701874.33,,5905,,35.6876,0.316,9.1E-6,35.178692,0.95093008,15.048439,0.05184,240.66309,0.4194,2634.7164,3.923,0.25115822,57.88782,0.012683299,99.735565,271.76565,0.5128,1,,,,4.5613834E-5,117.06346,1237.5404,0.42777142,0
7703520.36,,5905,,34.8682,0.316,9.1E-6,34.373421,0.92979348,14.498748,0.04857,230.3202,0.4014,2536.9233,3.293,0.64666431,56.210135,0.011034769,99.761803,269.546,0.4807,1,,,,4.5221947E-5,114.18085,1181.5321,0.42180114,0
7705026.63,,5905,,34.0738,0.316,9E-6,33.560478,0.92065427,13.94892,0.046,220.00344,0.3787,2439.1345,2.887,1.7573485,54.37701,0.0077548542,99.826014,267.25035,0.4585,1,,,,4.4920709E-5,111.61447,1126.3057,0.41563532,0
7706564.13,,5905,,33.2997,0.316,9.1E-6,32.762033,0.91418842,13.464558,0.04835,210.08379,0.3545,2352.1579,4.126,1.5799336,54.954617,0.017059403,99.617383,264.55131,0.5146,1,,,,4.2938209E-5,109.43993,1073.3508,0.41098056,0
7707967.33,,5905,,32.535,0.316,9.1E-6,32.002038,0.87845159,12.911408,0.04715,200.69527,0.3315,2254.7687,4.185,0.03720655,50.854075,0.0032628924,99.920831,262.6813,0.5172,1,,,,4.4367171E-5,105.86906,1024.1305,0.40345579,0
7709482.3,,5905,,31.7841,0.316,9E-6,31.25508,0.88304414,12.435063,0.04845,191.82648,0.3115,2170.1183,4.846,0.24060315,52.856313,0.018668586,99.560406,260.30736,0.5493,1,,,,4.1207639E-5,103.83312,976.88003,0.39785733,0
7710836.22,,5905,,31.0661,0.316,9E-6,30.552044,0.83490581,11.956982,0.03995,183.59503,0.296,2085.829,2.66,0.12492929,48.716546,,,258.30646,0.4378,1,,,,4.2815618E-5,101.92432,933.42741,0.39136438,0
7712194.91,,5905,,30.3465,0.316,9.1E-6,29.875846,0.84268623,11.422597,0.03774,175.76705,0.2841,1992.9859,2.394,2.0030112,47.879856,0.0042099218,99.890579,257.01735,0.4229,1,,,,4.1662637E-5,99.428652,892.56615,0.38233552,0
7713560.88,,5905,,29.6529,0.316,9E-6,29.188356,0.82238433,11.045383,0.03817,168.07042,0.2743,1925.2783,2.919,0.54942987,47.792811,0.0098208002,99.741651,254.30176,0.4484,1,,,,4.0370786E-5,95.663932,851.96013,0.37841744,0
7714916.69,,5905,,28.9778,0.316,9E-6,28.507304,0.80762943,10.612407,0.03555,160.54428,0.2657,1848.8701,2.41,92.663684,46.220438,0.0078576846,99.785293,252.1131,0.4188,1,,,,4.007292E-5,94.456659,812.66637,0.37226974,0
7716190.14,,5905,,28.3124,0.316,9.1E-6,27.834478,0.78620001,10.189437,0.03514,153.20297,0.2574,1774.2386,2.668,0.10366193,44.211913,0.0028559834,99.918075,249.91081,0.4327,1,,,,4.0157797E-5,92.252276,774.75818,0.3660725,0
7717485.52,,5905,,27.6659,0.316,9E-6,27.210575,0.776177,9.7913953,0.03336,146.53537,0.2491,1704.2466,2.426,1.0367854,44.291823,0.0080737417,99.767692,247.92716,0.4183,1,,,,3.8552544E-5,90.155566,740.41539,0.35983787,0
7718797.7,,5905,,27.0298,0.316,9.1E-6,26.583183,0.75692463,9.4027749,0.03199,139.89319,0.2398,1635.7789,2.315,2.7870514,43.151437,0.0073892777,99.780718,245.83227,0.4112,1,,,,3.7977546E-5,87.865767,706.66564,0.3537114,0
7720083.42,,5905,,26.4124,0.316,9E-6,25.958643,0.73870004,9.0203717,0.03058,133.39974,0.2293,1568.449,2.18,6.3416692,42.09045,0.0071444842,99.781552,243.71325,0.4025,1,,,,3.7332078E-5,85.780937,673.85115,0.34749011,0
7721477.64,,5905,,25.812,0.316,9.1E-6,25.352254,0.71787979,8.6509364,0.02934,127.21596,0.2178,1503.4918,2.096,0.73419255,40.819444,0.0061225793,99.806093,241.64909,0.3971,1,,,,3.6892708E-5,83.777027,642.73679,0.34122948,0
7722717.05,,5905,,25.2101,0.316,9E-6,24.784797,0.67209877,8.2660738,0.03125,121.58607,0.2057,1436.6342,2.966,0.074826562,37.813254,,,240.13824,0.4554,1,,,,3.7992874E-5,81.646636,614.28619,0.33351387,0
7723962.08,,5905,,24.6351,0.316,9.1E-6,24.23744,0.67878861,8.0076276,0.02732,116.23811,0.1928,1390.1701,1.998,13.417846,39.340085,0.0060445841,99.799199,237.51891,0.39,1,,,,3.5396958E-5,79.839799,587.4535,0.33038257,0
7725220.39,,5905,,24.0773,0.316,9.1E-6,23.660084,0.63625553,7.6491363,0.02595,110.76324,0.1788,1327.6629,1.848,4.6531,37.470035,,,235.6729,0.3814,1,,,,3.5432657E-5,77.182186,559.79957,0.32329286,0
7726411.28,,5905,,23.5284,0.316,9.1E-6,23.097645,0.61054991,7.3107629,0.02515,105.4667,0.1651,1268.5346,1.886,0.10908576,35.779803,,,233.78624,0.3847,1,,,,3.545393E-5,75.342995,533.50122,0.31651551,0
7727576.41,,5905,,22.9824,0.316,9.1E-6,22.554451,0.58944211,7.0235037,0.02436,100.43376,0.1527,1217.8016,1.879,0.040137347,35.036707,,,231.53605,0.3842,1,,,,3.475788E-5,73.711747,508.70324,0.31140212,0
7728718.45,,5905,,22.4684,0.316,9.1E-6,22.033898,0.58177653,6.7289464,0.02346,95.620438,0.142,1166.1273,1.846,0.09844234,34.462252,0.0012683194,99.951092,229.61839,0.3823,1,,,,3.3851768E-5,72.02159,485.49267,0.30539065,0
7729839.2,,5905,,21.9521,0.316,9E-6,21.52397,0.56261834,6.4484268,0.02136,91.018703,0.1328,1116.8977,1.374,2.2952335,34.258658,0.0039811915,99.84458,227.66674,0.347,1,,,,3.2644731E-5,70.634542,463.2813,0.29959281,0
7730979.78,,5905,,21.4474,0.316,9.1E-6,21.018425,0.54028062,6.1813425,0.02098,86.526557,0.1244,1069.9152,1.505,0.77668886,33.719478,0.0051524687,99.794138,225.61684,0.3575,1,,,,3.1785189E-5,69.112766,441.77421,0.2940916,0
7732092.61,,5905,,20.9577,0.316,9.1E-6,20.522273,0.5206323,5.9017118,0.01994,82.195213,0.1167,1021.0974,1.402,214.40648,33.077177,0.0059104969,99.758181,223.85555,0.3505,1,,,,3.0933431E-5,67.400675,421.16371,0.28757593,0
7733221.23,,5905,,20.4763,0.316,9E-6,20.037636,0.49582892,5.6478766,0.01878,78.054788,0.1093,976.57442,1.231,3.6281628,32.086678,0.0044308245,99.811977,221.91428,0.3369,1,,,,3.0484052E-5,65.79116,401.50685,0.28186342,0
7734356.41,,5905,,20.0108,0.316,9.1E-6,19.568198,0.47046855,5.4068582,0.01816,74.140056,0.1021,934.31612,1.246,0.23888709,31.025298,0.0025682509,99.8866,219.99461,0.3389,1,,,,3.0143635E-5,63.947115,382.91437,0.27630844,0
7735473.59,,5905,,19.5509,0.316,9.1E-6,19.108486,0.45508939,5.1691742,0.01745,70.409748,0.09502,892.77271,1.225,0.62848587,30.719295,0.0043909414,99.802971,218.16773,0.3381,1,,,,2.9110967E-5,62.823416,365.13422,0.27051721,0
7736655.23,,5905,,19.1035,0.316,9.1E-6,18.666591,0.43292718,4.9468408,0.0163,66.897646,0.08811,853.88962,1.017,10.145014,29.789629,0.003361358,99.84356,216.35462,0.32,1,,,,2.8702145E-5,60.973285,348.44162,0.2650104,0
7737790.23,,5905,,18.6699,0.316,9.1E-6,18.22505,0.41569232,4.7266263,0.01577,63.461313,0.08114,815.41941,1.049,0.6304459,29.11444,0.0035795401,99.828485,214.54722,0.3239,1,,,,2.8048314E-5,60.14571,332.15245,0.25934778,0
7738843.91,,5905,,18.244,0.316,9.1E-6,17.780704,0.40171193,4.5858639,0.02023,60.113376,0.07416,789.67761,2.339,1.5112927,30.370843,0.014628322,99.311778,211.48391,0.4487,1,,,,2.6155047E-5,58.61466,316.15343,0.25791239,0
7739943.72,,5905,,17.8263,0.316,9E-6,17.372646,0.38397912,4.3526378,0.01636,57.075043,0.06783,749.53538,1.541,0.9536057,29.286674,0.0098953684,99.518062,210.3308,0.3753,1,,,,2.5698872E-5,56.826042,301.80882,0.25054547,0
7741050.39,,5905,,17.4194,0.316,9.1E-6,16.960081,0.36669341,4.1268421,0.0137,54.059704,0.06185,710.59824,0.8919,0.3498833,27.232866,0.0042053362,99.779961,209.08018,0.311,1,,,,2.6142534E-5,55.774003,287.64435,0.24332679,0
7742060.86,,5905,,17.0174,0.316,9E-6,16.563329,0.35109988,3.95361,0.0146,51.258836,0.05684,680.23792,1.327,0.23032317,27.492594,0.0074689802,99.609004,207.17497,0.3601,1,,,,2.4825647E-5,53.461632,274.34386,0.23869658,0
7742798.3,,5905,,16.6258,0.316,9.1E-6,16.122617,0.34570148,3.7751093,0.01573,48.229694,0.05241,648.81113,1.718,0.78077317,27.665549,0.011454564,99.395673,204.8364,0.4072,1,,,,2.3574181E-5,53.033591,259.93879,0.23414991,0
7743534.3,,5905,,16.2524,0.316,9.1E-6,15.784665,0.32967565,3.588634,0.01184,45.936542,0.04987,616.85166,0.747,0.31534646,25.082509,0.0026521494,99.84642,204.00012,0.2985,1,,,,2.4625308E-5,52.763494,249.15565,0.22734939,0
7744216.38,,5905,,15.8753,0.316,9.1E-6,15.433625,0.31744362,3.4366861,0.0112,43.643775,0.04781,590.38553,0.6535,0.21640312,24.596734,0.002371734,99.859008,202.3922,0.2881,1,,,,2.4031666E-5,51.35648,238.19679,0.22267524,0
7744881.53,,5905,,15.5115,0.316,9.1E-6,15.07237,0.29987665,3.2968534,0.0109,41.358311,0.04589,565.8541,0.6909,0.2803234,24.00842,,,200.43732,0.2934,1,,,,2.3568986E-5,50.245844,227.17635,0.2187349,0
7745532.48,,5905,,15.1589,0.316,9E-6,14.730747,0.29639042,3.1448001,0.01031,39.213985,0.04387,539.51964,0.6266,0.16628059,23.555949,0.0022638543,99.857264,199.0285,0.2864,1,,,,2.2931908E-5,48.981991,216.99491,0.21348544,0
7746196.28,,5905,,14.8117,0.316,9E-6,14.384381,0.27997168,3.0059977,0.009983,37.126446,0.04133,515.35005,0.6484,0.55871135,22.943585,,,197.31721,0.2907,1,,,,2.2461618E-5,47.603772,206.91042,0.2089765,0
7746828.95,,5905,,14.4707,0.316,9E-6,14.057491,0.27288472,2.8722642,0.009455,35.189561,0.03841,492.13754,0.5862,0.32145408,22.463746,,,195.79988,0.2835,1,,,,2.190808E-5,46.888729,197.61305,0.20432268,0
7747474.95,,5905,,14.1408,0.316,9.2E-6,13.717123,0.27163301,2.7787843,0.008862,33.215202,0.03519,475.29148,0.4393,0.20731276,22.619372,0.0024779453,99.831254,193.19021,0.2606,1,,,,2.1043315E-5,46.239526,188.15947,0.20257777,0
7748101.02,,5905,,13.815,0.316,9.2E-6,13.416405,0.26038997,2.6812315,0.009223,31.543111,0.03255,458.09973,0.6936,0.12557452,22.371191,,,191.23111,0.2984,1,,,,2.0477217E-5,45.942575,179.99991,0.19984725,0
7748712.98,,5905,,13.5021,0.316,9.1E-6,13.084909,0.24760424,2.5659804,0.008548,29.738169,0.03015,437.95951,0.5641,0.035046449,21.489653,,,189.27035,0.2797,1,,,,2.0380018E-5,43.878104,171.21485,0.19610227,0
7749345.55,,5905,,13.1951,0.316,9.1E-6,12.805248,0.25264838,2.4592728,0.007924,28.253419,0.02879,419.49866,0.4284,1.8167591,21.463118,0.0023098582,99.828452,187.87684,0.2594,1,,,,1.9574313E-5,44.578806,163.97438,0.19205194,0
7749944.11,,5905,,12.8902,0.316,9.1E-6,12.497324,0.24383467,2.3456406,0.007918,26.683736,0.02793,399.85126,0.5552,0.085387311,20.755668,0.0012320363,99.904624,186.28347,0.2814,1,,,,1.9280698E-5,43.182617,156.1831,0.18769143,0
7750532.72,,5905,,12.596,0.316,9.1E-6,12.21794,0.23984931,2.2490531,0.00758,25.303902,0.02748,383.10534,0.5279,0.36291383,21.020408,0.0034764302,99.731361,184.69733,0.2782,1,,,,1.8268229E-5,42.364909,149.27805,0.18407793,0
7751117.72,,5905,,12.3053,0.316,9E-6,11.939046,0.23173487,2.1526082,0.006983,23.957704,0.02713,366.41574,0.3965,0.70474369,20.250617,0.0020790442,99.831784,183.14432,0.2564,1,,,,1.8120688E-5,41.387243,142.54082,0.18029985,0
7751687.41,,5905,,12.0242,0.316,9E-6,11.657311,0.22085409,2.0596578,0.00673,22.645023,0.02666,350.3156,0.3995,0.31555303,19.731295,,,181.47896,0.2578,1,,,,1.7754313E-5,40.66599,135.89289,0.17668379,0
7752251.55,,5905,,11.7533,0.316,9.2E-6,11.388358,0.21438919,1.9714967,0.006482,21.412615,0.02596,335.05766,0.3991,0.83202567,19.424689,,,179.90116,0.2587,1,,,,1.7249062E-5,39.630047,129.6947,0.1731151,0
7752808.44,,5905,,11.4781,0.316,9.2E-6,11.127574,0.20876396,1.8910697,0.006186,20.248057,0.02504,321.09798,0.3698,4.3662569,19.168249,,,178.24305,0.2537,1,,,,1.6751555E-5,38.940048,123.8229,0.16994447,0
7753360.53,,5905,,11.2183,0.316,9.1E-6,10.87716,0.20935583,1.8148219,0.005844,19.149499,0.02398,307.86918,0.3144,0.97903391,19.032521,0.0022078141,99.800831,176.64191,0.2429,1,,,,1.6204348E-5,38.738692,118.3126,0.16684704,0
7753905.86,,5905,,10.964,0.316,9.1E-6,10.62257,0.20349037,1.7452114,0.005544,18.071858,0.02275,295.71721,0.2649,0.56463722,18.765538,0.0018482141,99.828121,174.77391,0.2325,1,,,,1.5782445E-5,38.139805,112.839,0.16429276,0
7754449.33,,5905,,10.7117,0.316,9.1E-6,10.379846,0.1981883,1.6811242,0.005384,17.078127,0.02147,284.52787,0.2773,0.51299407,18.609212,0.0017888606,99.829398,172.9257,0.2347,1,,,,1.5312713E-5,37.625464,107.74121,0.16196042,0
7754991.03,,5905,,10.4667,0.316,9E-6,10.140486,0.1930674,1.6273237,0.005128,16.126399,0.02012,275.01702,0.2241,0.32484329,18.524602,0.0020212636,99.802028,170.78128,0.2221,1,,,,1.4872142E-5,37.359929,102.82947,0.16047787,0
7755528.23,,5905,,10.2266,0.316,9.1E-6,9.9095423,0.18878183,1.5691304,0.005022,15.235793,0.01875,264.86845,0.2573,7.1585871,18.414012,0.0023116558,99.768019,168.93203,0.2289,1,,,,1.4413784E-5,37.118801,98.199029,0.15834539,0
7756063.11,,5905,,9.9957,0.316,9.1E-6,9.6836368,0.18042921,1.5165009,0.004897,14.397473,0.01737,255.65732,0.2687,1.8247687,18.080416,,,166.97013,0.2309,1,,,,1.4140013E-5,37.008653,93.772822,0.15660448,0
7756594.05,,5905,,9.7655,0.316,9E-6,9.4575907,0.17928182,1.4648831,0.004642,13.569225,0.01593,246.61721,0.2158,0.34515991,18.15666,0.0021620512,99.770564,164.96691,0.2178,1,,,,1.3610637E-5,36.492507,89.446021,0.15488968,0
7757126.27,,5905,,9.5437,0.316,9.1E-6,9.2413163,0.17447192,1.4238388,0.004438,12.805052,0.01455,239.3233,0.1656,0.86058655,18.126916,0.0019378774,99.788546,162.72948,0.2042,1,,,,1.3227714E-5,36.311728,85.401928,0.15407316,0
7757656,,5905,,9.3243,0.316,9.1E-6,9.0279182,0.16913255,1.3888148,0.004313,12.074635,0.01324,233.02092,0.1499,0.3083929,18.175791,0.0019258319,99.783975,160.29741,0.1984,1,,,,1.2845357E-5,36.010412,81.503307,0.15383556,0
7758187.83,,5905,,9.111,0.316,9.1E-6,8.8212671,0.16569736,1.3645786,0.004236,11.386965,0.0121,228.47751,0.146,0.23991694,18.400992,0.0019728701,99.773175,157.55041,0.1947,1,,,,1.2442074E-5,36.503748,77.814754,0.1546919,0
7758718.7,,5905,,8.9031,0.316,9.1E-6,8.6207529,0.1613372,1.3481422,0.00413,10.742276,0.0112,225.21797,0.09644,0.62595241,18.7118,0.0020685979,99.756132,154.59262,0.1795,1,,,,1.2062834E-5,36.842479,74.317381,0.15638335,0
7759260.16,,5905,,8.6997,0.316,9.1E-6,8.4232209,0.15694648,1.3449286,0.004101,10.127493,0.01056,224.09194,0.07223,0.33323625,19.232603,0.0023187009,99.719961,151.17061,0.1699,1,,,,1.1681503E-5,37.461476,70.95065,0.15966916,0
7759810.55,,5905,,8.4988,0.316,9.1E-6,8.2304507,0.15244488,1.3574361,0.004145,9.5485444,0.01021,225.5028,0.08091,0.19578717,19.970975,0.0021417407,99.734946,147.25573,0.1673,1,,,,1.1319051E-5,38.411178,67.740318,0.16492853,0
7760375.11,,5905,,8.3039,0.316,9.2E-6,8.0393989,0.14769422,1.3925832,0.004359,8.9948914,0.01009,230.54069,0.1738,0.4090905,21.09329,0.0023539608,99.701606,142.61658,0.1815,1,,,,1.0959786E-5,39.873631,64.631934,0.17321981,0
7760962.38,,5905,,8.1126,0.316,9.2E-6,7.8519843,0.1417034,1.4827555,0.005388,8.4700117,0.01011,244.36131,0.4729,5.9487396,23.244602,0.0024499975,99.684136,136.40783,0.229,1,,,,1.0543649E-5,42.075141,61.653657,0.18883832,0
7761587.16,,5905,,7.9293,0.316,9.1E-6,7.6655478,0.12796487,1.8233723,0.01199,7.9650728,0.0102,298.04503,1.693,26.304861,29.371357,0.0015290345,99.799493,124.29112,0.3667,1,,,,1.0166786E-5,46.408071,58.760623,0.23786588,0
7762937.88,,5905,,7.7471,0.316,9.1E-6,7.4972079,0.17980256,3.1273044,0.08232,7.5317753,0.01029,505.05405,13.01,138.67049,64.973206,0.029793734,96.780769,101.48551,0.979,1,,,,8.0242943E-6,129.69007,56.208126,0.41712921,0
7766172.58,,5905,,7.5721,0.316,9E-6,7.3408548,0.11593189,14.33046,0.4016,7.1161282,0.01028,2286.9464,63.51,1864.4791,191.83745,,,57.833729,0.702,1,,,,1.1921272E-5,399.10905,53.888149,1.9521514,0
7770936.86,,5905,,7.3968,0.316,9E-6,7.1655905,0.13227239,3.8647648,0.03972,6.6855937,0.01002,621.53031,6.038,363.05836,62.303023,,,90.319042,0.3902,1,,,,9.9759254E-6,134.56613,51.345687,0.5393505,0
7772780.31,,5905,,7.2269,0.316,9.1E-6,7.0018535,0.12808981,2.6181568,0.02094,6.2938709,0.009382,422.81595,3.083,59.494653,44.324525,,,100.59999,0.3501,1,,,,9.5390972E-6,89.784279,49.025953,0.37392339,0
7773852.28,,5905,,7.0625,0.316,9.1E-6,6.8537465,0.14171205,1.9806646,0.01569,5.9457897,0.008345,321.04934,2.306,678.72864,34.68589,,,108.1006,0.3722,1,,,,9.2559062E-6,88.69181,46.973841,0.28899005,0
7776025.94,,5905,,6.9131,0.316,9.1E-6,6.6130442,0.14186413,1.4222232,0.008455,5.4073374,0.005769,231.66856,1.157,3.2969741,26.658645,,,116.49258,0.3157,1,,,,8.6901851E-6,68.826855,43.732354,0.21506331,0
7776708.92,,5905,,6.7624,0.316,9.1E-6,6.4548538,0.12917317,1.1993864,0.005905,5.0691365,0.004265,195.87929,0.7404,2.6582306,23.318528,,,120.35402,0.2769,1,,,,8.4001571E-6,52.716031,41.665137,0.18581155,0
7777334.19,,5905,,6.6042,0.316,9.2E-6,6.305482,0.12799719,1.0677328,0.009373,4.7584865,0.003733,174.6239,1.399,60.574205,23.03033,0.0070242449,98.837288,122.21587,0.4571,1,,,,7.6667739E-6,45.954771,39.759103,0.16933405,0
7777922.61,,5905,,6.4305,0.316,9.1E-6,6.1725404,0.12308722,0.91170636,0.00419,4.4891499,0.0045,149.53235,0.5011,7.6638599,18.7871,,,126.10861,0.2723,1,,,,7.9593098E-6,41.728272,38.100255,0.14770359,0
7778465.91,,5905,,6.2848,0.316,9E-6,6.031828,0.12075701,0.8052036,0.003721,4.213275,0.007041,132.31297,0.4468,4.2885934,17.273419,,,128.44396,0.2787,1,,,,7.6599175E-6,37.672502,36.382949,0.13349247,0
7778975.34,,5905,,6.1512,0.316,9.1E-6,5.8938294,0.11806333,0.71309307,0.003477,3.9510388,0.01097,117.39688,0.4332,2.3494805,15.725418,,,130.69204,0.298,1,,,,7.465422E-6,34.282709,34.737225,0.12098977,0
7779452.36,,5905,,6.0234,0.316,9E-6,5.7596526,0.11567432,0.6365224,0.002812,3.7069255,0.01514,104.97115,0.3252,2.1929719,14.530652,,,132.64539,0.2758,1,,,,7.2241186E-6,31.386911,33.173598,0.11051403,0
7779909.55,,5905,,5.8734,0.316,9E-6,5.6293686,0.11713105,0.56925287,0.002663,3.4791988,0.01859,94.041531,0.3228,1.7635858,13.52487,0.00076177658,99.841695,134.5629,0.2954,1,,,,6.9634546E-6,29.439689,31.689791,0.10112197,0
7780350.13,,5905,,5.729,0.316,9.1E-6,5.5002133,0.11107447,0.51119431,0.002005,3.2695824,0.02043,84.595389,0.2014,0.56744899,12.396565,,,136.27565,0.2506,1,,,,6.8240992E-6,26.908808,30.252346,0.092940816,0
7780772.63,,5905,,5.6088,0.316,9.1E-6,5.3748896,0.10868293,0.45869269,0.001871,3.0783326,0.01998,76.051668,0.1982,0.54416859,11.55093,,,138.06905,0.2649,1,,,,6.5840296E-6,24.800995,28.889438,0.085339929,0
7781176.48,,5905,,5.4716,0.316,9.1E-6,5.2528663,0.10622418,0.41448264,0.001779,2.904088,0.01753,68.844055,0.1997,0.60361316,10.771059,,,139.57094,0.2821,1,,,,6.3915771E-6,23.106395,27.592604,0.078905996,0
7781562.08,,5905,,5.3602,0.316,9E-6,5.1335675,0.10650225,0.37307582,0.001666,2.740172,0.01421,62.092735,0.1947,2.605783,10.13628,0.00058841779,99.862226,141.27144,0.2968,1,,,,6.1335134E-6,21.532597,26.353516,0.072673792,0
7781933.7,,5905,,5.2127,0.316,9.1E-6,5.0157725,0.10208816,0.33825641,0.001027,2.5866867,0.01116,56.399835,0,0.61786723,9.4363765,,,142.61219,0.154,1,,,,5.976853E-6,20.267774,25.157974,0.067438546,0
7782296.17,,5905,,5.0976,0.316,9E-6,4.900608,0.099058687,0.30724466,0.001591,2.4364502,0.009237,51.315946,0.205,0.97551859,8.8107428,,,143.87632,0.3461,1,,,,5.8242474E-6,18.913298,24.015958,0.062695213,0
7782637.3,,5905,,4.9856,0.316,9.1E-6,4.7889565,0.096646329,0.2770674,0.001228,2.2905074,0.009008,46.369108,0.1423,0.38526511,8.137534,,,145.528,0.3035,1,,,,5.6981769E-6,17.752908,22.934105,0.057855484,0
7782971.27,,5905,,4.8945,0.316,9.1E-6,4.6809258,0.097367697,0.25130849,0.001245,2.148493,0.009817,42.129114,0.1567,2.6414741,7.7935585,0.001162467,99.691039,146.94794,0.3399,1,,,,5.4207227E-6,16.766816,21.911066,0.053687775,0
7783304.17,,5905,,4.7613,0.316,9.2E-6,4.5749159,0.092483117,0.23222442,0.0009736,2.0115751,0.01088,38.956115,0.1065,0.32906487,7.3053089,,,147.45108,0.2911,1,,,,5.332576E-6,15.953904,20.929856,0.050760369,0
7783616.2,,5905,,4.651,0.316,9.1E-6,4.4723345,0.088836122,0.21065606,0.001188,1.8785345,0.01155,35.391768,0.1589,0.33115115,6.7783405,,,148.90538,0.3856,1,,,,5.2213027E-6,14.65931,20.001776,0.047102035,0
7783924.06,,5905,,4.5436,0.316,9E-6,4.3722815,0.091219844,0.18794114,0.0009739,1.7501803,0.01129,31.649701,0.1257,0.19539362,6.5933265,0.0033034426,99.033565,151.21763,0.364,1,,,,4.8420906E-6,13.907058,19.116846,0.042984683,0
7784224.25,,5905,,4.4376,0.316,9.1E-6,4.2742711,0.087584235,0.17447406,0.001153,1.6257066,0.01004,29.382751,0.163,0.54834206,6.1167467,0.0011206444,99.648506,151.53715,0.4482,1,,,,4.8187805E-6,13.140182,18.269394,0.040819604,0
7784513.59,,5905,,4.3521,0.316,9.1E-6,4.1760939,0.085440666,0.15837364,0.001027,1.5069608,0.008255,26.702593,0.1445,1.0026583,5.9791614,0.0037621911,98.80722,152.91261,0.4455,1,,,,4.5139719E-6,12.087364,17.439761,0.037923868,0
7784795.38,,5905,,4.2566,0.316,9.1E-6,4.0820132,0.081983598,0.14701869,0.0007356,1.3976358,0.00645,24.786812,0.09312,0.1359798,5.5000092,0.0019899968,99.316322,153.22073,0.3575,1,,,,4.534319E-6,11.495656,16.662832,0.036016221,0
7785070.83,,5905,,4.154,0.316,9.2E-6,3.9876866,0.078912781,0.13264904,0.0006217,1.2962203,0.004985,22.399332,0.07528,0.15293655,5.1033329,,,154.90076,0.3406,1,,,,4.3891575E-6,10.762063,15.901644,0.033264662,0
7785347.09,,5905,,4.0505,0.316,9.2E-6,3.896347,0.076445729,0.12210127,0.0008575,1.2045416,0.004204,20.62961,0.123,0.33192448,4.8133945,,,155.59117,0.4843,1,,,,4.2858756E-6,10.163301,15.18152,0.031337371,0
7785610.34,,5905,,3.9663,0.316,9.1E-6,3.806676,0.073338343,0.11226995,0.0007052,1.1226688,0.00402,18.983674,0.09819,0.50538663,4.4827213,,,156.32392,0.4434,1,,,,4.2348548E-6,9.4790855,14.490782,0.029492909,0
7785869.66,,5905,,3.8636,0.316,9.1E-6,3.7215066,0.075301631,0.099358791,0.0006582,1.0501939,0.004147,16.857165,0.09311,0.63443153,4.2401794,0.0011851912,99.519777,159.17839,0.472,1,,,,3.9924511E-6,8.9743967,13.849612,0.026698539,0
7786122.89,,5905,,3.7843,0.316,9.1E-6,3.6369975,0.074052879,0.092829411,0.0005347,0.98474243,0.00434,15.752956,0.07234,0.24591098,4.1519308,0.0017785587,99.264937,159.1287,0.4196,1,,,,3.8188314E-6,8.6475238,13.22775,0.025523639,0
7786375.98,,5905,,3.6838,0.316,9.1E-6,3.5547447,0.069964765,0.085466934,0.000893,0.92457487,0.004395,14.521494,0.1359,1.0248106,3.8493758,,,159.87345,0.6905,1,,,,3.7724281E-6,8.0785002,12.63621,0.024043059,0
7786627.95,,5905,,3.6076,0.316,9.1E-6,3.4753047,0.068026099,0.081441093,0.0006239,0.86956008,0.004194,13.826008,0.09116,0.22199125,3.6920675,0.0010035511,99.537189,158.83479,0.531,1,,,,3.7600823E-6,7.7340022,12.077742,0.023434231,0
7786927.59,,5905,,3.523,0.316,9.1E-6,3.3965468,0.069472253,0.068791009,0.0005397,0.81784679,0.003804,11.761796,0.0792,0.27490243,3.4273543,0.0020487425,99.069733,164.22066,0.5599,1,,,,3.4596574E-6,7.0649474,11.53653,0.02025322,0