File: PPMS_Data_and_Plotting/Data/RuCl3/Data/Heat Capacity/RuCl3_TB001_HC_9T_06-04-2025.csv
[Header]
TITLE,RuCl3_TB001_9T_HparraC_Heat_Capacity
BYAPP,HeatCapacity,3.9.6,1.7
INFO,33,MASS:Sample Mass (mg)
INFO,0.1,MASSERR:Sample Mass Error (mg)
INFO,207.43,MOLWGHT:Formula Weight (g/mole)
INFO,4,ATOMS:Atoms per Formula Unit
INFO,PPMS Heat Capacity Option 3.9.6 Build 3,APPNAME
DATATYPE,TIME,1
DATATYPE,COMMENT,2
STARTUPAXIS, X, 8, LINEAR, AUTO
STARTUPAXIS, Y1, 10, LINEAR, AUTO
[Data]
Time Stamp (Seconds),Comment (),System Status (Code),Puck Temp (Kelvin),System Temp (Kelvin),Field (Oersted),Pressure (Torr),Sample Temp (Kelvin),Temp Rise (Kelvin),Samp HC (J/mole-K),Samp HC Err (J/mole-K),Addenda HC (µJ/K),Addenda HC Err (µJ/K),Total HC (µJ/K),Total HC Err (µJ/K),Fit Deviation (ChiSquare),Time Const tau1 (seconds),Time Const tau2 (seconds),Sample Coupling (Percent),Debye Temp (Kelvin),Debye Temp Err (Kelvin),Cal Correction (Factor),Therm Resist (Ohms),Htr Resist (Ohms),Puck Resist (Ohms),Wire Cond (W/K),Meas Time (seconds),Temp Squared (K^2),Samp HC/Temp (J/mole-K/K),Addenda Offset HC (µJ/K)
8239076.48,Error: Warning: Current field is 90000.219 Oe;
8239076.63,Error: but addenda was obtained at 0.021 Oe.
8239371.45,Error: Temperature of platform does not match the system temperature : System = 2.9906 K;  Platform = 2.8614 K
8239542.98,,5905,,3.0008,90000.219,9.2E-6,2.8764585,0.028742355,0.11520482,0.001062,0.51577102,0.001799,18.843685,0.1596,0.20792625,6.5455479,,,117.11214,0.456,1,,,,2.8788552E-6,14.182561,8.2740134,0.040050925,0
8239671.13,,5905,,3.0129,90000.219,9E-6,2.8751431,0.026339502,0.12277741,0.001341,0.51507578,0.001799,20.047711,0.2049,0.21841619,6.8560175,,,114.60072,0.5135,1,,,,2.9241045E-6,13.091096,8.2664477,0.042703062,0
8240275.05,,5905,,2.9824,90000.219,9E-6,2.8760886,0.028933343,0.115881,0.001078,0.51555176,0.001799,18.951038,0.1621,0.10680695,6.7668229,0.00076887627,99.568991,116.86888,0.4584,1,,,,2.8120551E-6,13.712035,8.2718857,0.040291179,0
8240825.38,,5905,,3.2049,90000.219,9.1E-6,3.0745947,0.027782409,0.14201721,0.001439,0.62528382,0.002065,23.218776,0.2184,0.32518437,7.1594811,,,116.74587,0.4915,1,,,,3.2430808E-6,13.533646,9.4531328,0.046190547,0
8241117.05,,5905,,3.2253,90000.219,9.2E-6,3.0749679,0.029341279,0.14652105,0.001779,0.62543358,0.002066,23.93544,0.2741,0.13178215,7.8329671,0.0010089438,99.491505,115.55122,0.5658,1,,,,3.070545E-6,14.318962,9.4554277,0.047649619,0
8241189.94,,5905,,3.2287,90000.219,9.1E-6,3.0761547,0.030262043,0.1456906,0.001457,0.62617099,0.00207,23.804061,0.2209,0.46752378,7.518594,,,115.81504,0.4823,1,,,,3.1660256E-6,15.665934,9.4627278,0.047361271,0
8241381.31,,5905,,3.4316,90000.219,9.1E-6,3.2770769,0.030580738,0.17328385,0.001633,0.7421535,0.003038,28.309849,0.246,0.44973187,8.5770208,0.0019533503,99.100615,116.44868,0.4617,1,,,,3.3290739E-6,15.037188,10.739233,0.052877567,0
8241458.78,,5905,,3.4187,90000.219,9.1E-6,3.2785034,0.031816944,0.181458,0.002315,0.74282975,0.003045,29.61095,0.3578,0.96508891,8.5013845,0.0016840649,99.18403,114.72331,0.5856,1,,,,3.5103143E-6,17.154042,10.748584,0.055347817,0
8241775.44,,5905,,3.4287,90000.219,9.2E-6,3.2779659,0.032490233,0.17403778,0.00141,0.74252274,0.003042,28.430161,0.2081,0.20224509,8.3539696,0.002058295,99.022747,116.31183,0.4071,1,,,,3.4350544E-6,17.002769,10.745061,0.053093225,0
8241970.09,,5905,,3.6587,90000.219,9.1E-6,3.4760756,0.032094065,0.21041139,0.001591,0.86779991,0.004183,34.342108,0.2319,0.21861005,9.3026767,4.5707975E-6,99.998005,115.78,0.3829,1,,,,3.6917072E-6,16.707939,12.083101,0.060531304,0
8242052.83,,5905,,3.6404,90000.219,9E-6,3.4771433,0.033744023,0.20706694,0.001798,0.86860078,0.004188,33.810841,0.268,0.50432362,8.9927963,,,116.43577,0.4315,1,,,,3.7597695E-6,18.605353,12.090526,0.059550878,0
8242132.95,,5905,,3.6489,90000.219,9.2E-6,3.4764281,0.033002762,0.20902487,0.001399,0.86821599,0.004186,34.121944,0.1984,0.29247127,9.1303883,,,116.0472,0.3471,1,,,,3.7371843E-6,17.985593,12.085552,0.060126334,0
8242337.03,,5905,,3.8515,90000.219,9E-6,3.6762535,0.033620809,0.24973919,0.001372,1.0119428,0.004263,40.742904,0.182,0.19018709,10.196975,4.0884955E-6,99.998345,115.64957,0.2928,1,,,,3.9956502E-6,18.260777,13.51484,0.067933072,0
8242424.08,,5905,,3.8711,90000.219,9.1E-6,3.6774622,0.036629698,0.24446037,0.001604,1.0127366,0.004261,39.903891,0.2263,0.30803496,10.141251,0.0017289873,99.306406,116.51438,0.3427,1,,,,3.9609188E-6,20.39395,13.523728,0.066475292,0
8242511.19,,5905,,3.8468,90000.219,9.1E-6,3.6758489,0.035169904,0.25069948,0.001431,1.0118185,0.004264,40.895552,0.1928,0.28993803,10.173313,,,115.48901,0.3021,1,,,,4.0198853E-6,20.282503,13.511865,0.068201792,0
8242721.81,,5905,,4.063,90000.219,9.1E-6,3.8857931,0.036394909,0.28837258,0.001111,1.190803,0.004142,47.067943,0.1092,0.54089592,11.035575,0.00088810828,99.672684,116.51875,0.21,1,,,,4.2784177E-6,20.346626,15.099388,0.074212026,0
8242812.77,,5905,,4.0721,90000.219,9.1E-6,3.886406,0.038051083,0.29322104,0.001311,1.1913262,0.004144,47.839807,0.1534,2.0010308,11.305141,0.0020262439,99.256897,115.89124,0.2438,1,,,,4.2618144E-6,22.07115,15.104152,0.075447867,0
8242906.33,,5905,,4.0614,90000.219,9.1E-6,3.8867841,0.037751757,0.29164577,0.00115,1.1917757,0.004146,47.589647,0.1171,1.0960717,10.932696,,,116.11081,0.2149,1,,,,4.3529652E-6,22.610282,15.107091,0.075035238,0
8243119.84,,5905,,4.288,90000.219,9.1E-6,4.090466,0.03732815,0.33508303,0.001143,1.4031842,0.00654,54.71148,0.08309,0.26425157,11.767052,,,116.66918,0.1786,1,,,,4.6495487E-6,21.865393,16.731912,0.081918057,0
8243217.03,,5905,,4.2757,90000.219,9.1E-6,4.0917841,0.039318282,0.33509417,0.001278,1.4045897,0.006562,54.714659,0.1232,0.78719005,11.837834,,,116.70548,0.2078,1,,,,4.6220158E-6,23.534103,16.742697,0.081894393,0
8243314.5,,5905,,4.276,90000.219,9.1E-6,4.0918338,0.040345821,0.33637214,0.001322,1.4042727,0.006557,54.917654,0.134,0.96805896,12.010904,0.00027020681,99.909638,116.55891,0.2149,1,,,,4.5762433E-6,23.675669,16.743104,0.08220572,0
8243538.75,,5905,,4.5022,90000.219,9.1E-6,4.2925732,0.039302992,0.38379757,0.001666,1.6441466,0.01027,62.70243,0.1896,1.2328884,12.212505,,,117.01758,0.2392,1,,,,5.1342809E-6,24.021807,18.426185,0.089409674,0
8243637.89,,5905,,4.4904,90000.219,9.1E-6,4.2931487,0.040618071,0.38365871,0.00129,1.6452306,0.01028,62.681424,0.08839,0.12467898,12.699783,,,117.04738,0.1751,1,,,,4.9356295E-6,24.42501,18.431126,0.089365344,0
8243751.3,,5905,,4.51,90000.219,9.1E-6,4.2940949,0.042780397,0.38250813,0.001459,1.645946,0.01029,62.499092,0.1411,0.025218877,12.901582,0.00053108476,99.839233,117.19045,0.2088,1,,,,4.8516921E-6,25.399566,18.439251,0.089077707,0
8243984.31,,5905,,4.7149,90000.219,9.1E-6,4.4925108,0.042642747,0.42965134,0.001466,1.8988099,0.0115,70.251962,0.1065,0.71482912,13.517707,,,117.94635,0.1808,1,,,,5.1970324E-6,25.803165,20.182653,0.095637241,0
8244105.86,,5905,,4.7074,90000.219,9.1E-6,4.4931408,0.043576648,0.43656573,0.001675,1.899598,0.0115,71.352759,0.1631,0.54368598,13.625121,,,117.3368,0.2105,1,,,,5.2368532E-6,27.035414,20.188314,0.097162709,0
8244213.09,,5905,,4.7063,90000.219,9.1E-6,4.493709,0.04523672,0.43165299,0.001458,1.8998945,0.0115,70.571488,0.1024,0.51889415,13.712172,0.00059092079,99.835254,117.79517,0.1776,1,,,,5.1546731E-6,27.250242,20.193421,0.096057174,0
8244446.81,,5905,,4.9281,90000.219,9.1E-6,4.6948677,0.044551751,0.4862917,0.00169,2.1615927,0.009719,79.525649,0.1313,0.35784542,14.381441,,,118.27458,0.1866,1,,,,5.5297412E-6,27.424344,22.041783,0.10357943,0
8244558.91,,5905,,4.929,90000.219,9.1E-6,4.6960515,0.047513289,0.48215911,0.001894,2.1624959,0.009712,78.869099,0.1917,0.031557949,14.522022,0.0016157437,99.581209,118.64144,0.2185,1,,,,5.4526071E-6,28.762883,22.052899,0.1026733,0
8244671.28,,5905,,4.9175,90000.219,9.2E-6,4.6961732,0.04770209,0.48259373,0.001704,2.162566,0.009712,78.938312,0.1392,0.46165996,14.355089,0.00023870821,99.937557,118.60889,0.1914,1,,,,5.5022279E-6,29.044044,22.054043,0.10276319,0
8244910.28,,5905,,5.1353,90000.219,9.1E-6,4.8976764,0.04704309,0.53272835,0.001869,2.426187,0.009169,87.177841,0.1496,1.5903025,15.020277,,,119.68935,0.1914,1,,,,5.8040103E-6,28.710177,23.987234,0.10877165,0
8245026.69,,5905,,5.1329,90000.219,9E-6,4.8990243,0.049476106,0.53671051,0.00174,2.4271796,0.009176,87.812354,0.09819,0.55499405,15.184428,0.00099922166,99.754619,119.42546,0.1665,1,,,,5.796504E-6,30.040553,24.000439,0.10955457,0
8245141.92,,5905,,5.134,90000.219,9.1E-6,4.8990474,0.0496228,0.54077958,0.00179,2.427262,0.009176,88.459785,0.1148,0.20717403,15.294026,0.00067338395,99.834768,119.12573,0.1733,1,,,,5.7929988E-6,30.368856,24.000665,0.11038464,0
8245391.7,,5905,,5.3473,90000.219,9.2E-6,5.1013717,0.048240701,0.60157672,0.002182,2.691724,0.01319,98.396452,0.1903,0.21671696,15.452923,,,119.71741,0.2004,1,,,,6.3674976E-6,30.588052,26.023994,0.1179245,0
8245509.94,,5905,,5.347,90000.219,9.1E-6,5.1028756,0.051632008,0.58852218,0.002145,2.6934374,0.01323,96.321322,0.1897,0.16431728,16.059377,0.001201242,99.724131,120.63169,0.2033,1,,,,6.0135024E-6,30.905847,26.039339,0.11533148,0
8245633.16,,5905,,5.3587,90000.219,9E-6,5.1027201,0.05118849,0.59370116,0.002689,2.6936888,0.01323,97.145496,0.3176,0.29538979,15.846336,,,120.27623,0.2561,1,,,,6.1304706E-6,32.118754,26.037753,0.11634994,0
8245879.31,,5905,,5.5714,90000.219,9.1E-6,5.3051471,0.052459866,0.64613832,0.002342,2.969297,0.01863,105.76332,0.2043,4.552237,16.546085,0.0011291071,99.749356,121.56895,0.2033,1,,,,6.4072185E-6,31.692672,28.144586,0.12179461,0
8246005.7,,5905,,5.5666,90000.219,9.1E-6,5.3043216,0.052963265,0.64886245,0.003001,2.9686146,0.01862,106.19602,0.3602,0.29593078,16.465451,,,121.3797,0.2636,1,,,,6.449627E-6,33.09217,28.135828,0.12232713,0
8246131.31,,5905,,5.5623,90000.219,9.1E-6,5.3059997,0.052724654,0.65109834,0.002265,2.9709987,0.01866,106.55411,0.1759,0.37640104,16.572183,,,121.27895,0.1915,1,,,,6.429697E-6,32.930903,28.153633,0.12270983,0
8246384.75,,5905,,5.7867,90000.219,9.1E-6,5.5097281,0.054622363,0.70613385,0.002268,3.2752743,0.02041,115.61398,0.1197,0.71452214,17.223734,0.0003752104,99.920805,122.57489,0.1674,1,,,,6.7175033E-6,33.144365,30.357104,0.12816129,0
8246513.75,,5905,,5.7848,90000.219,9E-6,5.5106363,0.056421043,0.70376137,0.00222,3.2768026,0.0204,115.23807,0.09802,0.23367974,17.261239,0.0014053824,99.704513,122.7327,0.1599,1,,,,6.6947957E-6,34.447469,30.367113,0.12770964,0
8246642.8,,5905,,5.7821,90000.219,9.1E-6,5.510698,0.056735417,0.69854223,0.002429,3.276935,0.0204,114.40789,0.1895,2.2057814,17.188191,0.0019516307,99.590401,123.03899,0.1942,1,,,,6.6820244E-6,34.522478,30.367793,0.12676112,0
8246904.11,,5905,,6.0041,90000.219,9E-6,5.7121045,0.056811932,0.75918295,0.002564,3.6123443,0.01668,124.39062,0.1802,0.12344002,17.908857,0.0017365755,99.655053,124.04545,0.187,1,,,,6.9684281E-6,34.376382,32.628138,0.13290775,0
8247037.72,,5905,,5.9916,90000.219,9.1E-6,5.7126697,0.057125408,0.75526227,0.002509,3.6139601,0.01665,123.76849,0.1628,0.59921178,17.30607,,,124.27202,0.182,1,,,,7.1517388E-6,35.817713,32.634595,0.13220829,0
8247166.89,,5905,,5.9931,90000.219,9.1E-6,5.7127265,0.057025337,0.75995406,0.002574,3.6132292,0.01667,124.51418,0.1829,0.36457323,17.537893,0.00081873135,99.834074,124.01698,0.1878,1,,,,7.1108483E-6,34.61214,32.635244,0.13302826,0
8247168.89,Error: Warning: Current field is 90000.219 Oe;
8247168.98,Error: but addenda was obtained at 0.021 Oe.
8247250.02,Error: Temperature of platform does not match the system temperature : System = 5.9947 K;  Platform = 5.6836 K
8247418.8,,5905,,5.99,90000.219,9.2E-6,5.7129306,0.059126985,0.75403769,0.002814,3.6139303,0.01666,123.57365,0.2614,0.10220871,17.976481,0.00142008,99.721055,124.34494,0.2158,1,,,,6.8923063E-6,35.438145,32.637576,0.1319879,0
8247551.61,,5905,,6.0131,90000.219,9E-6,5.7131965,0.058869442,0.756588,0.002612,3.6141963,0.01665,123.97964,0.199,0.043466162,17.749645,0.0007515992,99.850183,124.21085,0.1939,1,,,,6.9947867E-6,35.952963,32.640615,0.13242814,0
8247683.77,,5905,,6.004,90000.219,9E-6,5.7130821,0.058222847,0.75858164,0.002746,3.6138531,0.01666,124.29646,0.239,0.37108991,17.697463,0.000666508,99.866429,124.09945,0.2072,1,,,,7.0322614E-6,35.49929,32.639308,0.13277975,0
8247927.66,,5905,,6.0482,90000.219,9.1E-6,5.762136,0.05803818,0.77046879,0.002448,3.7001418,0.01525,126.27388,0.1172,0.28221374,17.891562,0.0015538914,99.69383,124.51795,0.1655,1,,,,7.0781589E-6,35.394927,33.202211,0.13371236,0
8248059.98,,5905,,6.046,90000.219,9E-6,5.7627613,0.058495312,0.77398122,0.002511,3.7012375,0.01524,126.83377,0.1429,0.2890338,17.785499,0.00069148075,99.862598,124.33732,0.1738,1,,,,7.14055E-6,35.783123,33.209418,0.13430735,0
8248191.7,,5905,,6.0457,90000.219,9.1E-6,5.7626753,0.058411559,0.77321114,0.002456,3.70106,0.01524,126.71108,0.1169,0.13816559,17.792694,0.00036505244,99.927597,124.3822,0.1706,1,,,,7.126386E-6,35.570999,33.208426,0.13417573,0
8248436.11,,5905,,6.0959,90000.219,9E-6,5.8112363,0.058426431,0.78553733,0.002559,3.7882038,0.01376,128.75919,0.1494,0.089553655,18.117439,0.0015374447,99.702037,124.77081,0.1758,1,,,,7.1269298E-6,35.585387,33.770468,0.1351756,0
8248570.64,,5905,,6.1129,90000.219,9E-6,5.8117539,0.059203261,0.78866251,0.002607,3.7888943,0.01374,129.25707,0.1657,0.14518194,18.017703,0.00069000136,99.865249,124.61688,0.1808,1,,,,7.1830137E-6,36.234878,33.776483,0.13570129,0
8248703.55,,5905,,6.1036,90000.219,9.1E-6,5.8118547,0.058954574,0.78814278,0.002494,3.7893505,0.01374,129.17484,0.114,0.10122474,18.018177,0.0012648621,99.752926,124.64643,0.1638,1,,,,7.185872E-6,36.035406,33.777655,0.13560951,0
8248956.91,,5905,,6.1413,90000.219,9E-6,5.8598682,0.058899838,0.80127991,0.00257,3.8770108,0.01223,131.35248,0.1338,0.56913521,18.364902,0.0026184665,99.500039,124.98554,0.17,1,,,,7.1862184E-6,36.036353,34.338055,0.13674026,0
8249092.23,,5905,,6.1558,90000.219,9.1E-6,5.8599212,0.058135911,0.80522793,0.002603,3.8776325,0.01222,131.98119,0.1435,0.2698548,17.888044,,,124.78206,0.1729,1,,,,7.3781792E-6,36.729803,34.338677,0.13741276,0
8249225.72,,5905,,6.1492,90000.219,9.1E-6,5.8598255,0.059095932,0.79828246,0.002569,3.8767954,0.01223,130.8754,0.1376,0.27607863,18.143111,0.0015282979,99.706188,125.14087,0.1716,1,,,,7.2335216E-6,35.776088,34.337555,0.13622973,0
8249474.17,,5905,,6.212,90000.219,9E-6,5.90859,0.059270718,0.81457486,0.002586,3.9667936,0.01071,133.55736,0.1227,0.20231099,18.311657,0.0012289233,99.766646,125.33531,0.1662,1,,,,7.3096326E-6,36.286222,34.911435,0.13786282,0
8249608.69,,5905,,6.199,90000.219,9.1E-6,5.9088094,0.060003811,0.81458716,0.002653,3.9673151,0.0107,133.55983,0.1547,0.57796595,18.293438,0.0009154158,99.826114,125.33934,0.1765,1,,,,7.3129433E-6,36.623314,34.914029,0.13785978,0
8249743.67,,5905,,6.2155,90000.219,9.1E-6,5.9090322,0.059989575,0.81128053,0.002539,3.9676872,0.0107,133.03416,0.1011,0.17820491,18.17667,0.0015402875,99.706377,125.51413,0.1596,1,,,,7.3392397E-6,36.586876,34.916662,0.13729499,0
8249998.52,,5905,,6.2538,90000.219,9.1E-6,5.9568137,0.059093907,0.81394412,0.002777,4.0585259,0.009237,133.54874,0.2028,0.21976507,18.180372,,,126.39088,0.1937,1,,,,7.345765E-6,36.353339,35.483629,0.13664086,0
8250171.52,,5905,,6.2566,90000.219,9E-6,5.9575471,0.061105327,0.81744003,0.002784,4.0592529,0.009226,134.10564,0.2023,0.66370273,18.729402,0.0009505552,99.826833,126.22598,0.193,1,,,,7.1718472E-6,36.360745,35.492367,0.13721084,0
8250330.5,,5905,,6.2586,90000.219,9.2E-6,5.9578343,0.061277191,0.82187795,0.003097,4.0593405,0.009225,134.81175,0.2928,0.24995778,18.371768,0.0017077822,99.680805,126.00444,0.2212,1,,,,7.3600902E-6,37.458803,35.495789,0.13794911,0
8250593.28,,5905,,6.3034,90000.219,9.1E-6,6.0068614,0.06021662,0.83647408,0.002711,4.1527131,0.007848,137.22722,0.1531,0.55900865,18.378044,0.0012427297,99.769104,126.29803,0.176,1,,,,7.4831628E-6,36.743537,36.082384,0.1392531,0
8250727.94,,5905,,6.3136,90000.219,9.1E-6,6.0071882,0.060518923,0.84041189,0.002729,4.1534016,0.007838,137.85437,0.1559,0.7245402,18.442752,0.00048939385,99.909117,126.10732,0.1764,1,,,,7.4811142E-6,36.756087,36.08631,0.13990104,0
8250863.61,,5905,,6.308,90000.219,9.1E-6,6.0072693,0.060474085,0.84146952,0.002779,4.1536326,0.007835,138.02286,0.176,0.15118924,18.47656,0.0018961822,99.6473,126.05616,0.1826,1,,,,7.4950358E-6,36.885504,36.087285,0.14007521,0
8251114.58,,5905,,6.3671,90000.219,9E-6,6.0547876,0.060577083,0.85394457,0.002708,4.2453549,0.006645,140.09924,0.127,0.091705791,18.753693,0.0018233302,99.668155,126.43152,0.1672,1,,,,7.4938788E-6,36.95312,36.660453,0.14103626,0
8251252.19,,5905,,6.3505,90000.219,9.1E-6,6.0555873,0.061281264,0.85435772,0.002667,4.2465828,0.00663,140.16619,0.1016,0.11066145,18.546192,0.0014420734,99.734714,126.42783,0.1593,1,,,,7.5765851E-6,37.507385,36.670137,0.14108586,0
8251391.19,,5905,,6.3504,90000.219,9.1E-6,6.0550552,0.059531127,0.85083069,0.00266,4.246399,0.006633,139.60489,0.1038,0.26862488,18.19219,,,126.59117,0.1604,1,,,,7.6738915E-6,37.092384,36.663694,0.14051576,0
8251636.61,,5905,,6.4089,90000.219,9.1E-6,6.1032698,0.060080439,0.86707089,0.002735,4.3396218,0.005628,142.28177,0.1205,0.98781157,18.675275,0.00095530421,99.826744,126.79748,0.1651,1,,,,7.6311533E-6,36.38438,37.249902,0.14206662,0
8251774.53,,5905,,6.4124,90000.219,9.2E-6,6.1039879,0.061455142,0.86676782,0.003125,4.3409923,0.005615,142.23492,0.2694,0.24995131,18.683596,0.0010837554,99.803619,126.82718,0.2107,1,,,,7.6269038E-6,37.35055,37.258669,0.14200025,0
8251912.75,,5905,,6.4123,90000.219,9E-6,6.1040389,0.061691387,0.85919332,0.002883,4.3411252,0.005614,141.03003,0.1971,0.19424652,18.567588,0.0023980386,99.565438,127.19986,0.1896,1,,,,7.6266411E-6,37.367192,37.259291,0.14075817,0
8252166.58,,5905,,6.4706,90000.219,9.1E-6,6.1529383,0.060966919,0.88281922,0.002845,4.4374527,0.004825,144.885,0.1541,0.71180575,18.921266,0.0016150946,99.711763,127.06462,0.1749,1,,,,7.6780587E-6,37.135176,37.85865,0.14347929,0
8252307.03,,5905,,6.4654,90000.219,9.2E-6,6.153151,0.060502476,0.88344463,0.002807,4.4390349,0.004814,144.98608,0.1341,0.32623572,18.624544,,,127.03902,0.1688,1,,,,7.7846781E-6,37.842531,37.861267,0.14357597,0
8252445.63,,5905,,6.4533,90000.219,9.1E-6,6.1533856,0.061522378,0.87815429,0.002832,4.4382901,0.004819,144.14369,0.1542,0.92363355,18.693771,0.0011982005,99.784812,127.29849,0.1755,1,,,,7.7264085E-6,37.249087,37.864155,0.14271075,0
8252698.91,,5905,,6.5144,90000.219,9.1E-6,6.2017583,0.061000418,0.89888649,0.003342,4.5345241,0.004266,147.53821,0.308,0.018417504,18.832084,0.001369528,99.755354,127.30509,0.2199,1,,,,7.8524589E-6,37.387542,38.461806,0.14494059,0
8252837.72,,5905,,6.5154,90000.219,9E-6,6.2023044,0.061546668,0.89968637,0.003114,4.5356287,0.004261,147.66656,0.2394,0.1032298,18.729758,0.00063454184,99.886091,127.27856,0.1995,1,,,,7.8925089E-6,37.664168,38.46858,0.14505679,0
8253014.81,,5905,,6.5203,90000.219,9.1E-6,6.2016578,0.062451909,0.89965727,0.002956,4.5350969,0.004264,147.6614,0.1819,0.52335476,19.621995,0.0013347906,99.771033,127.26666,0.1825,1,,,,7.5415268E-6,37.459516,38.460559,0.14506722,0
8253283.95,,5905,,6.5681,90000.219,9.1E-6,6.2514628,0.063438259,0.90646614,0.002844,4.6344487,0.00391,148.84398,0.1172,0.86447755,19.060032,0.0019380349,99.661936,127.96669,0.164,1,,,,7.8340882E-6,39.243991,39.080787,0.14500065,0
8253424.02,,5905,,6.5734,90000.219,9.1E-6,6.2513173,0.062787202,0.90423918,0.002836,4.634539,0.00391,148.48978,0.1163,0.17835964,18.883249,0.0012152825,99.786757,128.06868,0.164,1,,,,7.8793446E-6,38.120064,39.078968,0.14464778,0
8253562.97,,5905,,6.567,90000.219,9.1E-6,6.2502779,0.060814631,0.9070581,0.003016,4.633393,0.003913,148.9371,0.1975,0.20822073,18.666384,,,127.9146,0.1876,1,,,,7.9788938E-6,37.766497,39.065973,0.14512284,0
8253825.58,,5905,,6.6197,90000.219,9.1E-6,6.2986002,0.061840592,0.91707903,0.003004,4.7304709,0.00375,150.6284,0.1817,0.050336409,19.015819,0.0015174197,99.737062,128.43228,0.1831,1,,,,7.9408088E-6,37.332768,39.672364,0.14560045,0
8253965.41,,5905,,6.6145,90000.219,9E-6,6.2992541,0.062622641,0.92184296,0.002923,4.731972,0.003749,151.3878,0.137,0.17795409,19.025549,0.0014808202,99.742375,128.22395,0.1695,1,,,,7.9763682E-6,38.031639,39.680602,0.14634161,0
8254104.45,,5905,,6.6215,90000.219,9E-6,6.2992552,0.062794438,0.92201425,0.003034,4.7321046,0.003749,151.41518,0.1883,0.27298928,19.161837,0.001658007,99.713485,128.21603,0.1844,1,,,,7.9232236E-6,38.051098,39.680615,0.14636877,0
8254366.41,,5905,,6.6729,90000.219,9E-6,6.3486006,0.062612288,0.93423297,0.003414,4.8328342,0.003749,153.45978,0.3036,0.099669912,18.9695,0.0011396709,99.802683,128.65455,0.2175,1,,,,8.1048206E-6,38.323674,40.30473,0.14715573,0
8254505.5,,5905,,6.6694,90000.219,9E-6,6.3487412,0.062925424,0.93200486,0.003332,4.8335473,0.003749,153.10603,0.2812,0.11549157,19.036922,0.00067506377,99.883896,128.75985,0.2114,1,,,,8.0513513E-6,37.939,40.306515,0.14680152,0
8254646.2,,5905,,6.6676,90000.219,9.1E-6,6.3489102,0.06288183,0.93622404,0.00343,4.8338964,0.003749,153.7776,0.3066,0.6387984,19.074188,0.00037780813,99.934906,128.56955,0.218,1,,,,8.067005E-6,38.073843,40.30866,0.14746217,0
8254898.86,,5905,,6.7162,90000.219,9.1E-6,6.3964058,0.061476052,0.94480329,0.003219,4.9332326,0.003891,155.24181,0.234,0.25260538,18.941722,,,129.13808,0.1975,1,,,,8.1957601E-6,38.148377,40.914007,0.14770847,0
8255039.47,,5905,,6.7289,90000.219,9E-6,6.3972117,0.063430016,0.94027969,0.003218,4.9343993,0.003893,154.52332,0.2379,0.26381385,19.301822,0.0025833126,99.565402,129.36115,0.1992,1,,,,8.0383865E-6,37.883445,40.924317,0.14698274,0
8255183.03,,5905,,6.7198,90000.219,9.1E-6,6.3968721,0.062059136,0.95061054,0.003307,4.9343912,0.003893,156.16685,0.2584,0.31832754,19.025608,,,128.88395,0.2036,1,,,,8.2082445E-6,38.603643,40.919973,0.14860553,0
8255454.5,,5905,,6.7528,90000.219,9E-6,6.4453672,0.062971219,0.96202043,0.003757,5.0352433,0.004155,158.08289,0.3771,0.24970008,19.475596,0.0023808613,99.602185,129.34555,0.2368,1,,,,8.1473641E-6,38.051216,41.542759,0.14925766,0
8255596.05,,5905,,6.7732,90000.219,9.1E-6,6.4463215,0.064655967,0.95283649,0.003771,5.0371582,0.004161,156.62374,0.3859,0.26690827,19.319154,0.0023704816,99.604432,129.77903,0.2411,1,,,,8.1373365E-6,38.951193,41.555061,0.14781089,0
8255737.42,,5905,,6.7528,90000.219,9.1E-6,6.4454975,0.062261935,0.96015489,0.00326,5.0361878,0.004158,157.78705,0.2339,0.13512936,18.900211,,,129.43189,0.1968,1,,,,8.348428E-6,38.638308,41.544438,0.14896521,0
8255988.39,,5905,,6.8205,90000.219,9E-6,6.4954921,0.062859376,0.97278621,0.003379,5.1411079,0.004531,159.90148,0.2629,0.36424893,19.301022,0.0016298025,99.727995,129.86876,0.2047,1,,,,8.3057805E-6,37.800422,42.191418,0.14976328,0
8256129.27,,5905,,6.8243,90000.219,9E-6,6.4959459,0.064577596,0.96785159,0.003545,5.1422087,0.004535,159.11754,0.3169,0.12298682,19.454201,0.0019626039,99.676493,130.09821,0.2206,1,,,,8.2039438E-6,38.602044,42.197313,0.14899317,0
8256271.64,,5905,,6.8065,90000.219,9.1E-6,6.4961086,0.064762091,0.96853027,0.003307,5.1425557,0.004537,159.22585,0.2425,0.14984754,19.402328,0.001882034,99.688794,130.07107,0.1996,1,,,,8.2305265E-6,38.908403,42.199427,0.14909392,0
8256532.64,,5905,,6.8739,90000.219,9.1E-6,6.5432059,0.062756481,0.9867936,0.003368,5.2443162,0.004973,162.23313,0.2466,0.17761472,19.30356,,,130.20068,0.1997,1,,,,8.4043112E-6,38.804657,42.813544,0.15081194,0
8256674.55,,5905,,6.883,90000.219,9E-6,6.5441153,0.064747046,0.98277736,0.003337,5.2453814,0.004978,161.59525,0.2394,0.26670678,19.667255,0.0027334752,99.555735,130.39598,0.1983,1,,,,8.2507905E-6,38.60712,42.825446,0.15017727,0
8256819.28,,5905,,6.8739,90000.219,9.1E-6,6.5439646,0.06363724,0.98363332,0.003359,5.2457212,0.00498,161.73176,0.2464,0.14409382,19.154114,,,130.35514,0.2002,1,,,,8.4437088E-6,39.33451,42.823473,0.15031153,0
8257083.56,,5905,,6.9334,90000.219,9.1E-6,6.5922144,0.064364365,0.99177308,0.003352,5.3490927,0.005475,163.13009,0.2363,0.71960611,19.624519,0.0026076547,99.579487,130.95595,0.1977,1,,,,8.3454079E-6,38.308228,43.45729,0.15044612,0
8257227.17,,5905,,6.909,90000.219,9.1E-6,6.5930685,0.06555363,0.99312578,0.00349,5.3506841,0.005483,163.34688,0.2811,0.11634186,19.472344,0.0014268554,99.768258,130.91342,0.2099,1,,,,8.4068914E-6,39.249038,43.468553,0.1506318,0
8257368.67,,5905,,6.9164,90000.219,9.1E-6,6.5927553,0.065348922,0.99161521,0.003478,5.3503601,0.005481,163.10624,0.2786,0.55471111,19.500818,0.0018185781,99.705308,130.97365,0.2094,1,,,,8.3871997E-6,38.944687,43.464422,0.15040983,0
8257636.88,,5905,,6.979,90000.219,9.1E-6,6.6406544,0.063029341,1.0102025,0.00367,5.4556598,0.006018,166.16859,0.3219,0.33816642,19.095848,,,131.11101,0.2199,1,,,,8.7018177E-6,39.001636,44.098291,0.15212394,0
8257779.34,,5905,,6.9713,90000.219,9.1E-6,6.6403331,0.063231219,1.0124722,0.003822,5.4553296,0.006016,166.52935,0.3627,0.46162378,19.58624,,,131.00662,0.2306,1,,,,8.5023641E-6,38.191697,44.094023,0.15247311,0
8257923.98,,5905,,6.9828,90000.219,9.1E-6,6.6408054,0.064033575,1.0106644,0.003361,5.4564478,0.006022,166.24286,0.2203,0.23924718,19.411284,,,131.09401,0.1924,1,,,,8.5642383E-6,39.172481,44.100296,0.15219004,0
8258195.58,,5905,,7.023,90000.219,9.1E-6,6.6904752,0.065061472,1.0152444,0.003619,5.5643805,0.006582,167.07943,0.3031,0.51824795,19.393679,0.0018730443,99.699225,131.8756,0.2157,1,,,,8.6394392E-6,38.822569,44.762459,0.15174474,0
8258337.36,,5905,,7.0272,90000.219,9E-6,6.6906538,0.065497891,1.018381,0.003582,5.5650258,0.006586,167.57906,0.2894,0.46008137,19.585027,0.002226571,99.644797,131.74358,0.2115,1,,,,8.585001E-6,38.787358,44.764848,0.15220949,0
8258480.39,,5905,,7.0292,90000.219,9.1E-6,6.6908034,0.065936336,1.0210612,0.003845,5.5656026,0.006589,168.00604,0.3632,0.14967291,19.773362,0.002513402,99.601771,131.63114,0.231,1,,,,8.528346E-6,39.170055,44.76685,0.15260667,0
8258741.59,,5905,,7.0852,90000.219,9.2E-6,6.7395627,0.066434152,1.0292218,0.003546,5.6738384,0.00714,169.41255,0.2683,0.32792836,19.822542,0.0022314587,99.651173,132.239,0.2058,1,,,,8.5744088E-6,39.546724,45.421705,0.15271345,0
8258884.98,,5905,,7.0749,90000.219,9.1E-6,6.7400773,0.066585713,1.0346045,0.00358,5.6749541,0.007145,170.26999,0.2749,0.69828588,19.751238,0.0018568113,99.707466,132.01932,0.2069,1,,,,8.6443617E-6,39.645085,45.428642,0.15350039,0
8259030.27,,5905,,7.077,90000.219,9.1E-6,6.7395302,0.06496982,1.0317148,0.003699,5.6748634,0.007145,169.81018,0.3145,0.30148996,19.398164,,,132.13175,0.2178,1,,,,8.7539305E-6,39.502477,45.421268,0.15308408,0
8259287.94,,5905,,7.1306,90000.219,9E-6,6.7874,0.064057451,1.0490236,0.003433,5.7827155,0.007662,172.67169,0.206,0.2255333,19.63122,,,132.33423,0.1882,1,,,,8.7957698E-6,38.796329,46.068799,0.15455456,0
8259431.2,,5905,,7.1405,90000.219,9.1E-6,6.7887127,0.066367046,1.0454733,0.003816,5.7841178,0.007668,172.10827,0.3383,0.29717881,19.654042,0.001692906,99.734175,132.5095,0.2236,1,,,,8.7786889E-6,39.262439,46.086621,0.1540017,0
8259575.7,,5905,,7.1279,90000.219,9.1E-6,6.7880756,0.064978268,1.0448656,0.003396,5.7839983,0.007668,172.01147,0.1951,0.25253936,19.462551,,,132.52275,0.1858,1,,,,8.8380739E-6,39.308084,46.077971,0.15392662,0
8259838.42,,5905,,7.1749,90000.219,9.1E-6,6.8361016,0.066255657,1.0538035,0.00377,5.8922198,0.008136,173.54162,0.3189,0.63131144,19.885627,0.0025564171,99.606719,133.08192,0.2188,1,,,,8.7591488E-6,38.925102,46.732285,0.15415269,0
8259983.34,,5905,,7.1769,90000.219,9.1E-6,6.8370463,0.067374618,1.052923,0.003591,5.8939851,0.008143,173.40332,0.262,0.16724384,19.612193,0.0013877132,99.784099,133.13741,0.2039,1,,,,8.8594609E-6,39.771253,46.745202,0.15400262,0
8260126.13,,5905,,7.1749,90000.219,9E-6,6.8368943,0.066339841,1.06327,0.003693,5.893513,0.008141,175.04894,0.2872,0.41618277,19.73658,0.0017250343,99.730722,132.70113,0.2091,1,,,,8.8916284E-6,39.224386,46.743124,0.15551945,0
8260382.23,,5905,,7.2262,90000.219,9.1E-6,6.8862053,0.067063588,1.0651341,0.0038,6.0066841,0.008565,175.45867,0.319,0.4024423,19.761267,0.0012970298,99.801138,133.58021,0.2187,1,,,,8.8954201E-6,39.473159,47.419824,0.15467649,0
8260527.44,,5905,,7.2319,90000.219,9.1E-6,6.886587,0.067083454,1.0732208,0.003747,6.0075581,0.008568,176.74605,0.2961,0.36627407,19.756047,0.0011719496,99.819049,133.25119,0.2116,1,,,,8.961563E-6,39.522535,47.425081,0.15584218,0
8260671.52,,5905,,7.2242,90000.219,9.1E-6,6.8866449,0.0673699,1.0688059,0.00357,6.0077771,0.008569,176.04392,0.2389,0.53140196,19.776565,0.0012702326,99.804811,133.43556,0.1973,1,,,,8.9178849E-6,39.512094,47.425878,0.1551998,0
8260930.47,,5905,,7.2764,90000.219,9E-6,6.9340644,0.065784684,1.084619,0.00367,6.1190443,0.008927,178.67088,0.2598,0.53533742,19.825948,,,133.69814,0.2022,1,,,,9.0119716E-6,39.55313,48.081249,0.15641894,0
8261074.97,,5905,,7.2723,90000.219,9.1E-6,6.9353505,0.067964523,1.0788066,0.003688,6.1207216,0.008932,177.74787,0.2715,0.28443199,19.863649,0.0014547855,99.779306,133.96269,0.206,1,,,,8.9668534E-6,39.651895,48.099086,0.15555186,0
8261240.17,,5905,,7.2967,90000.219,9.1E-6,6.9347474,0.066158466,1.0852975,0.003577,6.1206084,0.008931,178.78038,0.2234,0.20633927,19.657108,,,133.68343,0.1928,1,,,,9.094948E-6,39.727299,48.090722,0.15650137,0
8261506.8,,5905,,7.3375,90000.219,9E-6,6.9827124,0.065429824,1.1035039,0.003657,6.2326369,0.009237,181.78887,0.2355,0.21437284,19.843316,,,133.86356,0.1952,1,,,,9.161214E-6,39.314217,48.758273,0.1580337,0
8261651.78,,5905,,7.3398,90000.219,9.1E-6,6.9834925,0.066561053,1.0952334,0.003876,6.2346857,0.009242,180.47516,0.3184,0.51691854,19.732689,,,134.21471,0.2174,1,,,,9.1459995E-6,39.686633,48.769168,0.15683175,0
8261795.92,,5905,,7.3378,90000.219,9.1E-6,6.9833162,0.065961575,1.0983937,0.003587,6.2340113,0.00924,180.97725,0.2126,0.065567575,19.591461,,,134.08246,0.1899,1,,,,9.237558E-6,39.465377,48.766704,0.15728826,0
8262058.48,,5905,,7.3854,90000.219,9.1E-6,7.033365,0.067600496,1.1057589,0.003725,6.3510832,0.009506,182.26606,0.2587,0.22483165,20.117239,0.0031192192,99.537109,134.74288,0.2022,1,,,,9.0994474E-6,39.182921,49.468223,0.1572162,0
8262206.2,,5905,,7.3923,90000.219,9E-6,7.0335319,0.067145807,1.1130178,0.003712,6.3525775,0.009509,183.42237,0.2465,0.41217448,19.788311,,,134.45246,0.1983,1,,,,9.2692283E-6,40.234479,49.470572,0.15824451,0
8262350.98,,5905,,7.3906,90000.219,9E-6,7.0332632,0.06650904,1.1129401,0.003849,6.3521686,0.009508,183.4096,0.2948,0.37273628,19.807037,,,134.45045,0.2105,1,,,,9.2598199E-6,39.576622,49.466792,0.1582395,0
8262606.63,,5905,,7.4481,90000.219,9.1E-6,7.0825302,0.067974374,1.1248158,0.003971,6.4681965,0.009724,185.41493,0.3242,0.33688626,20.079634,0.001794105,99.734005,134.91401,0.2177,1,,,,9.2569208E-6,39.614074,50.162233,0.15881553,0
8262752.61,,5905,,7.4472,90000.219,9.1E-6,7.0830787,0.069189992,1.1212788,0.003729,6.4698388,0.009727,184.85387,0.2443,0.47471767,20.084362,0.0023776518,99.648425,135.0662,0.1982,1,,,,9.2341134E-6,40.159268,50.170004,0.15830387,0
8262897.66,,5905,,7.4258,90000.219,9.2E-6,7.0830467,0.069042086,1.1193647,0.003749,6.4695252,0.009726,184.54905,0.2541,0.22925416,19.865074,0.0018302071,99.726994,135.14254,0.2008,1,,,,9.313809E-6,40.168724,50.16955,0.15803436,0
8263171.67,,5905,,7.4742,90000.219,9.1E-6,7.1306483,0.068840409,1.1334972,0.003825,6.5842267,0.009898,186.91209,0.2679,0.41624816,20.254586,0.0014436823,99.789892,135.48288,0.204,1,,,,9.2462232E-6,39.730148,50.846145,0.15896131,0
8263318.53,,5905,,7.4909,90000.219,9.1E-6,7.1315084,0.070097581,1.1248705,0.00375,6.5859406,0.0099,185.54138,0.2488,0.29045407,19.90867,0.0018681976,99.725256,135.84478,0.2002,1,,,,9.3435148E-6,40.509172,50.858413,0.15773248,0
8263464.61,,5905,,7.4991,90000.219,9.2E-6,7.1311735,0.069120652,1.1317584,0.003946,6.5853152,0.009899,186.63654,0.3105,2.0580122,19.954557,0.0011827696,99.825606,135.56222,0.2149,1,,,,9.3682865E-6,39.817339,50.853635,0.15870577,0
8263739.27,,5905,,7.5454,90000.219,9.1E-6,7.1789446,0.067499862,1.151238,0.004131,6.7029683,0.01004,189.8532,0.3518,0.3439661,20.108147,,,135.6961,0.224,1,,,,9.4416058E-6,39.909115,51.537246,0.16036312,0
8263885.48,,5905,,7.5263,90000.219,9.2E-6,7.1796082,0.068322932,1.141381,0.003823,6.7045291,0.01004,188.28662,0.259,0.32948242,19.739815,,,136.09826,0.2023,1,,,,9.5384184E-6,40.216295,51.546773,0.15897539,0
8264030.75,,5905,,7.5474,90000.219,9E-6,7.1790535,0.067355036,1.1479866,0.003767,6.7029763,0.01004,189.33595,0.2297,0.16358254,19.822199,,,135.82617,0.1943,1,,,,9.5517127E-6,39.479631,51.538809,0.15990779,0
8264302.56,,5905,,7.5836,90000.219,9.2E-6,7.2284619,0.067615138,1.1600076,0.004035,6.8242228,0.01014,191.36961,0.315,0.94225262,20.018609,,,136.28683,0.2153,1,,,,9.5595857E-6,39.644397,52.250662,0.16047778,0
8264447.94,,5905,,7.5816,90000.219,9.1E-6,7.228986,0.068446102,1.1617815,0.003798,6.8257877,0.01014,191.65339,0.2264,0.37629984,20.075606,,,136.22729,0.1934,1,,,,9.5465807E-6,40.037218,52.258238,0.16071154,0
8264593.25,,5905,,7.5901,90000.219,9.1E-6,7.2297699,0.070006059,1.1613797,0.003925,6.8261276,0.01014,191.58982,0.2766,0.10914175,20.149577,0.0013761814,99.800883,136.25777,0.2057,1,,,,9.526023E-6,40.151211,52.269573,0.16063855,0
8264854.52,,5905,,7.642,90000.219,9.2E-6,7.2781586,0.07026884,1.1690627,0.004118,6.9454258,0.01022,192.93139,0.3339,0.78540084,20.189992,0.0013816773,99.802469,136.86853,0.2202,1,,,,9.5733704E-6,40.299154,52.971593,0.16062617,0
8265002.03,,5905,,7.6377,90000.219,9.1E-6,7.2785349,0.070562108,1.1734214,0.00384,6.9464788,0.01022,193.62586,0.2305,0.28985726,20.205472,0.0020126023,99.711309,136.70589,0.1944,1,,,,9.6086353E-6,40.379984,52.97707,0.1612167,0
8265149.39,,5905,,7.6399,90000.219,9.1E-6,7.2786143,0.070896999,1.1700522,0.004017,6.9467692,0.01022,193.09016,0.3005,0.68755409,20.248776,0.0015417034,99.780055,136.8385,0.2119,1,,,,9.5554291E-6,40.410945,52.978225,0.16075206,0
8265423.27,,5905,,7.6972,90000.219,9.1E-6,7.3273228,0.070924361,1.1791144,0.004057,7.06832,0.01027,194.6534,0.3055,0.69324008,20.256229,0.0019902036,99.718552,137.40034,0.2134,1,,,,9.6347485E-6,40.497552,53.689659,0.16092022,0
8265570.11,,5905,,7.6928,90000.219,9.1E-6,7.3270316,0.069369462,1.184022,0.003993,7.068983,0.01027,195.43483,0.2786,0.5918329,19.883577,,,137.20474,0.2063,1,,,,9.8289571E-6,40.512458,53.685392,0.16159641,0
8265715.28,,5905,,7.6994,90000.219,9.1E-6,7.3268816,0.06878715,1.1750588,0.003812,7.0686779,0.01027,194.00856,0.2163,0.29356922,19.656063,,,137.54998,0.1921,1,,,,9.8701637E-6,39.767154,53.683194,0.16037638,0
8265972.36,,5905,,7.7437,90000.219,9.1E-6,7.3763811,0.070398507,1.1880061,0.003902,7.1923502,0.0103,196.19202,0.2394,0.68443158,20.460924,0.0031907652,99.556746,137.97424,0.1977,1,,,,9.6282447E-6,39.312125,54.410998,0.16105542,0
8266120.91,,5905,,7.7446,90000.219,9.2E-6,7.3774374,0.070369315,1.1920425,0.003889,7.1961755,0.0103,196.838,0.229,0.18743837,19.900202,,,137.83803,0.1949,1,,,,9.8912561E-6,40.921848,54.426583,0.16157948,0
8266266.55,,5905,,7.7342,90000.219,9.1E-6,7.3771835,0.071098959,1.1897638,0.004012,7.1943833,0.0103,196.47369,0.2798,0.1723505,20.290222,0.0025347844,99.644786,137.92125,0.2073,1,,,,9.7152118E-6,39.800405,54.422837,0.16127616,0
8266535.41,,5905,,7.7787,90000.219,9E-6,7.4260793,0.071802396,1.2034456,0.004121,7.3182961,0.0103,198.77424,0.3052,2.3815706,20.329584,0.0016548225,99.770004,138.30712,0.2132,1,,,,9.7984976E-6,40.580444,55.146654,0.16205666,0
8266683.5,,5905,,7.7982,90000.219,9.2E-6,7.4268005,0.072391189,1.2014372,0.003867,7.3201808,0.0103,198.4566,0.2072,0.15226697,20.223405,0.0014035116,99.804316,138.39761,0.1899,1,,,,9.8310623E-6,40.659168,55.157366,0.16177049,0
8266830.55,,5905,,7.7916,90000.219,9.1E-6,7.4266496,0.072203283,1.1981004,0.004021,7.3197318,0.0103,197.92531,0.2749,0.29140797,20.158093,0.0021501199,99.699737,138.52318,0.2066,1,,,,9.8460791E-6,40.446811,55.155124,0.16132449,0
8267098.64,,5905,,7.8516,90000.219,9.1E-6,7.474236,0.071909425,1.2162258,0.004309,7.4417268,0.0103,200.93086,0.3553,1.0152273,20.370009,0.0012824973,99.823199,138.7146,0.225,1,,,,9.880255E-6,40.316186,55.864204,0.16272242,0
8267246.83,,5905,,7.8426,90000.219,9.1E-6,7.4744518,0.073101011,1.2113467,0.004168,7.4426998,0.0103,200.15562,0.314,0.039039047,20.423586,0.00243856,99.665544,138.90464,0.2158,1,,,,9.83071E-6,40.740019,55.86743,0.16206495,0
8267394.47,,5905,,7.8541,90000.219,9E-6,7.4747824,0.072957497,1.2139675,0.004052,7.4433579,0.0103,200.57322,0.2702,0.055986687,20.290627,0.0017292758,99.761007,138.81073,0.205,1,,,,9.9069764E-6,40.847172,55.872372,0.16240841,0
8267666.31,,5905,,7.8992,90000.219,9E-6,7.5228358,0.072585381,1.2254508,0.003991,7.5675887,0.01028,202.52433,0.2325,0.22553195,20.393679,0.0024471069,99.665452,139.26525,0.1961,1,,,,9.9616339E-6,40.581254,56.593058,0.16289746,0
8267815.13,,5905,,7.8921,90000.219,9.1E-6,7.5236913,0.073438378,1.2227182,0.003867,7.5699713,0.01028,202.09199,0.176,0.28762312,20.341967,0.0021894266,99.700716,139.3848,0.1829,1,,,,9.962365E-6,40.787359,56.605931,0.16251574,0
8267963.52,,5905,,7.9011,90000.219,9E-6,7.52277,0.071456536,1.2271969,0.004037,7.5690824,0.01028,202.8036,0.2497,0.28529578,20.115841,,,139.19794,0.2001,1,,,,1.0081786E-5,40.683934,56.592068,0.16313098,0
8268231.78,,5905,,7.9516,90000.219,9.1E-6,7.5724108,0.072490758,1.2393197,0.004024,7.6967163,0.01026,204.85985,0.2298,0.11209854,20.351242,0.0015881257,99.783789,139.65799,0.1954,1,,,,1.0086414E-5,40.231682,57.341405,0.1636625,0
8268378.78,,5905,,7.9466,90000.219,9.1E-6,7.5731751,0.073899876,1.2306169,0.003988,7.6990338,0.01026,203.47765,0.2249,0.15699062,20.280188,0.001797955,99.75597,140.00065,0.1951,1,,,,1.0056046E-5,40.702484,57.352981,0.16249683,0
8268525.83,,5905,,7.9378,90000.219,9.1E-6,7.5730799,0.073465131,1.2351995,0.004009,7.6986521,0.01026,204.20632,0.2284,0.17497885,20.260695,0.0017704574,99.758637,139.82549,0.1955,1,,,,1.0101523E-5,40.560376,57.351538,0.16310399,0
8268793.11,,5905,,7.9886,90000.219,9.2E-6,7.6215023,0.073407702,1.2460597,0.004051,7.8259744,0.01023,206.06138,0.2334,0.11785907,20.30292,0.0011340175,99.846926,140.30942,0.1969,1,,,,1.0163748E-5,40.521391,58.087297,0.16349266,0
8268940.45,,5905,,8.0048,90000.219,9.1E-6,7.6220882,0.073503509,1.2519218,0.004123,7.8274386,0.01023,206.99544,0.2569,0.54058512,20.179871,0.0011899047,99.837716,140.10079,0.2018,1,,,,1.0272958E-5,40.60584,58.096229,0.16424919,0
8269088.3,,5905,,7.9955,90000.219,9.2E-6,7.6210512,0.071948595,1.2463152,0.003997,7.8264772,0.01023,206.10253,0.208,0.42466591,20.021146,,,140.29152,0.1909,1,,,,1.0294243E-5,40.359742,58.080421,0.16353587,0
8269090.53,Error: Warning: Current field is 90000.219 Oe;
8269090.66,Error: but addenda was obtained at 0.021 Oe.
8269172.53,Error: Temperature of platform does not match the system temperature : System = 7.9975 K;  Platform = 7.5852 K
8269377.64,,5905,,7.9932,90000.219,9.1E-6,7.6233977,0.076118555,1.2582526,0.004023,7.8322512,0.01023,208.00742,0.2039,0.55408011,20.222605,,,139.88939,0.189,1,,,,1.0285887E-5,44.547682,58.116192,0.16505142,0
8269524.72,,5905,,8.0095,90000.219,9.1E-6,7.6217527,0.073847434,1.2458182,0.004077,7.8268103,0.01023,206.02379,0.2448,0.15051309,20.32836,0.0017701612,99.761248,140.3231,0.1996,1,,,,1.0157245E-5,40.44521,58.091114,0.1634556,0
8269672.73,,5905,,8.0095,90000.219,9.1E-6,7.6216963,0.074213529,1.2506968,0.004082,7.8271731,0.01023,206.8003,0.241,0.39279335,20.694543,0.0032166761,99.571606,140.13932,0.1982,1,,,,1.0032794E-5,40.65672,58.090255,0.16409691,0
8269956.55,,5905,,8.2294,90000.219,9.1E-6,7.8387278,0.07614678,1.3041141,0.004124,8.4114822,0.01012,215.88274,0.1878,0.1619681,20.800337,0.002493088,99.679036,142.13388,0.1866,1,,,,1.040968E-5,41.389087,61.445654,0.16636808,0
8270107.75,,5905,,8.2317,90000.219,9.1E-6,7.839892,0.076624538,1.3002978,0.004255,8.4143394,0.01012,215.27848,0.2553,0.32504018,20.348227,0.0019954928,99.738312,142.29397,0.2024,1,,,,1.060535E-5,41.600674,61.463907,0.1658566,0
8270256.58,,5905,,8.2267,90000.219,9.1E-6,7.8387644,0.074193512,1.3031347,0.00431,8.4135604,0.01012,215.72901,0.2745,0.15274603,20.384033,,,142.17015,0.2065,1,,,,1.0583235E-5,40.696455,61.446227,0.16624236,0
8270539.77,,5905,,8.4486,90000.219,9.1E-6,8.0577453,0.077915389,1.3444989,0.004482,9.0253376,0.01009,222.92142,0.2972,0.41954712,20.854178,0.0030254239,99.62537,144.62687,0.2132,1,,,,1.0726546E-5,40.768067,64.927259,0.16685796,0
[...]
8279158.47,,5905,,11.4084,90000.219,9.1E-6,11.017632,0.10943271,2.1028932,0.006548,19.714211,0.02455,354.2631,0.2395,0.095739758,22.263163,0.0027478317,99.764702,170.33441,0.2133,1,,,,1.5945997E-5,43.99243,121.38821,0.19086618,0
8279458.13,,5905,,11.6329,90000.219,9.1E-6,11.236245,0.11144223,2.1664311,0.006881,20.6756,0.02541,365.33271,0.3277,0.31359578,22.621354,0.0038579336,99.679775,171.99513,0.2289,1,,,,1.6196088E-5,44.526326,126.25319,0.19280739,0
8279642.89,,5905,,11.6361,90000.219,9E-6,11.239041,0.11311046,2.1676246,0.006697,20.688293,0.02542,365.53528,0.2077,0.87109393,22.430122,0.0029899482,99.749857,172.00629,0.2089,1,,,,1.6333002E-5,45.242709,126.31605,0.19286561,0
8279803.45,,5905,,11.6398,90000.219,9E-6,11.239103,0.11265595,2.1661925,0.006815,20.688422,0.02542,365.30759,0.2914,0.08066669,22.439477,0.0033976926,99.715956,172.04521,0.2229,1,,,,1.6320959E-5,44.860245,126.31743,0.19273714,0
8280103.06,,5905,,11.8643,90000.219,9.1E-6,11.458156,0.11375633,2.2305987,0.006859,21.673968,0.02613,376.5395,0.1849,1.3118368,22.713385,0.0034845711,99.716571,173.68942,0.2063,1,,,,1.6619726E-5,44.878955,131.28933,0.19467345,0
8280287.48,,5905,,11.8638,90000.219,9.1E-6,11.458295,0.11615778,2.2344837,0.007208,21.676619,0.02613,377.16022,0.3931,0.016544852,23.09441,0.0042704422,99.657734,173.59054,0.24,1,,,,1.638107E-5,45.426769,131.29253,0.19501013,0
8280475,,5905,,11.8639,90000.219,9.1E-6,11.456648,0.11636047,2.2301588,0.006981,21.666595,0.02612,376.46214,0.2782,0.060321097,22.486151,0.0028820075,99.76327,173.678,0.2215,1,,,,1.6777246E-5,46.188821,131.25477,0.19466068,0
8280775.59,,5905,,12.0911,90000.219,9.1E-6,11.674813,0.1152213,2.2924534,0.007227,22.668055,0.02667,387.37404,0.3172,0.034662989,22.5716,0.0029310138,99.763869,175.3629,0.2288,1,,,,1.7198021E-5,44.972302,136.30126,0.1963589,0
8280937.13,,5905,,12.0911,90000.219,9.1E-6,11.6759,0.11681401,2.2941025,0.007131,22.674321,0.02668,387.64265,0.253,0.21440648,22.760525,0.0035674527,99.714761,175.33706,0.2184,1,,,,1.7074551E-5,45.1432,136.32663,0.19648186,0
8281099.06,,5905,,12.0873,90000.219,9.1E-6,11.676455,0.11733751,2.2965839,0.007161,22.675932,0.02668,388.03903,0.2686,0.071620247,22.764326,0.0033066823,99.735462,175.28205,0.2208,1,,,,1.7086015E-5,45.52105,136.33961,0.19668502,0
8281397.25,,5905,,12.3216,90000.219,9.2E-6,11.894638,0.11864141,2.3594937,0.00762,23.697841,0.02705,399.06926,0.4192,0.13750848,23.170828,0.0041081479,99.681802,176.95112,0.2455,1,,,,1.7271568E-5,45.528652,141.48241,0.19836617,0
8281561.17,,5905,,12.3174,90000.219,9.1E-6,11.897429,0.12028908,2.3655047,0.007308,23.711097,0.02706,400.03879,0.2267,0.2888398,22.922186,0.0028441725,99.777088,176.8421,0.215,1,,,,1.7486543E-5,46.341657,141.54881,0.19882486,0
8281724.95,,5905,,12.3214,90000.219,9.1E-6,11.897454,0.11953844,2.364074,0.007366,23.710754,0.02706,399.81085,0.273,0.2688541,22.87225,0.0029301865,99.769953,176.87826,0.2223,1,,,,1.7515843E-5,45.844373,141.54942,0.19870419,0
8282027.16,,5905,,12.5415,90000.219,9.1E-6,12.114952,0.12085127,2.4310631,0.00774,24.750424,0.02734,411.5078,0.3775,0.14704961,23.472019,0.0041839615,99.683898,178.4363,0.2392,1,,,,1.7580962E-5,45.7445,146.77207,0.20066634,0
8282194.27,,5905,,12.5494,90000.219,9.2E-6,12.118244,0.1232812,2.4291963,0.007571,24.765384,0.02734,411.22577,0.2817,0.29566639,23.15743,0.0035293606,99.730154,178.53067,0.2246,1,,,,1.7800275E-5,46.944038,146.85184,0.20045777,0
8282359.17,,5905,,12.5454,90000.219,9.2E-6,12.118191,0.12231716,2.4298058,0.007613,24.765882,0.02734,411.32323,0.3075,0.083381666,23.148634,0.0032614488,99.750531,178.51489,0.2286,1,,,,1.7808044E-5,46.31486,146.85055,0.20050896,0
8282665.02,,5905,,12.7715,90000.219,9.1E-6,12.335538,0.12347472,2.499902,0.008019,25.826511,0.02763,423.53546,0.4184,0.13948791,23.678594,0.0046277571,99.657784,179.99574,0.246,1,,,,1.794102E-5,46.297269,152.1655,0.20265853,0
8282832.89,,5905,,12.7756,90000.219,9.1E-6,12.33861,0.12566498,2.4985642,0.007764,25.840314,0.02763,423.33643,0.2736,0.33969075,23.305947,0.0029667463,99.777519,180.07282,0.2242,1,,,,1.8200022E-5,47.357187,152.24131,0.20249965,0
8283022.81,,5905,,12.7756,90000.219,9.1E-6,12.334227,0.12435263,2.4971071,0.00787,25.81776,0.02763,423.08206,0.3439,0.050436815,23.184091,0.0026890463,99.797263,180.04399,0.2348,1,,,,1.8281499E-5,46.611895,152.13315,0.20245347,0
8283350.64,,5905,,13.0002,90000.219,9.1E-6,12.552837,0.12416635,2.5727145,0.008016,26.907106,0.02802,436.19977,0.2963,0.038123473,23.351911,0.0026046251,99.807012,181.4148,0.2281,1,,,,1.8711208E-5,46.368183,157.57373,0.20495083,0
8283518.11,,5905,,13.0001,90000.219,9.1E-6,12.555823,0.12488959,2.5694628,0.008123,26.919566,0.02803,435.69492,0.3684,5.5258403,22.803633,0.0009672721,99.926785,181.5348,0.239,1,,,,1.9118705E-5,46.703821,157.6487,0.20464311,0
8283680.38,,5905,,13.0001,90000.219,9E-6,12.553151,0.1246845,2.5657461,0.008031,26.909518,0.02802,435.09358,0.3202,0.0658417,23.52999,0.0036954053,99.728768,181.58413,0.232,1,,,,1.8535292E-5,45.607266,157.58159,0.20439061,0
8283983.09,,5905,,13.2278,90000.219,9.2E-6,12.773299,0.12792819,2.6440381,0.008426,28.031496,0.02863,448.67102,0.4147,0.10810504,24.059538,0.0041007482,99.708366,182.9184,0.2461,1,,,,1.8696313E-5,47.05998,163.15716,0.20699728,0
8284154.05,,5905,,13.2276,90000.219,9.1E-6,12.776662,0.13015886,2.6489834,0.008266,28.047813,0.02865,449.47409,0.314,0.1453186,23.808623,0.0031576796,99.772924,182.85209,0.2313,1,,,,1.8916402E-5,48.119077,163.24309,0.20732985,0
8284323.23,,5905,,13.2276,90000.219,9.1E-6,12.776794,0.12948432,2.6446099,0.00831,28.048146,0.02865,448.77864,0.3496,0.25139678,23.792125,0.0035497661,99.744869,182.9552,0.2367,1,,,,1.8904898E-5,47.617247,163.24646,0.20698541,0
8284630.84,,5905,,13.4556,90000.219,9E-6,12.996265,0.13069484,2.715953,0.008598,29.193857,0.02958,461.27431,0.396,0.17371605,24.345219,0.0045985471,99.680612,184.4459,0.244,1,,,,1.9000502E-5,47.58425,168.9029,0.2089795,0
8284802.7,,5905,,13.4556,90000.219,9E-6,12.999903,0.13292302,2.7173864,0.008416,29.211704,0.02959,461.5202,0.2763,0.29407922,23.994538,0.0035072861,99.752998,184.46491,0.2269,1,,,,1.9276181E-5,48.690438,168.99747,0.20903129,0
8284973.66,,5905,,13.4556,90000.219,9.1E-6,12.999674,0.1317494,2.7187169,0.008418,29.211113,0.02959,461.73128,0.2747,0.16609621,23.946494,0.0028712701,99.797362,184.43142,0.2266,1,,,,1.9316149E-5,47.989075,168.99152,0.20913732,0
8285278.2,,5905,,13.6826,90000.219,9E-6,13.216751,0.13279283,2.7937101,0.00895,30.372098,0.03092,474.82292,0.4618,0.13457877,24.598293,0.0048102964,99.672581,185.8091,0.2535,1,,,,1.9358652E-5,47.892989,174.68249,0.21137647,0
8285451.92,,5905,,13.6822,90000.219,9.1E-6,13.220638,0.13564173,2.7941356,0.0087,30.392266,0.03094,474.91078,0.3183,0.13415891,24.319502,0.0039021773,99.731588,185.85427,0.2335,1,,,,1.9574034E-5,49.196586,174.78528,0.2113465,0
8285647.77,,5905,,13.6822,90000.219,9E-6,13.220565,0.1347688,2.7925294,0.008647,30.391298,0.03094,474.65428,0.2826,0.637679,24.288477,0.0037547668,99.74154,185.88907,0.2286,1,,,,1.9586735E-5,48.639003,174.78335,0.21122617,0
8285959.64,,5905,,13.9107,90000.219,9.1E-6,13.437435,0.13550384,2.8725847,0.009151,31.578876,0.0326,488.57785,0.4491,0.1575552,24.814763,0.0046223362,99.691173,187.15642,0.252,1,,,,1.9742372E-5,48.576954,180.56465,0.21377479,0
8286135.2,,5905,,13.9062,90000.219,9.1E-6,13.441201,0.13811076,2.8748588,0.008965,31.597453,0.03263,488.95821,0.3368,0.18411403,24.637839,0.0038744638,99.739329,187.15921,0.2365,1,,,,1.9891211E-5,49.629527,180.66589,0.21388407,0
8286309.42,,5905,,13.9062,90000.219,9E-6,13.441474,0.13724859,2.8733101,0.008943,31.599229,0.03263,488.7136,0.3245,0.11517771,24.421645,0.0026190705,99.822434,187.19683,0.2349,1,,,,2.0042639E-5,49.275679,180.67323,0.21376451,0
8286624.13,,5905,,14.1342,90000.219,9.1E-6,13.659237,0.13913342,2.9531874,0.01005,32.819727,0.03454,502.64176,0.7284,11.105641,25.836586,0.0071085268,99.547658,188.48788,0.2897,1,,,,1.9531906E-5,48.843291,186.57475,0.21620442,0
8286804.83,,5905,,14.1389,90000.219,9.1E-6,13.666231,0.14307785,2.9523393,0.009151,32.854727,0.0346,502.54183,0.3057,0.22917516,24.795133,0.0038281306,99.746848,188.60257,0.2331,1,,,,2.0312701E-5,51.673172,186.76586,0.21603172,0
8286980.19,,5905,,14.1341,90000.219,9.1E-6,13.665021,0.13952377,2.9571542,0.009184,32.848956,0.03459,503.30206,0.3198,0.13540719,24.774431,0.0032501179,99.784615,188.48279,0.2348,1,,,,2.0353702E-5,49.590266,186.73279,0.2164032,0
8287295,,5905,,14.364,90000.219,9.1E-6,13.883253,0.14066823,3.0347008,0.00971,34.094063,0.03663,516.88405,0.4959,0.15129365,25.397769,0.0050267846,99.677976,189.83644,0.2587,1,,,,2.0408926E-5,49.548862,192.74471,0.21858716,0
8287473.34,,5905,,14.3636,90000.219,9.2E-6,13.887203,0.14348849,3.0351839,0.009447,34.11395,0.03666,516.98079,0.3428,0.17210813,25.047072,0.0040169781,99.739278,189.8803,0.2386,1,,,,2.0687445E-5,50.795538,192.85439,0.21855978,0
8287649.25,,5905,,14.3636,90000.219,9.1E-6,13.887041,0.14218564,3.0347229,0.009497,34.113756,0.03666,516.90726,0.3772,0.090518806,24.999585,0.0040504755,99.736633,189.88778,0.2431,1,,,,2.0724271E-5,50.094145,192.84992,0.21852912,0
8287965.39,,5905,,14.5898,90000.219,9.1E-6,14.105064,0.14304102,3.1179743,0.009868,35.380907,0.03872,531.41885,0.4527,0.1758524,25.579693,0.0050763795,99.679901,191.12409,0.2532,1,,,,2.0833166E-5,49.999171,198.95282,0.22105354,0
8288144.78,,5905,,14.596,90000.219,9.1E-6,14.108705,0.14625473,3.1213262,0.009934,35.402354,0.03875,531.97356,0.483,0.15124221,25.561959,0.0046985565,99.703452,191.10443,0.2571,1,,,,2.0865086E-5,51.159387,199.05554,0.22123408,0
8288349.03,,5905,,14.5898,90000.219,9.1E-6,14.110046,0.14582575,3.113288,0.009713,35.408458,0.03876,530.70087,0.3675,0.7662347,25.167415,0.00285739,99.817421,191.28821,0.2425,1,,,,2.1120424E-5,51.123918,199.09339,0.22064337,0
8288719.34,,5905,,14.8195,90000.219,9.1E-6,14.328904,0.14283012,3.161425,0.01196,36.710508,0.04074,539.66103,1.137,0.50660102,25.045271,,,193.2565,0.3436,1,,,,2.1547422E-5,50.33483,205.3175,0.22063271,0
8288896.75,,5905,,14.8195,90000.219,9.2E-6,14.330776,0.14326548,3.1741437,0.01232,36.72193,0.04076,541.69587,1.224,15.744821,25.040635,,,193.02116,0.3537,1,,,,2.1632673E-5,50.090541,205.37114,0.22149141,0
8289073.72,,5905,,14.8164,90000.219,9E-6,14.332494,0.14610481,3.204245,0.009937,36.725909,0.04076,546.48865,0.3362,1.1569986,25.702893,0.004766485,99.703521,192.4329,0.2388,1,,,,2.1316779E-5,50.08127,205.42037,0.22356507,0
8289422.81,,5905,,15.045,90000.219,9.2E-6,14.55034,0.14929323,3.2878914,0.01052,38.035186,0.04252,561.10522,0.5355,0.21703908,26.144669,0.0052305749,99.682657,193.67241,0.2642,1,,,,2.152094E-5,51.405785,211.71238,0.22596665,0
8289605.91,,5905,,15.045,90000.219,9.2E-6,14.553728,0.15166295,3.2890913,0.01026,38.05416,0.04255,561.31508,0.3876,0.094291104,25.829447,0.0039581328,99.757088,193.69375,0.2458,1,,,,2.1777588E-5,52.289338,211.81101,0.22599648,0
8289786.63,,5905,,15.0449,90000.219,9.1E-6,14.553484,0.15052278,3.2880882,0.01027,38.053686,0.04255,561.15503,0.3928,0.10941406,25.803987,0.0041114383,99.747477,193.71037,0.2465,1,,,,2.1794683E-5,51.658894,211.80389,0.22593135,0
8290109.56,,5905,,15.2731,90000.219,9E-6,14.772073,0.15131577,3.3841174,0.01083,39.388791,0.04405,577.76739,0.5546,0.1832711,26.418305,0.0045064811,99.730945,194.72468,0.2662,1,,,,2.1921204E-5,51.607975,218.21414,0.22908886,0
8290294.36,,5905,,15.2731,90000.219,9.1E-6,14.776241,0.15548217,3.3600138,0.01048,39.412362,0.04407,573.95632,0.3978,0.13531576,26.137214,0.0040068099,99.759869,195.24876,0.2481,1,,,,2.2005209E-5,52.83661,218.3373,0.227393,0
8290503.88,,5905,,15.2764,90000.219,9.1E-6,14.77638,0.15454257,3.3439872,0.01049,39.412914,0.04407,571.40722,0.4306,0.57902381,25.778708,0.0019259498,99.88356,195.56498,0.2528,1,,,,2.2188259E-5,52.274428,218.3414,0.22630626,0
8290827.8,,5905,,15.4985,90000.219,9.1E-6,14.990709,0.15593971,3.4766439,0.01179,40.751723,0.04536,593.85035,0.8423,2.2665192,28.181868,0.0099682874,99.444303,195.82009,0.3003,1,,,,2.1174253E-5,51.557417,224.72134,0.23191992,0
8291053.19,,5905,,15.4985,90000.219,9.2E-6,14.99719,0.16278951,3.515705,0.01263,40.784905,0.04539,600.09775,1.079,1.2738412,27.456234,0.010006236,99.422199,195.16877,0.326,1,,,,2.1966904E-5,56.363736,224.91571,0.23442424,0
8291301.66,,5905,,15.4985,90000.219,9E-6,15.000878,0.16158421,3.4592984,0.01246,40.806372,0.04541,591.14551,1.073,0.030621491,26.853961,0.0064200356,99.626964,196.28331,0.3291,1,,,,2.20848E-5,54.912467,225.02634,0.2306064,0
8291659.91,,5905,,15.7305,90000.219,9.1E-6,15.213091,0.15993239,3.5463402,0.01218,42.143684,0.04656,606.33029,0.9127,0.030186695,26.963786,0.0050704035,99.708625,197.40045,0.3092,1,,,,2.2543744E-5,53.707922,231.43814,0.23311109,0
8291875.92,,5905,,15.723,90000.219,9.1E-6,15.210987,0.16429707,3.5446405,0.01264,42.135538,0.04655,606.05173,1.06,0.18889748,28.007569,0.0089681812,99.503213,197.40503,0.3266,1,,,,2.1732421E-5,53.927571,231.37412,0.23303159,0
8292070.66,,5905,,15.7305,90000.219,9.1E-6,15.212114,0.16279294,3.5796587,0.01483,42.132539,0.04655,611.61978,1.609,0.022736414,26.565455,0.0074636817,99.560557,196.76656,0.3881,1,,,,2.3111251E-5,56.015138,231.40842,0.23531632,0
8292400.41,,5905,,15.9548,90000.219,9.1E-6,15.431325,0.16123118,3.6379333,0.01169,43.539255,0.04773,622.29739,0.6197,0.17607098,27.354418,0.0059109112,99.667108,198.51806,0.2747,1,,,,2.2815166E-5,53.130911,238.12578,0.23574991,0
8292589.66,,5905,,15.9543,90000.219,9.1E-6,15.436052,0.16498719,3.6396405,0.01135,43.568537,0.04775,622.59827,0.4254,0.17574879,26.976841,0.0041293586,99.764397,198.54745,0.2523,1,,,,2.312614E-5,54.708837,238.2717,0.23578831,0
8292778.67,,5905,,15.9548,90000.219,9.2E-6,15.43591,0.16367982,3.6368607,0.0114,43.566526,0.04775,622.15401,0.464,0.10432291,26.915336,0.0039263082,99.775627,198.59679,0.2568,1,,,,2.3160186E-5,53.953682,238.2673,0.23561039,0
8293113.88,,5905,,16.1817,90000.219,9.1E-6,15.651686,0.16489513,3.7260186,0.01183,44.969257,0.04897,637.74086,0.5611,0.17766125,27.582685,0.0056322807,99.687735,199.73399,0.2682,1,,,,2.3183642E-5,53.830672,244.97527,0.23805861,0
8293305.42,,5905,,16.1817,90000.219,9.1E-6,15.656811,0.16878161,3.7199862,0.01149,45.001912,0.04899,636.81382,0.3569,2.0012592,27.271794,0.0040257839,99.774856,199.90871,0.2453,1,,,,2.3396153E-5,55.165371,245.13574,0.23759539,0
8293495.92,,5905,,16.1763,90000.219,9.1E-6,15.655976,0.16715371,3.7335411,0.01167,44.997416,0.04899,638.96578,0.454,0.080954854,27.266763,0.0043472819,99.756016,199.65276,0.2559,1,,,,2.3483404E-5,54.543588,245.10959,0.23847386,0
8293829.98,,5905,,16.4066,90000.219,9E-6,15.876122,0.17107524,3.7901476,0.01328,46.455183,0.05039,649.42906,1.061,0.18924192,28.412871,0.0077884643,99.586025,201.43405,0.3258,1,,,,2.2938792E-5,54.533526,252.05125,0.23873258,0
8294055.64,,5905,,16.409,90000.219,9.1E-6,15.880201,0.1757585,3.8575269,0.01218,46.483073,0.05042,660.17632,0.546,3.9750379,28.89709,0.0069470674,99.63171,200.28963,0.2655,1,,,,2.2918765E-5,56.825741,252.18077,0.24291425,0
8294254.77,,5905,,16.4066,90000.219,9.1E-6,15.886249,0.17580973,3.8186837,0.01236,46.51541,0.05046,654.02908,0.6899,0.26344919,27.511131,0.0045073958,99.751548,201.05248,0.2832,1,,,,2.3824351E-5,57.79418,252.37291,0.24037667,0
8294587.67,,5905,,16.6361,90000.219,9.2E-6,16.100902,0.17224861,3.9155435,0.01248,47.957365,0.05207,670.88045,0.6133,0.19589194,28.234113,0.0061453584,99.671292,202.051,0.2744,1,,,,2.3828918E-5,55.022262,259.23905,0.24318783,0
8294812.42,,5905,,16.6357,90000.219,9.1E-6,16.10255,0.17649445,3.9153387,0.01219,47.967896,0.05209,670.8584,0.4438,0.55171811,27.940862,0.0047734431,99.742188,202.07525,0.2559,1,,,,2.4063451E-5,56.468225,259.29211,0.24315023,0
8295006.02,,5905,,16.6367,90000.219,9.1E-6,16.10466,0.17349565,3.9209935,0.01241,47.978954,0.0521,671.76909,0.5687,0.14281122,27.231408,0.0021398701,99.881412,202.00311,0.2694,1,,,,2.4694164E-5,55.881725,259.36007,0.2434695,0
8295339.94,,5905,,16.8649,90000.219,9.1E-6,16.322624,0.17408895,4.012556,0.01275,49.470088,0.05408,687.82688,0.612,0.39109881,28.637186,0.0065432924,99.656839,203.14464,0.2744,1,,,,2.4089915E-5,54.462817,266.42805,0.24582788,0
8295537.69,,5905,,16.8648,90000.219,9.1E-6,16.328374,0.18119461,4.009691,0.01275,49.506788,0.05413,687.40778,0.6169,0.461486,28.379755,0.0055904939,99.70462,203.26534,0.2751,1,,,,2.4283573E-5,57.274373,266.61579,0.24556585,0
8295733.89,,5905,,16.8649,90000.219,9.1E-6,16.329049,0.17982729,4.0109288,0.01254,49.511725,0.05413,687.60964,0.4926,0.77659206,28.205951,0.004296613,99.771655,203.25251,0.2617,1,,,,2.4426231E-5,56.75951,266.63784,0.2456315,0
8296075.06,,5905,,17.0867,90000.219,9.1E-6,16.546698,0.18050623,4.1075422,0.01314,51.018475,0.05645,704.4866,0.6702,0.25383486,28.839634,0.0060997008,99.684425,204.30832,0.2808,1,,,,2.4494274E-5,56.411903,273.79322,0.24823938,0
8296302.89,,5905,,17.0868,90000.219,9E-6,16.551662,0.1846009,4.1059501,0.01275,51.052321,0.0565,704.26716,0.4411,0.44918257,28.557806,0.0050225947,99.737923,204.39645,0.2567,1,,,,2.4716865E-5,57.679267,273.95752,0.24806875,0
8296530.05,,5905,,17.0924,90000.219,9.1E-6,16.55195,0.18348539,4.1072168,0.01273,51.053576,0.05651,704.46993,0.4277,1.5351089,28.558162,0.0051890909,99.729156,204.37864,0.2553,1,,,,2.4725547E-5,57.115612,273.96703,0.24814097,0
8296868.42,,5905,,17.3179,90000.219,9.1E-6,16.769706,0.1846768,4.2019795,0.0133,52.582779,0.05912,721.07491,0.6103,0.22966568,29.018839,0.0045283252,99.768793,205.47272,0.2749,1,,,,2.489801E-5,57.116323,281.22304,0.25056966,0
8297070.66,,5905,,17.3203,90000.219,9.1E-6,16.77424,0.18868397,4.2023227,0.01318,52.615601,0.05918,721.16234,0.5416,2.5793673,29.017991,0.0059861327,99.694328,205.52258,0.2678,1,,,,2.4917749E-5,58.037679,281.37513,0.25052239,0
8297300.83,,5905,,17.3144,90000.219,9.1E-6,16.775173,0.18821012,4.2096649,0.01316,52.621339,0.05919,722.33614,0.5115,1.0453816,28.929027,0.0051920664,99.733764,205.41237,0.2645,1,,,,2.5026558E-5,58.035981,281.40642,0.25094614,0
8297649.58,,5905,,17.545,90000.219,9E-6,16.990932,0.18911904,4.3085905,0.01379,54.161046,0.06204,739.61391,0.7072,0.28988514,29.521291,0.0062058328,99.689558,206.42107,0.2848,1,,,,2.5120601E-5,57.858054,288.69177,0.25358176,0
8297853.64,,5905,,17.545,90000.219,9.1E-6,16.996336,0.19290792,4.3081926,0.01347,54.195704,0.0621,739.58526,0.5293,0.18910359,29.114104,0.0044570984,99.774198,206.49319,0.2667,1,,,,2.545237E-5,59.042583,288.87543,0.25347773,0
8298054.88,,5905,,17.5456,90000.219,9.1E-6,16.996036,0.19155304,4.3062077,0.01347,54.195,0.0621,739.26878,0.5322,0.14375329,29.124492,0.0046487027,99.764649,206.52185,0.2671,1,,,,2.5434492E-5,58.228208,288.86523,0.25336542,0
8298459.27,,5905,,17.7826,90000.219,9E-6,17.218864,0.18936999,4.4183049,0.01385,55.796343,0.06524,758.70365,0.5638,0.11010572,28.53775,0.0025845817,99.866947,207.41107,0.2703,1,,,,2.6616372E-5,58.248985,296.48928,0.25659677,0
8298685.45,,5905,,17.7707,90000.219,9E-6,17.217481,0.19643459,4.4179634,0.01555,55.808526,0.06526,758.6615,1.257,2.55724,31.449398,0.012131918,99.431638,207.39986,0.3397,1,,,,2.4241641E-5,57.075499,296.44166,0.25659755,0
8298931.91,,5905,,17.7713,90000.219,9.1E-6,17.224388,0.20749056,4.4278939,0.01556,55.853789,0.06535,760.28661,1.254,0.96654514,31.226239,0.011670689,99.448731,207.32479,0.339,1,,,,2.4463591E-5,62.898795,296.67954,0.25707119,0
8299296.92,,5905,,18.0022,90000.219,9.2E-6,17.444603,0.20419965,4.5140175,0.01453,57.453415,0.06861,775.58762,0.7808,0.32774727,30.114552,0.006184743,99.699932,208.60447,0.2923,1,,,,2.5821048E-5,62.452478,304.31417,0.25876299,0
8299504.64,,5905,,18.0022,90000.219,9.1E-6,17.447112,0.20224867,4.498314,0.01401,57.47335,0.06865,773.10929,0.5148,0.94594562,29.741888,0.0050856439,99.751072,208.88192,0.2665,1,,,,2.6049546E-5,60.229104,304.40171,0.25782571,0
8299709.53,,5905,,17.9962,90000.219,9.1E-6,17.446185,0.20073814,4.5099792,0.01414,57.468157,0.06864,774.9599,0.578,0.29760677,29.807363,0.0048224627,99.763956,208.68692,0.2725,1,,,,2.6051679E-5,59.483777,304.36937,0.25850805,0